Workbook

Sheet Start Here
B2: Beverage Competitor Intelligence
B3: What's selling in energy, sparkling water and functional drinks on Amazon.ca, who wins, why, and where the open gaps are.
B5: 125 | C5: 102 | D5: 2,927 | E5: 50%
B6: product lines | C6: brands | D6: SKUs mapped | E6: are sugar free
B8: 📊 See the category | D8: 💡 Read the insights
B9: Big picture dashboard: KPIs, category charts and the headline takeaways at a glance. | D9: The 'so what': top findings, flavour whitespace, a positioning map and an opportunity shortlist.
B14: 🥤 Add live prices | D14: 📖 How it's built
B15: Turn estimates into decision grade data. Follow the simple capture steps, drop a file, done. | D15: Plain language methodology, the honesty model, scoring, and a clickable index of all tabs.
B20: What you can trust
B21: ✓ Retrieved | C21: 47 of 125 lines have nutrition retrieved and cited in the Enrichment Log. Sort or filter column P1 on any master tab to see exactly which.
B22: ◻ Recalled | C22: 60 lines were confirmed in a batch from recall rather than a retrieval. Marked to confirm, not sourced.
B23: ✗ No source | C23: 18 lines carry no enrichment entry at all. These are the weakest rows in the file.
B24: ◻ Pending | C24: Live prices, ratings and Subscribe & Save are left blank until captured, never guessed.
B25: ⚙ Advanced | C25: Every number is reproducible code, machine checked by an automated integrity test, and built in CI.
B27: Updated 2026-10-31 · tip: every tab is one click away from the index on the “How it's built” page.

Sheet README & Methodology
B2: Amazon.ca Beverage, Competitor Intelligence Master File
B3: Build date: 2026-10-31 | v3 Enterprise | 2927 SKUs from 125 product lines / 102 brands
B5: Table of Contents (click to jump)
B6: 1. Start Here | C6: Plain language home page, the simplest way in.
B7: 2. README & Methodology | C7: Honesty model, scoring, scope, and this index.
B8: 3. Executive Dashboard | C8: KPIs, charts and the top key findings at a glance.
B9: 4. Strategic Insights | C9: Synthesized findings, flavour whitespace, positioning map, opportunity shortlist.
B10: 5. Data Dictionary | C10: Every field defined, meaning, source class, fill status.
B11: 6. M1 Sparkling Electrolyte | C11: SKU level master: sparkling electrolyte / functional sparkling.
B12: 7. M2 Electrolyte RTD | C12: SKU level master: electrolyte beverages (RTD).
B13: 8. M3 Functional Beverage | C13: SKU level master: functional beverages (still/sparkling).
B14: 9. M4 Caffeine & Energy | C14: SKU level master: caffeine & energy beverages.
B15: 10. M5 Sparkling Water & Soda | C15: SKU level master: sparkling water & soda.
B16: 11. Brand Roll up | C16: Per brand SKU counts, avg nutrition and scores.
B17: 12. Category Benchmarks | C17: Per category averages, ranges and sugar free counts.
... B28: 23. Sources | C28: Source classes and references behind the stable attributes.
B30: CRITICAL, READ FIRST
B31: Data access limitation | C31: Generated with NO live access to Amazon (HTTP 403 on search, product, and brand pages). The file therefore contains NO live prices, Subscribe & Save terms, coupons, ratings, review counts, badges, ranks, or URLs. Those cells are intentionally BLANK and amber highlighted, they are NOT fabricated.
B32: SKU model, how the rows are built | C32: The Master tabs are SKU level. Because each flavour x pack size is a separate ASIN on Amazon, every product LINE is exploded into individual SKU rows (line x flavour x pack). These are DERIVED / CANDIDATE SKUs to verify against live listings, NOT confirmed ASINs. Flavour lists are representative not exhaustive, and some specific flavour+pack combinations may not exist exactly as shown. The live catalogue cannot be enumerated without Amazon access; this expansion approximates its shape.
B33: What IS filled (and its confidence) | C33: Stable attributes, brand, SKU, format/size, typical pack, flavours, caffeine/sodium/potassium/sugar/calories, sweetener, claims, positioning, plus an honest velocity ESTIMATE, filled from manufacturer + secondary sources. Treat all as APPROXIMATE and verify on the live label. Nutrition is per single serving and varies by flavour.
B34: What is BLANK (capture live) | C34: Fields 6, 9 to 14, 23 to 26, 30 and helper H2. All amber. Filled by a live capture pass (see 'Live Capture Protocol' tab).
B35: Built in automation | C35: Fields 7,8,11,14 are LIVE FORMULAS. Enter price (F), pack (E), S&S % as decimal (J, e.g. 0.15) and coupon value (H2); per unit, per 100 mL, S&S price and stacked floor compute instantly and the red row flag clears.
B36: NEW v2, computed analytics | C36: Columns C1 to C7 on every Master tab: Caffeine/100 mL, Sugar/100 mL, Sodium/100 mL, Sugar Free flag, Health Score, Functional Score, all live formulas off the nutrition you can already see.
B37: Health Score (0 to 100) model | C37: Formula: MAX of 0 and MIN of 100 and (100 minus sugar times 2.5 minus calories times 0.12 plus 12 when sugar is 1 g or under). Higher is lighter and cleaner. Transparent and editable; based on APPROXIMATE nutrition.
B38: Functional Score (0 to 100) model | C38: Sodium (>=100=20, >=30=10) + Potassium (>=100=20) + Caffeine (>=150=20, >=50=12, else 5) + Low sugar bonus (<=1 g=15). Higher = more 'functional' payload. A heuristic, not a medical claim.
B39: Stacking model (field 14) | C39: Lowest Effective is (Price less Coupon) times (1 less the S&S percentage). Assumes coupon + subscription stack on one order (usual Amazon behaviour); confirm per listing.
B40: Velocity estimate (field 27) | C40: Bands are ESTIMATES from brand prominence/category position because live review counts/BSR were not accessible. Re derive from real #Ratings + BSR once captured. Never a unit count.
B41: Scope rules | C41: RTD only. Powders, drink mix packets, tablets EXCLUDED (Liquid I.V., Nuun, LMNT, Cure powder, Cirkul). One PRIMARY category per product; overlaps noted.
B42: Cross tab linkage | C42: Pricing & Promo and Subscription tabs are LIVE LINKED to the Master tabs, fill a price once and those tabs update automatically.
... B46: Automated integrity test | C46: 'nothing fabricated' is machine enforced, not just promised: test_competitor_intel.py asserts every commercial cell is blank, every computed column is a formula, nutrition is in range, SKU counts reconcile across tabs, and all TOC links + Enrichment Log citations resolve. It runs automatically at the end of every build and the build fails if any check fails. Run it any time with: python3 test_competitor_intel.py

Sheet Executive Dashboard
B2: Executive Dashboard
B3: Amazon.ca ready to drink beverage field | 2026-10-31 | ESTIMATE and secondary data, see README
B5: 2927 | C5: 125 | D5: 102 | E5: 5 | F5: 12.9 | G5: =(COUNT('M1 Sparkling Electrolyte'!F2:F255)+COUNT('M2 Electrolyte RTD'!F2:F405)+COUNT('M3 Functional Beverage'!F2:F556)+COUNT('M4 Caffeine & Energy'!F2:F816)+COUNT('M5 Sparkling Water & Soda'!F2:F900))/2927
B6: SKUs | C6: Product lines | D6: Brands | E6: Categories | F6: Avg sugar (g) per line | G6: Price capture %
B19: Category direction (outside data, not computed from this file)
B20: Segment | C20: Dollar growth | D20: Volume growth | E20: Base period | F20: Geography | G20: Source
B21: Sports and hydration <<< Organika's lane | C21: +1.8% | D21: -0.2% | E21: 52 weeks to 19 Apr 2026 | F21: US multi outlet | G21: Circana via Beverage Industry 2026
B22: Energy | C22: +13.7% | D22: +12.0% | E22: LTM to 9 Aug 2026 | F22: US off premise | G22: Circana via Capstone Partners 8 Oct 2026
B23: Sparkling water, non flavoured | C23: +8.1% | D23: +5.8% | E23: 52 weeks to 19 Apr 2026 | F23: US multi outlet | G23: Circana via Beverage Industry 2026
B24: Prebiotic and gut soda | C24: declining | D24: declining | E24: H1 2026 | F24: US retail | G24: Beverage Digest 5 Aug 2026
B25: Cola, full sugar | C25: -8% | D25: not stated | E25: 2025 | F25: US | G25: Mintel via Beverage Industry 2026
B26: Cola, diet and zero | C26: +11.8% | D26: not stated | E26: 2025 | F26: US | G26: Mintel via Beverage Industry 2026
B27: Sparkling water, prior period | C27: +11.6% | D27: not stated | E27: 52 weeks to 10 Aug 2025 | F27: US multi outlet | G27: Circana via Beverage Industry 2026, the comparison period for the row above
B28: Canada, all segments | C28: no data held | D28: no data held | E28: n/a | F28: Canada | G28: None held. Owner Louis, by 30 Nov 2026: commission a NielsenIQ Canada or Circana Canada pull. Until then every rate above is a US proxy.
B29: Read this before any whitespace on the Strategic Insights tab. Organika's own lane grows 1.8% in dollars with volume going backwards, so a gap found there has to be won from a named competitor, not from category growth. Sparkling water growth slowed from 11.6% to 8.1% across the two 52 week periods. The two energy reads sit on different bases and channel definitions and are not averaged. Every rate in this block is US and none of it is ecommerce. Treat it as direction only, never as a level, and never quote one as a Canadian or an Amazon figure.
B32: Key findings (full synthesis on the 'Strategic Insights' tab)
B33: • Field scope | C33: 124 competitor lines across 101 brands and 5 ready to drink categories, plus the Organika benchmark line, 2927 SKU permutations in total. Nutrition provenance is carried per line in column P1: 47 of 125 lines retrieved and cited, 60 recalled and batch confirmed, 18 with no enrichment entry. Commercial fields await live capture.
B34: • Zero sugar is now the default, not the exception | C34: 62 of 125 lines (50%) are sugar free (≤1 g). Most sugar free category: Sparkling electrolyte / functional sparkling (90%); least: Functional beverage (still/sparkling) (35%). 26 lines still carry ≥30 g sugar, a shrinking, vulnerable segment.
B35: • Natural zero sweeteners, as a snapshot not a trend | C35: 7 lines are natural zero only (stevia or monk fruit) and 5 more blend natural with artificial, against 29 artificial only. This is the composition of the lines sampled, not a direction of travel: one cross section cannot show share moving. Outside benchmark: sucralose still leads sweetener new product development while monk fruit concentrate grows fastest (Innova via Food Ingredients First, 11 Feb 2026). EFSA reaffirmed the sucralose ADI in Feb 2026, so the shift is clean label, not safety.
B36: • Energy caffeine has bifurcated | C36: 12 of 37 energy lines (32%) now dose ≥200 mg caffeine. Read against Canadian law rather than as free positioning: Health Canada caps a single serve container at 180 mg and 400 mg per litre, and treats any container that cannot be resealed as single serve at any size. The size at which a resealable container stops being single serve is NOT settled in this file: Health Canada's proposed approach says 591 mL, its Category Specific Guidance says 750 mL, and that guidance is archived and superseded by the Supplemented Foods Regulations. Do not quote a resealable threshold externally without checking the current regulation. Every line above 180 mg is therefore a US formulation or not a compliant Canadian single serve, and this file cannot yet tell which. One carve out: the ceiling governs caffeinated energy drinks sold as foods, and an energy shot is normally licensed in Canada as a natural health product instead, so a flagged shot is a question rather than a breach. That carve out covers exactly one flagged line, 5-hour Energy Shot, and the classification is not confirmed here: look the product up in Health Canada's Licensed Natural Health Products Database before treating it as settled. US demand for that tier is not flattening: energy grew 13.7% in dollars LTM to 9 Aug 2026 (Circana via Capstone).
B67: Chart data (computed from stable attributes)
B68: Category | C68: # SKUs | D68: Avg sugar (g) per line | E68: Avg caffeine (mg) per line
B69: Sparkling electrolyte / functional sparkling | C69: 254 | D69: 0.8 | E69: 34.9
B70: Electrolyte beverage (RTD) | C70: 404 | D70: 9.5 | E70: 0
B71: Functional beverage (still/sparkling) | C71: 555 | D71: 6.5 | E71: 5.5
B72: Caffeine & energy beverage | C72: 815 | D72: 19.1 | E72: 154.6
B73: Sparkling water & soda | C73: 899 | D73: 15.2 | E73: 10.8
B75: Sweetener class | C75: # Products
B76: Caloric only | C76: 41
B77: Non caloric only | C77: 41
B78: None / unsweetened | C78: 23
B79: Blend (caloric + non caloric) | C79: 16
B80: Other | C80: 4

Sheet Strategic Insights
B2: Strategic Insights & Opportunity Whitespace
B3: Synthesis of verified STABLE attributes | 2026-10-31 | every figure computed from the data set, not asserted
B5: A. What the lines in this file show (computed from this file)
B6: Field scope | C6: 124 competitor lines across 101 brands and 5 ready to drink categories, plus the Organika benchmark line, 2927 SKU permutations in total. Nutrition provenance is carried per line in column P1: 47 of 125 lines retrieved and cited, 60 recalled and batch confirmed, 18 with no enrichment entry. Commercial fields await live capture.
B7: Zero sugar is now the default, not the exception | C7: 62 of 125 lines (50%) are sugar free (≤1 g). Most sugar free category: Sparkling electrolyte / functional sparkling (90%); least: Functional beverage (still/sparkling) (35%). 26 lines still carry ≥30 g sugar, a shrinking, vulnerable segment.
B8: Natural zero sweeteners, as a snapshot not a trend | C8: 7 lines are natural zero only (stevia or monk fruit) and 5 more blend natural with artificial, against 29 artificial only. This is the composition of the lines sampled, not a direction of travel: one cross section cannot show share moving. Outside benchmark: sucralose still leads sweetener new product development while monk fruit concentrate grows fastest (Innova via Food Ingredients First, 11 Feb 2026). EFSA reaffirmed the sucralose ADI in Feb 2026, so the shift is clean label, not safety.
B9: Energy caffeine has bifurcated | C9: 12 of 37 energy lines (32%) now dose ≥200 mg caffeine. Read against Canadian law rather than as free positioning: Health Canada caps a single serve container at 180 mg and 400 mg per litre, and treats any container that cannot be resealed as single serve at any size. The size at which a resealable container stops being single serve is NOT settled in this file: Health Canada's proposed approach says 591 mL, its Category Specific Guidance says 750 mL, and that guidance is archived and superseded by the Supplemented Foods Regulations. Do not quote a resealable threshold externally without checking the current regulation. Every line above 180 mg is therefore a US formulation or not a compliant Canadian single serve, and this file cannot yet tell which. One carve out: the ceiling governs caffeinated energy drinks sold as foods, and an energy shot is normally licensed in Canada as a natural health product instead, so a flagged shot is a question rather than a breach. That carve out covers exactly one flagged line, 5-hour Energy Shot, and the classification is not confirmed here: look the product up in Health Canada's Licensed Natural Health Products Database before treating it as settled. US demand for that tier is not flattening: energy grew 13.7% in dollars LTM to 9 Aug 2026 (Circana via Capstone).
B10: Flavour whitespace concentrated in a few families | C10: Least served flavour families across the field: Cola/Root Beer (4 brands); Coconut (9 brands); Ginger (11 brands). These are the clearest line extension gaps for a challenger brand (see Flavour Whitespace matrix below).
B11: Functional + electrolyte crossover is the structural growth vector | C11: Categories 1 to 3 (functional/electrolyte sparkling) skew sugar free with added minerals/vitamins; they are where premium price and Subscribe & Save retention concentrate once live pricing is captured.
B13: B. Flavour whitespace, # distinct brands offering each family, by category (low = opportunity)
B14: Flavour family | C14: Sparkling electrolyte / functional sparkling | D14: Electrolyte beverage (RTD) | E14: Functional beverage (still/sparkling) | F14: Caffeine & energy beverage | G14: Sparkling water & soda | H14: All
B15: Cola/Root Beer | C15: 0 | D15: 0 | E15: 2 | F15: 2 | G15: 1 | H15: 4
B16: Citrus (Lem/Lime) | C16: 9 | D16: 5 | E16: 12 | F16: 11 | G16: 19 | H16: 54
B17: Orange/Mango | C17: 3 | D17: 6 | E17: 14 | F17: 12 | G17: 12 | H17: 47
B18: Berry/Rasp | C18: 8 | D18: 11 | E18: 18 | F18: 18 | G18: 13 | H18: 67
B19: Cherry | C19: 4 | D19: 4 | E19: 8 | F19: 2 | G19: 14 | H19: 32
B20: Grape | C20: 0 | D20: 5 | E20: 2 | F20: 1 | G20: 5 | H20: 13
B21: Watermelon | C21: 2 | D21: 6 | E21: 4 | F21: 7 | G21: 5 | H21: 23
B22: Peach | C22: 1 | D22: 5 | E22: 5 | F22: 9 | G22: 4 | H22: 24
B23: Tropical/Pineapple | C23: 3 | D23: 5 | E23: 8 | F23: 11 | G23: 6 | H23: 32
B24: Grapefruit | C24: 3 | D24: 0 | E24: 2 | F24: 1 | G24: 8 | H24: 14
B25: Coconut | C25: 2 | D25: 2 | E25: 4 | F25: 0 | G25: 1 | H25: 9
B26: Ginger | C26: 1 | D26: 0 | E26: 9 | F26: 1 | G26: 1 | H26: 11
... B28: Original/Plain | C28: 2 | D28: 4 | E28: 4 | F28: 8 | G28: 21 | H28: 38
B29: Opportunity heat, red = 0 brands (clear whitespace in that category) · amber = 1 to 2 brands (thinly served).
B31: C. Nutrition positioning by category
B32: Category | C32: Lines | D32: % sugar free | E32: Median sugar (g) | F32: Caffeine range (mg) | G32: Positioning read
B33: Sparkling electrolyte / functional sparkling | C33: 10 | D33: 90% | E33: 0 | F33: 0 to 120 | G33: Premium clean tier; sugar free + minerals is table stakes.
B34: Electrolyte beverage (RTD) | C34: 21 | D34: 38% | E34: 3 | F34: 0 | G34: Performance hydration; sodium/potassium load is the differentiator.
B35: Functional beverage (still/sparkling) | C35: 20 | D35: 35% | E35: 5.5 | F35: 0 to 55 | G35: Benefit led (gut/adaptogen/vitamin); sugar varies widely, clean label gap exists.
B36: Caffeine & energy beverage | C36: 37 | D36: 43% | E36: 14 | F36: 18 to 300 | G36: Caffeine defined; dose tier + sweetener choice decide the shelf.
B37: Sparkling water & soda | C37: 37 | D37: 59% | E37: 0 | F37: 0 to 69 | G37: Split between zero everything seltzer and full sugar legacy soda.
B39: D. Sweetener strategy mix (count of lines)
B40: Sweetener strategy | C40: # lines | D40: % of field
B41: Caloric (sugar) | C41: 41 | D41: 33%
B42: Zero (artificial) | C42: 29 | D42: 23%
B43: Unsweetened | C43: 23 | D43: 18%
B44: Caloric + sweetener blend | C44: 16 | D44: 13%
B45: Zero (natural: stevia/monk) | C45: 7 | D45: 6%
B46: Zero (natural + artificial) | C46: 5 | D46: 4%
...

Sheet Data Dictionary
A1: Field # | B1: Field name | C1: Definition / how to read it | D1: Source class | E1: Status in this file
A2: 1 | B2: Brand | C2: Manufacturer/brand name. | D2: Stable | E2: Filled (approx)
A3: 2 | B3: Product Line / SKU Name | C3: Exact product/line name; confirm spelling. | D3: Stable | E3: Filled (approx)
A4: 3 | B4: Category | C4: One of five scope categories (primary). | D4: Assigned | E4: Filled
A5: 4 | B5: Format & Size | C5: Container type + single unit size. | D5: Stable | E5: Filled (approx)
A6: 5 | B6: Pack Count | C6: Units per multipack (typical). | D6: Stable | E6: Filled (typical)
A7: 6 | B7: One Time Price (CAD) | C7: List one time price. | D7: LIVE Amazon.ca | E7: BLANK, capture
A8: 7 | B8: Price / Unit (CAD) | C8: Price divided by pack count. | D8: Calculated | E8: Auto
A9: 8 | B9: Price / 100 mL (CAD) | C9: Price divided by total volume, times 100. | D9: Calculated | E9: Auto
A10: 9 | B10: S&S Offered (Y/N) | C10: Subscribe & Save offered? | D10: LIVE Amazon.ca | E10: BLANK, capture
A11: 10 | B11: S&S Discount % | C11: Enter decimal (0.15=15%). | D11: LIVE Amazon.ca | E11: BLANK, capture
A12: 11 | B12: S&S Price After Discount | C12: Price less the Subscribe and Save percentage. | D12: Calculated | E12: Auto
... A47: P3 | B47: Row Flag | C47: Flags unverified rows. | D47: Meta | E47: Filled

Sheet M1 Sparkling Electrolyte
A1: 1. Brand | B1: 2. Product Line / SKU Name | C1: 3. Category | D1: 4. Format & Size | E1: 5. Pack Count | F1: 6. One Time Price (CAD) | G1: 7. Price / Unit (CAD) | H1: 8. Price / 100 mL (CAD) | I1: 9. S&S Offered (Y/N) | J1: 10. S&S Discount % | K1: 11. S&S Price After Disc. | L1: 12. Coupon on Listing (Y/N + value) | M1: 13. Promotion Text | N1: 14. Lowest Effective Price (stacked) | O1: 15. All Flavours in Listing | P1: 16. Caffeine / Serving (mg) | Q1: 17. Sodium / Serving (mg) | R1: 18. Potassium / Serving (mg) | S1: 19. Sugar / Serving (g) | T1: 20. Calories / Serving | U1: 21. Sweetener Type | V1: 22. Key Functional Claims | W1: 23. Star Rating | X1: 24. Number of Ratings | Y1: 25. Amazon Badge | Z1: 26. Bestseller Rank in Category | AA1: 27a. Est. Weekly Velocity (band) | AB1: 27b. Velocity Signal Used | AC1: 28. Biggest Selling Message | AD1: 29. Why a Shopper Chooses This | AE1: 30. Direct Product URL | AF1: C1. Caffeine /100 mL (mg) | AG1: C2. Sugar /100 mL (g) | AH1: C3. Sodium /100 mL (mg) | AI1: C4. Sugar Free? (<=1 g) | AJ1: C5. Health Score (0 to 100) | AK1: C6. Functional Score (0 to 100) | AL1: H1. Unit Vol (mL) [calc helper] | AM1: H2. Coupon Value (CAD) [calc helper] | AN1: C7. Over Health Canada caffeine ceiling (180 mg per container or 400 mg per litre)? | AO1: 31. Supplemented Food Facts table (Y/N) | AP1: 32. Caution Identifier (Y/N/not required) | AQ1: 33. Bilingual EN and FR panel (Y/N) | AR1: P1. Attribute Provenance | AS1: P2. Commercial Field Status | AT1: P3. Row Flag
A2: Organika | B2: Organika Sparkling Electrolyte (BENCHMARK) | Raspberry | single 355mL | C2: 1) Sparkling electrolyte / functional sparkling | D2: 355 mL can | E2: 1 | G2: =IF(AND(ISNUMBER($F2),ISNUMBER($E2),$E2<>0),$F2/$E2,"") | H2: =IF(AND(ISNUMBER($F2),ISNUMBER($AL2),ISNUMBER($E2),($AL2*$E2)<>0),$F2/($AL2*$E2)*100,"") | K2: =IF(AND(ISNUMBER($F2),ISNUMBER($J2)),$F2*(1-$J2),"") | N2: =IF(ISNUMBER($F2),($F2-IF(ISNUMBER($AM2),$AM2,0))*(1-IF(ISNUMBER($J2),$J2,0)),"") | O2: Raspberry | P2: 0 | Q2: Split not published, 290 mg combined | R2: Split not published, 290 mg combined | S2: 0 | T2: 10 | U2: Not named on launch materials; no artificial sweeteners claimed | V2: BENCHMARK, Organika's own line. 290 mg combined electrolytes per 355 mL can from magnesium glycinate, potassium and sodium, plus Fibersol prebiotic fibre. Zero sugar, no caffeine, 10 calories. Launched August 2026. The per mineral split is not published: sodium and potassium carry no number on purpose, because only the combined figure is published. They are the single highest value cells to fill from the can, and until they are filled this line's Functional Score is understated by up to 40 points. | AA2: n/a | AB2: Benchmark line, not a competitor. No velocity estimated. | AC2: Organika's own sparkling electrolyte, read every competitor against this row | AD2: This is the row to beat, not a shopper choice. | AF2: =IF(AND(ISNUMBER($P2),ISNUMBER($AL2),$AL2<>0),ROUND($P2/$AL2*100,1),"") | AG2: =IF(AND(ISNUMBER($S2),ISNUMBER($AL2),$AL2<>0),ROUND($S2/$AL2*100,2),"") | AH2: =IF(AND(ISNUMBER($Q2),ISNUMBER($AL2),$AL2<>0),ROUND($Q2/$AL2*100,1),"") | AI2: =IF(ISNUMBER($S2),IF($S2<=1,"Yes","No"),"n/a") | AJ2: =IF(ISNUMBER($S2),ROUND(MAX(0,MIN(100,100-$S2*2.5-IF(ISNUMBER($T2),$T2,0)*0.12+IF($S2<=1,12,0))),0),"") | AK2: =IF(ISNUMBER($Q2),IF($Q2>=100,20,IF($Q2>=30,10,0)),0)+IF(ISNUMBER($R2),IF($R2>=100,20,0),0)+IF(ISNUMBER($P2),IF($P2>=150,20,IF($P2>=50,12,5)),0)+IF(ISNUMBER($S2),IF($S2<=1,15,0),0) | AL2: 355 | AN2: =IF(AND(ISNUMBER($P2),ISNUMBER($AL2),$AL2<>0),IF(OR($P2>180,$P2/$AL2*1000>400),"Over ceiling, confirm SKU","Within"),"n/a") | AR2: No enrichment entry, to confirm | AS2: BLANK -> requires live Amazon.ca capture | AT2: Unverified commercial data
A3: Organika | B3: Organika Sparkling Electrolyte (BENCHMARK) | Raspberry | 4 pack 355mL | C3: 1) Sparkling electrolyte / functional sparkling | D3: 355 mL can | E3: 4 | G3: =IF(AND(ISNUMBER($F3),ISNUMBER($E3),$E3<>0),$F3/$E3,"") | H3: =IF(AND(ISNUMBER($F3),ISNUMBER($AL3),ISNUMBER($E3),($AL3*$E3)<>0),$F3/($AL3*$E3)*100,"") | K3: =IF(AND(ISNUMBER($F3),ISNUMBER($J3)),$F3*(1-$J3),"") | N3: =IF(ISNUMBER($F3),($F3-IF(ISNUMBER($AM3),$AM3,0))*(1-IF(ISNUMBER($J3),$J3,0)),"") | O3: Raspberry | P3: 0 | Q3: Split not published, 290 mg combined | R3: Split not published, 290 mg combined | S3: 0 | T3: 10 | U3: Not named on launch materials; no artificial sweeteners claimed | V3: BENCHMARK, Organika's own line. 290 mg combined electrolytes per 355 mL can from magnesium glycinate, potassium and sodium, plus Fibersol prebiotic fibre. Zero sugar, no caffeine, 10 calories. Launched August 2026. The per mineral split is not published: sodium and potassium carry no number on purpose, because only the combined figure is published. They are the single highest value cells to fill from the can, and until they are filled this line's Functional Score is understated by up to 40 points. | AA3: n/a | AB3: Benchmark line, not a competitor. No velocity estimated. | AC3: Organika's own sparkling electrolyte, read every competitor against this row | AD3: This is the row to beat, not a shopper choice. | AF3: =IF(AND(ISNUMBER($P3),ISNUMBER($AL3),$AL3<>0),ROUND($P3/$AL3*100,1),"") | AG3: =IF(AND(ISNUMBER($S3),ISNUMBER($AL3),$AL3<>0),ROUND($S3/$AL3*100,2),"") | AH3: =IF(AND(ISNUMBER($Q3),ISNUMBER($AL3),$AL3<>0),ROUND($Q3/$AL3*100,1),"") | AI3: =IF(ISNUMBER($S3),IF($S3<=1,"Yes","No"),"n/a") | AJ3: =IF(ISNUMBER($S3),ROUND(MAX(0,MIN(100,100-$S3*2.5-IF(ISNUMBER($T3),$T3,0)*0.12+IF($S3<=1,12,0))),0),"") | AK3: =IF(ISNUMBER($Q3),IF($Q3>=100,20,IF($Q3>=30,10,0)),0)+IF(ISNUMBER($R3),IF($R3>=100,20,0),0)+IF(ISNUMBER($P3),IF($P3>=150,20,IF($P3>=50,12,5)),0)+IF(ISNUMBER($S3),IF($S3<=1,15,0),0) | AL3: 355 | AN3: =IF(AND(ISNUMBER($P3),ISNUMBER($AL3),$AL3<>0),IF(OR($P3>180,$P3/$AL3*1000>400),"Over ceiling, confirm SKU","Within"),"n/a") | AR3: No enrichment entry, to confirm | AS3: BLANK -> requires live Amazon.ca capture | AT3: Unverified commercial data
A4: Organika | B4: Organika Sparkling Electrolyte (BENCHMARK) | Lime Lemon | single 355mL | C4: 1) Sparkling electrolyte / functional sparkling | D4: 355 mL can | E4: 1 | G4: =IF(AND(ISNUMBER($F4),ISNUMBER($E4),$E4<>0),$F4/$E4,"") | H4: =IF(AND(ISNUMBER($F4),ISNUMBER($AL4),ISNUMBER($E4),($AL4*$E4)<>0),$F4/($AL4*$E4)*100,"") | K4: =IF(AND(ISNUMBER($F4),ISNUMBER($J4)),$F4*(1-$J4),"") | N4: =IF(ISNUMBER($F4),($F4-IF(ISNUMBER($AM4),$AM4,0))*(1-IF(ISNUMBER($J4),$J4,0)),"") | O4: Lime Lemon | P4: 0 | Q4: Split not published, 290 mg combined | R4: Split not published, 290 mg combined | S4: 0 | T4: 10 | U4: Not named on launch materials; no artificial sweeteners claimed | V4: BENCHMARK, Organika's own line. 290 mg combined electrolytes per 355 mL can from magnesium glycinate, potassium and sodium, plus Fibersol prebiotic fibre. Zero sugar, no caffeine, 10 calories. Launched August 2026. The per mineral split is not published: sodium and potassium carry no number on purpose, because only the combined figure is published. They are the single highest value cells to fill from the can, and until they are filled this line's Functional Score is understated by up to 40 points. | AA4: n/a | AB4: Benchmark line, not a competitor. No velocity estimated. | AC4: Organika's own sparkling electrolyte, read every competitor against this row | AD4: This is the row to beat, not a shopper choice. | AF4: =IF(AND(ISNUMBER($P4),ISNUMBER($AL4),$AL4<>0),ROUND($P4/$AL4*100,1),"") | AG4: =IF(AND(ISNUMBER($S4),ISNUMBER($AL4),$AL4<>0),ROUND($S4/$AL4*100,2),"") | AH4: =IF(AND(ISNUMBER($Q4),ISNUMBER($AL4),$AL4<>0),ROUND($Q4/$AL4*100,1),"") | AI4: =IF(ISNUMBER($S4),IF($S4<=1,"Yes","No"),"n/a") | AJ4: =IF(ISNUMBER($S4),ROUND(MAX(0,MIN(100,100-$S4*2.5-IF(ISNUMBER($T4),$T4,0)*0.12+IF($S4<=1,12,0))),0),"") | AK4: =IF(ISNUMBER($Q4),IF($Q4>=100,20,IF($Q4>=30,10,0)),0)+IF(ISNUMBER($R4),IF($R4>=100,20,0),0)+IF(ISNUMBER($P4),IF($P4>=150,20,IF($P4>=50,12,5)),0)+IF(ISNUMBER($S4),IF($S4<=1,15,0),0) | AL4: 355 | AN4: =IF(AND(ISNUMBER($P4),ISNUMBER($AL4),$AL4<>0),IF(OR($P4>180,$P4/$AL4*1000>400),"Over ceiling, confirm SKU","Within"),"n/a") | AR4: No enrichment entry, to confirm | AS4: BLANK -> requires live Amazon.ca capture | AT4: Unverified commercial data
A5: Organika | B5: Organika Sparkling Electrolyte (BENCHMARK) | Lime Lemon | 4 pack 355mL | C5: 1) Sparkling electrolyte / functional sparkling | D5: 355 mL can | E5: 4 | G5: =IF(AND(ISNUMBER($F5),ISNUMBER($E5),$E5<>0),$F5/$E5,"") | H5: =IF(AND(ISNUMBER($F5),ISNUMBER($AL5),ISNUMBER($E5),($AL5*$E5)<>0),$F5/($AL5*$E5)*100,"") | K5: =IF(AND(ISNUMBER($F5),ISNUMBER($J5)),$F5*(1-$J5),"") | N5: =IF(ISNUMBER($F5),($F5-IF(ISNUMBER($AM5),$AM5,0))*(1-IF(ISNUMBER($J5),$J5,0)),"") | O5: Lime Lemon | P5: 0 | Q5: Split not published, 290 mg combined | R5: Split not published, 290 mg combined | S5: 0 | T5: 10 | U5: Not named on launch materials; no artificial sweeteners claimed | V5: BENCHMARK, Organika's own line. 290 mg combined electrolytes per 355 mL can from magnesium glycinate, potassium and sodium, plus Fibersol prebiotic fibre. Zero sugar, no caffeine, 10 calories. Launched August 2026. The per mineral split is not published: sodium and potassium carry no number on purpose, because only the combined figure is published. They are the single highest value cells to fill from the can, and until they are filled this line's Functional Score is understated by up to 40 points. | AA5: n/a | AB5: Benchmark line, not a competitor. No velocity estimated. | AC5: Organika's own sparkling electrolyte, read every competitor against this row | AD5: This is the row to beat, not a shopper choice. | AF5: =IF(AND(ISNUMBER($P5),ISNUMBER($AL5),$AL5<>0),ROUND($P5/$AL5*100,1),"") | AG5: =IF(AND(ISNUMBER($S5),ISNUMBER($AL5),$AL5<>0),ROUND($S5/$AL5*100,2),"") | AH5: =IF(AND(ISNUMBER($Q5),ISNUMBER($AL5),$AL5<>0),ROUND($Q5/$AL5*100,1),"") | AI5: =IF(ISNUMBER($S5),IF($S5<=1,"Yes","No"),"n/a") | AJ5: =IF(ISNUMBER($S5),ROUND(MAX(0,MIN(100,100-$S5*2.5-IF(ISNUMBER($T5),$T5,0)*0.12+IF($S5<=1,12,0))),0),"") | AK5: =IF(ISNUMBER($Q5),IF($Q5>=100,20,IF($Q5>=30,10,0)),0)+IF(ISNUMBER($R5),IF($R5>=100,20,0),0)+IF(ISNUMBER($P5),IF($P5>=150,20,IF($P5>=50,12,5)),0)+IF(ISNUMBER($S5),IF($S5<=1,15,0),0) | AL5: 355 | AN5: =IF(AND(ISNUMBER($P5),ISNUMBER($AL5),$AL5<>0),IF(OR($P5>180,$P5/$AL5*1000>400),"Over ceiling, confirm SKU","Within"),"n/a") | AR5: No enrichment entry, to confirm | AS5: BLANK -> requires live Amazon.ca capture | AT5: Unverified commercial data
A6: Organika | B6: Organika Sparkling Electrolyte (BENCHMARK) | Passion Fruit Pineapple | single 355mL | C6: 1) Sparkling electrolyte / functional sparkling | D6: 355 mL can | E6: 1 | G6: =IF(AND(ISNUMBER($F6),ISNUMBER($E6),$E6<>0),$F6/$E6,"") | H6: =IF(AND(ISNUMBER($F6),ISNUMBER($AL6),ISNUMBER($E6),($AL6*$E6)<>0),$F6/($AL6*$E6)*100,"") | K6: =IF(AND(ISNUMBER($F6),ISNUMBER($J6)),$F6*(1-$J6),"") | N6: =IF(ISNUMBER($F6),($F6-IF(ISNUMBER($AM6),$AM6,0))*(1-IF(ISNUMBER($J6),$J6,0)),"") | O6: Passion Fruit Pineapple | P6: 0 | Q6: Split not published, 290 mg combined | R6: Split not published, 290 mg combined | S6: 0 | T6: 10 | U6: Not named on launch materials; no artificial sweeteners claimed | V6: BENCHMARK, Organika's own line. 290 mg combined electrolytes per 355 mL can from magnesium glycinate, potassium and sodium, plus Fibersol prebiotic fibre. Zero sugar, no caffeine, 10 calories. Launched August 2026. The per mineral split is not published: sodium and potassium carry no number on purpose, because only the combined figure is published. They are the single highest value cells to fill from the can, and until they are filled this line's Functional Score is understated by up to 40 points. | AA6: n/a | AB6: Benchmark line, not a competitor. No velocity estimated. | AC6: Organika's own sparkling electrolyte, read every competitor against this row | AD6: This is the row to beat, not a shopper choice. | AF6: =IF(AND(ISNUMBER($P6),ISNUMBER($AL6),$AL6<>0),ROUND($P6/$AL6*100,1),"") | AG6: =IF(AND(ISNUMBER($S6),ISNUMBER($AL6),$AL6<>0),ROUND($S6/$AL6*100,2),"") | AH6: =IF(AND(ISNUMBER($Q6),ISNUMBER($AL6),$AL6<>0),ROUND($Q6/$AL6*100,1),"") | AI6: =IF(ISNUMBER($S6),IF($S6<=1,"Yes","No"),"n/a") | AJ6: =IF(ISNUMBER($S6),ROUND(MAX(0,MIN(100,100-$S6*2.5-IF(ISNUMBER($T6),$T6,0)*0.12+IF($S6<=1,12,0))),0),"") | AK6: =IF(ISNUMBER($Q6),IF($Q6>=100,20,IF($Q6>=30,10,0)),0)+IF(ISNUMBER($R6),IF($R6>=100,20,0),0)+IF(ISNUMBER($P6),IF($P6>=150,20,IF($P6>=50,12,5)),0)+IF(ISNUMBER($S6),IF($S6<=1,15,0),0) | AL6: 355 | AN6: =IF(AND(ISNUMBER($P6),ISNUMBER($AL6),$AL6<>0),IF(OR($P6>180,$P6/$AL6*1000>400),"Over ceiling, confirm SKU","Within"),"n/a") | AR6: No enrichment entry, to confirm | AS6: BLANK -> requires live Amazon.ca capture | AT6: Unverified commercial data
A7: Organika | B7: Organika Sparkling Electrolyte (BENCHMARK) | Passion Fruit Pineapple | 4 pack 355mL | C7: 1) Sparkling electrolyte / functional sparkling | D7: 355 mL can | E7: 4 | G7: =IF(AND(ISNUMBER($F7),ISNUMBER($E7),$E7<>0),$F7/$E7,"") | H7: =IF(AND(ISNUMBER($F7),ISNUMBER($AL7),ISNUMBER($E7),($AL7*$E7)<>0),$F7/($AL7*$E7)*100,"") | K7: =IF(AND(ISNUMBER($F7),ISNUMBER($J7)),$F7*(1-$J7),"") | N7: =IF(ISNUMBER($F7),($F7-IF(ISNUMBER($AM7),$AM7,0))*(1-IF(ISNUMBER($J7),$J7,0)),"") | O7: Passion Fruit Pineapple | P7: 0 | Q7: Split not published, 290 mg combined | R7: Split not published, 290 mg combined | S7: 0 | T7: 10 | U7: Not named on launch materials; no artificial sweeteners claimed | V7: BENCHMARK, Organika's own line. 290 mg combined electrolytes per 355 mL can from magnesium glycinate, potassium and sodium, plus Fibersol prebiotic fibre. Zero sugar, no caffeine, 10 calories. Launched August 2026. The per mineral split is not published: sodium and potassium carry no number on purpose, because only the combined figure is published. They are the single highest value cells to fill from the can, and until they are filled this line's Functional Score is understated by up to 40 points. | AA7: n/a | AB7: Benchmark line, not a competitor. No velocity estimated. | AC7: Organika's own sparkling electrolyte, read every competitor against this row | AD7: This is the row to beat, not a shopper choice. | AF7: =IF(AND(ISNUMBER($P7),ISNUMBER($AL7),$AL7<>0),ROUND($P7/$AL7*100,1),"") | AG7: =IF(AND(ISNUMBER($S7),ISNUMBER($AL7),$AL7<>0),ROUND($S7/$AL7*100,2),"") | AH7: =IF(AND(ISNUMBER($Q7),ISNUMBER($AL7),$AL7<>0),ROUND($Q7/$AL7*100,1),"") | AI7: =IF(ISNUMBER($S7),IF($S7<=1,"Yes","No"),"n/a") | AJ7: =IF(ISNUMBER($S7),ROUND(MAX(0,MIN(100,100-$S7*2.5-IF(ISNUMBER($T7),$T7,0)*0.12+IF($S7<=1,12,0))),0),"") | AK7: =IF(ISNUMBER($Q7),IF($Q7>=100,20,IF($Q7>=30,10,0)),0)+IF(ISNUMBER($R7),IF($R7>=100,20,0),0)+IF(ISNUMBER($P7),IF($P7>=150,20,IF($P7>=50,12,5)),0)+IF(ISNUMBER($S7),IF($S7<=1,15,0),0) | AL7: 355 | AN7: =IF(AND(ISNUMBER($P7),ISNUMBER($AL7),$AL7<>0),IF(OR($P7>180,$P7/$AL7*1000>400),"Over ceiling, confirm SKU","Within"),"n/a") | AR7: No enrichment entry, to confirm | AS7: BLANK -> requires live Amazon.ca capture | AT7: Unverified commercial data
A8: Sparkling Ice | B8: Sparkling Ice (+ Antioxidants & Vitamins) | Black Raspberry | single 503mL | C8: 1) Sparkling electrolyte / functional sparkling | D8: 503 mL bottle | E8: 1 | G8: =IF(AND(ISNUMBER($F8),ISNUMBER($E8),$E8<>0),$F8/$E8,"") | H8: =IF(AND(ISNUMBER($F8),ISNUMBER($AL8),ISNUMBER($E8),($AL8*$E8)<>0),$F8/($AL8*$E8)*100,"") | K8: =IF(AND(ISNUMBER($F8),ISNUMBER($J8)),$F8*(1-$J8),"") | N8: =IF(ISNUMBER($F8),($F8-IF(ISNUMBER($AM8),$AM8,0))*(1-IF(ISNUMBER($J8),$J8,0)),"") | O8: Black Raspberry | P8: 0 | Q8: 0 | R8: 30 | S8: 0 | T8: 5 | U8: Sucralose | V8: Zero sugar, vitamins A/D/B, antioxidants (green tea), bold flavour | AA8: High | AB8: Mass market functional sparkling; strong shelf share | AC8: Bold zero sugar sparkling with added vitamins | AD8: Big flavour and added vitamins at zero sugar. | AF8: =IF(AND(ISNUMBER($P8),ISNUMBER($AL8),$AL8<>0),ROUND($P8/$AL8*100,1),"") | AG8: =IF(AND(ISNUMBER($S8),ISNUMBER($AL8),$AL8<>0),ROUND($S8/$AL8*100,2),"") | AH8: =IF(AND(ISNUMBER($Q8),ISNUMBER($AL8),$AL8<>0),ROUND($Q8/$AL8*100,1),"") | AI8: =IF(ISNUMBER($S8),IF($S8<=1,"Yes","No"),"n/a") | AJ8: =IF(ISNUMBER($S8),ROUND(MAX(0,MIN(100,100-$S8*2.5-IF(ISNUMBER($T8),$T8,0)*0.12+IF($S8<=1,12,0))),0),"") | AK8: =IF(ISNUMBER($Q8),IF($Q8>=100,20,IF($Q8>=30,10,0)),0)+IF(ISNUMBER($R8),IF($R8>=100,20,0),0)+IF(ISNUMBER($P8),IF($P8>=150,20,IF($P8>=50,12,5)),0)+IF(ISNUMBER($S8),IF($S8<=1,15,0),0) | AL8: 503 | AN8: =IF(AND(ISNUMBER($P8),ISNUMBER($AL8),$AL8<>0),IF(OR($P8>180,$P8/$AL8*1000>400),"Over ceiling, confirm SKU","Within"),"n/a") | AR8: Retrieved and cited, see Enrichment Log | AS8: BLANK -> requires live Amazon.ca capture | AT8: Unverified commercial data
A9: Sparkling Ice | B9: Sparkling Ice (+ Antioxidants & Vitamins) | Black Raspberry | 8 pack 503mL | C9: 1) Sparkling electrolyte / functional sparkling | D9: 503 mL bottle | E9: 8 | G9: =IF(AND(ISNUMBER($F9),ISNUMBER($E9),$E9<>0),$F9/$E9,"") | H9: =IF(AND(ISNUMBER($F9),ISNUMBER($AL9),ISNUMBER($E9),($AL9*$E9)<>0),$F9/($AL9*$E9)*100,"") | K9: =IF(AND(ISNUMBER($F9),ISNUMBER($J9)),$F9*(1-$J9),"") | N9: =IF(ISNUMBER($F9),($F9-IF(ISNUMBER($AM9),$AM9,0))*(1-IF(ISNUMBER($J9),$J9,0)),"") | O9: Black Raspberry | P9: 0 | Q9: 0 | R9: 30 | S9: 0 | T9: 5 | U9: Sucralose | V9: Zero sugar, vitamins A/D/B, antioxidants (green tea), bold flavour | AA9: High | AB9: Mass market functional sparkling; strong shelf share | AC9: Bold zero sugar sparkling with added vitamins | AD9: Big flavour and added vitamins at zero sugar. | AF9: =IF(AND(ISNUMBER($P9),ISNUMBER($AL9),$AL9<>0),ROUND($P9/$AL9*100,1),"") | AG9: =IF(AND(ISNUMBER($S9),ISNUMBER($AL9),$AL9<>0),ROUND($S9/$AL9*100,2),"") | AH9: =IF(AND(ISNUMBER($Q9),ISNUMBER($AL9),$AL9<>0),ROUND($Q9/$AL9*100,1),"") | AI9: =IF(ISNUMBER($S9),IF($S9<=1,"Yes","No"),"n/a") | AJ9: =IF(ISNUMBER($S9),ROUND(MAX(0,MIN(100,100-$S9*2.5-IF(ISNUMBER($T9),$T9,0)*0.12+IF($S9<=1,12,0))),0),"") | AK9: =IF(ISNUMBER($Q9),IF($Q9>=100,20,IF($Q9>=30,10,0)),0)+IF(ISNUMBER($R9),IF($R9>=100,20,0),0)+IF(ISNUMBER($P9),IF($P9>=150,20,IF($P9>=50,12,5)),0)+IF(ISNUMBER($S9),IF($S9<=1,15,0),0) | AL9: 503 | AN9: =IF(AND(ISNUMBER($P9),ISNUMBER($AL9),$AL9<>0),IF(OR($P9>180,$P9/$AL9*1000>400),"Over ceiling, confirm SKU","Within"),"n/a") | AR9: Retrieved and cited, see Enrichment Log | AS9: BLANK -> requires live Amazon.ca capture | AT9: Unverified commercial data
A10: Sparkling Ice | B10: Sparkling Ice (+ Antioxidants & Vitamins) | Black Raspberry | 12 pack 503mL | C10: 1) Sparkling electrolyte / functional sparkling | D10: 503 mL bottle | E10: 12 | G10: =IF(AND(ISNUMBER($F10),ISNUMBER($E10),$E10<>0),$F10/$E10,"") | H10: =IF(AND(ISNUMBER($F10),ISNUMBER($AL10),ISNUMBER($E10),($AL10*$E10)<>0),$F10/($AL10*$E10)*100,"") | K10: =IF(AND(ISNUMBER($F10),ISNUMBER($J10)),$F10*(1-$J10),"") | N10: =IF(ISNUMBER($F10),($F10-IF(ISNUMBER($AM10),$AM10,0))*(1-IF(ISNUMBER($J10),$J10,0)),"") | O10: Black Raspberry | P10: 0 | Q10: 0 | R10: 30 | S10: 0 | T10: 5 | U10: Sucralose | V10: Zero sugar, vitamins A/D/B, antioxidants (green tea), bold flavour | AA10: High | AB10: Mass market functional sparkling; strong shelf share | AC10: Bold zero sugar sparkling with added vitamins | AD10: Big flavour and added vitamins at zero sugar. | AF10: =IF(AND(ISNUMBER($P10),ISNUMBER($AL10),$AL10<>0),ROUND($P10/$AL10*100,1),"") | AG10: =IF(AND(ISNUMBER($S10),ISNUMBER($AL10),$AL10<>0),ROUND($S10/$AL10*100,2),"") | AH10: =IF(AND(ISNUMBER($Q10),ISNUMBER($AL10),$AL10<>0),ROUND($Q10/$AL10*100,1),"") | AI10: =IF(ISNUMBER($S10),IF($S10<=1,"Yes","No"),"n/a") | AJ10: =IF(ISNUMBER($S10),ROUND(MAX(0,MIN(100,100-$S10*2.5-IF(ISNUMBER($T10),$T10,0)*0.12+IF($S10<=1,12,0))),0),"") | AK10: =IF(ISNUMBER($Q10),IF($Q10>=100,20,IF($Q10>=30,10,0)),0)+IF(ISNUMBER($R10),IF($R10>=100,20,0),0)+IF(ISNUMBER($P10),IF($P10>=150,20,IF($P10>=50,12,5)),0)+IF(ISNUMBER($S10),IF($S10<=1,15,0),0) | AL10: 503 | AN10: =IF(AND(ISNUMBER($P10),ISNUMBER($AL10),$AL10<>0),IF(OR($P10>180,$P10/$AL10*1000>400),"Over ceiling, confirm SKU","Within"),"n/a") | AR10: Retrieved and cited, see Enrichment Log | AS10: BLANK -> requires live Amazon.ca capture | AT10: Unverified commercial data
A11: Sparkling Ice | B11: Sparkling Ice (+ Antioxidants & Vitamins) | Black Raspberry | 18 pack 503mL | C11: 1) Sparkling electrolyte / functional sparkling | D11: 503 mL bottle | E11: 18 | G11: =IF(AND(ISNUMBER($F11),ISNUMBER($E11),$E11<>0),$F11/$E11,"") | H11: =IF(AND(ISNUMBER($F11),ISNUMBER($AL11),ISNUMBER($E11),($AL11*$E11)<>0),$F11/($AL11*$E11)*100,"") | K11: =IF(AND(ISNUMBER($F11),ISNUMBER($J11)),$F11*(1-$J11),"") | N11: =IF(ISNUMBER($F11),($F11-IF(ISNUMBER($AM11),$AM11,0))*(1-IF(ISNUMBER($J11),$J11,0)),"") | O11: Black Raspberry | P11: 0 | Q11: 0 | R11: 30 | S11: 0 | T11: 5 | U11: Sucralose | V11: Zero sugar, vitamins A/D/B, antioxidants (green tea), bold flavour | AA11: High | AB11: Mass market functional sparkling; strong shelf share | AC11: Bold zero sugar sparkling with added vitamins | AD11: Big flavour and added vitamins at zero sugar. | AF11: =IF(AND(ISNUMBER($P11),ISNUMBER($AL11),$AL11<>0),ROUND($P11/$AL11*100,1),"") | AG11: =IF(AND(ISNUMBER($S11),ISNUMBER($AL11),$AL11<>0),ROUND($S11/$AL11*100,2),"") | AH11: =IF(AND(ISNUMBER($Q11),ISNUMBER($AL11),$AL11<>0),ROUND($Q11/$AL11*100,1),"") | AI11: =IF(ISNUMBER($S11),IF($S11<=1,"Yes","No"),"n/a") | AJ11: =IF(ISNUMBER($S11),ROUND(MAX(0,MIN(100,100-$S11*2.5-IF(ISNUMBER($T11),$T11,0)*0.12+IF($S11<=1,12,0))),0),"") | AK11: =IF(ISNUMBER($Q11),IF($Q11>=100,20,IF($Q11>=30,10,0)),0)+IF(ISNUMBER($R11),IF($R11>=100,20,0),0)+IF(ISNUMBER($P11),IF($P11>=150,20,IF($P11>=50,12,5)),0)+IF(ISNUMBER($S11),IF($S11<=1,15,0),0) | AL11: 503 | AN11: =IF(AND(ISNUMBER($P11),ISNUMBER($AL11),$AL11<>0),IF(OR($P11>180,$P11/$AL11*1000>400),"Over ceiling, confirm SKU","Within"),"n/a") | AR11: Retrieved and cited, see Enrichment Log | AS11: BLANK -> requires live Amazon.ca capture | AT11: Unverified commercial data
A12: Sparkling Ice | B12: Sparkling Ice (+ Antioxidants & Vitamins) | Black Raspberry | 24 pack 503mL | C12: 1) Sparkling electrolyte / functional sparkling | D12: 503 mL bottle | E12: 24 | G12: =IF(AND(ISNUMBER($F12),ISNUMBER($E12),$E12<>0),$F12/$E12,"") | H12: =IF(AND(ISNUMBER($F12),ISNUMBER($AL12),ISNUMBER($E12),($AL12*$E12)<>0),$F12/($AL12*$E12)*100,"") | K12: =IF(AND(ISNUMBER($F12),ISNUMBER($J12)),$F12*(1-$J12),"") | N12: =IF(ISNUMBER($F12),($F12-IF(ISNUMBER($AM12),$AM12,0))*(1-IF(ISNUMBER($J12),$J12,0)),"") | O12: Black Raspberry | P12: 0 | Q12: 0 | R12: 30 | S12: 0 | T12: 5 | U12: Sucralose | V12: Zero sugar, vitamins A/D/B, antioxidants (green tea), bold flavour | AA12: High | AB12: Mass market functional sparkling; strong shelf share | AC12: Bold zero sugar sparkling with added vitamins | AD12: Big flavour and added vitamins at zero sugar. | AF12: =IF(AND(ISNUMBER($P12),ISNUMBER($AL12),$AL12<>0),ROUND($P12/$AL12*100,1),"") | AG12: =IF(AND(ISNUMBER($S12),ISNUMBER($AL12),$AL12<>0),ROUND($S12/$AL12*100,2),"") | AH12: =IF(AND(ISNUMBER($Q12),ISNUMBER($AL12),$AL12<>0),ROUND($Q12/$AL12*100,1),"") | AI12: =IF(ISNUMBER($S12),IF($S12<=1,"Yes","No"),"n/a") | AJ12: =IF(ISNUMBER($S12),ROUND(MAX(0,MIN(100,100-$S12*2.5-IF(ISNUMBER($T12),$T12,0)*0.12+IF($S12<=1,12,0))),0),"") | AK12: =IF(ISNUMBER($Q12),IF($Q12>=100,20,IF($Q12>=30,10,0)),0)+IF(ISNUMBER($R12),IF($R12>=100,20,0),0)+IF(ISNUMBER($P12),IF($P12>=150,20,IF($P12>=50,12,5)),0)+IF(ISNUMBER($S12),IF($S12<=1,15,0),0) | AL12: 503 | AN12: =IF(AND(ISNUMBER($P12),ISNUMBER($AL12),$AL12<>0),IF(OR($P12>180,$P12/$AL12*1000>400),"Over ceiling, confirm SKU","Within"),"n/a") | AR12: Retrieved and cited, see Enrichment Log | AS12: BLANK -> requires live Amazon.ca capture | AT12: Unverified commercial data
A13: Sparkling Ice | B13: Sparkling Ice (+ Antioxidants & Vitamins) | Cherry Limeade | single 503mL | C13: 1) Sparkling electrolyte / functional sparkling | D13: 503 mL bottle | E13: 1 | G13: =IF(AND(ISNUMBER($F13),ISNUMBER($E13),$E13<>0),$F13/$E13,"") | H13: =IF(AND(ISNUMBER($F13),ISNUMBER($AL13),ISNUMBER($E13),($AL13*$E13)<>0),$F13/($AL13*$E13)*100,"") | K13: =IF(AND(ISNUMBER($F13),ISNUMBER($J13)),$F13*(1-$J13),"") | N13: =IF(ISNUMBER($F13),($F13-IF(ISNUMBER($AM13),$AM13,0))*(1-IF(ISNUMBER($J13),$J13,0)),"") | O13: Cherry Limeade | P13: 0 | Q13: 0 | R13: 30 | S13: 0 | T13: 5 | U13: Sucralose | V13: Zero sugar, vitamins A/D/B, antioxidants (green tea), bold flavour | AA13: High | AB13: Mass market functional sparkling; strong shelf share | AC13: Bold zero sugar sparkling with added vitamins | AD13: Big flavour and added vitamins at zero sugar. | AF13: =IF(AND(ISNUMBER($P13),ISNUMBER($AL13),$AL13<>0),ROUND($P13/$AL13*100,1),"") | AG13: =IF(AND(ISNUMBER($S13),ISNUMBER($AL13),$AL13<>0),ROUND($S13/$AL13*100,2),"") | AH13: =IF(AND(ISNUMBER($Q13),ISNUMBER($AL13),$AL13<>0),ROUND($Q13/$AL13*100,1),"") | AI13: =IF(ISNUMBER($S13),IF($S13<=1,"Yes","No"),"n/a") | AJ13: =IF(ISNUMBER($S13),ROUND(MAX(0,MIN(100,100-$S13*2.5-IF(ISNUMBER($T13),$T13,0)*0.12+IF($S13<=1,12,0))),0),"") | AK13: =IF(ISNUMBER($Q13),IF($Q13>=100,20,IF($Q13>=30,10,0)),0)+IF(ISNUMBER($R13),IF($R13>=100,20,0),0)+IF(ISNUMBER($P13),IF($P13>=150,20,IF($P13>=50,12,5)),0)+IF(ISNUMBER($S13),IF($S13<=1,15,0),0) | AL13: 503 | AN13: =IF(AND(ISNUMBER($P13),ISNUMBER($AL13),$AL13<>0),IF(OR($P13>180,$P13/$AL13*1000>400),"Over ceiling, confirm SKU","Within"),"n/a") | AR13: Retrieved and cited, see Enrichment Log | AS13: BLANK -> requires live Amazon.ca capture | AT13: Unverified commercial data
A14: Sparkling Ice | B14: Sparkling Ice (+ Antioxidants & Vitamins) | Cherry Limeade | 8 pack 503mL | C14: 1) Sparkling electrolyte / functional sparkling | D14: 503 mL bottle | E14: 8 | G14: =IF(AND(ISNUMBER($F14),ISNUMBER($E14),$E14<>0),$F14/$E14,"") | H14: =IF(AND(ISNUMBER($F14),ISNUMBER($AL14),ISNUMBER($E14),($AL14*$E14)<>0),$F14/($AL14*$E14)*100,"") | K14: =IF(AND(ISNUMBER($F14),ISNUMBER($J14)),$F14*(1-$J14),"") | N14: =IF(ISNUMBER($F14),($F14-IF(ISNUMBER($AM14),$AM14,0))*(1-IF(ISNUMBER($J14),$J14,0)),"") | O14: Cherry Limeade | P14: 0 | Q14: 0 | R14: 30 | S14: 0 | T14: 5 | U14: Sucralose | V14: Zero sugar, vitamins A/D/B, antioxidants (green tea), bold flavour | AA14: High | AB14: Mass market functional sparkling; strong shelf share | AC14: Bold zero sugar sparkling with added vitamins | AD14: Big flavour and added vitamins at zero sugar. | AF14: =IF(AND(ISNUMBER($P14),ISNUMBER($AL14),$AL14<>0),ROUND($P14/$AL14*100,1),"") | AG14: =IF(AND(ISNUMBER($S14),ISNUMBER($AL14),$AL14<>0),ROUND($S14/$AL14*100,2),"") | AH14: =IF(AND(ISNUMBER($Q14),ISNUMBER($AL14),$AL14<>0),ROUND($Q14/$AL14*100,1),"") | AI14: =IF(ISNUMBER($S14),IF($S14<=1,"Yes","No"),"n/a") | AJ14: =IF(ISNUMBER($S14),ROUND(MAX(0,MIN(100,100-$S14*2.5-IF(ISNUMBER($T14),$T14,0)*0.12+IF($S14<=1,12,0))),0),"") | AK14: =IF(ISNUMBER($Q14),IF($Q14>=100,20,IF($Q14>=30,10,0)),0)+IF(ISNUMBER($R14),IF($R14>=100,20,0),0)+IF(ISNUMBER($P14),IF($P14>=150,20,IF($P14>=50,12,5)),0)+IF(ISNUMBER($S14),IF($S14<=1,15,0),0) | AL14: 503 | AN14: =IF(AND(ISNUMBER($P14),ISNUMBER($AL14),$AL14<>0),IF(OR($P14>180,$P14/$AL14*1000>400),"Over ceiling, confirm SKU","Within"),"n/a") | AR14: Retrieved and cited, see Enrichment Log | AS14: BLANK -> requires live Amazon.ca capture | AT14: Unverified commercial data
A15: Sparkling Ice | B15: Sparkling Ice (+ Antioxidants & Vitamins) | Cherry Limeade | 12 pack 503mL | C15: 1) Sparkling electrolyte / functional sparkling | D15: 503 mL bottle | E15: 12 | G15: =IF(AND(ISNUMBER($F15),ISNUMBER($E15),$E15<>0),$F15/$E15,"") | H15: =IF(AND(ISNUMBER($F15),ISNUMBER($AL15),ISNUMBER($E15),($AL15*$E15)<>0),$F15/($AL15*$E15)*100,"") | K15: =IF(AND(ISNUMBER($F15),ISNUMBER($J15)),$F15*(1-$J15),"") | N15: =IF(ISNUMBER($F15),($F15-IF(ISNUMBER($AM15),$AM15,0))*(1-IF(ISNUMBER($J15),$J15,0)),"") | O15: Cherry Limeade | P15: 0 | Q15: 0 | R15: 30 | S15: 0 | T15: 5 | U15: Sucralose | V15: Zero sugar, vitamins A/D/B, antioxidants (green tea), bold flavour | AA15: High | AB15: Mass market functional sparkling; strong shelf share | AC15: Bold zero sugar sparkling with added vitamins | AD15: Big flavour and added vitamins at zero sugar. | AF15: =IF(AND(ISNUMBER($P15),ISNUMBER($AL15),$AL15<>0),ROUND($P15/$AL15*100,1),"") | AG15: =IF(AND(ISNUMBER($S15),ISNUMBER($AL15),$AL15<>0),ROUND($S15/$AL15*100,2),"") | AH15: =IF(AND(ISNUMBER($Q15),ISNUMBER($AL15),$AL15<>0),ROUND($Q15/$AL15*100,1),"") | AI15: =IF(ISNUMBER($S15),IF($S15<=1,"Yes","No"),"n/a") | AJ15: =IF(ISNUMBER($S15),ROUND(MAX(0,MIN(100,100-$S15*2.5-IF(ISNUMBER($T15),$T15,0)*0.12+IF($S15<=1,12,0))),0),"") | AK15: =IF(ISNUMBER($Q15),IF($Q15>=100,20,IF($Q15>=30,10,0)),0)+IF(ISNUMBER($R15),IF($R15>=100,20,0),0)+IF(ISNUMBER($P15),IF($P15>=150,20,IF($P15>=50,12,5)),0)+IF(ISNUMBER($S15),IF($S15<=1,15,0),0) | AL15: 503 | AN15: =IF(AND(ISNUMBER($P15),ISNUMBER($AL15),$AL15<>0),IF(OR($P15>180,$P15/$AL15*1000>400),"Over ceiling, confirm SKU","Within"),"n/a") | AR15: Retrieved and cited, see Enrichment Log | AS15: BLANK -> requires live Amazon.ca capture | AT15: Unverified commercial data
A16: Sparkling Ice | B16: Sparkling Ice (+ Antioxidants & Vitamins) | Cherry Limeade | 18 pack 503mL | C16: 1) Sparkling electrolyte / functional sparkling | D16: 503 mL bottle | E16: 18 | G16: =IF(AND(ISNUMBER($F16),ISNUMBER($E16),$E16<>0),$F16/$E16,"") | H16: =IF(AND(ISNUMBER($F16),ISNUMBER($AL16),ISNUMBER($E16),($AL16*$E16)<>0),$F16/($AL16*$E16)*100,"") | K16: =IF(AND(ISNUMBER($F16),ISNUMBER($J16)),$F16*(1-$J16),"") | N16: =IF(ISNUMBER($F16),($F16-IF(ISNUMBER($AM16),$AM16,0))*(1-IF(ISNUMBER($J16),$J16,0)),"") | O16: Cherry Limeade | P16: 0 | Q16: 0 | R16: 30 | S16: 0 | T16: 5 | U16: Sucralose | V16: Zero sugar, vitamins A/D/B, antioxidants (green tea), bold flavour | AA16: High | AB16: Mass market functional sparkling; strong shelf share | AC16: Bold zero sugar sparkling with added vitamins | AD16: Big flavour and added vitamins at zero sugar. | AF16: =IF(AND(ISNUMBER($P16),ISNUMBER($AL16),$AL16<>0),ROUND($P16/$AL16*100,1),"") | AG16: =IF(AND(ISNUMBER($S16),ISNUMBER($AL16),$AL16<>0),ROUND($S16/$AL16*100,2),"") | AH16: =IF(AND(ISNUMBER($Q16),ISNUMBER($AL16),$AL16<>0),ROUND($Q16/$AL16*100,1),"") | AI16: =IF(ISNUMBER($S16),IF($S16<=1,"Yes","No"),"n/a") | AJ16: =IF(ISNUMBER($S16),ROUND(MAX(0,MIN(100,100-$S16*2.5-IF(ISNUMBER($T16),$T16,0)*0.12+IF($S16<=1,12,0))),0),"") | AK16: =IF(ISNUMBER($Q16),IF($Q16>=100,20,IF($Q16>=30,10,0)),0)+IF(ISNUMBER($R16),IF($R16>=100,20,0),0)+IF(ISNUMBER($P16),IF($P16>=150,20,IF($P16>=50,12,5)),0)+IF(ISNUMBER($S16),IF($S16<=1,15,0),0) | AL16: 503 | AN16: =IF(AND(ISNUMBER($P16),ISNUMBER($AL16),$AL16<>0),IF(OR($P16>180,$P16/$AL16*1000>400),"Over ceiling, confirm SKU","Within"),"n/a") | AR16: Retrieved and cited, see Enrichment Log | AS16: BLANK -> requires live Amazon.ca capture | AT16: Unverified commercial data
A17: Sparkling Ice | B17: Sparkling Ice (+ Antioxidants & Vitamins) | Cherry Limeade | 24 pack 503mL | C17: 1) Sparkling electrolyte / functional sparkling | D17: 503 mL bottle | E17: 24 | G17: =IF(AND(ISNUMBER($F17),ISNUMBER($E17),$E17<>0),$F17/$E17,"") | H17: =IF(AND(ISNUMBER($F17),ISNUMBER($AL17),ISNUMBER($E17),($AL17*$E17)<>0),$F17/($AL17*$E17)*100,"") | K17: =IF(AND(ISNUMBER($F17),ISNUMBER($J17)),$F17*(1-$J17),"") | N17: =IF(ISNUMBER($F17),($F17-IF(ISNUMBER($AM17),$AM17,0))*(1-IF(ISNUMBER($J17),$J17,0)),"") | O17: Cherry Limeade | P17: 0 | Q17: 0 | R17: 30 | S17: 0 | T17: 5 | U17: Sucralose | V17: Zero sugar, vitamins A/D/B, antioxidants (green tea), bold flavour | AA17: High | AB17: Mass market functional sparkling; strong shelf share | AC17: Bold zero sugar sparkling with added vitamins | AD17: Big flavour and added vitamins at zero sugar. | AF17: =IF(AND(ISNUMBER($P17),ISNUMBER($AL17),$AL17<>0),ROUND($P17/$AL17*100,1),"") | AG17: =IF(AND(ISNUMBER($S17),ISNUMBER($AL17),$AL17<>0),ROUND($S17/$AL17*100,2),"") | AH17: =IF(AND(ISNUMBER($Q17),ISNUMBER($AL17),$AL17<>0),ROUND($Q17/$AL17*100,1),"") | AI17: =IF(ISNUMBER($S17),IF($S17<=1,"Yes","No"),"n/a") | AJ17: =IF(ISNUMBER($S17),ROUND(MAX(0,MIN(100,100-$S17*2.5-IF(ISNUMBER($T17),$T17,0)*0.12+IF($S17<=1,12,0))),0),"") | AK17: =IF(ISNUMBER($Q17),IF($Q17>=100,20,IF($Q17>=30,10,0)),0)+IF(ISNUMBER($R17),IF($R17>=100,20,0),0)+IF(ISNUMBER($P17),IF($P17>=150,20,IF($P17>=50,12,5)),0)+IF(ISNUMBER($S17),IF($S17<=1,15,0),0) | AL17: 503 | AN17: =IF(AND(ISNUMBER($P17),ISNUMBER($AL17),$AL17<>0),IF(OR($P17>180,$P17/$AL17*1000>400),"Over ceiling, confirm SKU","Within"),"n/a") | AR17: Retrieved and cited, see Enrichment Log | AS17: BLANK -> requires live Amazon.ca capture | AT17: Unverified commercial data
A18: Sparkling Ice | B18: Sparkling Ice (+ Antioxidants & Vitamins) | Orange Mango | single 503mL | C18: 1) Sparkling electrolyte / functional sparkling | D18: 503 mL bottle | E18: 1 | G18: =IF(AND(ISNUMBER($F18),ISNUMBER($E18),$E18<>0),$F18/$E18,"") | H18: =IF(AND(ISNUMBER($F18),ISNUMBER($AL18),ISNUMBER($E18),($AL18*$E18)<>0),$F18/($AL18*$E18)*100,"") | K18: =IF(AND(ISNUMBER($F18),ISNUMBER($J18)),$F18*(1-$J18),"") | N18: =IF(ISNUMBER($F18),($F18-IF(ISNUMBER($AM18),$AM18,0))*(1-IF(ISNUMBER($J18),$J18,0)),"") | O18: Orange Mango | P18: 0 | Q18: 0 | R18: 30 | S18: 0 | T18: 5 | U18: Sucralose | V18: Zero sugar, vitamins A/D/B, antioxidants (green tea), bold flavour | AA18: High | AB18: Mass market functional sparkling; strong shelf share | AC18: Bold zero sugar sparkling with added vitamins | AD18: Big flavour and added vitamins at zero sugar. | AF18: =IF(AND(ISNUMBER($P18),ISNUMBER($AL18),$AL18<>0),ROUND($P18/$AL18*100,1),"") | AG18: =IF(AND(ISNUMBER($S18),ISNUMBER($AL18),$AL18<>0),ROUND($S18/$AL18*100,2),"") | AH18: =IF(AND(ISNUMBER($Q18),ISNUMBER($AL18),$AL18<>0),ROUND($Q18/$AL18*100,1),"") | AI18: =IF(ISNUMBER($S18),IF($S18<=1,"Yes","No"),"n/a") | AJ18: =IF(ISNUMBER($S18),ROUND(MAX(0,MIN(100,100-$S18*2.5-IF(ISNUMBER($T18),$T18,0)*0.12+IF($S18<=1,12,0))),0),"") | AK18: =IF(ISNUMBER($Q18),IF($Q18>=100,20,IF($Q18>=30,10,0)),0)+IF(ISNUMBER($R18),IF($R18>=100,20,0),0)+IF(ISNUMBER($P18),IF($P18>=150,20,IF($P18>=50,12,5)),0)+IF(ISNUMBER($S18),IF($S18<=1,15,0),0) | AL18: 503 | AN18: =IF(AND(ISNUMBER($P18),ISNUMBER($AL18),$AL18<>0),IF(OR($P18>180,$P18/$AL18*1000>400),"Over ceiling, confirm SKU","Within"),"n/a") | AR18: Retrieved and cited, see Enrichment Log | AS18: BLANK -> requires live Amazon.ca capture | AT18: Unverified commercial data
A19: Sparkling Ice | B19: Sparkling Ice (+ Antioxidants & Vitamins) | Orange Mango | 8 pack 503mL | C19: 1) Sparkling electrolyte / functional sparkling | D19: 503 mL bottle | E19: 8 | G19: =IF(AND(ISNUMBER($F19),ISNUMBER($E19),$E19<>0),$F19/$E19,"") | H19: =IF(AND(ISNUMBER($F19),ISNUMBER($AL19),ISNUMBER($E19),($AL19*$E19)<>0),$F19/($AL19*$E19)*100,"") | K19: =IF(AND(ISNUMBER($F19),ISNUMBER($J19)),$F19*(1-$J19),"") | N19: =IF(ISNUMBER($F19),($F19-IF(ISNUMBER($AM19),$AM19,0))*(1-IF(ISNUMBER($J19),$J19,0)),"") | O19: Orange Mango | P19: 0 | Q19: 0 | R19: 30 | S19: 0 | T19: 5 | U19: Sucralose | V19: Zero sugar, vitamins A/D/B, antioxidants (green tea), bold flavour | AA19: High | AB19: Mass market functional sparkling; strong shelf share | AC19: Bold zero sugar sparkling with added vitamins | AD19: Big flavour and added vitamins at zero sugar. | AF19: =IF(AND(ISNUMBER($P19),ISNUMBER($AL19),$AL19<>0),ROUND($P19/$AL19*100,1),"") | AG19: =IF(AND(ISNUMBER($S19),ISNUMBER($AL19),$AL19<>0),ROUND($S19/$AL19*100,2),"") | AH19: =IF(AND(ISNUMBER($Q19),ISNUMBER($AL19),$AL19<>0),ROUND($Q19/$AL19*100,1),"") | AI19: =IF(ISNUMBER($S19),IF($S19<=1,"Yes","No"),"n/a") | AJ19: =IF(ISNUMBER($S19),ROUND(MAX(0,MIN(100,100-$S19*2.5-IF(ISNUMBER($T19),$T19,0)*0.12+IF($S19<=1,12,0))),0),"") | AK19: =IF(ISNUMBER($Q19),IF($Q19>=100,20,IF($Q19>=30,10,0)),0)+IF(ISNUMBER($R19),IF($R19>=100,20,0),0)+IF(ISNUMBER($P19),IF($P19>=150,20,IF($P19>=50,12,5)),0)+IF(ISNUMBER($S19),IF($S19<=1,15,0),0) | AL19: 503 | AN19: =IF(AND(ISNUMBER($P19),ISNUMBER($AL19),$AL19<>0),IF(OR($P19>180,$P19/$AL19*1000>400),"Over ceiling, confirm SKU","Within"),"n/a") | AR19: Retrieved and cited, see Enrichment Log | AS19: BLANK -> requires live Amazon.ca capture | AT19: Unverified commercial data
... A37: Sparkling Ice | B37: Sparkling Ice (+ Antioxidants & Vitamins) | Classic Lemonade | 24 pack 503mL | C37: 1) Sparkling electrolyte / functional sparkling | D37: 503 mL bottle | E37: 24 | G37: =IF(AND(ISNUMBER($F37),ISNUMBER($E37),$E37<>0),$F37/$E37,"") | H37: =IF(AND(ISNUMBER($F37),ISNUMBER($AL37),ISNUMBER($E37),($AL37*$E37)<>0),$F37/($AL37*$E37)*100,"") | K37: =IF(AND(ISNUMBER($F37),ISNUMBER($J37)),$F37*(1-$J37),"") | N37: =IF(ISNUMBER($F37),($F37-IF(ISNUMBER($AM37),$AM37,0))*(1-IF(ISNUMBER($J37),$J37,0)),"") | O37: Classic Lemonade | P37: 0 | Q37: 0 | R37: 30 | S37: 0 | T37: 5 | U37: Sucralose | V37: Zero sugar, vitamins A/D/B, antioxidants (green tea), bold flavour | AA37: High | AB37: Mass market functional sparkling; strong shelf share | AC37: Bold zero sugar sparkling with added vitamins | AD37: Big flavour and added vitamins at zero sugar. | AF37: =IF(AND(ISNUMBER($P37),ISNUMBER($AL37),$AL37<>0),ROUND($P37/$AL37*100,1),"") | AG37: =IF(AND(ISNUMBER($S37),ISNUMBER($AL37),$AL37<>0),ROUND($S37/$AL37*100,2),"") | AH37: =IF(AND(ISNUMBER($Q37),ISNUMBER($AL37),$AL37<>0),ROUND($Q37/$AL37*100,1),"") | AI37: =IF(ISNUMBER($S37),IF($S37<=1,"Yes","No"),"n/a") | AJ37: =IF(ISNUMBER($S37),ROUND(MAX(0,MIN(100,100-$S37*2.5-IF(ISNUMBER($T37),$T37,0)*0.12+IF($S37<=1,12,0))),0),"") | AK37: =IF(ISNUMBER($Q37),IF($Q37>=100,20,IF($Q37>=30,10,0)),0)+IF(ISNUMBER($R37),IF($R37>=100,20,0),0)+IF(ISNUMBER($P37),IF($P37>=150,20,IF($P37>=50,12,5)),0)+IF(ISNUMBER($S37),IF($S37<=1,15,0),0) | AL37: 503 | AN37: =IF(AND(ISNUMBER($P37),ISNUMBER($AL37),$AL37<>0),IF(OR($P37>180,$P37/$AL37*1000>400),"Over ceiling, confirm SKU","Within"),"n/a") | AR37: Retrieved and cited, see Enrichment Log | AS37: BLANK -> requires live Amazon.ca capture | AT37: Unverified commercial data
A38: BUBBL'R | B38: BUBBL'R Antioxidant Sparkling Water | Blackberribrilliance | single 473mL | C38: 1) Sparkling electrolyte / functional sparkling | D38: 473 mL can | E38: 1 | G38: =IF(AND(ISNUMBER($F38),ISNUMBER($E38),$E38<>0),$F38/$E38,"") | H38: =IF(AND(ISNUMBER($F38),ISNUMBER($AL38),ISNUMBER($E38),($AL38*$E38)<>0),$F38/($AL38*$E38)*100,"") | K38: =IF(AND(ISNUMBER($F38),ISNUMBER($J38)),$F38*(1-$J38),"") | N38: =IF(ISNUMBER($F38),($F38-IF(ISNUMBER($AM38),$AM38,0))*(1-IF(ISNUMBER($J38),$J38,0)),"") | O38: Blackberribrilliance | P38: 69 | Q38: 15 | R38: Not listed | S38: 0 | T38: 10 | U38: Erythritol + stevia | V38: Natural caffeine (69 mg), antioxidants, B vitamins, zero sugar | AA38: Medium | AB38: Mid caffeine functional sparkling; growing | AC38: Sparkling water with a light caffeine + antioxidant lift | AD38: Light natural caffeine and antioxidants without an energy drink dose. | AF38: =IF(AND(ISNUMBER($P38),ISNUMBER($AL38),$AL38<>0),ROUND($P38/$AL38*100,1),"") | AG38: =IF(AND(ISNUMBER($S38),ISNUMBER($AL38),$AL38<>0),ROUND($S38/$AL38*100,2),"") | AH38: =IF(AND(ISNUMBER($Q38),ISNUMBER($AL38),$AL38<>0),ROUND($Q38/$AL38*100,1),"") | AI38: =IF(ISNUMBER($S38),IF($S38<=1,"Yes","No"),"n/a") | AJ38: =IF(ISNUMBER($S38),ROUND(MAX(0,MIN(100,100-$S38*2.5-IF(ISNUMBER($T38),$T38,0)*0.12+IF($S38<=1,12,0))),0),"") | AK38: =IF(ISNUMBER($Q38),IF($Q38>=100,20,IF($Q38>=30,10,0)),0)+IF(ISNUMBER($R38),IF($R38>=100,20,0),0)+IF(ISNUMBER($P38),IF($P38>=150,20,IF($P38>=50,12,5)),0)+IF(ISNUMBER($S38),IF($S38<=1,15,0),0) | AL38: 473 | AN38: =IF(AND(ISNUMBER($P38),ISNUMBER($AL38),$AL38<>0),IF(OR($P38>180,$P38/$AL38*1000>400),"Over ceiling, confirm SKU","Within"),"n/a") | AR38: Recalled, batch confirmed, to confirm | AS38: BLANK -> requires live Amazon.ca capture | AT38: Unverified commercial data
