Workbook

Sheet README & Methodology
B2: Amazon.ca Beverage - Competitor Intelligence Master File
B3: Build date: 2026-06-06 | v3 Enterprise | 2898 SKUs from 124 product lines / 101 brands
B5: CRITICAL - READ FIRST
B6: Data-access limitation | C6: Generated with NO live access to Amazon (HTTP 403 on search, product, and brand pages). The file therefore contains NO live prices, Subscribe & Save terms, coupons, ratings, review counts, badges, ranks, or URLs. Those cells are intentionally BLANK and amber-highlighted - they are NOT fabricated.
B7: SKU model - HOW THE ~1000+ ROWS ARE BUILT | C7: The Master tabs are SKU-level. Because each flavour x pack-size is a separate ASIN on Amazon, every product LINE is exploded into individual SKU rows (line x flavour x pack). These are DERIVED / CANDIDATE SKUs to verify against live listings - NOT confirmed ASINs. Flavour lists are representative not exhaustive, and some specific flavour+pack combinations may not exist exactly as shown. The live catalogue cannot be enumerated without Amazon access; this expansion approximates its shape.
B8: What IS filled (and its confidence) | C8: Stable attributes - brand, SKU, format/size, typical pack, flavours, caffeine/sodium/potassium/sugar/calories, sweetener, claims, positioning, plus an honest velocity ESTIMATE - filled from manufacturer + secondary sources. Treat all as APPROXIMATE and verify on the live label. Nutrition is per single serving and varies by flavour.
B9: What is BLANK (capture live) | C9: Fields 6, 9-14, 23-26, 30 and helper H2. All amber. Filled by a live-capture pass (see 'Live-Capture Protocol' tab).
B10: Built-in automation | C10: Fields 7,8,11,14 are LIVE FORMULAS. Enter price (F), pack (E), S&S % as decimal (J, e.g. 0.15) and coupon value (H2); per-unit, per-100 mL, S&S price and stacked floor compute instantly and the red row-flag clears.
B11: NEW v2 - computed analytics | C11: Columns C1-C6 on every Master tab: Caffeine/100 mL, Sugar/100 mL, Sodium/100 mL, Sugar-Free flag, Health Score, Functional Score - all live formulas off the nutrition you can already see.
B12: Health Score (0-100) model | C12: =MAX(0, MIN(100, 100 - sugar*2.5 - calories*0.12 + 12 if sugar<=1)). Higher = lighter/cleaner. Transparent and editable; based on APPROXIMATE nutrition.
B13: Functional Score (0-100) model | C13: Sodium (>=100=20, >=30=10) + Potassium (>=100=20) + Caffeine (>=150=20, >=50=12, else 5) + Low-sugar bonus (<=1 g=15). Higher = more 'functional' payload. A heuristic, not a medical claim.
B14: Stacking model (field 14) | C14: Lowest Effective = (Price - Coupon) x (1 - S&S %). Assumes coupon + subscription stack on one order (usual Amazon behaviour); confirm per listing.
B15: Velocity estimate (field 27) | C15: Bands are ESTIMATES from brand prominence/category position because live review counts/BSR were not accessible. Re-derive from real #Ratings + BSR once captured. Never a unit count.
B16: Scope rules | C16: RTD only. Powders, drink-mix packets, tablets EXCLUDED (Liquid I.V., Nuun, LMNT, Cure powder, Cirkul). One PRIMARY category per product; overlaps noted.
B17: Cross-tab linkage | C17: Pricing & Promo and Subscription tabs are LIVE-LINKED to the Master tabs - fill a price once and those tabs update automatically.
B18: Tabs | C18: README, Executive Dashboard, Data Dictionary, 5 Master tabs, Brand Roll-up, Category Benchmarks, Nutrition Scoreboard, Pricing & Promo, Subscription Strategy, Why They Win, Velocity Estimate, Flavour Map, Live-Capture Protocol, QA & Integrity, Sources.
B19: Integrity statement | C19: Nothing in the commercial columns is invented. Where a live figure could not be obtained it is blank and flagged, so the file survives a fact-check against the live listings.

Sheet Executive Dashboard
B2: Executive Dashboard
B3: Amazon.ca RTD beverage landscape | 2026-06-06 | ESTIMATE/secondary data - see README
B5: 2898 | C5: 124 | D5: 101 | E5: 5 | F5: 12.9 | G5: =(COUNT('M1 - Sparkling Electrolyte'!F2:F249)+COUNT('M2 - Electrolyte RTD'!F2:F405)+COUNT('M3 - Functional Beverage'!F2:F544)+COUNT('M4 - Caffeine & Energy'!F2:F810)+COUNT('M5 - Sparkling Water & Soda'!F2:F895))/2898
B6: SKUs | C6: Product lines | D6: Brands | E6: Categories | F6: Avg sugar (g) | G6: Price capture %
B19: Chart data (computed from stable attributes)
B20: Category | C20: # Products | D20: Avg sugar (g) | E20: Avg caffeine (mg)
B21: Sparkling electrolyte | C21: 248 | D21: 0.9 | E21: 38.8
B22: Electrolyte beverage ( | C22: 404 | D22: 8.2 | E22: 0
B23: Functional beverage (s | C23: 543 | D23: 6.2 | E23: 6.8
B24: Caffeine & energy beve | C24: 809 | D24: 19.6 | E24: 153.6
B25: Sparkling water & soda | C25: 894 | D25: 15.2 | E25: 10.8
B27: Sweetener class | C27: # Products
B28: Caloric only | C28: 43
B29: Non-caloric only | C29: 41
B30: None / unsweetened | C30: 24
B31: Blend (caloric + non-caloric) | C31: 13
B32: Other | C32: 3

Sheet Data Dictionary
A1: Field # | B1: Field name | C1: Definition / how to read it | D1: Source class | E1: Status in this file
A2: 1 | B2: Brand | C2: Manufacturer/brand name. | D2: Stable | E2: Filled (approx)
A3: 2 | B3: Product Line / SKU Name | C3: Exact product/line name; confirm spelling. | D3: Stable | E3: Filled (approx)
A4: 3 | B4: Category | C4: One of five scope categories (primary). | D4: Assigned | E4: Filled
A5: 4 | B5: Format & Size | C5: Container type + single-unit size. | D5: Stable | E5: Filled (approx)
A6: 5 | B6: Pack Count | C6: Units per multipack (typical). | D6: Stable | E6: Filled (typical)
A7: 6 | B7: One-Time Price (CAD) | C7: List one-time price. | D7: LIVE Amazon.ca | E7: BLANK - capture
A8: 7 | B8: Price / Unit (CAD) | C8: =Price/Pack. | D8: Calculated | E8: Auto
A9: 8 | B9: Price / 100 mL (CAD) | C9: =Price/(UnitVol*Pack)*100. | D9: Calculated | E9: Auto
A10: 9 | B10: S&S Offered (Y/N) | C10: Subscribe & Save offered? | D10: LIVE Amazon.ca | E10: BLANK - capture
A11: 10 | B11: S&S Discount % | C11: Enter decimal (0.15=15%). | D11: LIVE Amazon.ca | E11: BLANK - capture
A12: 11 | B12: S&S Price After Discount | C12: =Price*(1-S&S%). | D12: Calculated | E12: Auto
A13: 12 | B13: Coupon (Y/N + value) | C13: Clippable coupon + value. | D13: LIVE Amazon.ca | E13: BLANK - capture
A14: 13 | B14: Promotion Text | C14: Multi-buy/lightning/Prime/bundle. | D14: LIVE Amazon.ca | E14: BLANK - capture
A15: 14 | B15: Lowest Effective Price | C15: =(Price-Coupon)*(1-S&S%). | D15: Calculated | E15: Auto
A16: 15 | B16: All Flavours | C16: Flavours in/around listing. | D16: Stable | E16: Filled (approx)
A17: 16 | B17: Caffeine / Serving (mg) | C17: Per serving; 'Not listed' if none. | D17: Stable | E17: Filled (approx)
A18: 17 | B18: Sodium / Serving (mg) | C18: Per serving. | D18: Stable | E18: Filled (approx)
A19: 18 | B19: Potassium / Serving (mg) | C19: Per serving; blank if not listed. | D19: Stable | E19: Filled (approx)
A20: 19 | B20: Sugar / Serving (g) | C20: Per serving. | D20: Stable | E20: Filled (approx)
A21: 20 | B21: Calories / Serving | C21: Per serving. | D21: Stable | E21: Filled (approx)
A22: 21 | B22: Sweetener Type | C22: Caloric/non-caloric sweetener(s). | D22: Stable | E22: Filled (approx)
A23: 22 | B23: Key Functional Claims | C23: Headline benefit claims. | D23: Stable | E23: Filled (approx)
A24: 23 | B24: Star Rating | C24: Average stars. | D24: LIVE Amazon.ca | E24: BLANK - capture
A25: 24 | B25: Number of Ratings | C25: Count of ratings. | D25: LIVE Amazon.ca | E25: BLANK - capture
A26: 25 | B26: Amazon Badge | C26: Choice / Best Seller / Overall Pick. | D26: LIVE Amazon.ca | E26: BLANK - capture
A27: 26 | B27: Bestseller Rank | C27: BSR if shown. | D27: LIVE Amazon.ca | E27: BLANK - capture
... A43: P3 | B43: Row Flag | C43: Flags unverified rows. | D43: Meta | E43: Filled

Sheet M1 - Sparkling Electrolyte
A1: 1. Brand | B1: 2. Product Line / SKU Name | C1: 3. Category | D1: 4. Format & Size | E1: 5. Pack Count | F1: 6. One-Time Price (CAD) | G1: 7. Price / Unit (CAD) | H1: 8. Price / 100 mL (CAD) | I1: 9. S&S Offered (Y/N) | J1: 10. S&S Discount % | K1: 11. S&S Price After Disc. | L1: 12. Coupon on Listing (Y/N + value) | M1: 13. Promotion Text | N1: 14. Lowest Effective Price (stacked) | O1: 15. All Flavours in Listing | P1: 16. Caffeine / Serving (mg) | Q1: 17. Sodium / Serving (mg) | R1: 18. Potassium / Serving (mg) | S1: 19. Sugar / Serving (g) | T1: 20. Calories / Serving | U1: 21. Sweetener Type | V1: 22. Key Functional Claims | W1: 23. Star Rating | X1: 24. Number of Ratings | Y1: 25. Amazon Badge | Z1: 26. Bestseller Rank in Category | AA1: 27a. Est. Weekly Velocity (band) | AB1: 27b. Velocity Signal Used | AC1: 28. Biggest Selling Message | AD1: 29. Why a Shopper Chooses This | AE1: 30. Direct Product URL | AF1: C1. Caffeine /100 mL (mg) | AG1: C2. Sugar /100 mL (g) | AH1: C3. Sodium /100 mL (mg) | AI1: C4. Sugar-Free? (<=1 g) | AJ1: C5. Health Score (0-100) | AK1: C6. Functional Score (0-100) | AL1: H1. Unit Vol (mL) [calc helper] | AM1: H2. Coupon Value (CAD) [calc helper] | AN1: P1. Attribute Provenance | AO1: P2. Commercial-Field Status | AP1: P3. Row Flag
A2: Sparkling Ice | B2: Sparkling Ice (+ Antioxidants & Vitamins) | Black Raspberry | single 503mL | C2: 1) Sparkling electrolyte / functional sparkling | D2: 503 mL bottle | E2: 1 | G2: =IF(AND(ISNUMBER($F2),ISNUMBER($E2),$E2<>0),$F2/$E2,"") | H2: =IF(AND(ISNUMBER($F2),ISNUMBER($AL2),ISNUMBER($E2),($AL2*$E2)<>0),$F2/($AL2*$E2)*100,"") | K2: =IF(AND(ISNUMBER($F2),ISNUMBER($J2)),$F2*(1-$J2),"") | N2: =IF(ISNUMBER($F2),($F2-IF(ISNUMBER($AM2),$AM2,0))*(1-IF(ISNUMBER($J2),$J2,0)),"") | O2: Black Raspberry | P2: 0 | Q2: 25 | R2: Not listed | S2: 0 | T2: 5 | U2: Sucralose | V2: Zero sugar, vitamins A/D/B, antioxidants (green tea), bold flavour | AA2: High | AB2: Mass-market functional sparkling; strong shelf share | AC2: Bold zero-sugar sparkling with added vitamins | AD2: Big flavour and added vitamins at zero sugar. | AF2: =IF(AND(ISNUMBER($P2),ISNUMBER($AL2),$AL2<>0),ROUND($P2/$AL2*100,1),"") | AG2: =IF(AND(ISNUMBER($S2),ISNUMBER($AL2),$AL2<>0),ROUND($S2/$AL2*100,2),"") | AH2: =IF(AND(ISNUMBER($Q2),ISNUMBER($AL2),$AL2<>0),ROUND($Q2/$AL2*100,1),"") | AI2: =IF(ISNUMBER($S2),IF($S2<=1,"Yes","No"),"n/a") | AJ2: =IF(ISNUMBER($S2),ROUND(MAX(0,MIN(100,100-$S2*2.5-IF(ISNUMBER($T2),$T2,0)*0.12+IF($S2<=1,12,0))),0),"") | AK2: =IF(ISNUMBER($Q2),IF($Q2>=100,20,IF($Q2>=30,10,0)),0)+IF(ISNUMBER($R2),IF($R2>=100,20,0),0)+IF(ISNUMBER($P2),IF($P2>=150,20,IF($P2>=50,12,5)),0)+IF(ISNUMBER($S2),IF($S2<=1,15,0),0) | AL2: 503 | AN2: Secondary/approx; NOT verified on Amazon.ca | AO2: BLANK -> requires live Amazon.ca capture | AP2: Unverified commercial data
A3: Sparkling Ice | B3: Sparkling Ice (+ Antioxidants & Vitamins) | Black Raspberry | 8-pack 503mL | C3: 1) Sparkling electrolyte / functional sparkling | D3: 503 mL bottle | E3: 8 | G3: =IF(AND(ISNUMBER($F3),ISNUMBER($E3),$E3<>0),$F3/$E3,"") | H3: =IF(AND(ISNUMBER($F3),ISNUMBER($AL3),ISNUMBER($E3),($AL3*$E3)<>0),$F3/($AL3*$E3)*100,"") | K3: =IF(AND(ISNUMBER($F3),ISNUMBER($J3)),$F3*(1-$J3),"") | N3: =IF(ISNUMBER($F3),($F3-IF(ISNUMBER($AM3),$AM3,0))*(1-IF(ISNUMBER($J3),$J3,0)),"") | O3: Black Raspberry | P3: 0 | Q3: 25 | R3: Not listed | S3: 0 | T3: 5 | U3: Sucralose | V3: Zero sugar, vitamins A/D/B, antioxidants (green tea), bold flavour | AA3: High | AB3: Mass-market functional sparkling; strong shelf share | AC3: Bold zero-sugar sparkling with added vitamins | AD3: Big flavour and added vitamins at zero sugar. | AF3: =IF(AND(ISNUMBER($P3),ISNUMBER($AL3),$AL3<>0),ROUND($P3/$AL3*100,1),"") | AG3: =IF(AND(ISNUMBER($S3),ISNUMBER($AL3),$AL3<>0),ROUND($S3/$AL3*100,2),"") | AH3: =IF(AND(ISNUMBER($Q3),ISNUMBER($AL3),$AL3<>0),ROUND($Q3/$AL3*100,1),"") | AI3: =IF(ISNUMBER($S3),IF($S3<=1,"Yes","No"),"n/a") | AJ3: =IF(ISNUMBER($S3),ROUND(MAX(0,MIN(100,100-$S3*2.5-IF(ISNUMBER($T3),$T3,0)*0.12+IF($S3<=1,12,0))),0),"") | AK3: =IF(ISNUMBER($Q3),IF($Q3>=100,20,IF($Q3>=30,10,0)),0)+IF(ISNUMBER($R3),IF($R3>=100,20,0),0)+IF(ISNUMBER($P3),IF($P3>=150,20,IF($P3>=50,12,5)),0)+IF(ISNUMBER($S3),IF($S3<=1,15,0),0) | AL3: 503 | AN3: Secondary/approx; NOT verified on Amazon.ca | AO3: BLANK -> requires live Amazon.ca capture | AP3: Unverified commercial data
A4: Sparkling Ice | B4: Sparkling Ice (+ Antioxidants & Vitamins) | Black Raspberry | 12-pack 503mL | C4: 1) Sparkling electrolyte / functional sparkling | D4: 503 mL bottle | E4: 12 | G4: =IF(AND(ISNUMBER($F4),ISNUMBER($E4),$E4<>0),$F4/$E4,"") | H4: =IF(AND(ISNUMBER($F4),ISNUMBER($AL4),ISNUMBER($E4),($AL4*$E4)<>0),$F4/($AL4*$E4)*100,"") | K4: =IF(AND(ISNUMBER($F4),ISNUMBER($J4)),$F4*(1-$J4),"") | N4: =IF(ISNUMBER($F4),($F4-IF(ISNUMBER($AM4),$AM4,0))*(1-IF(ISNUMBER($J4),$J4,0)),"") | O4: Black Raspberry | P4: 0 | Q4: 25 | R4: Not listed | S4: 0 | T4: 5 | U4: Sucralose | V4: Zero sugar, vitamins A/D/B, antioxidants (green tea), bold flavour | AA4: High | AB4: Mass-market functional sparkling; strong shelf share | AC4: Bold zero-sugar sparkling with added vitamins | AD4: Big flavour and added vitamins at zero sugar. | AF4: =IF(AND(ISNUMBER($P4),ISNUMBER($AL4),$AL4<>0),ROUND($P4/$AL4*100,1),"") | AG4: =IF(AND(ISNUMBER($S4),ISNUMBER($AL4),$AL4<>0),ROUND($S4/$AL4*100,2),"") | AH4: =IF(AND(ISNUMBER($Q4),ISNUMBER($AL4),$AL4<>0),ROUND($Q4/$AL4*100,1),"") | AI4: =IF(ISNUMBER($S4),IF($S4<=1,"Yes","No"),"n/a") | AJ4: =IF(ISNUMBER($S4),ROUND(MAX(0,MIN(100,100-$S4*2.5-IF(ISNUMBER($T4),$T4,0)*0.12+IF($S4<=1,12,0))),0),"") | AK4: =IF(ISNUMBER($Q4),IF($Q4>=100,20,IF($Q4>=30,10,0)),0)+IF(ISNUMBER($R4),IF($R4>=100,20,0),0)+IF(ISNUMBER($P4),IF($P4>=150,20,IF($P4>=50,12,5)),0)+IF(ISNUMBER($S4),IF($S4<=1,15,0),0) | AL4: 503 | AN4: Secondary/approx; NOT verified on Amazon.ca | AO4: BLANK -> requires live Amazon.ca capture | AP4: Unverified commercial data
A5: Sparkling Ice | B5: Sparkling Ice (+ Antioxidants & Vitamins) | Black Raspberry | 18-pack 503mL | C5: 1) Sparkling electrolyte / functional sparkling | D5: 503 mL bottle | E5: 18 | G5: =IF(AND(ISNUMBER($F5),ISNUMBER($E5),$E5<>0),$F5/$E5,"") | H5: =IF(AND(ISNUMBER($F5),ISNUMBER($AL5),ISNUMBER($E5),($AL5*$E5)<>0),$F5/($AL5*$E5)*100,"") | K5: =IF(AND(ISNUMBER($F5),ISNUMBER($J5)),$F5*(1-$J5),"") | N5: =IF(ISNUMBER($F5),($F5-IF(ISNUMBER($AM5),$AM5,0))*(1-IF(ISNUMBER($J5),$J5,0)),"") | O5: Black Raspberry | P5: 0 | Q5: 25 | R5: Not listed | S5: 0 | T5: 5 | U5: Sucralose | V5: Zero sugar, vitamins A/D/B, antioxidants (green tea), bold flavour | AA5: High | AB5: Mass-market functional sparkling; strong shelf share | AC5: Bold zero-sugar sparkling with added vitamins | AD5: Big flavour and added vitamins at zero sugar. | AF5: =IF(AND(ISNUMBER($P5),ISNUMBER($AL5),$AL5<>0),ROUND($P5/$AL5*100,1),"") | AG5: =IF(AND(ISNUMBER($S5),ISNUMBER($AL5),$AL5<>0),ROUND($S5/$AL5*100,2),"") | AH5: =IF(AND(ISNUMBER($Q5),ISNUMBER($AL5),$AL5<>0),ROUND($Q5/$AL5*100,1),"") | AI5: =IF(ISNUMBER($S5),IF($S5<=1,"Yes","No"),"n/a") | AJ5: =IF(ISNUMBER($S5),ROUND(MAX(0,MIN(100,100-$S5*2.5-IF(ISNUMBER($T5),$T5,0)*0.12+IF($S5<=1,12,0))),0),"") | AK5: =IF(ISNUMBER($Q5),IF($Q5>=100,20,IF($Q5>=30,10,0)),0)+IF(ISNUMBER($R5),IF($R5>=100,20,0),0)+IF(ISNUMBER($P5),IF($P5>=150,20,IF($P5>=50,12,5)),0)+IF(ISNUMBER($S5),IF($S5<=1,15,0),0) | AL5: 503 | AN5: Secondary/approx; NOT verified on Amazon.ca | AO5: BLANK -> requires live Amazon.ca capture | AP5: Unverified commercial data
A6: Sparkling Ice | B6: Sparkling Ice (+ Antioxidants & Vitamins) | Black Raspberry | 24-pack 503mL | C6: 1) Sparkling electrolyte / functional sparkling | D6: 503 mL bottle | E6: 24 | G6: =IF(AND(ISNUMBER($F6),ISNUMBER($E6),$E6<>0),$F6/$E6,"") | H6: =IF(AND(ISNUMBER($F6),ISNUMBER($AL6),ISNUMBER($E6),($AL6*$E6)<>0),$F6/($AL6*$E6)*100,"") | K6: =IF(AND(ISNUMBER($F6),ISNUMBER($J6)),$F6*(1-$J6),"") | N6: =IF(ISNUMBER($F6),($F6-IF(ISNUMBER($AM6),$AM6,0))*(1-IF(ISNUMBER($J6),$J6,0)),"") | O6: Black Raspberry | P6: 0 | Q6: 25 | R6: Not listed | S6: 0 | T6: 5 | U6: Sucralose | V6: Zero sugar, vitamins A/D/B, antioxidants (green tea), bold flavour | AA6: High | AB6: Mass-market functional sparkling; strong shelf share | AC6: Bold zero-sugar sparkling with added vitamins | AD6: Big flavour and added vitamins at zero sugar. | AF6: =IF(AND(ISNUMBER($P6),ISNUMBER($AL6),$AL6<>0),ROUND($P6/$AL6*100,1),"") | AG6: =IF(AND(ISNUMBER($S6),ISNUMBER($AL6),$AL6<>0),ROUND($S6/$AL6*100,2),"") | AH6: =IF(AND(ISNUMBER($Q6),ISNUMBER($AL6),$AL6<>0),ROUND($Q6/$AL6*100,1),"") | AI6: =IF(ISNUMBER($S6),IF($S6<=1,"Yes","No"),"n/a") | AJ6: =IF(ISNUMBER($S6),ROUND(MAX(0,MIN(100,100-$S6*2.5-IF(ISNUMBER($T6),$T6,0)*0.12+IF($S6<=1,12,0))),0),"") | AK6: =IF(ISNUMBER($Q6),IF($Q6>=100,20,IF($Q6>=30,10,0)),0)+IF(ISNUMBER($R6),IF($R6>=100,20,0),0)+IF(ISNUMBER($P6),IF($P6>=150,20,IF($P6>=50,12,5)),0)+IF(ISNUMBER($S6),IF($S6<=1,15,0),0) | AL6: 503 | AN6: Secondary/approx; NOT verified on Amazon.ca | AO6: BLANK -> requires live Amazon.ca capture | AP6: Unverified commercial data
A7: Sparkling Ice | B7: Sparkling Ice (+ Antioxidants & Vitamins) | Cherry Limeade | single 503mL | C7: 1) Sparkling electrolyte / functional sparkling | D7: 503 mL bottle | E7: 1 | G7: =IF(AND(ISNUMBER($F7),ISNUMBER($E7),$E7<>0),$F7/$E7,"") | H7: =IF(AND(ISNUMBER($F7),ISNUMBER($AL7),ISNUMBER($E7),($AL7*$E7)<>0),$F7/($AL7*$E7)*100,"") | K7: =IF(AND(ISNUMBER($F7),ISNUMBER($J7)),$F7*(1-$J7),"") | N7: =IF(ISNUMBER($F7),($F7-IF(ISNUMBER($AM7),$AM7,0))*(1-IF(ISNUMBER($J7),$J7,0)),"") | O7: Cherry Limeade | P7: 0 | Q7: 25 | R7: Not listed | S7: 0 | T7: 5 | U7: Sucralose | V7: Zero sugar, vitamins A/D/B, antioxidants (green tea), bold flavour | AA7: High | AB7: Mass-market functional sparkling; strong shelf share | AC7: Bold zero-sugar sparkling with added vitamins | AD7: Big flavour and added vitamins at zero sugar. | AF7: =IF(AND(ISNUMBER($P7),ISNUMBER($AL7),$AL7<>0),ROUND($P7/$AL7*100,1),"") | AG7: =IF(AND(ISNUMBER($S7),ISNUMBER($AL7),$AL7<>0),ROUND($S7/$AL7*100,2),"") | AH7: =IF(AND(ISNUMBER($Q7),ISNUMBER($AL7),$AL7<>0),ROUND($Q7/$AL7*100,1),"") | AI7: =IF(ISNUMBER($S7),IF($S7<=1,"Yes","No"),"n/a") | AJ7: =IF(ISNUMBER($S7),ROUND(MAX(0,MIN(100,100-$S7*2.5-IF(ISNUMBER($T7),$T7,0)*0.12+IF($S7<=1,12,0))),0),"") | AK7: =IF(ISNUMBER($Q7),IF($Q7>=100,20,IF($Q7>=30,10,0)),0)+IF(ISNUMBER($R7),IF($R7>=100,20,0),0)+IF(ISNUMBER($P7),IF($P7>=150,20,IF($P7>=50,12,5)),0)+IF(ISNUMBER($S7),IF($S7<=1,15,0),0) | AL7: 503 | AN7: Secondary/approx; NOT verified on Amazon.ca | AO7: BLANK -> requires live Amazon.ca capture | AP7: Unverified commercial data
A8: Sparkling Ice | B8: Sparkling Ice (+ Antioxidants & Vitamins) | Cherry Limeade | 8-pack 503mL | C8: 1) Sparkling electrolyte / functional sparkling | D8: 503 mL bottle | E8: 8 | G8: =IF(AND(ISNUMBER($F8),ISNUMBER($E8),$E8<>0),$F8/$E8,"") | H8: =IF(AND(ISNUMBER($F8),ISNUMBER($AL8),ISNUMBER($E8),($AL8*$E8)<>0),$F8/($AL8*$E8)*100,"") | K8: =IF(AND(ISNUMBER($F8),ISNUMBER($J8)),$F8*(1-$J8),"") | N8: =IF(ISNUMBER($F8),($F8-IF(ISNUMBER($AM8),$AM8,0))*(1-IF(ISNUMBER($J8),$J8,0)),"") | O8: Cherry Limeade | P8: 0 | Q8: 25 | R8: Not listed | S8: 0 | T8: 5 | U8: Sucralose | V8: Zero sugar, vitamins A/D/B, antioxidants (green tea), bold flavour | AA8: High | AB8: Mass-market functional sparkling; strong shelf share | AC8: Bold zero-sugar sparkling with added vitamins | AD8: Big flavour and added vitamins at zero sugar. | AF8: =IF(AND(ISNUMBER($P8),ISNUMBER($AL8),$AL8<>0),ROUND($P8/$AL8*100,1),"") | AG8: =IF(AND(ISNUMBER($S8),ISNUMBER($AL8),$AL8<>0),ROUND($S8/$AL8*100,2),"") | AH8: =IF(AND(ISNUMBER($Q8),ISNUMBER($AL8),$AL8<>0),ROUND($Q8/$AL8*100,1),"") | AI8: =IF(ISNUMBER($S8),IF($S8<=1,"Yes","No"),"n/a") | AJ8: =IF(ISNUMBER($S8),ROUND(MAX(0,MIN(100,100-$S8*2.5-IF(ISNUMBER($T8),$T8,0)*0.12+IF($S8<=1,12,0))),0),"") | AK8: =IF(ISNUMBER($Q8),IF($Q8>=100,20,IF($Q8>=30,10,0)),0)+IF(ISNUMBER($R8),IF($R8>=100,20,0),0)+IF(ISNUMBER($P8),IF($P8>=150,20,IF($P8>=50,12,5)),0)+IF(ISNUMBER($S8),IF($S8<=1,15,0),0) | AL8: 503 | AN8: Secondary/approx; NOT verified on Amazon.ca | AO8: BLANK -> requires live Amazon.ca capture | AP8: Unverified commercial data
A9: Sparkling Ice | B9: Sparkling Ice (+ Antioxidants & Vitamins) | Cherry Limeade | 12-pack 503mL | C9: 1) Sparkling electrolyte / functional sparkling | D9: 503 mL bottle | E9: 12 | G9: =IF(AND(ISNUMBER($F9),ISNUMBER($E9),$E9<>0),$F9/$E9,"") | H9: =IF(AND(ISNUMBER($F9),ISNUMBER($AL9),ISNUMBER($E9),($AL9*$E9)<>0),$F9/($AL9*$E9)*100,"") | K9: =IF(AND(ISNUMBER($F9),ISNUMBER($J9)),$F9*(1-$J9),"") | N9: =IF(ISNUMBER($F9),($F9-IF(ISNUMBER($AM9),$AM9,0))*(1-IF(ISNUMBER($J9),$J9,0)),"") | O9: Cherry Limeade | P9: 0 | Q9: 25 | R9: Not listed | S9: 0 | T9: 5 | U9: Sucralose | V9: Zero sugar, vitamins A/D/B, antioxidants (green tea), bold flavour | AA9: High | AB9: Mass-market functional sparkling; strong shelf share | AC9: Bold zero-sugar sparkling with added vitamins | AD9: Big flavour and added vitamins at zero sugar. | AF9: =IF(AND(ISNUMBER($P9),ISNUMBER($AL9),$AL9<>0),ROUND($P9/$AL9*100,1),"") | AG9: =IF(AND(ISNUMBER($S9),ISNUMBER($AL9),$AL9<>0),ROUND($S9/$AL9*100,2),"") | AH9: =IF(AND(ISNUMBER($Q9),ISNUMBER($AL9),$AL9<>0),ROUND($Q9/$AL9*100,1),"") | AI9: =IF(ISNUMBER($S9),IF($S9<=1,"Yes","No"),"n/a") | AJ9: =IF(ISNUMBER($S9),ROUND(MAX(0,MIN(100,100-$S9*2.5-IF(ISNUMBER($T9),$T9,0)*0.12+IF($S9<=1,12,0))),0),"") | AK9: =IF(ISNUMBER($Q9),IF($Q9>=100,20,IF($Q9>=30,10,0)),0)+IF(ISNUMBER($R9),IF($R9>=100,20,0),0)+IF(ISNUMBER($P9),IF($P9>=150,20,IF($P9>=50,12,5)),0)+IF(ISNUMBER($S9),IF($S9<=1,15,0),0) | AL9: 503 | AN9: Secondary/approx; NOT verified on Amazon.ca | AO9: BLANK -> requires live Amazon.ca capture | AP9: Unverified commercial data
A10: Sparkling Ice | B10: Sparkling Ice (+ Antioxidants & Vitamins) | Cherry Limeade | 18-pack 503mL | C10: 1) Sparkling electrolyte / functional sparkling | D10: 503 mL bottle | E10: 18 | G10: =IF(AND(ISNUMBER($F10),ISNUMBER($E10),$E10<>0),$F10/$E10,"") | H10: =IF(AND(ISNUMBER($F10),ISNUMBER($AL10),ISNUMBER($E10),($AL10*$E10)<>0),$F10/($AL10*$E10)*100,"") | K10: =IF(AND(ISNUMBER($F10),ISNUMBER($J10)),$F10*(1-$J10),"") | N10: =IF(ISNUMBER($F10),($F10-IF(ISNUMBER($AM10),$AM10,0))*(1-IF(ISNUMBER($J10),$J10,0)),"") | O10: Cherry Limeade | P10: 0 | Q10: 25 | R10: Not listed | S10: 0 | T10: 5 | U10: Sucralose | V10: Zero sugar, vitamins A/D/B, antioxidants (green tea), bold flavour | AA10: High | AB10: Mass-market functional sparkling; strong shelf share | AC10: Bold zero-sugar sparkling with added vitamins | AD10: Big flavour and added vitamins at zero sugar. | AF10: =IF(AND(ISNUMBER($P10),ISNUMBER($AL10),$AL10<>0),ROUND($P10/$AL10*100,1),"") | AG10: =IF(AND(ISNUMBER($S10),ISNUMBER($AL10),$AL10<>0),ROUND($S10/$AL10*100,2),"") | AH10: =IF(AND(ISNUMBER($Q10),ISNUMBER($AL10),$AL10<>0),ROUND($Q10/$AL10*100,1),"") | AI10: =IF(ISNUMBER($S10),IF($S10<=1,"Yes","No"),"n/a") | AJ10: =IF(ISNUMBER($S10),ROUND(MAX(0,MIN(100,100-$S10*2.5-IF(ISNUMBER($T10),$T10,0)*0.12+IF($S10<=1,12,0))),0),"") | AK10: =IF(ISNUMBER($Q10),IF($Q10>=100,20,IF($Q10>=30,10,0)),0)+IF(ISNUMBER($R10),IF($R10>=100,20,0),0)+IF(ISNUMBER($P10),IF($P10>=150,20,IF($P10>=50,12,5)),0)+IF(ISNUMBER($S10),IF($S10<=1,15,0),0) | AL10: 503 | AN10: Secondary/approx; NOT verified on Amazon.ca | AO10: BLANK -> requires live Amazon.ca capture | AP10: Unverified commercial data
A11: Sparkling Ice | B11: Sparkling Ice (+ Antioxidants & Vitamins) | Cherry Limeade | 24-pack 503mL | C11: 1) Sparkling electrolyte / functional sparkling | D11: 503 mL bottle | E11: 24 | G11: =IF(AND(ISNUMBER($F11),ISNUMBER($E11),$E11<>0),$F11/$E11,"") | H11: =IF(AND(ISNUMBER($F11),ISNUMBER($AL11),ISNUMBER($E11),($AL11*$E11)<>0),$F11/($AL11*$E11)*100,"") | K11: =IF(AND(ISNUMBER($F11),ISNUMBER($J11)),$F11*(1-$J11),"") | N11: =IF(ISNUMBER($F11),($F11-IF(ISNUMBER($AM11),$AM11,0))*(1-IF(ISNUMBER($J11),$J11,0)),"") | O11: Cherry Limeade | P11: 0 | Q11: 25 | R11: Not listed | S11: 0 | T11: 5 | U11: Sucralose | V11: Zero sugar, vitamins A/D/B, antioxidants (green tea), bold flavour | AA11: High | AB11: Mass-market functional sparkling; strong shelf share | AC11: Bold zero-sugar sparkling with added vitamins | AD11: Big flavour and added vitamins at zero sugar. | AF11: =IF(AND(ISNUMBER($P11),ISNUMBER($AL11),$AL11<>0),ROUND($P11/$AL11*100,1),"") | AG11: =IF(AND(ISNUMBER($S11),ISNUMBER($AL11),$AL11<>0),ROUND($S11/$AL11*100,2),"") | AH11: =IF(AND(ISNUMBER($Q11),ISNUMBER($AL11),$AL11<>0),ROUND($Q11/$AL11*100,1),"") | AI11: =IF(ISNUMBER($S11),IF($S11<=1,"Yes","No"),"n/a") | AJ11: =IF(ISNUMBER($S11),ROUND(MAX(0,MIN(100,100-$S11*2.5-IF(ISNUMBER($T11),$T11,0)*0.12+IF($S11<=1,12,0))),0),"") | AK11: =IF(ISNUMBER($Q11),IF($Q11>=100,20,IF($Q11>=30,10,0)),0)+IF(ISNUMBER($R11),IF($R11>=100,20,0),0)+IF(ISNUMBER($P11),IF($P11>=150,20,IF($P11>=50,12,5)),0)+IF(ISNUMBER($S11),IF($S11<=1,15,0),0) | AL11: 503 | AN11: Secondary/approx; NOT verified on Amazon.ca | AO11: BLANK -> requires live Amazon.ca capture | AP11: Unverified commercial data
A12: Sparkling Ice | B12: Sparkling Ice (+ Antioxidants & Vitamins) | Orange Mango | single 503mL | C12: 1) Sparkling electrolyte / functional sparkling | D12: 503 mL bottle | E12: 1 | G12: =IF(AND(ISNUMBER($F12),ISNUMBER($E12),$E12<>0),$F12/$E12,"") | H12: =IF(AND(ISNUMBER($F12),ISNUMBER($AL12),ISNUMBER($E12),($AL12*$E12)<>0),$F12/($AL12*$E12)*100,"") | K12: =IF(AND(ISNUMBER($F12),ISNUMBER($J12)),$F12*(1-$J12),"") | N12: =IF(ISNUMBER($F12),($F12-IF(ISNUMBER($AM12),$AM12,0))*(1-IF(ISNUMBER($J12),$J12,0)),"") | O12: Orange Mango | P12: 0 | Q12: 25 | R12: Not listed | S12: 0 | T12: 5 | U12: Sucralose | V12: Zero sugar, vitamins A/D/B, antioxidants (green tea), bold flavour | AA12: High | AB12: Mass-market functional sparkling; strong shelf share | AC12: Bold zero-sugar sparkling with added vitamins | AD12: Big flavour and added vitamins at zero sugar. | AF12: =IF(AND(ISNUMBER($P12),ISNUMBER($AL12),$AL12<>0),ROUND($P12/$AL12*100,1),"") | AG12: =IF(AND(ISNUMBER($S12),ISNUMBER($AL12),$AL12<>0),ROUND($S12/$AL12*100,2),"") | AH12: =IF(AND(ISNUMBER($Q12),ISNUMBER($AL12),$AL12<>0),ROUND($Q12/$AL12*100,1),"") | AI12: =IF(ISNUMBER($S12),IF($S12<=1,"Yes","No"),"n/a") | AJ12: =IF(ISNUMBER($S12),ROUND(MAX(0,MIN(100,100-$S12*2.5-IF(ISNUMBER($T12),$T12,0)*0.12+IF($S12<=1,12,0))),0),"") | AK12: =IF(ISNUMBER($Q12),IF($Q12>=100,20,IF($Q12>=30,10,0)),0)+IF(ISNUMBER($R12),IF($R12>=100,20,0),0)+IF(ISNUMBER($P12),IF($P12>=150,20,IF($P12>=50,12,5)),0)+IF(ISNUMBER($S12),IF($S12<=1,15,0),0) | AL12: 503 | AN12: Secondary/approx; NOT verified on Amazon.ca | AO12: BLANK -> requires live Amazon.ca capture | AP12: Unverified commercial data
A13: Sparkling Ice | B13: Sparkling Ice (+ Antioxidants & Vitamins) | Orange Mango | 8-pack 503mL | C13: 1) Sparkling electrolyte / functional sparkling | D13: 503 mL bottle | E13: 8 | G13: =IF(AND(ISNUMBER($F13),ISNUMBER($E13),$E13<>0),$F13/$E13,"") | H13: =IF(AND(ISNUMBER($F13),ISNUMBER($AL13),ISNUMBER($E13),($AL13*$E13)<>0),$F13/($AL13*$E13)*100,"") | K13: =IF(AND(ISNUMBER($F13),ISNUMBER($J13)),$F13*(1-$J13),"") | N13: =IF(ISNUMBER($F13),($F13-IF(ISNUMBER($AM13),$AM13,0))*(1-IF(ISNUMBER($J13),$J13,0)),"") | O13: Orange Mango | P13: 0 | Q13: 25 | R13: Not listed | S13: 0 | T13: 5 | U13: Sucralose | V13: Zero sugar, vitamins A/D/B, antioxidants (green tea), bold flavour | AA13: High | AB13: Mass-market functional sparkling; strong shelf share | AC13: Bold zero-sugar sparkling with added vitamins | AD13: Big flavour and added vitamins at zero sugar. | AF13: =IF(AND(ISNUMBER($P13),ISNUMBER($AL13),$AL13<>0),ROUND($P13/$AL13*100,1),"") | AG13: =IF(AND(ISNUMBER($S13),ISNUMBER($AL13),$AL13<>0),ROUND($S13/$AL13*100,2),"") | AH13: =IF(AND(ISNUMBER($Q13),ISNUMBER($AL13),$AL13<>0),ROUND($Q13/$AL13*100,1),"") | AI13: =IF(ISNUMBER($S13),IF($S13<=1,"Yes","No"),"n/a") | AJ13: =IF(ISNUMBER($S13),ROUND(MAX(0,MIN(100,100-$S13*2.5-IF(ISNUMBER($T13),$T13,0)*0.12+IF($S13<=1,12,0))),0),"") | AK13: =IF(ISNUMBER($Q13),IF($Q13>=100,20,IF($Q13>=30,10,0)),0)+IF(ISNUMBER($R13),IF($R13>=100,20,0),0)+IF(ISNUMBER($P13),IF($P13>=150,20,IF($P13>=50,12,5)),0)+IF(ISNUMBER($S13),IF($S13<=1,15,0),0) | AL13: 503 | AN13: Secondary/approx; NOT verified on Amazon.ca | AO13: BLANK -> requires live Amazon.ca capture | AP13: Unverified commercial data
... A146: Sound | B146: Sound Sparkling Water (Tea/Botanical) | Cucumber + Mint Green Tea | 24-pack 355mL | C146: 1) Sparkling electrolyte / functional sparkling | D146: 355 mL can | E146: 24 | G146: =IF(AND(ISNUMBER($F146),ISNUMBER($E146),$E146<>0),$F146/$E146,"") | H146: =IF(AND(ISNUMBER($F146),ISNUMBER($AL146),ISNUMBER($E146),($AL146*$E146)<>0),$F146/($AL146*$E146)*100,"") | K146: =IF(AND(ISNUMBER($F146),ISNUMBER($J146)),$F146*(1-$J146),"") | N146: =IF(ISNUMBER($F146),($F146-IF(ISNUMBER($AM146),$AM146,0))*(1-IF(ISNUMBER($J146),$J146,0)),"") | O146: Cucumber + Mint Green Tea | P146: 15 | Q146: 0 | R146: Not listed | S146: 0 | T146: 0 | U146: None (unsweetened) | V146: Real brewed tea/botanicals, unsweetened, zero sugar/calorie | AA146: Low | AB146: Emerging unsweetened-botanical niche | AC146: Unsweetened sparkling brewed tea and botanicals | AD146: Genuinely unsweetened with real tea/botanical character. | AF146: =IF(AND(ISNUMBER($P146),ISNUMBER($AL146),$AL146<>0),ROUND($P146/$AL146*100,1),"") | AG146: =IF(AND(ISNUMBER($S146),ISNUMBER($AL146),$AL146<>0),ROUND($S146/$AL146*100,2),"") | AH146: =IF(AND(ISNUMBER($Q146),ISNUMBER($AL146),$AL146<>0),ROUND($Q146/$AL146*100,1),"") | AI146: =IF(ISNUMBER($S146),IF($S146<=1,"Yes","No"),"n/a") | AJ146: =IF(ISNUMBER($S146),ROUND(MAX(0,MIN(100,100-$S146*2.5-IF(ISNUMBER($T146),$T146,0)*0.12+IF($S146<=1,12,0))),0),"") | AK146: =IF(ISNUMBER($Q146),IF($Q146>=100,20,IF($Q146>=30,10,0)),0)+IF(ISNUMBER($R146),IF($R146>=100,20,0),0)+IF(ISNUMBER($P146),IF($P146>=150,20,IF($P146>=50,12,5)),0)+IF(ISNUMBER($S146),IF($S146<=1,15,0),0) | AL146: 355 | AN146: Secondary/approx; NOT verified on Amazon.ca | AO146: BLANK -> requires live Amazon.ca capture | AP146: Unverified commercial data
A147: Halo Sport | B147: Halo Sport Sparkling Electrolyte Water | Lemon Lime | single 355mL | C147: 1) Sparkling electrolyte / functional sparkling | D147: 355 mL can | E147: 1 | G147: =IF(AND(ISNUMBER($F147),ISNUMBER($E147),$E147<>0),$F147/$E147,"") | H147: =IF(AND(ISNUMBER($F147),ISNUMBER($AL147),ISNUMBER($E147),($AL147*$E147)<>0),$F147/($AL147*$E147)*100,"") | K147: =IF(AND(ISNUMBER($F147),ISNUMBER($J147)),$F147*(1-$J147),"") | N147: =IF(ISNUMBER($F147),($F147-IF(ISNUMBER($AM147),$AM147,0))*(1-IF(ISNUMBER($J147),$J147,0)),"") | O147: Lemon Lime | P147: 0 | Q147: 110 | R147: 40 | S147: 0 | T147: 5 | U147: Stevia | V147: Sparkling electrolytes, zero sugar, light hydration | AA147: Low | AB147: Small emerging sparkling-electrolyte entrant | AC147: Sparkling, lightly-mineralled hydration | AD147: Electrolytes in a fizzy, zero-sugar format. | AF147: =IF(AND(ISNUMBER($P147),ISNUMBER($AL147),$AL147<>0),ROUND($P147/$AL147*100,1),"") | AG147: =IF(AND(ISNUMBER($S147),ISNUMBER($AL147),$AL147<>0),ROUND($S147/$AL147*100,2),"") | AH147: =IF(AND(ISNUMBER($Q147),ISNUMBER($AL147),$AL147<>0),ROUND($Q147/$AL147*100,1),"") | AI147: =IF(ISNUMBER($S147),IF($S147<=1,"Yes","No"),"n/a") | AJ147: =IF(ISNUMBER($S147),ROUND(MAX(0,MIN(100,100-$S147*2.5-IF(ISNUMBER($T147),$T147,0)*0.12+IF($S147<=1,12,0))),0),"") | AK147: =IF(ISNUMBER($Q147),IF($Q147>=100,20,IF($Q147>=30,10,0)),0)+IF(ISNUMBER($R147),IF($R147>=100,20,0),0)+IF(ISNUMBER($P147),IF($P147>=150,20,IF($P147>=50,12,5)),0)+IF(ISNUMBER($S147),IF($S147<=1,15,0),0) | AL147: 355 | AN147: Secondary/approx; NOT verified on Amazon.ca | AO147: BLANK -> requires live Amazon.ca capture | AP147: Unverified commercial data
A148: Halo Sport | B148: Halo Sport Sparkling Electrolyte Water | Lemon Lime | 8-pack 355mL | C148: 1) Sparkling electrolyte / functional sparkling | D148: 355 mL can | E148: 8 | G148: =IF(AND(ISNUMBER($F148),ISNUMBER($E148),$E148<>0),$F148/$E148,"") | H148: =IF(AND(ISNUMBER($F148),ISNUMBER($AL148),ISNUMBER($E148),($AL148*$E148)<>0),$F148/($AL148*$E148)*100,"") | K148: =IF(AND(ISNUMBER($F148),ISNUMBER($J148)),$F148*(1-$J148),"") | N148: =IF(ISNUMBER($F148),($F148-IF(ISNUMBER($AM148),$AM148,0))*(1-IF(ISNUMBER($J148),$J148,0)),"") | O148: Lemon Lime | P148: 0 | Q148: 110 | R148: 40 | S148: 0 | T148: 5 | U148: Stevia | V148: Sparkling electrolytes, zero sugar, light hydration | AA148: Low | AB148: Small emerging sparkling-electrolyte entrant | AC148: Sparkling, lightly-mineralled hydration | AD148: Electrolytes in a fizzy, zero-sugar format. | AF148: =IF(AND(ISNUMBER($P148),ISNUMBER($AL148),$AL148<>0),ROUND($P148/$AL148*100,1),"") | AG148: =IF(AND(ISNUMBER($S148),ISNUMBER($AL148),$AL148<>0),ROUND($S148/$AL148*100,2),"") | AH148: =IF(AND(ISNUMBER($Q148),ISNUMBER($AL148),$AL148<>0),ROUND($Q148/$AL148*100,1),"") | AI148: =IF(ISNUMBER($S148),IF($S148<=1,"Yes","No"),"n/a") | AJ148: =IF(ISNUMBER($S148),ROUND(MAX(0,MIN(100,100-$S148*2.5-IF(ISNUMBER($T148),$T148,0)*0.12+IF($S148<=1,12,0))),0),"") | AK148: =IF(ISNUMBER($Q148),IF($Q148>=100,20,IF($Q148>=30,10,0)),0)+IF(ISNUMBER($R148),IF($R148>=100,20,0),0)+IF(ISNUMBER($P148),IF($P148>=150,20,IF($P148>=50,12,5)),0)+IF(ISNUMBER($S148),IF($S148<=1,15,0),0) | AL148: 355 | AN148: Secondary/approx; NOT verified on Amazon.ca | AO148: BLANK -> requires live Amazon.ca capture | AP148: Unverified commercial data
A149: Halo Sport | B149: Halo Sport Sparkling Electrolyte Water | Lemon Lime | 12-pack 355mL | C149: 1) Sparkling electrolyte / functional sparkling | D149: 355 mL can | E149: 12 | G149: =IF(AND(ISNUMBER($F149),ISNUMBER($E149),$E149<>0),$F149/$E149,"") | H149: =IF(AND(ISNUMBER($F149),ISNUMBER($AL149),ISNUMBER($E149),($AL149*$E149)<>0),$F149/($AL149*$E149)*100,"") | K149: =IF(AND(ISNUMBER($F149),ISNUMBER($J149)),$F149*(1-$J149),"") | N149: =IF(ISNUMBER($F149),($F149-IF(ISNUMBER($AM149),$AM149,0))*(1-IF(ISNUMBER($J149),$J149,0)),"") | O149: Lemon Lime | P149: 0 | Q149: 110 | R149: 40 | S149: 0 | T149: 5 | U149: Stevia | V149: Sparkling electrolytes, zero sugar, light hydration | AA149: Low | AB149: Small emerging sparkling-electrolyte entrant | AC149: Sparkling, lightly-mineralled hydration | AD149: Electrolytes in a fizzy, zero-sugar format. | AF149: =IF(AND(ISNUMBER($P149),ISNUMBER($AL149),$AL149<>0),ROUND($P149/$AL149*100,1),"") | AG149: =IF(AND(ISNUMBER($S149),ISNUMBER($AL149),$AL149<>0),ROUND($S149/$AL149*100,2),"") | AH149: =IF(AND(ISNUMBER($Q149),ISNUMBER($AL149),$AL149<>0),ROUND($Q149/$AL149*100,1),"") | AI149: =IF(ISNUMBER($S149),IF($S149<=1,"Yes","No"),"n/a") | AJ149: =IF(ISNUMBER($S149),ROUND(MAX(0,MIN(100,100-$S149*2.5-IF(ISNUMBER($T149),$T149,0)*0.12+IF($S149<=1,12,0))),0),"") | AK149: =IF(ISNUMBER($Q149),IF($Q149>=100,20,IF($Q149>=30,10,0)),0)+IF(ISNUMBER($R149),IF($R149>=100,20,0),0)+IF(ISNUMBER($P149),IF($P149>=150,20,IF($P149>=50,12,5)),0)+IF(ISNUMBER($S149),IF($S149<=1,15,0),0) | AL149: 355 | AN149: Secondary/approx; NOT verified on Amazon.ca | AO149: BLANK -> requires live Amazon.ca capture | AP149: Unverified commercial data
A150: Halo Sport | B150: Halo Sport Sparkling Electrolyte Water | Lemon Lime | 15-pack 355mL | C150: 1) Sparkling electrolyte / functional sparkling | D150: 355 mL can | E150: 15 | G150: =IF(AND(ISNUMBER($F150),ISNUMBER($E150),$E150<>0),$F150/$E150,"") | H150: =IF(AND(ISNUMBER($F150),ISNUMBER($AL150),ISNUMBER($E150),($AL150*$E150)<>0),$F150/($AL150*$E150)*100,"") | K150: =IF(AND(ISNUMBER($F150),ISNUMBER($J150)),$F150*(1-$J150),"") | N150: =IF(ISNUMBER($F150),($F150-IF(ISNUMBER($AM150),$AM150,0))*(1-IF(ISNUMBER($J150),$J150,0)),"") | O150: Lemon Lime | P150: 0 | Q150: 110 | R150: 40 | S150: 0 | T150: 5 | U150: Stevia | V150: Sparkling electrolytes, zero sugar, light hydration | AA150: Low | AB150: Small emerging sparkling-electrolyte entrant | AC150: Sparkling, lightly-mineralled hydration | AD150: Electrolytes in a fizzy, zero-sugar format. | AF150: =IF(AND(ISNUMBER($P150),ISNUMBER($AL150),$AL150<>0),ROUND($P150/$AL150*100,1),"") | AG150: =IF(AND(ISNUMBER($S150),ISNUMBER($AL150),$AL150<>0),ROUND($S150/$AL150*100,2),"") | AH150: =IF(AND(ISNUMBER($Q150),ISNUMBER($AL150),$AL150<>0),ROUND($Q150/$AL150*100,1),"") | AI150: =IF(ISNUMBER($S150),IF($S150<=1,"Yes","No"),"n/a") | AJ150: =IF(ISNUMBER($S150),ROUND(MAX(0,MIN(100,100-$S150*2.5-IF(ISNUMBER($T150),$T150,0)*0.12+IF($S150<=1,12,0))),0),"") | AK150: =IF(ISNUMBER($Q150),IF($Q150>=100,20,IF($Q150>=30,10,0)),0)+IF(ISNUMBER($R150),IF($R150>=100,20,0),0)+IF(ISNUMBER($P150),IF($P150>=150,20,IF($P150>=50,12,5)),0)+IF(ISNUMBER($S150),IF($S150<=1,15,0),0) | AL150: 355 | AN150: Secondary/approx; NOT verified on Amazon.ca | AO150: BLANK -> requires live Amazon.ca capture | AP150: Unverified commercial data
A151: Halo Sport | B151: Halo Sport Sparkling Electrolyte Water | Lemon Lime | 18-pack 355mL | C151: 1) Sparkling electrolyte / functional sparkling | D151: 355 mL can | E151: 18 | G151: =IF(AND(ISNUMBER($F151),ISNUMBER($E151),$E151<>0),$F151/$E151,"") | H151: =IF(AND(ISNUMBER($F151),ISNUMBER($AL151),ISNUMBER($E151),($AL151*$E151)<>0),$F151/($AL151*$E151)*100,"") | K151: =IF(AND(ISNUMBER($F151),ISNUMBER($J151)),$F151*(1-$J151),"") | N151: =IF(ISNUMBER($F151),($F151-IF(ISNUMBER($AM151),$AM151,0))*(1-IF(ISNUMBER($J151),$J151,0)),"") | O151: Lemon Lime | P151: 0 | Q151: 110 | R151: 40 | S151: 0 | T151: 5 | U151: Stevia | V151: Sparkling electrolytes, zero sugar, light hydration | AA151: Low | AB151: Small emerging sparkling-electrolyte entrant | AC151: Sparkling, lightly-mineralled hydration | AD151: Electrolytes in a fizzy, zero-sugar format. | AF151: =IF(AND(ISNUMBER($P151),ISNUMBER($AL151),$AL151<>0),ROUND($P151/$AL151*100,1),"") | AG151: =IF(AND(ISNUMBER($S151),ISNUMBER($AL151),$AL151<>0),ROUND($S151/$AL151*100,2),"") | AH151: =IF(AND(ISNUMBER($Q151),ISNUMBER($AL151),$AL151<>0),ROUND($Q151/$AL151*100,1),"") | AI151: =IF(ISNUMBER($S151),IF($S151<=1,"Yes","No"),"n/a") | AJ151: =IF(ISNUMBER($S151),ROUND(MAX(0,MIN(100,100-$S151*2.5-IF(ISNUMBER($T151),$T151,0)*0.12+IF($S151<=1,12,0))),0),"") | AK151: =IF(ISNUMBER($Q151),IF($Q151>=100,20,IF($Q151>=30,10,0)),0)+IF(ISNUMBER($R151),IF($R151>=100,20,0),0)+IF(ISNUMBER($P151),IF($P151>=150,20,IF($P151>=50,12,5)),0)+IF(ISNUMBER($S151),IF($S151<=1,15,0),0) | AL151: 355 | AN151: Secondary/approx; NOT verified on Amazon.ca | AO151: BLANK -> requires live Amazon.ca capture | AP151: Unverified commercial data
A152: Halo Sport | B152: Halo Sport Sparkling Electrolyte Water | Lemon Lime | 24-pack 355mL | C152: 1) Sparkling electrolyte / functional sparkling | D152: 355 mL can | E152: 24 | G152: =IF(AND(ISNUMBER($F152),ISNUMBER($E152),$E152<>0),$F152/$E152,"") | H152: =IF(AND(ISNUMBER($F152),ISNUMBER($AL152),ISNUMBER($E152),($AL152*$E152)<>0),$F152/($AL152*$E152)*100,"") | K152: =IF(AND(ISNUMBER($F152),ISNUMBER($J152)),$F152*(1-$J152),"") | N152: =IF(ISNUMBER($F152),($F152-IF(ISNUMBER($AM152),$AM152,0))*(1-IF(ISNUMBER($J152),$J152,0)),"") | O152: Lemon Lime | P152: 0 | Q152: 110 | R152: 40 | S152: 0 | T152: 5 | U152: Stevia | V152: Sparkling electrolytes, zero sugar, light hydration | AA152: Low | AB152: Small emerging sparkling-electrolyte entrant | AC152: Sparkling, lightly-mineralled hydration | AD152: Electrolytes in a fizzy, zero-sugar format. | AF152: =IF(AND(ISNUMBER($P152),ISNUMBER($AL152),$AL152<>0),ROUND($P152/$AL152*100,1),"") | AG152: =IF(AND(ISNUMBER($S152),ISNUMBER($AL152),$AL152<>0),ROUND($S152/$AL152*100,2),"") | AH152: =IF(AND(ISNUMBER($Q152),ISNUMBER($AL152),$AL152<>0),ROUND($Q152/$AL152*100,1),"") | AI152: =IF(ISNUMBER($S152),IF($S152<=1,"Yes","No"),"n/a") | AJ152: =IF(ISNUMBER($S152),ROUND(MAX(0,MIN(100,100-$S152*2.5-IF(ISNUMBER($T152),$T152,0)*0.12+IF($S152<=1,12,0))),0),"") | AK152: =IF(ISNUMBER($Q152),IF($Q152>=100,20,IF($Q152>=30,10,0)),0)+IF(ISNUMBER($R152),IF($R152>=100,20,0),0)+IF(ISNUMBER($P152),IF($P152>=150,20,IF($P152>=50,12,5)),0)+IF(ISNUMBER($S152),IF($S152<=1,15,0),0) | AL152: 355 | AN152: Secondary/approx; NOT verified on Amazon.ca | AO152: BLANK -> requires live Amazon.ca capture | AP152: Unverified commercial data
A153: Halo Sport | B153: Halo Sport Sparkling Electrolyte Water | Berry | single 355mL | C153: 1) Sparkling electrolyte / functional sparkling | D153: 355 mL can | E153: 1 | G153: =IF(AND(ISNUMBER($F153),ISNUMBER($E153),$E153<>0),$F153/$E153,"") | H153: =IF(AND(ISNUMBER($F153),ISNUMBER($AL153),ISNUMBER($E153),($AL153*$E153)<>0),$F153/($AL153*$E153)*100,"") | K153: =IF(AND(ISNUMBER($F153),ISNUMBER($J153)),$F153*(1-$J153),"") | N153: =IF(ISNUMBER($F153),($F153-IF(ISNUMBER($AM153),$AM153,0))*(1-IF(ISNUMBER($J153),$J153,0)),"") | O153: Berry | P153: 0 | Q153: 110 | R153: 40 | S153: 0 | T153: 5 | U153: Stevia | V153: Sparkling electrolytes, zero sugar, light hydration | AA153: Low | AB153: Small emerging sparkling-electrolyte entrant | AC153: Sparkling, lightly-mineralled hydration | AD153: Electrolytes in a fizzy, zero-sugar format. | AF153: =IF(AND(ISNUMBER($P153),ISNUMBER($AL153),$AL153<>0),ROUND($P153/$AL153*100,1),"") | AG153: =IF(AND(ISNUMBER($S153),ISNUMBER($AL153),$AL153<>0),ROUND($S153/$AL153*100,2),"") | AH153: =IF(AND(ISNUMBER($Q153),ISNUMBER($AL153),$AL153<>0),ROUND($Q153/$AL153*100,1),"") | AI153: =IF(ISNUMBER($S153),IF($S153<=1,"Yes","No"),"n/a") | AJ153: =IF(ISNUMBER($S153),ROUND(MAX(0,MIN(100,100-$S153*2.5-IF(ISNUMBER($T153),$T153,0)*0.12+IF($S153<=1,12,0))),0),"") | AK153: =IF(ISNUMBER($Q153),IF($Q153>=100,20,IF($Q153>=30,10,0)),0)+IF(ISNUMBER($R153),IF($R153>=100,20,0),0)+IF(ISNUMBER($P153),IF($P153>=150,20,IF($P153>=50,12,5)),0)+IF(ISNUMBER($S153),IF($S153<=1,15,0),0) | AL153: 355 | AN153: Secondary/approx; NOT verified on Amazon.ca | AO153: BLANK -> requires live Amazon.ca capture | AP153: Unverified commercial data
A154: Halo Sport | B154: Halo Sport Sparkling Electrolyte Water | Berry | 8-pack 355mL | C154: 1) Sparkling electrolyte / functional sparkling | D154: 355 mL can | E154: 8 | G154: =IF(AND(ISNUMBER($F154),ISNUMBER($E154),$E154<>0),$F154/$E154,"") | H154: =IF(AND(ISNUMBER($F154),ISNUMBER($AL154),ISNUMBER($E154),($AL154*$E154)<>0),$F154/($AL154*$E154)*100,"") | K154: =IF(AND(ISNUMBER($F154),ISNUMBER($J154)),$F154*(1-$J154),"") | N154: =IF(ISNUMBER($F154),($F154-IF(ISNUMBER($AM154),$AM154,0))*(1-IF(ISNUMBER($J154),$J154,0)),"") | O154: Berry | P154: 0 | Q154: 110 | R154: 40 | S154: 0 | T154: 5 | U154: Stevia | V154: Sparkling electrolytes, zero sugar, light hydration | AA154: Low | AB154: Small emerging sparkling-electrolyte entrant | AC154: Sparkling, lightly-mineralled hydration | AD154: Electrolytes in a fizzy, zero-sugar format. | AF154: =IF(AND(ISNUMBER($P154),ISNUMBER($AL154),$AL154<>0),ROUND($P154/$AL154*100,1),"") | AG154: =IF(AND(ISNUMBER($S154),ISNUMBER($AL154),$AL154<>0),ROUND($S154/$AL154*100,2),"") | AH154: =IF(AND(ISNUMBER($Q154),ISNUMBER($AL154),$AL154<>0),ROUND($Q154/$AL154*100,1),"") | AI154: =IF(ISNUMBER($S154),IF($S154<=1,"Yes","No"),"n/a") | AJ154: =IF(ISNUMBER($S154),ROUND(MAX(0,MIN(100,100-$S154*2.5-IF(ISNUMBER($T154),$T154,0)*0.12+IF($S154<=1,12,0))),0),"") | AK154: =IF(ISNUMBER($Q154),IF($Q154>=100,20,IF($Q154>=30,10,0)),0)+IF(ISNUMBER($R154),IF($R154>=100,20,0),0)+IF(ISNUMBER($P154),IF($P154>=150,20,IF($P154>=50,12,5)),0)+IF(ISNUMBER($S154),IF($S154<=1,15,0),0) | AL154: 355 | AN154: Secondary/approx; NOT verified on Amazon.ca | AO154: BLANK -> requires live Amazon.ca capture | AP154: Unverified commercial data
A155: Halo Sport | B155: Halo Sport Sparkling Electrolyte Water | Berry | 12-pack 355mL | C155: 1) Sparkling electrolyte / functional sparkling | D155: 355 mL can | E155: 12 | G155: =IF(AND(ISNUMBER($F155),ISNUMBER($E155),$E155<>0),$F155/$E155,"") | H155: =IF(AND(ISNUMBER($F155),ISNUMBER($AL155),ISNUMBER($E155),($AL155*$E155)<>0),$F155/($AL155*$E155)*100,"") | K155: =IF(AND(ISNUMBER($F155),ISNUMBER($J155)),$F155*(1-$J155),"") | N155: =IF(ISNUMBER($F155),($F155-IF(ISNUMBER($AM155),$AM155,0))*(1-IF(ISNUMBER($J155),$J155,0)),"") | O155: Berry | P155: 0 | Q155: 110 | R155: 40 | S155: 0 | T155: 5 | U155: Stevia | V155: Sparkling electrolytes, zero sugar, light hydration | AA155: Low | AB155: Small emerging sparkling-electrolyte entrant | AC155: Sparkling, lightly-mineralled hydration | AD155: Electrolytes in a fizzy, zero-sugar format. | AF155: =IF(AND(ISNUMBER($P155),ISNUMBER($AL155),$AL155<>0),ROUND($P155/$AL155*100,1),"") | AG155: =IF(AND(ISNUMBER($S155),ISNUMBER($AL155),$AL155<>0),ROUND($S155/$AL155*100,2),"") | AH155: =IF(AND(ISNUMBER($Q155),ISNUMBER($AL155),$AL155<>0),ROUND($Q155/$AL155*100,1),"") | AI155: =IF(ISNUMBER($S155),IF($S155<=1,"Yes","No"),"n/a") | AJ155: =IF(ISNUMBER($S155),ROUND(MAX(0,MIN(100,100-$S155*2.5-IF(ISNUMBER($T155),$T155,0)*0.12+IF($S155<=1,12,0))),0),"") | AK155: =IF(ISNUMBER($Q155),IF($Q155>=100,20,IF($Q155>=30,10,0)),0)+IF(ISNUMBER($R155),IF($R155>=100,20,0),0)+IF(ISNUMBER($P155),IF($P155>=150,20,IF($P155>=50,12,5)),0)+IF(ISNUMBER($S155),IF($S155<=1,15,0),0) | AL155: 355 | AN155: Secondary/approx; NOT verified on Amazon.ca | AO155: BLANK -> requires live Amazon.ca capture | AP155: Unverified commercial data
A156: Halo Sport | B156: Halo Sport Sparkling Electrolyte Water | Berry | 15-pack 355mL | C156: 1) Sparkling electrolyte / functional sparkling | D156: 355 mL can | E156: 15 | G156: =IF(AND(ISNUMBER($F156),ISNUMBER($E156),$E156<>0),$F156/$E156,"") | H156: =IF(AND(ISNUMBER($F156),ISNUMBER($AL156),ISNUMBER($E156),($AL156*$E156)<>0),$F156/($AL156*$E156)*100,"") | K156: =IF(AND(ISNUMBER($F156),ISNUMBER($J156)),$F156*(1-$J156),"") | N156: =IF(ISNUMBER($F156),($F156-IF(ISNUMBER($AM156),$AM156,0))*(1-IF(ISNUMBER($J156),$J156,0)),"") | O156: Berry | P156: 0 | Q156: 110 | R156: 40 | S156: 0 | T156: 5 | U156: Stevia | V156: Sparkling electrolytes, zero sugar, light hydration | AA156: Low | AB156: Small emerging sparkling-electrolyte entrant | AC156: Sparkling, lightly-mineralled hydration | AD156: Electrolytes in a fizzy, zero-sugar format. | AF156: =IF(AND(ISNUMBER($P156),ISNUMBER($AL156),$AL156<>0),ROUND($P156/$AL156*100,1),"") | AG156: =IF(AND(ISNUMBER($S156),ISNUMBER($AL156),$AL156<>0),ROUND($S156/$AL156*100,2),"") | AH156: =IF(AND(ISNUMBER($Q156),ISNUMBER($AL156),$AL156<>0),ROUND($Q156/$AL156*100,1),"") | AI156: =IF(ISNUMBER($S156),IF($S156<=1,"Yes","No"),"n/a") | AJ156: =IF(ISNUMBER($S156),ROUND(MAX(0,MIN(100,100-$S156*2.5-IF(ISNUMBER($T156),$T156,0)*0.12+IF($S156<=1,12,0))),0),"") | AK156: =IF(ISNUMBER($Q156),IF($Q156>=100,20,IF($Q156>=30,10,0)),0)+IF(ISNUMBER($R156),IF($R156>=100,20,0),0)+IF(ISNUMBER($P156),IF($P156>=150,20,IF($P156>=50,12,5)),0)+IF(ISNUMBER($S156),IF($S156<=1,15,0),0) | AL156: 355 | AN156: Secondary/approx; NOT verified on Amazon.ca | AO156: BLANK -> requires live Amazon.ca capture | AP156: Unverified commercial data
A157: Halo Sport | B157: Halo Sport Sparkling Electrolyte Water | Berry | 18-pack 355mL | C157: 1) Sparkling electrolyte / functional sparkling | D157: 355 mL can | E157: 18 | G157: =IF(AND(ISNUMBER($F157),ISNUMBER($E157),$E157<>0),$F157/$E157,"") | H157: =IF(AND(ISNUMBER($F157),ISNUMBER($AL157),ISNUMBER($E157),($AL157*$E157)<>0),$F157/($AL157*$E157)*100,"") | K157: =IF(AND(ISNUMBER($F157),ISNUMBER($J157)),$F157*(1-$J157),"") | N157: =IF(ISNUMBER($F157),($F157-IF(ISNUMBER($AM157),$AM157,0))*(1-IF(ISNUMBER($J157),$J157,0)),"") | O157: Berry | P157: 0 | Q157: 110 | R157: 40 | S157: 0 | T157: 5 | U157: Stevia | V157: Sparkling electrolytes, zero sugar, light hydration | AA157: Low | AB157: Small emerging sparkling-electrolyte entrant | AC157: Sparkling, lightly-mineralled hydration | AD157: Electrolytes in a fizzy, zero-sugar format. | AF157: =IF(AND(ISNUMBER($P157),ISNUMBER($AL157),$AL157<>0),ROUND($P157/$AL157*100,1),"") | AG157: =IF(AND(ISNUMBER($S157),ISNUMBER($AL157),$AL157<>0),ROUND($S157/$AL157*100,2),"") | AH157: =IF(AND(ISNUMBER($Q157),ISNUMBER($AL157),$AL157<>0),ROUND($Q157/$AL157*100,1),"") | AI157: =IF(ISNUMBER($S157),IF($S157<=1,"Yes","No"),"n/a") | AJ157: =IF(ISNUMBER($S157),ROUND(MAX(0,MIN(100,100-$S157*2.5-IF(ISNUMBER($T157),$T157,0)*0.12+IF($S157<=1,12,0))),0),"") | AK157: =IF(ISNUMBER($Q157),IF($Q157>=100,20,IF($Q157>=30,10,0)),0)+IF(ISNUMBER($R157),IF($R157>=100,20,0),0)+IF(ISNUMBER($P157),IF($P157>=150,20,IF($P157>=50,12,5)),0)+IF(ISNUMBER($S157),IF($S157<=1,15,0),0) | AL157: 355 | AN157: Secondary/approx; NOT verified on Amazon.ca | AO157: BLANK -> requires live Amazon.ca capture | AP157: Unverified commercial data
A158: Halo Sport | B158: Halo Sport Sparkling Electrolyte Water | Berry | 24-pack 355mL | C158: 1) Sparkling electrolyte / functional sparkling | D158: 355 mL can | E158: 24 | G158: =IF(AND(ISNUMBER($F158),ISNUMBER($E158),$E158<>0),$F158/$E158,"") | H158: =IF(AND(ISNUMBER($F158),ISNUMBER($AL158),ISNUMBER($E158),($AL158*$E158)<>0),$F158/($AL158*$E158)*100,"") | K158: =IF(AND(ISNUMBER($F158),ISNUMBER($J158)),$F158*(1-$J158),"") | N158: =IF(ISNUMBER($F158),($F158-IF(ISNUMBER($AM158),$AM158,0))*(1-IF(ISNUMBER($J158),$J158,0)),"") | O158: Berry | P158: 0 | Q158: 110 | R158: 40 | S158: 0 | T158: 5 | U158: Stevia | V158: Sparkling electrolytes, zero sugar, light hydration | AA158: Low | AB158: Small emerging sparkling-electrolyte entrant | AC158: Sparkling, lightly-mineralled hydration | AD158: Electrolytes in a fizzy, zero-sugar format. | AF158: =IF(AND(ISNUMBER($P158),ISNUMBER($AL158),$AL158<>0),ROUND($P158/$AL158*100,1),"") | AG158: =IF(AND(ISNUMBER($S158),ISNUMBER($AL158),$AL158<>0),ROUND($S158/$AL158*100,2),"") | AH158: =IF(AND(ISNUMBER($Q158),ISNUMBER($AL158),$AL158<>0),ROUND($Q158/$AL158*100,1),"") | AI158: =IF(ISNUMBER($S158),IF($S158<=1,"Yes","No"),"n/a") | AJ158: =IF(ISNUMBER($S158),ROUND(MAX(0,MIN(100,100-$S158*2.5-IF(ISNUMBER($T158),$T158,0)*0.12+IF($S158<=1,12,0))),0),"") | AK158: =IF(ISNUMBER($Q158),IF($Q158>=100,20,IF($Q158>=30,10,0)),0)+IF(ISNUMBER($R158),IF($R158>=100,20,0),0)+IF(ISNUMBER($P158),IF($P158>=150,20,IF($P158>=50,12,5)),0)+IF(ISNUMBER($S158),IF($S158<=1,15,0),0) | AL158: 355 | AN158: Secondary/approx; NOT verified on Amazon.ca | AO158: BLANK -> requires live Amazon.ca capture | AP158: Unverified commercial data
... A170: Halo Sport | B170: Halo Sport Sparkling Electrolyte Water | Grapefruit | 24-pack 355mL | C170: 1) Sparkling electrolyte / functional sparkling | D170: 355 mL can | E170: 24 | G170: =IF(AND(ISNUMBER($F170),ISNUMBER($E170),$E170<>0),$F170/$E170,"") | H170: =IF(AND(ISNUMBER($F170),ISNUMBER($AL170),ISNUMBER($E170),($AL170*$E170)<>0),$F170/($AL170*$E170)*100,"") | K170: =IF(AND(ISNUMBER($F170),ISNUMBER($J170)),$F170*(1-$J170),"") | N170: =IF(ISNUMBER($F170),($F170-IF(ISNUMBER($AM170),$AM170,0))*(1-IF(ISNUMBER($J170),$J170,0)),"") | O170: Grapefruit | P170: 0 | Q170: 110 | R170: 40 | S170: 0 | T170: 5 | U170: Stevia | V170: Sparkling electrolytes, zero sugar, light hydration | AA170: Low | AB170: Small emerging sparkling-electrolyte entrant | AC170: Sparkling, lightly-mineralled hydration | AD170: Electrolytes in a fizzy, zero-sugar format. | AF170: =IF(AND(ISNUMBER($P170),ISNUMBER($AL170),$AL170<>0),ROUND($P170/$AL170*100,1),"") | AG170: =IF(AND(ISNUMBER($S170),ISNUMBER($AL170),$AL170<>0),ROUND($S170/$AL170*100,2),"") | AH170: =IF(AND(ISNUMBER($Q170),ISNUMBER($AL170),$AL170<>0),ROUND($Q170/$AL170*100,1),"") | AI170: =IF(ISNUMBER($S170),IF($S170<=1,"Yes","No"),"n/a") | AJ170: =IF(ISNUMBER($S170),ROUND(MAX(0,MIN(100,100-$S170*2.5-IF(ISNUMBER($T170),$T170,0)*0.12+IF($S170<=1,12,0))),0),"") | AK170: =IF(ISNUMBER($Q170),IF($Q170>=100,20,IF($Q170>=30,10,0)),0)+IF(ISNUMBER($R170),IF($R170>=100,20,0),0)+IF(ISNUMBER($P170),IF($P170>=150,20,IF($P170>=50,12,5)),0)+IF(ISNUMBER($S170),IF($S170<=1,15,0),0) | AL170: 355 | AN170: Secondary/approx; NOT verified on Amazon.ca | AO170: BLANK -> requires live Amazon.ca capture | AP170: Unverified commercial data
A171: Gorgie | B171: Gorgie Energy Sparkling Water | Watermelon | single 355mL | C171: 1) Sparkling electrolyte / functional sparkling | D171: 355 mL can | E171: 1 | G171: =IF(AND(ISNUMBER($F171),ISNUMBER($E171),$E171<>0),$F171/$E171,"") | H171: =IF(AND(ISNUMBER($F171),ISNUMBER($AL171),ISNUMBER($E171),($AL171*$E171)<>0),$F171/($AL171*$E171)*100,"") | K171: =IF(AND(ISNUMBER($F171),ISNUMBER($J171)),$F171*(1-$J171),"") | N171: =IF(ISNUMBER($F171),($F171-IF(ISNUMBER($AM171),$AM171,0))*(1-IF(ISNUMBER($J171),$J171,0)),"") | O171: Watermelon | P171: 120 | Q171: 10 | R171: Not listed | S171: 0 | T171: 10 | U171: Stevia | V171: 120 mg natural caffeine, L-theanine, biotin, zero sugar | AA171: Low | AB171: New social-driven entrant; small footprint | AC171: A lighter, prettier caffeinated sparkling energy | AD171: Mid-dose caffeine with a clean, lifestyle aesthetic. | AF171: =IF(AND(ISNUMBER($P171),ISNUMBER($AL171),$AL171<>0),ROUND($P171/$AL171*100,1),"") | AG171: =IF(AND(ISNUMBER($S171),ISNUMBER($AL171),$AL171<>0),ROUND($S171/$AL171*100,2),"") | AH171: =IF(AND(ISNUMBER($Q171),ISNUMBER($AL171),$AL171<>0),ROUND($Q171/$AL171*100,1),"") | AI171: =IF(ISNUMBER($S171),IF($S171<=1,"Yes","No"),"n/a") | AJ171: =IF(ISNUMBER($S171),ROUND(MAX(0,MIN(100,100-$S171*2.5-IF(ISNUMBER($T171),$T171,0)*0.12+IF($S171<=1,12,0))),0),"") | AK171: =IF(ISNUMBER($Q171),IF($Q171>=100,20,IF($Q171>=30,10,0)),0)+IF(ISNUMBER($R171),IF($R171>=100,20,0),0)+IF(ISNUMBER($P171),IF($P171>=150,20,IF($P171>=50,12,5)),0)+IF(ISNUMBER($S171),IF($S171<=1,15,0),0) | AL171: 355 | AN171: Secondary/approx; NOT verified on Amazon.ca | AO171: BLANK -> requires live Amazon.ca capture | AP171: Unverified commercial data
A172: Gorgie | B172: Gorgie Energy Sparkling Water | Watermelon | 8-pack 355mL | C172: 1) Sparkling electrolyte / functional sparkling | D172: 355 mL can | E172: 8 | G172: =IF(AND(ISNUMBER($F172),ISNUMBER($E172),$E172<>0),$F172/$E172,"") | H172: =IF(AND(ISNUMBER($F172),ISNUMBER($AL172),ISNUMBER($E172),($AL172*$E172)<>0),$F172/($AL172*$E172)*100,"") | K172: =IF(AND(ISNUMBER($F172),ISNUMBER($J172)),$F172*(1-$J172),"") | N172: =IF(ISNUMBER($F172),($F172-IF(ISNUMBER($AM172),$AM172,0))*(1-IF(ISNUMBER($J172),$J172,0)),"") | O172: Watermelon | P172: 120 | Q172: 10 | R172: Not listed | S172: 0 | T172: 10 | U172: Stevia | V172: 120 mg natural caffeine, L-theanine, biotin, zero sugar | AA172: Low | AB172: New social-driven entrant; small footprint | AC172: A lighter, prettier caffeinated sparkling energy | AD172: Mid-dose caffeine with a clean, lifestyle aesthetic. | AF172: =IF(AND(ISNUMBER($P172),ISNUMBER($AL172),$AL172<>0),ROUND($P172/$AL172*100,1),"") | AG172: =IF(AND(ISNUMBER($S172),ISNUMBER($AL172),$AL172<>0),ROUND($S172/$AL172*100,2),"") | AH172: =IF(AND(ISNUMBER($Q172),ISNUMBER($AL172),$AL172<>0),ROUND($Q172/$AL172*100,1),"") | AI172: =IF(ISNUMBER($S172),IF($S172<=1,"Yes","No"),"n/a") | AJ172: =IF(ISNUMBER($S172),ROUND(MAX(0,MIN(100,100-$S172*2.5-IF(ISNUMBER($T172),$T172,0)*0.12+IF($S172<=1,12,0))),0),"") | AK172: =IF(ISNUMBER($Q172),IF($Q172>=100,20,IF($Q172>=30,10,0)),0)+IF(ISNUMBER($R172),IF($R172>=100,20,0),0)+IF(ISNUMBER($P172),IF($P172>=150,20,IF($P172>=50,12,5)),0)+IF(ISNUMBER($S172),IF($S172<=1,15,0),0) | AL172: 355 | AN172: Secondary/approx; NOT verified on Amazon.ca | AO172: BLANK -> requires live Amazon.ca capture | AP172: Unverified commercial data
A173: Gorgie | B173: Gorgie Energy Sparkling Water | Watermelon | 12-pack 355mL | C173: 1) Sparkling electrolyte / functional sparkling | D173: 355 mL can | E173: 12 | G173: =IF(AND(ISNUMBER($F173),ISNUMBER($E173),$E173<>0),$F173/$E173,"") | H173: =IF(AND(ISNUMBER($F173),ISNUMBER($AL173),ISNUMBER($E173),($AL173*$E173)<>0),$F173/($AL173*$E173)*100,"") | K173: =IF(AND(ISNUMBER($F173),ISNUMBER($J173)),$F173*(1-$J173),"") | N173: =IF(ISNUMBER($F173),($F173-IF(ISNUMBER($AM173),$AM173,0))*(1-IF(ISNUMBER($J173),$J173,0)),"") | O173: Watermelon | P173: 120 | Q173: 10 | R173: Not listed | S173: 0 | T173: 10 | U173: Stevia | V173: 120 mg natural caffeine, L-theanine, biotin, zero sugar | AA173: Low | AB173: New social-driven entrant; small footprint | AC173: A lighter, prettier caffeinated sparkling energy | AD173: Mid-dose caffeine with a clean, lifestyle aesthetic. | AF173: =IF(AND(ISNUMBER($P173),ISNUMBER($AL173),$AL173<>0),ROUND($P173/$AL173*100,1),"") | AG173: =IF(AND(ISNUMBER($S173),ISNUMBER($AL173),$AL173<>0),ROUND($S173/$AL173*100,2),"") | AH173: =IF(AND(ISNUMBER($Q173),ISNUMBER($AL173),$AL173<>0),ROUND($Q173/$AL173*100,1),"") | AI173: =IF(ISNUMBER($S173),IF($S173<=1,"Yes","No"),"n/a") | AJ173: =IF(ISNUMBER($S173),ROUND(MAX(0,MIN(100,100-$S173*2.5-IF(ISNUMBER($T173),$T173,0)*0.12+IF($S173<=1,12,0))),0),"") | AK173: =IF(ISNUMBER($Q173),IF($Q173>=100,20,IF($Q173>=30,10,0)),0)+IF(ISNUMBER($R173),IF($R173>=100,20,0),0)+IF(ISNUMBER($P173),IF($P173>=150,20,IF($P173>=50,12,5)),0)+IF(ISNUMBER($S173),IF($S173<=1,15,0),0) | AL173: 355 | AN173: Secondary/approx; NOT verified on Amazon.ca | AO173: BLANK -> requires live Amazon.ca capture | AP173: Unverified commercial data
A174: Gorgie | B174: Gorgie Energy Sparkling Water | Watermelon | 15-pack 355mL | C174: 1) Sparkling electrolyte / functional sparkling | D174: 355 mL can | E174: 15 | G174: =IF(AND(ISNUMBER($F174),ISNUMBER($E174),$E174<>0),$F174/$E174,"") | H174: =IF(AND(ISNUMBER($F174),ISNUMBER($AL174),ISNUMBER($E174),($AL174*$E174)<>0),$F174/($AL174*$E174)*100,"") | K174: =IF(AND(ISNUMBER($F174),ISNUMBER($J174)),$F174*(1-$J174),"") | N174: =IF(ISNUMBER($F174),($F174-IF(ISNUMBER($AM174),$AM174,0))*(1-IF(ISNUMBER($J174),$J174,0)),"") | O174: Watermelon | P174: 120 | Q174: 10 | R174: Not listed | S174: 0 | T174: 10 | U174: Stevia | V174: 120 mg natural caffeine, L-theanine, biotin, zero sugar | AA174: Low | AB174: New social-driven entrant; small footprint | AC174: A lighter, prettier caffeinated sparkling energy | AD174: Mid-dose caffeine with a clean, lifestyle aesthetic. | AF174: =IF(AND(ISNUMBER($P174),ISNUMBER($AL174),$AL174<>0),ROUND($P174/$AL174*100,1),"") | AG174: =IF(AND(ISNUMBER($S174),ISNUMBER($AL174),$AL174<>0),ROUND($S174/$AL174*100,2),"") | AH174: =IF(AND(ISNUMBER($Q174),ISNUMBER($AL174),$AL174<>0),ROUND($Q174/$AL174*100,1),"") | AI174: =IF(ISNUMBER($S174),IF($S174<=1,"Yes","No"),"n/a") | AJ174: =IF(ISNUMBER($S174),ROUND(MAX(0,MIN(100,100-$S174*2.5-IF(ISNUMBER($T174),$T174,0)*0.12+IF($S174<=1,12,0))),0),"") | AK174: =IF(ISNUMBER($Q174),IF($Q174>=100,20,IF($Q174>=30,10,0)),0)+IF(ISNUMBER($R174),IF($R174>=100,20,0),0)+IF(ISNUMBER($P174),IF($P174>=150,20,IF($P174>=50,12,5)),0)+IF(ISNUMBER($S174),IF($S174<=1,15,0),0) | AL174: 355 | AN174: Secondary/approx; NOT verified on Amazon.ca | AO174: BLANK -> requires live Amazon.ca capture | AP174: Unverified commercial data
A175: Gorgie | B175: Gorgie Energy Sparkling Water | Watermelon | 18-pack 355mL | C175: 1) Sparkling electrolyte / functional sparkling | D175: 355 mL can | E175: 18 | G175: =IF(AND(ISNUMBER($F175),ISNUMBER($E175),$E175<>0),$F175/$E175,"") | H175: =IF(AND(ISNUMBER($F175),ISNUMBER($AL175),ISNUMBER($E175),($AL175*$E175)<>0),$F175/($AL175*$E175)*100,"") | K175: =IF(AND(ISNUMBER($F175),ISNUMBER($J175)),$F175*(1-$J175),"") | N175: =IF(ISNUMBER($F175),($F175-IF(ISNUMBER($AM175),$AM175,0))*(1-IF(ISNUMBER($J175),$J175,0)),"") | O175: Watermelon | P175: 120 | Q175: 10 | R175: Not listed | S175: 0 | T175: 10 | U175: Stevia | V175: 120 mg natural caffeine, L-theanine, biotin, zero sugar | AA175: Low | AB175: New social-driven entrant; small footprint | AC175: A lighter, prettier caffeinated sparkling energy | AD175: Mid-dose caffeine with a clean, lifestyle aesthetic. | AF175: =IF(AND(ISNUMBER($P175),ISNUMBER($AL175),$AL175<>0),ROUND($P175/$AL175*100,1),"") | AG175: =IF(AND(ISNUMBER($S175),ISNUMBER($AL175),$AL175<>0),ROUND($S175/$AL175*100,2),"") | AH175: =IF(AND(ISNUMBER($Q175),ISNUMBER($AL175),$AL175<>0),ROUND($Q175/$AL175*100,1),"") | AI175: =IF(ISNUMBER($S175),IF($S175<=1,"Yes","No"),"n/a") | AJ175: =IF(ISNUMBER($S175),ROUND(MAX(0,MIN(100,100-$S175*2.5-IF(ISNUMBER($T175),$T175,0)*0.12+IF($S175<=1,12,0))),0),"") | AK175: =IF(ISNUMBER($Q175),IF($Q175>=100,20,IF($Q175>=30,10,0)),0)+IF(ISNUMBER($R175),IF($R175>=100,20,0),0)+IF(ISNUMBER($P175),IF($P175>=150,20,IF($P175>=50,12,5)),0)+IF(ISNUMBER($S175),IF($S175<=1,15,0),0) | AL175: 355 | AN175: Secondary/approx; NOT verified on Amazon.ca | AO175: BLANK -> requires live Amazon.ca capture | AP175: Unverified commercial data
