Workbook

Sheet README & Methodology
B2: Amazon.ca Beverage - Competitor Intelligence Master File
B3: Build date: 2026-06-13 | v3 Enterprise | 2921 SKUs from 124 product lines / 101 brands
B5: Table of Contents (click to jump)
B6: 1. README & Methodology | C6: Start here — honesty model, scoring, scope, this index.
B7: 2. Executive Dashboard | C7: KPIs, charts and the top key findings at a glance.
B8: 3. Strategic Insights | C8: Synthesized findings, flavour whitespace, positioning map, opportunity shortlist.
B9: 4. Data Dictionary | C9: Every field defined — meaning, source class, fill status.
B10: 5. M1 - Sparkling Electrolyte | C10: SKU-level master: sparkling electrolyte / functional sparkling.
B11: 6. M2 - Electrolyte RTD | C11: SKU-level master: electrolyte beverages (RTD).
B12: 7. M3 - Functional Beverage | C12: SKU-level master: functional beverages (still/sparkling).
B13: 8. M4 - Caffeine & Energy | C13: SKU-level master: caffeine & energy beverages.
B14: 9. M5 - Sparkling Water & Soda | C14: SKU-level master: sparkling water & soda.
B15: 10. Brand Roll-up | C15: Per-brand SKU counts, avg nutrition and scores.
B16: 11. Category Benchmarks | C16: Per-category averages, ranges and sugar-free counts.
B17: 12. Nutrition Scoreboard | C17: All lines ranked by Health Score with data bars.
... B26: 21. Sources | C26: Source classes and references behind the stable attributes.
B28: CRITICAL - READ FIRST
B29: Data-access limitation | C29: Generated with NO live access to Amazon (HTTP 403 on search, product, and brand pages). The file therefore contains NO live prices, Subscribe & Save terms, coupons, ratings, review counts, badges, ranks, or URLs. Those cells are intentionally BLANK and amber-highlighted - they are NOT fabricated.
B30: SKU model - HOW THE ~1000+ ROWS ARE BUILT | C30: The Master tabs are SKU-level. Because each flavour x pack-size is a separate ASIN on Amazon, every product LINE is exploded into individual SKU rows (line x flavour x pack). These are DERIVED / CANDIDATE SKUs to verify against live listings - NOT confirmed ASINs. Flavour lists are representative not exhaustive, and some specific flavour+pack combinations may not exist exactly as shown. The live catalogue cannot be enumerated without Amazon access; this expansion approximates its shape.
B31: What IS filled (and its confidence) | C31: Stable attributes - brand, SKU, format/size, typical pack, flavours, caffeine/sodium/potassium/sugar/calories, sweetener, claims, positioning, plus an honest velocity ESTIMATE - filled from manufacturer + secondary sources. Treat all as APPROXIMATE and verify on the live label. Nutrition is per single serving and varies by flavour.
B32: What is BLANK (capture live) | C32: Fields 6, 9-14, 23-26, 30 and helper H2. All amber. Filled by a live-capture pass (see 'Live-Capture Protocol' tab).
B33: Built-in automation | C33: Fields 7,8,11,14 are LIVE FORMULAS. Enter price (F), pack (E), S&S % as decimal (J, e.g. 0.15) and coupon value (H2); per-unit, per-100 mL, S&S price and stacked floor compute instantly and the red row-flag clears.
B34: NEW v2 - computed analytics | C34: Columns C1-C6 on every Master tab: Caffeine/100 mL, Sugar/100 mL, Sodium/100 mL, Sugar-Free flag, Health Score, Functional Score - all live formulas off the nutrition you can already see.
B35: Health Score (0-100) model | C35: =MAX(0, MIN(100, 100 - sugar*2.5 - calories*0.12 + 12 if sugar<=1)). Higher = lighter/cleaner. Transparent and editable; based on APPROXIMATE nutrition.
B36: Functional Score (0-100) model | C36: Sodium (>=100=20, >=30=10) + Potassium (>=100=20) + Caffeine (>=150=20, >=50=12, else 5) + Low-sugar bonus (<=1 g=15). Higher = more 'functional' payload. A heuristic, not a medical claim.
B37: Stacking model (field 14) | C37: Lowest Effective = (Price - Coupon) x (1 - S&S %). Assumes coupon + subscription stack on one order (usual Amazon behaviour); confirm per listing.
B38: Velocity estimate (field 27) | C38: Bands are ESTIMATES from brand prominence/category position because live review counts/BSR were not accessible. Re-derive from real #Ratings + BSR once captured. Never a unit count.
B39: Scope rules | C39: RTD only. Powders, drink-mix packets, tablets EXCLUDED (Liquid I.V., Nuun, LMNT, Cure powder, Cirkul). One PRIMARY category per product; overlaps noted.
B40: Cross-tab linkage | C40: Pricing & Promo and Subscription tabs are LIVE-LINKED to the Master tabs - fill a price once and those tabs update automatically.
B41: Tabs | C41: README, Executive Dashboard, Strategic Insights, Data Dictionary, 5 Master tabs, Brand Roll-up, Category Benchmarks, Nutrition Scoreboard, Pricing & Promo, Subscription Strategy, Why They Win, Velocity Estimate, Flavour Map, Live-Capture Protocol, QA & Integrity, Enrichment Log, Sources.
B42: Strategic Insights tab | C42: Synthesized 'so what' layer: top findings, a flavour-whitespace matrix (category x family), nutrition positioning by category, the sweetener-strategy mix, and a prioritized opportunity shortlist. Every figure is COMPUTED from the verified stable attributes — no live commercial data required.
B43: Integrity statement | C43: Nothing in the commercial columns is invented. Where a live figure could not be obtained it is blank and flagged, so the file survives a fact-check against the live listings.
B44: Automated integrity test | C44: 'nothing fabricated' is machine-enforced, not just promised: test_competitor_intel.py asserts every commercial cell is blank, every computed column is a formula, nutrition is in range, SKU counts reconcile across tabs, and all TOC links + Enrichment Log citations resolve. It runs automatically at the end of every build and the build fails if any check fails. Run it any time with: python3 test_competitor_intel.py

Sheet Executive Dashboard
B2: Executive Dashboard
B3: Amazon.ca RTD beverage landscape | 2026-06-13 | ESTIMATE/secondary data - see README
B5: 2921 | C5: 124 | D5: 101 | E5: 5 | F5: 13 | G5: =(COUNT('M1 - Sparkling Electrolyte'!F2:F249)+COUNT('M2 - Electrolyte RTD'!F2:F405)+COUNT('M3 - Functional Beverage'!F2:F556)+COUNT('M4 - Caffeine & Energy'!F2:F816)+COUNT('M5 - Sparkling Water & Soda'!F2:F900))/2921
B6: SKUs | C6: Product lines | D6: Brands | E6: Categories | F6: Avg sugar (g) | G6: Price capture %
B28: Key findings (full synthesis on the 'Strategic Insights' tab)
B29: • Field scope | C29: 124 product lines across 101 brands and 5 RTD categories (2921 SKU permutations). All nutrition attributes secondary-source verified (see Enrichment Log); commercial fields await live capture.
B30: • Zero-sugar is now the default, not the exception | C30: 61 of 124 lines (49%) are sugar-free (≤1 g). Most sugar-free category: Sparkling electrolyte / functional sparkling (89%); least: Functional beverage (still/sparkling (35%). 26 lines still carry ≥30 g sugar — a shrinking, vulnerable segment.
B31: • Natural-zero sweeteners are the live battleground | C31: 12 lines use natural-zero sweeteners (stevia/monk fruit) vs 29 pure-artificial-zero. Stevia/monk is the clean-label wedge brands use to undercut sucralose-based incumbents — the fastest-moving positioning lever in the set.
B32: • Energy caffeine has bifurcated | C32: 12 of 37 energy lines (32%) now dose ≥200 mg caffeine. The category is splitting into a high-dose performance tier (200-300 mg) and a mainstream 80-160 mg tier; the 160-200 mg middle is thin.
B45: Chart data (computed from stable attributes)
B46: Category | C46: # Products | D46: Avg sugar (g) | E46: Avg caffeine (mg)
B47: Sparkling electrolyte | C47: 248 | D47: 0.9 | E47: 38.8
B48: Electrolyte beverage ( | C48: 404 | D48: 9.5 | E48: 0
B49: Functional beverage (s | C49: 555 | D49: 6.5 | E49: 5.5
B50: Caffeine & energy beve | C50: 815 | D50: 19.1 | E50: 154.6
B51: Sparkling water & soda | C51: 899 | D51: 15.2 | E51: 10.8
B53: Sweetener class | C53: # Products
B54: Caloric only | C54: 41
B55: Non-caloric only | C55: 41
B56: None / unsweetened | C56: 23
B57: Blend (caloric + non-caloric) | C57: 16
B58: Other | C58: 3

Sheet Strategic Insights
B2: Strategic Insights & Opportunity Whitespace
B3: Synthesis of verified STABLE attributes | 2026-06-13 | every figure computed from the data set, not asserted
B5: A. Top strategic findings
B6: Field scope | C6: 124 product lines across 101 brands and 5 RTD categories (2921 SKU permutations). All nutrition attributes secondary-source verified (see Enrichment Log); commercial fields await live capture.
B7: Zero-sugar is now the default, not the exception | C7: 61 of 124 lines (49%) are sugar-free (≤1 g). Most sugar-free category: Sparkling electrolyte / functional sparkling (89%); least: Functional beverage (still/sparkling (35%). 26 lines still carry ≥30 g sugar — a shrinking, vulnerable segment.
B8: Natural-zero sweeteners are the live battleground | C8: 12 lines use natural-zero sweeteners (stevia/monk fruit) vs 29 pure-artificial-zero. Stevia/monk is the clean-label wedge brands use to undercut sucralose-based incumbents — the fastest-moving positioning lever in the set.
B9: Energy caffeine has bifurcated | C9: 12 of 37 energy lines (32%) now dose ≥200 mg caffeine. The category is splitting into a high-dose performance tier (200-300 mg) and a mainstream 80-160 mg tier; the 160-200 mg middle is thin.
B10: Flavour whitespace concentrated in a few families | C10: Least-served flavour families across the field: Cola/Root Beer (5 brands); Coconut (9 brands); Ginger (11 brands). These are the clearest line-extension gaps for a challenger brand (see Flavour Whitespace matrix below).
B11: Functional + electrolyte crossover is the structural growth vector | C11: Categories 1-3 (functional/electrolyte sparkling) skew sugar-free with added minerals/vitamins; they are where premium price and Subscribe & Save retention concentrate once live pricing is captured.
B13: B. Flavour whitespace — # distinct brands offering each family, by category (low = opportunity)
B14: Flavour family | C14: 1) | D14: 2) | E14: 3) | F14: 4) | G14: 5) | H14: All
B15: Cola/Root Beer | C15: 0 | D15: 0 | E15: 2 | F15: 3 | G15: 1 | H15: 5
B16: Citrus (Lem/Lime) | C16: 8 | D16: 5 | E16: 12 | F16: 11 | G16: 19 | H16: 53
B17: Orange/Mango | C17: 3 | D17: 6 | E17: 14 | F17: 12 | G17: 12 | H17: 47
B18: Berry/Rasp | C18: 7 | D18: 11 | E18: 18 | F18: 18 | G18: 13 | H18: 66
B19: Cherry | C19: 4 | D19: 4 | E19: 8 | F19: 2 | G19: 14 | H19: 32
B20: Grape | C20: 3 | D20: 5 | E20: 4 | F20: 2 | G20: 11 | H20: 24
B21: Watermelon | C21: 2 | D21: 6 | E21: 4 | F21: 7 | G21: 5 | H21: 23
B22: Peach | C22: 1 | D22: 5 | E22: 5 | F22: 9 | G22: 4 | H22: 24
B23: Tropical/Pineapple | C23: 2 | D23: 5 | E23: 8 | F23: 11 | G23: 6 | H23: 31
B24: Grapefruit | C24: 3 | D24: 0 | E24: 2 | F24: 1 | G24: 8 | H24: 14
B25: Coconut | C25: 2 | D25: 2 | E25: 4 | F25: 0 | G25: 1 | H25: 9
B26: Ginger | C26: 1 | D26: 0 | E26: 9 | F26: 1 | G26: 1 | H26: 11
... B28: Original/Plain | C28: 2 | D28: 4 | E28: 4 | F28: 8 | G28: 21 | H28: 38
B29: Opportunity heat — red = 0 brands (clear whitespace in that category) · amber = 1-2 brands (thinly served).
B31: C. Nutrition positioning by category
B32: Category | C32: Lines | D32: % sugar-free | E32: Median sugar (g) | F32: Caffeine range (mg) | G32: Positioning read
B33: Sparkling electrolyte / functional sparkling | C33: 9 | D33: 89% | E33: 0 | F33: 0-120 | G33: Premium clean tier; sugar-free + minerals is table stakes.
B34: Electrolyte beverage (RTD | C34: 21 | D34: 38% | E34: 3 | F34: 0 | G34: Performance hydration; sodium/potassium load is the differentiator.
B35: Functional beverage (still/sparkling | C35: 20 | D35: 35% | E35: 5.5 | F35: 0-55 | G35: Benefit-led (gut/adaptogen/vitamin); sugar varies widely — clean-label gap exists.
B36: Caffeine & energy beverage | C36: 37 | D36: 43% | E36: 14 | F36: 18-300 | G36: Caffeine-defined; dose tier + sweetener choice decide the shelf.
B37: Sparkling water & soda | C37: 37 | D37: 59% | E37: 0 | F37: 0-69 | G37: Split between zero-everything seltzer and full-sugar legacy soda.
B39: D. Sweetener strategy mix (count of lines)
B40: Sweetener strategy | C40: # lines | D40: % of field
B41: Caloric (sugar) | C41: 41 | D41: 33%
B42: Zero (artificial) | C42: 29 | D42: 23%
B43: Unsweetened | C43: 23 | D43: 19%
B44: Caloric + sweetener blend | C44: 16 | D44: 13%
B45: Zero (natural: stevia/monk) | C45: 7 | D45: 6%
B46: Zero (natural + artificial) | C46: 5 | D46: 4%
...

Sheet Data Dictionary
A1: Field # | B1: Field name | C1: Definition / how to read it | D1: Source class | E1: Status in this file
A2: 1 | B2: Brand | C2: Manufacturer/brand name. | D2: Stable | E2: Filled (approx)
A3: 2 | B3: Product Line / SKU Name | C3: Exact product/line name; confirm spelling. | D3: Stable | E3: Filled (approx)
A4: 3 | B4: Category | C4: One of five scope categories (primary). | D4: Assigned | E4: Filled
A5: 4 | B5: Format & Size | C5: Container type + single-unit size. | D5: Stable | E5: Filled (approx)
A6: 5 | B6: Pack Count | C6: Units per multipack (typical). | D6: Stable | E6: Filled (typical)
A7: 6 | B7: One-Time Price (CAD) | C7: List one-time price. | D7: LIVE Amazon.ca | E7: BLANK - capture
A8: 7 | B8: Price / Unit (CAD) | C8: =Price/Pack. | D8: Calculated | E8: Auto
A9: 8 | B9: Price / 100 mL (CAD) | C9: =Price/(UnitVol*Pack)*100. | D9: Calculated | E9: Auto
A10: 9 | B10: S&S Offered (Y/N) | C10: Subscribe & Save offered? | D10: LIVE Amazon.ca | E10: BLANK - capture
A11: 10 | B11: S&S Discount % | C11: Enter decimal (0.15=15%). | D11: LIVE Amazon.ca | E11: BLANK - capture
A12: 11 | B12: S&S Price After Discount | C12: =Price*(1-S&S%). | D12: Calculated | E12: Auto
A13: 12 | B13: Coupon (Y/N + value) | C13: Clippable coupon + value. | D13: LIVE Amazon.ca | E13: BLANK - capture
A14: 13 | B14: Promotion Text | C14: Multi-buy/lightning/Prime/bundle. | D14: LIVE Amazon.ca | E14: BLANK - capture
A15: 14 | B15: Lowest Effective Price | C15: =(Price-Coupon)*(1-S&S%). | D15: Calculated | E15: Auto
A16: 15 | B16: All Flavours | C16: Flavours in/around listing. | D16: Stable | E16: Filled (approx)
A17: 16 | B17: Caffeine / Serving (mg) | C17: Per serving; 'Not listed' if none. | D17: Stable | E17: Filled (approx)
A18: 17 | B18: Sodium / Serving (mg) | C18: Per serving. | D18: Stable | E18: Filled (approx)
A19: 18 | B19: Potassium / Serving (mg) | C19: Per serving; blank if not listed. | D19: Stable | E19: Filled (approx)
A20: 19 | B20: Sugar / Serving (g) | C20: Per serving. | D20: Stable | E20: Filled (approx)
A21: 20 | B21: Calories / Serving | C21: Per serving. | D21: Stable | E21: Filled (approx)
A22: 21 | B22: Sweetener Type | C22: Caloric/non-caloric sweetener(s). | D22: Stable | E22: Filled (approx)
A23: 22 | B23: Key Functional Claims | C23: Headline benefit claims. | D23: Stable | E23: Filled (approx)
A24: 23 | B24: Star Rating | C24: Average stars. | D24: LIVE Amazon.ca | E24: BLANK - capture
A25: 24 | B25: Number of Ratings | C25: Count of ratings. | D25: LIVE Amazon.ca | E25: BLANK - capture
A26: 25 | B26: Amazon Badge | C26: Choice / Best Seller / Overall Pick. | D26: LIVE Amazon.ca | E26: BLANK - capture
A27: 26 | B27: Bestseller Rank | C27: BSR if shown. | D27: LIVE Amazon.ca | E27: BLANK - capture
... A43: P3 | B43: Row Flag | C43: Flags unverified rows. | D43: Meta | E43: Filled

Sheet M1 - Sparkling Electrolyte
A1: 1. Brand | B1: 2. Product Line / SKU Name | C1: 3. Category | D1: 4. Format & Size | E1: 5. Pack Count | F1: 6. One-Time Price (CAD) | G1: 7. Price / Unit (CAD) | H1: 8. Price / 100 mL (CAD) | I1: 9. S&S Offered (Y/N) | J1: 10. S&S Discount % | K1: 11. S&S Price After Disc. | L1: 12. Coupon on Listing (Y/N + value) | M1: 13. Promotion Text | N1: 14. Lowest Effective Price (stacked) | O1: 15. All Flavours in Listing | P1: 16. Caffeine / Serving (mg) | Q1: 17. Sodium / Serving (mg) | R1: 18. Potassium / Serving (mg) | S1: 19. Sugar / Serving (g) | T1: 20. Calories / Serving | U1: 21. Sweetener Type | V1: 22. Key Functional Claims | W1: 23. Star Rating | X1: 24. Number of Ratings | Y1: 25. Amazon Badge | Z1: 26. Bestseller Rank in Category | AA1: 27a. Est. Weekly Velocity (band) | AB1: 27b. Velocity Signal Used | AC1: 28. Biggest Selling Message | AD1: 29. Why a Shopper Chooses This | AE1: 30. Direct Product URL | AF1: C1. Caffeine /100 mL (mg) | AG1: C2. Sugar /100 mL (g) | AH1: C3. Sodium /100 mL (mg) | AI1: C4. Sugar-Free? (<=1 g) | AJ1: C5. Health Score (0-100) | AK1: C6. Functional Score (0-100) | AL1: H1. Unit Vol (mL) [calc helper] | AM1: H2. Coupon Value (CAD) [calc helper] | AN1: P1. Attribute Provenance | AO1: P2. Commercial-Field Status | AP1: P3. Row Flag
A2: Sparkling Ice | B2: Sparkling Ice (+ Antioxidants & Vitamins) | Black Raspberry | single 503mL | C2: 1) Sparkling electrolyte / functional sparkling | D2: 503 mL bottle | E2: 1 | G2: =IF(AND(ISNUMBER($F2),ISNUMBER($E2),$E2<>0),$F2/$E2,"") | H2: =IF(AND(ISNUMBER($F2),ISNUMBER($AL2),ISNUMBER($E2),($AL2*$E2)<>0),$F2/($AL2*$E2)*100,"") | K2: =IF(AND(ISNUMBER($F2),ISNUMBER($J2)),$F2*(1-$J2),"") | N2: =IF(ISNUMBER($F2),($F2-IF(ISNUMBER($AM2),$AM2,0))*(1-IF(ISNUMBER($J2),$J2,0)),"") | O2: Black Raspberry | P2: 0 | Q2: 0 | R2: 30 | S2: 0 | T2: 5 | U2: Sucralose | V2: Zero sugar, vitamins A/D/B, antioxidants (green tea), bold flavour | AA2: High | AB2: Mass-market functional sparkling; strong shelf share | AC2: Bold zero-sugar sparkling with added vitamins | AD2: Big flavour and added vitamins at zero sugar. | AF2: =IF(AND(ISNUMBER($P2),ISNUMBER($AL2),$AL2<>0),ROUND($P2/$AL2*100,1),"") | AG2: =IF(AND(ISNUMBER($S2),ISNUMBER($AL2),$AL2<>0),ROUND($S2/$AL2*100,2),"") | AH2: =IF(AND(ISNUMBER($Q2),ISNUMBER($AL2),$AL2<>0),ROUND($Q2/$AL2*100,1),"") | AI2: =IF(ISNUMBER($S2),IF($S2<=1,"Yes","No"),"n/a") | AJ2: =IF(ISNUMBER($S2),ROUND(MAX(0,MIN(100,100-$S2*2.5-IF(ISNUMBER($T2),$T2,0)*0.12+IF($S2<=1,12,0))),0),"") | AK2: =IF(ISNUMBER($Q2),IF($Q2>=100,20,IF($Q2>=30,10,0)),0)+IF(ISNUMBER($R2),IF($R2>=100,20,0),0)+IF(ISNUMBER($P2),IF($P2>=150,20,IF($P2>=50,12,5)),0)+IF(ISNUMBER($S2),IF($S2<=1,15,0),0) | AL2: 503 | AN2: Secondary/approx; NOT verified on Amazon.ca | AO2: BLANK -> requires live Amazon.ca capture | AP2: Unverified commercial data
A3: Sparkling Ice | B3: Sparkling Ice (+ Antioxidants & Vitamins) | Black Raspberry | 8-pack 503mL | C3: 1) Sparkling electrolyte / functional sparkling | D3: 503 mL bottle | E3: 8 | G3: =IF(AND(ISNUMBER($F3),ISNUMBER($E3),$E3<>0),$F3/$E3,"") | H3: =IF(AND(ISNUMBER($F3),ISNUMBER($AL3),ISNUMBER($E3),($AL3*$E3)<>0),$F3/($AL3*$E3)*100,"") | K3: =IF(AND(ISNUMBER($F3),ISNUMBER($J3)),$F3*(1-$J3),"") | N3: =IF(ISNUMBER($F3),($F3-IF(ISNUMBER($AM3),$AM3,0))*(1-IF(ISNUMBER($J3),$J3,0)),"") | O3: Black Raspberry | P3: 0 | Q3: 0 | R3: 30 | S3: 0 | T3: 5 | U3: Sucralose | V3: Zero sugar, vitamins A/D/B, antioxidants (green tea), bold flavour | AA3: High | AB3: Mass-market functional sparkling; strong shelf share | AC3: Bold zero-sugar sparkling with added vitamins | AD3: Big flavour and added vitamins at zero sugar. | AF3: =IF(AND(ISNUMBER($P3),ISNUMBER($AL3),$AL3<>0),ROUND($P3/$AL3*100,1),"") | AG3: =IF(AND(ISNUMBER($S3),ISNUMBER($AL3),$AL3<>0),ROUND($S3/$AL3*100,2),"") | AH3: =IF(AND(ISNUMBER($Q3),ISNUMBER($AL3),$AL3<>0),ROUND($Q3/$AL3*100,1),"") | AI3: =IF(ISNUMBER($S3),IF($S3<=1,"Yes","No"),"n/a") | AJ3: =IF(ISNUMBER($S3),ROUND(MAX(0,MIN(100,100-$S3*2.5-IF(ISNUMBER($T3),$T3,0)*0.12+IF($S3<=1,12,0))),0),"") | AK3: =IF(ISNUMBER($Q3),IF($Q3>=100,20,IF($Q3>=30,10,0)),0)+IF(ISNUMBER($R3),IF($R3>=100,20,0),0)+IF(ISNUMBER($P3),IF($P3>=150,20,IF($P3>=50,12,5)),0)+IF(ISNUMBER($S3),IF($S3<=1,15,0),0) | AL3: 503 | AN3: Secondary/approx; NOT verified on Amazon.ca | AO3: BLANK -> requires live Amazon.ca capture | AP3: Unverified commercial data
A4: Sparkling Ice | B4: Sparkling Ice (+ Antioxidants & Vitamins) | Black Raspberry | 12-pack 503mL | C4: 1) Sparkling electrolyte / functional sparkling | D4: 503 mL bottle | E4: 12 | G4: =IF(AND(ISNUMBER($F4),ISNUMBER($E4),$E4<>0),$F4/$E4,"") | H4: =IF(AND(ISNUMBER($F4),ISNUMBER($AL4),ISNUMBER($E4),($AL4*$E4)<>0),$F4/($AL4*$E4)*100,"") | K4: =IF(AND(ISNUMBER($F4),ISNUMBER($J4)),$F4*(1-$J4),"") | N4: =IF(ISNUMBER($F4),($F4-IF(ISNUMBER($AM4),$AM4,0))*(1-IF(ISNUMBER($J4),$J4,0)),"") | O4: Black Raspberry | P4: 0 | Q4: 0 | R4: 30 | S4: 0 | T4: 5 | U4: Sucralose | V4: Zero sugar, vitamins A/D/B, antioxidants (green tea), bold flavour | AA4: High | AB4: Mass-market functional sparkling; strong shelf share | AC4: Bold zero-sugar sparkling with added vitamins | AD4: Big flavour and added vitamins at zero sugar. | AF4: =IF(AND(ISNUMBER($P4),ISNUMBER($AL4),$AL4<>0),ROUND($P4/$AL4*100,1),"") | AG4: =IF(AND(ISNUMBER($S4),ISNUMBER($AL4),$AL4<>0),ROUND($S4/$AL4*100,2),"") | AH4: =IF(AND(ISNUMBER($Q4),ISNUMBER($AL4),$AL4<>0),ROUND($Q4/$AL4*100,1),"") | AI4: =IF(ISNUMBER($S4),IF($S4<=1,"Yes","No"),"n/a") | AJ4: =IF(ISNUMBER($S4),ROUND(MAX(0,MIN(100,100-$S4*2.5-IF(ISNUMBER($T4),$T4,0)*0.12+IF($S4<=1,12,0))),0),"") | AK4: =IF(ISNUMBER($Q4),IF($Q4>=100,20,IF($Q4>=30,10,0)),0)+IF(ISNUMBER($R4),IF($R4>=100,20,0),0)+IF(ISNUMBER($P4),IF($P4>=150,20,IF($P4>=50,12,5)),0)+IF(ISNUMBER($S4),IF($S4<=1,15,0),0) | AL4: 503 | AN4: Secondary/approx; NOT verified on Amazon.ca | AO4: BLANK -> requires live Amazon.ca capture | AP4: Unverified commercial data
A5: Sparkling Ice | B5: Sparkling Ice (+ Antioxidants & Vitamins) | Black Raspberry | 18-pack 503mL | C5: 1) Sparkling electrolyte / functional sparkling | D5: 503 mL bottle | E5: 18 | G5: =IF(AND(ISNUMBER($F5),ISNUMBER($E5),$E5<>0),$F5/$E5,"") | H5: =IF(AND(ISNUMBER($F5),ISNUMBER($AL5),ISNUMBER($E5),($AL5*$E5)<>0),$F5/($AL5*$E5)*100,"") | K5: =IF(AND(ISNUMBER($F5),ISNUMBER($J5)),$F5*(1-$J5),"") | N5: =IF(ISNUMBER($F5),($F5-IF(ISNUMBER($AM5),$AM5,0))*(1-IF(ISNUMBER($J5),$J5,0)),"") | O5: Black Raspberry | P5: 0 | Q5: 0 | R5: 30 | S5: 0 | T5: 5 | U5: Sucralose | V5: Zero sugar, vitamins A/D/B, antioxidants (green tea), bold flavour | AA5: High | AB5: Mass-market functional sparkling; strong shelf share | AC5: Bold zero-sugar sparkling with added vitamins | AD5: Big flavour and added vitamins at zero sugar. | AF5: =IF(AND(ISNUMBER($P5),ISNUMBER($AL5),$AL5<>0),ROUND($P5/$AL5*100,1),"") | AG5: =IF(AND(ISNUMBER($S5),ISNUMBER($AL5),$AL5<>0),ROUND($S5/$AL5*100,2),"") | AH5: =IF(AND(ISNUMBER($Q5),ISNUMBER($AL5),$AL5<>0),ROUND($Q5/$AL5*100,1),"") | AI5: =IF(ISNUMBER($S5),IF($S5<=1,"Yes","No"),"n/a") | AJ5: =IF(ISNUMBER($S5),ROUND(MAX(0,MIN(100,100-$S5*2.5-IF(ISNUMBER($T5),$T5,0)*0.12+IF($S5<=1,12,0))),0),"") | AK5: =IF(ISNUMBER($Q5),IF($Q5>=100,20,IF($Q5>=30,10,0)),0)+IF(ISNUMBER($R5),IF($R5>=100,20,0),0)+IF(ISNUMBER($P5),IF($P5>=150,20,IF($P5>=50,12,5)),0)+IF(ISNUMBER($S5),IF($S5<=1,15,0),0) | AL5: 503 | AN5: Secondary/approx; NOT verified on Amazon.ca | AO5: BLANK -> requires live Amazon.ca capture | AP5: Unverified commercial data
A6: Sparkling Ice | B6: Sparkling Ice (+ Antioxidants & Vitamins) | Black Raspberry | 24-pack 503mL | C6: 1) Sparkling electrolyte / functional sparkling | D6: 503 mL bottle | E6: 24 | G6: =IF(AND(ISNUMBER($F6),ISNUMBER($E6),$E6<>0),$F6/$E6,"") | H6: =IF(AND(ISNUMBER($F6),ISNUMBER($AL6),ISNUMBER($E6),($AL6*$E6)<>0),$F6/($AL6*$E6)*100,"") | K6: =IF(AND(ISNUMBER($F6),ISNUMBER($J6)),$F6*(1-$J6),"") | N6: =IF(ISNUMBER($F6),($F6-IF(ISNUMBER($AM6),$AM6,0))*(1-IF(ISNUMBER($J6),$J6,0)),"") | O6: Black Raspberry | P6: 0 | Q6: 0 | R6: 30 | S6: 0 | T6: 5 | U6: Sucralose | V6: Zero sugar, vitamins A/D/B, antioxidants (green tea), bold flavour | AA6: High | AB6: Mass-market functional sparkling; strong shelf share | AC6: Bold zero-sugar sparkling with added vitamins | AD6: Big flavour and added vitamins at zero sugar. | AF6: =IF(AND(ISNUMBER($P6),ISNUMBER($AL6),$AL6<>0),ROUND($P6/$AL6*100,1),"") | AG6: =IF(AND(ISNUMBER($S6),ISNUMBER($AL6),$AL6<>0),ROUND($S6/$AL6*100,2),"") | AH6: =IF(AND(ISNUMBER($Q6),ISNUMBER($AL6),$AL6<>0),ROUND($Q6/$AL6*100,1),"") | AI6: =IF(ISNUMBER($S6),IF($S6<=1,"Yes","No"),"n/a") | AJ6: =IF(ISNUMBER($S6),ROUND(MAX(0,MIN(100,100-$S6*2.5-IF(ISNUMBER($T6),$T6,0)*0.12+IF($S6<=1,12,0))),0),"") | AK6: =IF(ISNUMBER($Q6),IF($Q6>=100,20,IF($Q6>=30,10,0)),0)+IF(ISNUMBER($R6),IF($R6>=100,20,0),0)+IF(ISNUMBER($P6),IF($P6>=150,20,IF($P6>=50,12,5)),0)+IF(ISNUMBER($S6),IF($S6<=1,15,0),0) | AL6: 503 | AN6: Secondary/approx; NOT verified on Amazon.ca | AO6: BLANK -> requires live Amazon.ca capture | AP6: Unverified commercial data
A7: Sparkling Ice | B7: Sparkling Ice (+ Antioxidants & Vitamins) | Cherry Limeade | single 503mL | C7: 1) Sparkling electrolyte / functional sparkling | D7: 503 mL bottle | E7: 1 | G7: =IF(AND(ISNUMBER($F7),ISNUMBER($E7),$E7<>0),$F7/$E7,"") | H7: =IF(AND(ISNUMBER($F7),ISNUMBER($AL7),ISNUMBER($E7),($AL7*$E7)<>0),$F7/($AL7*$E7)*100,"") | K7: =IF(AND(ISNUMBER($F7),ISNUMBER($J7)),$F7*(1-$J7),"") | N7: =IF(ISNUMBER($F7),($F7-IF(ISNUMBER($AM7),$AM7,0))*(1-IF(ISNUMBER($J7),$J7,0)),"") | O7: Cherry Limeade | P7: 0 | Q7: 0 | R7: 30 | S7: 0 | T7: 5 | U7: Sucralose | V7: Zero sugar, vitamins A/D/B, antioxidants (green tea), bold flavour | AA7: High | AB7: Mass-market functional sparkling; strong shelf share | AC7: Bold zero-sugar sparkling with added vitamins | AD7: Big flavour and added vitamins at zero sugar. | AF7: =IF(AND(ISNUMBER($P7),ISNUMBER($AL7),$AL7<>0),ROUND($P7/$AL7*100,1),"") | AG7: =IF(AND(ISNUMBER($S7),ISNUMBER($AL7),$AL7<>0),ROUND($S7/$AL7*100,2),"") | AH7: =IF(AND(ISNUMBER($Q7),ISNUMBER($AL7),$AL7<>0),ROUND($Q7/$AL7*100,1),"") | AI7: =IF(ISNUMBER($S7),IF($S7<=1,"Yes","No"),"n/a") | AJ7: =IF(ISNUMBER($S7),ROUND(MAX(0,MIN(100,100-$S7*2.5-IF(ISNUMBER($T7),$T7,0)*0.12+IF($S7<=1,12,0))),0),"") | AK7: =IF(ISNUMBER($Q7),IF($Q7>=100,20,IF($Q7>=30,10,0)),0)+IF(ISNUMBER($R7),IF($R7>=100,20,0),0)+IF(ISNUMBER($P7),IF($P7>=150,20,IF($P7>=50,12,5)),0)+IF(ISNUMBER($S7),IF($S7<=1,15,0),0) | AL7: 503 | AN7: Secondary/approx; NOT verified on Amazon.ca | AO7: BLANK -> requires live Amazon.ca capture | AP7: Unverified commercial data
A8: Sparkling Ice | B8: Sparkling Ice (+ Antioxidants & Vitamins) | Cherry Limeade | 8-pack 503mL | C8: 1) Sparkling electrolyte / functional sparkling | D8: 503 mL bottle | E8: 8 | G8: =IF(AND(ISNUMBER($F8),ISNUMBER($E8),$E8<>0),$F8/$E8,"") | H8: =IF(AND(ISNUMBER($F8),ISNUMBER($AL8),ISNUMBER($E8),($AL8*$E8)<>0),$F8/($AL8*$E8)*100,"") | K8: =IF(AND(ISNUMBER($F8),ISNUMBER($J8)),$F8*(1-$J8),"") | N8: =IF(ISNUMBER($F8),($F8-IF(ISNUMBER($AM8),$AM8,0))*(1-IF(ISNUMBER($J8),$J8,0)),"") | O8: Cherry Limeade | P8: 0 | Q8: 0 | R8: 30 | S8: 0 | T8: 5 | U8: Sucralose | V8: Zero sugar, vitamins A/D/B, antioxidants (green tea), bold flavour | AA8: High | AB8: Mass-market functional sparkling; strong shelf share | AC8: Bold zero-sugar sparkling with added vitamins | AD8: Big flavour and added vitamins at zero sugar. | AF8: =IF(AND(ISNUMBER($P8),ISNUMBER($AL8),$AL8<>0),ROUND($P8/$AL8*100,1),"") | AG8: =IF(AND(ISNUMBER($S8),ISNUMBER($AL8),$AL8<>0),ROUND($S8/$AL8*100,2),"") | AH8: =IF(AND(ISNUMBER($Q8),ISNUMBER($AL8),$AL8<>0),ROUND($Q8/$AL8*100,1),"") | AI8: =IF(ISNUMBER($S8),IF($S8<=1,"Yes","No"),"n/a") | AJ8: =IF(ISNUMBER($S8),ROUND(MAX(0,MIN(100,100-$S8*2.5-IF(ISNUMBER($T8),$T8,0)*0.12+IF($S8<=1,12,0))),0),"") | AK8: =IF(ISNUMBER($Q8),IF($Q8>=100,20,IF($Q8>=30,10,0)),0)+IF(ISNUMBER($R8),IF($R8>=100,20,0),0)+IF(ISNUMBER($P8),IF($P8>=150,20,IF($P8>=50,12,5)),0)+IF(ISNUMBER($S8),IF($S8<=1,15,0),0) | AL8: 503 | AN8: Secondary/approx; NOT verified on Amazon.ca | AO8: BLANK -> requires live Amazon.ca capture | AP8: Unverified commercial data
A9: Sparkling Ice | B9: Sparkling Ice (+ Antioxidants & Vitamins) | Cherry Limeade | 12-pack 503mL | C9: 1) Sparkling electrolyte / functional sparkling | D9: 503 mL bottle | E9: 12 | G9: =IF(AND(ISNUMBER($F9),ISNUMBER($E9),$E9<>0),$F9/$E9,"") | H9: =IF(AND(ISNUMBER($F9),ISNUMBER($AL9),ISNUMBER($E9),($AL9*$E9)<>0),$F9/($AL9*$E9)*100,"") | K9: =IF(AND(ISNUMBER($F9),ISNUMBER($J9)),$F9*(1-$J9),"") | N9: =IF(ISNUMBER($F9),($F9-IF(ISNUMBER($AM9),$AM9,0))*(1-IF(ISNUMBER($J9),$J9,0)),"") | O9: Cherry Limeade | P9: 0 | Q9: 0 | R9: 30 | S9: 0 | T9: 5 | U9: Sucralose | V9: Zero sugar, vitamins A/D/B, antioxidants (green tea), bold flavour | AA9: High | AB9: Mass-market functional sparkling; strong shelf share | AC9: Bold zero-sugar sparkling with added vitamins | AD9: Big flavour and added vitamins at zero sugar. | AF9: =IF(AND(ISNUMBER($P9),ISNUMBER($AL9),$AL9<>0),ROUND($P9/$AL9*100,1),"") | AG9: =IF(AND(ISNUMBER($S9),ISNUMBER($AL9),$AL9<>0),ROUND($S9/$AL9*100,2),"") | AH9: =IF(AND(ISNUMBER($Q9),ISNUMBER($AL9),$AL9<>0),ROUND($Q9/$AL9*100,1),"") | AI9: =IF(ISNUMBER($S9),IF($S9<=1,"Yes","No"),"n/a") | AJ9: =IF(ISNUMBER($S9),ROUND(MAX(0,MIN(100,100-$S9*2.5-IF(ISNUMBER($T9),$T9,0)*0.12+IF($S9<=1,12,0))),0),"") | AK9: =IF(ISNUMBER($Q9),IF($Q9>=100,20,IF($Q9>=30,10,0)),0)+IF(ISNUMBER($R9),IF($R9>=100,20,0),0)+IF(ISNUMBER($P9),IF($P9>=150,20,IF($P9>=50,12,5)),0)+IF(ISNUMBER($S9),IF($S9<=1,15,0),0) | AL9: 503 | AN9: Secondary/approx; NOT verified on Amazon.ca | AO9: BLANK -> requires live Amazon.ca capture | AP9: Unverified commercial data
A10: Sparkling Ice | B10: Sparkling Ice (+ Antioxidants & Vitamins) | Cherry Limeade | 18-pack 503mL | C10: 1) Sparkling electrolyte / functional sparkling | D10: 503 mL bottle | E10: 18 | G10: =IF(AND(ISNUMBER($F10),ISNUMBER($E10),$E10<>0),$F10/$E10,"") | H10: =IF(AND(ISNUMBER($F10),ISNUMBER($AL10),ISNUMBER($E10),($AL10*$E10)<>0),$F10/($AL10*$E10)*100,"") | K10: =IF(AND(ISNUMBER($F10),ISNUMBER($J10)),$F10*(1-$J10),"") | N10: =IF(ISNUMBER($F10),($F10-IF(ISNUMBER($AM10),$AM10,0))*(1-IF(ISNUMBER($J10),$J10,0)),"") | O10: Cherry Limeade | P10: 0 | Q10: 0 | R10: 30 | S10: 0 | T10: 5 | U10: Sucralose | V10: Zero sugar, vitamins A/D/B, antioxidants (green tea), bold flavour | AA10: High | AB10: Mass-market functional sparkling; strong shelf share | AC10: Bold zero-sugar sparkling with added vitamins | AD10: Big flavour and added vitamins at zero sugar. | AF10: =IF(AND(ISNUMBER($P10),ISNUMBER($AL10),$AL10<>0),ROUND($P10/$AL10*100,1),"") | AG10: =IF(AND(ISNUMBER($S10),ISNUMBER($AL10),$AL10<>0),ROUND($S10/$AL10*100,2),"") | AH10: =IF(AND(ISNUMBER($Q10),ISNUMBER($AL10),$AL10<>0),ROUND($Q10/$AL10*100,1),"") | AI10: =IF(ISNUMBER($S10),IF($S10<=1,"Yes","No"),"n/a") | AJ10: =IF(ISNUMBER($S10),ROUND(MAX(0,MIN(100,100-$S10*2.5-IF(ISNUMBER($T10),$T10,0)*0.12+IF($S10<=1,12,0))),0),"") | AK10: =IF(ISNUMBER($Q10),IF($Q10>=100,20,IF($Q10>=30,10,0)),0)+IF(ISNUMBER($R10),IF($R10>=100,20,0),0)+IF(ISNUMBER($P10),IF($P10>=150,20,IF($P10>=50,12,5)),0)+IF(ISNUMBER($S10),IF($S10<=1,15,0),0) | AL10: 503 | AN10: Secondary/approx; NOT verified on Amazon.ca | AO10: BLANK -> requires live Amazon.ca capture | AP10: Unverified commercial data
A11: Sparkling Ice | B11: Sparkling Ice (+ Antioxidants & Vitamins) | Cherry Limeade | 24-pack 503mL | C11: 1) Sparkling electrolyte / functional sparkling | D11: 503 mL bottle | E11: 24 | G11: =IF(AND(ISNUMBER($F11),ISNUMBER($E11),$E11<>0),$F11/$E11,"") | H11: =IF(AND(ISNUMBER($F11),ISNUMBER($AL11),ISNUMBER($E11),($AL11*$E11)<>0),$F11/($AL11*$E11)*100,"") | K11: =IF(AND(ISNUMBER($F11),ISNUMBER($J11)),$F11*(1-$J11),"") | N11: =IF(ISNUMBER($F11),($F11-IF(ISNUMBER($AM11),$AM11,0))*(1-IF(ISNUMBER($J11),$J11,0)),"") | O11: Cherry Limeade | P11: 0 | Q11: 0 | R11: 30 | S11: 0 | T11: 5 | U11: Sucralose | V11: Zero sugar, vitamins A/D/B, antioxidants (green tea), bold flavour | AA11: High | AB11: Mass-market functional sparkling; strong shelf share | AC11: Bold zero-sugar sparkling with added vitamins | AD11: Big flavour and added vitamins at zero sugar. | AF11: =IF(AND(ISNUMBER($P11),ISNUMBER($AL11),$AL11<>0),ROUND($P11/$AL11*100,1),"") | AG11: =IF(AND(ISNUMBER($S11),ISNUMBER($AL11),$AL11<>0),ROUND($S11/$AL11*100,2),"") | AH11: =IF(AND(ISNUMBER($Q11),ISNUMBER($AL11),$AL11<>0),ROUND($Q11/$AL11*100,1),"") | AI11: =IF(ISNUMBER($S11),IF($S11<=1,"Yes","No"),"n/a") | AJ11: =IF(ISNUMBER($S11),ROUND(MAX(0,MIN(100,100-$S11*2.5-IF(ISNUMBER($T11),$T11,0)*0.12+IF($S11<=1,12,0))),0),"") | AK11: =IF(ISNUMBER($Q11),IF($Q11>=100,20,IF($Q11>=30,10,0)),0)+IF(ISNUMBER($R11),IF($R11>=100,20,0),0)+IF(ISNUMBER($P11),IF($P11>=150,20,IF($P11>=50,12,5)),0)+IF(ISNUMBER($S11),IF($S11<=1,15,0),0) | AL11: 503 | AN11: Secondary/approx; NOT verified on Amazon.ca | AO11: BLANK -> requires live Amazon.ca capture | AP11: Unverified commercial data
A12: Sparkling Ice | B12: Sparkling Ice (+ Antioxidants & Vitamins) | Orange Mango | single 503mL | C12: 1) Sparkling electrolyte / functional sparkling | D12: 503 mL bottle | E12: 1 | G12: =IF(AND(ISNUMBER($F12),ISNUMBER($E12),$E12<>0),$F12/$E12,"") | H12: =IF(AND(ISNUMBER($F12),ISNUMBER($AL12),ISNUMBER($E12),($AL12*$E12)<>0),$F12/($AL12*$E12)*100,"") | K12: =IF(AND(ISNUMBER($F12),ISNUMBER($J12)),$F12*(1-$J12),"") | N12: =IF(ISNUMBER($F12),($F12-IF(ISNUMBER($AM12),$AM12,0))*(1-IF(ISNUMBER($J12),$J12,0)),"") | O12: Orange Mango | P12: 0 | Q12: 0 | R12: 30 | S12: 0 | T12: 5 | U12: Sucralose | V12: Zero sugar, vitamins A/D/B, antioxidants (green tea), bold flavour | AA12: High | AB12: Mass-market functional sparkling; strong shelf share | AC12: Bold zero-sugar sparkling with added vitamins | AD12: Big flavour and added vitamins at zero sugar. | AF12: =IF(AND(ISNUMBER($P12),ISNUMBER($AL12),$AL12<>0),ROUND($P12/$AL12*100,1),"") | AG12: =IF(AND(ISNUMBER($S12),ISNUMBER($AL12),$AL12<>0),ROUND($S12/$AL12*100,2),"") | AH12: =IF(AND(ISNUMBER($Q12),ISNUMBER($AL12),$AL12<>0),ROUND($Q12/$AL12*100,1),"") | AI12: =IF(ISNUMBER($S12),IF($S12<=1,"Yes","No"),"n/a") | AJ12: =IF(ISNUMBER($S12),ROUND(MAX(0,MIN(100,100-$S12*2.5-IF(ISNUMBER($T12),$T12,0)*0.12+IF($S12<=1,12,0))),0),"") | AK12: =IF(ISNUMBER($Q12),IF($Q12>=100,20,IF($Q12>=30,10,0)),0)+IF(ISNUMBER($R12),IF($R12>=100,20,0),0)+IF(ISNUMBER($P12),IF($P12>=150,20,IF($P12>=50,12,5)),0)+IF(ISNUMBER($S12),IF($S12<=1,15,0),0) | AL12: 503 | AN12: Secondary/approx; NOT verified on Amazon.ca | AO12: BLANK -> requires live Amazon.ca capture | AP12: Unverified commercial data
A13: Sparkling Ice | B13: Sparkling Ice (+ Antioxidants & Vitamins) | Orange Mango | 8-pack 503mL | C13: 1) Sparkling electrolyte / functional sparkling | D13: 503 mL bottle | E13: 8 | G13: =IF(AND(ISNUMBER($F13),ISNUMBER($E13),$E13<>0),$F13/$E13,"") | H13: =IF(AND(ISNUMBER($F13),ISNUMBER($AL13),ISNUMBER($E13),($AL13*$E13)<>0),$F13/($AL13*$E13)*100,"") | K13: =IF(AND(ISNUMBER($F13),ISNUMBER($J13)),$F13*(1-$J13),"") | N13: =IF(ISNUMBER($F13),($F13-IF(ISNUMBER($AM13),$AM13,0))*(1-IF(ISNUMBER($J13),$J13,0)),"") | O13: Orange Mango | P13: 0 | Q13: 0 | R13: 30 | S13: 0 | T13: 5 | U13: Sucralose | V13: Zero sugar, vitamins A/D/B, antioxidants (green tea), bold flavour | AA13: High | AB13: Mass-market functional sparkling; strong shelf share | AC13: Bold zero-sugar sparkling with added vitamins | AD13: Big flavour and added vitamins at zero sugar. | AF13: =IF(AND(ISNUMBER($P13),ISNUMBER($AL13),$AL13<>0),ROUND($P13/$AL13*100,1),"") | AG13: =IF(AND(ISNUMBER($S13),ISNUMBER($AL13),$AL13<>0),ROUND($S13/$AL13*100,2),"") | AH13: =IF(AND(ISNUMBER($Q13),ISNUMBER($AL13),$AL13<>0),ROUND($Q13/$AL13*100,1),"") | AI13: =IF(ISNUMBER($S13),IF($S13<=1,"Yes","No"),"n/a") | AJ13: =IF(ISNUMBER($S13),ROUND(MAX(0,MIN(100,100-$S13*2.5-IF(ISNUMBER($T13),$T13,0)*0.12+IF($S13<=1,12,0))),0),"") | AK13: =IF(ISNUMBER($Q13),IF($Q13>=100,20,IF($Q13>=30,10,0)),0)+IF(ISNUMBER($R13),IF($R13>=100,20,0),0)+IF(ISNUMBER($P13),IF($P13>=150,20,IF($P13>=50,12,5)),0)+IF(ISNUMBER($S13),IF($S13<=1,15,0),0) | AL13: 503 | AN13: Secondary/approx; NOT verified on Amazon.ca | AO13: BLANK -> requires live Amazon.ca capture | AP13: Unverified commercial data
... A31: Sparkling Ice | B31: Sparkling Ice (+ Antioxidants & Vitamins) | Classic Lemonade | 24-pack 503mL | C31: 1) Sparkling electrolyte / functional sparkling | D31: 503 mL bottle | E31: 24 | G31: =IF(AND(ISNUMBER($F31),ISNUMBER($E31),$E31<>0),$F31/$E31,"") | H31: =IF(AND(ISNUMBER($F31),ISNUMBER($AL31),ISNUMBER($E31),($AL31*$E31)<>0),$F31/($AL31*$E31)*100,"") | K31: =IF(AND(ISNUMBER($F31),ISNUMBER($J31)),$F31*(1-$J31),"") | N31: =IF(ISNUMBER($F31),($F31-IF(ISNUMBER($AM31),$AM31,0))*(1-IF(ISNUMBER($J31),$J31,0)),"") | O31: Classic Lemonade | P31: 0 | Q31: 0 | R31: 30 | S31: 0 | T31: 5 | U31: Sucralose | V31: Zero sugar, vitamins A/D/B, antioxidants (green tea), bold flavour | AA31: High | AB31: Mass-market functional sparkling; strong shelf share | AC31: Bold zero-sugar sparkling with added vitamins | AD31: Big flavour and added vitamins at zero sugar. | AF31: =IF(AND(ISNUMBER($P31),ISNUMBER($AL31),$AL31<>0),ROUND($P31/$AL31*100,1),"") | AG31: =IF(AND(ISNUMBER($S31),ISNUMBER($AL31),$AL31<>0),ROUND($S31/$AL31*100,2),"") | AH31: =IF(AND(ISNUMBER($Q31),ISNUMBER($AL31),$AL31<>0),ROUND($Q31/$AL31*100,1),"") | AI31: =IF(ISNUMBER($S31),IF($S31<=1,"Yes","No"),"n/a") | AJ31: =IF(ISNUMBER($S31),ROUND(MAX(0,MIN(100,100-$S31*2.5-IF(ISNUMBER($T31),$T31,0)*0.12+IF($S31<=1,12,0))),0),"") | AK31: =IF(ISNUMBER($Q31),IF($Q31>=100,20,IF($Q31>=30,10,0)),0)+IF(ISNUMBER($R31),IF($R31>=100,20,0),0)+IF(ISNUMBER($P31),IF($P31>=150,20,IF($P31>=50,12,5)),0)+IF(ISNUMBER($S31),IF($S31<=1,15,0),0) | AL31: 503 | AN31: Secondary/approx; NOT verified on Amazon.ca | AO31: BLANK -> requires live Amazon.ca capture | AP31: Unverified commercial data
A32: BUBBL'R | B32: BUBBL'R Antioxidant Sparkling Water | Blackberribrilliance | single 473mL | C32: 1) Sparkling electrolyte / functional sparkling | D32: 473 mL can | E32: 1 | G32: =IF(AND(ISNUMBER($F32),ISNUMBER($E32),$E32<>0),$F32/$E32,"") | H32: =IF(AND(ISNUMBER($F32),ISNUMBER($AL32),ISNUMBER($E32),($AL32*$E32)<>0),$F32/($AL32*$E32)*100,"") | K32: =IF(AND(ISNUMBER($F32),ISNUMBER($J32)),$F32*(1-$J32),"") | N32: =IF(ISNUMBER($F32),($F32-IF(ISNUMBER($AM32),$AM32,0))*(1-IF(ISNUMBER($J32),$J32,0)),"") | O32: Blackberribrilliance | P32: 69 | Q32: 15 | R32: Not listed | S32: 0 | T32: 10 | U32: Erythritol + stevia | V32: Natural caffeine (69 mg), antioxidants, B-vitamins, zero sugar | AA32: Medium | AB32: Mid-caffeine functional sparkling; growing | AC32: Sparkling water with a light caffeine + antioxidant lift | AD32: Light natural caffeine and antioxidants without an energy-drink dose. | AF32: =IF(AND(ISNUMBER($P32),ISNUMBER($AL32),$AL32<>0),ROUND($P32/$AL32*100,1),"") | AG32: =IF(AND(ISNUMBER($S32),ISNUMBER($AL32),$AL32<>0),ROUND($S32/$AL32*100,2),"") | AH32: =IF(AND(ISNUMBER($Q32),ISNUMBER($AL32),$AL32<>0),ROUND($Q32/$AL32*100,1),"") | AI32: =IF(ISNUMBER($S32),IF($S32<=1,"Yes","No"),"n/a") | AJ32: =IF(ISNUMBER($S32),ROUND(MAX(0,MIN(100,100-$S32*2.5-IF(ISNUMBER($T32),$T32,0)*0.12+IF($S32<=1,12,0))),0),"") | AK32: =IF(ISNUMBER($Q32),IF($Q32>=100,20,IF($Q32>=30,10,0)),0)+IF(ISNUMBER($R32),IF($R32>=100,20,0),0)+IF(ISNUMBER($P32),IF($P32>=150,20,IF($P32>=50,12,5)),0)+IF(ISNUMBER($S32),IF($S32<=1,15,0),0) | AL32: 473 | AN32: Secondary/approx; NOT verified on Amazon.ca | AO32: BLANK -> requires live Amazon.ca capture | AP32: Unverified commercial data
A33: BUBBL'R | B33: BUBBL'R Antioxidant Sparkling Water | Blackberribrilliance | 8-pack 473mL | C33: 1) Sparkling electrolyte / functional sparkling | D33: 473 mL can | E33: 8 | G33: =IF(AND(ISNUMBER($F33),ISNUMBER($E33),$E33<>0),$F33/$E33,"") | H33: =IF(AND(ISNUMBER($F33),ISNUMBER($AL33),ISNUMBER($E33),($AL33*$E33)<>0),$F33/($AL33*$E33)*100,"") | K33: =IF(AND(ISNUMBER($F33),ISNUMBER($J33)),$F33*(1-$J33),"") | N33: =IF(ISNUMBER($F33),($F33-IF(ISNUMBER($AM33),$AM33,0))*(1-IF(ISNUMBER($J33),$J33,0)),"") | O33: Blackberribrilliance | P33: 69 | Q33: 15 | R33: Not listed | S33: 0 | T33: 10 | U33: Erythritol + stevia | V33: Natural caffeine (69 mg), antioxidants, B-vitamins, zero sugar | AA33: Medium | AB33: Mid-caffeine functional sparkling; growing | AC33: Sparkling water with a light caffeine + antioxidant lift | AD33: Light natural caffeine and antioxidants without an energy-drink dose. | AF33: =IF(AND(ISNUMBER($P33),ISNUMBER($AL33),$AL33<>0),ROUND($P33/$AL33*100,1),"") | AG33: =IF(AND(ISNUMBER($S33),ISNUMBER($AL33),$AL33<>0),ROUND($S33/$AL33*100,2),"") | AH33: =IF(AND(ISNUMBER($Q33),ISNUMBER($AL33),$AL33<>0),ROUND($Q33/$AL33*100,1),"") | AI33: =IF(ISNUMBER($S33),IF($S33<=1,"Yes","No"),"n/a") | AJ33: =IF(ISNUMBER($S33),ROUND(MAX(0,MIN(100,100-$S33*2.5-IF(ISNUMBER($T33),$T33,0)*0.12+IF($S33<=1,12,0))),0),"") | AK33: =IF(ISNUMBER($Q33),IF($Q33>=100,20,IF($Q33>=30,10,0)),0)+IF(ISNUMBER($R33),IF($R33>=100,20,0),0)+IF(ISNUMBER($P33),IF($P33>=150,20,IF($P33>=50,12,5)),0)+IF(ISNUMBER($S33),IF($S33<=1,15,0),0) | AL33: 473 | AN33: Secondary/approx; NOT verified on Amazon.ca | AO33: BLANK -> requires live Amazon.ca capture | AP33: Unverified commercial data
A34: BUBBL'R | B34: BUBBL'R Antioxidant Sparkling Water | Blackberribrilliance | 12-pack 473mL | C34: 1) Sparkling electrolyte / functional sparkling | D34: 473 mL can | E34: 12 | G34: =IF(AND(ISNUMBER($F34),ISNUMBER($E34),$E34<>0),$F34/$E34,"") | H34: =IF(AND(ISNUMBER($F34),ISNUMBER($AL34),ISNUMBER($E34),($AL34*$E34)<>0),$F34/($AL34*$E34)*100,"") | K34: =IF(AND(ISNUMBER($F34),ISNUMBER($J34)),$F34*(1-$J34),"") | N34: =IF(ISNUMBER($F34),($F34-IF(ISNUMBER($AM34),$AM34,0))*(1-IF(ISNUMBER($J34),$J34,0)),"") | O34: Blackberribrilliance | P34: 69 | Q34: 15 | R34: Not listed | S34: 0 | T34: 10 | U34: Erythritol + stevia | V34: Natural caffeine (69 mg), antioxidants, B-vitamins, zero sugar | AA34: Medium | AB34: Mid-caffeine functional sparkling; growing | AC34: Sparkling water with a light caffeine + antioxidant lift | AD34: Light natural caffeine and antioxidants without an energy-drink dose. | AF34: =IF(AND(ISNUMBER($P34),ISNUMBER($AL34),$AL34<>0),ROUND($P34/$AL34*100,1),"") | AG34: =IF(AND(ISNUMBER($S34),ISNUMBER($AL34),$AL34<>0),ROUND($S34/$AL34*100,2),"") | AH34: =IF(AND(ISNUMBER($Q34),ISNUMBER($AL34),$AL34<>0),ROUND($Q34/$AL34*100,1),"") | AI34: =IF(ISNUMBER($S34),IF($S34<=1,"Yes","No"),"n/a") | AJ34: =IF(ISNUMBER($S34),ROUND(MAX(0,MIN(100,100-$S34*2.5-IF(ISNUMBER($T34),$T34,0)*0.12+IF($S34<=1,12,0))),0),"") | AK34: =IF(ISNUMBER($Q34),IF($Q34>=100,20,IF($Q34>=30,10,0)),0)+IF(ISNUMBER($R34),IF($R34>=100,20,0),0)+IF(ISNUMBER($P34),IF($P34>=150,20,IF($P34>=50,12,5)),0)+IF(ISNUMBER($S34),IF($S34<=1,15,0),0) | AL34: 473 | AN34: Secondary/approx; NOT verified on Amazon.ca | AO34: BLANK -> requires live Amazon.ca capture | AP34: Unverified commercial data
A35: BUBBL'R | B35: BUBBL'R Antioxidant Sparkling Water | Blackberribrilliance | 18-pack 473mL | C35: 1) Sparkling electrolyte / functional sparkling | D35: 473 mL can | E35: 18 | G35: =IF(AND(ISNUMBER($F35),ISNUMBER($E35),$E35<>0),$F35/$E35,"") | H35: =IF(AND(ISNUMBER($F35),ISNUMBER($AL35),ISNUMBER($E35),($AL35*$E35)<>0),$F35/($AL35*$E35)*100,"") | K35: =IF(AND(ISNUMBER($F35),ISNUMBER($J35)),$F35*(1-$J35),"") | N35: =IF(ISNUMBER($F35),($F35-IF(ISNUMBER($AM35),$AM35,0))*(1-IF(ISNUMBER($J35),$J35,0)),"") | O35: Blackberribrilliance | P35: 69 | Q35: 15 | R35: Not listed | S35: 0 | T35: 10 | U35: Erythritol + stevia | V35: Natural caffeine (69 mg), antioxidants, B-vitamins, zero sugar | AA35: Medium | AB35: Mid-caffeine functional sparkling; growing | AC35: Sparkling water with a light caffeine + antioxidant lift | AD35: Light natural caffeine and antioxidants without an energy-drink dose. | AF35: =IF(AND(ISNUMBER($P35),ISNUMBER($AL35),$AL35<>0),ROUND($P35/$AL35*100,1),"") | AG35: =IF(AND(ISNUMBER($S35),ISNUMBER($AL35),$AL35<>0),ROUND($S35/$AL35*100,2),"") | AH35: =IF(AND(ISNUMBER($Q35),ISNUMBER($AL35),$AL35<>0),ROUND($Q35/$AL35*100,1),"") | AI35: =IF(ISNUMBER($S35),IF($S35<=1,"Yes","No"),"n/a") | AJ35: =IF(ISNUMBER($S35),ROUND(MAX(0,MIN(100,100-$S35*2.5-IF(ISNUMBER($T35),$T35,0)*0.12+IF($S35<=1,12,0))),0),"") | AK35: =IF(ISNUMBER($Q35),IF($Q35>=100,20,IF($Q35>=30,10,0)),0)+IF(ISNUMBER($R35),IF($R35>=100,20,0),0)+IF(ISNUMBER($P35),IF($P35>=150,20,IF($P35>=50,12,5)),0)+IF(ISNUMBER($S35),IF($S35<=1,15,0),0) | AL35: 473 | AN35: Secondary/approx; NOT verified on Amazon.ca | AO35: BLANK -> requires live Amazon.ca capture | AP35: Unverified commercial data
A36: BUBBL'R | B36: BUBBL'R Antioxidant Sparkling Water | Blackberribrilliance | 24-pack 473mL | C36: 1) Sparkling electrolyte / functional sparkling | D36: 473 mL can | E36: 24 | G36: =IF(AND(ISNUMBER($F36),ISNUMBER($E36),$E36<>0),$F36/$E36,"") | H36: =IF(AND(ISNUMBER($F36),ISNUMBER($AL36),ISNUMBER($E36),($AL36*$E36)<>0),$F36/($AL36*$E36)*100,"") | K36: =IF(AND(ISNUMBER($F36),ISNUMBER($J36)),$F36*(1-$J36),"") | N36: =IF(ISNUMBER($F36),($F36-IF(ISNUMBER($AM36),$AM36,0))*(1-IF(ISNUMBER($J36),$J36,0)),"") | O36: Blackberribrilliance | P36: 69 | Q36: 15 | R36: Not listed | S36: 0 | T36: 10 | U36: Erythritol + stevia | V36: Natural caffeine (69 mg), antioxidants, B-vitamins, zero sugar | AA36: Medium | AB36: Mid-caffeine functional sparkling; growing | AC36: Sparkling water with a light caffeine + antioxidant lift | AD36: Light natural caffeine and antioxidants without an energy-drink dose. | AF36: =IF(AND(ISNUMBER($P36),ISNUMBER($AL36),$AL36<>0),ROUND($P36/$AL36*100,1),"") | AG36: =IF(AND(ISNUMBER($S36),ISNUMBER($AL36),$AL36<>0),ROUND($S36/$AL36*100,2),"") | AH36: =IF(AND(ISNUMBER($Q36),ISNUMBER($AL36),$AL36<>0),ROUND($Q36/$AL36*100,1),"") | AI36: =IF(ISNUMBER($S36),IF($S36<=1,"Yes","No"),"n/a") | AJ36: =IF(ISNUMBER($S36),ROUND(MAX(0,MIN(100,100-$S36*2.5-IF(ISNUMBER($T36),$T36,0)*0.12+IF($S36<=1,12,0))),0),"") | AK36: =IF(ISNUMBER($Q36),IF($Q36>=100,20,IF($Q36>=30,10,0)),0)+IF(ISNUMBER($R36),IF($R36>=100,20,0),0)+IF(ISNUMBER($P36),IF($P36>=150,20,IF($P36>=50,12,5)),0)+IF(ISNUMBER($S36),IF($S36<=1,15,0),0) | AL36: 473 | AN36: Secondary/approx; NOT verified on Amazon.ca | AO36: BLANK -> requires live Amazon.ca capture | AP36: Unverified commercial data
A37: BUBBL'R | B37: BUBBL'R Antioxidant Sparkling Water | Strawbeary Lemonade | single 473mL | C37: 1) Sparkling electrolyte / functional sparkling | D37: 473 mL can | E37: 1 | G37: =IF(AND(ISNUMBER($F37),ISNUMBER($E37),$E37<>0),$F37/$E37,"") | H37: =IF(AND(ISNUMBER($F37),ISNUMBER($AL37),ISNUMBER($E37),($AL37*$E37)<>0),$F37/($AL37*$E37)*100,"") | K37: =IF(AND(ISNUMBER($F37),ISNUMBER($J37)),$F37*(1-$J37),"") | N37: =IF(ISNUMBER($F37),($F37-IF(ISNUMBER($AM37),$AM37,0))*(1-IF(ISNUMBER($J37),$J37,0)),"") | O37: Strawbeary Lemonade | P37: 69 | Q37: 15 | R37: Not listed | S37: 0 | T37: 10 | U37: Erythritol + stevia | V37: Natural caffeine (69 mg), antioxidants, B-vitamins, zero sugar | AA37: Medium | AB37: Mid-caffeine functional sparkling; growing | AC37: Sparkling water with a light caffeine + antioxidant lift | AD37: Light natural caffeine and antioxidants without an energy-drink dose. | AF37: =IF(AND(ISNUMBER($P37),ISNUMBER($AL37),$AL37<>0),ROUND($P37/$AL37*100,1),"") | AG37: =IF(AND(ISNUMBER($S37),ISNUMBER($AL37),$AL37<>0),ROUND($S37/$AL37*100,2),"") | AH37: =IF(AND(ISNUMBER($Q37),ISNUMBER($AL37),$AL37<>0),ROUND($Q37/$AL37*100,1),"") | AI37: =IF(ISNUMBER($S37),IF($S37<=1,"Yes","No"),"n/a") | AJ37: =IF(ISNUMBER($S37),ROUND(MAX(0,MIN(100,100-$S37*2.5-IF(ISNUMBER($T37),$T37,0)*0.12+IF($S37<=1,12,0))),0),"") | AK37: =IF(ISNUMBER($Q37),IF($Q37>=100,20,IF($Q37>=30,10,0)),0)+IF(ISNUMBER($R37),IF($R37>=100,20,0),0)+IF(ISNUMBER($P37),IF($P37>=150,20,IF($P37>=50,12,5)),0)+IF(ISNUMBER($S37),IF($S37<=1,15,0),0) | AL37: 473 | AN37: Secondary/approx; NOT verified on Amazon.ca | AO37: BLANK -> requires live Amazon.ca capture | AP37: Unverified commercial data
A38: BUBBL'R | B38: BUBBL'R Antioxidant Sparkling Water | Strawbeary Lemonade | 8-pack 473mL | C38: 1) Sparkling electrolyte / functional sparkling | D38: 473 mL can | E38: 8 | G38: =IF(AND(ISNUMBER($F38),ISNUMBER($E38),$E38<>0),$F38/$E38,"") | H38: =IF(AND(ISNUMBER($F38),ISNUMBER($AL38),ISNUMBER($E38),($AL38*$E38)<>0),$F38/($AL38*$E38)*100,"") | K38: =IF(AND(ISNUMBER($F38),ISNUMBER($J38)),$F38*(1-$J38),"") | N38: =IF(ISNUMBER($F38),($F38-IF(ISNUMBER($AM38),$AM38,0))*(1-IF(ISNUMBER($J38),$J38,0)),"") | O38: Strawbeary Lemonade | P38: 69 | Q38: 15 | R38: Not listed | S38: 0 | T38: 10 | U38: Erythritol + stevia | V38: Natural caffeine (69 mg), antioxidants, B-vitamins, zero sugar | AA38: Medium | AB38: Mid-caffeine functional sparkling; growing | AC38: Sparkling water with a light caffeine + antioxidant lift | AD38: Light natural caffeine and antioxidants without an energy-drink dose. | AF38: =IF(AND(ISNUMBER($P38),ISNUMBER($AL38),$AL38<>0),ROUND($P38/$AL38*100,1),"") | AG38: =IF(AND(ISNUMBER($S38),ISNUMBER($AL38),$AL38<>0),ROUND($S38/$AL38*100,2),"") | AH38: =IF(AND(ISNUMBER($Q38),ISNUMBER($AL38),$AL38<>0),ROUND($Q38/$AL38*100,1),"") | AI38: =IF(ISNUMBER($S38),IF($S38<=1,"Yes","No"),"n/a") | AJ38: =IF(ISNUMBER($S38),ROUND(MAX(0,MIN(100,100-$S38*2.5-IF(ISNUMBER($T38),$T38,0)*0.12+IF($S38<=1,12,0))),0),"") | AK38: =IF(ISNUMBER($Q38),IF($Q38>=100,20,IF($Q38>=30,10,0)),0)+IF(ISNUMBER($R38),IF($R38>=100,20,0),0)+IF(ISNUMBER($P38),IF($P38>=150,20,IF($P38>=50,12,5)),0)+IF(ISNUMBER($S38),IF($S38<=1,15,0),0) | AL38: 473 | AN38: Secondary/approx; NOT verified on Amazon.ca | AO38: BLANK -> requires live Amazon.ca capture | AP38: Unverified commercial data
A39: BUBBL'R | B39: BUBBL'R Antioxidant Sparkling Water | Strawbeary Lemonade | 12-pack 473mL | C39: 1) Sparkling electrolyte / functional sparkling | D39: 473 mL can | E39: 12 | G39: =IF(AND(ISNUMBER($F39),ISNUMBER($E39),$E39<>0),$F39/$E39,"") | H39: =IF(AND(ISNUMBER($F39),ISNUMBER($AL39),ISNUMBER($E39),($AL39*$E39)<>0),$F39/($AL39*$E39)*100,"") | K39: =IF(AND(ISNUMBER($F39),ISNUMBER($J39)),$F39*(1-$J39),"") | N39: =IF(ISNUMBER($F39),($F39-IF(ISNUMBER($AM39),$AM39,0))*(1-IF(ISNUMBER($J39),$J39,0)),"") | O39: Strawbeary Lemonade | P39: 69 | Q39: 15 | R39: Not listed | S39: 0 | T39: 10 | U39: Erythritol + stevia | V39: Natural caffeine (69 mg), antioxidants, B-vitamins, zero sugar | AA39: Medium | AB39: Mid-caffeine functional sparkling; growing | AC39: Sparkling water with a light caffeine + antioxidant lift | AD39: Light natural caffeine and antioxidants without an energy-drink dose. | AF39: =IF(AND(ISNUMBER($P39),ISNUMBER($AL39),$AL39<>0),ROUND($P39/$AL39*100,1),"") | AG39: =IF(AND(ISNUMBER($S39),ISNUMBER($AL39),$AL39<>0),ROUND($S39/$AL39*100,2),"") | AH39: =IF(AND(ISNUMBER($Q39),ISNUMBER($AL39),$AL39<>0),ROUND($Q39/$AL39*100,1),"") | AI39: =IF(ISNUMBER($S39),IF($S39<=1,"Yes","No"),"n/a") | AJ39: =IF(ISNUMBER($S39),ROUND(MAX(0,MIN(100,100-$S39*2.5-IF(ISNUMBER($T39),$T39,0)*0.12+IF($S39<=1,12,0))),0),"") | AK39: =IF(ISNUMBER($Q39),IF($Q39>=100,20,IF($Q39>=30,10,0)),0)+IF(ISNUMBER($R39),IF($R39>=100,20,0),0)+IF(ISNUMBER($P39),IF($P39>=150,20,IF($P39>=50,12,5)),0)+IF(ISNUMBER($S39),IF($S39<=1,15,0),0) | AL39: 473 | AN39: Secondary/approx; NOT verified on Amazon.ca | AO39: BLANK -> requires live Amazon.ca capture | AP39: Unverified commercial data
A40: BUBBL'R | B40: BUBBL'R Antioxidant Sparkling Water | Strawbeary Lemonade | 18-pack 473mL | C40: 1) Sparkling electrolyte / functional sparkling | D40: 473 mL can | E40: 18 | G40: =IF(AND(ISNUMBER($F40),ISNUMBER($E40),$E40<>0),$F40/$E40,"") | H40: =IF(AND(ISNUMBER($F40),ISNUMBER($AL40),ISNUMBER($E40),($AL40*$E40)<>0),$F40/($AL40*$E40)*100,"") | K40: =IF(AND(ISNUMBER($F40),ISNUMBER($J40)),$F40*(1-$J40),"") | N40: =IF(ISNUMBER($F40),($F40-IF(ISNUMBER($AM40),$AM40,0))*(1-IF(ISNUMBER($J40),$J40,0)),"") | O40: Strawbeary Lemonade | P40: 69 | Q40: 15 | R40: Not listed | S40: 0 | T40: 10 | U40: Erythritol + stevia | V40: Natural caffeine (69 mg), antioxidants, B-vitamins, zero sugar | AA40: Medium | AB40: Mid-caffeine functional sparkling; growing | AC40: Sparkling water with a light caffeine + antioxidant lift | AD40: Light natural caffeine and antioxidants without an energy-drink dose. | AF40: =IF(AND(ISNUMBER($P40),ISNUMBER($AL40),$AL40<>0),ROUND($P40/$AL40*100,1),"") | AG40: =IF(AND(ISNUMBER($S40),ISNUMBER($AL40),$AL40<>0),ROUND($S40/$AL40*100,2),"") | AH40: =IF(AND(ISNUMBER($Q40),ISNUMBER($AL40),$AL40<>0),ROUND($Q40/$AL40*100,1),"") | AI40: =IF(ISNUMBER($S40),IF($S40<=1,"Yes","No"),"n/a") | AJ40: =IF(ISNUMBER($S40),ROUND(MAX(0,MIN(100,100-$S40*2.5-IF(ISNUMBER($T40),$T40,0)*0.12+IF($S40<=1,12,0))),0),"") | AK40: =IF(ISNUMBER($Q40),IF($Q40>=100,20,IF($Q40>=30,10,0)),0)+IF(ISNUMBER($R40),IF($R40>=100,20,0),0)+IF(ISNUMBER($P40),IF($P40>=150,20,IF($P40>=50,12,5)),0)+IF(ISNUMBER($S40),IF($S40<=1,15,0),0) | AL40: 473 | AN40: Secondary/approx; NOT verified on Amazon.ca | AO40: BLANK -> requires live Amazon.ca capture | AP40: Unverified commercial data
A41: BUBBL'R | B41: BUBBL'R Antioxidant Sparkling Water | Strawbeary Lemonade | 24-pack 473mL | C41: 1) Sparkling electrolyte / functional sparkling | D41: 473 mL can | E41: 24 | G41: =IF(AND(ISNUMBER($F41),ISNUMBER($E41),$E41<>0),$F41/$E41,"") | H41: =IF(AND(ISNUMBER($F41),ISNUMBER($AL41),ISNUMBER($E41),($AL41*$E41)<>0),$F41/($AL41*$E41)*100,"") | K41: =IF(AND(ISNUMBER($F41),ISNUMBER($J41)),$F41*(1-$J41),"") | N41: =IF(ISNUMBER($F41),($F41-IF(ISNUMBER($AM41),$AM41,0))*(1-IF(ISNUMBER($J41),$J41,0)),"") | O41: Strawbeary Lemonade | P41: 69 | Q41: 15 | R41: Not listed | S41: 0 | T41: 10 | U41: Erythritol + stevia | V41: Natural caffeine (69 mg), antioxidants, B-vitamins, zero sugar | AA41: Medium | AB41: Mid-caffeine functional sparkling; growing | AC41: Sparkling water with a light caffeine + antioxidant lift | AD41: Light natural caffeine and antioxidants without an energy-drink dose. | AF41: =IF(AND(ISNUMBER($P41),ISNUMBER($AL41),$AL41<>0),ROUND($P41/$AL41*100,1),"") | AG41: =IF(AND(ISNUMBER($S41),ISNUMBER($AL41),$AL41<>0),ROUND($S41/$AL41*100,2),"") | AH41: =IF(AND(ISNUMBER($Q41),ISNUMBER($AL41),$AL41<>0),ROUND($Q41/$AL41*100,1),"") | AI41: =IF(ISNUMBER($S41),IF($S41<=1,"Yes","No"),"n/a") | AJ41: =IF(ISNUMBER($S41),ROUND(MAX(0,MIN(100,100-$S41*2.5-IF(ISNUMBER($T41),$T41,0)*0.12+IF($S41<=1,12,0))),0),"") | AK41: =IF(ISNUMBER($Q41),IF($Q41>=100,20,IF($Q41>=30,10,0)),0)+IF(ISNUMBER($R41),IF($R41>=100,20,0),0)+IF(ISNUMBER($P41),IF($P41>=150,20,IF($P41>=50,12,5)),0)+IF(ISNUMBER($S41),IF($S41<=1,15,0),0) | AL41: 473 | AN41: Secondary/approx; NOT verified on Amazon.ca | AO41: BLANK -> requires live Amazon.ca capture | AP41: Unverified commercial data
A42: BUBBL'R | B42: BUBBL'R Antioxidant Sparkling Water | Tropic'b'r | single 473mL | C42: 1) Sparkling electrolyte / functional sparkling | D42: 473 mL can | E42: 1 | G42: =IF(AND(ISNUMBER($F42),ISNUMBER($E42),$E42<>0),$F42/$E42,"") | H42: =IF(AND(ISNUMBER($F42),ISNUMBER($AL42),ISNUMBER($E42),($AL42*$E42)<>0),$F42/($AL42*$E42)*100,"") | K42: =IF(AND(ISNUMBER($F42),ISNUMBER($J42)),$F42*(1-$J42),"") | N42: =IF(ISNUMBER($F42),($F42-IF(ISNUMBER($AM42),$AM42,0))*(1-IF(ISNUMBER($J42),$J42,0)),"") | O42: Tropic'b'r | P42: 69 | Q42: 15 | R42: Not listed | S42: 0 | T42: 10 | U42: Erythritol + stevia | V42: Natural caffeine (69 mg), antioxidants, B-vitamins, zero sugar | AA42: Medium | AB42: Mid-caffeine functional sparkling; growing | AC42: Sparkling water with a light caffeine + antioxidant lift | AD42: Light natural caffeine and antioxidants without an energy-drink dose. | AF42: =IF(AND(ISNUMBER($P42),ISNUMBER($AL42),$AL42<>0),ROUND($P42/$AL42*100,1),"") | AG42: =IF(AND(ISNUMBER($S42),ISNUMBER($AL42),$AL42<>0),ROUND($S42/$AL42*100,2),"") | AH42: =IF(AND(ISNUMBER($Q42),ISNUMBER($AL42),$AL42<>0),ROUND($Q42/$AL42*100,1),"") | AI42: =IF(ISNUMBER($S42),IF($S42<=1,"Yes","No"),"n/a") | AJ42: =IF(ISNUMBER($S42),ROUND(MAX(0,MIN(100,100-$S42*2.5-IF(ISNUMBER($T42),$T42,0)*0.12+IF($S42<=1,12,0))),0),"") | AK42: =IF(ISNUMBER($Q42),IF($Q42>=100,20,IF($Q42>=30,10,0)),0)+IF(ISNUMBER($R42),IF($R42>=100,20,0),0)+IF(ISNUMBER($P42),IF($P42>=150,20,IF($P42>=50,12,5)),0)+IF(ISNUMBER($S42),IF($S42<=1,15,0),0) | AL42: 473 | AN42: Secondary/approx; NOT verified on Amazon.ca | AO42: BLANK -> requires live Amazon.ca capture | AP42: Unverified commercial data
A43: BUBBL'R | B43: BUBBL'R Antioxidant Sparkling Water | Tropic'b'r | 8-pack 473mL | C43: 1) Sparkling electrolyte / functional sparkling | D43: 473 mL can | E43: 8 | G43: =IF(AND(ISNUMBER($F43),ISNUMBER($E43),$E43<>0),$F43/$E43,"") | H43: =IF(AND(ISNUMBER($F43),ISNUMBER($AL43),ISNUMBER($E43),($AL43*$E43)<>0),$F43/($AL43*$E43)*100,"") | K43: =IF(AND(ISNUMBER($F43),ISNUMBER($J43)),$F43*(1-$J43),"") | N43: =IF(ISNUMBER($F43),($F43-IF(ISNUMBER($AM43),$AM43,0))*(1-IF(ISNUMBER($J43),$J43,0)),"") | O43: Tropic'b'r | P43: 69 | Q43: 15 | R43: Not listed | S43: 0 | T43: 10 | U43: Erythritol + stevia | V43: Natural caffeine (69 mg), antioxidants, B-vitamins, zero sugar | AA43: Medium | AB43: Mid-caffeine functional sparkling; growing | AC43: Sparkling water with a light caffeine + antioxidant lift | AD43: Light natural caffeine and antioxidants without an energy-drink dose. | AF43: =IF(AND(ISNUMBER($P43),ISNUMBER($AL43),$AL43<>0),ROUND($P43/$AL43*100,1),"") | AG43: =IF(AND(ISNUMBER($S43),ISNUMBER($AL43),$AL43<>0),ROUND($S43/$AL43*100,2),"") | AH43: =IF(AND(ISNUMBER($Q43),ISNUMBER($AL43),$AL43<>0),ROUND($Q43/$AL43*100,1),"") | AI43: =IF(ISNUMBER($S43),IF($S43<=1,"Yes","No"),"n/a") | AJ43: =IF(ISNUMBER($S43),ROUND(MAX(0,MIN(100,100-$S43*2.5-IF(ISNUMBER($T43),$T43,0)*0.12+IF($S43<=1,12,0))),0),"") | AK43: =IF(ISNUMBER($Q43),IF($Q43>=100,20,IF($Q43>=30,10,0)),0)+IF(ISNUMBER($R43),IF($R43>=100,20,0),0)+IF(ISNUMBER($P43),IF($P43>=150,20,IF($P43>=50,12,5)),0)+IF(ISNUMBER($S43),IF($S43<=1,15,0),0) | AL43: 473 | AN43: Secondary/approx; NOT verified on Amazon.ca | AO43: BLANK -> requires live Amazon.ca capture | AP43: Unverified commercial data
... A146: Sound | B146: Sound Sparkling Water (Tea/Botanical) | Cucumber + Mint Green Tea | 24-pack 355mL | C146: 1) Sparkling electrolyte / functional sparkling | D146: 355 mL can | E146: 24 | G146: =IF(AND(ISNUMBER($F146),ISNUMBER($E146),$E146<>0),$F146/$E146,"") | H146: =IF(AND(ISNUMBER($F146),ISNUMBER($AL146),ISNUMBER($E146),($AL146*$E146)<>0),$F146/($AL146*$E146)*100,"") | K146: =IF(AND(ISNUMBER($F146),ISNUMBER($J146)),$F146*(1-$J146),"") | N146: =IF(ISNUMBER($F146),($F146-IF(ISNUMBER($AM146),$AM146,0))*(1-IF(ISNUMBER($J146),$J146,0)),"") | O146: Cucumber + Mint Green Tea | P146: 15 | Q146: 0 | R146: Not listed | S146: 0 | T146: 0 | U146: None (unsweetened) | V146: Real brewed tea/botanicals, unsweetened, zero sugar/calorie | AA146: Low | AB146: Emerging unsweetened-botanical niche | AC146: Unsweetened sparkling brewed tea and botanicals | AD146: Genuinely unsweetened with real tea/botanical character. | AF146: =IF(AND(ISNUMBER($P146),ISNUMBER($AL146),$AL146<>0),ROUND($P146/$AL146*100,1),"") | AG146: =IF(AND(ISNUMBER($S146),ISNUMBER($AL146),$AL146<>0),ROUND($S146/$AL146*100,2),"") | AH146: =IF(AND(ISNUMBER($Q146),ISNUMBER($AL146),$AL146<>0),ROUND($Q146/$AL146*100,1),"") | AI146: =IF(ISNUMBER($S146),IF($S146<=1,"Yes","No"),"n/a") | AJ146: =IF(ISNUMBER($S146),ROUND(MAX(0,MIN(100,100-$S146*2.5-IF(ISNUMBER($T146),$T146,0)*0.12+IF($S146<=1,12,0))),0),"") | AK146: =IF(ISNUMBER($Q146),IF($Q146>=100,20,IF($Q146>=30,10,0)),0)+IF(ISNUMBER($R146),IF($R146>=100,20,0),0)+IF(ISNUMBER($P146),IF($P146>=150,20,IF($P146>=50,12,5)),0)+IF(ISNUMBER($S146),IF($S146<=1,15,0),0) | AL146: 355 | AN146: Secondary/approx; NOT verified on Amazon.ca | AO146: BLANK -> requires live Amazon.ca capture | AP146: Unverified commercial data
