Workbook

Sheet README
B2: Costco UK – Bee Propolis Spray 30ml x 2 Pack
B3: Market Test ROI Model – v2.0
B5: HOW TO USE THIS MODEL
B6: INSTRUCTIONS
B8: 1. Open the 'Inputs' sheet. Only the YELLOW cells are editable – everything else is calculated.
B10: 2. Inputs are grouped into four blocks:
B11: • Product & Distribution – test horizon and number of warehouses.
B12: • Pricing & Cost – selling price, landed cost (gross margin recalculates automatically).
B13: • Base Demand – organic units sold per warehouse per week with no promo support.
B14: • Promo Economics – cost per warehouse for Demo / End Cap / Fence / Advertising, plus the TPD and Markdown discount %.
B16: 3. Each of the three scenarios (BEST / IDEAL / WORST) has its own activity grid on the Inputs sheet. For every week, tick (1) or leave blank (0) for each promo lever, and set the demand lift multiplier. Base demand is multiplied by the lift to get that week's units.
B18: 4. The 'Forecast' sheet shows the week-by-week P&L for each scenario, fully driven off Inputs. Do not edit this sheet – it will rebuild itself when Inputs change.
... B35: Light Blue: Summary KPI

Sheet Inputs
B2: INPUTS & ASSUMPTIONS — change yellow cells only
B4: 1. Product & Distribution
B5: SKU | C5: Bee Propolis Spray 30ml x 2 | E5: Costco UK market test SKU.
B6: Test Warehouses | C6: 20 | E6: Number of Costco UK warehouses included in the market test.
B7: Test Period (Weeks) | C7: 26 | E7: Forecast horizon. Model is built for 26 weeks (Week 2 through Week 27).
B9: 2. Pricing & Cost (per unit, £)
B10: Selling Price (MSRP) | C10: 15.99 | E10: Retail price to member per 30ml x 2 pack.
B11: Cost Price (landed) | C11: 7.29 | E11: Brand's cost to Costco delivered to depot.
B12: Gross Margin per unit | C12: =C10-C11 | E12: Calculated. Selling price less landed cost.
B13: Gross Margin % | C13: =IFERROR((C10-C11)/C10,0) | E13: Calculated. Healthy supplements benchmark is 45-60%.
B15: 3. Base Demand (no promo support)
B16: Units / Warehouse / Week | C16: 13.79 | E16: Equivalent to the original assumption '500 × 0.8 / 29' from the prior 30ml SKU test (500 lifetime units × 80% sell-through over a 29-week reference window).
B17: Base Units / Week (all warehouses) | C17: =C16*$C$6 | E17: Calculated. Per-warehouse rate × number of warehouses.
B19: 4. Promo Economics
B20: Demo £ / warehouse / week | C20: 199 | E20: Costco UK standard demo rate per warehouse per weekend.
B21: Demo cost factor (overhead × staffing) | C21: 1.86 | E21: Multiplier on raw demo fee to capture staffing, POS print & overhead.
B22: Demo Total £ / week | C22: =C20*$C$6*C21 | E22: Calculated. Demo rate × warehouses × cost factor.
B23: End Cap £ / warehouse / 2-week cycle | C23: 850 | E23: Costco UK standard end cap rental per warehouse for a 2-week placement.
B24: End Cap cost factor | C24: 1.86 | E24: Same overhead multiplier as demo.
B25: End Cap Total £ / week | C25: =C23*$C$6*C24/2 | E25: Calculated. Rate × warehouses × factor ÷ 2 (booked over 2 weeks).
B26: Fence £ / week (when active) | C26: 0 | E26: Optional fence display. Currently not budgeted.
B27: Advertising £ / week (when active) | C27: 0 | E27: External media / coupon insert support. Currently not budgeted.
B28: TPD discount % | C28: 0.25 | E28: Standard TPD: 20% off MSRP. Grossed up by 0.8 retail margin → 25% deduction on net.
B29: Markdown discount % | C29: 0.5 | E29: Clearance pricing in worst-case markdown weeks.
B31: 5. Scenario Activity & Demand Lift (1 = promo active that week, 0 = off; Lift = demand multiplier vs base)
B33: BEST – x2 Demo (Wks 5-6) + TPD
B34: Rationale: Two national demo weekends combined with a TPD price promo. Demo lifts unit velocity ~3x in-week (Costco benchmark for supplements). No end cap booked, no markdown needed.
B35: Week | F35: W2 | G35: W3 | H35: W4 | I35: W5 | J35: W6 | K35: W7 | L35: W8 | M35: W9 | N35: W10 | O35: W11 | P35: W12 | Q35: W13 | R35: W14 | S35: W15 | T35: W16 | U35: W17 | V35: W18 | W35: W19 | X35: W20 | Y35: W21 | Z35: W22 | AA35: W23 | AB35: W24 | AC35: W25 | AD35: W26 | AE35: W27
B36: Demo | F36: 0 | G36: 0 | H36: 0 | I36: 1 | J36: 1 | K36: 0 | L36: 0 | M36: 0 | N36: 0 | O36: 0 | P36: 0 | Q36: 0 | R36: 0 | S36: 0 | T36: 0 | U36: 0 | V36: 0 | W36: 0 | X36: 0 | Y36: 0 | Z36: 0 | AA36: 0 | AB36: 0 | AC36: 0 | AD36: 0 | AE36: 0
B37: End Cap | F37: 0 | G37: 0 | H37: 0 | I37: 0 | J37: 0 | K37: 0 | L37: 0 | M37: 0 | N37: 0 | O37: 0 | P37: 0 | Q37: 0 | R37: 0 | S37: 0 | T37: 0 | U37: 0 | V37: 0 | W37: 0 | X37: 0 | Y37: 0 | Z37: 0 | AA37: 0 | AB37: 0 | AC37: 0 | AD37: 0 | AE37: 0
B38: Fence | F38: 0 | G38: 0 | H38: 0 | I38: 0 | J38: 0 | K38: 0 | L38: 0 | M38: 0 | N38: 0 | O38: 0 | P38: 0 | Q38: 0 | R38: 0 | S38: 0 | T38: 0 | U38: 0 | V38: 0 | W38: 0 | X38: 0 | Y38: 0 | Z38: 0 | AA38: 0 | AB38: 0 | AC38: 0 | AD38: 0 | AE38: 0
B39: TPD | F39: 0 | G39: 0 | H39: 0 | I39: 1 | J39: 1 | K39: 0 | L39: 0 | M39: 0 | N39: 0 | O39: 0 | P39: 0 | Q39: 0 | R39: 0 | S39: 0 | T39: 0 | U39: 0 | V39: 0 | W39: 0 | X39: 0 | Y39: 0 | Z39: 0 | AA39: 0 | AB39: 0 | AC39: 0 | AD39: 0 | AE39: 0
B40: Markdown | F40: 0 | G40: 0 | H40: 0 | I40: 0 | J40: 0 | K40: 0 | L40: 0 | M40: 0 | N40: 0 | O40: 0 | P40: 0 | Q40: 0 | R40: 0 | S40: 0 | T40: 0 | U40: 0 | V40: 0 | W40: 0 | X40: 0 | Y40: 0 | Z40: 0 | AA40: 0 | AB40: 0 | AC40: 0 | AD40: 0 | AE40: 0
B41: Advert | F41: 0 | G41: 0 | H41: 0 | I41: 0 | J41: 0 | K41: 0 | L41: 0 | M41: 0 | N41: 0 | O41: 0 | P41: 0 | Q41: 0 | R41: 0 | S41: 0 | T41: 0 | U41: 0 | V41: 0 | W41: 0 | X41: 0 | Y41: 0 | Z41: 0 | AA41: 0 | AB41: 0 | AC41: 0 | AD41: 0 | AE41: 0
B42: Lift Multiplier (x base) | F42: 1 | G42: 1 | H42: 1 | I42: 3 | J42: 3 | K42: 1 | L42: 1 | M42: 1 | N42: 1 | O42: 1 | P42: 1 | Q42: 1 | R42: 1 | S42: 1 | T42: 1 | U42: 1 | V42: 1 | W42: 1 | X42: 1 | Y42: 1 | Z42: 1 | AA42: 1 | AB42: 1 | AC42: 1 | AD42: 1 | AE42: 1
B44: IDEAL – x2 Demo + End Cap (Wks 5-6) + TPD
B45: Rationale: Full-court press: demo + end cap + TPD all running together for two weeks. Stacking end cap on demo weeks lifts velocity to ~3.6x (incremental ~20% on top of demo-only).
B46: Week | F46: W2 | G46: W3 | H46: W4 | I46: W5 | J46: W6 | K46: W7 | L46: W8 | M46: W9 | N46: W10 | O46: W11 | P46: W12 | Q46: W13 | R46: W14 | S46: W15 | T46: W16 | U46: W17 | V46: W18 | W46: W19 | X46: W20 | Y46: W21 | Z46: W22 | AA46: W23 | AB46: W24 | AC46: W25 | AD46: W26 | AE46: W27
B47: Demo | F47: 0 | G47: 0 | H47: 0 | I47: 1 | J47: 1 | K47: 0 | L47: 0 | M47: 0 | N47: 0 | O47: 0 | P47: 0 | Q47: 0 | R47: 0 | S47: 0 | T47: 0 | U47: 0 | V47: 0 | W47: 0 | X47: 0 | Y47: 0 | Z47: 0 | AA47: 0 | AB47: 0 | AC47: 0 | AD47: 0 | AE47: 0
B48: End Cap | F48: 0 | G48: 0 | H48: 0 | I48: 1 | J48: 1 | K48: 0 | L48: 0 | M48: 0 | N48: 0 | O48: 0 | P48: 0 | Q48: 0 | R48: 0 | S48: 0 | T48: 0 | U48: 0 | V48: 0 | W48: 0 | X48: 0 | Y48: 0 | Z48: 0 | AA48: 0 | AB48: 0 | AC48: 0 | AD48: 0 | AE48: 0
...

Sheet Forecast
B2: FORECAST — Weekly P&L (all values calculated, do not edit)
B4: BEST – x2 Demo (Wks 5-6) + TPD
B5: Week | F5: W2 | G5: W3 | H5: W4 | I5: W5 | J5: W6 | K5: W7 | L5: W8 | M5: W9 | N5: W10 | O5: W11 | P5: W12 | Q5: W13 | R5: W14 | S5: W15 | T5: W16 | U5: W17 | V5: W18 | W5: W19 | X5: W20 | Y5: W21 | Z5: W22 | AA5: W23 | AB5: W24 | AC5: W25 | AD5: W26 | AE5: W27 | AF5: TOTAL
B6: POS Units | F6: =ROUND(Inputs!$C$17*Inputs!F42,0) | G6: =ROUND(Inputs!$C$17*Inputs!G42,0) | H6: =ROUND(Inputs!$C$17*Inputs!H42,0) | I6: =ROUND(Inputs!$C$17*Inputs!I42,0) | J6: =ROUND(Inputs!$C$17*Inputs!J42,0) | K6: =ROUND(Inputs!$C$17*Inputs!K42,0) | L6: =ROUND(Inputs!$C$17*Inputs!L42,0) | M6: =ROUND(Inputs!$C$17*Inputs!M42,0) | ... AE6: =ROUND(Inputs!$C$17*Inputs!AE42,0) | AF6: =SUM(F6:AE6)
B7: Selling Price | F7: =Inputs!$C$10 | G7: =Inputs!$C$10 | H7: =Inputs!$C$10 | I7: =Inputs!$C$10 | J7: =Inputs!$C$10 | K7: =Inputs!$C$10 | L7: =Inputs!$C$10 | M7: =Inputs!$C$10 | ... AF7: =Inputs!$C$10
B8: Revenue | F8: =F6*F7 | G8: =G6*G7 | H8: =H6*H7 | I8: =I6*I7 | J8: =J6*J7 | K8: =K6*K7 | L8: =L6*L7 | M8: =M6*M7 | ... AE8: =AE6*AE7 | AF8: =SUM(F8:AE8)
B9: Cost Price | F9: =Inputs!$C$11 | G9: =Inputs!$C$11 | H9: =Inputs!$C$11 | I9: =Inputs!$C$11 | J9: =Inputs!$C$11 | K9: =Inputs!$C$11 | L9: =Inputs!$C$11 | M9: =Inputs!$C$11 | ... AF9: =Inputs!$C$11
B10: Raw COGS | F10: =F6*F9 | G10: =G6*G9 | H10: =H6*H9 | I10: =I6*I9 | J10: =J6*J9 | K10: =K6*K9 | L10: =L6*L9 | M10: =M6*M9 | ... AE10: =AE6*AE9 | AF10: =SUM(F10:AE10)
B11: — Demo Spend | F11: =Inputs!F36*Inputs!$C$22 | G11: =Inputs!G36*Inputs!$C$22 | H11: =Inputs!H36*Inputs!$C$22 | I11: =Inputs!I36*Inputs!$C$22 | J11: =Inputs!J36*Inputs!$C$22 | K11: =Inputs!K36*Inputs!$C$22 | L11: =Inputs!L36*Inputs!$C$22 | M11: =Inputs!M36*Inputs!$C$22 | ... AE11: =Inputs!AE36*Inputs!$C$22 | AF11: =SUM(F11:AE11)
B12: — End Cap Spend | F12: =Inputs!F37*Inputs!$C$25 | G12: =Inputs!G37*Inputs!$C$25 | H12: =Inputs!H37*Inputs!$C$25 | I12: =Inputs!I37*Inputs!$C$25 | J12: =Inputs!J37*Inputs!$C$25 | K12: =Inputs!K37*Inputs!$C$25 | L12: =Inputs!L37*Inputs!$C$25 | M12: =Inputs!M37*Inputs!$C$25 | ... AE12: =Inputs!AE37*Inputs!$C$25 | AF12: =SUM(F12:AE12)
B13: — Fence Spend | F13: =Inputs!F38*Inputs!$C$26 | G13: =Inputs!G38*Inputs!$C$26 | H13: =Inputs!H38*Inputs!$C$26 | I13: =Inputs!I38*Inputs!$C$26 | J13: =Inputs!J38*Inputs!$C$26 | K13: =Inputs!K38*Inputs!$C$26 | L13: =Inputs!L38*Inputs!$C$26 | M13: =Inputs!M38*Inputs!$C$26 | ... AE13: =Inputs!AE38*Inputs!$C$26 | AF13: =SUM(F13:AE13)
B14: — TPD Spend | F14: =Inputs!F39*F6*F7*Inputs!$C$28 | G14: =Inputs!G39*G6*G7*Inputs!$C$28 | H14: =Inputs!H39*H6*H7*Inputs!$C$28 | I14: =Inputs!I39*I6*I7*Inputs!$C$28 | J14: =Inputs!J39*J6*J7*Inputs!$C$28 | K14: =Inputs!K39*K6*K7*Inputs!$C$28 | L14: =Inputs!L39*L6*L7*Inputs!$C$28 | M14: =Inputs!M39*M6*M7*Inputs!$C$28 | ... AE14: =Inputs!AE39*AE6*AE7*Inputs!$C$28 | AF14: =SUM(F14:AE14)
B15: — Markdown Spend | F15: =Inputs!F40*F6*F7*Inputs!$C$29 | G15: =Inputs!G40*G6*G7*Inputs!$C$29 | H15: =Inputs!H40*H6*H7*Inputs!$C$29 | I15: =Inputs!I40*I6*I7*Inputs!$C$29 | J15: =Inputs!J40*J6*J7*Inputs!$C$29 | K15: =Inputs!K40*K6*K7*Inputs!$C$29 | L15: =Inputs!L40*L6*L7*Inputs!$C$29 | M15: =Inputs!M40*M6*M7*Inputs!$C$29 | ... AE15: =Inputs!AE40*AE6*AE7*Inputs!$C$29 | AF15: =SUM(F15:AE15)
B16: — Advertising Spend | F16: =Inputs!F41*Inputs!$C$27 | G16: =Inputs!G41*Inputs!$C$27 | H16: =Inputs!H41*Inputs!$C$27 | I16: =Inputs!I41*Inputs!$C$27 | J16: =Inputs!J41*Inputs!$C$27 | K16: =Inputs!K41*Inputs!$C$27 | L16: =Inputs!L41*Inputs!$C$27 | M16: =Inputs!M41*Inputs!$C$27 | ... AE16: =Inputs!AE41*Inputs!$C$27 | AF16: =SUM(F16:AE16)
B17: Total Promo Spend | F17: =SUM(F11:F16) | G17: =SUM(G11:G16) | H17: =SUM(H11:H16) | I17: =SUM(I11:I16) | J17: =SUM(J11:J16) | K17: =SUM(K11:K16) | L17: =SUM(L11:L16) | M17: =SUM(M11:M16) | ... AE17: =SUM(AE11:AE16) | AF17: =SUM(F17:AE17)
B18: Gross Profit | F18: =F8-F10 | G18: =G8-G10 | H18: =H8-H10 | I18: =I8-I10 | J18: =J8-J10 | K18: =K8-K10 | L18: =L8-L10 | M18: =M8-M10 | ... AE18: =AE8-AE10 | AF18: =SUM(F18:AE18)
B19: Net Profit (after promo) | F19: =F18-F17 | G19: =G18-G17 | H19: =H18-H17 | I19: =I18-I17 | J19: =J18-J17 | K19: =K18-K17 | L19: =L18-L17 | M19: =M18-M17 | ... AE19: =AE18-AE17 | AF19: =SUM(F19:AE19)
B22: IDEAL – x2 Demo + End Cap (Wks 5-6) + TPD
B23: Week | F23: W2 | G23: W3 | H23: W4 | I23: W5 | J23: W6 | K23: W7 | L23: W8 | M23: W9 | N23: W10 | O23: W11 | P23: W12 | Q23: W13 | R23: W14 | S23: W15 | T23: W16 | U23: W17 | V23: W18 | W23: W19 | X23: W20 | Y23: W21 | Z23: W22 | AA23: W23 | AB23: W24 | AC23: W25 | AD23: W26 | AE23: W27 | AF23: TOTAL
B24: POS Units | F24: =ROUND(Inputs!$C$17*Inputs!F53,0) | G24: =ROUND(Inputs!$C$17*Inputs!G53,0) | H24: =ROUND(Inputs!$C$17*Inputs!H53,0) | I24: =ROUND(Inputs!$C$17*Inputs!I53,0) | J24: =ROUND(Inputs!$C$17*Inputs!J53,0) | K24: =ROUND(Inputs!$C$17*Inputs!K53,0) | L24: =ROUND(Inputs!$C$17*Inputs!L53,0) | M24: =ROUND(Inputs!$C$17*Inputs!M53,0) | ... AE24: =ROUND(Inputs!$C$17*Inputs!AE53,0) | AF24: =SUM(F24:AE24)
B25: Selling Price | F25: =Inputs!$C$10 | G25: =Inputs!$C$10 | H25: =Inputs!$C$10 | I25: =Inputs!$C$10 | J25: =Inputs!$C$10 | K25: =Inputs!$C$10 | L25: =Inputs!$C$10 | M25: =Inputs!$C$10 | ... AF25: =Inputs!$C$10
B26: Revenue | F26: =F24*F25 | G26: =G24*G25 | H26: =H24*H25 | I26: =I24*I25 | J26: =J24*J25 | K26: =K24*K25 | L26: =L24*L25 | M26: =M24*M25 | ... AE26: =AE24*AE25 | AF26: =SUM(F26:AE26)
B27: Cost Price | F27: =Inputs!$C$11 | G27: =Inputs!$C$11 | H27: =Inputs!$C$11 | I27: =Inputs!$C$11 | J27: =Inputs!$C$11 | K27: =Inputs!$C$11 | L27: =Inputs!$C$11 | M27: =Inputs!$C$11 | ... AF27: =Inputs!$C$11
B28: Raw COGS | F28: =F24*F27 | G28: =G24*G27 | H28: =H24*H27 | I28: =I24*I27 | J28: =J24*J27 | K28: =K24*K27 | L28: =L24*L27 | M28: =M24*M27 | ... AE28: =AE24*AE27 | AF28: =SUM(F28:AE28)
B29: — Demo Spend | F29: =Inputs!F47*Inputs!$C$22 | G29: =Inputs!G47*Inputs!$C$22 | H29: =Inputs!H47*Inputs!$C$22 | I29: =Inputs!I47*Inputs!$C$22 | J29: =Inputs!J47*Inputs!$C$22 | K29: =Inputs!K47*Inputs!$C$22 | L29: =Inputs!L47*Inputs!$C$22 | M29: =Inputs!M47*Inputs!$C$22 | ... AE29: =Inputs!AE47*Inputs!$C$22 | AF29: =SUM(F29:AE29)
B30: — End Cap Spend | F30: =Inputs!F48*Inputs!$C$25 | G30: =Inputs!G48*Inputs!$C$25 | H30: =Inputs!H48*Inputs!$C$25 | I30: =Inputs!I48*Inputs!$C$25 | J30: =Inputs!J48*Inputs!$C$25 | K30: =Inputs!K48*Inputs!$C$25 | L30: =Inputs!L48*Inputs!$C$25 | M30: =Inputs!M48*Inputs!$C$25 | ... AE30: =Inputs!AE48*Inputs!$C$25 | AF30: =SUM(F30:AE30)
B31: — Fence Spend | F31: =Inputs!F49*Inputs!$C$26 | G31: =Inputs!G49*Inputs!$C$26 | H31: =Inputs!H49*Inputs!$C$26 | I31: =Inputs!I49*Inputs!$C$26 | J31: =Inputs!J49*Inputs!$C$26 | K31: =Inputs!K49*Inputs!$C$26 | L31: =Inputs!L49*Inputs!$C$26 | M31: =Inputs!M49*Inputs!$C$26 | ... AE31: =Inputs!AE49*Inputs!$C$26 | AF31: =SUM(F31:AE31)
B32: — TPD Spend | F32: =Inputs!F50*F24*F25*Inputs!$C$28 | G32: =Inputs!G50*G24*G25*Inputs!$C$28 | H32: =Inputs!H50*H24*H25*Inputs!$C$28 | I32: =Inputs!I50*I24*I25*Inputs!$C$28 | J32: =Inputs!J50*J24*J25*Inputs!$C$28 | K32: =Inputs!K50*K24*K25*Inputs!$C$28 | L32: =Inputs!L50*L24*L25*Inputs!$C$28 | M32: =Inputs!M50*M24*M25*Inputs!$C$28 | ... AE32: =Inputs!AE50*AE24*AE25*Inputs!$C$28 | AF32: =SUM(F32:AE32)
B33: — Markdown Spend | F33: =Inputs!F51*F24*F25*Inputs!$C$29 | G33: =Inputs!G51*G24*G25*Inputs!$C$29 | H33: =Inputs!H51*H24*H25*Inputs!$C$29 | I33: =Inputs!I51*I24*I25*Inputs!$C$29 | J33: =Inputs!J51*J24*J25*Inputs!$C$29 | K33: =Inputs!K51*K24*K25*Inputs!$C$29 | L33: =Inputs!L51*L24*L25*Inputs!$C$29 | M33: =Inputs!M51*M24*M25*Inputs!$C$29 | ... AE33: =Inputs!AE51*AE24*AE25*Inputs!$C$29 | AF33: =SUM(F33:AE33)
B34: — Advertising Spend | F34: =Inputs!F52*Inputs!$C$27 | G34: =Inputs!G52*Inputs!$C$27 | H34: =Inputs!H52*Inputs!$C$27 | I34: =Inputs!I52*Inputs!$C$27 | J34: =Inputs!J52*Inputs!$C$27 | K34: =Inputs!K52*Inputs!$C$27 | L34: =Inputs!L52*Inputs!$C$27 | M34: =Inputs!M52*Inputs!$C$27 | ... AE34: =Inputs!AE52*Inputs!$C$27 | AF34: =SUM(F34:AE34)
B35: Total Promo Spend | F35: =SUM(F29:F34) | G35: =SUM(G29:G34) | H35: =SUM(H29:H34) | I35: =SUM(I29:I34) | J35: =SUM(J29:J34) | K35: =SUM(K29:K34) | L35: =SUM(L29:L34) | M35: =SUM(M29:M34) | ... AE35: =SUM(AE29:AE34) | AF35: =SUM(F35:AE35)
B36: Gross Profit | F36: =F26-F28 | G36: =G26-G28 | H36: =H26-H28 | I36: =I26-I28 | J36: =J26-J28 | K36: =K26-K28 | L36: =L26-L28 | M36: =M26-M28 | ... AE36: =AE26-AE28 | AF36: =SUM(F36:AE36)
B37: Net Profit (after promo) | F37: =F36-F35 | G37: =G36-G35 | H37: =H36-H35 | I37: =I36-I35 | J37: =J36-J35 | K37: =K36-K35 | L37: =L36-L35 | M37: =M36-M35 | ... AE37: =AE36-AE35 | AF37: =SUM(F37:AE37)
B40: WORST – Demo+EndCap+TPD then Markdown (Wks 18-20)
B41: Week | F41: W2 | G41: W3 | H41: W4 | I41: W5 | J41: W6 | K41: W7 | L41: W8 | M41: W9 | N41: W10 | O41: W11 | P41: W12 | Q41: W13 | R41: W14 | S41: W15 | T41: W16 | U41: W17 | V41: W18 | W41: W19 | X41: W20 | Y41: W21 | Z41: W22 | AA41: W23 | AB41: W24 | AC41: W25 | AD41: W26 | AE41: W27 | AF41: TOTAL
B42: POS Units | F42: =ROUND(Inputs!$C$17*Inputs!F64,0) | G42: =ROUND(Inputs!$C$17*Inputs!G64,0) | H42: =ROUND(Inputs!$C$17*Inputs!H64,0) | I42: =ROUND(Inputs!$C$17*Inputs!I64,0) | J42: =ROUND(Inputs!$C$17*Inputs!J64,0) | K42: =ROUND(Inputs!$C$17*Inputs!K64,0) | L42: =ROUND(Inputs!$C$17*Inputs!L64,0) | M42: =ROUND(Inputs!$C$17*Inputs!M64,0) | ... AE42: =ROUND(Inputs!$C$17*Inputs!AE64,0) | AF42: =SUM(F42:AE42)
B43: Selling Price | F43: =Inputs!$C$10 | G43: =Inputs!$C$10 | H43: =Inputs!$C$10 | I43: =Inputs!$C$10 | J43: =Inputs!$C$10 | K43: =Inputs!$C$10 | L43: =Inputs!$C$10 | M43: =Inputs!$C$10 | ... AF43: =Inputs!$C$10
B44: Revenue | F44: =F42*F43 | G44: =G42*G43 | H44: =H42*H43 | I44: =I42*I43 | J44: =J42*J43 | K44: =K42*K43 | L44: =L42*L43 | M44: =M42*M43 | ... AE44: =AE42*AE43 | AF44: =SUM(F44:AE44)
B45: Cost Price | F45: =Inputs!$C$11 | G45: =Inputs!$C$11 | H45: =Inputs!$C$11 | I45: =Inputs!$C$11 | J45: =Inputs!$C$11 | K45: =Inputs!$C$11 | L45: =Inputs!$C$11 | M45: =Inputs!$C$11 | ... AF45: =Inputs!$C$11
B46: Raw COGS | F46: =F42*F45 | G46: =G42*G45 | H46: =H42*H45 | I46: =I42*I45 | J46: =J42*J45 | K46: =K42*K45 | L46: =L42*L45 | M46: =M42*M45 | ... AE46: =AE42*AE45 | AF46: =SUM(F46:AE46)
...

Sheet Summary
B2: ROI SUMMARY — Scenario Comparison
B4: Metric | C4: BEST | D4: IDEAL | E4: WORST
B5: Units Sold | C5: =Forecast!AF6 | D5: =Forecast!AF24 | E5: =Forecast!AF42
B6: Revenue | C6: =Forecast!AF8 | D6: =Forecast!AF26 | E6: =Forecast!AF44
B7: Raw COGS | C7: =Forecast!AF10 | D7: =Forecast!AF28 | E7: =Forecast!AF46
B8: Gross Profit | C8: =Forecast!AF18 | D8: =Forecast!AF36 | E8: =Forecast!AF54
B9: Gross Margin % | C9: =IFERROR(Forecast!AF18/Forecast!AF8,0) | D9: =IFERROR(Forecast!AF36/Forecast!AF26,0) | E9: =IFERROR(Forecast!AF54/Forecast!AF44,0)
B10: Demo Spend | C10: =Forecast!AF11 | D10: =Forecast!AF29 | E10: =Forecast!AF47
B11: End Cap Spend | C11: =Forecast!AF12 | D11: =Forecast!AF30 | E11: =Forecast!AF48
B12: Fence Spend | C12: =Forecast!AF13 | D12: =Forecast!AF31 | E12: =Forecast!AF49
B13: TPD Spend | C13: =Forecast!AF14 | D13: =Forecast!AF32 | E13: =Forecast!AF50
B14: Markdown Spend | C14: =Forecast!AF15 | D14: =Forecast!AF33 | E14: =Forecast!AF51
B15: Advertising Spend | C15: =Forecast!AF16 | D15: =Forecast!AF34 | E15: =Forecast!AF52
B16: Total Promo Spend | C16: =Forecast!AF17 | D16: =Forecast!AF35 | E16: =Forecast!AF53
B17: Net Profit | C17: =Forecast!AF19 | D17: =Forecast!AF37 | E17: =Forecast!AF55
B18: Net Margin % | C18: =IFERROR(Forecast!AF19/Forecast!AF8,0) | D18: =IFERROR(Forecast!AF37/Forecast!AF26,0) | E18: =IFERROR(Forecast!AF55/Forecast!AF44,0)
B19: ROI on Promo Spend | C19: =IFERROR(Forecast!AF19/Forecast!AF17,0) | D19: =IFERROR(Forecast!AF37/Forecast!AF35,0) | E19: =IFERROR(Forecast!AF55/Forecast!AF53,0)
B20: Avg Units / WH / Week | C20: =IFERROR(Forecast!AF6/Inputs!$C$6/Inputs!$C$7,0) | D20: =IFERROR(Forecast!AF24/Inputs!$C$6/Inputs!$C$7,0) | E20: =IFERROR(Forecast!AF42/Inputs!$C$6/Inputs!$C$7,0)
B23: Why each scenario?
B24: BEST | C24: Two national demo weekends combined with a TPD price promo. Demo lifts unit velocity ~3x in-week (Costco benchmark for supplements). No end cap booked, no markdown needed.
B25: IDEAL | C25: Full-court press: demo + end cap + TPD all running together for two weeks. Stacking end cap on demo weeks lifts velocity to ~3.6x (incremental ~20% on top of demo-only).
B26: WORST | C26: Same launch plan as IDEAL but sell-through stalls after the promo weeks. Residual inventory is cleared via three weeks of 50% markdown (Wks 18-20). Wk 20 spike reflects clearance blow-out (~2,400 units in one week).
