Workbook
Name StartDate: Inputs!$C$20
Name WHs: Inputs!$C$21
Name Period: Inputs!$C$22
Name Price: Inputs!$C$25
Name Cost: Inputs!$C$26
Name BaseUnits: Inputs!$C$32
Name DemoCost: Inputs!$C$37
Name EndCapCost: Inputs!$C$41
Name FenceCost: Inputs!$C$42
Name AdvertCost: Inputs!$C$43
Name TPDPct: Inputs!$C$44
Name MdPct: Inputs!$C$45

Sheet README
B2: Costco UK — D93 Portfolio ROI Model
B3: v7.0 · Currency dropdown on every tab
B5: HOW TO USE
B7: 1. Display Currency. Every tab has its own dropdown (GBP / USD / CAD / EUR)
B8: at the top. Switching the dropdown on a tab converts every money cell on
B9: that tab and updates the column headers with the right symbol.
B11: 2. FX rates live in one place — the FX Rate Table on the Inputs sheet.
B12: Edit any rate there and every tab updates.
B14: 3. Tabs are INDEPENDENT. Set them all to the same currency for a consistent
B15: pitch deck view, or set them differently if you want to compare. Summary
B16: automatically adjusts its pull from Forecast if the two tabs disagree.
B18: 4. Inputs themselves stay in GBP — the source of truth for the brand's
... B31: Grey: Reference / structure

Sheet Inputs
B2: INPUTS & ASSUMPTIONS — change any yellow cell
B3: Field | C3: Value | D3: Notes / justification
B5: 1. Display Currency
B6: Display Currency | C6: GBP | D6: Dropdown. Inputs stays in GBP — this selection is informational here. Each display tab has its own currency dropdown that drives that tab.
B7: FX Rate (auto, from table) | C7: =VLOOKUP(C6,B13:D16,3,FALSE) | D7: Reference only — display tabs each look up their own rate.
B8: Currency Symbol (auto) | C8: =VLOOKUP(C6,B13:D16,2,FALSE) | D8: Reference only.
B10: FX Rate Table — edit rates as needed (rate is per 1 GBP)
B12: Code | C12: Symbol | D12: Rate (× GBP)
B13: GBP | C13: £ | D13: 1
B14: USD | C14: $ | D14: 1.27
B15: CAD | C15: C$ | D15: 1.71
B16: EUR | C16: € | D16: 1.17
B18: 2. Product & Distribution
B19: SKU | C19: Bee Propolis Spray 30ml x 2 | D19: Costco UK market test SKU.
B20: Test Start Date (W1) | C20: 46034 | D20: Week-commencing date for W1.
B21: Test Warehouses | C21: 20 | D21: Warehouses in test.
B22: Test Period (Weeks) | C22: 26 | D22: Forecast horizon (26 weeks).
B24: 3. Pricing & Cost (per unit, GBP)
B25: Selling Price (MSRP, £) | C25: 15.99 | D25: Retail per pack.
B26: Cost Price (landed, £) | C26: 7.29 | D26: Brand cost delivered.
B27: Gross Margin per unit (£) | C27: =C25-C26 | D27: Default = SP − Cost.
B28: Gross Margin % | C28: =IFERROR((C25-C26)/C25,0) | D28: Default = GP ÷ SP.
B30: 4. Base Demand (no promo)
B31: Units / Warehouse / Week | C31: 13.79 | D31: Prior 30ml SKU run-rate (500 × 0.8 / 29).
B32: Base Units / Week (all warehouses) | C32: =C31*C21 | D32: Default = per-wh rate × warehouses.
B34: 5. Promo Economics (GBP)
B35: Demo £ / warehouse / week | C35: 199 | D35: Costco demo rate.
B36: Demo cost factor | C36: 1.86 | D36: Overhead multiplier.
B37: Demo Total £ / week | C37: =C35*C21*C36 | D37: Default = rate × wh × factor.
B38: End Cap £ / warehouse / booking | C38: 850 | D38: End cap rental.
B39: End Cap cost factor | C39: 1.86 | D39: Same multiplier.
B40: End Cap booking cycle (weeks) | C40: 2 | D40: Per-week cost = total ÷ this.
B41: End Cap Total £ / week | C41: =C38*C21*C39/C40 | D41: Default = rate × wh × factor ÷ cycle.
B42: Fence £ / week (when active) | C42: 0 | D42: Not currently budgeted.
B43: Advertising £ / week (when active) | C43: 0 | D43: Not currently budgeted.
B44: TPD discount % (of net) | C44: 0.25 | D44: 20% off MSRP ≈ 25% on net.
B45: Markdown discount % | C45: 0.5 | D45: Clearance pricing.
B47: 6. Scenario activity & demand lift
B48: Toggle 1 = promo active, 0 = off. Lift is demand multiplier vs base. Dates auto-fill.
B50: BEST – x2 Demo (Wks 5-6) + TPD
...

Sheet Forecast
B2: ="FORECAST — Weekly P&L by Scenario (Display: "&$G$3&" "&$C$3&")"
B3: Display Currency: | C3: GBP | D3: FX Rate (× GBP): | E3: =VLOOKUP(C3,Inputs!$B$13:$D$16,3,FALSE) | F3: Symbol: | G3: =VLOOKUP(C3,Inputs!$B$13:$D$16,2,FALSE)
B5: BEST – x2 Demo (Wks 5-6) + TPD
B6: Week | F6: W1 | G6: W2 | H6: W3 | I6: W4 | J6: W5 | K6: W6 | L6: W7 | M6: W8 | N6: W9 | O6: W10 | P6: W11 | Q6: W12 | R6: W13 | S6: W14 | T6: W15 | U6: W16 | V6: W17 | W6: W18 | X6: W19 | Y6: W20 | Z6: W21 | AA6: W22 | AB6: W23 | AC6: W24 | AD6: W25 | AE6: W26 | AF6: TOTAL
B7: Wk-commencing | F7: =StartDate+7*0 | G7: =StartDate+7*1 | H7: =StartDate+7*2 | I7: =StartDate+7*3 | J7: =StartDate+7*4 | K7: =StartDate+7*5 | L7: =StartDate+7*6 | M7: =StartDate+7*7 | N7: =StartDate+7*8 | O7: =StartDate+7*9 | P7: =StartDate+7*10 | Q7: =StartDate+7*11 | R7: =StartDate+7*12 | S7: =StartDate+7*13 | T7: =StartDate+7*14 | U7: =StartDate+7*15 | V7: =StartDate+7*16 | W7: =StartDate+7*17 | X7: =StartDate+7*18 | Y7: =StartDate+7*19 | Z7: =StartDate+7*20 | AA7: =StartDate+7*21 | AB7: =StartDate+7*22 | AC7: =StartDate+7*23 | AD7: =StartDate+7*24 | AE7: =StartDate+7*25
B8: POS Units | F8: =ROUND(BaseUnits*Inputs!F60,0) | G8: =ROUND(BaseUnits*Inputs!G60,0) | H8: =ROUND(BaseUnits*Inputs!H60,0) | I8: =ROUND(BaseUnits*Inputs!I60,0) | J8: =ROUND(BaseUnits*Inputs!J60,0) | K8: =ROUND(BaseUnits*Inputs!K60,0) | L8: =ROUND(BaseUnits*Inputs!L60,0) | M8: =ROUND(BaseUnits*Inputs!M60,0) | ... AE8: =ROUND(BaseUnits*Inputs!AE60,0) | AF8: =SUM(F8:AE8)
B9: ="Selling Price ("&$G$3&")" | F9: =Price*$E$3 | G9: =Price*$E$3 | H9: =Price*$E$3 | I9: =Price*$E$3 | J9: =Price*$E$3 | K9: =Price*$E$3 | L9: =Price*$E$3 | M9: =Price*$E$3 | ... AF9: =Price*$E$3
B10: ="Revenue ("&$G$3&")" | F10: =F8*F9 | G10: =G8*G9 | H10: =H8*H9 | I10: =I8*I9 | J10: =J8*J9 | K10: =K8*K9 | L10: =L8*L9 | M10: =M8*M9 | ... AE10: =AE8*AE9 | AF10: =SUM(F10:AE10)
B11: ="Cost Price ("&$G$3&")" | F11: =Cost*$E$3 | G11: =Cost*$E$3 | H11: =Cost*$E$3 | I11: =Cost*$E$3 | J11: =Cost*$E$3 | K11: =Cost*$E$3 | L11: =Cost*$E$3 | M11: =Cost*$E$3 | ... AF11: =Cost*$E$3
B12: ="Raw COGS ("&$G$3&")" | F12: =F8*F11 | G12: =G8*G11 | H12: =H8*H11 | I12: =I8*I11 | J12: =J8*J11 | K12: =K8*K11 | L12: =L8*L11 | M12: =M8*M11 | ... AE12: =AE8*AE11 | AF12: =SUM(F12:AE12)
B13: ="— Demo Spend ("&$G$3&")" | F13: =Inputs!F54*DemoCost*$E$3 | G13: =Inputs!G54*DemoCost*$E$3 | H13: =Inputs!H54*DemoCost*$E$3 | I13: =Inputs!I54*DemoCost*$E$3 | J13: =Inputs!J54*DemoCost*$E$3 | K13: =Inputs!K54*DemoCost*$E$3 | L13: =Inputs!L54*DemoCost*$E$3 | M13: =Inputs!M54*DemoCost*$E$3 | ... AE13: =Inputs!AE54*DemoCost*$E$3 | AF13: =SUM(F13:AE13)
B14: ="— End Cap Spend ("&$G$3&")" | F14: =Inputs!F55*EndCapCost*$E$3 | G14: =Inputs!G55*EndCapCost*$E$3 | H14: =Inputs!H55*EndCapCost*$E$3 | I14: =Inputs!I55*EndCapCost*$E$3 | J14: =Inputs!J55*EndCapCost*$E$3 | K14: =Inputs!K55*EndCapCost*$E$3 | L14: =Inputs!L55*EndCapCost*$E$3 | M14: =Inputs!M55*EndCapCost*$E$3 | ... AE14: =Inputs!AE55*EndCapCost*$E$3 | AF14: =SUM(F14:AE14)
B15: ="— Fence Spend ("&$G$3&")" | F15: =Inputs!F56*FenceCost*$E$3 | G15: =Inputs!G56*FenceCost*$E$3 | H15: =Inputs!H56*FenceCost*$E$3 | I15: =Inputs!I56*FenceCost*$E$3 | J15: =Inputs!J56*FenceCost*$E$3 | K15: =Inputs!K56*FenceCost*$E$3 | L15: =Inputs!L56*FenceCost*$E$3 | M15: =Inputs!M56*FenceCost*$E$3 | ... AE15: =Inputs!AE56*FenceCost*$E$3 | AF15: =SUM(F15:AE15)
B16: ="— TPD Spend ("&$G$3&")" | F16: =Inputs!F57*F8*F9*TPDPct | G16: =Inputs!G57*G8*G9*TPDPct | H16: =Inputs!H57*H8*H9*TPDPct | I16: =Inputs!I57*I8*I9*TPDPct | J16: =Inputs!J57*J8*J9*TPDPct | K16: =Inputs!K57*K8*K9*TPDPct | L16: =Inputs!L57*L8*L9*TPDPct | M16: =Inputs!M57*M8*M9*TPDPct | ... AE16: =Inputs!AE57*AE8*AE9*TPDPct | AF16: =SUM(F16:AE16)
B17: ="— Markdown Spend ("&$G$3&")" | F17: =Inputs!F58*F8*F9*MdPct | G17: =Inputs!G58*G8*G9*MdPct | H17: =Inputs!H58*H8*H9*MdPct | I17: =Inputs!I58*I8*I9*MdPct | J17: =Inputs!J58*J8*J9*MdPct | K17: =Inputs!K58*K8*K9*MdPct | L17: =Inputs!L58*L8*L9*MdPct | M17: =Inputs!M58*M8*M9*MdPct | ... AE17: =Inputs!AE58*AE8*AE9*MdPct | AF17: =SUM(F17:AE17)
B18: ="— Advertising Spend ("&$G$3&")" | F18: =Inputs!F59*AdvertCost*$E$3 | G18: =Inputs!G59*AdvertCost*$E$3 | H18: =Inputs!H59*AdvertCost*$E$3 | I18: =Inputs!I59*AdvertCost*$E$3 | J18: =Inputs!J59*AdvertCost*$E$3 | K18: =Inputs!K59*AdvertCost*$E$3 | L18: =Inputs!L59*AdvertCost*$E$3 | M18: =Inputs!M59*AdvertCost*$E$3 | ... AE18: =Inputs!AE59*AdvertCost*$E$3 | AF18: =SUM(F18:AE18)
B19: ="Total Promo Spend ("&$G$3&")" | F19: =SUM(F13:F18) | G19: =SUM(G13:G18) | H19: =SUM(H13:H18) | I19: =SUM(I13:I18) | J19: =SUM(J13:J18) | K19: =SUM(K13:K18) | L19: =SUM(L13:L18) | M19: =SUM(M13:M18) | ... AE19: =SUM(AE13:AE18) | AF19: =SUM(F19:AE19)
B20: ="Gross Profit ("&$G$3&")" | F20: =F10-F12 | G20: =G10-G12 | H20: =H10-H12 | I20: =I10-I12 | J20: =J10-J12 | K20: =K10-K12 | L20: =L10-L12 | M20: =M10-M12 | ... AE20: =AE10-AE12 | AF20: =SUM(F20:AE20)
B21: ="Net Profit after promo ("&$G$3&")" | F21: =F20-F19 | G21: =G20-G19 | H21: =H20-H19 | I21: =I20-I19 | J21: =J20-J19 | K21: =K20-K19 | L21: =L20-L19 | M21: =M20-M19 | ... AE21: =AE20-AE19 | AF21: =SUM(F21:AE21)
B24: IDEAL – x2 Demo + End Cap (Wks 5-6) + TPD
B25: Week | F25: W1 | G25: W2 | H25: W3 | I25: W4 | J25: W5 | K25: W6 | L25: W7 | M25: W8 | N25: W9 | O25: W10 | P25: W11 | Q25: W12 | R25: W13 | S25: W14 | T25: W15 | U25: W16 | V25: W17 | W25: W18 | X25: W19 | Y25: W20 | Z25: W21 | AA25: W22 | AB25: W23 | AC25: W24 | AD25: W25 | AE25: W26 | AF25: TOTAL
B26: Wk-commencing | F26: =StartDate+7*0 | G26: =StartDate+7*1 | H26: =StartDate+7*2 | I26: =StartDate+7*3 | J26: =StartDate+7*4 | K26: =StartDate+7*5 | L26: =StartDate+7*6 | M26: =StartDate+7*7 | N26: =StartDate+7*8 | O26: =StartDate+7*9 | P26: =StartDate+7*10 | Q26: =StartDate+7*11 | R26: =StartDate+7*12 | S26: =StartDate+7*13 | T26: =StartDate+7*14 | U26: =StartDate+7*15 | V26: =StartDate+7*16 | W26: =StartDate+7*17 | X26: =StartDate+7*18 | Y26: =StartDate+7*19 | Z26: =StartDate+7*20 | AA26: =StartDate+7*21 | AB26: =StartDate+7*22 | AC26: =StartDate+7*23 | AD26: =StartDate+7*24 | AE26: =StartDate+7*25
B27: POS Units | F27: =ROUND(BaseUnits*Inputs!F72,0) | G27: =ROUND(BaseUnits*Inputs!G72,0) | H27: =ROUND(BaseUnits*Inputs!H72,0) | I27: =ROUND(BaseUnits*Inputs!I72,0) | J27: =ROUND(BaseUnits*Inputs!J72,0) | K27: =ROUND(BaseUnits*Inputs!K72,0) | L27: =ROUND(BaseUnits*Inputs!L72,0) | M27: =ROUND(BaseUnits*Inputs!M72,0) | ... AE27: =ROUND(BaseUnits*Inputs!AE72,0) | AF27: =SUM(F27:AE27)
B28: ="Selling Price ("&$G$3&")" | F28: =Price*$E$3 | G28: =Price*$E$3 | H28: =Price*$E$3 | I28: =Price*$E$3 | J28: =Price*$E$3 | K28: =Price*$E$3 | L28: =Price*$E$3 | M28: =Price*$E$3 | ... AF28: =Price*$E$3
B29: ="Revenue ("&$G$3&")" | F29: =F27*F28 | G29: =G27*G28 | H29: =H27*H28 | I29: =I27*I28 | J29: =J27*J28 | K29: =K27*K28 | L29: =L27*L28 | M29: =M27*M28 | ... AE29: =AE27*AE28 | AF29: =SUM(F29:AE29)
B30: ="Cost Price ("&$G$3&")" | F30: =Cost*$E$3 | G30: =Cost*$E$3 | H30: =Cost*$E$3 | I30: =Cost*$E$3 | J30: =Cost*$E$3 | K30: =Cost*$E$3 | L30: =Cost*$E$3 | M30: =Cost*$E$3 | ... AF30: =Cost*$E$3
B31: ="Raw COGS ("&$G$3&")" | F31: =F27*F30 | G31: =G27*G30 | H31: =H27*H30 | I31: =I27*I30 | J31: =J27*J30 | K31: =K27*K30 | L31: =L27*L30 | M31: =M27*M30 | ... AE31: =AE27*AE30 | AF31: =SUM(F31:AE31)
B32: ="— Demo Spend ("&$G$3&")" | F32: =Inputs!F66*DemoCost*$E$3 | G32: =Inputs!G66*DemoCost*$E$3 | H32: =Inputs!H66*DemoCost*$E$3 | I32: =Inputs!I66*DemoCost*$E$3 | J32: =Inputs!J66*DemoCost*$E$3 | K32: =Inputs!K66*DemoCost*$E$3 | L32: =Inputs!L66*DemoCost*$E$3 | M32: =Inputs!M66*DemoCost*$E$3 | ... AE32: =Inputs!AE66*DemoCost*$E$3 | AF32: =SUM(F32:AE32)
B33: ="— End Cap Spend ("&$G$3&")" | F33: =Inputs!F67*EndCapCost*$E$3 | G33: =Inputs!G67*EndCapCost*$E$3 | H33: =Inputs!H67*EndCapCost*$E$3 | I33: =Inputs!I67*EndCapCost*$E$3 | J33: =Inputs!J67*EndCapCost*$E$3 | K33: =Inputs!K67*EndCapCost*$E$3 | L33: =Inputs!L67*EndCapCost*$E$3 | M33: =Inputs!M67*EndCapCost*$E$3 | ... AE33: =Inputs!AE67*EndCapCost*$E$3 | AF33: =SUM(F33:AE33)
B34: ="— Fence Spend ("&$G$3&")" | F34: =Inputs!F68*FenceCost*$E$3 | G34: =Inputs!G68*FenceCost*$E$3 | H34: =Inputs!H68*FenceCost*$E$3 | I34: =Inputs!I68*FenceCost*$E$3 | J34: =Inputs!J68*FenceCost*$E$3 | K34: =Inputs!K68*FenceCost*$E$3 | L34: =Inputs!L68*FenceCost*$E$3 | M34: =Inputs!M68*FenceCost*$E$3 | ... AE34: =Inputs!AE68*FenceCost*$E$3 | AF34: =SUM(F34:AE34)
B35: ="— TPD Spend ("&$G$3&")" | F35: =Inputs!F69*F27*F28*TPDPct | G35: =Inputs!G69*G27*G28*TPDPct | H35: =Inputs!H69*H27*H28*TPDPct | I35: =Inputs!I69*I27*I28*TPDPct | J35: =Inputs!J69*J27*J28*TPDPct | K35: =Inputs!K69*K27*K28*TPDPct | L35: =Inputs!L69*L27*L28*TPDPct | M35: =Inputs!M69*M27*M28*TPDPct | ... AE35: =Inputs!AE69*AE27*AE28*TPDPct | AF35: =SUM(F35:AE35)
B36: ="— Markdown Spend ("&$G$3&")" | F36: =Inputs!F70*F27*F28*MdPct | G36: =Inputs!G70*G27*G28*MdPct | H36: =Inputs!H70*H27*H28*MdPct | I36: =Inputs!I70*I27*I28*MdPct | J36: =Inputs!J70*J27*J28*MdPct | K36: =Inputs!K70*K27*K28*MdPct | L36: =Inputs!L70*L27*L28*MdPct | M36: =Inputs!M70*M27*M28*MdPct | ... AE36: =Inputs!AE70*AE27*AE28*MdPct | AF36: =SUM(F36:AE36)
B37: ="— Advertising Spend ("&$G$3&")" | F37: =Inputs!F71*AdvertCost*$E$3 | G37: =Inputs!G71*AdvertCost*$E$3 | H37: =Inputs!H71*AdvertCost*$E$3 | I37: =Inputs!I71*AdvertCost*$E$3 | J37: =Inputs!J71*AdvertCost*$E$3 | K37: =Inputs!K71*AdvertCost*$E$3 | L37: =Inputs!L71*AdvertCost*$E$3 | M37: =Inputs!M71*AdvertCost*$E$3 | ... AE37: =Inputs!AE71*AdvertCost*$E$3 | AF37: =SUM(F37:AE37)
B38: ="Total Promo Spend ("&$G$3&")" | F38: =SUM(F32:F37) | G38: =SUM(G32:G37) | H38: =SUM(H32:H37) | I38: =SUM(I32:I37) | J38: =SUM(J32:J37) | K38: =SUM(K32:K37) | L38: =SUM(L32:L37) | M38: =SUM(M32:M37) | ... AE38: =SUM(AE32:AE37) | AF38: =SUM(F38:AE38)
B39: ="Gross Profit ("&$G$3&")" | F39: =F29-F31 | G39: =G29-G31 | H39: =H29-H31 | I39: =I29-I31 | J39: =J29-J31 | K39: =K29-K31 | L39: =L29-L31 | M39: =M29-M31 | ... AE39: =AE29-AE31 | AF39: =SUM(F39:AE39)
B40: ="Net Profit after promo ("&$G$3&")" | F40: =F39-F38 | G40: =G39-G38 | H40: =H39-H38 | I40: =I39-I38 | J40: =J39-J38 | K40: =K39-K38 | L40: =L39-L38 | M40: =M39-M38 | ... AE40: =AE39-AE38 | AF40: =SUM(F40:AE40)
B43: WORST – Demo+EndCap+TPD then Markdown (Wks 18-20)
B44: Week | F44: W1 | G44: W2 | H44: W3 | I44: W4 | J44: W5 | K44: W6 | L44: W7 | M44: W8 | N44: W9 | O44: W10 | P44: W11 | Q44: W12 | R44: W13 | S44: W14 | T44: W15 | U44: W16 | V44: W17 | W44: W18 | X44: W19 | Y44: W20 | Z44: W21 | AA44: W22 | AB44: W23 | AC44: W24 | AD44: W25 | AE44: W26 | AF44: TOTAL
B45: Wk-commencing | F45: =StartDate+7*0 | G45: =StartDate+7*1 | H45: =StartDate+7*2 | I45: =StartDate+7*3 | J45: =StartDate+7*4 | K45: =StartDate+7*5 | L45: =StartDate+7*6 | M45: =StartDate+7*7 | N45: =StartDate+7*8 | O45: =StartDate+7*9 | P45: =StartDate+7*10 | Q45: =StartDate+7*11 | R45: =StartDate+7*12 | S45: =StartDate+7*13 | T45: =StartDate+7*14 | U45: =StartDate+7*15 | V45: =StartDate+7*16 | W45: =StartDate+7*17 | X45: =StartDate+7*18 | Y45: =StartDate+7*19 | Z45: =StartDate+7*20 | AA45: =StartDate+7*21 | AB45: =StartDate+7*22 | AC45: =StartDate+7*23 | AD45: =StartDate+7*24 | AE45: =StartDate+7*25
B46: POS Units | F46: =ROUND(BaseUnits*Inputs!F84,0) | G46: =ROUND(BaseUnits*Inputs!G84,0) | H46: =ROUND(BaseUnits*Inputs!H84,0) | I46: =ROUND(BaseUnits*Inputs!I84,0) | J46: =ROUND(BaseUnits*Inputs!J84,0) | K46: =ROUND(BaseUnits*Inputs!K84,0) | L46: =ROUND(BaseUnits*Inputs!L84,0) | M46: =ROUND(BaseUnits*Inputs!M84,0) | ... AE46: =ROUND(BaseUnits*Inputs!AE84,0) | AF46: =SUM(F46:AE46)
...

Sheet Summary
B2: ="ROI SUMMARY — Bee Propolis Scenario Comparison (Display: "&$G$3&" "&$C$3&")"
B3: Display Currency: | C3: GBP | D3: FX Rate (× GBP): | E3: =VLOOKUP(C3,Inputs!$B$13:$D$16,3,FALSE) | F3: Symbol: | G3: =VLOOKUP(C3,Inputs!$B$13:$D$16,2,FALSE)
B4: ="Test window: W1 ("&TEXT(StartDate,"dd-mmm-yyyy")&") → W"&Period&" ("&TEXT(StartDate+7*(Period-1),"dd-mmm-yyyy")&")"
B6: Metric | C6: BEST | D6: IDEAL | E6: WORST
B7: Units Sold | C7: =Forecast!AF8 | D7: =Forecast!AF27 | E7: =Forecast!AF46
B8: ="Revenue ("&$G$3&")" | C8: =Forecast!AF10*($E$3/Forecast!$E$3) | D8: =Forecast!AF29*($E$3/Forecast!$E$3) | E8: =Forecast!AF48*($E$3/Forecast!$E$3)
B9: ="Raw COGS ("&$G$3&")" | C9: =Forecast!AF12*($E$3/Forecast!$E$3) | D9: =Forecast!AF31*($E$3/Forecast!$E$3) | E9: =Forecast!AF50*($E$3/Forecast!$E$3)
B10: ="Gross Profit ("&$G$3&")" | C10: =Forecast!AF20*($E$3/Forecast!$E$3) | D10: =Forecast!AF39*($E$3/Forecast!$E$3) | E10: =Forecast!AF58*($E$3/Forecast!$E$3)
B11: Gross Margin % | C11: =IFERROR(Forecast!AF20/Forecast!AF10,0) | D11: =IFERROR(Forecast!AF39/Forecast!AF29,0) | E11: =IFERROR(Forecast!AF58/Forecast!AF48,0)
B12: ="Demo Spend ("&$G$3&")" | C12: =Forecast!AF13*($E$3/Forecast!$E$3) | D12: =Forecast!AF32*($E$3/Forecast!$E$3) | E12: =Forecast!AF51*($E$3/Forecast!$E$3)
B13: ="End Cap Spend ("&$G$3&")" | C13: =Forecast!AF14*($E$3/Forecast!$E$3) | D13: =Forecast!AF33*($E$3/Forecast!$E$3) | E13: =Forecast!AF52*($E$3/Forecast!$E$3)
B14: ="Fence Spend ("&$G$3&")" | C14: =Forecast!AF15*($E$3/Forecast!$E$3) | D14: =Forecast!AF34*($E$3/Forecast!$E$3) | E14: =Forecast!AF53*($E$3/Forecast!$E$3)
B15: ="TPD Spend ("&$G$3&")" | C15: =Forecast!AF16*($E$3/Forecast!$E$3) | D15: =Forecast!AF35*($E$3/Forecast!$E$3) | E15: =Forecast!AF54*($E$3/Forecast!$E$3)
B16: ="Markdown Spend ("&$G$3&")" | C16: =Forecast!AF17*($E$3/Forecast!$E$3) | D16: =Forecast!AF36*($E$3/Forecast!$E$3) | E16: =Forecast!AF55*($E$3/Forecast!$E$3)
B17: ="Advertising Spend ("&$G$3&")" | C17: =Forecast!AF18*($E$3/Forecast!$E$3) | D17: =Forecast!AF37*($E$3/Forecast!$E$3) | E17: =Forecast!AF56*($E$3/Forecast!$E$3)
B18: ="Total Promo Spend ("&$G$3&")" | C18: =Forecast!AF19*($E$3/Forecast!$E$3) | D18: =Forecast!AF38*($E$3/Forecast!$E$3) | E18: =Forecast!AF57*($E$3/Forecast!$E$3)
B19: ="Net Profit ("&$G$3&")" | C19: =Forecast!AF21*($E$3/Forecast!$E$3) | D19: =Forecast!AF40*($E$3/Forecast!$E$3) | E19: =Forecast!AF59*($E$3/Forecast!$E$3)
B20: Net Margin % | C20: =IFERROR(Forecast!AF21/Forecast!AF10,0) | D20: =IFERROR(Forecast!AF40/Forecast!AF29,0) | E20: =IFERROR(Forecast!AF59/Forecast!AF48,0)
B21: ROI on Promo Spend | C21: =IFERROR(Forecast!AF21/Forecast!AF19,0) | D21: =IFERROR(Forecast!AF40/Forecast!AF38,0) | E21: =IFERROR(Forecast!AF59/Forecast!AF57,0)
B22: Avg Units / WH / Week | C22: =IFERROR(Forecast!AF8/WHs/Period,0) | D22: =IFERROR(Forecast!AF27/WHs/Period,0) | E22: =IFERROR(Forecast!AF46/WHs/Period,0)
B25: Why each scenario?
B26: BEST | C26: Two demo weekends with TPD. Demo lifts ~3x in-week. No end cap, no markdown.
B27: IDEAL | C27: Demo + end cap + TPD stacked for two weeks. Combined velocity ~3.6x base.
B28: WORST | C28: Promo plan as IDEAL but residual inventory clears at 50% off over Wks 18-20.

Sheet Portfolio
B2: ="PORTFOLIO — D93 Pitch SKUs · Annual Y1 Roll-Up (Display: "&$G$3&" "&$C$3&")"
B3: Display Currency: | C3: GBP | D3: FX Rate (× GBP): | E3: =VLOOKUP(C3,Inputs!$B$13:$D$16,3,FALSE) | F3: Symbol: | G3: =VLOOKUP(C3,Inputs!$B$13:$D$16,2,FALSE)
B4: SP / Cost / Promo are entered in the currently-selected display currency. Bee Propolis pre-filled; fill SKUs 2-7 from Asana into the yellow cells. Bottom row blends across SKUs.
B6: # | C6: Code | D6: SKU | E6: Pack | F6: ="SP ("&$G$3&")" | G6: ="Cost ("&$G$3&")" | H6: ="GM/u ("&$G$3&")" | I6: GM % | J6: Y1 Units | K6: ="Revenue ("&$G$3&")" | L6: ="COGS ("&$G$3&")" | M6: ="GP ("&$G$3&")" | N6: ="Promo ("&$G$3&")" | O6: ="Net Profit ("&$G$3&")" | P6: Net % | Q6: ROI % | R6: Rationale / status
B7: 1 | C7: UK-D93-#1 | D7: Bee Propolis Spray 30ml x2 | E7: 30ml x 2 | F7: 15.99 | G7: 7.29 | H7: =IFERROR(F7-G7,0) | I7: =IFERROR((F7-G7)/F7,0) | J7: 17000 | K7: =IFERROR(J7*F7,0) | L7: =IFERROR(J7*G7,0) | M7: =IFERROR(K7-L7,0) | N7: 25000 | O7: =IFERROR(M7-N7,0) | P7: =IFERROR(O7/K7,0) | Q7: =IFERROR(O7/N7,0) | R7: Lead pitch — strong GP%, supported by demo + TPD.
B8: 2 | C8: UK-D93-#2 | D8: Mag 8-in-1 90's/120's | H8: =IFERROR(F8-G8,0) | I8: =IFERROR((F8-G8)/F8,0) | K8: =IFERROR(J8*F8,0) | L8: =IFERROR(J8*G8,0) | M8: =IFERROR(K8-L8,0) | O8: =IFERROR(M8-N8,0) | P8: =IFERROR(O8/K8,0) | Q8: =IFERROR(O8/N8,0)
B9: 3 | C9: UK-D93-#3 | D9: O1 450g | H9: =IFERROR(F9-G9,0) | I9: =IFERROR((F9-G9)/F9,0) | K9: =IFERROR(J9*F9,0) | L9: =IFERROR(J9*G9,0) | M9: =IFERROR(K9-L9,0) | O9: =IFERROR(M9-N9,0) | P9: =IFERROR(O9/K9,0) | Q9: =IFERROR(O9/N9,0)
B10: 4 | C10: UK-D93-#4 | D10: Belli Bliss Raspberry, 450g | H10: =IFERROR(F10-G10,0) | I10: =IFERROR((F10-G10)/F10,0) | K10: =IFERROR(J10*F10,0) | L10: =IFERROR(J10*G10,0) | M10: =IFERROR(K10-L10,0) | O10: =IFERROR(M10-N10,0) | P10: =IFERROR(O10/K10,0) | Q10: =IFERROR(O10/N10,0)
B11: 5 | C11: UK-D93-#5 | D11: Daily Boost | H11: =IFERROR(F11-G11,0) | I11: =IFERROR((F11-G11)/F11,0) | K11: =IFERROR(J11*F11,0) | L11: =IFERROR(J11*G11,0) | M11: =IFERROR(K11-L11,0) | O11: =IFERROR(M11-N11,0) | P11: =IFERROR(O11/K11,0) | Q11: =IFERROR(O11/N11,0)
B12: 6 | C12: UK-D93-#6 | D12: Berberine 90's/120's | H12: =IFERROR(F12-G12,0) | I12: =IFERROR((F12-G12)/F12,0) | K12: =IFERROR(J12*F12,0) | L12: =IFERROR(J12*G12,0) | M12: =IFERROR(K12-L12,0) | O12: =IFERROR(M12-N12,0) | P12: =IFERROR(O12/K12,0) | Q12: =IFERROR(O12/N12,0)
B13: 7 | C13: UK-D93-#7 | D13: L-theanine Capsules 90's/120's | H13: =IFERROR(F13-G13,0) | I13: =IFERROR((F13-G13)/F13,0) | K13: =IFERROR(J13*F13,0) | L13: =IFERROR(J13*G13,0) | M13: =IFERROR(K13-L13,0) | O13: =IFERROR(M13-N13,0) | P13: =IFERROR(O13/K13,0) | Q13: =IFERROR(O13/N13,0)
D14: PORTFOLIO TOTAL / BLENDED | I14: =IFERROR(SUM(M7:M13)/SUM(K7:K13),0) | J14: =SUM(J7:J13) | K14: =SUM(K7:K13) | L14: =SUM(L7:L13) | M14: =SUM(M7:M13) | N14: =SUM(N7:N13) | O14: =SUM(O7:O13) | P14: =IFERROR(O14/K14,0) | Q14: =IFERROR(O14/N14,0) | R14: Blended across SKUs
