Workbook
Name StartDate: Inputs!$C$21
Name WHs: Inputs!$C$22
Name Period: 26
Name Price: Inputs!$C$25
Name Cost: Inputs!$C$26
Name BaseUnits: Inputs!$C$31
Name DemoCost: Inputs!$C$34
Name EndCapCost: Inputs!$C$35
Name TPDPct: Inputs!$C$36
Name MdPct: Inputs!$C$37

Sheet README
B2: Costco UK — D93 Portfolio ROI
B3: v8 · simplified
B5: HOW TO USE
B7: 1. Open Inputs. Edit any YELLOW cell. Calculated cells (grey) update automatically.
B9: 2. Pick a Display Currency at the top of any tab. Each tab is independent — set them
B10: all the same for a consistent pitch view.
B12: 3. Forecast: 26-week P&L for the Bee Propolis market test under three scenarios.
B13: Summary: side-by-side KPIs across the three scenarios.
B14: Portfolio: annual Y1 roll-up across all seven D93 SKUs with blended margin & ROI.
B16: 4. Test Start Date (W1) on Inputs drives every week column's date.
B18: COLOUR KEY
B19: Yellow: Editable input
... B21: Grey: Calculated

Sheet Inputs
B2: INPUTS — change any yellow cell
B4: 1. Display Currency (master copy — each tab has its own)
B5: Display Currency | C5: GBP | D5: Each display tab has its own dropdown; this one is just here for reference.
B7: FX Rate Table — edit rates (rate is per 1 GBP)
B12: Code | C12: Symbol | D12: Rate (× GBP)
B13: GBP | C13: £ | D13: 1
B14: USD | C14: $ | D14: 1.27
B15: CAD | C15: C$ | D15: 1.71
B16: EUR | C16: € | D16: 1.17
B19: 2. Product & Distribution
B20: SKU | C20: Bee Propolis Spray 30ml x 2 | D20: Costco UK market test SKU.
B21: Test Start Date (W1) | C21: 46034 | D21: Week-commencing date for W1.
B22: Warehouses in test | C22: 20 | D22: Number of Costco UK warehouses.
B24: 3. Pricing (GBP)
B25: Selling Price (MSRP) | C25: 15.99 | D25: Retail per pack.
B26: Cost Price (landed) | C26: 7.29 | D26: Brand cost delivered.
B27: Gross Margin per unit | C27: =C25-C26 | D27: SP − Cost (auto).
B28: Gross Margin % | C28: =IFERROR((C25-C26)/C25,0) | D28: GP ÷ SP (auto).
B30: 4. Base Demand
B31: Base Units / Week (all warehouses) | C31: 276 | D31: Organic weekly sell-through across all test warehouses, no promo.
B33: 5. Promo Economics (GBP)
B34: Demo Total £ / week (all warehouses) | C34: 7403 | D34: All-warehouse demo cost in a demo week. ~£199/wh × 20 wh × 1.86 factor.
B35: End Cap Total £ / week (all warehouses) | C35: 15810 | D35: All-warehouse end cap cost in an end cap week. ~£850/wh × 20 wh × 1.86 ÷ 2-week cycle.
B36: TPD discount % (of net) | C36: 0.25 | D36: 20% off MSRP ≈ 25% off net.
B37: Markdown discount % | C37: 0.5 | D37: Clearance pricing.
B39: 6. Scenario activity (1 = on / 0 = off per week) and demand lift
B41: BEST · Demo + TPD (Wks 5-6)
B42: Rationale: Two demo weekends with TPD. ~3x lift in-promo weeks.
B43: Week | F43: W1 | G43: W2 | H43: W3 | I43: W4 | J43: W5 | K43: W6 | L43: W7 | M43: W8 | N43: W9 | O43: W10 | P43: W11 | Q43: W12 | R43: W13 | S43: W14 | T43: W15 | U43: W16 | V43: W17 | W43: W18 | X43: W19 | Y43: W20 | Z43: W21 | AA43: W22 | AB43: W23 | AC43: W24 | AD43: W25 | AE43: W26
B44: Wk-commencing | F44: =StartDate+7*0 | G44: =StartDate+7*1 | H44: =StartDate+7*2 | I44: =StartDate+7*3 | J44: =StartDate+7*4 | K44: =StartDate+7*5 | L44: =StartDate+7*6 | M44: =StartDate+7*7 | N44: =StartDate+7*8 | O44: =StartDate+7*9 | P44: =StartDate+7*10 | Q44: =StartDate+7*11 | R44: =StartDate+7*12 | S44: =StartDate+7*13 | T44: =StartDate+7*14 | U44: =StartDate+7*15 | V44: =StartDate+7*16 | W44: =StartDate+7*17 | X44: =StartDate+7*18 | Y44: =StartDate+7*19 | Z44: =StartDate+7*20 | AA44: =StartDate+7*21 | AB44: =StartDate+7*22 | AC44: =StartDate+7*23 | AD44: =StartDate+7*24 | AE44: =StartDate+7*25
B45: Demo | F45: 0 | G45: 0 | H45: 0 | I45: 0 | J45: 1 | K45: 1 | L45: 0 | M45: 0 | N45: 0 | O45: 0 | P45: 0 | Q45: 0 | R45: 0 | S45: 0 | T45: 0 | U45: 0 | V45: 0 | W45: 0 | X45: 0 | Y45: 0 | Z45: 0 | AA45: 0 | AB45: 0 | AC45: 0 | AD45: 0 | AE45: 0
B46: End Cap | F46: 0 | G46: 0 | H46: 0 | I46: 0 | J46: 0 | K46: 0 | L46: 0 | M46: 0 | N46: 0 | O46: 0 | P46: 0 | Q46: 0 | R46: 0 | S46: 0 | T46: 0 | U46: 0 | V46: 0 | W46: 0 | X46: 0 | Y46: 0 | Z46: 0 | AA46: 0 | AB46: 0 | AC46: 0 | AD46: 0 | AE46: 0
B47: TPD | F47: 0 | G47: 0 | H47: 0 | I47: 0 | J47: 1 | K47: 1 | L47: 0 | M47: 0 | N47: 0 | O47: 0 | P47: 0 | Q47: 0 | R47: 0 | S47: 0 | T47: 0 | U47: 0 | V47: 0 | W47: 0 | X47: 0 | Y47: 0 | Z47: 0 | AA47: 0 | AB47: 0 | AC47: 0 | AD47: 0 | AE47: 0
B48: Markdown | F48: 0 | G48: 0 | H48: 0 | I48: 0 | J48: 0 | K48: 0 | L48: 0 | M48: 0 | N48: 0 | O48: 0 | P48: 0 | Q48: 0 | R48: 0 | S48: 0 | T48: 0 | U48: 0 | V48: 0 | W48: 0 | X48: 0 | Y48: 0 | Z48: 0 | AA48: 0 | AB48: 0 | AC48: 0 | AD48: 0 | AE48: 0
B49: Lift Multiplier (x base) | F49: 1 | G49: 1 | H49: 1 | I49: 1 | J49: 3 | K49: 3 | L49: 1 | M49: 1 | N49: 1 | O49: 1 | P49: 1 | Q49: 1 | R49: 1 | S49: 1 | T49: 1 | U49: 1 | V49: 1 | W49: 1 | X49: 1 | Y49: 1 | Z49: 1 | AA49: 1 | AB49: 1 | AC49: 1 | AD49: 1 | AE49: 1
B51: IDEAL · Demo + End Cap + TPD (Wks 5-6)
B52: Rationale: Stacked demo + end cap + TPD. ~3.6x lift.
B53: Week | F53: W1 | G53: W2 | H53: W3 | I53: W4 | J53: W5 | K53: W6 | L53: W7 | M53: W8 | N53: W9 | O53: W10 | P53: W11 | Q53: W12 | R53: W13 | S53: W14 | T53: W15 | U53: W16 | V53: W17 | W53: W18 | X53: W19 | Y53: W20 | Z53: W21 | AA53: W22 | AB53: W23 | AC53: W24 | AD53: W25 | AE53: W26
B54: Wk-commencing | F54: =StartDate+7*0 | G54: =StartDate+7*1 | H54: =StartDate+7*2 | I54: =StartDate+7*3 | J54: =StartDate+7*4 | K54: =StartDate+7*5 | L54: =StartDate+7*6 | M54: =StartDate+7*7 | N54: =StartDate+7*8 | O54: =StartDate+7*9 | P54: =StartDate+7*10 | Q54: =StartDate+7*11 | R54: =StartDate+7*12 | S54: =StartDate+7*13 | T54: =StartDate+7*14 | U54: =StartDate+7*15 | V54: =StartDate+7*16 | W54: =StartDate+7*17 | X54: =StartDate+7*18 | Y54: =StartDate+7*19 | Z54: =StartDate+7*20 | AA54: =StartDate+7*21 | AB54: =StartDate+7*22 | AC54: =StartDate+7*23 | AD54: =StartDate+7*24 | AE54: =StartDate+7*25
B55: Demo | F55: 0 | G55: 0 | H55: 0 | I55: 0 | J55: 1 | K55: 1 | L55: 0 | M55: 0 | N55: 0 | O55: 0 | P55: 0 | Q55: 0 | R55: 0 | S55: 0 | T55: 0 | U55: 0 | V55: 0 | W55: 0 | X55: 0 | Y55: 0 | Z55: 0 | AA55: 0 | AB55: 0 | AC55: 0 | AD55: 0 | AE55: 0
...

Sheet Forecast
B2: ="FORECAST — Weekly P&L (Display: "&$Z$3&" "&$C$3&")"
B3: Display Currency | C3: GBP | D3: ="("&VLOOKUP(C3,Inputs!$B$13:$D$16,2,FALSE)&" · rate "&TEXT(VLOOKUP(C3,Inputs!$B$13:$D$16,3,FALSE),"0.0000")&")" | Y3: =VLOOKUP(C3,Inputs!$B$13:$D$16,3,FALSE) | Z3: =VLOOKUP(C3,Inputs!$B$13:$D$16,2,FALSE)
B5: BEST · Demo + TPD (Wks 5-6)
B6: Week | F6: W1 | G6: W2 | H6: W3 | I6: W4 | J6: W5 | K6: W6 | L6: W7 | M6: W8 | N6: W9 | O6: W10 | P6: W11 | Q6: W12 | R6: W13 | S6: W14 | T6: W15 | U6: W16 | V6: W17 | W6: W18 | X6: W19 | Y6: W20 | Z6: W21 | AA6: W22 | AB6: W23 | AC6: W24 | AD6: W25 | AE6: W26 | AF6: TOTAL
B7: Wk-commencing | F7: =StartDate+7*0 | G7: =StartDate+7*1 | H7: =StartDate+7*2 | I7: =StartDate+7*3 | J7: =StartDate+7*4 | K7: =StartDate+7*5 | L7: =StartDate+7*6 | M7: =StartDate+7*7 | N7: =StartDate+7*8 | O7: =StartDate+7*9 | P7: =StartDate+7*10 | Q7: =StartDate+7*11 | R7: =StartDate+7*12 | S7: =StartDate+7*13 | T7: =StartDate+7*14 | U7: =StartDate+7*15 | V7: =StartDate+7*16 | W7: =StartDate+7*17 | X7: =StartDate+7*18 | Y7: =StartDate+7*19 | Z7: =StartDate+7*20 | AA7: =StartDate+7*21 | AB7: =StartDate+7*22 | AC7: =StartDate+7*23 | AD7: =StartDate+7*24 | AE7: =StartDate+7*25
B8: POS Units | F8: =ROUND(BaseUnits*Inputs!F49,0) | G8: =ROUND(BaseUnits*Inputs!G49,0) | H8: =ROUND(BaseUnits*Inputs!H49,0) | I8: =ROUND(BaseUnits*Inputs!I49,0) | J8: =ROUND(BaseUnits*Inputs!J49,0) | K8: =ROUND(BaseUnits*Inputs!K49,0) | L8: =ROUND(BaseUnits*Inputs!L49,0) | M8: =ROUND(BaseUnits*Inputs!M49,0) | ... AE8: =ROUND(BaseUnits*Inputs!AE49,0) | AF8: =SUM(F8:AE8)
B9: ="Revenue ("&$Z$3&")" | F9: =F8*Price*$Y$3 | G9: =G8*Price*$Y$3 | H9: =H8*Price*$Y$3 | I9: =I8*Price*$Y$3 | J9: =J8*Price*$Y$3 | K9: =K8*Price*$Y$3 | L9: =L8*Price*$Y$3 | M9: =M8*Price*$Y$3 | ... AE9: =AE8*Price*$Y$3 | AF9: =SUM(F9:AE9)
B10: ="Raw COGS ("&$Z$3&")" | F10: =F8*Cost*$Y$3 | G10: =G8*Cost*$Y$3 | H10: =H8*Cost*$Y$3 | I10: =I8*Cost*$Y$3 | J10: =J8*Cost*$Y$3 | K10: =K8*Cost*$Y$3 | L10: =L8*Cost*$Y$3 | M10: =M8*Cost*$Y$3 | ... AE10: =AE8*Cost*$Y$3 | AF10: =SUM(F10:AE10)
B11: ="Gross Profit ("&$Z$3&")" | F11: =F9-F10 | G11: =G9-G10 | H11: =H9-H10 | I11: =I9-I10 | J11: =J9-J10 | K11: =K9-K10 | L11: =L9-L10 | M11: =M9-M10 | ... AE11: =AE9-AE10 | AF11: =SUM(F11:AE11)
B12: ="Promo Spend ("&$Z$3&")" | F12: =(Inputs!F45*DemoCost+Inputs!F46*EndCapCost+Inputs!F47*F8*Price*TPDPct+Inputs!F48*F8*Price*MdPct)*$Y$3 | G12: =(Inputs!G45*DemoCost+Inputs!G46*EndCapCost+Inputs!G47*G8*Price*TPDPct+Inputs!G48*G8*Price*MdPct)*$Y$3 | H12: =(Inputs!H45*DemoCost+Inputs!H46*EndCapCost+Inputs!H47*H8*Price*TPDPct+Inputs!H48*H8*Price*MdPct)*$Y$3 | I12: =(Inputs!I45*DemoCost+Inputs!I46*EndCapCost+Inputs!I47*I8*Price*TPDPct+Inputs!I48*I8*Price*MdPct)*$Y$3 | J12: =(Inputs!J45*DemoCost+Inputs!J46*EndCapCost+Inputs!J47*J8*Price*TPDPct+Inputs!J48*J8*Price*MdPct)*$Y$3 | K12: =(Inputs!K45*DemoCost+Inputs!K46*EndCapCost+Inputs!K47*K8*Price*TPDPct+Inputs!K48*K8*Price*MdPct)*$Y$3 | L12: =(Inputs!L45*DemoCost+Inputs!L46*EndCapCost+Inputs!L47*L8*Price*TPDPct+Inputs!L48*L8*Price*MdPct)*$Y$3 | M12: =(Inputs!M45*DemoCost+Inputs!M46*EndCapCost+Inputs!M47*M8*Price*TPDPct+Inputs!M48*M8*Price*MdPct)*$Y$3 | ... AE12: =(Inputs!AE45*DemoCost+Inputs!AE46*EndCapCost+Inputs!AE47*AE8*Price*TPDPct+Inputs!AE48*AE8*Price*MdPct)*$Y$3 | AF12: =SUM(F12:AE12)
B13: ="Net Profit ("&$Z$3&")" | F13: =F11-F12 | G13: =G11-G12 | H13: =H11-H12 | I13: =I11-I12 | J13: =J11-J12 | K13: =K11-K12 | L13: =L11-L12 | M13: =M11-M12 | ... AE13: =AE11-AE12 | AF13: =SUM(F13:AE13)
B16: IDEAL · Demo + End Cap + TPD (Wks 5-6)
B17: Week | F17: W1 | G17: W2 | H17: W3 | I17: W4 | J17: W5 | K17: W6 | L17: W7 | M17: W8 | N17: W9 | O17: W10 | P17: W11 | Q17: W12 | R17: W13 | S17: W14 | T17: W15 | U17: W16 | V17: W17 | W17: W18 | X17: W19 | Y17: W20 | Z17: W21 | AA17: W22 | AB17: W23 | AC17: W24 | AD17: W25 | AE17: W26 | AF17: TOTAL
B18: Wk-commencing | F18: =StartDate+7*0 | G18: =StartDate+7*1 | H18: =StartDate+7*2 | I18: =StartDate+7*3 | J18: =StartDate+7*4 | K18: =StartDate+7*5 | L18: =StartDate+7*6 | M18: =StartDate+7*7 | N18: =StartDate+7*8 | O18: =StartDate+7*9 | P18: =StartDate+7*10 | Q18: =StartDate+7*11 | R18: =StartDate+7*12 | S18: =StartDate+7*13 | T18: =StartDate+7*14 | U18: =StartDate+7*15 | V18: =StartDate+7*16 | W18: =StartDate+7*17 | X18: =StartDate+7*18 | Y18: =StartDate+7*19 | Z18: =StartDate+7*20 | AA18: =StartDate+7*21 | AB18: =StartDate+7*22 | AC18: =StartDate+7*23 | AD18: =StartDate+7*24 | AE18: =StartDate+7*25
B19: POS Units | F19: =ROUND(BaseUnits*Inputs!F59,0) | G19: =ROUND(BaseUnits*Inputs!G59,0) | H19: =ROUND(BaseUnits*Inputs!H59,0) | I19: =ROUND(BaseUnits*Inputs!I59,0) | J19: =ROUND(BaseUnits*Inputs!J59,0) | K19: =ROUND(BaseUnits*Inputs!K59,0) | L19: =ROUND(BaseUnits*Inputs!L59,0) | M19: =ROUND(BaseUnits*Inputs!M59,0) | ... AE19: =ROUND(BaseUnits*Inputs!AE59,0) | AF19: =SUM(F19:AE19)
B20: ="Revenue ("&$Z$3&")" | F20: =F19*Price*$Y$3 | G20: =G19*Price*$Y$3 | H20: =H19*Price*$Y$3 | I20: =I19*Price*$Y$3 | J20: =J19*Price*$Y$3 | K20: =K19*Price*$Y$3 | L20: =L19*Price*$Y$3 | M20: =M19*Price*$Y$3 | ... AE20: =AE19*Price*$Y$3 | AF20: =SUM(F20:AE20)
B21: ="Raw COGS ("&$Z$3&")" | F21: =F19*Cost*$Y$3 | G21: =G19*Cost*$Y$3 | H21: =H19*Cost*$Y$3 | I21: =I19*Cost*$Y$3 | J21: =J19*Cost*$Y$3 | K21: =K19*Cost*$Y$3 | L21: =L19*Cost*$Y$3 | M21: =M19*Cost*$Y$3 | ... AE21: =AE19*Cost*$Y$3 | AF21: =SUM(F21:AE21)
B22: ="Gross Profit ("&$Z$3&")" | F22: =F20-F21 | G22: =G20-G21 | H22: =H20-H21 | I22: =I20-I21 | J22: =J20-J21 | K22: =K20-K21 | L22: =L20-L21 | M22: =M20-M21 | ... AE22: =AE20-AE21 | AF22: =SUM(F22:AE22)
B23: ="Promo Spend ("&$Z$3&")" | F23: =(Inputs!F55*DemoCost+Inputs!F56*EndCapCost+Inputs!F57*F19*Price*TPDPct+Inputs!F58*F19*Price*MdPct)*$Y$3 | G23: =(Inputs!G55*DemoCost+Inputs!G56*EndCapCost+Inputs!G57*G19*Price*TPDPct+Inputs!G58*G19*Price*MdPct)*$Y$3 | H23: =(Inputs!H55*DemoCost+Inputs!H56*EndCapCost+Inputs!H57*H19*Price*TPDPct+Inputs!H58*H19*Price*MdPct)*$Y$3 | I23: =(Inputs!I55*DemoCost+Inputs!I56*EndCapCost+Inputs!I57*I19*Price*TPDPct+Inputs!I58*I19*Price*MdPct)*$Y$3 | J23: =(Inputs!J55*DemoCost+Inputs!J56*EndCapCost+Inputs!J57*J19*Price*TPDPct+Inputs!J58*J19*Price*MdPct)*$Y$3 | K23: =(Inputs!K55*DemoCost+Inputs!K56*EndCapCost+Inputs!K57*K19*Price*TPDPct+Inputs!K58*K19*Price*MdPct)*$Y$3 | L23: =(Inputs!L55*DemoCost+Inputs!L56*EndCapCost+Inputs!L57*L19*Price*TPDPct+Inputs!L58*L19*Price*MdPct)*$Y$3 | M23: =(Inputs!M55*DemoCost+Inputs!M56*EndCapCost+Inputs!M57*M19*Price*TPDPct+Inputs!M58*M19*Price*MdPct)*$Y$3 | ... AE23: =(Inputs!AE55*DemoCost+Inputs!AE56*EndCapCost+Inputs!AE57*AE19*Price*TPDPct+Inputs!AE58*AE19*Price*MdPct)*$Y$3 | AF23: =SUM(F23:AE23)
B24: ="Net Profit ("&$Z$3&")" | F24: =F22-F23 | G24: =G22-G23 | H24: =H22-H23 | I24: =I22-I23 | J24: =J22-J23 | K24: =K22-K23 | L24: =L22-L23 | M24: =M22-M23 | ... AE24: =AE22-AE23 | AF24: =SUM(F24:AE24)
B27: WORST · Launch then markdown clearance
B28: Week | F28: W1 | G28: W2 | H28: W3 | I28: W4 | J28: W5 | K28: W6 | L28: W7 | M28: W8 | N28: W9 | O28: W10 | P28: W11 | Q28: W12 | R28: W13 | S28: W14 | T28: W15 | U28: W16 | V28: W17 | W28: W18 | X28: W19 | Y28: W20 | Z28: W21 | AA28: W22 | AB28: W23 | AC28: W24 | AD28: W25 | AE28: W26 | AF28: TOTAL
B29: Wk-commencing | F29: =StartDate+7*0 | G29: =StartDate+7*1 | H29: =StartDate+7*2 | I29: =StartDate+7*3 | J29: =StartDate+7*4 | K29: =StartDate+7*5 | L29: =StartDate+7*6 | M29: =StartDate+7*7 | N29: =StartDate+7*8 | O29: =StartDate+7*9 | P29: =StartDate+7*10 | Q29: =StartDate+7*11 | R29: =StartDate+7*12 | S29: =StartDate+7*13 | T29: =StartDate+7*14 | U29: =StartDate+7*15 | V29: =StartDate+7*16 | W29: =StartDate+7*17 | X29: =StartDate+7*18 | Y29: =StartDate+7*19 | Z29: =StartDate+7*20 | AA29: =StartDate+7*21 | AB29: =StartDate+7*22 | AC29: =StartDate+7*23 | AD29: =StartDate+7*24 | AE29: =StartDate+7*25
B30: POS Units | F30: =ROUND(BaseUnits*Inputs!F69,0) | G30: =ROUND(BaseUnits*Inputs!G69,0) | H30: =ROUND(BaseUnits*Inputs!H69,0) | I30: =ROUND(BaseUnits*Inputs!I69,0) | J30: =ROUND(BaseUnits*Inputs!J69,0) | K30: =ROUND(BaseUnits*Inputs!K69,0) | L30: =ROUND(BaseUnits*Inputs!L69,0) | M30: =ROUND(BaseUnits*Inputs!M69,0) | ... AE30: =ROUND(BaseUnits*Inputs!AE69,0) | AF30: =SUM(F30:AE30)
B31: ="Revenue ("&$Z$3&")" | F31: =F30*Price*$Y$3 | G31: =G30*Price*$Y$3 | H31: =H30*Price*$Y$3 | I31: =I30*Price*$Y$3 | J31: =J30*Price*$Y$3 | K31: =K30*Price*$Y$3 | L31: =L30*Price*$Y$3 | M31: =M30*Price*$Y$3 | ... AE31: =AE30*Price*$Y$3 | AF31: =SUM(F31:AE31)
B32: ="Raw COGS ("&$Z$3&")" | F32: =F30*Cost*$Y$3 | G32: =G30*Cost*$Y$3 | H32: =H30*Cost*$Y$3 | I32: =I30*Cost*$Y$3 | J32: =J30*Cost*$Y$3 | K32: =K30*Cost*$Y$3 | L32: =L30*Cost*$Y$3 | M32: =M30*Cost*$Y$3 | ... AE32: =AE30*Cost*$Y$3 | AF32: =SUM(F32:AE32)
B33: ="Gross Profit ("&$Z$3&")" | F33: =F31-F32 | G33: =G31-G32 | H33: =H31-H32 | I33: =I31-I32 | J33: =J31-J32 | K33: =K31-K32 | L33: =L31-L32 | M33: =M31-M32 | ... AE33: =AE31-AE32 | AF33: =SUM(F33:AE33)
B34: ="Promo Spend ("&$Z$3&")" | F34: =(Inputs!F65*DemoCost+Inputs!F66*EndCapCost+Inputs!F67*F30*Price*TPDPct+Inputs!F68*F30*Price*MdPct)*$Y$3 | G34: =(Inputs!G65*DemoCost+Inputs!G66*EndCapCost+Inputs!G67*G30*Price*TPDPct+Inputs!G68*G30*Price*MdPct)*$Y$3 | H34: =(Inputs!H65*DemoCost+Inputs!H66*EndCapCost+Inputs!H67*H30*Price*TPDPct+Inputs!H68*H30*Price*MdPct)*$Y$3 | I34: =(Inputs!I65*DemoCost+Inputs!I66*EndCapCost+Inputs!I67*I30*Price*TPDPct+Inputs!I68*I30*Price*MdPct)*$Y$3 | J34: =(Inputs!J65*DemoCost+Inputs!J66*EndCapCost+Inputs!J67*J30*Price*TPDPct+Inputs!J68*J30*Price*MdPct)*$Y$3 | K34: =(Inputs!K65*DemoCost+Inputs!K66*EndCapCost+Inputs!K67*K30*Price*TPDPct+Inputs!K68*K30*Price*MdPct)*$Y$3 | L34: =(Inputs!L65*DemoCost+Inputs!L66*EndCapCost+Inputs!L67*L30*Price*TPDPct+Inputs!L68*L30*Price*MdPct)*$Y$3 | M34: =(Inputs!M65*DemoCost+Inputs!M66*EndCapCost+Inputs!M67*M30*Price*TPDPct+Inputs!M68*M30*Price*MdPct)*$Y$3 | ... AE34: =(Inputs!AE65*DemoCost+Inputs!AE66*EndCapCost+Inputs!AE67*AE30*Price*TPDPct+Inputs!AE68*AE30*Price*MdPct)*$Y$3 | AF34: =SUM(F34:AE34)
B35: ="Net Profit ("&$Z$3&")" | F35: =F33-F34 | G35: =G33-G34 | H35: =H33-H34 | I35: =I33-I34 | J35: =J33-J34 | K35: =K33-K34 | L35: =L33-L34 | M35: =M33-M34 | ... AE35: =AE33-AE34 | AF35: =SUM(F35:AE35)

Sheet Summary
B2: ="ROI SUMMARY (Display: "&$Z$3&" "&$C$3&")"
B3: Display Currency | C3: GBP | D3: ="("&VLOOKUP(C3,Inputs!$B$13:$D$16,2,FALSE)&" · rate "&TEXT(VLOOKUP(C3,Inputs!$B$13:$D$16,3,FALSE),"0.0000")&")" | Y3: =VLOOKUP(C3,Inputs!$B$13:$D$16,3,FALSE) | Z3: =VLOOKUP(C3,Inputs!$B$13:$D$16,2,FALSE)
B4: ="Test window: W1 ("&TEXT(StartDate,"dd-mmm-yyyy")&") → W"&Period&" ("&TEXT(StartDate+7*(Period-1),"dd-mmm-yyyy")&")"
B6: Metric | C6: BEST | D6: IDEAL | E6: WORST
B7: Units Sold | C7: =Forecast!AF8 | D7: =Forecast!AF19 | E7: =Forecast!AF30
B8: ="Revenue ("&$Z$3&")" | C8: =Forecast!AF9*($Y$3/Forecast!$Y$3) | D8: =Forecast!AF20*($Y$3/Forecast!$Y$3) | E8: =Forecast!AF31*($Y$3/Forecast!$Y$3)
B9: ="Gross Profit ("&$Z$3&")" | C9: =Forecast!AF11*($Y$3/Forecast!$Y$3) | D9: =Forecast!AF22*($Y$3/Forecast!$Y$3) | E9: =Forecast!AF33*($Y$3/Forecast!$Y$3)
B10: Gross Margin % | C10: =IFERROR(Forecast!AF11/Forecast!AF9,0) | D10: =IFERROR(Forecast!AF22/Forecast!AF20,0) | E10: =IFERROR(Forecast!AF33/Forecast!AF31,0)
B11: ="Promo Spend ("&$Z$3&")" | C11: =Forecast!AF12*($Y$3/Forecast!$Y$3) | D11: =Forecast!AF23*($Y$3/Forecast!$Y$3) | E11: =Forecast!AF34*($Y$3/Forecast!$Y$3)
B12: ="Net Profit ("&$Z$3&")" | C12: =Forecast!AF13*($Y$3/Forecast!$Y$3) | D12: =Forecast!AF24*($Y$3/Forecast!$Y$3) | E12: =Forecast!AF35*($Y$3/Forecast!$Y$3)
B13: ROI on Promo Spend | C13: =IFERROR(Forecast!AF13/Forecast!AF12,0) | D13: =IFERROR(Forecast!AF24/Forecast!AF23,0) | E13: =IFERROR(Forecast!AF35/Forecast!AF34,0)
B16: Why each scenario?
B17: BEST | C17: Two demo weekends with TPD. ~3x lift in-promo weeks.
B18: IDEAL | C18: Stacked demo + end cap + TPD. ~3.6x lift.
B19: WORST | C19: Launch as IDEAL, then 50% markdown to clear Wks 18-20.

Sheet Portfolio
B2: ="PORTFOLIO — D93 Pitch SKUs · Y1 Roll-Up (Display: "&$Z$3&" "&$C$3&")"
B3: Display Currency | C3: GBP | D3: ="("&VLOOKUP(C3,Inputs!$B$13:$D$16,2,FALSE)&" · rate "&TEXT(VLOOKUP(C3,Inputs!$B$13:$D$16,3,FALSE),"0.0000")&")" | Y3: =VLOOKUP(C3,Inputs!$B$13:$D$16,3,FALSE) | Z3: =VLOOKUP(C3,Inputs!$B$13:$D$16,2,FALSE)
B4: Bee Propolis pre-filled. Fill SP / Cost / Y1 Units / Promo Spend for SKUs 2-7 (yellow cells). Bottom row blends across SKUs.
B6: # | C6: SKU | D6: ="SP ("&$Z$3&")" | E6: ="Cost ("&$Z$3&")" | F6: GM % | G6: Y1 Units | H6: ="Revenue ("&$Z$3&")" | I6: ="Promo ("&$Z$3&")" | J6: ="Net Profit ("&$Z$3&")" | K6: ROI | L6: Rationale
B7: 1 | C7: Bee Propolis Spray 30ml x2 | D7: 15.99 | E7: 7.29 | F7: =IFERROR((D7-E7)/D7,0) | G7: 17000 | H7: =IFERROR(G7*D7,0) | I7: 25000 | J7: =IFERROR((G7*(D7-E7))-I7,0) | K7: =IFERROR(J7/I7,0) | L7: Lead pitch — strong GP%.
B8: 2 | C8: Mag 8-in-1 90's/120's | F8: =IFERROR((D8-E8)/D8,0) | H8: =IFERROR(G8*D8,0) | J8: =IFERROR((G8*(D8-E8))-I8,0) | K8: =IFERROR(J8/I8,0)
B9: 3 | C9: O1 450g | F9: =IFERROR((D9-E9)/D9,0) | H9: =IFERROR(G9*D9,0) | J9: =IFERROR((G9*(D9-E9))-I9,0) | K9: =IFERROR(J9/I9,0)
B10: 4 | C10: Belli Bliss Raspberry, 450g | F10: =IFERROR((D10-E10)/D10,0) | H10: =IFERROR(G10*D10,0) | J10: =IFERROR((G10*(D10-E10))-I10,0) | K10: =IFERROR(J10/I10,0)
B11: 5 | C11: Daily Boost | F11: =IFERROR((D11-E11)/D11,0) | H11: =IFERROR(G11*D11,0) | J11: =IFERROR((G11*(D11-E11))-I11,0) | K11: =IFERROR(J11/I11,0)
B12: 6 | C12: Berberine 90's/120's | F12: =IFERROR((D12-E12)/D12,0) | H12: =IFERROR(G12*D12,0) | J12: =IFERROR((G12*(D12-E12))-I12,0) | K12: =IFERROR(J12/I12,0)
B13: 7 | C13: L-theanine Capsules 90's/120's | F13: =IFERROR((D13-E13)/D13,0) | H13: =IFERROR(G13*D13,0) | J13: =IFERROR((G13*(D13-E13))-I13,0) | K13: =IFERROR(J13/I13,0)
C14: PORTFOLIO TOTAL / BLENDED | F14: =IFERROR(SUM(H7:H13)*0+ (SUMPRODUCT(G7:G13,(D7:D13-E7:E13)))/SUM(H7:H13),0) | G14: =SUM(G7:G13) | H14: =SUM(H7:H13) | I14: =SUM(I7:I13) | J14: =SUM(J7:J13) | K14: =IFERROR(J14/I14,0) | L14: Blended across SKUs
