Workbook
Name StartDate: Inputs!$C$21
Name WHs: Inputs!$C$22
Name Period: 26
Name Price: Inputs!$C$25
Name Cost: Inputs!$C$26
Name BaseUnits: Inputs!$C$31
Name DemoCost: Inputs!$C$34
Name EndCapCost: Inputs!$C$35
Name TPDPct: Inputs!$C$36
Name MdPct: Inputs!$C$37
Name PBest: Inputs!$C$40
Name PIdeal: Inputs!$C$41
Name PWorst: Inputs!$C$42

Sheet Start Here
B2: Costco UK — D93 Portfolio ROI Model
B3: v9 enterprise · 8 tabs · scenario-weighted, multi-year, multi-currency
B5: WHAT THIS MODEL DOES
B7: Costs out the Bee Propolis Spray Costco UK market test under three scenarios (BEST / IDEAL / WORST), rolls those into Y1 numbers, then blends Bee Propolis with the other six D93 pitch SKUs into a 3-year portfolio view with blended margin and ROI.
B9: HOW TO USE
B11: 1. Open the Inputs tab. Change any YELLOW cell. Grey cells calculate themselves.
B12: 2. Pick a Display Currency at the top of any output tab (Forecast, Cumulative, Summary, Portfolio, Pitch Memo).
B13: 3. Forecast = 26-week weekly P&L per scenario.
B14: 4. Cumulative = running Net Profit per scenario + break-even week (line chart).
B15: 5. Sensitivity = Lift × Demo Cost grid showing Net Profit (where the model breaks).
B16: 6. Summary = scenario KPI comparison + probability-weighted Expected Value + bar chart.
B17: 7. Portfolio = 3-year roll-up across all seven SKUs with blended margin/ROI.
... B53: v1 original George spreadsheet (rebuilt from scratch).

Sheet Inputs
B2: INPUTS — change any yellow cell
B4: 1. Display Currency (master copy — each tab has its own)
B5: Display Currency | C5: GBP | D5: Reference only. Each display tab has its own dropdown.
B7: FX Rate Table — edit rates (rate is per 1 GBP)
B12: Code | C12: Symbol | D12: Rate (× GBP)
B13: GBP | C13: £ | D13: 1
B14: USD | C14: $ | D14: 1.27
B15: CAD | C15: C$ | D15: 1.71
B16: EUR | C16: € | D16: 1.17
B19: 2. Product & Distribution
B20: SKU | C20: Bee Propolis Spray 30ml x 2 | D20: Costco UK market test SKU.
B21: Test Start Date (W1) | C21: 46034 | D21: Week-commencing date for W1.
B22: Warehouses in test | C22: 20 | D22: Number of Costco UK warehouses.
B24: 3. Pricing (GBP)
B25: Selling Price (MSRP) | C25: 15.99 | D25: Retail per pack.
B26: Cost Price (landed) | C26: 7.29 | D26: Brand cost delivered.
B27: Gross Margin per unit | C27: =C25-C26 | D27: SP − Cost (auto).
B28: Gross Margin % | C28: =IFERROR((C25-C26)/C25,0) | D28: GP ÷ SP (auto).
B30: 4. Base Demand
B31: Base Units / Week (all warehouses) | C31: 276 | D31: Organic weekly units across test warehouses, no promo.
B33: 5. Promo Economics (GBP)
B34: Demo Total £ / week | C34: 7403 | D34: All-warehouse demo cost in a demo week. ~£199/wh × 20 wh × 1.86 factor.
B35: End Cap Total £ / week | C35: 15810 | D35: All-warehouse end cap. ~£850/wh × 20 wh × 1.86 ÷ 2-week cycle.
B36: TPD discount % (of net) | C36: 0.25 | D36: 20% off MSRP ≈ 25% off net.
B37: Markdown discount % | C37: 0.5 | D37: Clearance pricing.
B39: 6. Scenario Probability Weights (must sum to 100%)
B40: P(BEST) | C40: 0.3 | D40: Demo + TPD only. ~3x lift in-promo. No end cap, no clearance.
B41: P(IDEAL) | C41: 0.5 | D41: Demo + end cap + TPD stacked. ~3.6x lift.
B42: P(WORST) | C42: 0.2 | D42: Launch as IDEAL; 50% markdown to clear residual stock Wks 18-20.
B43: Sum of weights | C43: =SUM(C40:C42) | D43: ="(should be 100%)"
B45: 7. Scenario activity (1 = on / 0 = off per week) and demand lift
B47: BEST · Demo + TPD (Wks 5-6)
B48: Rationale: Demo + TPD only. ~3x lift in-promo. No end cap, no clearance.
B49: Week | F49: W1 | G49: W2 | H49: W3 | I49: W4 | J49: W5 | K49: W6 | L49: W7 | M49: W8 | N49: W9 | O49: W10 | P49: W11 | Q49: W12 | R49: W13 | S49: W14 | T49: W15 | U49: W16 | V49: W17 | W49: W18 | X49: W19 | Y49: W20 | Z49: W21 | AA49: W22 | AB49: W23 | AC49: W24 | AD49: W25 | AE49: W26
B50: Wk-commencing | F50: =StartDate+7*0 | G50: =StartDate+7*1 | H50: =StartDate+7*2 | I50: =StartDate+7*3 | J50: =StartDate+7*4 | K50: =StartDate+7*5 | L50: =StartDate+7*6 | M50: =StartDate+7*7 | N50: =StartDate+7*8 | O50: =StartDate+7*9 | P50: =StartDate+7*10 | Q50: =StartDate+7*11 | R50: =StartDate+7*12 | S50: =StartDate+7*13 | T50: =StartDate+7*14 | U50: =StartDate+7*15 | V50: =StartDate+7*16 | W50: =StartDate+7*17 | X50: =StartDate+7*18 | Y50: =StartDate+7*19 | Z50: =StartDate+7*20 | AA50: =StartDate+7*21 | AB50: =StartDate+7*22 | AC50: =StartDate+7*23 | AD50: =StartDate+7*24 | AE50: =StartDate+7*25
B51: Demo | F51: 0 | G51: 0 | H51: 0 | I51: 0 | J51: 1 | K51: 1 | L51: 0 | M51: 0 | N51: 0 | O51: 0 | P51: 0 | Q51: 0 | R51: 0 | S51: 0 | T51: 0 | U51: 0 | V51: 0 | W51: 0 | X51: 0 | Y51: 0 | Z51: 0 | AA51: 0 | AB51: 0 | AC51: 0 | AD51: 0 | AE51: 0
B52: End Cap | F52: 0 | G52: 0 | H52: 0 | I52: 0 | J52: 0 | K52: 0 | L52: 0 | M52: 0 | N52: 0 | O52: 0 | P52: 0 | Q52: 0 | R52: 0 | S52: 0 | T52: 0 | U52: 0 | V52: 0 | W52: 0 | X52: 0 | Y52: 0 | Z52: 0 | AA52: 0 | AB52: 0 | AC52: 0 | AD52: 0 | AE52: 0
B53: TPD | F53: 0 | G53: 0 | H53: 0 | I53: 0 | J53: 1 | K53: 1 | L53: 0 | M53: 0 | N53: 0 | O53: 0 | P53: 0 | Q53: 0 | R53: 0 | S53: 0 | T53: 0 | U53: 0 | V53: 0 | W53: 0 | X53: 0 | Y53: 0 | Z53: 0 | AA53: 0 | AB53: 0 | AC53: 0 | AD53: 0 | AE53: 0
B54: Markdown | F54: 0 | G54: 0 | H54: 0 | I54: 0 | J54: 0 | K54: 0 | L54: 0 | M54: 0 | N54: 0 | O54: 0 | P54: 0 | Q54: 0 | R54: 0 | S54: 0 | T54: 0 | U54: 0 | V54: 0 | W54: 0 | X54: 0 | Y54: 0 | Z54: 0 | AA54: 0 | AB54: 0 | AC54: 0 | AD54: 0 | AE54: 0
B55: Lift Multiplier (x base) | F55: 1 | G55: 1 | H55: 1 | I55: 1 | J55: 3 | K55: 3 | L55: 1 | M55: 1 | N55: 1 | O55: 1 | P55: 1 | Q55: 1 | R55: 1 | S55: 1 | T55: 1 | U55: 1 | V55: 1 | W55: 1 | X55: 1 | Y55: 1 | Z55: 1 | AA55: 1 | AB55: 1 | AC55: 1 | AD55: 1 | AE55: 1
...

Sheet Forecast
B2: ="FORECAST — Weekly P&L (Display: "&$Z$3&" "&$C$3&")"
B3: Display Currency | C3: GBP | D3: ="("&VLOOKUP(C3,Inputs!$B$13:$D$16,2,FALSE)&" · rate "&TEXT(VLOOKUP(C3,Inputs!$B$13:$D$16,3,FALSE),"0.0000")&")" | Y3: =VLOOKUP(C3,Inputs!$B$13:$D$16,3,FALSE) | Z3: =VLOOKUP(C3,Inputs!$B$13:$D$16,2,FALSE)
B5: BEST · Demo + TPD (Wks 5-6)
B6: Week | F6: W1 | G6: W2 | H6: W3 | I6: W4 | J6: W5 | K6: W6 | L6: W7 | M6: W8 | N6: W9 | O6: W10 | P6: W11 | Q6: W12 | R6: W13 | S6: W14 | T6: W15 | U6: W16 | V6: W17 | W6: W18 | X6: W19 | Y6: W20 | Z6: W21 | AA6: W22 | AB6: W23 | AC6: W24 | AD6: W25 | AE6: W26 | AF6: TOTAL
B7: Wk-commencing | F7: =StartDate+7*0 | G7: =StartDate+7*1 | H7: =StartDate+7*2 | I7: =StartDate+7*3 | J7: =StartDate+7*4 | K7: =StartDate+7*5 | L7: =StartDate+7*6 | M7: =StartDate+7*7 | N7: =StartDate+7*8 | O7: =StartDate+7*9 | P7: =StartDate+7*10 | Q7: =StartDate+7*11 | R7: =StartDate+7*12 | S7: =StartDate+7*13 | T7: =StartDate+7*14 | U7: =StartDate+7*15 | V7: =StartDate+7*16 | W7: =StartDate+7*17 | X7: =StartDate+7*18 | Y7: =StartDate+7*19 | Z7: =StartDate+7*20 | AA7: =StartDate+7*21 | AB7: =StartDate+7*22 | AC7: =StartDate+7*23 | AD7: =StartDate+7*24 | AE7: =StartDate+7*25
B8: POS Units | F8: =ROUND(BaseUnits*Inputs!F55,0) | G8: =ROUND(BaseUnits*Inputs!G55,0) | H8: =ROUND(BaseUnits*Inputs!H55,0) | I8: =ROUND(BaseUnits*Inputs!I55,0) | J8: =ROUND(BaseUnits*Inputs!J55,0) | K8: =ROUND(BaseUnits*Inputs!K55,0) | L8: =ROUND(BaseUnits*Inputs!L55,0) | M8: =ROUND(BaseUnits*Inputs!M55,0) | ... AE8: =ROUND(BaseUnits*Inputs!AE55,0) | AF8: =SUM(F8:AE8)
B9: ="Revenue ("&$Z$3&")" | F9: =F8*Price*$Y$3 | G9: =G8*Price*$Y$3 | H9: =H8*Price*$Y$3 | I9: =I8*Price*$Y$3 | J9: =J8*Price*$Y$3 | K9: =K8*Price*$Y$3 | L9: =L8*Price*$Y$3 | M9: =M8*Price*$Y$3 | ... AE9: =AE8*Price*$Y$3 | AF9: =SUM(F9:AE9)
B10: ="Raw COGS ("&$Z$3&")" | F10: =F8*Cost*$Y$3 | G10: =G8*Cost*$Y$3 | H10: =H8*Cost*$Y$3 | I10: =I8*Cost*$Y$3 | J10: =J8*Cost*$Y$3 | K10: =K8*Cost*$Y$3 | L10: =L8*Cost*$Y$3 | M10: =M8*Cost*$Y$3 | ... AE10: =AE8*Cost*$Y$3 | AF10: =SUM(F10:AE10)
B11: ="Gross Profit ("&$Z$3&")" | F11: =F9-F10 | G11: =G9-G10 | H11: =H9-H10 | I11: =I9-I10 | J11: =J9-J10 | K11: =K9-K10 | L11: =L9-L10 | M11: =M9-M10 | ... AE11: =AE9-AE10 | AF11: =SUM(F11:AE11)
B12: ="Promo Spend ("&$Z$3&")" | F12: =(Inputs!F51*DemoCost+Inputs!F52*EndCapCost+Inputs!F53*F8*Price*TPDPct+Inputs!F54*F8*Price*MdPct)*$Y$3 | G12: =(Inputs!G51*DemoCost+Inputs!G52*EndCapCost+Inputs!G53*G8*Price*TPDPct+Inputs!G54*G8*Price*MdPct)*$Y$3 | H12: =(Inputs!H51*DemoCost+Inputs!H52*EndCapCost+Inputs!H53*H8*Price*TPDPct+Inputs!H54*H8*Price*MdPct)*$Y$3 | I12: =(Inputs!I51*DemoCost+Inputs!I52*EndCapCost+Inputs!I53*I8*Price*TPDPct+Inputs!I54*I8*Price*MdPct)*$Y$3 | J12: =(Inputs!J51*DemoCost+Inputs!J52*EndCapCost+Inputs!J53*J8*Price*TPDPct+Inputs!J54*J8*Price*MdPct)*$Y$3 | K12: =(Inputs!K51*DemoCost+Inputs!K52*EndCapCost+Inputs!K53*K8*Price*TPDPct+Inputs!K54*K8*Price*MdPct)*$Y$3 | L12: =(Inputs!L51*DemoCost+Inputs!L52*EndCapCost+Inputs!L53*L8*Price*TPDPct+Inputs!L54*L8*Price*MdPct)*$Y$3 | M12: =(Inputs!M51*DemoCost+Inputs!M52*EndCapCost+Inputs!M53*M8*Price*TPDPct+Inputs!M54*M8*Price*MdPct)*$Y$3 | ... AE12: =(Inputs!AE51*DemoCost+Inputs!AE52*EndCapCost+Inputs!AE53*AE8*Price*TPDPct+Inputs!AE54*AE8*Price*MdPct)*$Y$3 | AF12: =SUM(F12:AE12)
B13: ="Net Profit ("&$Z$3&")" | F13: =F11-F12 | G13: =G11-G12 | H13: =H11-H12 | I13: =I11-I12 | J13: =J11-J12 | K13: =K11-K12 | L13: =L11-L12 | M13: =M11-M12 | ... AE13: =AE11-AE12 | AF13: =SUM(F13:AE13)
B16: IDEAL · Demo + End Cap + TPD (Wks 5-6)
B17: Week | F17: W1 | G17: W2 | H17: W3 | I17: W4 | J17: W5 | K17: W6 | L17: W7 | M17: W8 | N17: W9 | O17: W10 | P17: W11 | Q17: W12 | R17: W13 | S17: W14 | T17: W15 | U17: W16 | V17: W17 | W17: W18 | X17: W19 | Y17: W20 | Z17: W21 | AA17: W22 | AB17: W23 | AC17: W24 | AD17: W25 | AE17: W26 | AF17: TOTAL
B18: Wk-commencing | F18: =StartDate+7*0 | G18: =StartDate+7*1 | H18: =StartDate+7*2 | I18: =StartDate+7*3 | J18: =StartDate+7*4 | K18: =StartDate+7*5 | L18: =StartDate+7*6 | M18: =StartDate+7*7 | N18: =StartDate+7*8 | O18: =StartDate+7*9 | P18: =StartDate+7*10 | Q18: =StartDate+7*11 | R18: =StartDate+7*12 | S18: =StartDate+7*13 | T18: =StartDate+7*14 | U18: =StartDate+7*15 | V18: =StartDate+7*16 | W18: =StartDate+7*17 | X18: =StartDate+7*18 | Y18: =StartDate+7*19 | Z18: =StartDate+7*20 | AA18: =StartDate+7*21 | AB18: =StartDate+7*22 | AC18: =StartDate+7*23 | AD18: =StartDate+7*24 | AE18: =StartDate+7*25
B19: POS Units | F19: =ROUND(BaseUnits*Inputs!F65,0) | G19: =ROUND(BaseUnits*Inputs!G65,0) | H19: =ROUND(BaseUnits*Inputs!H65,0) | I19: =ROUND(BaseUnits*Inputs!I65,0) | J19: =ROUND(BaseUnits*Inputs!J65,0) | K19: =ROUND(BaseUnits*Inputs!K65,0) | L19: =ROUND(BaseUnits*Inputs!L65,0) | M19: =ROUND(BaseUnits*Inputs!M65,0) | ... AE19: =ROUND(BaseUnits*Inputs!AE65,0) | AF19: =SUM(F19:AE19)
B20: ="Revenue ("&$Z$3&")" | F20: =F19*Price*$Y$3 | G20: =G19*Price*$Y$3 | H20: =H19*Price*$Y$3 | I20: =I19*Price*$Y$3 | J20: =J19*Price*$Y$3 | K20: =K19*Price*$Y$3 | L20: =L19*Price*$Y$3 | M20: =M19*Price*$Y$3 | ... AE20: =AE19*Price*$Y$3 | AF20: =SUM(F20:AE20)
B21: ="Raw COGS ("&$Z$3&")" | F21: =F19*Cost*$Y$3 | G21: =G19*Cost*$Y$3 | H21: =H19*Cost*$Y$3 | I21: =I19*Cost*$Y$3 | J21: =J19*Cost*$Y$3 | K21: =K19*Cost*$Y$3 | L21: =L19*Cost*$Y$3 | M21: =M19*Cost*$Y$3 | ... AE21: =AE19*Cost*$Y$3 | AF21: =SUM(F21:AE21)
B22: ="Gross Profit ("&$Z$3&")" | F22: =F20-F21 | G22: =G20-G21 | H22: =H20-H21 | I22: =I20-I21 | J22: =J20-J21 | K22: =K20-K21 | L22: =L20-L21 | M22: =M20-M21 | ... AE22: =AE20-AE21 | AF22: =SUM(F22:AE22)
B23: ="Promo Spend ("&$Z$3&")" | F23: =(Inputs!F61*DemoCost+Inputs!F62*EndCapCost+Inputs!F63*F19*Price*TPDPct+Inputs!F64*F19*Price*MdPct)*$Y$3 | G23: =(Inputs!G61*DemoCost+Inputs!G62*EndCapCost+Inputs!G63*G19*Price*TPDPct+Inputs!G64*G19*Price*MdPct)*$Y$3 | H23: =(Inputs!H61*DemoCost+Inputs!H62*EndCapCost+Inputs!H63*H19*Price*TPDPct+Inputs!H64*H19*Price*MdPct)*$Y$3 | I23: =(Inputs!I61*DemoCost+Inputs!I62*EndCapCost+Inputs!I63*I19*Price*TPDPct+Inputs!I64*I19*Price*MdPct)*$Y$3 | J23: =(Inputs!J61*DemoCost+Inputs!J62*EndCapCost+Inputs!J63*J19*Price*TPDPct+Inputs!J64*J19*Price*MdPct)*$Y$3 | K23: =(Inputs!K61*DemoCost+Inputs!K62*EndCapCost+Inputs!K63*K19*Price*TPDPct+Inputs!K64*K19*Price*MdPct)*$Y$3 | L23: =(Inputs!L61*DemoCost+Inputs!L62*EndCapCost+Inputs!L63*L19*Price*TPDPct+Inputs!L64*L19*Price*MdPct)*$Y$3 | M23: =(Inputs!M61*DemoCost+Inputs!M62*EndCapCost+Inputs!M63*M19*Price*TPDPct+Inputs!M64*M19*Price*MdPct)*$Y$3 | ... AE23: =(Inputs!AE61*DemoCost+Inputs!AE62*EndCapCost+Inputs!AE63*AE19*Price*TPDPct+Inputs!AE64*AE19*Price*MdPct)*$Y$3 | AF23: =SUM(F23:AE23)
B24: ="Net Profit ("&$Z$3&")" | F24: =F22-F23 | G24: =G22-G23 | H24: =H22-H23 | I24: =I22-I23 | J24: =J22-J23 | K24: =K22-K23 | L24: =L22-L23 | M24: =M22-M23 | ... AE24: =AE22-AE23 | AF24: =SUM(F24:AE24)
B27: WORST · Launch then markdown clearance
B28: Week | F28: W1 | G28: W2 | H28: W3 | I28: W4 | J28: W5 | K28: W6 | L28: W7 | M28: W8 | N28: W9 | O28: W10 | P28: W11 | Q28: W12 | R28: W13 | S28: W14 | T28: W15 | U28: W16 | V28: W17 | W28: W18 | X28: W19 | Y28: W20 | Z28: W21 | AA28: W22 | AB28: W23 | AC28: W24 | AD28: W25 | AE28: W26 | AF28: TOTAL
B29: Wk-commencing | F29: =StartDate+7*0 | G29: =StartDate+7*1 | H29: =StartDate+7*2 | I29: =StartDate+7*3 | J29: =StartDate+7*4 | K29: =StartDate+7*5 | L29: =StartDate+7*6 | M29: =StartDate+7*7 | N29: =StartDate+7*8 | O29: =StartDate+7*9 | P29: =StartDate+7*10 | Q29: =StartDate+7*11 | R29: =StartDate+7*12 | S29: =StartDate+7*13 | T29: =StartDate+7*14 | U29: =StartDate+7*15 | V29: =StartDate+7*16 | W29: =StartDate+7*17 | X29: =StartDate+7*18 | Y29: =StartDate+7*19 | Z29: =StartDate+7*20 | AA29: =StartDate+7*21 | AB29: =StartDate+7*22 | AC29: =StartDate+7*23 | AD29: =StartDate+7*24 | AE29: =StartDate+7*25
B30: POS Units | F30: =ROUND(BaseUnits*Inputs!F75,0) | G30: =ROUND(BaseUnits*Inputs!G75,0) | H30: =ROUND(BaseUnits*Inputs!H75,0) | I30: =ROUND(BaseUnits*Inputs!I75,0) | J30: =ROUND(BaseUnits*Inputs!J75,0) | K30: =ROUND(BaseUnits*Inputs!K75,0) | L30: =ROUND(BaseUnits*Inputs!L75,0) | M30: =ROUND(BaseUnits*Inputs!M75,0) | ... AE30: =ROUND(BaseUnits*Inputs!AE75,0) | AF30: =SUM(F30:AE30)
B31: ="Revenue ("&$Z$3&")" | F31: =F30*Price*$Y$3 | G31: =G30*Price*$Y$3 | H31: =H30*Price*$Y$3 | I31: =I30*Price*$Y$3 | J31: =J30*Price*$Y$3 | K31: =K30*Price*$Y$3 | L31: =L30*Price*$Y$3 | M31: =M30*Price*$Y$3 | ... AE31: =AE30*Price*$Y$3 | AF31: =SUM(F31:AE31)
B32: ="Raw COGS ("&$Z$3&")" | F32: =F30*Cost*$Y$3 | G32: =G30*Cost*$Y$3 | H32: =H30*Cost*$Y$3 | I32: =I30*Cost*$Y$3 | J32: =J30*Cost*$Y$3 | K32: =K30*Cost*$Y$3 | L32: =L30*Cost*$Y$3 | M32: =M30*Cost*$Y$3 | ... AE32: =AE30*Cost*$Y$3 | AF32: =SUM(F32:AE32)
B33: ="Gross Profit ("&$Z$3&")" | F33: =F31-F32 | G33: =G31-G32 | H33: =H31-H32 | I33: =I31-I32 | J33: =J31-J32 | K33: =K31-K32 | L33: =L31-L32 | M33: =M31-M32 | ... AE33: =AE31-AE32 | AF33: =SUM(F33:AE33)
B34: ="Promo Spend ("&$Z$3&")" | F34: =(Inputs!F71*DemoCost+Inputs!F72*EndCapCost+Inputs!F73*F30*Price*TPDPct+Inputs!F74*F30*Price*MdPct)*$Y$3 | G34: =(Inputs!G71*DemoCost+Inputs!G72*EndCapCost+Inputs!G73*G30*Price*TPDPct+Inputs!G74*G30*Price*MdPct)*$Y$3 | H34: =(Inputs!H71*DemoCost+Inputs!H72*EndCapCost+Inputs!H73*H30*Price*TPDPct+Inputs!H74*H30*Price*MdPct)*$Y$3 | I34: =(Inputs!I71*DemoCost+Inputs!I72*EndCapCost+Inputs!I73*I30*Price*TPDPct+Inputs!I74*I30*Price*MdPct)*$Y$3 | J34: =(Inputs!J71*DemoCost+Inputs!J72*EndCapCost+Inputs!J73*J30*Price*TPDPct+Inputs!J74*J30*Price*MdPct)*$Y$3 | K34: =(Inputs!K71*DemoCost+Inputs!K72*EndCapCost+Inputs!K73*K30*Price*TPDPct+Inputs!K74*K30*Price*MdPct)*$Y$3 | L34: =(Inputs!L71*DemoCost+Inputs!L72*EndCapCost+Inputs!L73*L30*Price*TPDPct+Inputs!L74*L30*Price*MdPct)*$Y$3 | M34: =(Inputs!M71*DemoCost+Inputs!M72*EndCapCost+Inputs!M73*M30*Price*TPDPct+Inputs!M74*M30*Price*MdPct)*$Y$3 | ... AE34: =(Inputs!AE71*DemoCost+Inputs!AE72*EndCapCost+Inputs!AE73*AE30*Price*TPDPct+Inputs!AE74*AE30*Price*MdPct)*$Y$3 | AF34: =SUM(F34:AE34)
B35: ="Net Profit ("&$Z$3&")" | F35: =F33-F34 | G35: =G33-G34 | H35: =H33-H34 | I35: =I33-I34 | J35: =J33-J34 | K35: =K33-K34 | L35: =L33-L34 | M35: =M33-M34 | ... AE35: =AE33-AE34 | AF35: =SUM(F35:AE35)

Sheet Cumulative
B2: ="CUMULATIVE Net Profit & break-even (Display: "&$Z$3&" "&$C$3&")"
B3: Display Currency | C3: GBP | D3: ="("&VLOOKUP(C3,Inputs!$B$13:$D$16,2,FALSE)&" · rate "&TEXT(VLOOKUP(C3,Inputs!$B$13:$D$16,3,FALSE),"0.0000")&")" | Y3: =VLOOKUP(C3,Inputs!$B$13:$D$16,3,FALSE) | Z3: =VLOOKUP(C3,Inputs!$B$13:$D$16,2,FALSE)
B5: Scenario | F5: W1 | G5: W2 | H5: W3 | I5: W4 | J5: W5 | K5: W6 | L5: W7 | M5: W8 | N5: W9 | O5: W10 | P5: W11 | Q5: W12 | R5: W13 | S5: W14 | T5: W15 | U5: W16 | V5: W17 | W5: W18 | X5: W19 | Y5: W20 | Z5: W21 | AA5: W22 | AB5: W23 | AC5: W24 | AD5: W25 | AE5: W26
B6: Wk-commencing | F6: =StartDate+7*0 | G6: =StartDate+7*1 | H6: =StartDate+7*2 | I6: =StartDate+7*3 | J6: =StartDate+7*4 | K6: =StartDate+7*5 | L6: =StartDate+7*6 | M6: =StartDate+7*7 | N6: =StartDate+7*8 | O6: =StartDate+7*9 | P6: =StartDate+7*10 | Q6: =StartDate+7*11 | R6: =StartDate+7*12 | S6: =StartDate+7*13 | T6: =StartDate+7*14 | U6: =StartDate+7*15 | V6: =StartDate+7*16 | W6: =StartDate+7*17 | X6: =StartDate+7*18 | Y6: =StartDate+7*19 | Z6: =StartDate+7*20 | AA6: =StartDate+7*21 | AB6: =StartDate+7*22 | AC6: =StartDate+7*23 | AD6: =StartDate+7*24 | AE6: =StartDate+7*25
B7: BEST | F7: =SUM(Forecast!F13:Forecast!F13)*($Y$3/Forecast!$Y$3) | G7: =SUM(Forecast!F13:Forecast!G13)*($Y$3/Forecast!$Y$3) | H7: =SUM(Forecast!F13:Forecast!H13)*($Y$3/Forecast!$Y$3) | I7: =SUM(Forecast!F13:Forecast!I13)*($Y$3/Forecast!$Y$3) | J7: =SUM(Forecast!F13:Forecast!J13)*($Y$3/Forecast!$Y$3) | K7: =SUM(Forecast!F13:Forecast!K13)*($Y$3/Forecast!$Y$3) | L7: =SUM(Forecast!F13:Forecast!L13)*($Y$3/Forecast!$Y$3) | M7: =SUM(Forecast!F13:Forecast!M13)*($Y$3/Forecast!$Y$3) | N7: =SUM(Forecast!F13:Forecast!N13)*($Y$3/Forecast!$Y$3) | O7: =SUM(Forecast!F13:Forecast!O13)*($Y$3/Forecast!$Y$3) | P7: =SUM(Forecast!F13:Forecast!P13)*($Y$3/Forecast!$Y$3) | Q7: =SUM(Forecast!F13:Forecast!Q13)*($Y$3/Forecast!$Y$3) | R7: =SUM(Forecast!F13:Forecast!R13)*($Y$3/Forecast!$Y$3) | S7: =SUM(Forecast!F13:Forecast!S13)*($Y$3/Forecast!$Y$3) | T7: =SUM(Forecast!F13:Forecast!T13)*($Y$3/Forecast!$Y$3) | U7: =SUM(Forecast!F13:Forecast!U13)*($Y$3/Forecast!$Y$3) | V7: =SUM(Forecast!F13:Forecast!V13)*($Y$3/Forecast!$Y$3) | W7: =SUM(Forecast!F13:Forecast!W13)*($Y$3/Forecast!$Y$3) | X7: =SUM(Forecast!F13:Forecast!X13)*($Y$3/Forecast!$Y$3) | Y7: =SUM(Forecast!F13:Forecast!Y13)*($Y$3/Forecast!$Y$3) | Z7: =SUM(Forecast!F13:Forecast!Z13)*($Y$3/Forecast!$Y$3) | AA7: =SUM(Forecast!F13:Forecast!AA13)*($Y$3/Forecast!$Y$3) | AB7: =SUM(Forecast!F13:Forecast!AB13)*($Y$3/Forecast!$Y$3) | AC7: =SUM(Forecast!F13:Forecast!AC13)*($Y$3/Forecast!$Y$3) | AD7: =SUM(Forecast!F13:Forecast!AD13)*($Y$3/Forecast!$Y$3) | AE7: =SUM(Forecast!F13:Forecast!AE13)*($Y$3/Forecast!$Y$3)
B8: IDEAL | F8: =SUM(Forecast!F24:Forecast!F24)*($Y$3/Forecast!$Y$3) | G8: =SUM(Forecast!F24:Forecast!G24)*($Y$3/Forecast!$Y$3) | H8: =SUM(Forecast!F24:Forecast!H24)*($Y$3/Forecast!$Y$3) | I8: =SUM(Forecast!F24:Forecast!I24)*($Y$3/Forecast!$Y$3) | J8: =SUM(Forecast!F24:Forecast!J24)*($Y$3/Forecast!$Y$3) | K8: =SUM(Forecast!F24:Forecast!K24)*($Y$3/Forecast!$Y$3) | L8: =SUM(Forecast!F24:Forecast!L24)*($Y$3/Forecast!$Y$3) | M8: =SUM(Forecast!F24:Forecast!M24)*($Y$3/Forecast!$Y$3) | N8: =SUM(Forecast!F24:Forecast!N24)*($Y$3/Forecast!$Y$3) | O8: =SUM(Forecast!F24:Forecast!O24)*($Y$3/Forecast!$Y$3) | P8: =SUM(Forecast!F24:Forecast!P24)*($Y$3/Forecast!$Y$3) | Q8: =SUM(Forecast!F24:Forecast!Q24)*($Y$3/Forecast!$Y$3) | R8: =SUM(Forecast!F24:Forecast!R24)*($Y$3/Forecast!$Y$3) | S8: =SUM(Forecast!F24:Forecast!S24)*($Y$3/Forecast!$Y$3) | T8: =SUM(Forecast!F24:Forecast!T24)*($Y$3/Forecast!$Y$3) | U8: =SUM(Forecast!F24:Forecast!U24)*($Y$3/Forecast!$Y$3) | V8: =SUM(Forecast!F24:Forecast!V24)*($Y$3/Forecast!$Y$3) | W8: =SUM(Forecast!F24:Forecast!W24)*($Y$3/Forecast!$Y$3) | X8: =SUM(Forecast!F24:Forecast!X24)*($Y$3/Forecast!$Y$3) | Y8: =SUM(Forecast!F24:Forecast!Y24)*($Y$3/Forecast!$Y$3) | Z8: =SUM(Forecast!F24:Forecast!Z24)*($Y$3/Forecast!$Y$3) | AA8: =SUM(Forecast!F24:Forecast!AA24)*($Y$3/Forecast!$Y$3) | AB8: =SUM(Forecast!F24:Forecast!AB24)*($Y$3/Forecast!$Y$3) | AC8: =SUM(Forecast!F24:Forecast!AC24)*($Y$3/Forecast!$Y$3) | AD8: =SUM(Forecast!F24:Forecast!AD24)*($Y$3/Forecast!$Y$3) | AE8: =SUM(Forecast!F24:Forecast!AE24)*($Y$3/Forecast!$Y$3)
B9: WORST | F9: =SUM(Forecast!F35:Forecast!F35)*($Y$3/Forecast!$Y$3) | G9: =SUM(Forecast!F35:Forecast!G35)*($Y$3/Forecast!$Y$3) | H9: =SUM(Forecast!F35:Forecast!H35)*($Y$3/Forecast!$Y$3) | I9: =SUM(Forecast!F35:Forecast!I35)*($Y$3/Forecast!$Y$3) | J9: =SUM(Forecast!F35:Forecast!J35)*($Y$3/Forecast!$Y$3) | K9: =SUM(Forecast!F35:Forecast!K35)*($Y$3/Forecast!$Y$3) | L9: =SUM(Forecast!F35:Forecast!L35)*($Y$3/Forecast!$Y$3) | M9: =SUM(Forecast!F35:Forecast!M35)*($Y$3/Forecast!$Y$3) | N9: =SUM(Forecast!F35:Forecast!N35)*($Y$3/Forecast!$Y$3) | O9: =SUM(Forecast!F35:Forecast!O35)*($Y$3/Forecast!$Y$3) | P9: =SUM(Forecast!F35:Forecast!P35)*($Y$3/Forecast!$Y$3) | Q9: =SUM(Forecast!F35:Forecast!Q35)*($Y$3/Forecast!$Y$3) | R9: =SUM(Forecast!F35:Forecast!R35)*($Y$3/Forecast!$Y$3) | S9: =SUM(Forecast!F35:Forecast!S35)*($Y$3/Forecast!$Y$3) | T9: =SUM(Forecast!F35:Forecast!T35)*($Y$3/Forecast!$Y$3) | U9: =SUM(Forecast!F35:Forecast!U35)*($Y$3/Forecast!$Y$3) | V9: =SUM(Forecast!F35:Forecast!V35)*($Y$3/Forecast!$Y$3) | W9: =SUM(Forecast!F35:Forecast!W35)*($Y$3/Forecast!$Y$3) | X9: =SUM(Forecast!F35:Forecast!X35)*($Y$3/Forecast!$Y$3) | Y9: =SUM(Forecast!F35:Forecast!Y35)*($Y$3/Forecast!$Y$3) | Z9: =SUM(Forecast!F35:Forecast!Z35)*($Y$3/Forecast!$Y$3) | AA9: =SUM(Forecast!F35:Forecast!AA35)*($Y$3/Forecast!$Y$3) | AB9: =SUM(Forecast!F35:Forecast!AB35)*($Y$3/Forecast!$Y$3) | AC9: =SUM(Forecast!F35:Forecast!AC35)*($Y$3/Forecast!$Y$3) | AD9: =SUM(Forecast!F35:Forecast!AD35)*($Y$3/Forecast!$Y$3) | AE9: =SUM(Forecast!F35:Forecast!AE35)*($Y$3/Forecast!$Y$3)
B12: Break-Even Analysis
B13: Scenario | C13: Break-even Week | D13: Wk-commencing | E13: Y1 Net Profit | F13: Status
B14: BEST | C14: =IFERROR(MATCH(TRUE,INDEX(F7:AE7>0,0),0),0) | D14: =IF(C14>0,StartDate+7*(C14-1),"never") | E14: =AE7 | F14: =IF(E14>=0,"Pays back","Loss-making")
B15: IDEAL | C15: =IFERROR(MATCH(TRUE,INDEX(F8:AE8>0,0),0),0) | D15: =IF(C15>0,StartDate+7*(C15-1),"never") | E15: =AE8 | F15: =IF(E15>=0,"Pays back","Loss-making")
B16: WORST | C16: =IFERROR(MATCH(TRUE,INDEX(F9:AE9>0,0),0),0) | D16: =IF(C16>0,StartDate+7*(C16-1),"never") | E16: =AE9 | F16: =IF(E16>=0,"Pays back","Loss-making")

Sheet Sensitivity
B2: ="SENSITIVITY — IDEAL scenario Net Profit (GBP) (×lift vs ×demo cost)"
B3: Each cell shows Y1 Net Profit if BOTH Demo-week lift multipliers AND the Demo Total £/week were the values at that row/column intersection. Highlights how robust the IDEAL plan is.
B5: Lift ↓ / Demo Cost → | C5: 5000 | D5: 6000 | E5: 7403 | F5: 9000 | G5: 11000 | H5: 13000
B6: 2 | C6: =24*BaseUnits*(Price-Cost)+2*BaseUnits*2.0*(Price-Cost)-2*(5000+EndCapCost+BaseUnits*2.0*Price*TPDPct) | D6: =24*BaseUnits*(Price-Cost)+2*BaseUnits*2.0*(Price-Cost)-2*(6000+EndCapCost+BaseUnits*2.0*Price*TPDPct) | E6: =24*BaseUnits*(Price-Cost)+2*BaseUnits*2.0*(Price-Cost)-2*(7403+EndCapCost+BaseUnits*2.0*Price*TPDPct) | F6: =24*BaseUnits*(Price-Cost)+2*BaseUnits*2.0*(Price-Cost)-2*(9000+EndCapCost+BaseUnits*2.0*Price*TPDPct) | G6: =24*BaseUnits*(Price-Cost)+2*BaseUnits*2.0*(Price-Cost)-2*(11000+EndCapCost+BaseUnits*2.0*Price*TPDPct) | H6: =24*BaseUnits*(Price-Cost)+2*BaseUnits*2.0*(Price-Cost)-2*(13000+EndCapCost+BaseUnits*2.0*Price*TPDPct)
B7: 2.5 | C7: =24*BaseUnits*(Price-Cost)+2*BaseUnits*2.5*(Price-Cost)-2*(5000+EndCapCost+BaseUnits*2.5*Price*TPDPct) | D7: =24*BaseUnits*(Price-Cost)+2*BaseUnits*2.5*(Price-Cost)-2*(6000+EndCapCost+BaseUnits*2.5*Price*TPDPct) | E7: =24*BaseUnits*(Price-Cost)+2*BaseUnits*2.5*(Price-Cost)-2*(7403+EndCapCost+BaseUnits*2.5*Price*TPDPct) | F7: =24*BaseUnits*(Price-Cost)+2*BaseUnits*2.5*(Price-Cost)-2*(9000+EndCapCost+BaseUnits*2.5*Price*TPDPct) | G7: =24*BaseUnits*(Price-Cost)+2*BaseUnits*2.5*(Price-Cost)-2*(11000+EndCapCost+BaseUnits*2.5*Price*TPDPct) | H7: =24*BaseUnits*(Price-Cost)+2*BaseUnits*2.5*(Price-Cost)-2*(13000+EndCapCost+BaseUnits*2.5*Price*TPDPct)
B8: 3 | C8: =24*BaseUnits*(Price-Cost)+2*BaseUnits*3.0*(Price-Cost)-2*(5000+EndCapCost+BaseUnits*3.0*Price*TPDPct) | D8: =24*BaseUnits*(Price-Cost)+2*BaseUnits*3.0*(Price-Cost)-2*(6000+EndCapCost+BaseUnits*3.0*Price*TPDPct) | E8: =24*BaseUnits*(Price-Cost)+2*BaseUnits*3.0*(Price-Cost)-2*(7403+EndCapCost+BaseUnits*3.0*Price*TPDPct) | F8: =24*BaseUnits*(Price-Cost)+2*BaseUnits*3.0*(Price-Cost)-2*(9000+EndCapCost+BaseUnits*3.0*Price*TPDPct) | G8: =24*BaseUnits*(Price-Cost)+2*BaseUnits*3.0*(Price-Cost)-2*(11000+EndCapCost+BaseUnits*3.0*Price*TPDPct) | H8: =24*BaseUnits*(Price-Cost)+2*BaseUnits*3.0*(Price-Cost)-2*(13000+EndCapCost+BaseUnits*3.0*Price*TPDPct)
B9: 3.6 | C9: =24*BaseUnits*(Price-Cost)+2*BaseUnits*3.6*(Price-Cost)-2*(5000+EndCapCost+BaseUnits*3.6*Price*TPDPct) | D9: =24*BaseUnits*(Price-Cost)+2*BaseUnits*3.6*(Price-Cost)-2*(6000+EndCapCost+BaseUnits*3.6*Price*TPDPct) | E9: =24*BaseUnits*(Price-Cost)+2*BaseUnits*3.6*(Price-Cost)-2*(7403+EndCapCost+BaseUnits*3.6*Price*TPDPct) | F9: =24*BaseUnits*(Price-Cost)+2*BaseUnits*3.6*(Price-Cost)-2*(9000+EndCapCost+BaseUnits*3.6*Price*TPDPct) | G9: =24*BaseUnits*(Price-Cost)+2*BaseUnits*3.6*(Price-Cost)-2*(11000+EndCapCost+BaseUnits*3.6*Price*TPDPct) | H9: =24*BaseUnits*(Price-Cost)+2*BaseUnits*3.6*(Price-Cost)-2*(13000+EndCapCost+BaseUnits*3.6*Price*TPDPct)
B10: 4 | C10: =24*BaseUnits*(Price-Cost)+2*BaseUnits*4.0*(Price-Cost)-2*(5000+EndCapCost+BaseUnits*4.0*Price*TPDPct) | D10: =24*BaseUnits*(Price-Cost)+2*BaseUnits*4.0*(Price-Cost)-2*(6000+EndCapCost+BaseUnits*4.0*Price*TPDPct) | E10: =24*BaseUnits*(Price-Cost)+2*BaseUnits*4.0*(Price-Cost)-2*(7403+EndCapCost+BaseUnits*4.0*Price*TPDPct) | F10: =24*BaseUnits*(Price-Cost)+2*BaseUnits*4.0*(Price-Cost)-2*(9000+EndCapCost+BaseUnits*4.0*Price*TPDPct) | G10: =24*BaseUnits*(Price-Cost)+2*BaseUnits*4.0*(Price-Cost)-2*(11000+EndCapCost+BaseUnits*4.0*Price*TPDPct) | H10: =24*BaseUnits*(Price-Cost)+2*BaseUnits*4.0*(Price-Cost)-2*(13000+EndCapCost+BaseUnits*4.0*Price*TPDPct)
B11: 4.5 | C11: =24*BaseUnits*(Price-Cost)+2*BaseUnits*4.5*(Price-Cost)-2*(5000+EndCapCost+BaseUnits*4.5*Price*TPDPct) | D11: =24*BaseUnits*(Price-Cost)+2*BaseUnits*4.5*(Price-Cost)-2*(6000+EndCapCost+BaseUnits*4.5*Price*TPDPct) | E11: =24*BaseUnits*(Price-Cost)+2*BaseUnits*4.5*(Price-Cost)-2*(7403+EndCapCost+BaseUnits*4.5*Price*TPDPct) | F11: =24*BaseUnits*(Price-Cost)+2*BaseUnits*4.5*(Price-Cost)-2*(9000+EndCapCost+BaseUnits*4.5*Price*TPDPct) | G11: =24*BaseUnits*(Price-Cost)+2*BaseUnits*4.5*(Price-Cost)-2*(11000+EndCapCost+BaseUnits*4.5*Price*TPDPct) | H11: =24*BaseUnits*(Price-Cost)+2*BaseUnits*4.5*(Price-Cost)-2*(13000+EndCapCost+BaseUnits*4.5*Price*TPDPct)
B12: 5 | C12: =24*BaseUnits*(Price-Cost)+2*BaseUnits*5.0*(Price-Cost)-2*(5000+EndCapCost+BaseUnits*5.0*Price*TPDPct) | D12: =24*BaseUnits*(Price-Cost)+2*BaseUnits*5.0*(Price-Cost)-2*(6000+EndCapCost+BaseUnits*5.0*Price*TPDPct) | E12: =24*BaseUnits*(Price-Cost)+2*BaseUnits*5.0*(Price-Cost)-2*(7403+EndCapCost+BaseUnits*5.0*Price*TPDPct) | F12: =24*BaseUnits*(Price-Cost)+2*BaseUnits*5.0*(Price-Cost)-2*(9000+EndCapCost+BaseUnits*5.0*Price*TPDPct) | G12: =24*BaseUnits*(Price-Cost)+2*BaseUnits*5.0*(Price-Cost)-2*(11000+EndCapCost+BaseUnits*5.0*Price*TPDPct) | H12: =24*BaseUnits*(Price-Cost)+2*BaseUnits*5.0*(Price-Cost)-2*(13000+EndCapCost+BaseUnits*5.0*Price*TPDPct)
B14: Reading the grid
B15: • Centre cell (lift 3.6x, demo £7,403) ≈ the IDEAL base case. Green = better Net Profit, red = worse. If your numbers land in the red zone, the plan is exposed.
B17: Note: this grid is GBP-only (the model's source currency). Switch the display currency on other tabs for reporting.

Sheet Summary
B2: ="ROI SUMMARY (Display: "&$Z$3&" "&$C$3&")"
B3: Display Currency | C3: GBP | D3: ="("&VLOOKUP(C3,Inputs!$B$13:$D$16,2,FALSE)&" · rate "&TEXT(VLOOKUP(C3,Inputs!$B$13:$D$16,3,FALSE),"0.0000")&")" | Y3: =VLOOKUP(C3,Inputs!$B$13:$D$16,3,FALSE) | Z3: =VLOOKUP(C3,Inputs!$B$13:$D$16,2,FALSE)
B4: ="Test window: W1 ("&TEXT(StartDate,"dd-mmm-yyyy")&") → W"&Period&" ("&TEXT(StartDate+7*(Period-1),"dd-mmm-yyyy")&")"
B6: Metric | C6: BEST | D6: IDEAL | E6: WORST | F6: E[Value]
B7: Probability weight | C7: =PBest | D7: =PIdeal | E7: =PWorst | F7: =PBest+PIdeal+PWorst
B8: Units Sold | C8: =Forecast!AF8 | D8: =Forecast!AF19 | E8: =Forecast!AF30 | F8: =C8*PBest+D8*PIdeal+E8*PWorst
B9: ="Revenue ("&$Z$3&")" | C9: =Forecast!AF9*($Y$3/Forecast!$Y$3) | D9: =Forecast!AF20*($Y$3/Forecast!$Y$3) | E9: =Forecast!AF31*($Y$3/Forecast!$Y$3) | F9: =C9*PBest+D9*PIdeal+E9*PWorst
B10: ="Gross Profit ("&$Z$3&")" | C10: =Forecast!AF11*($Y$3/Forecast!$Y$3) | D10: =Forecast!AF22*($Y$3/Forecast!$Y$3) | E10: =Forecast!AF33*($Y$3/Forecast!$Y$3) | F10: =C10*PBest+D10*PIdeal+E10*PWorst
B11: Gross Margin % | C11: =IFERROR(Forecast!AF11/Forecast!AF9,0) | D11: =IFERROR(Forecast!AF22/Forecast!AF20,0) | E11: =IFERROR(Forecast!AF33/Forecast!AF31,0) | F11: =C11*PBest+D11*PIdeal+E11*PWorst
B12: ="Promo Spend ("&$Z$3&")" | C12: =Forecast!AF12*($Y$3/Forecast!$Y$3) | D12: =Forecast!AF23*($Y$3/Forecast!$Y$3) | E12: =Forecast!AF34*($Y$3/Forecast!$Y$3) | F12: =C12*PBest+D12*PIdeal+E12*PWorst
B13: ="Net Profit ("&$Z$3&")" | C13: =Forecast!AF13*($Y$3/Forecast!$Y$3) | D13: =Forecast!AF24*($Y$3/Forecast!$Y$3) | E13: =Forecast!AF35*($Y$3/Forecast!$Y$3) | F13: =C13*PBest+D13*PIdeal+E13*PWorst
B14: ROI on Promo Spend | C14: =IFERROR(Forecast!AF13/Forecast!AF12,0) | D14: =IFERROR(Forecast!AF24/Forecast!AF23,0) | E14: =IFERROR(Forecast!AF35/Forecast!AF34,0) | F14: =C14*PBest+D14*PIdeal+E14*PWorst
B17: Scenario notes
B18: BEST | C18: Demo + TPD only. ~3x lift in-promo. No end cap, no clearance.
B19: IDEAL | C19: Demo + end cap + TPD stacked. ~3.6x lift.
B20: WORST | C20: Launch as IDEAL; 50% markdown to clear residual stock Wks 18-20.

Sheet Portfolio
B2: ="PORTFOLIO — D93 Pitch SKUs · 3-Year View (Display: "&$Z$3&" "&$C$3&")"
B3: Display Currency | C3: GBP | D3: ="("&VLOOKUP(C3,Inputs!$B$13:$D$16,2,FALSE)&" · rate "&TEXT(VLOOKUP(C3,Inputs!$B$13:$D$16,3,FALSE),"0.0000")&")" | Y3: =VLOOKUP(C3,Inputs!$B$13:$D$16,3,FALSE) | Z3: =VLOOKUP(C3,Inputs!$B$13:$D$16,2,FALSE)
B4: Enter SP / Cost / Y1 Units / Y1 Promo / Growth % per SKU. All inputs in GBP — display column converts. Y2 and Y3 use the per-SKU growth rate.
B6: # | C6: SKU | D6: ="SP ("&$Z$3&")" | E6: ="Cost ("&$Z$3&")" | F6: GM % | G6: Y1 Units | H6: ="Y1 Revenue ("&$Z$3&")" | I6: ="Y1 Promo ("&$Z$3&")" | J6: ="Y1 Net ("&$Z$3&")" | K6: Growth | L6: ="Y2 Net ("&$Z$3&")" | M6: ="Y3 Net ("&$Z$3&")" | N6: ="3-Yr Net ("&$Z$3&")" | O6: 3-Yr ROI | P6: Rationale
B7: 1 | C7: Bee Propolis Spray 30ml x2 | D7: 15.99 | E7: 7.29 | F7: =IFERROR((D7-E7)/D7,0) | G7: 17000 | H7: =IFERROR(G7*D7*$Y$3,0) | I7: 25000 | J7: =IFERROR((G7*(D7-E7)-I7)*$Y$3,0) | K7: 0.1 | L7: =IFERROR(J7*(1+K7),0) | M7: =IFERROR(L7*(1+K7),0) | N7: =J7+L7+M7 | O7: =IFERROR(N7/(I7*$Y$3),0) | P7: Lead pitch — strong GP%.
B8: 2 | C8: Mag 8-in-1 90's/120's | F8: =IFERROR((D8-E8)/D8,0) | H8: =IFERROR(G8*D8*$Y$3,0) | J8: =IFERROR((G8*(D8-E8)-I8)*$Y$3,0) | K8: 0.1 | L8: =IFERROR(J8*(1+K8),0) | M8: =IFERROR(L8*(1+K8),0) | N8: =J8+L8+M8 | O8: =IFERROR(N8/(I8*$Y$3),0)
B9: 3 | C9: O1 450g | F9: =IFERROR((D9-E9)/D9,0) | H9: =IFERROR(G9*D9*$Y$3,0) | J9: =IFERROR((G9*(D9-E9)-I9)*$Y$3,0) | K9: 0.1 | L9: =IFERROR(J9*(1+K9),0) | M9: =IFERROR(L9*(1+K9),0) | N9: =J9+L9+M9 | O9: =IFERROR(N9/(I9*$Y$3),0)
B10: 4 | C10: Belli Bliss Raspberry, 450g | F10: =IFERROR((D10-E10)/D10,0) | H10: =IFERROR(G10*D10*$Y$3,0) | J10: =IFERROR((G10*(D10-E10)-I10)*$Y$3,0) | K10: 0.1 | L10: =IFERROR(J10*(1+K10),0) | M10: =IFERROR(L10*(1+K10),0) | N10: =J10+L10+M10 | O10: =IFERROR(N10/(I10*$Y$3),0)
B11: 5 | C11: Daily Boost | F11: =IFERROR((D11-E11)/D11,0) | H11: =IFERROR(G11*D11*$Y$3,0) | J11: =IFERROR((G11*(D11-E11)-I11)*$Y$3,0) | K11: 0.1 | L11: =IFERROR(J11*(1+K11),0) | M11: =IFERROR(L11*(1+K11),0) | N11: =J11+L11+M11 | O11: =IFERROR(N11/(I11*$Y$3),0)
B12: 6 | C12: Berberine 90's/120's | F12: =IFERROR((D12-E12)/D12,0) | H12: =IFERROR(G12*D12*$Y$3,0) | J12: =IFERROR((G12*(D12-E12)-I12)*$Y$3,0) | K12: 0.1 | L12: =IFERROR(J12*(1+K12),0) | M12: =IFERROR(L12*(1+K12),0) | N12: =J12+L12+M12 | O12: =IFERROR(N12/(I12*$Y$3),0)
B13: 7 | C13: L-theanine Capsules 90's/120's | F13: =IFERROR((D13-E13)/D13,0) | H13: =IFERROR(G13*D13*$Y$3,0) | J13: =IFERROR((G13*(D13-E13)-I13)*$Y$3,0) | K13: 0.1 | L13: =IFERROR(J13*(1+K13),0) | M13: =IFERROR(L13*(1+K13),0) | N13: =J13+L13+M13 | O13: =IFERROR(N13/(I13*$Y$3),0)
C14: PORTFOLIO TOTAL / BLENDED | F14: =IFERROR(SUMPRODUCT(G7:G13,D7:D13-E7:E13)/SUM(H7:H13)*$Y$3,0) | G14: =SUM(G7:G13) | H14: =SUM(H7:H13) | I14: =SUM(I7:I13) | J14: =SUM(J7:J13) | L14: =SUM(L7:L13) | M14: =SUM(M7:M13) | N14: =SUM(N7:N13) | O14: =IFERROR(N14/(I14*$Y$3),0) | P14: Blended across SKUs

Sheet Pitch Memo
B2: PITCH MEMO — D93 Portfolio (live numbers)
B3: Display Currency | C3: GBP | D3: ="("&VLOOKUP(C3,Inputs!$B$13:$D$16,2,FALSE)&" · rate "&TEXT(VLOOKUP(C3,Inputs!$B$13:$D$16,3,FALSE),"0.0000")&")" | Y3: =VLOOKUP(C3,Inputs!$B$13:$D$16,3,FALSE) | Z3: =VLOOKUP(C3,Inputs!$B$13:$D$16,2,FALSE)
B5: THE ASK
B6: ="Approve the D93 portfolio pitch for Costco UK — seven SKUs, Bee Propolis Spray as lead, targeting a 26-week market test starting "&TEXT(StartDate,"dd-mmm-yyyy")&"."
B8: HEADLINE
B9: ="Expected-value Net Profit on the Bee Propolis test: "&$Z$3&" "&TEXT(Summary!F13*($Y$3/Summary!$Y$3),"#,##0")&" across BEST/IDEAL/WORST weighted "&TEXT(PBest,"0%")&"/"&TEXT(PIdeal,"0%")&"/"&TEXT(PWorst,"0%")&"."
B11: BEST CASE
B12: ="If BEST plays out: Net Profit "&$Z$3&" "&TEXT(Summary!C13*($Y$3/Summary!$Y$3),"#,##0")&"."
B14: BASE CASE (IDEAL)
B15: ="IDEAL Net Profit "&$Z$3&" "&TEXT(Summary!D13*($Y$3/Summary!$Y$3),"#,##0")&", GM% "&TEXT(Summary!D11,"0.0%")&", ROI on promo "&TEXT(Summary!D14,"0%")&"."
B17: WORST CASE
B18: ="WORST Net Profit "&$Z$3&" "&TEXT(Summary!E13*($Y$3/Summary!$Y$3),"#,##0")&" (markdown clearance Wks 18-20)."
B20: 3-YEAR PORTFOLIO
B21: ="Blended 3-year Net Profit across all seven SKUs: "&$Z$3&" "&TEXT(Portfolio!N14*($Y$3/Portfolio!$Y$3),"#,##0")&". Blended ROI: "&TEXT(Portfolio!O14,"0%")&"."
B23: WHY THIS MIX
B24: ="Bee Propolis carries the GM% anchor ("&TEXT(Portfolio!F7,"0.0%")&"); lower-margin SKUs contribute volume. Blended GM% = "&TEXT(Portfolio!F14,"0.0%")&"."
B26: KEY ASSUMPTIONS
B27: ="Base demand "&TEXT(BaseUnits,"#,##0")&" units/week across "&TEXT(WHs,"#,##0")&" warehouses. Demo lift 3.0-3.6x. TPD = "&TEXT(TPDPct,"0%")&" off net."
B29: RISKS
B30: ="(1) Demo lift below 3x → see Sensitivity tab. (2) Inventory overrun forces markdown → WORST. (3) FX move on COGS — model is GBP-source, refresh FX Table on Inputs."
B32: DECISION
B33: ="GO / NO-GO with terms by [date]. Test launches W1 = "&TEXT(StartDate,"dd-mmm-yyyy")&"."
