Workbook
Name scnList: 'Lookups_and_Assumptions'!$B$6:$B$12
Name bizList: 'Lookups_and_Assumptions'!$B$15:$B$19
Name ccyList: 'Lookups_and_Assumptions'!$B$22:$B$25
Name selScenario: 'Inputs_and_Control_Center'!$C$7
Name selBusinessModel: 'Inputs_and_Control_Center'!$C$8
Name selBaseCurrency: 'Inputs_and_Control_Center'!$C$9
Name selReportingCurrency: 'Inputs_and_Control_Center'!$C$10
Name TargetGM: 'Inputs_and_Control_Center'!$F$6
Name TargetNM: 'Inputs_and_Control_Center'!$F$7
Name TargetROI: 'Inputs_and_Control_Center'!$F$8
Name MaxTradePct: 'Inputs_and_Control_Center'!$F$9
Name MinContribUnit: 'Inputs_and_Control_Center'!$F$10
Name SKU: 'Inputs_and_Control_Center'!$C$14
Name UnitsPerCase: 'Inputs_and_Control_Center'!$C$20
Name NumStores: 'Inputs_and_Control_Center'!$C$22
Name ListPrice: 'Inputs_and_Control_Center'!$C$24
Name InvoicePrice: 'Inputs_and_Control_Center'!$C$25
Name WholesalePrice: 'Inputs_and_Control_Center'!$C$26
Name SRP: 'Inputs_and_Control_Center'!$C$27
Name PromoRetail: 'Inputs_and_Control_Center'!$C$28
Name PromoDepth: 'Inputs_and_Control_Center'!$C$29
Name RetailerMargin: 'Inputs_and_Control_Center'!$C$30
Name DistributorMargin: 'Inputs_and_Control_Center'!$C$31
Name vc_pu: 'Inputs_and_Control_Center'!$C$44
Name BrokerPct: 'Inputs_and_Control_Center'!$C$45
Name DistributorPct: 'Inputs_and_Control_Center'!$C$46
Name vc_pct: 'Inputs_and_Control_Center'!$C$47
Name ded_trade_pu: 'Inputs_and_Control_Center'!$C$67
Name ded_trade_pct: 'Inputs_and_Control_Center'!$D$67
Name ded_trade_fix: 'Inputs_and_Control_Center'!$E$67
Name ded_other_pu: 'Inputs_and_Control_Center'!$C$75
Name ded_other_pct: 'Inputs_and_Control_Center'!$D$75
Name ded_other_fix: 'Inputs_and_Control_Center'!$E$75
Name ForecastUnits: 'Inputs_and_Control_Center'!$C$77
Name BaseUnits: 'Inputs_and_Control_Center'!$C$78
Name PromoLiftPct: 'Inputs_and_Control_Center'!$C$79
Name CannibPct: 'Inputs_and_Control_Center'!$C$80
Name ForwardBuyPct: 'Inputs_and_Control_Center'!$C$81
Name PantryPct: 'Inputs_and_Control_Center'!$C$82
Name PostDipPct: 'Inputs_and_Control_Center'!$C$83
Name VelocityPSPW: 'Inputs_and_Control_Center'!$C$84
Name PromoWeeks: 'Inputs_and_Control_Center'!$C$85
Name FillRate: 'Inputs_and_Control_Center'!$C$86
Name ACV: 'Inputs_and_Control_Center'!$C$87
Name FixedCommercialTotal: 'Inputs_and_Control_Center'!$C$97
Name MinGM: 'Inputs_and_Control_Center'!$C$99
Name MinNM: 'Inputs_and_Control_Center'!$C$100
Name PriceApprovalThr: 'Inputs_and_Control_Center'!$C$101
Name scnHeaders: 'Scenarios'!$C$6:$I$6
Name volMult: 'Scenarios'!$C$7:$I$7
Name priceMult: 'Scenarios'!$C$8:$I$8
Name vcMult: 'Scenarios'!$C$9:$I$9
Name tradeMult: 'Scenarios'!$C$10:$I$10
Name fillMult: 'Scenarios'!$C$11:$I$11
Name cannibMult: 'Scenarios'!$C$12:$I$12
Name promoFlag: 'Scenarios'!$C$13:$I$13
Name fxMult: 'Scenarios'!$C$14:$I$14
Name actVolM: 'Calculations_Gross_to_Net'!$C$6
Name actPriceM: 'Calculations_Gross_to_Net'!$C$7
Name actVcM: 'Calculations_Gross_to_Net'!$C$8

Sheet Read_Me_and_Definitions
B2: READ ME & DEFINITIONS
B3: Enterprise CPG Commercial Decision System — purpose, version control, metric definitions, and logic notes.
B5: A. MODEL PURPOSE
B6: Purpose | C6: Enterprise commercial operating tool to evaluate pricing, promotion, trade investment, distribution structure and customer profitability — and produce a GO / REVIEW / STOP decision.
B7: Decisions supported | C7: Should we take this deal? Run this promo? What wholesale price hits target margin? What is true net realized price? How much incremental volume to break even? What if cost / fill / FX move?
B8: Primary users | C8: CFO, GM, SVP Sales, RGM lead, Commercial Finance, Category & Customer teams.
B9: Owner | C9: Commercial Finance Systems (model owner). Business owner: RGM lead.
B10: Model grain | C10: One product × one customer/retailer/distributor path × one scenario × one market × one currency. Template is reusable across SKUs/customers.
B11: B. VERSION CONTROL
B12: Model name | C12: CPG Commercial Decision System
B13: Version | C13: 1.0
B14: Owner | C14: Commercial Finance Systems
B15: Created | C15: 2026-06-26
B16: Last update | C16: 2026-06-26
B17: Change log | C17: v1.0 — initial build: GtN engine, scenario engine, promo ROI, FX, dashboard, audit.
B19: C. METRIC DEFINITIONS
B20: Metric | C20: Definition / formula
B21: Gross Sales | C21: Effective Units × Active Wholesale Price.
B22: On-Invoice Deductions | C22: Trade deductions taken on the invoice (per-unit trade elements).
B23: Off-Invoice Deductions | C23: Trade taken after invoice: scan/bill backs, markdown, display, % & fixed trade.
B24: Gross-to-Net Deductions | C24: On-invoice + off-invoice trade + other financial deductions (accruals, EPD, customer deductions, chargebacks, claims).
B25: Net Sales | C25: Gross Sales − Total Gross-to-Net Deductions.
B26: Gross Profit / Margin % | C26: Gross Sales − Total Variable Cost ; ÷ Gross Sales.
B27: Contribution / Margin % | C27: Net Sales − Total Variable Cost ; ÷ Net Sales.
B28: Net Profit / Margin % | C28: Contribution − Fixed Commercial Cost ; ÷ Net Sales.
B29: Trade Spend $ / % Gross / % Net | C29: Sum of trade-investment elements ; ÷ Gross ; ÷ Net.
B30: Net Realized Price /unit /case | C30: Net Sales ÷ Effective Units (or ÷ cases).
B31: Profit per Unit / Case | C31: Net Profit ÷ Effective Units (or ÷ cases).
... B38: Trade Efficiency | C38: Net Profit ÷ Trade Spend ($ profit per $ trade).
B39: D. LOGIC NOTES
B40: Variable cost | C40: Per-unit: COGS, packaging, co-man, inbound/outbound freight, duty, warehousing, compliance, returns/spoilage, other. Plus broker & distributor fees as % of gross.
B41: Fixed commercial cost | C41: Annualized account support, broker support, account mgmt, merchandising, listing amortization, promo development, other.
B42: Distributor fees | C42: Modeled as % of gross (variable) and, where relevant, in distributor margin grossing-up of shelf price.
B43: Retailer margin | C43: Shelf price = distributor sell ÷ (1 − retailer margin); distributor sell = wholesale ÷ (1 − distributor margin) when business model = Distributor.
B44: Scenario overrides | C44: Each scenario stores driver MULTIPLIERS (1.00 = base) for volume, price, var-cost, trade, fill, cannibalization, promo flag, FX. The Calc engine pulls the active column via INDEX/MATCH(selScenario).
B45: FX translation | C45: Rates are USD value of 1 currency unit. value_in_reporting = value_base × fxBaseRate ÷ fxReportingRate. Edit rates on Currency_and_FX.
B46: Break-even logic | C46: Units: Fixed ÷ contribution/unit. Price: closed-form solution setting Net Margin = target (see Calc §8 helpers a,b,c).
B47: Recommendation logic | C47: GO when GM≥min, NM≥min, contribution/unit≥min, trade%≤max, and (no promo OR ROI≥hurdle). STOP when net profit<0 or contribution/unit≤0. Otherwise REVIEW.
B48: User vs calculated | C48: User inputs = YELLOW cells (Inputs tab, scenario drivers, FX rates, promo spend/lift). Everything else is a locked formula.
B49: E. HOW TO USE (60-second guide)
...

Sheet Inputs_and_Control_Center
B2: INPUTS & CONTROL CENTER
B3: Single source of truth. ONLY yellow cells are user inputs. Change an assumption and every tab recalculates instantly.
B5: CONTROL BAR — set the active scenario & targets here
B6: Model Name | C6: CPG Commercial Decision System | E6: Target Gross Margin % | F6: 0.42 | H6: DECISION STATUS | I6: =INDEX(Scenarios!$C$38:$I$38,MATCH(selScenario,scnHeaders,0))
B7: Active Scenario | C7: Base Case | E7: Target Net Margin % | F7: 0.12 | H7: MODEL INTEGRITY | I7: =chkOverall
B8: Business Model | C8: Distributor | E8: Target Promo ROI (x) | F8: 1
B9: Base Currency | C9: USD | E9: Max Trade Spend % Gross | F9: 0.22
B10: Reporting Currency | C10: CAD | E10: Min Contribution / Unit | F10: 0.15
B13: A. BUSINESS CONTEXT
B14: SKU / Product Name | C14: Zephyr Sparkling 355ml 12pk | D14: text
B15: Brand | C15: Zephyr | D15: text
B16: Customer / Retailer / Distributor | C16: National Grocery via UDF Distributor | D16: text
B17: Channel | C17: Grocery | D17: text
B18: Market / Region | C18: Canada | D18: text
B19: Launch vs Existing flag | C19: Existing | D19: text
B20: Units per Case | C20: 12 | D20: units/case
B21: Servings per Unit | C21: 1 | D21: svgs/unit
B22: Number of Stores | C22: 1200 | D22: stores
B23: B. PRICING INPUTS
B24: List Price / unit | C24: 1.8 | D24: $/unit
B25: Invoice Price / unit | C25: 1.65 | D25: $/unit
B26: Wholesale Price / unit (company sells at) | C26: 1.5 | D26: $/unit | E26: Net invoice price the company realizes before off-invoice deductions
B27: Suggested Retail Price / unit | C27: 2.49 | D27: $/unit
B28: Promo Retail Price / unit | C28: 1.99 | D28: $/unit
B29: Promo Depth % | C29: 0.2 | D29: % off SRP
B30: Retailer Target Margin % | C30: 0.3 | D30: % of retail
B31: Distributor Target Margin % | C31: 0.12 | D31: % of dist sell
B32: C. COST STACK (per unit, except broker/distributor %)
B33: Cost element | C33: $ / unit | D33: Note
B34: COGS / Product Cost | C34: 0.55 | D34: $/unit
B35: Packaging | C35: 0.09 | D35: $/unit
B36: Co-Manufacturing | C36: 0.04 | D36: $/unit
B37: Inbound Freight | C37: 0.03 | D37: $/unit
B38: Outbound Freight | C38: 0.05 | D38: $/unit
B39: Duty / Tariffs / Import | C39: 0.01 | D39: $/unit
B40: Warehousing / Pick-Pack | C40: 0.02 | D40: $/unit
B41: Compliance / Quality / Reg | C41: 0.01 | D41: $/unit
B42: Returns & Spoilage allowance | C42: 0.02 | D42: $/unit
B43: Other Variable Cost | C43: 0.01 | D43: $/unit
B44: Σ Variable Cost per Unit (sum) | C44: =SUM(C34:C43)
...

Sheet Calculations_Gross_to_Net
B2: CALCULATIONS — GROSS TO NET ENGINE
B3: Detailed line-item P&L for the ACTIVE scenario. Active multipliers are pulled from the Scenario tab via INDEX/MATCH. Formulas only — no hardcodes.
B5: 0. ACTIVE ASSUMPTION RESOLUTION (driven by selScenario)
B6: Active Volume mult | C6: =INDEX(volMult,MATCH(selScenario,scnHeaders,0))
B7: Active Price mult | C7: =INDEX(priceMult,MATCH(selScenario,scnHeaders,0))
B8: Active Var-cost mult | C8: =INDEX(vcMult,MATCH(selScenario,scnHeaders,0))
B9: Active Trade mult | C9: =INDEX(tradeMult,MATCH(selScenario,scnHeaders,0))
B10: Active Fill mult | C10: =INDEX(fillMult,MATCH(selScenario,scnHeaders,0))
B11: Active Cannib mult | C11: =INDEX(cannibMult,MATCH(selScenario,scnHeaders,0))
B12: Active Promo flag | C12: =INDEX(promoFlag,MATCH(selScenario,scnHeaders,0))
B13: Active FX stress mult | C13: =INDEX(fxMult,MATCH(selScenario,scnHeaders,0))
B14: 1. VOLUME ENGINE
B15: Effective Fill Rate | C15: =MIN(1,FillRate*actFillM)
B16: Effective Units Sold | C16: =ForecastUnits*actVolM*actFill
B17: Case Sales | C17: =actUnits/UnitsPerCase
B18: Base (non-promo) Volume | C18: =BaseUnits*actVolM
B19: Gross Promo Lift Units | C19: =actBase*PromoLiftPct*actPromoF
B20: Cannibalized Volume | C20: =actLift*CannibPct*actCannibM
B21: Forward-Buy Volume | C21: =actLift*ForwardBuyPct
B22: Post-Promo Dip Volume | C22: =actLift*PostDipPct
B23: TRUE Net Incremental Volume | C23: =actLift-actCannibVol-actDip
B24: 2. REVENUE ENGINE
B25: Active Wholesale Price /unit | C25: =WholesalePrice*actPriceM
B26: Gross Sales | C26: =actUnits*actPrice
B27: On-Invoice Deductions | C27: =(ded_trade_pu*actUnits)*actTradeM | D27: per-unit trade applied on invoice
B28: Off-Invoice Deductions | C28: =(ded_trade_pct*actGross+ded_trade_fix)*actTradeM | D28: % and fixed trade
B29: Trade Spend $ | C29: =(ded_trade_pct*actGross+ded_trade_pu*actUnits+ded_trade_fix)*actTradeM
B30: Other GtN Deductions $ | C30: =(ded_other_pct*actGross+ded_other_pu*actUnits+ded_other_fix)*actTradeM
B31: Total Gross-to-Net Deductions | C31: =actTradeSpend+actOtherDed
B32: Net Sales | C32: =actGross-actGtN
B33: Net Realized Price /unit | C33: =IF(actUnits=0,0,actNet/actUnits)
B34: Net Realized Price /case | C34: =IF(actCases=0,0,actNet/actCases)
B35: 3. COST ENGINE
B36: Variable Cost per Unit (scaled) | C36: =vc_pu*actVcM
B37: Total Per-Unit Variable Cost | C37: =actVCpu*actUnits
B38: Broker Fee $ | C38: =BrokerPct*actGross
B39: Distributor Fee $ | C39: =DistributorPct*actGross
B40: Total Variable Cost | C40: =actVCpu*actUnits+vc_pct*actGross
B41: Fixed Commercial Cost | C41: =FixedCommercialTotal
B42: Total Direct Cost | C42: =actVCost+actFixed
...

Sheet Scenarios
B2: SCENARIO ENGINE
B3: Each scenario is a set of DRIVER MULTIPLIERS on the base inputs. The active scenario (selScenario) is read by the Calc engine via INDEX/MATCH.
B6: Driver (multiplier on base; 1.00 = base) | C6: Base Case | D6: Promo Case | E6: High Volume Case | F6: Low Volume Case | G6: Cost Inflation Case | H6: Margin Recovery Case | I6: Custom Scenario
B7: Volume multiplier | C7: 1 | D7: 1.3 | E7: 1.2 | F7: 0.8 | G7: 1 | H7: 0.95 | I7: 1
B8: Wholesale price mult | C8: 1 | D8: 0.95 | E8: 1 | F8: 1 | G8: 1 | H8: 1.06 | I8: 1
B9: Variable cost mult | C9: 1 | D9: 1 | E9: 0.98 | F9: 1.02 | G9: 1.12 | H9: 1 | I9: 1
B10: Trade spend mult | C10: 1 | D10: 1.35 | E10: 1.05 | F10: 1 | G10: 1 | H10: 0.85 | I10: 1
B11: Fill-rate mult | C11: 1 | D11: 1 | E11: 1 | F11: 0.97 | G11: 1 | H11: 1 | I11: 1
B12: Cannibalization mult | C12: 1 | D12: 1.3 | E12: 1.1 | F12: 0.9 | G12: 1 | H12: 1 | I12: 1
B13: Promo active flag (1/0) | C13: 0 | D13: 1 | E13: 0 | F13: 0 | G13: 0 | H13: 0 | I13: 0
B14: FX stress mult | C14: 1 | D14: 1 | E14: 1 | F14: 1 | G14: 1 | H14: 1 | I14: 1
B16: SCENARIO RESULTS (full P&L computed per scenario, identical bucket math to the Calc engine)
B17: Metric | C17: Base Case | D17: Promo Case | E17: High Volume Case | F17: Low Volume Case | G17: Cost Inflation Case | H17: Margin Recovery Case | I17: Custom Scenario | K17: Hurdle test
B18: Effective Units | C18: =ForecastUnits*C7*MIN(1,FillRate*C11) | D18: =ForecastUnits*D7*MIN(1,FillRate*D11) | E18: =ForecastUnits*E7*MIN(1,FillRate*E11) | F18: =ForecastUnits*F7*MIN(1,FillRate*F11) | G18: =ForecastUnits*G7*MIN(1,FillRate*G11) | H18: =ForecastUnits*H7*MIN(1,FillRate*H11) | I18: =ForecastUnits*I7*MIN(1,FillRate*I11)
B19: Gross Sales | C19: =C18*WholesalePrice*C8 | D19: =D18*WholesalePrice*D8 | E19: =E18*WholesalePrice*E8 | F19: =F18*WholesalePrice*F8 | G19: =G18*WholesalePrice*G8 | H19: =H18*WholesalePrice*H8 | I19: =I18*WholesalePrice*I8
B20: Trade Spend $ | C20: =(ded_trade_pct*C19+ded_trade_pu*C18+ded_trade_fix)*C10 | D20: =(ded_trade_pct*D19+ded_trade_pu*D18+ded_trade_fix)*D10 | E20: =(ded_trade_pct*E19+ded_trade_pu*E18+ded_trade_fix)*E10 | F20: =(ded_trade_pct*F19+ded_trade_pu*F18+ded_trade_fix)*F10 | G20: =(ded_trade_pct*G19+ded_trade_pu*G18+ded_trade_fix)*G10 | H20: =(ded_trade_pct*H19+ded_trade_pu*H18+ded_trade_fix)*H10 | I20: =(ded_trade_pct*I19+ded_trade_pu*I18+ded_trade_fix)*I10
B21: Other GtN Deductions $ | C21: =(ded_other_pct*C19+ded_other_pu*C18+ded_other_fix)*C10 | D21: =(ded_other_pct*D19+ded_other_pu*D18+ded_other_fix)*D10 | E21: =(ded_other_pct*E19+ded_other_pu*E18+ded_other_fix)*E10 | F21: =(ded_other_pct*F19+ded_other_pu*F18+ded_other_fix)*F10 | G21: =(ded_other_pct*G19+ded_other_pu*G18+ded_other_fix)*G10 | H21: =(ded_other_pct*H19+ded_other_pu*H18+ded_other_fix)*H10 | I21: =(ded_other_pct*I19+ded_other_pu*I18+ded_other_fix)*I10
B22: Total Gross-to-Net Deductions | C22: =C20+C21 | D22: =D20+D21 | E22: =E20+E21 | F22: =F20+F21 | G22: =G20+G21 | H22: =H20+H21 | I22: =I20+I21
B23: Net Sales | C23: =C19-C22 | D23: =D19-D22 | E23: =E19-E22 | F23: =F19-F22 | G23: =G19-G22 | H23: =H19-H22 | I23: =I19-I22
B24: Total Variable Cost | C24: =(vc_pu*C9)*C18+vc_pct*C19 | D24: =(vc_pu*D9)*D18+vc_pct*D19 | E24: =(vc_pu*E9)*E18+vc_pct*E19 | F24: =(vc_pu*F9)*F18+vc_pct*F19 | G24: =(vc_pu*G9)*G18+vc_pct*G19 | H24: =(vc_pu*H9)*H18+vc_pct*H19 | I24: =(vc_pu*I9)*I18+vc_pct*I19
B25: Gross Profit $ | C25: =C19-C24 | D25: =D19-D24 | E25: =E19-E24 | F25: =F19-F24 | G25: =G19-G24 | H25: =H19-H24 | I25: =I19-I24
B26: Gross Margin % | C26: =IF(C19=0,0,C25/C19) | D26: =IF(D19=0,0,D25/D19) | E26: =IF(E19=0,0,E25/E19) | F26: =IF(F19=0,0,F25/F19) | G26: =IF(G19=0,0,G25/G19) | H26: =IF(H19=0,0,H25/H19) | I26: =IF(I19=0,0,I25/I19)
B27: Contribution $ | C27: =C23-C24 | D27: =D23-D24 | E27: =E23-E24 | F27: =F23-F24 | G27: =G23-G24 | H27: =H23-H24 | I27: =I23-I24
B28: Contribution Margin % | C28: =IF(C23=0,0,C27/C23) | D28: =IF(D23=0,0,D27/D23) | E28: =IF(E23=0,0,E27/E23) | F28: =IF(F23=0,0,F27/F23) | G28: =IF(G23=0,0,G27/G23) | H28: =IF(H23=0,0,H27/H23) | I28: =IF(I23=0,0,I27/I23)
B29: Net Profit $ | C29: =C27-FixedCommercialTotal | D29: =D27-FixedCommercialTotal | E29: =E27-FixedCommercialTotal | F29: =F27-FixedCommercialTotal | G29: =G27-FixedCommercialTotal | H29: =H27-FixedCommercialTotal | I29: =I27-FixedCommercialTotal
B30: Net Margin % | C30: =IF(C23=0,0,C29/C23) | D30: =IF(D23=0,0,D29/D23) | E30: =IF(E23=0,0,E29/E23) | F30: =IF(F23=0,0,F29/F23) | G30: =IF(G23=0,0,G29/G23) | H30: =IF(H23=0,0,H29/H23) | I30: =IF(I23=0,0,I29/I23)
B31: Trade Spend % Gross | C31: =IF(C19=0,0,C20/C19) | D31: =IF(D19=0,0,D20/D19) | E31: =IF(E19=0,0,E20/E19) | F31: =IF(F19=0,0,F20/F19) | G31: =IF(G19=0,0,G20/G19) | H31: =IF(H19=0,0,H20/H19) | I31: =IF(I19=0,0,I20/I19)
B32: Profit / Unit | C32: =IF(C18=0,0,C29/C18) | D32: =IF(D18=0,0,D29/D18) | E32: =IF(E18=0,0,E29/E18) | F32: =IF(F18=0,0,F29/F18) | G32: =IF(G18=0,0,G29/G18) | H32: =IF(H18=0,0,H29/H18) | I32: =IF(I18=0,0,I29/I18)
B33: Contribution / Unit | C33: =IF(C18=0,0,C27/C18) | D33: =IF(D18=0,0,D27/D18) | E33: =IF(E18=0,0,E27/E18) | F33: =IF(F18=0,0,F27/F18) | G33: =IF(G18=0,0,G27/G18) | H33: =IF(H18=0,0,H27/H18) | I33: =IF(I18=0,0,I27/I18)
B34: Break-Even Units | C34: =IF(C33<=0,"n/a",FixedCommercialTotal/C33) | D34: =IF(D33<=0,"n/a",FixedCommercialTotal/D33) | E34: =IF(E33<=0,"n/a",FixedCommercialTotal/E33) | F34: =IF(F33<=0,"n/a",FixedCommercialTotal/F33) | G34: =IF(G33<=0,"n/a",FixedCommercialTotal/G33) | H34: =IF(H33<=0,"n/a",FixedCommercialTotal/H33) | I34: =IF(I33<=0,"n/a",FixedCommercialTotal/I33)
B35: Promo Spend (vs Base) $ | C35: =C20-$C$20 | D35: =D20-$C$20 | E35: =E20-$C$20 | F35: =F20-$C$20 | G35: =G20-$C$20 | H35: =H20-$C$20 | I35: =I20-$C$20
B36: Incremental Net Profit (vs Base) $ | C36: =C29-$C$29 | D36: =D29-$C$29 | E36: =E29-$C$29 | F36: =F29-$C$29 | G36: =G29-$C$29 | H36: =H29-$C$29 | I36: =I29-$C$29
B37: Promo ROI (x) | C37: =IF(C35<=0,0,C36/C35) | D37: =IF(D35<=0,0,D36/D35) | E37: =IF(E35<=0,0,E36/E35) | F37: =IF(F35<=0,0,F36/F35) | G37: =IF(G35<=0,0,G36/G35) | H37: =IF(H35<=0,0,H36/H35) | I37: =IF(I35<=0,0,I36/I35)
B38: DECISION STATUS | C38: =IF(OR(C29<0,C33<=0),"STOP",IF(AND(C26>=MinGM,C30>=MinNM,C33>=MinContribUnit,C31<=MaxTradePct,OR(C13=0,C37>=TargetROI)),"GO","REVIEW")) | D38: =IF(OR(D29<0,D33<=0),"STOP",IF(AND(D26>=MinGM,D30>=MinNM,D33>=MinContribUnit,D31<=MaxTradePct,OR(D13=0,D37>=TargetROI)),"GO","REVIEW")) | E38: =IF(OR(E29<0,E33<=0),"STOP",IF(AND(E26>=MinGM,E30>=MinNM,E33>=MinContribUnit,E31<=MaxTradePct,OR(E13=0,E37>=TargetROI)),"GO","REVIEW")) | F38: =IF(OR(F29<0,F33<=0),"STOP",IF(AND(F26>=MinGM,F30>=MinNM,F33>=MinContribUnit,F31<=MaxTradePct,OR(F13=0,F37>=TargetROI)),"GO","REVIEW")) | G38: =IF(OR(G29<0,G33<=0),"STOP",IF(AND(G26>=MinGM,G30>=MinNM,G33>=MinContribUnit,G31<=MaxTradePct,OR(G13=0,G37>=TargetROI)),"GO","REVIEW")) | H38: =IF(OR(H29<0,H33<=0),"STOP",IF(AND(H26>=MinGM,H30>=MinNM,H33>=MinContribUnit,H31<=MaxTradePct,OR(H13=0,H37>=TargetROI)),"GO","REVIEW")) | I38: =IF(OR(I29<0,I33<=0),"STOP",IF(AND(I26>=MinGM,I30>=MinNM,I33>=MinContribUnit,I31<=MaxTradePct,OR(I13=0,I37>=TargetROI)),"GO","REVIEW"))
B40: VARIANCE & RANKING
B41: Net Profit variance vs Base | C41: =C29-$C$29 | D41: =D29-$C$29 | E41: =E29-$C$29 | F41: =F29-$C$29 | G41: =G29-$C$29 | H41: =H29-$C$29 | I41: =I29-$C$29
B42: Best-case Net Profit | C42: =MAX(C29:I29)
B43: Worst-case Net Profit | C43: =MIN(C29:I29)

Sheet Promotions_and_ROI
B2: PROMOTIONS & ROI
B3: Tactic-by-tactic incremental economics. Each promo is judged on TRUE incremental profit, not gross sales lift. Flags expose value-destroying programs.
B5: PER-TACTIC PROMOTION ANALYSIS (evaluated at base volume & active cost)
B6: Tactic | C6: Spend $ | D6: Base Vol | E6: Lift % | F6: Incr Vol (gross) | G6: Cannib | H6: True Incr Vol | I6: Contrib/unit | J6: Incr Contrib $ | K6: Incr Net Profit $ | L6: ROI (x) | M6: BE Lift % | N6: Verdict
B7: TPD | C7: =18000 | D7: =actBase | E7: 0.18 | F7: =D7*E7 | G7: 0.1 | H7: =F7*(1-G7) | I7: =actCPU | J7: =H7*I7 | K7: =J7-C7 | L7: =IF(C7=0,0,K7/C7) | M7: =IF(OR(actCPU<=0,D7=0),"n/a",C7/(actCPU*D7)) | N7: =IF(K7<0,"STOP",IF(L7>=TargetROI,"GO","REVIEW"))
B8: End Cap | C8: 18000 | D8: =actBase | E8: 0.12 | F8: =D8*E8 | G8: 0.15 | H8: =F8*(1-G8) | I8: =actCPU | J8: =H8*I8 | K8: =J8-C8 | L8: =IF(C8=0,0,K8/C8) | M8: =IF(OR(actCPU<=0,D8=0),"n/a",C8/(actCPU*D8)) | N8: =IF(K8<0,"STOP",IF(L8>=TargetROI,"GO","REVIEW"))
B9: Fence / Feature | C9: 12000 | D9: =actBase | E9: 0.1 | F9: =D9*E9 | G9: 0.12 | H9: =F9*(1-G9) | I9: =actCPU | J9: =H9*I9 | K9: =J9-C9 | L9: =IF(C9=0,0,K9/C9) | M9: =IF(OR(actCPU<=0,D9=0),"n/a",C9/(actCPU*D9)) | N9: =IF(K9<0,"STOP",IF(L9>=TargetROI,"GO","REVIEW"))
B10: Display Allowance | C10: 12000 | D10: =actBase | E10: 0.14 | F10: =D10*E10 | G10: 0.18 | H10: =F10*(1-G10) | I10: =actCPU | J10: =H10*I10 | K10: =J10-C10 | L10: =IF(C10=0,0,K10/C10) | M10: =IF(OR(actCPU<=0,D10=0),"n/a",C10/(actCPU*D10)) | N10: =IF(K10<0,"STOP",IF(L10>=TargetROI,"GO","REVIEW"))
B11: Advertising | C11: 9000 | D11: =actBase | E11: 0.08 | F11: =D11*E11 | G11: 0.05 | H11: =F11*(1-G11) | I11: =actCPU | J11: =H11*I11 | K11: =J11-C11 | L11: =IF(C11=0,0,K11/C11) | M11: =IF(OR(actCPU<=0,D11=0),"n/a",C11/(actCPU*D11)) | N11: =IF(K11<0,"STOP",IF(L11>=TargetROI,"GO","REVIEW"))
B12: Flyer Support | C12: 7500 | D12: =actBase | E12: 0.07 | F12: =D12*E12 | G12: 0.06 | H12: =F12*(1-G12) | I12: =actCPU | J12: =H12*I12 | K12: =J12-C12 | L12: =IF(C12=0,0,K12/C12) | M12: =IF(OR(actCPU<=0,D12=0),"n/a",C12/(actCPU*D12)) | N12: =IF(K12<0,"STOP",IF(L12>=TargetROI,"GO","REVIEW"))
B13: Digital Support | C13: 6000 | D13: =actBase | E13: 0.06 | F13: =D13*E13 | G13: 0.04 | H13: =F13*(1-G13) | I13: =actCPU | J13: =H13*I13 | K13: =J13-C13 | L13: =IF(C13=0,0,K13/C13) | M13: =IF(OR(actCPU<=0,D13=0),"n/a",C13/(actCPU*D13)) | N13: =IF(K13<0,"STOP",IF(L13>=TargetROI,"GO","REVIEW"))
B14: Demo Support | C14: 4000 | D14: =actBase | E14: 0.05 | F14: =D14*E14 | G14: 0.03 | H14: =F14*(1-G14) | I14: =actCPU | J14: =H14*I14 | K14: =J14-C14 | L14: =IF(C14=0,0,K14/C14) | M14: =IF(OR(actCPU<=0,D14=0),"n/a",C14/(actCPU*D14)) | N14: =IF(K14<0,"STOP",IF(L14>=TargetROI,"GO","REVIEW"))
B15: COMBINED STACK | C15: =SUM(C7:C14) | F15: =SUM(F7:F14) | H15: =SUM(H7:H14) | J15: =SUM(J7:J14) | K15: =SUM(K7:K14) | L15: =IF(C15=0,0,K15/C15) | N15: =IF(K15<0,"STOP",IF(L15>=TargetROI,"GO","REVIEW"))
B17: AUTOMATIC FLAGS
B18: Any tactic ROI below hurdle | C18: =IF(COUNTIF(L7:L14,"<"&TargetROI)>0,"⚠ YES","OK")
B19: Any negative incremental profit | C19: =IF(COUNTIF(K7:K14,"<0")>0,"⚠ YES","OK")
B20: Combined stack ROI below hurdle | C20: =IF(L15<TargetROI,"⚠ YES","OK")
B21: Combined trade > max trade % | C21: =IF((C15)/actGross>MaxTradePct,"⚠ YES","OK")
B22: Profit per $1 promo spend (stack) | C22: =IF(C15=0,0,K15/C15)

Sheet Currency_and_FX
B2: CURRENCY & FX
B3: Edit the rate table (USD value of 1 unit of each currency). Switch base/reporting currency on the Inputs tab. KPIs translate automatically.
B5: FX RATE TABLE (USD value of 1 unit of currency)
B6: Currency | C6: USD per 1 unit | D6: Note
B7: USD | C7: 1 | D7: reference
B8: CAD | C8: 0.73 | D8: editable
B9: JPY | C9: 0.0064 | D9: editable
B10: KRW | C10: 0.00072 | D10: editable
B12: CONVERSION FACTORS
B13: Base currency (USD value of 1 unit) | C13: =INDEX(fxRate,MATCH(selBaseCurrency,fxCcy,0))
B14: Reporting currency (USD value of 1 unit) | C14: =INDEX(fxRate,MATCH(selReportingCurrency,fxCcy,0))
B15: Base → Reporting factor | C15: =fxBaseRate/fxRptRate | D15: value_in_reporting = value_base × this
B18: TRANSLATED KPI TABLE (active scenario, all currencies)
B19: KPI (in base currency) | C19: Base value | D19: USD | E19: CAD | F19: JPY | G19: KRW
B20: Gross Sales | C20: =actGross | D20: =actGross*fxBaseRate/INDEX(fxRate,MATCH("USD",fxCcy,0)) | E20: =actGross*fxBaseRate/INDEX(fxRate,MATCH("CAD",fxCcy,0)) | F20: =actGross*fxBaseRate/INDEX(fxRate,MATCH("JPY",fxCcy,0)) | G20: =actGross*fxBaseRate/INDEX(fxRate,MATCH("KRW",fxCcy,0))
B21: Net Sales | C21: =actNet | D21: =actNet*fxBaseRate/INDEX(fxRate,MATCH("USD",fxCcy,0)) | E21: =actNet*fxBaseRate/INDEX(fxRate,MATCH("CAD",fxCcy,0)) | F21: =actNet*fxBaseRate/INDEX(fxRate,MATCH("JPY",fxCcy,0)) | G21: =actNet*fxBaseRate/INDEX(fxRate,MATCH("KRW",fxCcy,0))
B22: Trade Spend $ | C22: =actTradeSpend | D22: =actTradeSpend*fxBaseRate/INDEX(fxRate,MATCH("USD",fxCcy,0)) | E22: =actTradeSpend*fxBaseRate/INDEX(fxRate,MATCH("CAD",fxCcy,0)) | F22: =actTradeSpend*fxBaseRate/INDEX(fxRate,MATCH("JPY",fxCcy,0)) | G22: =actTradeSpend*fxBaseRate/INDEX(fxRate,MATCH("KRW",fxCcy,0))
B23: Contribution $ | C23: =actContrib | D23: =actContrib*fxBaseRate/INDEX(fxRate,MATCH("USD",fxCcy,0)) | E23: =actContrib*fxBaseRate/INDEX(fxRate,MATCH("CAD",fxCcy,0)) | F23: =actContrib*fxBaseRate/INDEX(fxRate,MATCH("JPY",fxCcy,0)) | G23: =actContrib*fxBaseRate/INDEX(fxRate,MATCH("KRW",fxCcy,0))
B24: Net Profit $ | C24: =actNP | D24: =actNP*fxBaseRate/INDEX(fxRate,MATCH("USD",fxCcy,0)) | E24: =actNP*fxBaseRate/INDEX(fxRate,MATCH("CAD",fxCcy,0)) | F24: =actNP*fxBaseRate/INDEX(fxRate,MATCH("JPY",fxCcy,0)) | G24: =actNP*fxBaseRate/INDEX(fxRate,MATCH("KRW",fxCcy,0))

Sheet Dashboard_Executive_View
B2: EXECUTIVE DASHBOARD
B3: One-screen readout for CFO / GM / SVP Sales / RGM / Commercial Finance. Color = green above hurdle, yellow caution, red below hurdle / value destruction.
B5: A. HEADER
B6: Product | C6: ='Inputs_and_Control_Center'!C14 | E6: Customer | F6: ='Inputs_and_Control_Center'!C16 | H6: Channel | I6: ='Inputs_and_Control_Center'!C17 | K6: DECISION | L6: =INDEX(Scenarios!$C$38:$I$38,MATCH(selScenario,scnHeaders,0))
B7: Scenario | C7: =selScenario | E7: Base Ccy | F7: =selBaseCurrency | H7: Reporting Ccy | I7: =selReportingCurrency | K7: INTEGRITY | L7: =chkOverall
B9: B. CORE FINANCIAL KPIs (active scenario, base currency)
B10: Gross Sales | D10: Net Sales | F10: Gross Profit $ | H10: Gross Margin %
B11: =actGross | D11: =actNet | F11: =actGP | H11: =actGM
B13: Contribution $ | D13: Contribution Margin % | F13: Net Profit $ | H13: Net Margin %
B14: =actContrib | D14: =actCM | F14: =actNP | H14: =actNM
B16: C. TRADE & DEDUCTION KPIs
B17: Total Trade Spend $ | D17: Trade % of Gross | F17: Trade % of Net | H17: Total GtN Deductions | J17: Trade Efficiency (x) | L17: GtN Leakage % of Gross
B18: =actTradeSpend | D18: =actTradePctG | F18: =actTradePctN | H18: =actGtN | J18: =actTradeEff | L18: =IF(actGross=0,0,actGtN/actGross)
B21: D. UNIT ECONOMICS | E. BREAK-EVEN
B22: Net Realized Price /unit | D22: Net Realized Price /case | F22: Profit / Unit | H22: Profit / Case | J22: Break-Even Units | L22: BE Wholesale Price
B23: =actNRPunit | D23: =actNRPcase | F23: =actPPU | H23: =actPPC | J23: =beUnits | L23: =beWholesale
B25: F. CUSTOMER PATH ECONOMICS
B26: Retailer Margin % | D26: Retailer $ /unit | F26: Distributor Margin % | H26: Distributor $ /unit | J26: Company Net Real. /unit | L26: Retail Shelf Price
B27: =actRetMgnPct | D27: =actRetMgnU | F27: =actDistMgnPct | H27: =actDistMgnU | J27: =actNRPunit | L27: =actRetailReq
B29: G. SCENARIO COMPARISON
B30: Metric | D30: Base | E30: Active | F30: Best NP | G30: Worst NP | H30: Δ vs Base
B31: Net Profit $ | D31: =Scenarios!C29 | E31: =INDEX(Scenarios!$C$29:$I$29,MATCH(selScenario,scnHeaders,0)) | F31: =MAX(Scenarios!C29:I29) | G31: =MIN(Scenarios!C29:I29) | H31: =E31-D31
B32: Net Margin % | D32: =Scenarios!C30 | E32: =INDEX(Scenarios!$C$30:$I$30,MATCH(selScenario,scnHeaders,0)) | F32: =MAX(Scenarios!C30:I30) | G32: =MIN(Scenarios!C30:I30) | H32: =E32-D32
B33: Gross Margin % | D33: =Scenarios!C26 | E33: =INDEX(Scenarios!$C$26:$I$26,MATCH(selScenario,scnHeaders,0)) | F33: =MAX(Scenarios!C26:I26) | G33: =MIN(Scenarios!C26:I26) | H33: =E33-D33
B34: Trade % Gross | D34: =Scenarios!C31 | E34: =INDEX(Scenarios!$C$31:$I$31,MATCH(selScenario,scnHeaders,0)) | F34: =MAX(Scenarios!C31:I31) | G34: =MIN(Scenarios!C31:I31) | H34: =E34-D34
B36: H. GROSS-TO-NET WATERFALL & TRADE MIX
B37: Gross Sales | C37: =actGross
B38: On-Invoice | C38: =-actOnInv
B39: Off-Invoice | C39: =-actOffInv
B40: Other GtN | C40: =-actOtherDed
B41: Net Sales | C41: =actNet
B42: Variable Cost | C42: =-actVCost
B43: Contribution | C43: =actContrib
B44: Fixed | C44: =-actFixed
B45: Net Profit | C45: =actNP

Sheet Checks_Controls_and_Audit
B2: CHECKS, CONTROLS & AUDIT
B3: Automated integrity tests. If any CRITICAL check fails, the model is flagged UNSAFE and the banner turns red. Review before any business decision.
B5: =IF(chkOverall="HEALTHY","✔ MODEL HEALTHY — SAFE TO USE","⚠ "&chkOverall)
B7: CONTROL CHECKS
B8: # | C8: Check | D8: Expected | E8: Actual / delta | F8: Status | G8: Severity
B9: 1 | C9: Net Sales ≤ Gross Sales | D9: actNet | E9: TRUE | F9: =IF(actNet<=actGross,"PASS","FAIL") | G9: Critical
B10: 2 | C10: Calc Net Sales = Scenario-table Net Sales | D10: ABS<$1 | E10: =actNet-(INDEX(Scenarios!$C$23:$I$23,MATCH(selScenario,scnHeaders,0))) | F10: =IF(ABS(actNet-(INDEX(Scenarios!$C$23:$I$23,MATCH(selScenario,scnHeaders,0))))<1,"PASS","FAIL") | G10: Critical
B11: 3 | C11: Calc Net Profit = Scenario-table Net Profit | D11: ABS<$1 | E11: =actNP-(INDEX(Scenarios!$C$29:$I$29,MATCH(selScenario,scnHeaders,0))) | F11: =IF(ABS(actNP-(INDEX(Scenarios!$C$29:$I$29,MATCH(selScenario,scnHeaders,0))))<1,"PASS","FAIL") | G11: Critical
B12: 4 | C12: Trade Spend reconciles (Calc vs Scenario) | D12: ABS<$1 | E12: =actTradeSpend-(INDEX(Scenarios!$C$20:$I$20,MATCH(selScenario,scnHeaders,0))) | F12: =IF(ABS(actTradeSpend-(INDEX(Scenarios!$C$20:$I$20,MATCH(selScenario,scnHeaders,0))))<1,"PASS","FAIL") | G12: Critical
B13: 5 | C13: Gross Margin %% ties to $ (GP/Gross) | D13: ≈0 | E13: — | F13: =IF(ABS(actGM-IF(actGross=0,0,actGP/actGross))<0.0001,"PASS","FAIL") | G13: High
B14: 6 | C14: Net Margin %% ties to $ (NP/Net) | D14: ≈0 | E14: — | F14: =IF(ABS(actNM-IF(actNet=0,0,actNP/actNet))<0.0001,"PASS","FAIL") | G14: High
B15: 7 | C15: Per-unit × units ties to total NP | D15: ABS<$1 | E15: =actPPU*actUnits-actNP | F15: =IF(ABS(actPPU*actUnits-actNP)<1,"PASS","FAIL") | G15: High
B16: 8 | C16: Scenario selector is valid | D16: found | E16: — | F16: =IF(COUNTIF(scnHeaders,selScenario)=1,"PASS","FAIL") | G16: Critical
B17: 9 | C17: Break-even contribution is positive | D17: >0 | E17: =actCPU | F17: =IF(actCPU>0,"PASS","WARN") | G17: High
B18: 10 | C18: Trade Spend %% within ceiling | D18: ≤max | E18: =actTradePctG | F18: =IF(actTradePctG<=MaxTradePct,"PASS","WARN") | G18: Medium
B19: 11 | C19: Gross Margin %% meets minimum hurdle | D19: ≥min | E19: =actGM | F19: =IF(actGM>=MinGM,"PASS","WARN") | G19: Medium
B20: 12 | C20: Net Margin %% meets minimum hurdle | D20: ≥min | E20: =actNM | F20: =IF(actNM>=MinNM,"PASS","WARN") | G20: Medium
B21: 13 | C21: FX factor reconciles (base/report) | D21: ≈0 | E21: — | F21: =IF(ABS(fxFactor-fxBaseRate/fxRptRate)<0.0000001,"PASS","FAIL") | G21: High
B22: 14 | C22: FX translation non-zero when rate set | D22: >0 | E22: — | F22: =IF(AND(fxBaseRate>0,fxRptRate>0),"PASS","FAIL") | G22: High
B23: 15 | C23: No negative Effective Units | D23: ≥0 | E23: =actUnits | F23: =IF(actUnits>=0,"PASS","FAIL") | G23: Critical
B24: 16 | C24: Required assumptions present (price, units) | D24: all>0 | E24: — | F24: =IF(AND(WholesalePrice>0,ForecastUnits>0,UnitsPerCase>0),"PASS","FAIL") | G24: Critical
B25: 17 | C25: Fixed cost subtotal non-negative | D25: ≥0 | E25: =FixedCommercialTotal | F25: =IF(FixedCommercialTotal>=0,"PASS","FAIL") | G25: Medium
B26: 18 | C26: Net Realized Price ≤ Wholesale Price | D26: ≤ | E26: =actPrice-actNRPunit | F26: =IF(actNRPunit<=actPrice+0.0001,"PASS","WARN") | G26: Medium
B28: MODEL HEALTH SUMMARY
B29: Total checks | C29: =COUNTA(C9:C26)
B30: Passes | C30: =COUNTIF(F9:F26,"PASS")
B31: Warnings | C31: =COUNTIF(F9:F26,"WARN")
B32: Critical failures | C32: =COUNTIFS(F9:F26,"FAIL",G9:G26,"Critical")
B33: OVERALL MODEL STATUS | C33: =IF(C32>0,"UNSAFE — CRITICAL FAIL",IF(COUNTIF(F9:F26,"FAIL")>0,"REVIEW — CHECK FAILS",IF(C31>0,"CAUTION — WARNINGS","HEALTHY")))

Sheet Lookups_and_Assumptions
B2: LOOKUPS & ASSUMPTIONS
B3: Pick-lists, FX seed values and reference tables. Edit lists here; the rest of the workbook references them.
B5: Scenario list (selScenario)
B6: Base Case
B7: Promo Case
B8: High Volume Case
B9: Low Volume Case
B10: Cost Inflation Case
B11: Margin Recovery Case
B12: Custom Scenario
B14: Business model list (selBusinessModel)
B15: Direct Retailer
... B31: STOP
