Workbook
Name UNITS_PER_CASE: Inputs!$B$5
Name SKU_LIST: Inputs!$A$9:$A$11
Name WHOLESALE_TABLE: Inputs!$B$9:$B$11
Name COGS_TABLE: Inputs!$C$9:$C$11
Name BEVMAX_LEAD: Inputs!$B$14
Name BEVMAX_CAP: Inputs!$B$15
Name TIER_LIST: Inputs!$A$19:$A$21
Name VELOCITY_TABLE: Inputs!$B$19:$D$21
Name RAMP_W1: Inputs!$B$24
Name RAMP_W2: Inputs!$B$25
Name RAMP_W3: Inputs!$B$26
Name RAMP_W4PLUS: Inputs!$B$27
Name ONLINE_AMZ: Inputs!$B$31:$B$33
Name ONLINE_DTC: Inputs!$C$31:$C$33
Name DOORS_ID: Doors!$A$5:$A$104
Name DOORS_BANNER: Doors!$B$5:$B$104
Name DOORS_NAME: Doors!$C$5:$C$104
Name DOORS_REGION: Doors!$E$5:$E$104
Name DOORS_TIER: Doors!$F$5:$F$104
Name DOORS_LIMELEMON: Doors!$G$5:$G$104
Name DOORS_PINEAPPLE: Doors!$H$5:$H$104
Name DOORS_RASPBERRY: Doors!$I$5:$I$104
Name DOORS_LAUNCH: Doors!$J$5:$J$104
Name BULK_ENABLED: 'Bulk Edit'!$B$5:$B$24
Name BULK_TIER: 'Bulk Edit'!$C$5:$C$24
Name BULK_SKU: 'Bulk Edit'!$D$5:$D$24
Name BULK_START: 'Bulk Edit'!$E$5:$E$24
Name BULK_END: 'Bulk Edit'!$F$5:$F$24
Name BULK_VALUE: 'Bulk Edit'!$G$5:$G$24
Name ACT_ID: Activations!$A$5:$A$34
Name ACT_TYPE: Activations!$B$5:$B$34
Name ACT_DOOR_SCOPE: Activations!$C$5:$C$34
Name ACT_SKU_SCOPE: Activations!$D$5:$D$34
Name ACT_START: Activations!$E$5:$E$34
Name ACT_END: Activations!$F$5:$F$34
Name ACT_UPLIFT: Activations!$G$5:$G$34
Name ACT_POSTLIFT: Activations!$H$5:$H$34
Name ACT_TRIAL: Activations!$I$5:$I$34
Name ACT_COST: Activations!$J$5:$J$34
Name ACTIVE_SCENARIO: Scenarios!$B$5
Name SCEN_MULT_TABLE: Scenarios!$B$9:$D$11
Name SCEN_NAMES: Scenarios!$B$8:$D$8
Name ACTIVE_MULT_TABLE: Scenarios!$B$14:$B$16
Name VG_DOOR_ID: 'Velocity Grid'!$B$5:$B$304
Name VG_BANNER: 'Velocity Grid'!$D$5:$D$304
Name VG_REGION: 'Velocity Grid'!$E$5:$E$304
Name VG_TIER: 'Velocity Grid'!$F$5:$F$304
Name VG_SKU: 'Velocity Grid'!$G$5:$G$304
Name VG_AUTH: 'Velocity Grid'!$H$5:$H$304
Name VG_LAUNCH: 'Velocity Grid'!$I$5:$I$304
Name VG_W1: 'Velocity Grid'!$J$5:$J$304
Name VG_W2: 'Velocity Grid'!$K$5:$K$304
Name VG_W3: 'Velocity Grid'!$L$5:$L$304
Name VG_W4: 'Velocity Grid'!$M$5:$M$304
Name VG_W5: 'Velocity Grid'!$N$5:$N$304
Name VG_W6: 'Velocity Grid'!$O$5:$O$304
Name VG_W7: 'Velocity Grid'!$P$5:$P$304
Name VG_W8: 'Velocity Grid'!$Q$5:$Q$304
Name VG_W9: 'Velocity Grid'!$R$5:$R$304
Name VG_W10: 'Velocity Grid'!$S$5:$S$304

Sheet Inputs
A1: Inputs and assumptions
A2: All yellow cells are editable. Source notes in column D.
A4: Case math
A5: Units per case | B5: 24 | D5: Six four packs per case. Locked structural constant.
A7: Wholesale pricing per case
A8: SKU | B8: Wholesale per case | C8: COGS per case | D8: Source note
A9: Lime Lemon | B9: 36 | C9: 18.5 | D9: Louis estimate, to validate with finance.
A10: Pineapple Passion Fruit | B10: 36 | C10: 18.5 | D10: Louis estimate, to validate with finance.
A11: Raspberry | B11: 36 | C11: 18.5 | D11: Louis estimate, to validate with finance.
A13: Bevmax co manufacturer
A14: Lead time in weeks | B14: 6 | D14: Weeks from PO release to delivery. Louis estimate, to validate.
A15: Weekly run capacity in cases | B15: 2500 | D15: Max cases per production week. Louis estimate, to validate.
A17: Default velocity by tier and SKU, units per week at steady state
A18: Tier | B18: Lime Lemon | C18: Pineapple Passion Fruit | D18: Raspberry | F18: Source: Louis estimate, to validate with category data.
A19: A | B19: 16 | C19: 14 | D19: 12
A20: B | B20: 10 | C20: 8 | D20: 7
A21: C | B21: 5 | C21: 4 | D21: 3
A23: Ramp curve, percent of steady state
A24: Week 1 | B24: 0.4 | D24: Editable. Louis estimate based on launch heuristic.
A25: Week 2 | B25: 0.6
A26: Week 3 | B26: 0.8
A27: Week 4 onward | B27: 1
A29: Online baseline, units per week at steady state
A30: SKU | B30: Amazon.ca | C30: Shopify DTC | D30: Source note
A31: Lime Lemon | B31: 160 | C31: 80 | D31: Placeholder. Louis estimate, to validate with channel managers.
A32: Pineapple Passion Fruit | B32: 140 | C32: 70 | D32: Placeholder. Louis estimate, to validate with channel managers.
A33: Raspberry | B33: 120 | C33: 60 | D33: Placeholder. Louis estimate, to validate with channel managers.
A35: Online ramp uses the same ramp curve above, starting from week 1.

Sheet Doors
A1: Door master list
A2: Replace placeholder rows with your authoritative door list. Launch Week is the first week a door receives shipment.
A4: Door ID | B4: Banner | C4: Store Name | D4: City | E4: Region | F4: Tier | G4: Lime Lemon Auth | H4: Pineapple Passion Fruit Auth | I4: Raspberry Auth | J4: Launch Week
A5: D001 | B5: Choices Markets | C5: Choices Vancouver 01 | D5: Vancouver | E5: Lower Mainland | F5: A | G5: Y | H5: Y | I5: Y | J5: 1
A6: D002 | B6: Nature's Fare Markets | C6: NatFare Burnaby 02 | D6: Burnaby | E6: Lower Mainland | F6: A | G6: Y | H6: Y | I6: Y | J6: 1
A7: D003 | B7: Whole Foods Market | C7: WFM Richmond 03 | D7: Richmond | E7: Lower Mainland | F7: A | G7: Y | H7: Y | I7: Y | J7: 1
A8: D004 | B8: Pomme Natural Market | C8: Pomme Surrey 04 | D8: Surrey | E8: Lower Mainland | F8: A | G8: Y | H8: Y | I8: Y | J8: 1
A9: D005 | B9: IGA Marketplace | C9: IGA Coquitlam 05 | D9: Coquitlam | E9: Lower Mainland | F9: A | G9: Y | H9: Y | I9: Y | J9: 1
A10: D006 | B10: Save On Foods | C10: SOF North Vancouver 06 | D10: North Vancouver | E10: Lower Mainland | F10: A | G10: Y | H10: Y | I10: Y | J10: 1
A11: D007 | B11: Urban Fare | C11: Urban West Vancouver 07 | D11: West Vancouver | E11: Lower Mainland | F11: A | G11: Y | H11: Y | I11: Y | J11: 1
A12: D008 | B12: Independent Grocer | C12: Indie Langley 08 | D12: Langley | E12: Lower Mainland | F12: A | G12: Y | H12: Y | I12: Y | J12: 1
A13: D009 | B13: Stong's Market | C13: Stongs New Westminster 09 | D13: New Westminster | E13: Lower Mainland | F13: A | G13: Y | H13: Y | I13: Y | J13: 1
A14: D010 | B14: Fresh St Market | C14: FreshSt Vancouver 01 | D14: Vancouver | E14: Lower Mainland | F14: A | G14: Y | H14: Y | I14: Y | J14: 1
A15: D011 | B15: Choices Markets | C15: Choices Burnaby 02 | D15: Burnaby | E15: Lower Mainland | F15: A | G15: Y | H15: Y | I15: Y | J15: 1
A16: D012 | B16: Nature's Fare Markets | C16: NatFare Richmond 03 | D16: Richmond | E16: Lower Mainland | F16: A | G16: Y | H16: Y | I16: Y | J16: 1
... A104: D100 | B104: Fresh St Market | C104: FreshSt Prince George 01 | D104: Prince George | E104: North | F104: C | G104: Y | H104: N | I104: Y | J104: 5

Sheet Velocity Grid
A1: Velocity Grid
A2: Heart of the model. Each row is one SKU at one door. W1 through W13 hold units per week. Formulas reflow when Inputs, Activations, Bulk Edit, or Scenarios change. Overtype a cell to apply a hard override. Overridden cells highlight in amber automatically.
A4: Row ID | B4: Door ID | C4: Door Name | D4: Banner | E4: Region | F4: Tier | G4: SKU | H4: Authorized | I4: Launch Week | J4: W1 | K4: W2 | L4: W3 | M4: W4 | N4: W5 | O4: W6 | P4: W7 | Q4: W8 | R4: W9 | S4: W10 | T4: W11 | U4: W12 | V4: W13
A5: R0001 | B5: =Doors!$A$5 | C5: =Doors!$C$5 | D5: =Doors!$B$5 | E5: =Doors!$E$5 | F5: =Doors!$F$5 | G5: Lime Lemon | H5: =Doors!$G$5 | I5: =Doors!$J$5 | J5: =IF(OR($H5<>"Y",1<$I5),0,IF(SUMPRODUCT(((BULK_ENABLED="Y")*((BULK_TIER="ALL")+(BULK_TIER=$F5))*((BULK_SKU="ALL")+(BULK_SKU=$G5))*(BULK_START<=1)*(BULK_END>=1)))>0,IFERROR(SUMPRODUCT(((BULK_ENABLED="Y")*((BULK_TIER="ALL")+(BULK_TIER=$F5))*((BULK_SKU="ALL")+(BULK_SKU=$G5))*(BULK_START<=1)*(BULK_END>=1))*IFERROR(BULK_VALUE,0))/MAX(1,SUMPRODUCT(((BULK_ENABLED="Y")*((BULK_TIER="ALL")+(BULK_TIER=$F5))*((BULK_SKU="ALL")+(BULK_SKU=$G5))*(BULK_START<=1)*(BULK_END>=1)))),0),ROUND((INDEX(VELOCITY_TABLE,MATCH($F5,TIER_LIST,0),1))*(IF((1-$I5+1)<=0,0,IF((1-$I5+1)=1,RAMP_W1,IF((1-$I5+1)=2,RAMP_W2,IF((1-$I5+1)=3,RAMP_W3,RAMP_W4PLUS)))))*(INDEX(ACTIVE_MULT_TABLE,1,1))*(1+SUMPRODUCT(SIGN(((ACT_DOOR_SCOPE="ALL")+(ACT_DOOR_SCOPE="TIER_"&$F5)+(ACT_DOOR_SCOPE=$B5)))*SIGN(((ACT_SKU_SCOPE="ALL")+(ACT_SKU_SCOPE=$G5)))*(ACT_START<=1)*(ACT_END>=1)*IFERROR(ACT_UPLIFT-1,0)))*(1+SUMPRODUCT(SIGN(((ACT_DOOR_SCOPE="ALL")+(ACT_DOOR_SCOPE="TIER_"&$F5)+(ACT_DOOR_SCOPE=$B5)))*SIGN(((ACT_SKU_SCOPE="ALL")+(ACT_SKU_SCOPE=$G5)))*(1>ACT_END)*(ACT_END>0)*IFERROR(ACT_POSTLIFT,0))),0))) | K5: =IF(OR($H5<>"Y",2<$I5),0,IF(SUMPRODUCT(((BULK_ENABLED="Y")*((BULK_TIER="ALL")+(BULK_TIER=$F5))*((BULK_SKU="ALL")+(BULK_SKU=$G5))*(BULK_START<=2)*(BULK_END>=2)))>0,IFERROR(SUMPRODUCT(((BULK_ENABLED="Y")*((BULK_TIER="ALL")+(BULK_TIER=$F5))*((BULK_SKU="ALL")+(BULK_SKU=$G5))*(BULK_START<=2)*(BULK_END>=2))*IFERROR(BULK_VALUE,0))/MAX(1,SUMPRODUCT(((BULK_ENABLED="Y")*((BULK_TIER="ALL")+(BULK_TIER=$F5))*((BULK_SKU="ALL")+(BULK_SKU=$G5))*(BULK_START<=2)*(BULK_END>=2)))),0),ROUND((INDEX(VELOCITY_TABLE,MATCH($F5,TIER_LIST,0),1))*(IF((2-$I5+1)<=0,0,IF((2-$I5+1)=1,RAMP_W1,IF((2-$I5+1)=2,RAMP_W2,IF((2-$I5+1)=3,RAMP_W3,RAMP_W4PLUS)))))*(INDEX(ACTIVE_MULT_TABLE,1,1))*(1+SUMPRODUCT(SIGN(((ACT_DOOR_SCOPE="ALL")+(ACT_DOOR_SCOPE="TIER_"&$F5)+(ACT_DOOR_SCOPE=$B5)))*SIGN(((ACT_SKU_SCOPE="ALL")+(ACT_SKU_SCOPE=$G5)))*(ACT_START<=2)*(ACT_END>=2)*IFERROR(ACT_UPLIFT-1,0)))*(1+SUMPRODUCT(SIGN(((ACT_DOOR_SCOPE="ALL")+(ACT_DOOR_SCOPE="TIER_"&$F5)+(ACT_DOOR_SCOPE=$B5)))*SIGN(((ACT_SKU_SCOPE="ALL")+(ACT_SKU_SCOPE=$G5)))*(2>ACT_END)*(ACT_END>0)*IFERROR(ACT_POSTLIFT,0))),0))) | L5: =IF(OR($H5<>"Y",3<$I5),0,IF(SUMPRODUCT(((BULK_ENABLED="Y")*((BULK_TIER="ALL")+(BULK_TIER=$F5))*((BULK_SKU="ALL")+(BULK_SKU=$G5))*(BULK_START<=3)*(BULK_END>=3)))>0,IFERROR(SUMPRODUCT(((BULK_ENABLED="Y")*((BULK_TIER="ALL")+(BULK_TIER=$F5))*((BULK_SKU="ALL")+(BULK_SKU=$G5))*(BULK_START<=3)*(BULK_END>=3))*IFERROR(BULK_VALUE,0))/MAX(1,SUMPRODUCT(((BULK_ENABLED="Y")*((BULK_TIER="ALL")+(BULK_TIER=$F5))*((BULK_SKU="ALL")+(BULK_SKU=$G5))*(BULK_START<=3)*(BULK_END>=3)))),0),ROUND((INDEX(VELOCITY_TABLE,MATCH($F5,TIER_LIST,0),1))*(IF((3-$I5+1)<=0,0,IF((3-$I5+1)=1,RAMP_W1,IF((3-$I5+1)=2,RAMP_W2,IF((3-$I5+1)=3,RAMP_W3,RAMP_W4PLUS)))))*(INDEX(ACTIVE_MULT_TABLE,1,1))*(1+SUMPRODUCT(SIGN(((ACT_DOOR_SCOPE="ALL")+(ACT_DOOR_SCOPE="TIER_"&$F5)+(ACT_DOOR_SCOPE=$B5)))*SIGN(((ACT_SKU_SCOPE="ALL")+(ACT_SKU_SCOPE=$G5)))*(ACT_START<=3)*(ACT_END>=3)*IFERROR(ACT_UPLIFT-1,0)))*(1+SUMPRODUCT(SIGN(((ACT_DOOR_SCOPE="ALL")+(ACT_DOOR_SCOPE="TIER_"&$F5)+(ACT_DOOR_SCOPE=$B5)))*SIGN(((ACT_SKU_SCOPE="ALL")+(ACT_SKU_SCOPE=$G5)))*(3>ACT_END)*(ACT_END>0)*IFERROR(ACT_POSTLIFT,0))),0))) | M5: =IF(OR($H5<>"Y",4<$I5),0,IF(SUMPRODUCT(((BULK_ENABLED="Y")*((BULK_TIER="ALL")+(BULK_TIER=$F5))*((BULK_SKU="ALL")+(BULK_SKU=$G5))*(BULK_START<=4)*(BULK_END>=4)))>0,IFERROR(SUMPRODUCT(((BULK_ENABLED="Y")*((BULK_TIER="ALL")+(BULK_TIER=$F5))*((BULK_SKU="ALL")+(BULK_SKU=$G5))*(BULK_START<=4)*(BULK_END>=4))*IFERROR(BULK_VALUE,0))/MAX(1,SUMPRODUCT(((BULK_ENABLED="Y")*((BULK_TIER="ALL")+(BULK_TIER=$F5))*((BULK_SKU="ALL")+(BULK_SKU=$G5))*(BULK_START<=4)*(BULK_END>=4)))),0),ROUND((INDEX(VELOCITY_TABLE,MATCH($F5,TIER_LIST,0),1))*(IF((4-$I5+1)<=0,0,IF((4-$I5+1)=1,RAMP_W1,IF((4-$I5+1)=2,RAMP_W2,IF((4-$I5+1)=3,RAMP_W3,RAMP_W4PLUS)))))*(INDEX(ACTIVE_MULT_TABLE,1,1))*(1+SUMPRODUCT(SIGN(((ACT_DOOR_SCOPE="ALL")+(ACT_DOOR_SCOPE="TIER_"&$F5)+(ACT_DOOR_SCOPE=$B5)))*SIGN(((ACT_SKU_SCOPE="ALL")+(ACT_SKU_SCOPE=$G5)))*(ACT_START<=4)*(ACT_END>=4)*IFERROR(ACT_UPLIFT-1,0)))*(1+SUMPRODUCT(SIGN(((ACT_DOOR_SCOPE="ALL")+(ACT_DOOR_SCOPE="TIER_"&$F5)+(ACT_DOOR_SCOPE=$B5)))*SIGN(((ACT_SKU_SCOPE="ALL")+(ACT_SKU_SCOPE=$G5)))*(4>ACT_END)*(ACT_END>0)*IFERROR(ACT_POSTLIFT,0))),0))) | N5: =IF(OR($H5<>"Y",5<$I5),0,IF(SUMPRODUCT(((BULK_ENABLED="Y")*((BULK_TIER="ALL")+(BULK_TIER=$F5))*((BULK_SKU="ALL")+(BULK_SKU=$G5))*(BULK_START<=5)*(BULK_END>=5)))>0,IFERROR(SUMPRODUCT(((BULK_ENABLED="Y")*((BULK_TIER="ALL")+(BULK_TIER=$F5))*((BULK_SKU="ALL")+(BULK_SKU=$G5))*(BULK_START<=5)*(BULK_END>=5))*IFERROR(BULK_VALUE,0))/MAX(1,SUMPRODUCT(((BULK_ENABLED="Y")*((BULK_TIER="ALL")+(BULK_TIER=$F5))*((BULK_SKU="ALL")+(BULK_SKU=$G5))*(BULK_START<=5)*(BULK_END>=5)))),0),ROUND((INDEX(VELOCITY_TABLE,MATCH($F5,TIER_LIST,0),1))*(IF((5-$I5+1)<=0,0,IF((5-$I5+1)=1,RAMP_W1,IF((5-$I5+1)=2,RAMP_W2,IF((5-$I5+1)=3,RAMP_W3,RAMP_W4PLUS)))))*(INDEX(ACTIVE_MULT_TABLE,1,1))*(1+SUMPRODUCT(SIGN(((ACT_DOOR_SCOPE="ALL")+(ACT_DOOR_SCOPE="TIER_"&$F5)+(ACT_DOOR_SCOPE=$B5)))*SIGN(((ACT_SKU_SCOPE="ALL")+(ACT_SKU_SCOPE=$G5)))*(ACT_START<=5)*(ACT_END>=5)*IFERROR(ACT_UPLIFT-1,0)))*(1+SUMPRODUCT(SIGN(((ACT_DOOR_SCOPE="ALL")+(ACT_DOOR_SCOPE="TIER_"&$F5)+(ACT_DOOR_SCOPE=$B5)))*SIGN(((ACT_SKU_SCOPE="ALL")+(ACT_SKU_SCOPE=$G5)))*(5>ACT_END)*(ACT_END>0)*IFERROR(ACT_POSTLIFT,0))),0))) | O5: =IF(OR($H5<>"Y",6<$I5),0,IF(SUMPRODUCT(((BULK_ENABLED="Y")*((BULK_TIER="ALL")+(BULK_TIER=$F5))*((BULK_SKU="ALL")+(BULK_SKU=$G5))*(BULK_START<=6)*(BULK_END>=6)))>0,IFERROR(SUMPRODUCT(((BULK_ENABLED="Y")*((BULK_TIER="ALL")+(BULK_TIER=$F5))*((BULK_SKU="ALL")+(BULK_SKU=$G5))*(BULK_START<=6)*(BULK_END>=6))*IFERROR(BULK_VALUE,0))/MAX(1,SUMPRODUCT(((BULK_ENABLED="Y")*((BULK_TIER="ALL")+(BULK_TIER=$F5))*((BULK_SKU="ALL")+(BULK_SKU=$G5))*(BULK_START<=6)*(BULK_END>=6)))),0),ROUND((INDEX(VELOCITY_TABLE,MATCH($F5,TIER_LIST,0),1))*(IF((6-$I5+1)<=0,0,IF((6-$I5+1)=1,RAMP_W1,IF((6-$I5+1)=2,RAMP_W2,IF((6-$I5+1)=3,RAMP_W3,RAMP_W4PLUS)))))*(INDEX(ACTIVE_MULT_TABLE,1,1))*(1+SUMPRODUCT(SIGN(((ACT_DOOR_SCOPE="ALL")+(ACT_DOOR_SCOPE="TIER_"&$F5)+(ACT_DOOR_SCOPE=$B5)))*SIGN(((ACT_SKU_SCOPE="ALL")+(ACT_SKU_SCOPE=$G5)))*(ACT_START<=6)*(ACT_END>=6)*IFERROR(ACT_UPLIFT-1,0)))*(1+SUMPRODUCT(SIGN(((ACT_DOOR_SCOPE="ALL")+(ACT_DOOR_SCOPE="TIER_"&$F5)+(ACT_DOOR_SCOPE=$B5)))*SIGN(((ACT_SKU_SCOPE="ALL")+(ACT_SKU_SCOPE=$G5)))*(6>ACT_END)*(ACT_END>0)*IFERROR(ACT_POSTLIFT,0))),0))) | P5: =IF(OR($H5<>"Y",7<$I5),0,IF(SUMPRODUCT(((BULK_ENABLED="Y")*((BULK_TIER="ALL")+(BULK_TIER=$F5))*((BULK_SKU="ALL")+(BULK_SKU=$G5))*(BULK_START<=7)*(BULK_END>=7)))>0,IFERROR(SUMPRODUCT(((BULK_ENABLED="Y")*((BULK_TIER="ALL")+(BULK_TIER=$F5))*((BULK_SKU="ALL")+(BULK_SKU=$G5))*(BULK_START<=7)*(BULK_END>=7))*IFERROR(BULK_VALUE,0))/MAX(1,SUMPRODUCT(((BULK_ENABLED="Y")*((BULK_TIER="ALL")+(BULK_TIER=$F5))*((BULK_SKU="ALL")+(BULK_SKU=$G5))*(BULK_START<=7)*(BULK_END>=7)))),0),ROUND((INDEX(VELOCITY_TABLE,MATCH($F5,TIER_LIST,0),1))*(IF((7-$I5+1)<=0,0,IF((7-$I5+1)=1,RAMP_W1,IF((7-$I5+1)=2,RAMP_W2,IF((7-$I5+1)=3,RAMP_W3,RAMP_W4PLUS)))))*(INDEX(ACTIVE_MULT_TABLE,1,1))*(1+SUMPRODUCT(SIGN(((ACT_DOOR_SCOPE="ALL")+(ACT_DOOR_SCOPE="TIER_"&$F5)+(ACT_DOOR_SCOPE=$B5)))*SIGN(((ACT_SKU_SCOPE="ALL")+(ACT_SKU_SCOPE=$G5)))*(ACT_START<=7)*(ACT_END>=7)*IFERROR(ACT_UPLIFT-1,0)))*(1+SUMPRODUCT(SIGN(((ACT_DOOR_SCOPE="ALL")+(ACT_DOOR_SCOPE="TIER_"&$F5)+(ACT_DOOR_SCOPE=$B5)))*SIGN(((ACT_SKU_SCOPE="ALL")+(ACT_SKU_SCOPE=$G5)))*(7>ACT_END)*(ACT_END>0)*IFERROR(ACT_POSTLIFT,0))),0))) | Q5: =IF(OR($H5<>"Y",8<$I5),0,IF(SUMPRODUCT(((BULK_ENABLED="Y")*((BULK_TIER="ALL")+(BULK_TIER=$F5))*((BULK_SKU="ALL")+(BULK_SKU=$G5))*(BULK_START<=8)*(BULK_END>=8)))>0,IFERROR(SUMPRODUCT(((BULK_ENABLED="Y")*((BULK_TIER="ALL")+(BULK_TIER=$F5))*((BULK_SKU="ALL")+(BULK_SKU=$G5))*(BULK_START<=8)*(BULK_END>=8))*IFERROR(BULK_VALUE,0))/MAX(1,SUMPRODUCT(((BULK_ENABLED="Y")*((BULK_TIER="ALL")+(BULK_TIER=$F5))*((BULK_SKU="ALL")+(BULK_SKU=$G5))*(BULK_START<=8)*(BULK_END>=8)))),0),ROUND((INDEX(VELOCITY_TABLE,MATCH($F5,TIER_LIST,0),1))*(IF((8-$I5+1)<=0,0,IF((8-$I5+1)=1,RAMP_W1,IF((8-$I5+1)=2,RAMP_W2,IF((8-$I5+1)=3,RAMP_W3,RAMP_W4PLUS)))))*(INDEX(ACTIVE_MULT_TABLE,1,1))*(1+SUMPRODUCT(SIGN(((ACT_DOOR_SCOPE="ALL")+(ACT_DOOR_SCOPE="TIER_"&$F5)+(ACT_DOOR_SCOPE=$B5)))*SIGN(((ACT_SKU_SCOPE="ALL")+(ACT_SKU_SCOPE=$G5)))*(ACT_START<=8)*(ACT_END>=8)*IFERROR(ACT_UPLIFT-1,0)))*(1+SUMPRODUCT(SIGN(((ACT_DOOR_SCOPE="ALL")+(ACT_DOOR_SCOPE="TIER_"&$F5)+(ACT_DOOR_SCOPE=$B5)))*SIGN(((ACT_SKU_SCOPE="ALL")+(ACT_SKU_SCOPE=$G5)))*(8>ACT_END)*(ACT_END>0)*IFERROR(ACT_POSTLIFT,0))),0))) | R5: =IF(OR($H5<>"Y",9<$I5),0,IF(SUMPRODUCT(((BULK_ENABLED="Y")*((BULK_TIER="ALL")+(BULK_TIER=$F5))*((BULK_SKU="ALL")+(BULK_SKU=$G5))*(BULK_START<=9)*(BULK_END>=9)))>0,IFERROR(SUMPRODUCT(((BULK_ENABLED="Y")*((BULK_TIER="ALL")+(BULK_TIER=$F5))*((BULK_SKU="ALL")+(BULK_SKU=$G5))*(BULK_START<=9)*(BULK_END>=9))*IFERROR(BULK_VALUE,0))/MAX(1,SUMPRODUCT(((BULK_ENABLED="Y")*((BULK_TIER="ALL")+(BULK_TIER=$F5))*((BULK_SKU="ALL")+(BULK_SKU=$G5))*(BULK_START<=9)*(BULK_END>=9)))),0),ROUND((INDEX(VELOCITY_TABLE,MATCH($F5,TIER_LIST,0),1))*(IF((9-$I5+1)<=0,0,IF((9-$I5+1)=1,RAMP_W1,IF((9-$I5+1)=2,RAMP_W2,IF((9-$I5+1)=3,RAMP_W3,RAMP_W4PLUS)))))*(INDEX(ACTIVE_MULT_TABLE,1,1))*(1+SUMPRODUCT(SIGN(((ACT_DOOR_SCOPE="ALL")+(ACT_DOOR_SCOPE="TIER_"&$F5)+(ACT_DOOR_SCOPE=$B5)))*SIGN(((ACT_SKU_SCOPE="ALL")+(ACT_SKU_SCOPE=$G5)))*(ACT_START<=9)*(ACT_END>=9)*IFERROR(ACT_UPLIFT-1,0)))*(1+SUMPRODUCT(SIGN(((ACT_DOOR_SCOPE="ALL")+(ACT_DOOR_SCOPE="TIER_"&$F5)+(ACT_DOOR_SCOPE=$B5)))*SIGN(((ACT_SKU_SCOPE="ALL")+(ACT_SKU_SCOPE=$G5)))*(9>ACT_END)*(ACT_END>0)*IFERROR(ACT_POSTLIFT,0))),0))) | S5: =IF(OR($H5<>"Y",10<$I5),0,IF(SUMPRODUCT(((BULK_ENABLED="Y")*((BULK_TIER="ALL")+(BULK_TIER=$F5))*((BULK_SKU="ALL")+(BULK_SKU=$G5))*(BULK_START<=10)*(BULK_END>=10)))>0,IFERROR(SUMPRODUCT(((BULK_ENABLED="Y")*((BULK_TIER="ALL")+(BULK_TIER=$F5))*((BULK_SKU="ALL")+(BULK_SKU=$G5))*(BULK_START<=10)*(BULK_END>=10))*IFERROR(BULK_VALUE,0))/MAX(1,SUMPRODUCT(((BULK_ENABLED="Y")*((BULK_TIER="ALL")+(BULK_TIER=$F5))*((BULK_SKU="ALL")+(BULK_SKU=$G5))*(BULK_START<=10)*(BULK_END>=10)))),0),ROUND((INDEX(VELOCITY_TABLE,MATCH($F5,TIER_LIST,0),1))*(IF((10-$I5+1)<=0,0,IF((10-$I5+1)=1,RAMP_W1,IF((10-$I5+1)=2,RAMP_W2,IF((10-$I5+1)=3,RAMP_W3,RAMP_W4PLUS)))))*(INDEX(ACTIVE_MULT_TABLE,1,1))*(1+SUMPRODUCT(SIGN(((ACT_DOOR_SCOPE="ALL")+(ACT_DOOR_SCOPE="TIER_"&$F5)+(ACT_DOOR_SCOPE=$B5)))*SIGN(((ACT_SKU_SCOPE="ALL")+(ACT_SKU_SCOPE=$G5)))*(ACT_START<=10)*(ACT_END>=10)*IFERROR(ACT_UPLIFT-1,0)))*(1+SUMPRODUCT(SIGN(((ACT_DOOR_SCOPE="ALL")+(ACT_DOOR_SCOPE="TIER_"&$F5)+(ACT_DOOR_SCOPE=$B5)))*SIGN(((ACT_SKU_SCOPE="ALL")+(ACT_SKU_SCOPE=$G5)))*(10>ACT_END)*(ACT_END>0)*IFERROR(ACT_POSTLIFT,0))),0))) | T5: =IF(OR($H5<>"Y",11<$I5),0,IF(SUMPRODUCT(((BULK_ENABLED="Y")*((BULK_TIER="ALL")+(BULK_TIER=$F5))*((BULK_SKU="ALL")+(BULK_SKU=$G5))*(BULK_START<=11)*(BULK_END>=11)))>0,IFERROR(SUMPRODUCT(((BULK_ENABLED="Y")*((BULK_TIER="ALL")+(BULK_TIER=$F5))*((BULK_SKU="ALL")+(BULK_SKU=$G5))*(BULK_START<=11)*(BULK_END>=11))*IFERROR(BULK_VALUE,0))/MAX(1,SUMPRODUCT(((BULK_ENABLED="Y")*((BULK_TIER="ALL")+(BULK_TIER=$F5))*((BULK_SKU="ALL")+(BULK_SKU=$G5))*(BULK_START<=11)*(BULK_END>=11)))),0),ROUND((INDEX(VELOCITY_TABLE,MATCH($F5,TIER_LIST,0),1))*(IF((11-$I5+1)<=0,0,IF((11-$I5+1)=1,RAMP_W1,IF((11-$I5+1)=2,RAMP_W2,IF((11-$I5+1)=3,RAMP_W3,RAMP_W4PLUS)))))*(INDEX(ACTIVE_MULT_TABLE,1,1))*(1+SUMPRODUCT(SIGN(((ACT_DOOR_SCOPE="ALL")+(ACT_DOOR_SCOPE="TIER_"&$F5)+(ACT_DOOR_SCOPE=$B5)))*SIGN(((ACT_SKU_SCOPE="ALL")+(ACT_SKU_SCOPE=$G5)))*(ACT_START<=11)*(ACT_END>=11)*IFERROR(ACT_UPLIFT-1,0)))*(1+SUMPRODUCT(SIGN(((ACT_DOOR_SCOPE="ALL")+(ACT_DOOR_SCOPE="TIER_"&$F5)+(ACT_DOOR_SCOPE=$B5)))*SIGN(((ACT_SKU_SCOPE="ALL")+(ACT_SKU_SCOPE=$G5)))*(11>ACT_END)*(ACT_END>0)*IFERROR(ACT_POSTLIFT,0))),0))) | U5: =IF(OR($H5<>"Y",12<$I5),0,IF(SUMPRODUCT(((BULK_ENABLED="Y")*((BULK_TIER="ALL")+(BULK_TIER=$F5))*((BULK_SKU="ALL")+(BULK_SKU=$G5))*(BULK_START<=12)*(BULK_END>=12)))>0,IFERROR(SUMPRODUCT(((BULK_ENABLED="Y")*((BULK_TIER="ALL")+(BULK_TIER=$F5))*((BULK_SKU="ALL")+(BULK_SKU=$G5))*(BULK_START<=12)*(BULK_END>=12))*IFERROR(BULK_VALUE,0))/MAX(1,SUMPRODUCT(((BULK_ENABLED="Y")*((BULK_TIER="ALL")+(BULK_TIER=$F5))*((BULK_SKU="ALL")+(BULK_SKU=$G5))*(BULK_START<=12)*(BULK_END>=12)))),0),ROUND((INDEX(VELOCITY_TABLE,MATCH($F5,TIER_LIST,0),1))*(IF((12-$I5+1)<=0,0,IF((12-$I5+1)=1,RAMP_W1,IF((12-$I5+1)=2,RAMP_W2,IF((12-$I5+1)=3,RAMP_W3,RAMP_W4PLUS)))))*(INDEX(ACTIVE_MULT_TABLE,1,1))*(1+SUMPRODUCT(SIGN(((ACT_DOOR_SCOPE="ALL")+(ACT_DOOR_SCOPE="TIER_"&$F5)+(ACT_DOOR_SCOPE=$B5)))*SIGN(((ACT_SKU_SCOPE="ALL")+(ACT_SKU_SCOPE=$G5)))*(ACT_START<=12)*(ACT_END>=12)*IFERROR(ACT_UPLIFT-1,0)))*(1+SUMPRODUCT(SIGN(((ACT_DOOR_SCOPE="ALL")+(ACT_DOOR_SCOPE="TIER_"&$F5)+(ACT_DOOR_SCOPE=$B5)))*SIGN(((ACT_SKU_SCOPE="ALL")+(ACT_SKU_SCOPE=$G5)))*(12>ACT_END)*(ACT_END>0)*IFERROR(ACT_POSTLIFT,0))),0))) | V5: =IF(OR($H5<>"Y",13<$I5),0,IF(SUMPRODUCT(((BULK_ENABLED="Y")*((BULK_TIER="ALL")+(BULK_TIER=$F5))*((BULK_SKU="ALL")+(BULK_SKU=$G5))*(BULK_START<=13)*(BULK_END>=13)))>0,IFERROR(SUMPRODUCT(((BULK_ENABLED="Y")*((BULK_TIER="ALL")+(BULK_TIER=$F5))*((BULK_SKU="ALL")+(BULK_SKU=$G5))*(BULK_START<=13)*(BULK_END>=13))*IFERROR(BULK_VALUE,0))/MAX(1,SUMPRODUCT(((BULK_ENABLED="Y")*((BULK_TIER="ALL")+(BULK_TIER=$F5))*((BULK_SKU="ALL")+(BULK_SKU=$G5))*(BULK_START<=13)*(BULK_END>=13)))),0),ROUND((INDEX(VELOCITY_TABLE,MATCH($F5,TIER_LIST,0),1))*(IF((13-$I5+1)<=0,0,IF((13-$I5+1)=1,RAMP_W1,IF((13-$I5+1)=2,RAMP_W2,IF((13-$I5+1)=3,RAMP_W3,RAMP_W4PLUS)))))*(INDEX(ACTIVE_MULT_TABLE,1,1))*(1+SUMPRODUCT(SIGN(((ACT_DOOR_SCOPE="ALL")+(ACT_DOOR_SCOPE="TIER_"&$F5)+(ACT_DOOR_SCOPE=$B5)))*SIGN(((ACT_SKU_SCOPE="ALL")+(ACT_SKU_SCOPE=$G5)))*(ACT_START<=13)*(ACT_END>=13)*IFERROR(ACT_UPLIFT-1,0)))*(1+SUMPRODUCT(SIGN(((ACT_DOOR_SCOPE="ALL")+(ACT_DOOR_SCOPE="TIER_"&$F5)+(ACT_DOOR_SCOPE=$B5)))*SIGN(((ACT_SKU_SCOPE="ALL")+(ACT_SKU_SCOPE=$G5)))*(13>ACT_END)*(ACT_END>0)*IFERROR(ACT_POSTLIFT,0))),0)))
A6: R0002 | B6: =Doors!$A$5 | C6: =Doors!$C$5 | D6: =Doors!$B$5 | E6: =Doors!$E$5 | F6: =Doors!$F$5 | G6: Pineapple Passion Fruit | H6: =Doors!$H$5 | I6: =Doors!$J$5 | J6: =IF(OR($H6<>"Y",1<$I6),0,IF(SUMPRODUCT(((BULK_ENABLED="Y")*((BULK_TIER="ALL")+(BULK_TIER=$F6))*((BULK_SKU="ALL")+(BULK_SKU=$G6))*(BULK_START<=1)*(BULK_END>=1)))>0,IFERROR(SUMPRODUCT(((BULK_ENABLED="Y")*((BULK_TIER="ALL")+(BULK_TIER=$F6))*((BULK_SKU="ALL")+(BULK_SKU=$G6))*(BULK_START<=1)*(BULK_END>=1))*IFERROR(BULK_VALUE,0))/MAX(1,SUMPRODUCT(((BULK_ENABLED="Y")*((BULK_TIER="ALL")+(BULK_TIER=$F6))*((BULK_SKU="ALL")+(BULK_SKU=$G6))*(BULK_START<=1)*(BULK_END>=1)))),0),ROUND((INDEX(VELOCITY_TABLE,MATCH($F6,TIER_LIST,0),2))*(IF((1-$I6+1)<=0,0,IF((1-$I6+1)=1,RAMP_W1,IF((1-$I6+1)=2,RAMP_W2,IF((1-$I6+1)=3,RAMP_W3,RAMP_W4PLUS)))))*(INDEX(ACTIVE_MULT_TABLE,2,1))*(1+SUMPRODUCT(SIGN(((ACT_DOOR_SCOPE="ALL")+(ACT_DOOR_SCOPE="TIER_"&$F6)+(ACT_DOOR_SCOPE=$B6)))*SIGN(((ACT_SKU_SCOPE="ALL")+(ACT_SKU_SCOPE=$G6)))*(ACT_START<=1)*(ACT_END>=1)*IFERROR(ACT_UPLIFT-1,0)))*(1+SUMPRODUCT(SIGN(((ACT_DOOR_SCOPE="ALL")+(ACT_DOOR_SCOPE="TIER_"&$F6)+(ACT_DOOR_SCOPE=$B6)))*SIGN(((ACT_SKU_SCOPE="ALL")+(ACT_SKU_SCOPE=$G6)))*(1>ACT_END)*(ACT_END>0)*IFERROR(ACT_POSTLIFT,0))),0))) | K6: =IF(OR($H6<>"Y",2<$I6),0,IF(SUMPRODUCT(((BULK_ENABLED="Y")*((BULK_TIER="ALL")+(BULK_TIER=$F6))*((BULK_SKU="ALL")+(BULK_SKU=$G6))*(BULK_START<=2)*(BULK_END>=2)))>0,IFERROR(SUMPRODUCT(((BULK_ENABLED="Y")*((BULK_TIER="ALL")+(BULK_TIER=$F6))*((BULK_SKU="ALL")+(BULK_SKU=$G6))*(BULK_START<=2)*(BULK_END>=2))*IFERROR(BULK_VALUE,0))/MAX(1,SUMPRODUCT(((BULK_ENABLED="Y")*((BULK_TIER="ALL")+(BULK_TIER=$F6))*((BULK_SKU="ALL")+(BULK_SKU=$G6))*(BULK_START<=2)*(BULK_END>=2)))),0),ROUND((INDEX(VELOCITY_TABLE,MATCH($F6,TIER_LIST,0),2))*(IF((2-$I6+1)<=0,0,IF((2-$I6+1)=1,RAMP_W1,IF((2-$I6+1)=2,RAMP_W2,IF((2-$I6+1)=3,RAMP_W3,RAMP_W4PLUS)))))*(INDEX(ACTIVE_MULT_TABLE,2,1))*(1+SUMPRODUCT(SIGN(((ACT_DOOR_SCOPE="ALL")+(ACT_DOOR_SCOPE="TIER_"&$F6)+(ACT_DOOR_SCOPE=$B6)))*SIGN(((ACT_SKU_SCOPE="ALL")+(ACT_SKU_SCOPE=$G6)))*(ACT_START<=2)*(ACT_END>=2)*IFERROR(ACT_UPLIFT-1,0)))*(1+SUMPRODUCT(SIGN(((ACT_DOOR_SCOPE="ALL")+(ACT_DOOR_SCOPE="TIER_"&$F6)+(ACT_DOOR_SCOPE=$B6)))*SIGN(((ACT_SKU_SCOPE="ALL")+(ACT_SKU_SCOPE=$G6)))*(2>ACT_END)*(ACT_END>0)*IFERROR(ACT_POSTLIFT,0))),0))) | L6: =IF(OR($H6<>"Y",3<$I6),0,IF(SUMPRODUCT(((BULK_ENABLED="Y")*((BULK_TIER="ALL")+(BULK_TIER=$F6))*((BULK_SKU="ALL")+(BULK_SKU=$G6))*(BULK_START<=3)*(BULK_END>=3)))>0,IFERROR(SUMPRODUCT(((BULK_ENABLED="Y")*((BULK_TIER="ALL")+(BULK_TIER=$F6))*((BULK_SKU="ALL")+(BULK_SKU=$G6))*(BULK_START<=3)*(BULK_END>=3))*IFERROR(BULK_VALUE,0))/MAX(1,SUMPRODUCT(((BULK_ENABLED="Y")*((BULK_TIER="ALL")+(BULK_TIER=$F6))*((BULK_SKU="ALL")+(BULK_SKU=$G6))*(BULK_START<=3)*(BULK_END>=3)))),0),ROUND((INDEX(VELOCITY_TABLE,MATCH($F6,TIER_LIST,0),2))*(IF((3-$I6+1)<=0,0,IF((3-$I6+1)=1,RAMP_W1,IF((3-$I6+1)=2,RAMP_W2,IF((3-$I6+1)=3,RAMP_W3,RAMP_W4PLUS)))))*(INDEX(ACTIVE_MULT_TABLE,2,1))*(1+SUMPRODUCT(SIGN(((ACT_DOOR_SCOPE="ALL")+(ACT_DOOR_SCOPE="TIER_"&$F6)+(ACT_DOOR_SCOPE=$B6)))*SIGN(((ACT_SKU_SCOPE="ALL")+(ACT_SKU_SCOPE=$G6)))*(ACT_START<=3)*(ACT_END>=3)*IFERROR(ACT_UPLIFT-1,0)))*(1+SUMPRODUCT(SIGN(((ACT_DOOR_SCOPE="ALL")+(ACT_DOOR_SCOPE="TIER_"&$F6)+(ACT_DOOR_SCOPE=$B6)))*SIGN(((ACT_SKU_SCOPE="ALL")+(ACT_SKU_SCOPE=$G6)))*(3>ACT_END)*(ACT_END>0)*IFERROR(ACT_POSTLIFT,0))),0))) | M6: =IF(OR($H6<>"Y",4<$I6),0,IF(SUMPRODUCT(((BULK_ENABLED="Y")*((BULK_TIER="ALL")+(BULK_TIER=$F6))*((BULK_SKU="ALL")+(BULK_SKU=$G6))*(BULK_START<=4)*(BULK_END>=4)))>0,IFERROR(SUMPRODUCT(((BULK_ENABLED="Y")*((BULK_TIER="ALL")+(BULK_TIER=$F6))*((BULK_SKU="ALL")+(BULK_SKU=$G6))*(BULK_START<=4)*(BULK_END>=4))*IFERROR(BULK_VALUE,0))/MAX(1,SUMPRODUCT(((BULK_ENABLED="Y")*((BULK_TIER="ALL")+(BULK_TIER=$F6))*((BULK_SKU="ALL")+(BULK_SKU=$G6))*(BULK_START<=4)*(BULK_END>=4)))),0),ROUND((INDEX(VELOCITY_TABLE,MATCH($F6,TIER_LIST,0),2))*(IF((4-$I6+1)<=0,0,IF((4-$I6+1)=1,RAMP_W1,IF((4-$I6+1)=2,RAMP_W2,IF((4-$I6+1)=3,RAMP_W3,RAMP_W4PLUS)))))*(INDEX(ACTIVE_MULT_TABLE,2,1))*(1+SUMPRODUCT(SIGN(((ACT_DOOR_SCOPE="ALL")+(ACT_DOOR_SCOPE="TIER_"&$F6)+(ACT_DOOR_SCOPE=$B6)))*SIGN(((ACT_SKU_SCOPE="ALL")+(ACT_SKU_SCOPE=$G6)))*(ACT_START<=4)*(ACT_END>=4)*IFERROR(ACT_UPLIFT-1,0)))*(1+SUMPRODUCT(SIGN(((ACT_DOOR_SCOPE="ALL")+(ACT_DOOR_SCOPE="TIER_"&$F6)+(ACT_DOOR_SCOPE=$B6)))*SIGN(((ACT_SKU_SCOPE="ALL")+(ACT_SKU_SCOPE=$G6)))*(4>ACT_END)*(ACT_END>0)*IFERROR(ACT_POSTLIFT,0))),0))) | N6: =IF(OR($H6<>"Y",5<$I6),0,IF(SUMPRODUCT(((BULK_ENABLED="Y")*((BULK_TIER="ALL")+(BULK_TIER=$F6))*((BULK_SKU="ALL")+(BULK_SKU=$G6))*(BULK_START<=5)*(BULK_END>=5)))>0,IFERROR(SUMPRODUCT(((BULK_ENABLED="Y")*((BULK_TIER="ALL")+(BULK_TIER=$F6))*((BULK_SKU="ALL")+(BULK_SKU=$G6))*(BULK_START<=5)*(BULK_END>=5))*IFERROR(BULK_VALUE,0))/MAX(1,SUMPRODUCT(((BULK_ENABLED="Y")*((BULK_TIER="ALL")+(BULK_TIER=$F6))*((BULK_SKU="ALL")+(BULK_SKU=$G6))*(BULK_START<=5)*(BULK_END>=5)))),0),ROUND((INDEX(VELOCITY_TABLE,MATCH($F6,TIER_LIST,0),2))*(IF((5-$I6+1)<=0,0,IF((5-$I6+1)=1,RAMP_W1,IF((5-$I6+1)=2,RAMP_W2,IF((5-$I6+1)=3,RAMP_W3,RAMP_W4PLUS)))))*(INDEX(ACTIVE_MULT_TABLE,2,1))*(1+SUMPRODUCT(SIGN(((ACT_DOOR_SCOPE="ALL")+(ACT_DOOR_SCOPE="TIER_"&$F6)+(ACT_DOOR_SCOPE=$B6)))*SIGN(((ACT_SKU_SCOPE="ALL")+(ACT_SKU_SCOPE=$G6)))*(ACT_START<=5)*(ACT_END>=5)*IFERROR(ACT_UPLIFT-1,0)))*(1+SUMPRODUCT(SIGN(((ACT_DOOR_SCOPE="ALL")+(ACT_DOOR_SCOPE="TIER_"&$F6)+(ACT_DOOR_SCOPE=$B6)))*SIGN(((ACT_SKU_SCOPE="ALL")+(ACT_SKU_SCOPE=$G6)))*(5>ACT_END)*(ACT_END>0)*IFERROR(ACT_POSTLIFT,0))),0))) | O6: =IF(OR($H6<>"Y",6<$I6),0,IF(SUMPRODUCT(((BULK_ENABLED="Y")*((BULK_TIER="ALL")+(BULK_TIER=$F6))*((BULK_SKU="ALL")+(BULK_SKU=$G6))*(BULK_START<=6)*(BULK_END>=6)))>0,IFERROR(SUMPRODUCT(((BULK_ENABLED="Y")*((BULK_TIER="ALL")+(BULK_TIER=$F6))*((BULK_SKU="ALL")+(BULK_SKU=$G6))*(BULK_START<=6)*(BULK_END>=6))*IFERROR(BULK_VALUE,0))/MAX(1,SUMPRODUCT(((BULK_ENABLED="Y")*((BULK_TIER="ALL")+(BULK_TIER=$F6))*((BULK_SKU="ALL")+(BULK_SKU=$G6))*(BULK_START<=6)*(BULK_END>=6)))),0),ROUND((INDEX(VELOCITY_TABLE,MATCH($F6,TIER_LIST,0),2))*(IF((6-$I6+1)<=0,0,IF((6-$I6+1)=1,RAMP_W1,IF((6-$I6+1)=2,RAMP_W2,IF((6-$I6+1)=3,RAMP_W3,RAMP_W4PLUS)))))*(INDEX(ACTIVE_MULT_TABLE,2,1))*(1+SUMPRODUCT(SIGN(((ACT_DOOR_SCOPE="ALL")+(ACT_DOOR_SCOPE="TIER_"&$F6)+(ACT_DOOR_SCOPE=$B6)))*SIGN(((ACT_SKU_SCOPE="ALL")+(ACT_SKU_SCOPE=$G6)))*(ACT_START<=6)*(ACT_END>=6)*IFERROR(ACT_UPLIFT-1,0)))*(1+SUMPRODUCT(SIGN(((ACT_DOOR_SCOPE="ALL")+(ACT_DOOR_SCOPE="TIER_"&$F6)+(ACT_DOOR_SCOPE=$B6)))*SIGN(((ACT_SKU_SCOPE="ALL")+(ACT_SKU_SCOPE=$G6)))*(6>ACT_END)*(ACT_END>0)*IFERROR(ACT_POSTLIFT,0))),0))) | P6: =IF(OR($H6<>"Y",7<$I6),0,IF(SUMPRODUCT(((BULK_ENABLED="Y")*((BULK_TIER="ALL")+(BULK_TIER=$F6))*((BULK_SKU="ALL")+(BULK_SKU=$G6))*(BULK_START<=7)*(BULK_END>=7)))>0,IFERROR(SUMPRODUCT(((BULK_ENABLED="Y")*((BULK_TIER="ALL")+(BULK_TIER=$F6))*((BULK_SKU="ALL")+(BULK_SKU=$G6))*(BULK_START<=7)*(BULK_END>=7))*IFERROR(BULK_VALUE,0))/MAX(1,SUMPRODUCT(((BULK_ENABLED="Y")*((BULK_TIER="ALL")+(BULK_TIER=$F6))*((BULK_SKU="ALL")+(BULK_SKU=$G6))*(BULK_START<=7)*(BULK_END>=7)))),0),ROUND((INDEX(VELOCITY_TABLE,MATCH($F6,TIER_LIST,0),2))*(IF((7-$I6+1)<=0,0,IF((7-$I6+1)=1,RAMP_W1,IF((7-$I6+1)=2,RAMP_W2,IF((7-$I6+1)=3,RAMP_W3,RAMP_W4PLUS)))))*(INDEX(ACTIVE_MULT_TABLE,2,1))*(1+SUMPRODUCT(SIGN(((ACT_DOOR_SCOPE="ALL")+(ACT_DOOR_SCOPE="TIER_"&$F6)+(ACT_DOOR_SCOPE=$B6)))*SIGN(((ACT_SKU_SCOPE="ALL")+(ACT_SKU_SCOPE=$G6)))*(ACT_START<=7)*(ACT_END>=7)*IFERROR(ACT_UPLIFT-1,0)))*(1+SUMPRODUCT(SIGN(((ACT_DOOR_SCOPE="ALL")+(ACT_DOOR_SCOPE="TIER_"&$F6)+(ACT_DOOR_SCOPE=$B6)))*SIGN(((ACT_SKU_SCOPE="ALL")+(ACT_SKU_SCOPE=$G6)))*(7>ACT_END)*(ACT_END>0)*IFERROR(ACT_POSTLIFT,0))),0))) | Q6: =IF(OR($H6<>"Y",8<$I6),0,IF(SUMPRODUCT(((BULK_ENABLED="Y")*((BULK_TIER="ALL")+(BULK_TIER=$F6))*((BULK_SKU="ALL")+(BULK_SKU=$G6))*(BULK_START<=8)*(BULK_END>=8)))>0,IFERROR(SUMPRODUCT(((BULK_ENABLED="Y")*((BULK_TIER="ALL")+(BULK_TIER=$F6))*((BULK_SKU="ALL")+(BULK_SKU=$G6))*(BULK_START<=8)*(BULK_END>=8))*IFERROR(BULK_VALUE,0))/MAX(1,SUMPRODUCT(((BULK_ENABLED="Y")*((BULK_TIER="ALL")+(BULK_TIER=$F6))*((BULK_SKU="ALL")+(BULK_SKU=$G6))*(BULK_START<=8)*(BULK_END>=8)))),0),ROUND((INDEX(VELOCITY_TABLE,MATCH($F6,TIER_LIST,0),2))*(IF((8-$I6+1)<=0,0,IF((8-$I6+1)=1,RAMP_W1,IF((8-$I6+1)=2,RAMP_W2,IF((8-$I6+1)=3,RAMP_W3,RAMP_W4PLUS)))))*(INDEX(ACTIVE_MULT_TABLE,2,1))*(1+SUMPRODUCT(SIGN(((ACT_DOOR_SCOPE="ALL")+(ACT_DOOR_SCOPE="TIER_"&$F6)+(ACT_DOOR_SCOPE=$B6)))*SIGN(((ACT_SKU_SCOPE="ALL")+(ACT_SKU_SCOPE=$G6)))*(ACT_START<=8)*(ACT_END>=8)*IFERROR(ACT_UPLIFT-1,0)))*(1+SUMPRODUCT(SIGN(((ACT_DOOR_SCOPE="ALL")+(ACT_DOOR_SCOPE="TIER_"&$F6)+(ACT_DOOR_SCOPE=$B6)))*SIGN(((ACT_SKU_SCOPE="ALL")+(ACT_SKU_SCOPE=$G6)))*(8>ACT_END)*(ACT_END>0)*IFERROR(ACT_POSTLIFT,0))),0))) | R6: =IF(OR($H6<>"Y",9<$I6),0,IF(SUMPRODUCT(((BULK_ENABLED="Y")*((BULK_TIER="ALL")+(BULK_TIER=$F6))*((BULK_SKU="ALL")+(BULK_SKU=$G6))*(BULK_START<=9)*(BULK_END>=9)))>0,IFERROR(SUMPRODUCT(((BULK_ENABLED="Y")*((BULK_TIER="ALL")+(BULK_TIER=$F6))*((BULK_SKU="ALL")+(BULK_SKU=$G6))*(BULK_START<=9)*(BULK_END>=9))*IFERROR(BULK_VALUE,0))/MAX(1,SUMPRODUCT(((BULK_ENABLED="Y")*((BULK_TIER="ALL")+(BULK_TIER=$F6))*((BULK_SKU="ALL")+(BULK_SKU=$G6))*(BULK_START<=9)*(BULK_END>=9)))),0),ROUND((INDEX(VELOCITY_TABLE,MATCH($F6,TIER_LIST,0),2))*(IF((9-$I6+1)<=0,0,IF((9-$I6+1)=1,RAMP_W1,IF((9-$I6+1)=2,RAMP_W2,IF((9-$I6+1)=3,RAMP_W3,RAMP_W4PLUS)))))*(INDEX(ACTIVE_MULT_TABLE,2,1))*(1+SUMPRODUCT(SIGN(((ACT_DOOR_SCOPE="ALL")+(ACT_DOOR_SCOPE="TIER_"&$F6)+(ACT_DOOR_SCOPE=$B6)))*SIGN(((ACT_SKU_SCOPE="ALL")+(ACT_SKU_SCOPE=$G6)))*(ACT_START<=9)*(ACT_END>=9)*IFERROR(ACT_UPLIFT-1,0)))*(1+SUMPRODUCT(SIGN(((ACT_DOOR_SCOPE="ALL")+(ACT_DOOR_SCOPE="TIER_"&$F6)+(ACT_DOOR_SCOPE=$B6)))*SIGN(((ACT_SKU_SCOPE="ALL")+(ACT_SKU_SCOPE=$G6)))*(9>ACT_END)*(ACT_END>0)*IFERROR(ACT_POSTLIFT,0))),0))) | S6: =IF(OR($H6<>"Y",10<$I6),0,IF(SUMPRODUCT(((BULK_ENABLED="Y")*((BULK_TIER="ALL")+(BULK_TIER=$F6))*((BULK_SKU="ALL")+(BULK_SKU=$G6))*(BULK_START<=10)*(BULK_END>=10)))>0,IFERROR(SUMPRODUCT(((BULK_ENABLED="Y")*((BULK_TIER="ALL")+(BULK_TIER=$F6))*((BULK_SKU="ALL")+(BULK_SKU=$G6))*(BULK_START<=10)*(BULK_END>=10))*IFERROR(BULK_VALUE,0))/MAX(1,SUMPRODUCT(((BULK_ENABLED="Y")*((BULK_TIER="ALL")+(BULK_TIER=$F6))*((BULK_SKU="ALL")+(BULK_SKU=$G6))*(BULK_START<=10)*(BULK_END>=10)))),0),ROUND((INDEX(VELOCITY_TABLE,MATCH($F6,TIER_LIST,0),2))*(IF((10-$I6+1)<=0,0,IF((10-$I6+1)=1,RAMP_W1,IF((10-$I6+1)=2,RAMP_W2,IF((10-$I6+1)=3,RAMP_W3,RAMP_W4PLUS)))))*(INDEX(ACTIVE_MULT_TABLE,2,1))*(1+SUMPRODUCT(SIGN(((ACT_DOOR_SCOPE="ALL")+(ACT_DOOR_SCOPE="TIER_"&$F6)+(ACT_DOOR_SCOPE=$B6)))*SIGN(((ACT_SKU_SCOPE="ALL")+(ACT_SKU_SCOPE=$G6)))*(ACT_START<=10)*(ACT_END>=10)*IFERROR(ACT_UPLIFT-1,0)))*(1+SUMPRODUCT(SIGN(((ACT_DOOR_SCOPE="ALL")+(ACT_DOOR_SCOPE="TIER_"&$F6)+(ACT_DOOR_SCOPE=$B6)))*SIGN(((ACT_SKU_SCOPE="ALL")+(ACT_SKU_SCOPE=$G6)))*(10>ACT_END)*(ACT_END>0)*IFERROR(ACT_POSTLIFT,0))),0))) | T6: =IF(OR($H6<>"Y",11<$I6),0,IF(SUMPRODUCT(((BULK_ENABLED="Y")*((BULK_TIER="ALL")+(BULK_TIER=$F6))*((BULK_SKU="ALL")+(BULK_SKU=$G6))*(BULK_START<=11)*(BULK_END>=11)))>0,IFERROR(SUMPRODUCT(((BULK_ENABLED="Y")*((BULK_TIER="ALL")+(BULK_TIER=$F6))*((BULK_SKU="ALL")+(BULK_SKU=$G6))*(BULK_START<=11)*(BULK_END>=11))*IFERROR(BULK_VALUE,0))/MAX(1,SUMPRODUCT(((BULK_ENABLED="Y")*((BULK_TIER="ALL")+(BULK_TIER=$F6))*((BULK_SKU="ALL")+(BULK_SKU=$G6))*(BULK_START<=11)*(BULK_END>=11)))),0),ROUND((INDEX(VELOCITY_TABLE,MATCH($F6,TIER_LIST,0),2))*(IF((11-$I6+1)<=0,0,IF((11-$I6+1)=1,RAMP_W1,IF((11-$I6+1)=2,RAMP_W2,IF((11-$I6+1)=3,RAMP_W3,RAMP_W4PLUS)))))*(INDEX(ACTIVE_MULT_TABLE,2,1))*(1+SUMPRODUCT(SIGN(((ACT_DOOR_SCOPE="ALL")+(ACT_DOOR_SCOPE="TIER_"&$F6)+(ACT_DOOR_SCOPE=$B6)))*SIGN(((ACT_SKU_SCOPE="ALL")+(ACT_SKU_SCOPE=$G6)))*(ACT_START<=11)*(ACT_END>=11)*IFERROR(ACT_UPLIFT-1,0)))*(1+SUMPRODUCT(SIGN(((ACT_DOOR_SCOPE="ALL")+(ACT_DOOR_SCOPE="TIER_"&$F6)+(ACT_DOOR_SCOPE=$B6)))*SIGN(((ACT_SKU_SCOPE="ALL")+(ACT_SKU_SCOPE=$G6)))*(11>ACT_END)*(ACT_END>0)*IFERROR(ACT_POSTLIFT,0))),0))) | U6: =IF(OR($H6<>"Y",12<$I6),0,IF(SUMPRODUCT(((BULK_ENABLED="Y")*((BULK_TIER="ALL")+(BULK_TIER=$F6))*((BULK_SKU="ALL")+(BULK_SKU=$G6))*(BULK_START<=12)*(BULK_END>=12)))>0,IFERROR(SUMPRODUCT(((BULK_ENABLED="Y")*((BULK_TIER="ALL")+(BULK_TIER=$F6))*((BULK_SKU="ALL")+(BULK_SKU=$G6))*(BULK_START<=12)*(BULK_END>=12))*IFERROR(BULK_VALUE,0))/MAX(1,SUMPRODUCT(((BULK_ENABLED="Y")*((BULK_TIER="ALL")+(BULK_TIER=$F6))*((BULK_SKU="ALL")+(BULK_SKU=$G6))*(BULK_START<=12)*(BULK_END>=12)))),0),ROUND((INDEX(VELOCITY_TABLE,MATCH($F6,TIER_LIST,0),2))*(IF((12-$I6+1)<=0,0,IF((12-$I6+1)=1,RAMP_W1,IF((12-$I6+1)=2,RAMP_W2,IF((12-$I6+1)=3,RAMP_W3,RAMP_W4PLUS)))))*(INDEX(ACTIVE_MULT_TABLE,2,1))*(1+SUMPRODUCT(SIGN(((ACT_DOOR_SCOPE="ALL")+(ACT_DOOR_SCOPE="TIER_"&$F6)+(ACT_DOOR_SCOPE=$B6)))*SIGN(((ACT_SKU_SCOPE="ALL")+(ACT_SKU_SCOPE=$G6)))*(ACT_START<=12)*(ACT_END>=12)*IFERROR(ACT_UPLIFT-1,0)))*(1+SUMPRODUCT(SIGN(((ACT_DOOR_SCOPE="ALL")+(ACT_DOOR_SCOPE="TIER_"&$F6)+(ACT_DOOR_SCOPE=$B6)))*SIGN(((ACT_SKU_SCOPE="ALL")+(ACT_SKU_SCOPE=$G6)))*(12>ACT_END)*(ACT_END>0)*IFERROR(ACT_POSTLIFT,0))),0))) | V6: =IF(OR($H6<>"Y",13<$I6),0,IF(SUMPRODUCT(((BULK_ENABLED="Y")*((BULK_TIER="ALL")+(BULK_TIER=$F6))*((BULK_SKU="ALL")+(BULK_SKU=$G6))*(BULK_START<=13)*(BULK_END>=13)))>0,IFERROR(SUMPRODUCT(((BULK_ENABLED="Y")*((BULK_TIER="ALL")+(BULK_TIER=$F6))*((BULK_SKU="ALL")+(BULK_SKU=$G6))*(BULK_START<=13)*(BULK_END>=13))*IFERROR(BULK_VALUE,0))/MAX(1,SUMPRODUCT(((BULK_ENABLED="Y")*((BULK_TIER="ALL")+(BULK_TIER=$F6))*((BULK_SKU="ALL")+(BULK_SKU=$G6))*(BULK_START<=13)*(BULK_END>=13)))),0),ROUND((INDEX(VELOCITY_TABLE,MATCH($F6,TIER_LIST,0),2))*(IF((13-$I6+1)<=0,0,IF((13-$I6+1)=1,RAMP_W1,IF((13-$I6+1)=2,RAMP_W2,IF((13-$I6+1)=3,RAMP_W3,RAMP_W4PLUS)))))*(INDEX(ACTIVE_MULT_TABLE,2,1))*(1+SUMPRODUCT(SIGN(((ACT_DOOR_SCOPE="ALL")+(ACT_DOOR_SCOPE="TIER_"&$F6)+(ACT_DOOR_SCOPE=$B6)))*SIGN(((ACT_SKU_SCOPE="ALL")+(ACT_SKU_SCOPE=$G6)))*(ACT_START<=13)*(ACT_END>=13)*IFERROR(ACT_UPLIFT-1,0)))*(1+SUMPRODUCT(SIGN(((ACT_DOOR_SCOPE="ALL")+(ACT_DOOR_SCOPE="TIER_"&$F6)+(ACT_DOOR_SCOPE=$B6)))*SIGN(((ACT_SKU_SCOPE="ALL")+(ACT_SKU_SCOPE=$G6)))*(13>ACT_END)*(ACT_END>0)*IFERROR(ACT_POSTLIFT,0))),0)))
A7: R0003 | B7: =Doors!$A$5 | C7: =Doors!$C$5 | D7: =Doors!$B$5 | E7: =Doors!$E$5 | F7: =Doors!$F$5 | G7: Raspberry | H7: =Doors!$I$5 | I7: =Doors!$J$5 | J7: =IF(OR($H7<>"Y",1<$I7),0,IF(SUMPRODUCT(((BULK_ENABLED="Y")*((BULK_TIER="ALL")+(BULK_TIER=$F7))*((BULK_SKU="ALL")+(BULK_SKU=$G7))*(BULK_START<=1)*(BULK_END>=1)))>0,IFERROR(SUMPRODUCT(((BULK_ENABLED="Y")*((BULK_TIER="ALL")+(BULK_TIER=$F7))*((BULK_SKU="ALL")+(BULK_SKU=$G7))*(BULK_START<=1)*(BULK_END>=1))*IFERROR(BULK_VALUE,0))/MAX(1,SUMPRODUCT(((BULK_ENABLED="Y")*((BULK_TIER="ALL")+(BULK_TIER=$F7))*((BULK_SKU="ALL")+(BULK_SKU=$G7))*(BULK_START<=1)*(BULK_END>=1)))),0),ROUND((INDEX(VELOCITY_TABLE,MATCH($F7,TIER_LIST,0),3))*(IF((1-$I7+1)<=0,0,IF((1-$I7+1)=1,RAMP_W1,IF((1-$I7+1)=2,RAMP_W2,IF((1-$I7+1)=3,RAMP_W3,RAMP_W4PLUS)))))*(INDEX(ACTIVE_MULT_TABLE,3,1))*(1+SUMPRODUCT(SIGN(((ACT_DOOR_SCOPE="ALL")+(ACT_DOOR_SCOPE="TIER_"&$F7)+(ACT_DOOR_SCOPE=$B7)))*SIGN(((ACT_SKU_SCOPE="ALL")+(ACT_SKU_SCOPE=$G7)))*(ACT_START<=1)*(ACT_END>=1)*IFERROR(ACT_UPLIFT-1,0)))*(1+SUMPRODUCT(SIGN(((ACT_DOOR_SCOPE="ALL")+(ACT_DOOR_SCOPE="TIER_"&$F7)+(ACT_DOOR_SCOPE=$B7)))*SIGN(((ACT_SKU_SCOPE="ALL")+(ACT_SKU_SCOPE=$G7)))*(1>ACT_END)*(ACT_END>0)*IFERROR(ACT_POSTLIFT,0))),0))) | K7: =IF(OR($H7<>"Y",2<$I7),0,IF(SUMPRODUCT(((BULK_ENABLED="Y")*((BULK_TIER="ALL")+(BULK_TIER=$F7))*((BULK_SKU="ALL")+(BULK_SKU=$G7))*(BULK_START<=2)*(BULK_END>=2)))>0,IFERROR(SUMPRODUCT(((BULK_ENABLED="Y")*((BULK_TIER="ALL")+(BULK_TIER=$F7))*((BULK_SKU="ALL")+(BULK_SKU=$G7))*(BULK_START<=2)*(BULK_END>=2))*IFERROR(BULK_VALUE,0))/MAX(1,SUMPRODUCT(((BULK_ENABLED="Y")*((BULK_TIER="ALL")+(BULK_TIER=$F7))*((BULK_SKU="ALL")+(BULK_SKU=$G7))*(BULK_START<=2)*(BULK_END>=2)))),0),ROUND((INDEX(VELOCITY_TABLE,MATCH($F7,TIER_LIST,0),3))*(IF((2-$I7+1)<=0,0,IF((2-$I7+1)=1,RAMP_W1,IF((2-$I7+1)=2,RAMP_W2,IF((2-$I7+1)=3,RAMP_W3,RAMP_W4PLUS)))))*(INDEX(ACTIVE_MULT_TABLE,3,1))*(1+SUMPRODUCT(SIGN(((ACT_DOOR_SCOPE="ALL")+(ACT_DOOR_SCOPE="TIER_"&$F7)+(ACT_DOOR_SCOPE=$B7)))*SIGN(((ACT_SKU_SCOPE="ALL")+(ACT_SKU_SCOPE=$G7)))*(ACT_START<=2)*(ACT_END>=2)*IFERROR(ACT_UPLIFT-1,0)))*(1+SUMPRODUCT(SIGN(((ACT_DOOR_SCOPE="ALL")+(ACT_DOOR_SCOPE="TIER_"&$F7)+(ACT_DOOR_SCOPE=$B7)))*SIGN(((ACT_SKU_SCOPE="ALL")+(ACT_SKU_SCOPE=$G7)))*(2>ACT_END)*(ACT_END>0)*IFERROR(ACT_POSTLIFT,0))),0))) | L7: =IF(OR($H7<>"Y",3<$I7),0,IF(SUMPRODUCT(((BULK_ENABLED="Y")*((BULK_TIER="ALL")+(BULK_TIER=$F7))*((BULK_SKU="ALL")+(BULK_SKU=$G7))*(BULK_START<=3)*(BULK_END>=3)))>0,IFERROR(SUMPRODUCT(((BULK_ENABLED="Y")*((BULK_TIER="ALL")+(BULK_TIER=$F7))*((BULK_SKU="ALL")+(BULK_SKU=$G7))*(BULK_START<=3)*(BULK_END>=3))*IFERROR(BULK_VALUE,0))/MAX(1,SUMPRODUCT(((BULK_ENABLED="Y")*((BULK_TIER="ALL")+(BULK_TIER=$F7))*((BULK_SKU="ALL")+(BULK_SKU=$G7))*(BULK_START<=3)*(BULK_END>=3)))),0),ROUND((INDEX(VELOCITY_TABLE,MATCH($F7,TIER_LIST,0),3))*(IF((3-$I7+1)<=0,0,IF((3-$I7+1)=1,RAMP_W1,IF((3-$I7+1)=2,RAMP_W2,IF((3-$I7+1)=3,RAMP_W3,RAMP_W4PLUS)))))*(INDEX(ACTIVE_MULT_TABLE,3,1))*(1+SUMPRODUCT(SIGN(((ACT_DOOR_SCOPE="ALL")+(ACT_DOOR_SCOPE="TIER_"&$F7)+(ACT_DOOR_SCOPE=$B7)))*SIGN(((ACT_SKU_SCOPE="ALL")+(ACT_SKU_SCOPE=$G7)))*(ACT_START<=3)*(ACT_END>=3)*IFERROR(ACT_UPLIFT-1,0)))*(1+SUMPRODUCT(SIGN(((ACT_DOOR_SCOPE="ALL")+(ACT_DOOR_SCOPE="TIER_"&$F7)+(ACT_DOOR_SCOPE=$B7)))*SIGN(((ACT_SKU_SCOPE="ALL")+(ACT_SKU_SCOPE=$G7)))*(3>ACT_END)*(ACT_END>0)*IFERROR(ACT_POSTLIFT,0))),0))) | M7: =IF(OR($H7<>"Y",4<$I7),0,IF(SUMPRODUCT(((BULK_ENABLED="Y")*((BULK_TIER="ALL")+(BULK_TIER=$F7))*((BULK_SKU="ALL")+(BULK_SKU=$G7))*(BULK_START<=4)*(BULK_END>=4)))>0,IFERROR(SUMPRODUCT(((BULK_ENABLED="Y")*((BULK_TIER="ALL")+(BULK_TIER=$F7))*((BULK_SKU="ALL")+(BULK_SKU=$G7))*(BULK_START<=4)*(BULK_END>=4))*IFERROR(BULK_VALUE,0))/MAX(1,SUMPRODUCT(((BULK_ENABLED="Y")*((BULK_TIER="ALL")+(BULK_TIER=$F7))*((BULK_SKU="ALL")+(BULK_SKU=$G7))*(BULK_START<=4)*(BULK_END>=4)))),0),ROUND((INDEX(VELOCITY_TABLE,MATCH($F7,TIER_LIST,0),3))*(IF((4-$I7+1)<=0,0,IF((4-$I7+1)=1,RAMP_W1,IF((4-$I7+1)=2,RAMP_W2,IF((4-$I7+1)=3,RAMP_W3,RAMP_W4PLUS)))))*(INDEX(ACTIVE_MULT_TABLE,3,1))*(1+SUMPRODUCT(SIGN(((ACT_DOOR_SCOPE="ALL")+(ACT_DOOR_SCOPE="TIER_"&$F7)+(ACT_DOOR_SCOPE=$B7)))*SIGN(((ACT_SKU_SCOPE="ALL")+(ACT_SKU_SCOPE=$G7)))*(ACT_START<=4)*(ACT_END>=4)*IFERROR(ACT_UPLIFT-1,0)))*(1+SUMPRODUCT(SIGN(((ACT_DOOR_SCOPE="ALL")+(ACT_DOOR_SCOPE="TIER_"&$F7)+(ACT_DOOR_SCOPE=$B7)))*SIGN(((ACT_SKU_SCOPE="ALL")+(ACT_SKU_SCOPE=$G7)))*(4>ACT_END)*(ACT_END>0)*IFERROR(ACT_POSTLIFT,0))),0))) | N7: =IF(OR($H7<>"Y",5<$I7),0,IF(SUMPRODUCT(((BULK_ENABLED="Y")*((BULK_TIER="ALL")+(BULK_TIER=$F7))*((BULK_SKU="ALL")+(BULK_SKU=$G7))*(BULK_START<=5)*(BULK_END>=5)))>0,IFERROR(SUMPRODUCT(((BULK_ENABLED="Y")*((BULK_TIER="ALL")+(BULK_TIER=$F7))*((BULK_SKU="ALL")+(BULK_SKU=$G7))*(BULK_START<=5)*(BULK_END>=5))*IFERROR(BULK_VALUE,0))/MAX(1,SUMPRODUCT(((BULK_ENABLED="Y")*((BULK_TIER="ALL")+(BULK_TIER=$F7))*((BULK_SKU="ALL")+(BULK_SKU=$G7))*(BULK_START<=5)*(BULK_END>=5)))),0),ROUND((INDEX(VELOCITY_TABLE,MATCH($F7,TIER_LIST,0),3))*(IF((5-$I7+1)<=0,0,IF((5-$I7+1)=1,RAMP_W1,IF((5-$I7+1)=2,RAMP_W2,IF((5-$I7+1)=3,RAMP_W3,RAMP_W4PLUS)))))*(INDEX(ACTIVE_MULT_TABLE,3,1))*(1+SUMPRODUCT(SIGN(((ACT_DOOR_SCOPE="ALL")+(ACT_DOOR_SCOPE="TIER_"&$F7)+(ACT_DOOR_SCOPE=$B7)))*SIGN(((ACT_SKU_SCOPE="ALL")+(ACT_SKU_SCOPE=$G7)))*(ACT_START<=5)*(ACT_END>=5)*IFERROR(ACT_UPLIFT-1,0)))*(1+SUMPRODUCT(SIGN(((ACT_DOOR_SCOPE="ALL")+(ACT_DOOR_SCOPE="TIER_"&$F7)+(ACT_DOOR_SCOPE=$B7)))*SIGN(((ACT_SKU_SCOPE="ALL")+(ACT_SKU_SCOPE=$G7)))*(5>ACT_END)*(ACT_END>0)*IFERROR(ACT_POSTLIFT,0))),0))) | O7: =IF(OR($H7<>"Y",6<$I7),0,IF(SUMPRODUCT(((BULK_ENABLED="Y")*((BULK_TIER="ALL")+(BULK_TIER=$F7))*((BULK_SKU="ALL")+(BULK_SKU=$G7))*(BULK_START<=6)*(BULK_END>=6)))>0,IFERROR(SUMPRODUCT(((BULK_ENABLED="Y")*((BULK_TIER="ALL")+(BULK_TIER=$F7))*((BULK_SKU="ALL")+(BULK_SKU=$G7))*(BULK_START<=6)*(BULK_END>=6))*IFERROR(BULK_VALUE,0))/MAX(1,SUMPRODUCT(((BULK_ENABLED="Y")*((BULK_TIER="ALL")+(BULK_TIER=$F7))*((BULK_SKU="ALL")+(BULK_SKU=$G7))*(BULK_START<=6)*(BULK_END>=6)))),0),ROUND((INDEX(VELOCITY_TABLE,MATCH($F7,TIER_LIST,0),3))*(IF((6-$I7+1)<=0,0,IF((6-$I7+1)=1,RAMP_W1,IF((6-$I7+1)=2,RAMP_W2,IF((6-$I7+1)=3,RAMP_W3,RAMP_W4PLUS)))))*(INDEX(ACTIVE_MULT_TABLE,3,1))*(1+SUMPRODUCT(SIGN(((ACT_DOOR_SCOPE="ALL")+(ACT_DOOR_SCOPE="TIER_"&$F7)+(ACT_DOOR_SCOPE=$B7)))*SIGN(((ACT_SKU_SCOPE="ALL")+(ACT_SKU_SCOPE=$G7)))*(ACT_START<=6)*(ACT_END>=6)*IFERROR(ACT_UPLIFT-1,0)))*(1+SUMPRODUCT(SIGN(((ACT_DOOR_SCOPE="ALL")+(ACT_DOOR_SCOPE="TIER_"&$F7)+(ACT_DOOR_SCOPE=$B7)))*SIGN(((ACT_SKU_SCOPE="ALL")+(ACT_SKU_SCOPE=$G7)))*(6>ACT_END)*(ACT_END>0)*IFERROR(ACT_POSTLIFT,0))),0))) | P7: =IF(OR($H7<>"Y",7<$I7),0,IF(SUMPRODUCT(((BULK_ENABLED="Y")*((BULK_TIER="ALL")+(BULK_TIER=$F7))*((BULK_SKU="ALL")+(BULK_SKU=$G7))*(BULK_START<=7)*(BULK_END>=7)))>0,IFERROR(SUMPRODUCT(((BULK_ENABLED="Y")*((BULK_TIER="ALL")+(BULK_TIER=$F7))*((BULK_SKU="ALL")+(BULK_SKU=$G7))*(BULK_START<=7)*(BULK_END>=7))*IFERROR(BULK_VALUE,0))/MAX(1,SUMPRODUCT(((BULK_ENABLED="Y")*((BULK_TIER="ALL")+(BULK_TIER=$F7))*((BULK_SKU="ALL")+(BULK_SKU=$G7))*(BULK_START<=7)*(BULK_END>=7)))),0),ROUND((INDEX(VELOCITY_TABLE,MATCH($F7,TIER_LIST,0),3))*(IF((7-$I7+1)<=0,0,IF((7-$I7+1)=1,RAMP_W1,IF((7-$I7+1)=2,RAMP_W2,IF((7-$I7+1)=3,RAMP_W3,RAMP_W4PLUS)))))*(INDEX(ACTIVE_MULT_TABLE,3,1))*(1+SUMPRODUCT(SIGN(((ACT_DOOR_SCOPE="ALL")+(ACT_DOOR_SCOPE="TIER_"&$F7)+(ACT_DOOR_SCOPE=$B7)))*SIGN(((ACT_SKU_SCOPE="ALL")+(ACT_SKU_SCOPE=$G7)))*(ACT_START<=7)*(ACT_END>=7)*IFERROR(ACT_UPLIFT-1,0)))*(1+SUMPRODUCT(SIGN(((ACT_DOOR_SCOPE="ALL")+(ACT_DOOR_SCOPE="TIER_"&$F7)+(ACT_DOOR_SCOPE=$B7)))*SIGN(((ACT_SKU_SCOPE="ALL")+(ACT_SKU_SCOPE=$G7)))*(7>ACT_END)*(ACT_END>0)*IFERROR(ACT_POSTLIFT,0))),0))) | Q7: =IF(OR($H7<>"Y",8<$I7),0,IF(SUMPRODUCT(((BULK_ENABLED="Y")*((BULK_TIER="ALL")+(BULK_TIER=$F7))*((BULK_SKU="ALL")+(BULK_SKU=$G7))*(BULK_START<=8)*(BULK_END>=8)))>0,IFERROR(SUMPRODUCT(((BULK_ENABLED="Y")*((BULK_TIER="ALL")+(BULK_TIER=$F7))*((BULK_SKU="ALL")+(BULK_SKU=$G7))*(BULK_START<=8)*(BULK_END>=8))*IFERROR(BULK_VALUE,0))/MAX(1,SUMPRODUCT(((BULK_ENABLED="Y")*((BULK_TIER="ALL")+(BULK_TIER=$F7))*((BULK_SKU="ALL")+(BULK_SKU=$G7))*(BULK_START<=8)*(BULK_END>=8)))),0),ROUND((INDEX(VELOCITY_TABLE,MATCH($F7,TIER_LIST,0),3))*(IF((8-$I7+1)<=0,0,IF((8-$I7+1)=1,RAMP_W1,IF((8-$I7+1)=2,RAMP_W2,IF((8-$I7+1)=3,RAMP_W3,RAMP_W4PLUS)))))*(INDEX(ACTIVE_MULT_TABLE,3,1))*(1+SUMPRODUCT(SIGN(((ACT_DOOR_SCOPE="ALL")+(ACT_DOOR_SCOPE="TIER_"&$F7)+(ACT_DOOR_SCOPE=$B7)))*SIGN(((ACT_SKU_SCOPE="ALL")+(ACT_SKU_SCOPE=$G7)))*(ACT_START<=8)*(ACT_END>=8)*IFERROR(ACT_UPLIFT-1,0)))*(1+SUMPRODUCT(SIGN(((ACT_DOOR_SCOPE="ALL")+(ACT_DOOR_SCOPE="TIER_"&$F7)+(ACT_DOOR_SCOPE=$B7)))*SIGN(((ACT_SKU_SCOPE="ALL")+(ACT_SKU_SCOPE=$G7)))*(8>ACT_END)*(ACT_END>0)*IFERROR(ACT_POSTLIFT,0))),0))) | R7: =IF(OR($H7<>"Y",9<$I7),0,IF(SUMPRODUCT(((BULK_ENABLED="Y")*((BULK_TIER="ALL")+(BULK_TIER=$F7))*((BULK_SKU="ALL")+(BULK_SKU=$G7))*(BULK_START<=9)*(BULK_END>=9)))>0,IFERROR(SUMPRODUCT(((BULK_ENABLED="Y")*((BULK_TIER="ALL")+(BULK_TIER=$F7))*((BULK_SKU="ALL")+(BULK_SKU=$G7))*(BULK_START<=9)*(BULK_END>=9))*IFERROR(BULK_VALUE,0))/MAX(1,SUMPRODUCT(((BULK_ENABLED="Y")*((BULK_TIER="ALL")+(BULK_TIER=$F7))*((BULK_SKU="ALL")+(BULK_SKU=$G7))*(BULK_START<=9)*(BULK_END>=9)))),0),ROUND((INDEX(VELOCITY_TABLE,MATCH($F7,TIER_LIST,0),3))*(IF((9-$I7+1)<=0,0,IF((9-$I7+1)=1,RAMP_W1,IF((9-$I7+1)=2,RAMP_W2,IF((9-$I7+1)=3,RAMP_W3,RAMP_W4PLUS)))))*(INDEX(ACTIVE_MULT_TABLE,3,1))*(1+SUMPRODUCT(SIGN(((ACT_DOOR_SCOPE="ALL")+(ACT_DOOR_SCOPE="TIER_"&$F7)+(ACT_DOOR_SCOPE=$B7)))*SIGN(((ACT_SKU_SCOPE="ALL")+(ACT_SKU_SCOPE=$G7)))*(ACT_START<=9)*(ACT_END>=9)*IFERROR(ACT_UPLIFT-1,0)))*(1+SUMPRODUCT(SIGN(((ACT_DOOR_SCOPE="ALL")+(ACT_DOOR_SCOPE="TIER_"&$F7)+(ACT_DOOR_SCOPE=$B7)))*SIGN(((ACT_SKU_SCOPE="ALL")+(ACT_SKU_SCOPE=$G7)))*(9>ACT_END)*(ACT_END>0)*IFERROR(ACT_POSTLIFT,0))),0))) | S7: =IF(OR($H7<>"Y",10<$I7),0,IF(SUMPRODUCT(((BULK_ENABLED="Y")*((BULK_TIER="ALL")+(BULK_TIER=$F7))*((BULK_SKU="ALL")+(BULK_SKU=$G7))*(BULK_START<=10)*(BULK_END>=10)))>0,IFERROR(SUMPRODUCT(((BULK_ENABLED="Y")*((BULK_TIER="ALL")+(BULK_TIER=$F7))*((BULK_SKU="ALL")+(BULK_SKU=$G7))*(BULK_START<=10)*(BULK_END>=10))*IFERROR(BULK_VALUE,0))/MAX(1,SUMPRODUCT(((BULK_ENABLED="Y")*((BULK_TIER="ALL")+(BULK_TIER=$F7))*((BULK_SKU="ALL")+(BULK_SKU=$G7))*(BULK_START<=10)*(BULK_END>=10)))),0),ROUND((INDEX(VELOCITY_TABLE,MATCH($F7,TIER_LIST,0),3))*(IF((10-$I7+1)<=0,0,IF((10-$I7+1)=1,RAMP_W1,IF((10-$I7+1)=2,RAMP_W2,IF((10-$I7+1)=3,RAMP_W3,RAMP_W4PLUS)))))*(INDEX(ACTIVE_MULT_TABLE,3,1))*(1+SUMPRODUCT(SIGN(((ACT_DOOR_SCOPE="ALL")+(ACT_DOOR_SCOPE="TIER_"&$F7)+(ACT_DOOR_SCOPE=$B7)))*SIGN(((ACT_SKU_SCOPE="ALL")+(ACT_SKU_SCOPE=$G7)))*(ACT_START<=10)*(ACT_END>=10)*IFERROR(ACT_UPLIFT-1,0)))*(1+SUMPRODUCT(SIGN(((ACT_DOOR_SCOPE="ALL")+(ACT_DOOR_SCOPE="TIER_"&$F7)+(ACT_DOOR_SCOPE=$B7)))*SIGN(((ACT_SKU_SCOPE="ALL")+(ACT_SKU_SCOPE=$G7)))*(10>ACT_END)*(ACT_END>0)*IFERROR(ACT_POSTLIFT,0))),0))) | T7: =IF(OR($H7<>"Y",11<$I7),0,IF(SUMPRODUCT(((BULK_ENABLED="Y")*((BULK_TIER="ALL")+(BULK_TIER=$F7))*((BULK_SKU="ALL")+(BULK_SKU=$G7))*(BULK_START<=11)*(BULK_END>=11)))>0,IFERROR(SUMPRODUCT(((BULK_ENABLED="Y")*((BULK_TIER="ALL")+(BULK_TIER=$F7))*((BULK_SKU="ALL")+(BULK_SKU=$G7))*(BULK_START<=11)*(BULK_END>=11))*IFERROR(BULK_VALUE,0))/MAX(1,SUMPRODUCT(((BULK_ENABLED="Y")*((BULK_TIER="ALL")+(BULK_TIER=$F7))*((BULK_SKU="ALL")+(BULK_SKU=$G7))*(BULK_START<=11)*(BULK_END>=11)))),0),ROUND((INDEX(VELOCITY_TABLE,MATCH($F7,TIER_LIST,0),3))*(IF((11-$I7+1)<=0,0,IF((11-$I7+1)=1,RAMP_W1,IF((11-$I7+1)=2,RAMP_W2,IF((11-$I7+1)=3,RAMP_W3,RAMP_W4PLUS)))))*(INDEX(ACTIVE_MULT_TABLE,3,1))*(1+SUMPRODUCT(SIGN(((ACT_DOOR_SCOPE="ALL")+(ACT_DOOR_SCOPE="TIER_"&$F7)+(ACT_DOOR_SCOPE=$B7)))*SIGN(((ACT_SKU_SCOPE="ALL")+(ACT_SKU_SCOPE=$G7)))*(ACT_START<=11)*(ACT_END>=11)*IFERROR(ACT_UPLIFT-1,0)))*(1+SUMPRODUCT(SIGN(((ACT_DOOR_SCOPE="ALL")+(ACT_DOOR_SCOPE="TIER_"&$F7)+(ACT_DOOR_SCOPE=$B7)))*SIGN(((ACT_SKU_SCOPE="ALL")+(ACT_SKU_SCOPE=$G7)))*(11>ACT_END)*(ACT_END>0)*IFERROR(ACT_POSTLIFT,0))),0))) | U7: =IF(OR($H7<>"Y",12<$I7),0,IF(SUMPRODUCT(((BULK_ENABLED="Y")*((BULK_TIER="ALL")+(BULK_TIER=$F7))*((BULK_SKU="ALL")+(BULK_SKU=$G7))*(BULK_START<=12)*(BULK_END>=12)))>0,IFERROR(SUMPRODUCT(((BULK_ENABLED="Y")*((BULK_TIER="ALL")+(BULK_TIER=$F7))*((BULK_SKU="ALL")+(BULK_SKU=$G7))*(BULK_START<=12)*(BULK_END>=12))*IFERROR(BULK_VALUE,0))/MAX(1,SUMPRODUCT(((BULK_ENABLED="Y")*((BULK_TIER="ALL")+(BULK_TIER=$F7))*((BULK_SKU="ALL")+(BULK_SKU=$G7))*(BULK_START<=12)*(BULK_END>=12)))),0),ROUND((INDEX(VELOCITY_TABLE,MATCH($F7,TIER_LIST,0),3))*(IF((12-$I7+1)<=0,0,IF((12-$I7+1)=1,RAMP_W1,IF((12-$I7+1)=2,RAMP_W2,IF((12-$I7+1)=3,RAMP_W3,RAMP_W4PLUS)))))*(INDEX(ACTIVE_MULT_TABLE,3,1))*(1+SUMPRODUCT(SIGN(((ACT_DOOR_SCOPE="ALL")+(ACT_DOOR_SCOPE="TIER_"&$F7)+(ACT_DOOR_SCOPE=$B7)))*SIGN(((ACT_SKU_SCOPE="ALL")+(ACT_SKU_SCOPE=$G7)))*(ACT_START<=12)*(ACT_END>=12)*IFERROR(ACT_UPLIFT-1,0)))*(1+SUMPRODUCT(SIGN(((ACT_DOOR_SCOPE="ALL")+(ACT_DOOR_SCOPE="TIER_"&$F7)+(ACT_DOOR_SCOPE=$B7)))*SIGN(((ACT_SKU_SCOPE="ALL")+(ACT_SKU_SCOPE=$G7)))*(12>ACT_END)*(ACT_END>0)*IFERROR(ACT_POSTLIFT,0))),0))) | V7: =IF(OR($H7<>"Y",13<$I7),0,IF(SUMPRODUCT(((BULK_ENABLED="Y")*((BULK_TIER="ALL")+(BULK_TIER=$F7))*((BULK_SKU="ALL")+(BULK_SKU=$G7))*(BULK_START<=13)*(BULK_END>=13)))>0,IFERROR(SUMPRODUCT(((BULK_ENABLED="Y")*((BULK_TIER="ALL")+(BULK_TIER=$F7))*((BULK_SKU="ALL")+(BULK_SKU=$G7))*(BULK_START<=13)*(BULK_END>=13))*IFERROR(BULK_VALUE,0))/MAX(1,SUMPRODUCT(((BULK_ENABLED="Y")*((BULK_TIER="ALL")+(BULK_TIER=$F7))*((BULK_SKU="ALL")+(BULK_SKU=$G7))*(BULK_START<=13)*(BULK_END>=13)))),0),ROUND((INDEX(VELOCITY_TABLE,MATCH($F7,TIER_LIST,0),3))*(IF((13-$I7+1)<=0,0,IF((13-$I7+1)=1,RAMP_W1,IF((13-$I7+1)=2,RAMP_W2,IF((13-$I7+1)=3,RAMP_W3,RAMP_W4PLUS)))))*(INDEX(ACTIVE_MULT_TABLE,3,1))*(1+SUMPRODUCT(SIGN(((ACT_DOOR_SCOPE="ALL")+(ACT_DOOR_SCOPE="TIER_"&$F7)+(ACT_DOOR_SCOPE=$B7)))*SIGN(((ACT_SKU_SCOPE="ALL")+(ACT_SKU_SCOPE=$G7)))*(ACT_START<=13)*(ACT_END>=13)*IFERROR(ACT_UPLIFT-1,0)))*(1+SUMPRODUCT(SIGN(((ACT_DOOR_SCOPE="ALL")+(ACT_DOOR_SCOPE="TIER_"&$F7)+(ACT_DOOR_SCOPE=$B7)))*SIGN(((ACT_SKU_SCOPE="ALL")+(ACT_SKU_SCOPE=$G7)))*(13>ACT_END)*(ACT_END>0)*IFERROR(ACT_POSTLIFT,0))),0)))
