Workbook

Sheet Start Here
A1: Organika RTD — Sparkling Electrolytes
A4: Launch business case · Aug 1 – Nov 1, 2026 · CDN $ · v1.1
A6: Everything updates automatically. You only do three things 👇
A8: 1 | B8: Set your price
B9: On the Assumptions tab, type one Master price (top-right) — every channel uses it. Want different prices per channel? Just type over any channel cell.
A11: 2 | B11: Set your channel mix
B12: On Assumptions, enter the % of cases each channel sells. The green check confirms it totals 100%.
A14: 3 | B14: Read the answer
B15: Open Executive Summary: your margin, a clear go / no-go verdict, the price you'd need to hit target, and best / base / worst.
A17: WHAT'S INSIDE
B18: 📋 Executive Summary — the one-screen answer — margin, verdict, scenarios
B19: 💰 Business Case — break-even, ROI, payback, inventory, cannibalization, waterfall
B20: 🎛️ Assumptions — the only place you type — price, mix, targets
B21: 📊 Dashboard — P&L with by-channel / by-SKU tables and charts
B22: 🧪 Scenarios — trial any CP × MSRP; sensitivity heatmaps
B23: ⚖️ Blended — volume-weighted P&L across all channels
B24: 📑 TTL + 3 flavour tabs — the detailed per-SKU P&Ls
B25: 🏭 Cost Build-up — bottom-up cost from the Bevmax quote
A27: THE NUMBERS BEHIND IT
B28: 1 case = 24 cans = 6 × 4-pack (355 ml). Production run 40,500 cans (13,500 / flavour).
B29: Bevmax landed cost $1.21 / can = $29.10 / case. Fully-loaded COGS $32.12 / case.
B30: Run = 1,687.5 cases vs sell-in plan 1,500 → ~188 cases surplus inventory.
B31: Source: Bevmax quote OG2026-05-21 v15 · FOB Airdrie AB, excl. GST · elliott.zhong@organika.com

Sheet Executive Summary
A1: ORGANIKA RTD — EXECUTIVE SUMMARY
A2: CDN $ | Aug 1 – Nov 1, 2026 | 3 SKUs × 11 channels | blended = volume-weighted
A4: RECOMMENDATION
A5: =IF('TTL ORGANIKA RTD'!M17>=Assumptions!C10,"✅ PASS — blended GP% "&TEXT('TTL ORGANIKA RTD'!M17,"0.0%")&" meets the "&TEXT(Assumptions!C10,"0%")&" target",IF('TTL ORGANIKA RTD'!M17>=Assumptions!C9,"🟡 OK — GP% "&TEXT('TTL ORGANIKA RTD'!M17,"0.0%")&" clears the "&TEXT(Assumptions!C9,"0%")&" minimum (under target)","❌ BELOW MIN — GP% "&TEXT('TTL ORGANIKA RTD'!M17,"0.0%")&" under "&TEXT(Assumptions!C9,"0%")))
A7: PERIOD TOTALS | D7: BLENDED — PER CASE
A8: Physical cases | B8: ='TTL ORGANIKA RTD'!M9 | D8: Net sales / case | E8: ='TTL ORGANIKA RTD'!M28
A9: Gross revenue | B9: ='TTL ORGANIKA RTD'!M10 | D9: COGS / case | E9: ='TTL ORGANIKA RTD'!M31
A10: Net sales | B10: ='TTL ORGANIKA RTD'!M12 | D10: Gross profit / case | E10: ='TTL ORGANIKA RTD'!M32
A11: Cost of sales | B11: ='TTL ORGANIKA RTD'!M15 | D11: Blended GP % | E11: ='TTL ORGANIKA RTD'!M33
A12: Gross profit | B12: ='TTL ORGANIKA RTD'!M16 | D12: A&P / case | E12: ='TTL ORGANIKA RTD'!M34
A13: Blended GP % | B13: ='TTL ORGANIKA RTD'!M17 | D13: CAAP / case | E13: ='TTL ORGANIKA RTD'!M35
A14: A&P | B14: ='TTL ORGANIKA RTD'!M22
A15: CAAP | B15: ='TTL ORGANIKA RTD'!M24
A17: MARGIN GATE & PRICE-TO-HIT-MARGIN
A18: Minimum GM% | B18: =Assumptions!C9 | D18: CP /case to hit min GM% | E18: ='Cost Build-up'!$D$46/(1-Assumptions!C9)
A19: Target GM% | B19: =Assumptions!C10 | D19: CP /case to hit target GM% | E19: ='Cost Build-up'!$D$46/(1-Assumptions!C10)
A20: Blended GP% (live) | B20: ='TTL ORGANIKA RTD'!M17 | D20: COGS /case (fully loaded) | E20: ='Cost Build-up'!$D$46
A22: PRICE SCENARIOS (from Scenarios tab)
A23: Scenario | B23: Conservative | C23: Base | D23: Stretch
A24: Organika GP % | B24: =Scenarios!B14 | C24: =Scenarios!C14 | D24: =Scenarios!D14
A25: GP $/case | B25: =Scenarios!B13 | C25: =Scenarios!C13 | D25: =Scenarios!D13
A26: Retailer margin % | B26: =Scenarios!B15 | C26: =Scenarios!C15 | D26: =Scenarios!D15

Sheet Business Case
A1: ORGANIKA RTD — BUSINESS CASE (break-even, ROI, risk)
A2: CDN $ | Aug 1 – Nov 1, 2026 | pulls from TTL + Cost Build-up | 🟡 edit yellow
A4: DISCRETIONARY LAUNCH SPEND (not already in COGS) | H4: P&L bridge / case
A5: Slotting / listing fees | B5: 10000 | H5: Gross Rev | I5: 0 | J5: 0 | K5: ='TTL ORGANIKA RTD'!M26
A6: Fixed launch marketing (beyond A&P %) | B6: 15000 | H6: Discounts | I6: ='TTL ORGANIKA RTD'!M28 | J6: ='TTL ORGANIKA RTD'!M27 | K6: 0
A7: Other one-time (not in COGS) | B7: 0 | H7: COGS | I7: ='TTL ORGANIKA RTD'!M32 | J7: ='TTL ORGANIKA RTD'!M31 | K7: 0
A8: Total launch spend | B8: =SUM(B5:B7) | H8: A&P | I8: ='TTL ORGANIKA RTD'!M35 | J8: ='TTL ORGANIKA RTD'!M34 | K8: 0
C9: Bevmax setup & allergen are already inside COGS — not added here. | H9: CAAP | I9: 0 | J9: 0 | K9: ='TTL ORGANIKA RTD'!M35
A11: BREAK-EVEN · ROI · PAYBACK
A12: Blended CAAP / case (contribution) | B12: ='TTL ORGANIKA RTD'!M35
A13: Break-even cases (cover launch spend) | B13: =IFERROR(B8/B12,"-")
A14: Plan cases (period) | B14: ='TTL ORGANIKA RTD'!M9
A15: Margin of safety (cases) | B15: =B14-B13
A16: Margin of safety (%) | B16: =IFERROR(B15/B14,"-")
A17: Total CAAP (period) | B17: ='TTL ORGANIKA RTD'!M24
A18: Launch profit (CAAP − launch spend) | B18: =B17-B8
A19: ROI on launch spend | B19: =IFERROR(B18/B8,"-")
A21: PRODUCTION RUN & INVENTORY (sell-through)
A22: Run cost — cash to produce | B22: ='Cost Build-up'!D26 | C22: Bevmax run subtotal
A23: Deposit required (50%, 4 wks pre-prod) | B23: 24552.87
A24: Cans produced | B24: ='Cost Build-up'!D6
A25: Cases produced | B25: ='Cost Build-up'!D11
A26: Cases sold (plan) | B26: ='TTL ORGANIKA RTD'!M9
A27: Sell-through % | B27: =IFERROR(B26/B25,"-")
A28: Ending inventory (cases) | B28: =B25-B26 | E28: Months stored | F28: 6
A29: Ending inventory value @ COGS | B29: =B28*'Cost Build-up'!$D$46 | E29: Free months | F29: 3
A30: Est. surplus warehousing cost | B30: =MAX(0,(F28-F29))*ROUNDUP(B28/F30,0)*F31 | E30: Cases / pallet | F30: 60
E31: Warehousing $/pallet/mo | F31: 100
A33: CATEGORY BENCHMARK & CANNIBALIZATION
A34: Category average GM% (benchmark) | B34: 0.55
A35: Our blended GP% | B35: ='TTL ORGANIKA RTD'!M17
A36: vs category (pts) | B36: =B35-B34
A37: Cannibalization rate (% of our volume) | B37: 0.2
A38: Existing-SKU CAAP / case (lost) | B38: 20
A39: Cannibalized cases | B39: =B14*B37
A40: Lost CAAP (cannibalized) | B40: =B39*B38
A41: Net incremental CAAP (after cannib.) | B41: =B18-B40
A43: BEST / BASE / WORST CASE
A44: Driver | B44: Worst | C44: Base | D44: Best
A45: CP / case (wholesale) | B45: 60 | C45: 72 | D45: 84 | E45: Worst COGS +% | G45: 0.15
...

Sheet Assumptions
A1: ORGANIKA RTD — ASSUMPTIONS (control panel)
A2: 🟡 Type in yellow cells. Start with the Master price (top-right) — that's all you need. CDN $ per case (24 cans).
A4: GLOBAL | E4: ▶ QUICK START — one price for every channel
A5: Period start | C5: Aug 1, 2026 | E5: Master CP ($/case) | G5: 72
A6: Period end | C6: Nov 1, 2026 | E6: Master MSRP ($/case) | G6: 108
A7: Cans per case | C7: 24 | E7: Master discount (%) | G7: 0
A8: Four-packs per case | C8: 6 | E8: Master A&P (% of net) | G8: 0.08
A9: Minimum GM% (gate) | C9: 0.5 | E9: ↳ Channels inherit these. Type over any single channel below to override it.
A10: Target GM% | C10: 0.6
A11: A&P split — Consumer % | C11: 0.5 | D11: sum → | E11: =C11+C12+C13
A12: A&P split — Trade % | C12: 0.3
A13: A&P split — Sales % | C13: 0.2
A15: VOLUME — total cases per flavour (whole period)
A16: Lime Lemon | C16: 500
A17: Passion Fruit Pineapple | C17: 500
A18: Raspberry | C18: 500
A19: TOTAL cases | C19: =SUM(C16:C18)
A21: CHANNEL MIX & (optional) per-channel price overrides
A22: Channel | B22: CP $/case | C22: MSRP $/case | D22: Disc % | E22: A&P % net | F22: Mix % 🟡 | G22: CP /4-pack | H22: Cust margin % | I22: Cases (all SKUs)
A23: Shopify | B23: =$G$5 | C23: =$G$6 | D23: =$G$7 | E23: =$G$8 | F23: 0.12 | G23: =B23/$C$8 | H23: =IFERROR((C23-B23)/C23,"-") | I23: =F23*$C$19
A24: Amazon | B24: =$G$5 | C24: =$G$6 | D24: =$G$7 | E24: =$G$8 | F24: 0.1 | G24: =B24/$C$8 | H24: =IFERROR((C24-B24)/C24,"-") | I24: =F24*$C$19
A25: On-premise | B25: =$G$5 | C25: =$G$6 | D25: =$G$7 | E25: =$G$8 | F25: 0.06 | G25: =B25/$C$8 | H25: =IFERROR((C25-B25)/C25,"-") | I25: =F25*$C$19
A26: Retail | B26: =$G$5 | C26: =$G$6 | D26: =$G$7 | E26: =$G$8 | F26: 0.18 | G26: =B26/$C$8 | H26: =IFERROR((C26-B26)/C26,"-") | I26: =F26*$C$19
A27: Distributor | B27: =$G$5 | C27: =$G$6 | D27: =$G$7 | E27: =$G$8 | F27: 0.2 | G27: =B27/$C$8 | H27: =IFERROR((C27-B27)/C27,"-") | I27: =F27*$C$19
A28: Corporate Office | B28: =$G$5 | C28: =$G$6 | D28: =$G$7 | E28: =$G$8 | F28: 0.02 | G28: =B28/$C$8 | H28: =IFERROR((C28-B28)/C28,"-") | I28: =F28*$C$19
A29: Purity Life | B29: =$G$5 | C29: =$G$6 | D29: =$G$7 | E29: =$G$8 | F29: 0.08 | G29: =B29/$C$8 | H29: =IFERROR((C29-B29)/C29,"-") | I29: =F29*$C$19
A30: Natural & Specialty Direct | B30: =$G$5 | C30: =$G$6 | D30: =$G$7 | E30: =$G$8 | F30: 0.1 | G30: =B30/$C$8 | H30: =IFERROR((C30-B30)/C30,"-") | I30: =F30*$C$19
A31: FDM Direct | B31: =$G$5 | C31: =$G$6 | D31: =$G$7 | E31: =$G$8 | F31: 0.08 | G31: =B31/$C$8 | H31: =IFERROR((C31-B31)/C31,"-") | I31: =F31*$C$19
A32: Convenience | B32: =$G$5 | C32: =$G$6 | D32: =$G$7 | E32: =$G$8 | F32: 0.04 | G32: =B32/$C$8 | H32: =IFERROR((C32-B32)/C32,"-") | I32: =F32*$C$19
A33: Fitness Centre | B33: =$G$5 | C33: =$G$6 | D33: =$G$7 | E33: =$G$8 | F33: 0.02 | G33: =B33/$C$8 | H33: =IFERROR((C33-B33)/C33,"-") | I33: =F33*$C$19
A34: TOTAL | F34: =SUM(F23:F33) | I34: =SUM(I23:I33)
A36: CHECKS
A37: Channel mix sums to 100% | C37: =IF(ABS(F34-1)<0.005,"✓ 100%","✗ "&TEXT(F34,"0.0%"))
A38: Blended GP% (live) | C38: ='TTL ORGANIKA RTD'!M17
A39: GP% ≥ minimum? | C39: =IF(C38>=C9,"✓ ≥ "&TEXT(C9,"0%"),"✗ below min")
A40: GP% ≥ target? | C40: =IF(C38>=C10,"✓ ≥ "&TEXT(C10,"0%"),"– below target")
A41: Total CAAP > 0? | C41: =IF('TTL ORGANIKA RTD'!M24>0,"✓","✗")

Sheet Dashboard
A1: ORGANIKA RTD — DASHBOARD
A2: CDN $ | 6×4×355 ml (24 cans/case) | Aug 1 – Nov 1, 2026 | 3 SKUs × 11 channels
A4: TOTAL P&L — ALL SKUs × ALL CHANNELS | D4: BLENDED — PER CASE
A5: Physical Cases | B5: ='TTL ORGANIKA RTD'!M9 | D5: Gross Rev / case | E5: ='TTL ORGANIKA RTD'!M26
A6: Gross Revenue | B6: ='TTL ORGANIKA RTD'!M10 | D6: Discounts / case | E6: ='TTL ORGANIKA RTD'!M27
A7: Discounts | B7: ='TTL ORGANIKA RTD'!M11 | D7: Net Sales / case | E7: ='TTL ORGANIKA RTD'!M28
A8: Net Sales | B8: ='TTL ORGANIKA RTD'!M12 | D8: COGS / case | E8: ='TTL ORGANIKA RTD'!M31
A9: Cost of Sales | B9: ='TTL ORGANIKA RTD'!M15 | D9: Gross Profit / case | E9: ='TTL ORGANIKA RTD'!M32
A10: Gross Profit | B10: ='TTL ORGANIKA RTD'!M16 | D10: GP % | E10: ='TTL ORGANIKA RTD'!M33
A11: GP % | B11: ='TTL ORGANIKA RTD'!M17 | D11: A&P / case | E11: ='TTL ORGANIKA RTD'!M34
A12: A&P | B12: ='TTL ORGANIKA RTD'!M22 | D12: CAAP / case | E12: ='TTL ORGANIKA RTD'!M35
A13: CAAP | B13: ='TTL ORGANIKA RTD'!M24
A15: BY SKU
A16: SKU | B16: Cases | C16: Net Sales | D16: Gross Profit | E16: GP % | F16: A&P | G16: CAAP
A17: Lime Lemon | B17: ='Lime Lemon'!M9 | C17: ='Lime Lemon'!M12 | D17: ='Lime Lemon'!M16 | E17: ='Lime Lemon'!M17 | F17: ='Lime Lemon'!M22 | G17: ='Lime Lemon'!M24
A18: Passion Fruit Pineapple | B18: ='Passion Fruit Pineapple'!M9 | C18: ='Passion Fruit Pineapple'!M12 | D18: ='Passion Fruit Pineapple'!M16 | E18: ='Passion Fruit Pineapple'!M17 | F18: ='Passion Fruit Pineapple'!M22 | G18: ='Passion Fruit Pineapple'!M24
A19: Raspberry | B19: ='Raspberry'!M9 | C19: ='Raspberry'!M12 | D19: ='Raspberry'!M16 | E19: ='Raspberry'!M17 | F19: ='Raspberry'!M22 | G19: ='Raspberry'!M24
A20: TOTAL | B20: ='TTL ORGANIKA RTD'!M9 | C20: ='TTL ORGANIKA RTD'!M12 | D20: ='TTL ORGANIKA RTD'!M16 | E20: ='TTL ORGANIKA RTD'!M17 | F20: ='TTL ORGANIKA RTD'!M22 | G20: ='TTL ORGANIKA RTD'!M24
A22: BY CHANNEL
A23: Channel | B23: Cases | C23: Net Sales | D23: Gross Profit | E23: GP % | F23: A&P | G23: CAAP
A24: Shopify | B24: ='TTL ORGANIKA RTD'!B9 | C24: ='TTL ORGANIKA RTD'!B12 | D24: ='TTL ORGANIKA RTD'!B16 | E24: ='TTL ORGANIKA RTD'!B17 | F24: ='TTL ORGANIKA RTD'!B22 | G24: ='TTL ORGANIKA RTD'!B24
A25: Amazon | B25: ='TTL ORGANIKA RTD'!C9 | C25: ='TTL ORGANIKA RTD'!C12 | D25: ='TTL ORGANIKA RTD'!C16 | E25: ='TTL ORGANIKA RTD'!C17 | F25: ='TTL ORGANIKA RTD'!C22 | G25: ='TTL ORGANIKA RTD'!C24
A26: On-premise | B26: ='TTL ORGANIKA RTD'!D9 | C26: ='TTL ORGANIKA RTD'!D12 | D26: ='TTL ORGANIKA RTD'!D16 | E26: ='TTL ORGANIKA RTD'!D17 | F26: ='TTL ORGANIKA RTD'!D22 | G26: ='TTL ORGANIKA RTD'!D24
A27: Retail | B27: ='TTL ORGANIKA RTD'!E9 | C27: ='TTL ORGANIKA RTD'!E12 | D27: ='TTL ORGANIKA RTD'!E16 | E27: ='TTL ORGANIKA RTD'!E17 | F27: ='TTL ORGANIKA RTD'!E22 | G27: ='TTL ORGANIKA RTD'!E24
A28: Distributor | B28: ='TTL ORGANIKA RTD'!F9 | C28: ='TTL ORGANIKA RTD'!F12 | D28: ='TTL ORGANIKA RTD'!F16 | E28: ='TTL ORGANIKA RTD'!F17 | F28: ='TTL ORGANIKA RTD'!F22 | G28: ='TTL ORGANIKA RTD'!F24
A29: Corporate Office | B29: ='TTL ORGANIKA RTD'!G9 | C29: ='TTL ORGANIKA RTD'!G12 | D29: ='TTL ORGANIKA RTD'!G16 | E29: ='TTL ORGANIKA RTD'!G17 | F29: ='TTL ORGANIKA RTD'!G22 | G29: ='TTL ORGANIKA RTD'!G24
A30: Purity Life | B30: ='TTL ORGANIKA RTD'!H9 | C30: ='TTL ORGANIKA RTD'!H12 | D30: ='TTL ORGANIKA RTD'!H16 | E30: ='TTL ORGANIKA RTD'!H17 | F30: ='TTL ORGANIKA RTD'!H22 | G30: ='TTL ORGANIKA RTD'!H24
A31: Natural & Specialty Direct | B31: ='TTL ORGANIKA RTD'!I9 | C31: ='TTL ORGANIKA RTD'!I12 | D31: ='TTL ORGANIKA RTD'!I16 | E31: ='TTL ORGANIKA RTD'!I17 | F31: ='TTL ORGANIKA RTD'!I22 | G31: ='TTL ORGANIKA RTD'!I24
A32: FDM Direct | B32: ='TTL ORGANIKA RTD'!J9 | C32: ='TTL ORGANIKA RTD'!J12 | D32: ='TTL ORGANIKA RTD'!J16 | E32: ='TTL ORGANIKA RTD'!J17 | F32: ='TTL ORGANIKA RTD'!J22 | G32: ='TTL ORGANIKA RTD'!J24
A33: Convenience | B33: ='TTL ORGANIKA RTD'!K9 | C33: ='TTL ORGANIKA RTD'!K12 | D33: ='TTL ORGANIKA RTD'!K16 | E33: ='TTL ORGANIKA RTD'!K17 | F33: ='TTL ORGANIKA RTD'!K22 | G33: ='TTL ORGANIKA RTD'!K24
A34: Fitness Centre | B34: ='TTL ORGANIKA RTD'!L9 | C34: ='TTL ORGANIKA RTD'!L12 | D34: ='TTL ORGANIKA RTD'!L16 | E34: ='TTL ORGANIKA RTD'!L17 | F34: ='TTL ORGANIKA RTD'!L22 | G34: ='TTL ORGANIKA RTD'!L24
A35: TOTAL | B35: ='TTL ORGANIKA RTD'!M9 | C35: ='TTL ORGANIKA RTD'!M12 | D35: ='TTL ORGANIKA RTD'!M16 | E35: ='TTL ORGANIKA RTD'!M17 | F35: ='TTL ORGANIKA RTD'!M22 | G35: ='TTL ORGANIKA RTD'!M24

Sheet Scenarios
A1: ORGANIKA RTD — SCENARIOS & PRICE SENSITIVITY
A2: CDN $ per case (24 cans = 6 × 4-pack) | 🟡 yellow = edit | COGS pulled live from Cost Build-up ($D$46)
A4: SCENARIO COMPARISON (CP = wholesale price, MSRP = shelf price)
A5: Scenario | B5: Conservative | C5: Base | D5: Stretch | E5: Scenario 4 | F5: Scenario 5
A6: CP — wholesale ($/case) | B6: 54 | C6: 60 | D6: 66
A7: MSRP — retail ($/case) | B7: 84 | C7: 96 | D7: 108
A8: Promo / discount (% off CP) | B8: 0 | C8: 0 | D8: 0
A9: Volume (cases) | B9: 500 | C9: 500 | D9: 500
A10: A&P ($/case) | B10: 0 | C10: 0 | D10: 0
A11: Net price ($/case) | B11: =B6*(1-B8) | C11: =C6*(1-C8) | D11: =D6*(1-D8) | E11: =E6*(1-E8) | F11: =F6*(1-F8)
A12: COGS ($/case) | B12: ='Cost Build-up'!$D$46 | C12: ='Cost Build-up'!$D$46 | D12: ='Cost Build-up'!$D$46 | E12: ='Cost Build-up'!$D$46 | F12: ='Cost Build-up'!$D$46
A13: Organika GP ($/case) | B13: =B11-B12 | C13: =C11-C12 | D13: =D11-D12 | E13: =E11-E12 | F13: =F11-F12
A14: Organika GP % | B14: =IFERROR(B13/B11,"-") | C14: =IFERROR(C13/C11,"-") | D14: =IFERROR(D13/D11,"-") | E14: =IFERROR(E13/E11,"-") | F14: =IFERROR(F13/F11,"-")
A15: Customer margin % | B15: =IFERROR((B7-B6)/B7,"-") | C15: =IFERROR((C7-C6)/C7,"-") | D15: =IFERROR((D7-D6)/D7,"-") | E15: =IFERROR((E7-E6)/E7,"-") | F15: =IFERROR((F7-F6)/F7,"-")
A16: CAAP ($/case) | B16: =B13-B10 | C16: =C13-C10 | D16: =D13-D10 | E16: =E13-E10 | F16: =F13-F10
A17: — per-pack & period —
A18: CP / 4-pack | B18: =B6/6 | C18: =C6/6 | D18: =D6/6 | E18: =E6/6 | F18: =F6/6
A19: MSRP / 4-pack | B19: =B7/6 | C19: =C7/6 | D19: =D7/6 | E19: =E7/6 | F19: =F7/6
A20: Net sales — period ($) | B20: =B11*B9 | C20: =C11*C9 | D20: =D11*D9 | E20: =E11*E9 | F20: =F11*F9
A21: Gross profit — period ($) | B21: =B13*B9 | C21: =C13*C9 | D21: =D13*D9 | E21: =E13*E9 | F21: =F13*F9
A22: CAAP — period ($) | B22: =B16*B9 | C22: =C16*C9 | D22: =D16*D9 | E22: =E16*E9 | F22: =F16*F9
A24: PRICE SENSITIVITY — Organika margin as CP varies
A25: CP start ($/case) | B25: 48 | C25: step ($) | D25: 4 | E25: ref MSRP ($/case) | F25: 96 | G25: promo % | H25: 0
A26: CP /case | B26: CP /4-pack | C26: Net /case | D26: COGS /case | E26: GP /case | F26: GP % | G26: Cust margin %
A27: =$B$25+0*$D$25 | B27: =A27/6 | C27: =A27*(1-$H$25) | D27: ='Cost Build-up'!$D$46 | E27: =C27-D27 | F27: =IFERROR(E27/C27,"-") | G27: =IFERROR(($F$25-A27)/$F$25,"-")
A28: =$B$25+1*$D$25 | B28: =A28/6 | C28: =A28*(1-$H$25) | D28: ='Cost Build-up'!$D$46 | E28: =C28-D28 | F28: =IFERROR(E28/C28,"-") | G28: =IFERROR(($F$25-A28)/$F$25,"-")
A29: =$B$25+2*$D$25 | B29: =A29/6 | C29: =A29*(1-$H$25) | D29: ='Cost Build-up'!$D$46 | E29: =C29-D29 | F29: =IFERROR(E29/C29,"-") | G29: =IFERROR(($F$25-A29)/$F$25,"-")
A30: =$B$25+3*$D$25 | B30: =A30/6 | C30: =A30*(1-$H$25) | D30: ='Cost Build-up'!$D$46 | E30: =C30-D30 | F30: =IFERROR(E30/C30,"-") | G30: =IFERROR(($F$25-A30)/$F$25,"-")
A31: =$B$25+4*$D$25 | B31: =A31/6 | C31: =A31*(1-$H$25) | D31: ='Cost Build-up'!$D$46 | E31: =C31-D31 | F31: =IFERROR(E31/C31,"-") | G31: =IFERROR(($F$25-A31)/$F$25,"-")
A32: =$B$25+5*$D$25 | B32: =A32/6 | C32: =A32*(1-$H$25) | D32: ='Cost Build-up'!$D$46 | E32: =C32-D32 | F32: =IFERROR(E32/C32,"-") | G32: =IFERROR(($F$25-A32)/$F$25,"-")
A33: =$B$25+6*$D$25 | B33: =A33/6 | C33: =A33*(1-$H$25) | D33: ='Cost Build-up'!$D$46 | E33: =C33-D33 | F33: =IFERROR(E33/C33,"-") | G33: =IFERROR(($F$25-A33)/$F$25,"-")
A34: =$B$25+7*$D$25 | B34: =A34/6 | C34: =A34*(1-$H$25) | D34: ='Cost Build-up'!$D$46 | E34: =C34-D34 | F34: =IFERROR(E34/C34,"-") | G34: =IFERROR(($F$25-A34)/$F$25,"-")
A35: =$B$25+8*$D$25 | B35: =A35/6 | C35: =A35*(1-$H$25) | D35: ='Cost Build-up'!$D$46 | E35: =C35-D35 | F35: =IFERROR(E35/C35,"-") | G35: =IFERROR(($F$25-A35)/$F$25,"-")
A36: =$B$25+9*$D$25 | B36: =A36/6 | C36: =A36*(1-$H$25) | D36: ='Cost Build-up'!$D$46 | E36: =C36-D36 | F36: =IFERROR(E36/C36,"-") | G36: =IFERROR(($F$25-A36)/$F$25,"-")
A39: CUSTOMER (RETAILER) MARGIN % — CP (down) × MSRP (across)
A40: CP ↓ / MSRP → | B40: 84 | C40: 90 | D40: 96 | E40: 102 | F40: 108 | G40: 114 | H40: 120
A41: =$B$25+0*$D$25 | B41: =IFERROR((B$40-$A41)/B$40,"-") | C41: =IFERROR((C$40-$A41)/C$40,"-") | D41: =IFERROR((D$40-$A41)/D$40,"-") | E41: =IFERROR((E$40-$A41)/E$40,"-") | F41: =IFERROR((F$40-$A41)/F$40,"-") | G41: =IFERROR((G$40-$A41)/G$40,"-") | H41: =IFERROR((H$40-$A41)/H$40,"-")
A42: =$B$25+1*$D$25 | B42: =IFERROR((B$40-$A42)/B$40,"-") | C42: =IFERROR((C$40-$A42)/C$40,"-") | D42: =IFERROR((D$40-$A42)/D$40,"-") | E42: =IFERROR((E$40-$A42)/E$40,"-") | F42: =IFERROR((F$40-$A42)/F$40,"-") | G42: =IFERROR((G$40-$A42)/G$40,"-") | H42: =IFERROR((H$40-$A42)/H$40,"-")
A43: =$B$25+2*$D$25 | B43: =IFERROR((B$40-$A43)/B$40,"-") | C43: =IFERROR((C$40-$A43)/C$40,"-") | D43: =IFERROR((D$40-$A43)/D$40,"-") | E43: =IFERROR((E$40-$A43)/E$40,"-") | F43: =IFERROR((F$40-$A43)/F$40,"-") | G43: =IFERROR((G$40-$A43)/G$40,"-") | H43: =IFERROR((H$40-$A43)/H$40,"-")
A44: =$B$25+3*$D$25 | B44: =IFERROR((B$40-$A44)/B$40,"-") | C44: =IFERROR((C$40-$A44)/C$40,"-") | D44: =IFERROR((D$40-$A44)/D$40,"-") | E44: =IFERROR((E$40-$A44)/E$40,"-") | F44: =IFERROR((F$40-$A44)/F$40,"-") | G44: =IFERROR((G$40-$A44)/G$40,"-") | H44: =IFERROR((H$40-$A44)/H$40,"-")
...

Sheet Blended
A1: ORGANIKA RTD — BLENDED (all channels)
A2: CDN $ | Volume-weighted average across all 11 channels | per case = 24 cans | Aug 1 – Nov 1, 2026
A4: CDN $ | B4: Lime Lemon | C4: Passion Fruit Pineapple | D4: Raspberry | E4: TOTAL
A6: PERIOD TOTALS (Aug 1 – Nov 1)
A7: Physical Cases | B7: ='Lime Lemon'!M9 | C7: ='Passion Fruit Pineapple'!M9 | D7: ='Raspberry'!M9 | E7: ='TTL ORGANIKA RTD'!M9
A8: Gross Revenue | B8: ='Lime Lemon'!M10 | C8: ='Passion Fruit Pineapple'!M10 | D8: ='Raspberry'!M10 | E8: ='TTL ORGANIKA RTD'!M10
A9: Discounts | B9: ='Lime Lemon'!M11 | C9: ='Passion Fruit Pineapple'!M11 | D9: ='Raspberry'!M11 | E9: ='TTL ORGANIKA RTD'!M11
A10: Net Sales | B10: ='Lime Lemon'!M12 | C10: ='Passion Fruit Pineapple'!M12 | D10: ='Raspberry'!M12 | E10: ='TTL ORGANIKA RTD'!M12
A11: COGS Direct | B11: ='Lime Lemon'!M13 | C11: ='Passion Fruit Pineapple'!M13 | D11: ='Raspberry'!M13 | E11: ='TTL ORGANIKA RTD'!M13
A12: COGS Indirect | B12: ='Lime Lemon'!M14 | C12: ='Passion Fruit Pineapple'!M14 | D12: ='Raspberry'!M14 | E12: ='TTL ORGANIKA RTD'!M14
A13: Cost of Sales | B13: ='Lime Lemon'!M15 | C13: ='Passion Fruit Pineapple'!M15 | D13: ='Raspberry'!M15 | E13: ='TTL ORGANIKA RTD'!M15
A14: Gross Profit | B14: ='Lime Lemon'!M16 | C14: ='Passion Fruit Pineapple'!M16 | D14: ='Raspberry'!M16 | E14: ='TTL ORGANIKA RTD'!M16
A15: GP % | B15: ='Lime Lemon'!M17 | C15: ='Passion Fruit Pineapple'!M17 | D15: ='Raspberry'!M17 | E15: ='TTL ORGANIKA RTD'!M17
A16: A&P | B16: ='Lime Lemon'!M22 | C16: ='Passion Fruit Pineapple'!M22 | D16: ='Raspberry'!M22 | E16: ='TTL ORGANIKA RTD'!M22
A17: Contrib After A&P (CAAP) | B17: ='Lime Lemon'!M24 | C17: ='Passion Fruit Pineapple'!M24 | D17: ='Raspberry'!M24 | E17: ='TTL ORGANIKA RTD'!M24
A19: BLENDED PER CASE (avg across channels)
A20: Gross Rev / case | B20: ='Lime Lemon'!M26 | C20: ='Passion Fruit Pineapple'!M26 | D20: ='Raspberry'!M26 | E20: ='TTL ORGANIKA RTD'!M26
A21: Discounts / case | B21: ='Lime Lemon'!M27 | C21: ='Passion Fruit Pineapple'!M27 | D21: ='Raspberry'!M27 | E21: ='TTL ORGANIKA RTD'!M27
A22: Net Sales / case | B22: ='Lime Lemon'!M28 | C22: ='Passion Fruit Pineapple'!M28 | D22: ='Raspberry'!M28 | E22: ='TTL ORGANIKA RTD'!M28
A23: COGS / case | B23: ='Lime Lemon'!M31 | C23: ='Passion Fruit Pineapple'!M31 | D23: ='Raspberry'!M31 | E23: ='TTL ORGANIKA RTD'!M31
A24: Gross Profit / case | B24: ='Lime Lemon'!M32 | C24: ='Passion Fruit Pineapple'!M32 | D24: ='Raspberry'!M32 | E24: ='TTL ORGANIKA RTD'!M32
A25: GP % | B25: ='Lime Lemon'!M33 | C25: ='Passion Fruit Pineapple'!M33 | D25: ='Raspberry'!M33 | E25: ='TTL ORGANIKA RTD'!M33
A26: A&P / case | B26: ='Lime Lemon'!M34 | C26: ='Passion Fruit Pineapple'!M34 | D26: ='Raspberry'!M34 | E26: ='TTL ORGANIKA RTD'!M34
A27: CAAP / case | B27: ='Lime Lemon'!M35 | C27: ='Passion Fruit Pineapple'!M35 | D27: ='Raspberry'!M35 | E27: ='TTL ORGANIKA RTD'!M35

Sheet TTL ORGANIKA RTD
A1: ORGANIKA RTD — TOTAL (3 SKUs)
A2: CDN $ | Per case of 24 cans (6×4×355 ml) | Period: Aug 1 – Nov 1, 2026
A4: CDN $ | B4: Shopify | C4: Amazon | D4: On-premise | E4: Retail | F4: Distributor | G4: Corporate Office | H4: Purity Life | I4: Natural & Specialty Direct | J4: FDM Direct | K4: Convenience | L4: Fitness Centre | M4: Total
A6: ⚫ Roll-up of the three SKU tabs — all formulas
A8: Organika RTD — All SKUs (Lime Lemon + Passion Fruit Pineapple + Raspberry)
A9: Physical Cases | B9: ='Lime Lemon'!B9+'Passion Fruit Pineapple'!B9+'Raspberry'!B9 | C9: ='Lime Lemon'!C9+'Passion Fruit Pineapple'!C9+'Raspberry'!C9 | D9: ='Lime Lemon'!D9+'Passion Fruit Pineapple'!D9+'Raspberry'!D9 | E9: ='Lime Lemon'!E9+'Passion Fruit Pineapple'!E9+'Raspberry'!E9 | F9: ='Lime Lemon'!F9+'Passion Fruit Pineapple'!F9+'Raspberry'!F9 | G9: ='Lime Lemon'!G9+'Passion Fruit Pineapple'!G9+'Raspberry'!G9 | H9: ='Lime Lemon'!H9+'Passion Fruit Pineapple'!H9+'Raspberry'!H9 | I9: ='Lime Lemon'!I9+'Passion Fruit Pineapple'!I9+'Raspberry'!I9 | ... L9: ='Lime Lemon'!L9+'Passion Fruit Pineapple'!L9+'Raspberry'!L9 | M9: =SUM(B9:L9)
A10: Gross Revenue | B10: ='Lime Lemon'!B10+'Passion Fruit Pineapple'!B10+'Raspberry'!B10 | C10: ='Lime Lemon'!C10+'Passion Fruit Pineapple'!C10+'Raspberry'!C10 | D10: ='Lime Lemon'!D10+'Passion Fruit Pineapple'!D10+'Raspberry'!D10 | E10: ='Lime Lemon'!E10+'Passion Fruit Pineapple'!E10+'Raspberry'!E10 | F10: ='Lime Lemon'!F10+'Passion Fruit Pineapple'!F10+'Raspberry'!F10 | G10: ='Lime Lemon'!G10+'Passion Fruit Pineapple'!G10+'Raspberry'!G10 | H10: ='Lime Lemon'!H10+'Passion Fruit Pineapple'!H10+'Raspberry'!H10 | I10: ='Lime Lemon'!I10+'Passion Fruit Pineapple'!I10+'Raspberry'!I10 | ... L10: ='Lime Lemon'!L10+'Passion Fruit Pineapple'!L10+'Raspberry'!L10 | M10: =SUM(B10:L10)
A11: Discounts | B11: ='Lime Lemon'!B11+'Passion Fruit Pineapple'!B11+'Raspberry'!B11 | C11: ='Lime Lemon'!C11+'Passion Fruit Pineapple'!C11+'Raspberry'!C11 | D11: ='Lime Lemon'!D11+'Passion Fruit Pineapple'!D11+'Raspberry'!D11 | E11: ='Lime Lemon'!E11+'Passion Fruit Pineapple'!E11+'Raspberry'!E11 | F11: ='Lime Lemon'!F11+'Passion Fruit Pineapple'!F11+'Raspberry'!F11 | G11: ='Lime Lemon'!G11+'Passion Fruit Pineapple'!G11+'Raspberry'!G11 | H11: ='Lime Lemon'!H11+'Passion Fruit Pineapple'!H11+'Raspberry'!H11 | I11: ='Lime Lemon'!I11+'Passion Fruit Pineapple'!I11+'Raspberry'!I11 | ... L11: ='Lime Lemon'!L11+'Passion Fruit Pineapple'!L11+'Raspberry'!L11 | M11: =SUM(B11:L11)
A12: Net Sales | B12: ='Lime Lemon'!B12+'Passion Fruit Pineapple'!B12+'Raspberry'!B12 | C12: ='Lime Lemon'!C12+'Passion Fruit Pineapple'!C12+'Raspberry'!C12 | D12: ='Lime Lemon'!D12+'Passion Fruit Pineapple'!D12+'Raspberry'!D12 | E12: ='Lime Lemon'!E12+'Passion Fruit Pineapple'!E12+'Raspberry'!E12 | F12: ='Lime Lemon'!F12+'Passion Fruit Pineapple'!F12+'Raspberry'!F12 | G12: ='Lime Lemon'!G12+'Passion Fruit Pineapple'!G12+'Raspberry'!G12 | H12: ='Lime Lemon'!H12+'Passion Fruit Pineapple'!H12+'Raspberry'!H12 | I12: ='Lime Lemon'!I12+'Passion Fruit Pineapple'!I12+'Raspberry'!I12 | ... L12: ='Lime Lemon'!L12+'Passion Fruit Pineapple'!L12+'Raspberry'!L12 | M12: =SUM(B12:L12)
A13: COGS Direct | B13: ='Lime Lemon'!B13+'Passion Fruit Pineapple'!B13+'Raspberry'!B13 | C13: ='Lime Lemon'!C13+'Passion Fruit Pineapple'!C13+'Raspberry'!C13 | D13: ='Lime Lemon'!D13+'Passion Fruit Pineapple'!D13+'Raspberry'!D13 | E13: ='Lime Lemon'!E13+'Passion Fruit Pineapple'!E13+'Raspberry'!E13 | F13: ='Lime Lemon'!F13+'Passion Fruit Pineapple'!F13+'Raspberry'!F13 | G13: ='Lime Lemon'!G13+'Passion Fruit Pineapple'!G13+'Raspberry'!G13 | H13: ='Lime Lemon'!H13+'Passion Fruit Pineapple'!H13+'Raspberry'!H13 | I13: ='Lime Lemon'!I13+'Passion Fruit Pineapple'!I13+'Raspberry'!I13 | ... L13: ='Lime Lemon'!L13+'Passion Fruit Pineapple'!L13+'Raspberry'!L13 | M13: =SUM(B13:L13)
A14: COGS Indirect | B14: ='Lime Lemon'!B14+'Passion Fruit Pineapple'!B14+'Raspberry'!B14 | C14: ='Lime Lemon'!C14+'Passion Fruit Pineapple'!C14+'Raspberry'!C14 | D14: ='Lime Lemon'!D14+'Passion Fruit Pineapple'!D14+'Raspberry'!D14 | E14: ='Lime Lemon'!E14+'Passion Fruit Pineapple'!E14+'Raspberry'!E14 | F14: ='Lime Lemon'!F14+'Passion Fruit Pineapple'!F14+'Raspberry'!F14 | G14: ='Lime Lemon'!G14+'Passion Fruit Pineapple'!G14+'Raspberry'!G14 | H14: ='Lime Lemon'!H14+'Passion Fruit Pineapple'!H14+'Raspberry'!H14 | I14: ='Lime Lemon'!I14+'Passion Fruit Pineapple'!I14+'Raspberry'!I14 | ... L14: ='Lime Lemon'!L14+'Passion Fruit Pineapple'!L14+'Raspberry'!L14 | M14: =SUM(B14:L14)
A15: Cost of Sales | B15: ='Lime Lemon'!B15+'Passion Fruit Pineapple'!B15+'Raspberry'!B15 | C15: ='Lime Lemon'!C15+'Passion Fruit Pineapple'!C15+'Raspberry'!C15 | D15: ='Lime Lemon'!D15+'Passion Fruit Pineapple'!D15+'Raspberry'!D15 | E15: ='Lime Lemon'!E15+'Passion Fruit Pineapple'!E15+'Raspberry'!E15 | F15: ='Lime Lemon'!F15+'Passion Fruit Pineapple'!F15+'Raspberry'!F15 | G15: ='Lime Lemon'!G15+'Passion Fruit Pineapple'!G15+'Raspberry'!G15 | H15: ='Lime Lemon'!H15+'Passion Fruit Pineapple'!H15+'Raspberry'!H15 | I15: ='Lime Lemon'!I15+'Passion Fruit Pineapple'!I15+'Raspberry'!I15 | ... L15: ='Lime Lemon'!L15+'Passion Fruit Pineapple'!L15+'Raspberry'!L15 | M15: =SUM(B15:L15)
A16: Gross Profit | B16: ='Lime Lemon'!B16+'Passion Fruit Pineapple'!B16+'Raspberry'!B16 | C16: ='Lime Lemon'!C16+'Passion Fruit Pineapple'!C16+'Raspberry'!C16 | D16: ='Lime Lemon'!D16+'Passion Fruit Pineapple'!D16+'Raspberry'!D16 | E16: ='Lime Lemon'!E16+'Passion Fruit Pineapple'!E16+'Raspberry'!E16 | F16: ='Lime Lemon'!F16+'Passion Fruit Pineapple'!F16+'Raspberry'!F16 | G16: ='Lime Lemon'!G16+'Passion Fruit Pineapple'!G16+'Raspberry'!G16 | H16: ='Lime Lemon'!H16+'Passion Fruit Pineapple'!H16+'Raspberry'!H16 | I16: ='Lime Lemon'!I16+'Passion Fruit Pineapple'!I16+'Raspberry'!I16 | ... L16: ='Lime Lemon'!L16+'Passion Fruit Pineapple'!L16+'Raspberry'!L16 | M16: =SUM(B16:L16)
A17: GP % | B17: =IFERROR(B16/B12,"-") | C17: =IFERROR(C16/C12,"-") | D17: =IFERROR(D16/D12,"-") | E17: =IFERROR(E16/E12,"-") | F17: =IFERROR(F16/F12,"-") | G17: =IFERROR(G16/G12,"-") | H17: =IFERROR(H16/H12,"-") | I17: =IFERROR(I16/I12,"-") | ... M17: =IFERROR(M16/M12,"-")
A19: A&P Consumer | B19: ='Lime Lemon'!B19+'Passion Fruit Pineapple'!B19+'Raspberry'!B19 | C19: ='Lime Lemon'!C19+'Passion Fruit Pineapple'!C19+'Raspberry'!C19 | D19: ='Lime Lemon'!D19+'Passion Fruit Pineapple'!D19+'Raspberry'!D19 | E19: ='Lime Lemon'!E19+'Passion Fruit Pineapple'!E19+'Raspberry'!E19 | F19: ='Lime Lemon'!F19+'Passion Fruit Pineapple'!F19+'Raspberry'!F19 | G19: ='Lime Lemon'!G19+'Passion Fruit Pineapple'!G19+'Raspberry'!G19 | H19: ='Lime Lemon'!H19+'Passion Fruit Pineapple'!H19+'Raspberry'!H19 | I19: ='Lime Lemon'!I19+'Passion Fruit Pineapple'!I19+'Raspberry'!I19 | ... L19: ='Lime Lemon'!L19+'Passion Fruit Pineapple'!L19+'Raspberry'!L19 | M19: =SUM(B19:L19)
A20: A&P Trade | B20: ='Lime Lemon'!B20+'Passion Fruit Pineapple'!B20+'Raspberry'!B20 | C20: ='Lime Lemon'!C20+'Passion Fruit Pineapple'!C20+'Raspberry'!C20 | D20: ='Lime Lemon'!D20+'Passion Fruit Pineapple'!D20+'Raspberry'!D20 | E20: ='Lime Lemon'!E20+'Passion Fruit Pineapple'!E20+'Raspberry'!E20 | F20: ='Lime Lemon'!F20+'Passion Fruit Pineapple'!F20+'Raspberry'!F20 | G20: ='Lime Lemon'!G20+'Passion Fruit Pineapple'!G20+'Raspberry'!G20 | H20: ='Lime Lemon'!H20+'Passion Fruit Pineapple'!H20+'Raspberry'!H20 | I20: ='Lime Lemon'!I20+'Passion Fruit Pineapple'!I20+'Raspberry'!I20 | ... L20: ='Lime Lemon'!L20+'Passion Fruit Pineapple'!L20+'Raspberry'!L20 | M20: =SUM(B20:L20)
A21: A&P Sales | B21: ='Lime Lemon'!B21+'Passion Fruit Pineapple'!B21+'Raspberry'!B21 | C21: ='Lime Lemon'!C21+'Passion Fruit Pineapple'!C21+'Raspberry'!C21 | D21: ='Lime Lemon'!D21+'Passion Fruit Pineapple'!D21+'Raspberry'!D21 | E21: ='Lime Lemon'!E21+'Passion Fruit Pineapple'!E21+'Raspberry'!E21 | F21: ='Lime Lemon'!F21+'Passion Fruit Pineapple'!F21+'Raspberry'!F21 | G21: ='Lime Lemon'!G21+'Passion Fruit Pineapple'!G21+'Raspberry'!G21 | H21: ='Lime Lemon'!H21+'Passion Fruit Pineapple'!H21+'Raspberry'!H21 | I21: ='Lime Lemon'!I21+'Passion Fruit Pineapple'!I21+'Raspberry'!I21 | ... L21: ='Lime Lemon'!L21+'Passion Fruit Pineapple'!L21+'Raspberry'!L21 | M21: =SUM(B21:L21)
A22: A&P | B22: ='Lime Lemon'!B22+'Passion Fruit Pineapple'!B22+'Raspberry'!B22 | C22: ='Lime Lemon'!C22+'Passion Fruit Pineapple'!C22+'Raspberry'!C22 | D22: ='Lime Lemon'!D22+'Passion Fruit Pineapple'!D22+'Raspberry'!D22 | E22: ='Lime Lemon'!E22+'Passion Fruit Pineapple'!E22+'Raspberry'!E22 | F22: ='Lime Lemon'!F22+'Passion Fruit Pineapple'!F22+'Raspberry'!F22 | G22: ='Lime Lemon'!G22+'Passion Fruit Pineapple'!G22+'Raspberry'!G22 | H22: ='Lime Lemon'!H22+'Passion Fruit Pineapple'!H22+'Raspberry'!H22 | I22: ='Lime Lemon'!I22+'Passion Fruit Pineapple'!I22+'Raspberry'!I22 | ... L22: ='Lime Lemon'!L22+'Passion Fruit Pineapple'!L22+'Raspberry'!L22 | M22: =SUM(B22:L22)
A24: Contrib After A&P (CAAP) | B24: ='Lime Lemon'!B24+'Passion Fruit Pineapple'!B24+'Raspberry'!B24 | C24: ='Lime Lemon'!C24+'Passion Fruit Pineapple'!C24+'Raspberry'!C24 | D24: ='Lime Lemon'!D24+'Passion Fruit Pineapple'!D24+'Raspberry'!D24 | E24: ='Lime Lemon'!E24+'Passion Fruit Pineapple'!E24+'Raspberry'!E24 | F24: ='Lime Lemon'!F24+'Passion Fruit Pineapple'!F24+'Raspberry'!F24 | G24: ='Lime Lemon'!G24+'Passion Fruit Pineapple'!G24+'Raspberry'!G24 | H24: ='Lime Lemon'!H24+'Passion Fruit Pineapple'!H24+'Raspberry'!H24 | I24: ='Lime Lemon'!I24+'Passion Fruit Pineapple'!I24+'Raspberry'!I24 | ... L24: ='Lime Lemon'!L24+'Passion Fruit Pineapple'!L24+'Raspberry'!L24 | M24: =SUM(B24:L24)
A26: Gross Rev - per case | B26: =IFERROR(B10/B9,"-") | C26: =IFERROR(C10/C9,"-") | D26: =IFERROR(D10/D9,"-") | E26: =IFERROR(E10/E9,"-") | F26: =IFERROR(F10/F9,"-") | G26: =IFERROR(G10/G9,"-") | H26: =IFERROR(H10/H9,"-") | I26: =IFERROR(I10/I9,"-") | ... M26: =IFERROR(M10/M9,"-")
A27: Discounts - per case | B27: =IFERROR(B11/B9,"-") | C27: =IFERROR(C11/C9,"-") | D27: =IFERROR(D11/D9,"-") | E27: =IFERROR(E11/E9,"-") | F27: =IFERROR(F11/F9,"-") | G27: =IFERROR(G11/G9,"-") | H27: =IFERROR(H11/H9,"-") | I27: =IFERROR(I11/I9,"-") | ... M27: =IFERROR(M11/M9,"-")
A28: Net Sales - per case | B28: =IFERROR(B12/B9,"-") | C28: =IFERROR(C12/C9,"-") | D28: =IFERROR(D12/D9,"-") | E28: =IFERROR(E12/E9,"-") | F28: =IFERROR(F12/F9,"-") | G28: =IFERROR(G12/G9,"-") | H28: =IFERROR(H12/H9,"-") | I28: =IFERROR(I12/I9,"-") | ... M28: =IFERROR(M12/M9,"-")
A29: COGS Direct - per case | B29: =IFERROR(B13/B9,"-") | C29: =IFERROR(C13/C9,"-") | D29: =IFERROR(D13/D9,"-") | E29: =IFERROR(E13/E9,"-") | F29: =IFERROR(F13/F9,"-") | G29: =IFERROR(G13/G9,"-") | H29: =IFERROR(H13/H9,"-") | I29: =IFERROR(I13/I9,"-") | ... M29: =IFERROR(M13/M9,"-")
A30: COGS Indirect - per case | B30: =IFERROR(B14/B9,"-") | C30: =IFERROR(C14/C9,"-") | D30: =IFERROR(D14/D9,"-") | E30: =IFERROR(E14/E9,"-") | F30: =IFERROR(F14/F9,"-") | G30: =IFERROR(G14/G9,"-") | H30: =IFERROR(H14/H9,"-") | I30: =IFERROR(I14/I9,"-") | ... M30: =IFERROR(M14/M9,"-")
A31: Cost of Sales - per case | B31: =IFERROR(B15/B9,"-") | C31: =IFERROR(C15/C9,"-") | D31: =IFERROR(D15/D9,"-") | E31: =IFERROR(E15/E9,"-") | F31: =IFERROR(F15/F9,"-") | G31: =IFERROR(G15/G9,"-") | H31: =IFERROR(H15/H9,"-") | I31: =IFERROR(I15/I9,"-") | ... M31: =IFERROR(M15/M9,"-")
A32: Gross Profit - per case | B32: =IFERROR(B16/B9,"-") | C32: =IFERROR(C16/C9,"-") | D32: =IFERROR(D16/D9,"-") | E32: =IFERROR(E16/E9,"-") | F32: =IFERROR(F16/F9,"-") | G32: =IFERROR(G16/G9,"-") | H32: =IFERROR(H16/H9,"-") | I32: =IFERROR(I16/I9,"-") | ... M32: =IFERROR(M16/M9,"-")
A33: GP % | B33: =IFERROR(B32/B28,"-") | C33: =IFERROR(C32/C28,"-") | D33: =IFERROR(D32/D28,"-") | E33: =IFERROR(E32/E28,"-") | F33: =IFERROR(F32/F28,"-") | G33: =IFERROR(G32/G28,"-") | H33: =IFERROR(H32/H28,"-") | I33: =IFERROR(I32/I28,"-") | ... M33: =IFERROR(M32/M28,"-")
A34: A&P - per case | B34: =IFERROR(B22/B9,"-") | C34: =IFERROR(C22/C9,"-") | D34: =IFERROR(D22/D9,"-") | E34: =IFERROR(E22/E9,"-") | F34: =IFERROR(F22/F9,"-") | G34: =IFERROR(G22/G9,"-") | H34: =IFERROR(H22/H9,"-") | I34: =IFERROR(I22/I9,"-") | ... M34: =IFERROR(M22/M9,"-")
A35: CAAP - per case | B35: =IFERROR(B32-B34,0) | C35: =IFERROR(C32-C34,0) | D35: =IFERROR(D32-D34,0) | E35: =IFERROR(E32-E34,0) | F35: =IFERROR(F32-F34,0) | G35: =IFERROR(G32-G34,0) | H35: =IFERROR(H32-H34,0) | I35: =IFERROR(I32-I34,0) | ... M35: =IFERROR(M32-M34,0)

Sheet Lime Lemon
A1: ORGANIKA RTD — LIME LEMON
A2: CDN $ | Per case of 24 cans (6×4×355 ml) | Period: Aug 1 – Nov 1, 2026
A4: CDN $ | B4: Shopify | C4: Amazon | D4: On-premise | E4: Retail | F4: Distributor | G4: Corporate Office | H4: Purity Life | I4: Natural & Specialty Direct | J4: FDM Direct | K4: Convenience | L4: Fitness Centre | M4: Total
A6: ⚫ All values are formulas — edit inputs on the 🟡 Assumptions tab (pricing, mix, A&P)
A8: Organika RTD — Lime Lemon (6×4×355 ml)
A9: Physical Cases | B9: =Assumptions!$C$16*Assumptions!$F$23 | C9: =Assumptions!$C$16*Assumptions!$F$24 | D9: =Assumptions!$C$16*Assumptions!$F$25 | E9: =Assumptions!$C$16*Assumptions!$F$26 | F9: =Assumptions!$C$16*Assumptions!$F$27 | G9: =Assumptions!$C$16*Assumptions!$F$28 | H9: =Assumptions!$C$16*Assumptions!$F$29 | I9: =Assumptions!$C$16*Assumptions!$F$30 | J9: =Assumptions!$C$16*Assumptions!$F$31 | K9: =Assumptions!$C$16*Assumptions!$F$32 | L9: =Assumptions!$C$16*Assumptions!$F$33 | M9: =SUM(B9:L9)
A10: Gross Revenue | B10: =B26*B9 | C10: =C26*C9 | D10: =D26*D9 | E10: =E26*E9 | F10: =F26*F9 | G10: =G26*G9 | H10: =H26*H9 | I10: =I26*I9 | ... L10: =L26*L9 | M10: =SUM(B10:L10)
A11: Discounts | B11: =B27*B9 | C11: =C27*C9 | D11: =D27*D9 | E11: =E27*E9 | F11: =F27*F9 | G11: =G27*G9 | H11: =H27*H9 | I11: =I27*I9 | ... L11: =L27*L9 | M11: =SUM(B11:L11)
A12: Net Sales | B12: =B10-B11 | C12: =C10-C11 | D12: =D10-D11 | E12: =E10-E11 | F12: =F10-F11 | G12: =G10-G11 | H12: =H10-H11 | I12: =I10-I11 | ... M12: =M10-M11
A13: COGS Direct | B13: =B29*B9 | C13: =C29*C9 | D13: =D29*D9 | E13: =E29*E9 | F13: =F29*F9 | G13: =G29*G9 | H13: =H29*H9 | I13: =I29*I9 | ... L13: =L29*L9 | M13: =SUM(B13:L13)
A14: COGS Indirect | B14: =B30*B9 | C14: =C30*C9 | D14: =D30*D9 | E14: =E30*E9 | F14: =F30*F9 | G14: =G30*G9 | H14: =H30*H9 | I14: =I30*I9 | ... L14: =L30*L9 | M14: =SUM(B14:L14)
A15: Cost of Sales | B15: =B13+B14 | C15: =C13+C14 | D15: =D13+D14 | E15: =E13+E14 | F15: =F13+F14 | G15: =G13+G14 | H15: =H13+H14 | I15: =I13+I14 | ... M15: =M13+M14
A16: Gross Profit | B16: =B12-B15 | C16: =C12-C15 | D16: =D12-D15 | E16: =E12-E15 | F16: =F12-F15 | G16: =G12-G15 | H16: =H12-H15 | I16: =I12-I15 | ... M16: =M12-M15
A17: GP % | B17: =IFERROR(B16/B12,"-") | C17: =IFERROR(C16/C12,"-") | D17: =IFERROR(D16/D12,"-") | E17: =IFERROR(E16/E12,"-") | F17: =IFERROR(F16/F12,"-") | G17: =IFERROR(G16/G12,"-") | H17: =IFERROR(H16/H12,"-") | I17: =IFERROR(I16/I12,"-") | ... M17: =IFERROR(M16/M12,"-")
A19: A&P Consumer | B19: =B22*Assumptions!$C$11 | C19: =C22*Assumptions!$C$11 | D19: =D22*Assumptions!$C$11 | E19: =E22*Assumptions!$C$11 | F19: =F22*Assumptions!$C$11 | G19: =G22*Assumptions!$C$11 | H19: =H22*Assumptions!$C$11 | I19: =I22*Assumptions!$C$11 | ... L19: =L22*Assumptions!$C$11 | M19: =SUM(B19:L19)
A20: A&P Trade | B20: =B22*Assumptions!$C$12 | C20: =C22*Assumptions!$C$12 | D20: =D22*Assumptions!$C$12 | E20: =E22*Assumptions!$C$12 | F20: =F22*Assumptions!$C$12 | G20: =G22*Assumptions!$C$12 | H20: =H22*Assumptions!$C$12 | I20: =I22*Assumptions!$C$12 | ... L20: =L22*Assumptions!$C$12 | M20: =SUM(B20:L20)
A21: A&P Sales | B21: =B22*Assumptions!$C$13 | C21: =C22*Assumptions!$C$13 | D21: =D22*Assumptions!$C$13 | E21: =E22*Assumptions!$C$13 | F21: =F22*Assumptions!$C$13 | G21: =G22*Assumptions!$C$13 | H21: =H22*Assumptions!$C$13 | I21: =I22*Assumptions!$C$13 | ... L21: =L22*Assumptions!$C$13 | M21: =SUM(B21:L21)
A22: A&P | B22: =B12*Assumptions!$E$23 | C22: =C12*Assumptions!$E$24 | D22: =D12*Assumptions!$E$25 | E22: =E12*Assumptions!$E$26 | F22: =F12*Assumptions!$E$27 | G22: =G12*Assumptions!$E$28 | H22: =H12*Assumptions!$E$29 | I22: =I12*Assumptions!$E$30 | J22: =J12*Assumptions!$E$31 | K22: =K12*Assumptions!$E$32 | L22: =L12*Assumptions!$E$33 | M22: =M19+M20+M21
A24: Contrib After A&P (CAAP) | B24: =B16-B22 | C24: =C16-C22 | D24: =D16-D22 | E24: =E16-E22 | F24: =F16-F22 | G24: =G16-G22 | H24: =H16-H22 | I24: =I16-I22 | ... M24: =M16-M22
A26: Gross Rev - per case | B26: =Assumptions!$B$23 | C26: =Assumptions!$B$24 | D26: =Assumptions!$B$25 | E26: =Assumptions!$B$26 | F26: =Assumptions!$B$27 | G26: =Assumptions!$B$28 | H26: =Assumptions!$B$29 | I26: =Assumptions!$B$30 | J26: =Assumptions!$B$31 | K26: =Assumptions!$B$32 | L26: =Assumptions!$B$33 | M26: =IFERROR(M10/M9,"-")
A27: Discounts - per case | B27: =Assumptions!$B$23*Assumptions!$D$23 | C27: =Assumptions!$B$24*Assumptions!$D$24 | D27: =Assumptions!$B$25*Assumptions!$D$25 | E27: =Assumptions!$B$26*Assumptions!$D$26 | F27: =Assumptions!$B$27*Assumptions!$D$27 | G27: =Assumptions!$B$28*Assumptions!$D$28 | H27: =Assumptions!$B$29*Assumptions!$D$29 | I27: =Assumptions!$B$30*Assumptions!$D$30 | J27: =Assumptions!$B$31*Assumptions!$D$31 | K27: =Assumptions!$B$32*Assumptions!$D$32 | L27: =Assumptions!$B$33*Assumptions!$D$33 | M27: =IFERROR(M11/M9,"-")
A28: Net Sales - per case | B28: =B26-B27 | C28: =C26-C27 | D28: =D26-D27 | E28: =E26-E27 | F28: =F26-F27 | G28: =G26-G27 | H28: =H26-H27 | I28: =I26-I27 | ... L28: =L26-L27 | M28: =IFERROR(M12/M9,"-")
A29: COGS Direct - per case | B29: ='Cost Build-up'!$D$44 | C29: ='Cost Build-up'!$D$44 | D29: ='Cost Build-up'!$D$44 | E29: ='Cost Build-up'!$D$44 | F29: ='Cost Build-up'!$D$44 | G29: ='Cost Build-up'!$D$44 | H29: ='Cost Build-up'!$D$44 | I29: ='Cost Build-up'!$D$44 | ... L29: ='Cost Build-up'!$D$44 | M29: =IFERROR(M13/M9,"-")
A30: COGS Indirect - per case | B30: ='Cost Build-up'!$D$45 | C30: ='Cost Build-up'!$D$45 | D30: ='Cost Build-up'!$D$45 | E30: ='Cost Build-up'!$D$45 | F30: ='Cost Build-up'!$D$45 | G30: ='Cost Build-up'!$D$45 | H30: ='Cost Build-up'!$D$45 | I30: ='Cost Build-up'!$D$45 | ... L30: ='Cost Build-up'!$D$45 | M30: =IFERROR(M14/M9,"-")
A31: Cost of Sales - per case | B31: =B29+B30 | C31: =C29+C30 | D31: =D29+D30 | E31: =E29+E30 | F31: =F29+F30 | G31: =G29+G30 | H31: =H29+H30 | I31: =I29+I30 | ... L31: =L29+L30 | M31: =IFERROR(M15/M9,"-")
A32: Gross Profit - per case | B32: =B28-B31 | C32: =C28-C31 | D32: =D28-D31 | E32: =E28-E31 | F32: =F28-F31 | G32: =G28-G31 | H32: =H28-H31 | I32: =I28-I31 | ... L32: =L28-L31 | M32: =IFERROR(M16/M9,"-")
A33: GP % | B33: =IFERROR(B32/B28,"-") | C33: =IFERROR(C32/C28,"-") | D33: =IFERROR(D32/D28,"-") | E33: =IFERROR(E32/E28,"-") | F33: =IFERROR(F32/F28,"-") | G33: =IFERROR(G32/G28,"-") | H33: =IFERROR(H32/H28,"-") | I33: =IFERROR(I32/I28,"-") | ... M33: =IFERROR(M32/M28,"-")
A34: A&P - per case | B34: =IFERROR(B22/B9,"-") | C34: =IFERROR(C22/C9,"-") | D34: =IFERROR(D22/D9,"-") | E34: =IFERROR(E22/E9,"-") | F34: =IFERROR(F22/F9,"-") | G34: =IFERROR(G22/G9,"-") | H34: =IFERROR(H22/H9,"-") | I34: =IFERROR(I22/I9,"-") | ... M34: =IFERROR(M22/M9,"-")
A35: CAAP - per case | B35: =B32-B34 | C35: =C32-C34 | D35: =D32-D34 | E35: =E32-E34 | F35: =F32-F34 | G35: =G32-G34 | H35: =H32-H34 | I35: =I32-I34 | ... L35: =L32-L34 | M35: =IFERROR(M32-M34,0)

Sheet Passion Fruit Pineapple
A1: ORGANIKA RTD — PASSION FRUIT PINEAPPLE
A2: CDN $ | Per case of 24 cans (6×4×355 ml) | Period: Aug 1 – Nov 1, 2026
A4: CDN $ | B4: Shopify | C4: Amazon | D4: On-premise | E4: Retail | F4: Distributor | G4: Corporate Office | H4: Purity Life | I4: Natural & Specialty Direct | J4: FDM Direct | K4: Convenience | L4: Fitness Centre | M4: Total
A6: ⚫ All values are formulas — edit inputs on the 🟡 Assumptions tab (pricing, mix, A&P)
A8: Organika RTD — Passion Fruit Pineapple (6×4×355 ml)
A9: Physical Cases | B9: =Assumptions!$C$17*Assumptions!$F$23 | C9: =Assumptions!$C$17*Assumptions!$F$24 | D9: =Assumptions!$C$17*Assumptions!$F$25 | E9: =Assumptions!$C$17*Assumptions!$F$26 | F9: =Assumptions!$C$17*Assumptions!$F$27 | G9: =Assumptions!$C$17*Assumptions!$F$28 | H9: =Assumptions!$C$17*Assumptions!$F$29 | I9: =Assumptions!$C$17*Assumptions!$F$30 | J9: =Assumptions!$C$17*Assumptions!$F$31 | K9: =Assumptions!$C$17*Assumptions!$F$32 | L9: =Assumptions!$C$17*Assumptions!$F$33 | M9: =SUM(B9:L9)
A10: Gross Revenue | B10: =B26*B9 | C10: =C26*C9 | D10: =D26*D9 | E10: =E26*E9 | F10: =F26*F9 | G10: =G26*G9 | H10: =H26*H9 | I10: =I26*I9 | ... L10: =L26*L9 | M10: =SUM(B10:L10)
A11: Discounts | B11: =B27*B9 | C11: =C27*C9 | D11: =D27*D9 | E11: =E27*E9 | F11: =F27*F9 | G11: =G27*G9 | H11: =H27*H9 | I11: =I27*I9 | ... L11: =L27*L9 | M11: =SUM(B11:L11)
A12: Net Sales | B12: =B10-B11 | C12: =C10-C11 | D12: =D10-D11 | E12: =E10-E11 | F12: =F10-F11 | G12: =G10-G11 | H12: =H10-H11 | I12: =I10-I11 | ... M12: =M10-M11
A13: COGS Direct | B13: =B29*B9 | C13: =C29*C9 | D13: =D29*D9 | E13: =E29*E9 | F13: =F29*F9 | G13: =G29*G9 | H13: =H29*H9 | I13: =I29*I9 | ... L13: =L29*L9 | M13: =SUM(B13:L13)
A14: COGS Indirect | B14: =B30*B9 | C14: =C30*C9 | D14: =D30*D9 | E14: =E30*E9 | F14: =F30*F9 | G14: =G30*G9 | H14: =H30*H9 | I14: =I30*I9 | ... L14: =L30*L9 | M14: =SUM(B14:L14)
A15: Cost of Sales | B15: =B13+B14 | C15: =C13+C14 | D15: =D13+D14 | E15: =E13+E14 | F15: =F13+F14 | G15: =G13+G14 | H15: =H13+H14 | I15: =I13+I14 | ... M15: =M13+M14
A16: Gross Profit | B16: =B12-B15 | C16: =C12-C15 | D16: =D12-D15 | E16: =E12-E15 | F16: =F12-F15 | G16: =G12-G15 | H16: =H12-H15 | I16: =I12-I15 | ... M16: =M12-M15
A17: GP % | B17: =IFERROR(B16/B12,"-") | C17: =IFERROR(C16/C12,"-") | D17: =IFERROR(D16/D12,"-") | E17: =IFERROR(E16/E12,"-") | F17: =IFERROR(F16/F12,"-") | G17: =IFERROR(G16/G12,"-") | H17: =IFERROR(H16/H12,"-") | I17: =IFERROR(I16/I12,"-") | ... M17: =IFERROR(M16/M12,"-")
A19: A&P Consumer | B19: =B22*Assumptions!$C$11 | C19: =C22*Assumptions!$C$11 | D19: =D22*Assumptions!$C$11 | E19: =E22*Assumptions!$C$11 | F19: =F22*Assumptions!$C$11 | G19: =G22*Assumptions!$C$11 | H19: =H22*Assumptions!$C$11 | I19: =I22*Assumptions!$C$11 | ... L19: =L22*Assumptions!$C$11 | M19: =SUM(B19:L19)
A20: A&P Trade | B20: =B22*Assumptions!$C$12 | C20: =C22*Assumptions!$C$12 | D20: =D22*Assumptions!$C$12 | E20: =E22*Assumptions!$C$12 | F20: =F22*Assumptions!$C$12 | G20: =G22*Assumptions!$C$12 | H20: =H22*Assumptions!$C$12 | I20: =I22*Assumptions!$C$12 | ... L20: =L22*Assumptions!$C$12 | M20: =SUM(B20:L20)
A21: A&P Sales | B21: =B22*Assumptions!$C$13 | C21: =C22*Assumptions!$C$13 | D21: =D22*Assumptions!$C$13 | E21: =E22*Assumptions!$C$13 | F21: =F22*Assumptions!$C$13 | G21: =G22*Assumptions!$C$13 | H21: =H22*Assumptions!$C$13 | I21: =I22*Assumptions!$C$13 | ... L21: =L22*Assumptions!$C$13 | M21: =SUM(B21:L21)
A22: A&P | B22: =B12*Assumptions!$E$23 | C22: =C12*Assumptions!$E$24 | D22: =D12*Assumptions!$E$25 | E22: =E12*Assumptions!$E$26 | F22: =F12*Assumptions!$E$27 | G22: =G12*Assumptions!$E$28 | H22: =H12*Assumptions!$E$29 | I22: =I12*Assumptions!$E$30 | J22: =J12*Assumptions!$E$31 | K22: =K12*Assumptions!$E$32 | L22: =L12*Assumptions!$E$33 | M22: =M19+M20+M21
A24: Contrib After A&P (CAAP) | B24: =B16-B22 | C24: =C16-C22 | D24: =D16-D22 | E24: =E16-E22 | F24: =F16-F22 | G24: =G16-G22 | H24: =H16-H22 | I24: =I16-I22 | ... M24: =M16-M22
A26: Gross Rev - per case | B26: =Assumptions!$B$23 | C26: =Assumptions!$B$24 | D26: =Assumptions!$B$25 | E26: =Assumptions!$B$26 | F26: =Assumptions!$B$27 | G26: =Assumptions!$B$28 | H26: =Assumptions!$B$29 | I26: =Assumptions!$B$30 | J26: =Assumptions!$B$31 | K26: =Assumptions!$B$32 | L26: =Assumptions!$B$33 | M26: =IFERROR(M10/M9,"-")
A27: Discounts - per case | B27: =Assumptions!$B$23*Assumptions!$D$23 | C27: =Assumptions!$B$24*Assumptions!$D$24 | D27: =Assumptions!$B$25*Assumptions!$D$25 | E27: =Assumptions!$B$26*Assumptions!$D$26 | F27: =Assumptions!$B$27*Assumptions!$D$27 | G27: =Assumptions!$B$28*Assumptions!$D$28 | H27: =Assumptions!$B$29*Assumptions!$D$29 | I27: =Assumptions!$B$30*Assumptions!$D$30 | J27: =Assumptions!$B$31*Assumptions!$D$31 | K27: =Assumptions!$B$32*Assumptions!$D$32 | L27: =Assumptions!$B$33*Assumptions!$D$33 | M27: =IFERROR(M11/M9,"-")
A28: Net Sales - per case | B28: =B26-B27 | C28: =C26-C27 | D28: =D26-D27 | E28: =E26-E27 | F28: =F26-F27 | G28: =G26-G27 | H28: =H26-H27 | I28: =I26-I27 | ... L28: =L26-L27 | M28: =IFERROR(M12/M9,"-")
A29: COGS Direct - per case | B29: ='Cost Build-up'!$D$44 | C29: ='Cost Build-up'!$D$44 | D29: ='Cost Build-up'!$D$44 | E29: ='Cost Build-up'!$D$44 | F29: ='Cost Build-up'!$D$44 | G29: ='Cost Build-up'!$D$44 | H29: ='Cost Build-up'!$D$44 | I29: ='Cost Build-up'!$D$44 | ... L29: ='Cost Build-up'!$D$44 | M29: =IFERROR(M13/M9,"-")
A30: COGS Indirect - per case | B30: ='Cost Build-up'!$D$45 | C30: ='Cost Build-up'!$D$45 | D30: ='Cost Build-up'!$D$45 | E30: ='Cost Build-up'!$D$45 | F30: ='Cost Build-up'!$D$45 | G30: ='Cost Build-up'!$D$45 | H30: ='Cost Build-up'!$D$45 | I30: ='Cost Build-up'!$D$45 | ... L30: ='Cost Build-up'!$D$45 | M30: =IFERROR(M14/M9,"-")
A31: Cost of Sales - per case | B31: =B29+B30 | C31: =C29+C30 | D31: =D29+D30 | E31: =E29+E30 | F31: =F29+F30 | G31: =G29+G30 | H31: =H29+H30 | I31: =I29+I30 | ... L31: =L29+L30 | M31: =IFERROR(M15/M9,"-")
A32: Gross Profit - per case | B32: =B28-B31 | C32: =C28-C31 | D32: =D28-D31 | E32: =E28-E31 | F32: =F28-F31 | G32: =G28-G31 | H32: =H28-H31 | I32: =I28-I31 | ... L32: =L28-L31 | M32: =IFERROR(M16/M9,"-")
A33: GP % | B33: =IFERROR(B32/B28,"-") | C33: =IFERROR(C32/C28,"-") | D33: =IFERROR(D32/D28,"-") | E33: =IFERROR(E32/E28,"-") | F33: =IFERROR(F32/F28,"-") | G33: =IFERROR(G32/G28,"-") | H33: =IFERROR(H32/H28,"-") | I33: =IFERROR(I32/I28,"-") | ... M33: =IFERROR(M32/M28,"-")
A34: A&P - per case | B34: =IFERROR(B22/B9,"-") | C34: =IFERROR(C22/C9,"-") | D34: =IFERROR(D22/D9,"-") | E34: =IFERROR(E22/E9,"-") | F34: =IFERROR(F22/F9,"-") | G34: =IFERROR(G22/G9,"-") | H34: =IFERROR(H22/H9,"-") | I34: =IFERROR(I22/I9,"-") | ... M34: =IFERROR(M22/M9,"-")
A35: CAAP - per case | B35: =B32-B34 | C35: =C32-C34 | D35: =D32-D34 | E35: =E32-E34 | F35: =F32-F34 | G35: =G32-G34 | H35: =H32-H34 | I35: =I32-I34 | ... L35: =L32-L34 | M35: =IFERROR(M32-M34,0)

Sheet Raspberry
A1: ORGANIKA RTD — RASPBERRY
A2: CDN $ | Per case of 24 cans (6×4×355 ml) | Period: Aug 1 – Nov 1, 2026
A4: CDN $ | B4: Shopify | C4: Amazon | D4: On-premise | E4: Retail | F4: Distributor | G4: Corporate Office | H4: Purity Life | I4: Natural & Specialty Direct | J4: FDM Direct | K4: Convenience | L4: Fitness Centre | M4: Total
A6: ⚫ All values are formulas — edit inputs on the 🟡 Assumptions tab (pricing, mix, A&P)
A8: Organika RTD — Raspberry (6×4×355 ml)
A9: Physical Cases | B9: =Assumptions!$C$18*Assumptions!$F$23 | C9: =Assumptions!$C$18*Assumptions!$F$24 | D9: =Assumptions!$C$18*Assumptions!$F$25 | E9: =Assumptions!$C$18*Assumptions!$F$26 | F9: =Assumptions!$C$18*Assumptions!$F$27 | G9: =Assumptions!$C$18*Assumptions!$F$28 | H9: =Assumptions!$C$18*Assumptions!$F$29 | I9: =Assumptions!$C$18*Assumptions!$F$30 | J9: =Assumptions!$C$18*Assumptions!$F$31 | K9: =Assumptions!$C$18*Assumptions!$F$32 | L9: =Assumptions!$C$18*Assumptions!$F$33 | M9: =SUM(B9:L9)
A10: Gross Revenue | B10: =B26*B9 | C10: =C26*C9 | D10: =D26*D9 | E10: =E26*E9 | F10: =F26*F9 | G10: =G26*G9 | H10: =H26*H9 | I10: =I26*I9 | ... L10: =L26*L9 | M10: =SUM(B10:L10)
A11: Discounts | B11: =B27*B9 | C11: =C27*C9 | D11: =D27*D9 | E11: =E27*E9 | F11: =F27*F9 | G11: =G27*G9 | H11: =H27*H9 | I11: =I27*I9 | ... L11: =L27*L9 | M11: =SUM(B11:L11)
A12: Net Sales | B12: =B10-B11 | C12: =C10-C11 | D12: =D10-D11 | E12: =E10-E11 | F12: =F10-F11 | G12: =G10-G11 | H12: =H10-H11 | I12: =I10-I11 | ... M12: =M10-M11
A13: COGS Direct | B13: =B29*B9 | C13: =C29*C9 | D13: =D29*D9 | E13: =E29*E9 | F13: =F29*F9 | G13: =G29*G9 | H13: =H29*H9 | I13: =I29*I9 | ... L13: =L29*L9 | M13: =SUM(B13:L13)
A14: COGS Indirect | B14: =B30*B9 | C14: =C30*C9 | D14: =D30*D9 | E14: =E30*E9 | F14: =F30*F9 | G14: =G30*G9 | H14: =H30*H9 | I14: =I30*I9 | ... L14: =L30*L9 | M14: =SUM(B14:L14)
A15: Cost of Sales | B15: =B13+B14 | C15: =C13+C14 | D15: =D13+D14 | E15: =E13+E14 | F15: =F13+F14 | G15: =G13+G14 | H15: =H13+H14 | I15: =I13+I14 | ... M15: =M13+M14
A16: Gross Profit | B16: =B12-B15 | C16: =C12-C15 | D16: =D12-D15 | E16: =E12-E15 | F16: =F12-F15 | G16: =G12-G15 | H16: =H12-H15 | I16: =I12-I15 | ... M16: =M12-M15
A17: GP % | B17: =IFERROR(B16/B12,"-") | C17: =IFERROR(C16/C12,"-") | D17: =IFERROR(D16/D12,"-") | E17: =IFERROR(E16/E12,"-") | F17: =IFERROR(F16/F12,"-") | G17: =IFERROR(G16/G12,"-") | H17: =IFERROR(H16/H12,"-") | I17: =IFERROR(I16/I12,"-") | ... M17: =IFERROR(M16/M12,"-")
A19: A&P Consumer | B19: =B22*Assumptions!$C$11 | C19: =C22*Assumptions!$C$11 | D19: =D22*Assumptions!$C$11 | E19: =E22*Assumptions!$C$11 | F19: =F22*Assumptions!$C$11 | G19: =G22*Assumptions!$C$11 | H19: =H22*Assumptions!$C$11 | I19: =I22*Assumptions!$C$11 | ... L19: =L22*Assumptions!$C$11 | M19: =SUM(B19:L19)
A20: A&P Trade | B20: =B22*Assumptions!$C$12 | C20: =C22*Assumptions!$C$12 | D20: =D22*Assumptions!$C$12 | E20: =E22*Assumptions!$C$12 | F20: =F22*Assumptions!$C$12 | G20: =G22*Assumptions!$C$12 | H20: =H22*Assumptions!$C$12 | I20: =I22*Assumptions!$C$12 | ... L20: =L22*Assumptions!$C$12 | M20: =SUM(B20:L20)
A21: A&P Sales | B21: =B22*Assumptions!$C$13 | C21: =C22*Assumptions!$C$13 | D21: =D22*Assumptions!$C$13 | E21: =E22*Assumptions!$C$13 | F21: =F22*Assumptions!$C$13 | G21: =G22*Assumptions!$C$13 | H21: =H22*Assumptions!$C$13 | I21: =I22*Assumptions!$C$13 | ... L21: =L22*Assumptions!$C$13 | M21: =SUM(B21:L21)
A22: A&P | B22: =B12*Assumptions!$E$23 | C22: =C12*Assumptions!$E$24 | D22: =D12*Assumptions!$E$25 | E22: =E12*Assumptions!$E$26 | F22: =F12*Assumptions!$E$27 | G22: =G12*Assumptions!$E$28 | H22: =H12*Assumptions!$E$29 | I22: =I12*Assumptions!$E$30 | J22: =J12*Assumptions!$E$31 | K22: =K12*Assumptions!$E$32 | L22: =L12*Assumptions!$E$33 | M22: =M19+M20+M21
A24: Contrib After A&P (CAAP) | B24: =B16-B22 | C24: =C16-C22 | D24: =D16-D22 | E24: =E16-E22 | F24: =F16-F22 | G24: =G16-G22 | H24: =H16-H22 | I24: =I16-I22 | ... M24: =M16-M22
A26: Gross Rev - per case | B26: =Assumptions!$B$23 | C26: =Assumptions!$B$24 | D26: =Assumptions!$B$25 | E26: =Assumptions!$B$26 | F26: =Assumptions!$B$27 | G26: =Assumptions!$B$28 | H26: =Assumptions!$B$29 | I26: =Assumptions!$B$30 | J26: =Assumptions!$B$31 | K26: =Assumptions!$B$32 | L26: =Assumptions!$B$33 | M26: =IFERROR(M10/M9,"-")
A27: Discounts - per case | B27: =Assumptions!$B$23*Assumptions!$D$23 | C27: =Assumptions!$B$24*Assumptions!$D$24 | D27: =Assumptions!$B$25*Assumptions!$D$25 | E27: =Assumptions!$B$26*Assumptions!$D$26 | F27: =Assumptions!$B$27*Assumptions!$D$27 | G27: =Assumptions!$B$28*Assumptions!$D$28 | H27: =Assumptions!$B$29*Assumptions!$D$29 | I27: =Assumptions!$B$30*Assumptions!$D$30 | J27: =Assumptions!$B$31*Assumptions!$D$31 | K27: =Assumptions!$B$32*Assumptions!$D$32 | L27: =Assumptions!$B$33*Assumptions!$D$33 | M27: =IFERROR(M11/M9,"-")
A28: Net Sales - per case | B28: =B26-B27 | C28: =C26-C27 | D28: =D26-D27 | E28: =E26-E27 | F28: =F26-F27 | G28: =G26-G27 | H28: =H26-H27 | I28: =I26-I27 | ... L28: =L26-L27 | M28: =IFERROR(M12/M9,"-")
A29: COGS Direct - per case | B29: ='Cost Build-up'!$D$44 | C29: ='Cost Build-up'!$D$44 | D29: ='Cost Build-up'!$D$44 | E29: ='Cost Build-up'!$D$44 | F29: ='Cost Build-up'!$D$44 | G29: ='Cost Build-up'!$D$44 | H29: ='Cost Build-up'!$D$44 | I29: ='Cost Build-up'!$D$44 | ... L29: ='Cost Build-up'!$D$44 | M29: =IFERROR(M13/M9,"-")
A30: COGS Indirect - per case | B30: ='Cost Build-up'!$D$45 | C30: ='Cost Build-up'!$D$45 | D30: ='Cost Build-up'!$D$45 | E30: ='Cost Build-up'!$D$45 | F30: ='Cost Build-up'!$D$45 | G30: ='Cost Build-up'!$D$45 | H30: ='Cost Build-up'!$D$45 | I30: ='Cost Build-up'!$D$45 | ... L30: ='Cost Build-up'!$D$45 | M30: =IFERROR(M14/M9,"-")
A31: Cost of Sales - per case | B31: =B29+B30 | C31: =C29+C30 | D31: =D29+D30 | E31: =E29+E30 | F31: =F29+F30 | G31: =G29+G30 | H31: =H29+H30 | I31: =I29+I30 | ... L31: =L29+L30 | M31: =IFERROR(M15/M9,"-")
A32: Gross Profit - per case | B32: =B28-B31 | C32: =C28-C31 | D32: =D28-D31 | E32: =E28-E31 | F32: =F28-F31 | G32: =G28-G31 | H32: =H28-H31 | I32: =I28-I31 | ... L32: =L28-L31 | M32: =IFERROR(M16/M9,"-")
A33: GP % | B33: =IFERROR(B32/B28,"-") | C33: =IFERROR(C32/C28,"-") | D33: =IFERROR(D32/D28,"-") | E33: =IFERROR(E32/E28,"-") | F33: =IFERROR(F32/F28,"-") | G33: =IFERROR(G32/G28,"-") | H33: =IFERROR(H32/H28,"-") | I33: =IFERROR(I32/I28,"-") | ... M33: =IFERROR(M32/M28,"-")
A34: A&P - per case | B34: =IFERROR(B22/B9,"-") | C34: =IFERROR(C22/C9,"-") | D34: =IFERROR(D22/D9,"-") | E34: =IFERROR(E22/E9,"-") | F34: =IFERROR(F22/F9,"-") | G34: =IFERROR(G22/G9,"-") | H34: =IFERROR(H22/H9,"-") | I34: =IFERROR(I22/I9,"-") | ... M34: =IFERROR(M22/M9,"-")
A35: CAAP - per case | B35: =B32-B34 | C35: =C32-C34 | D35: =D32-D34 | E35: =E32-E34 | F35: =F32-F34 | G35: =G32-G34 | H35: =H32-H34 | I35: =I32-I34 | ... L35: =L32-L34 | M35: =IFERROR(M32-M34,0)

Sheet Cost Build-up
A1: ORGANIKA RTD — BOTTOM-UP COST (Bevmax quote)
A2: CDN $ | Quote OG2026-05-21 v15 (4-pk w/ sleeves) | Pack Summer 2026 | FOB Airdrie AB | excl. GST
A4: RUN PARAMETERS
A6: Total run size | B6: cans | D6: 40500
A7: Number of SKUs | B7: SKUs | D7: 3
A8: Cans per SKU | B8: cans | D8: =D6/D7
A9: Cans per case | B9: cans | D9: 24
A10: Cans per 4-pack | B10: cans | D10: 4
A11: Cases per run | B11: cases | D11: =D6/D9
A13: BEVMAX QUOTE — COST LINES
A14: Cost line | B14: UofM | C14: Rate $ | D14: Total $ | E14: $/can
A15: Tolling (blend/fill/pasteurize/carbonate) | B15: per can | C15: 0.3 | D15: 12150 | E15: =D15/$D$6
A16: 4-packing | B16: per can | C16: 0.05 | D16: 2025 | E16: =D16/$D$6
A17: Skid packing | B17: per run | C17: — | D17: 439.45 | E17: =D17/$D$6
A18: Ingredients | B18: per can | C18: 0.16 | D18: 6480 | E18: =D18/$D$6
A19: Brite can + 202 LOE end | B19: per can | C19: 0.32 | D19: 12960 | E19: =D19/$D$6
A20: Sleeves + application | B20: per label | C20: 0.163 | D20: 6601.5 | E20: =D20/$D$6
A21: Sleeve-perforation setup (one-time) | B21: per setup | C21: — | D21: 489 | E21: =D21/$D$6
A22: 4-pk printed carton | B22: per carton | C22: 0.411 | D22: 6165 | E22: =D22/$D$6
A23: 24-pk white tray | B23: per tray | C23: 0.86 | D23: 1451.25 | E23: =D23/$D$6
A24: Grip sheets | B24: per tray | C24: 1.25 | D24: 175.78 | E24: =D24/$D$6
A25: Tray labels | B25: per tray | C25: 0.05 | D25: 168.75 | E25: =D25/$D$6
A26: Subtotal — Bevmax (FOB Airdrie) | D26: =SUM(D15:D25) | E26: =D26/$D$6
A28: Bevmax cost / can | D28: =D26/$D$6
A29: Bevmax cost / 4-pack | D29: =D28*D10
A30: Bevmax cost / case (24) | D30: =D28*D9
A32: ADDERS TO LANDED COST (per case)
A33: Allergen handling (amortized) | D33: =167.5/D11
A34: Inbound freight to DC | D34: 0
A35: Testing / misc | D35: 0
A37: OVERHEAD (% of landed direct)
A38: OH cost % | C38: 0.05
A39: Other COGS % | C39: 0.05
A43: → COGS TO P&L (per case)
A44: COGS Direct / case | D44: =D30+D33+D34+D35
A45: COGS Indirect / case | D45: =(C38+C39)*D44
A46: COGS Total / case | D46: =D44+D45
A47: COGS / 4-pack | D47: =D46/D9*D10
A48: COGS / can | D48: =D46/D9
