Workbook
Name LU_Owner: OFFSET(Lookups!$A$3,0,0,MAX(1,COUNTA(Lookups!$A$3:$A$1000)),1)
Name LU_Type: OFFSET(Lookups!$B$3,0,0,MAX(1,COUNTA(Lookups!$B$3:$B$1000)),1)
Name LU_Priority: OFFSET(Lookups!$C$3,0,0,MAX(1,COUNTA(Lookups!$C$3:$C$1000)),1)
Name LU_Status: OFFSET(Lookups!$D$3,0,0,MAX(1,COUNTA(Lookups!$D$3:$D$1000)),1)
Name LU_Warm: OFFSET(Lookups!$E$3,0,0,MAX(1,COUNTA(Lookups!$E$3:$E$1000)),1)
Name LU_Source: OFFSET(Lookups!$F$3,0,0,MAX(1,COUNTA(Lookups!$F$3:$F$1000)),1)
Name LU_Activation: OFFSET(Lookups!$G$3,0,0,MAX(1,COUNTA(Lookups!$G$3:$G$1000)),1)
Name LU_Want: OFFSET(Lookups!$H$3,0,0,MAX(1,COUNTA(Lookups!$H$3:$H$1000)),1)
Name LU_Risks: OFFSET(Lookups!$I$3,0,0,MAX(1,COUNTA(Lookups!$I$3:$I$1000)),1)
Name LU_InBC: OFFSET(Lookups!$J$3,0,0,MAX(1,COUNTA(Lookups!$J$3:$J$1000)),1)
Name LU_SKU: OFFSET(Lookups!$K$3,0,0,MAX(1,COUNTA(Lookups!$K$3:$K$1000)),1)
Name LU_Role: OFFSET(Lookups!$L$3,0,0,MAX(1,COUNTA(Lookups!$L$3:$L$1000)),1)
Name LU_City: OFFSET(Lookups!$M$3,0,0,MAX(1,COUNTA(Lookups!$M$3:$M$1000)),1)
Name LU_Neighbourhood: OFFSET(Lookups!$N$3,0,0,MAX(1,COUNTA(Lookups!$N$3:$N$1000)),1)
Name LU_EventStatus: OFFSET(Lookups!$O$3,0,0,MAX(1,COUNTA(Lookups!$O$3:$O$1000)),1)

Sheet Dashboard
A1: Organika RTD · Community Partnerships Command Centre
A2: Live overview. Every number updates on its own as the team works the type tabs. | L2: ="As of "&TEXT(TODAY(),"yyyy/mm/dd")
A4: Total Partners | C4: P1 Partners | E4: Active Conversations | G4: Activations Booked | I4: Cans Sampled to Date | K4: Cost Per Can Sampled | M4: Days Until Costco Road Show
A5: =SUM(E8:E15) | C5: =COUNTIF('Master List'!$E$3:$E$500,"P1") | E5: =COUNTIF('Master List'!$F$3:$F$500,"Outreach Sent")+COUNTIF('Master List'!$F$3:$F$500,"In Conversation")+COUNTIF('Master List'!$F$3:$F$500,"Proposal Sent")+COUNTIF('Master List'!$F$3:$F$500,"Agreed") | G5: =COUNT('Master List'!$V$3:$V$500) | I5: =24*SUM('Master List'!$X$3:$X$500) | K5: =IFERROR(SUM('Master List'!$Y$3:$Y$500)/(24*SUM('Master List'!$X$3:$X$500)),0) | M5: =MAX(0,DATE(2026,8,1)-TODAY())
A7: Pipeline by Stage | B7: Count | D7: Partners by Type | E7: Count | G7: Priority | H7: Count | J7: Budget | K7: $
A8: Open | B8: =COUNTIF('Master List'!$F$3:$F$500,"Open") | D8: Run Clubs | E8: =COUNTA('Run Clubs'!$B$3:$B$32) | G8: P1 | H8: =COUNTIF('Master List'!$E$3:$E$500,"P1") | J8: Total Budget | K8: =Budget!B14
A9: Outreach Sent | B9: =COUNTIF('Master List'!$F$3:$F$500,"Outreach Sent") | D9: Gyms & Studios | E9: =COUNTA('Gyms & Studios'!$B$3:$B$32) | G9: P2 | H9: =COUNTIF('Master List'!$E$3:$E$500,"P2") | J9: Committed | K9: =Budget!C14
A10: In Conversation | B10: =COUNTIF('Master List'!$F$3:$F$500,"In Conversation") | D10: Events & Festivals | E10: =COUNTA('Events & Festivals'!$B$3:$B$32) | G10: P3 | H10: =COUNTIF('Master List'!$E$3:$E$500,"P3") | J10: Spent | K10: =Budget!D14
A11: Proposal Sent | B11: =COUNTIF('Master List'!$F$3:$F$500,"Proposal Sent") | D11: Sports Teams & Leagues | E11: =COUNTA('Sports Teams & Leagues'!$B$3:$B$32) | J11: Remaining | K11: =Budget!E14
A12: Agreed | B12: =COUNTIF('Master List'!$F$3:$F$500,"Agreed") | D12: Campus & Student Groups | E12: =COUNTA('Campus & Student Groups'!$B$3:$B$32) | G12: Activations | H12: Count | J12: % Spent | K12: =Budget!F14
A13: Activated | B13: =COUNTIF('Master List'!$F$3:$F$500,"Activated") | D13: Wellness & Recovery | E13: =COUNTA('Wellness & Recovery'!$B$3:$B$32) | G13: Next 30 Days | H13: =COUNTIFS('Master List'!$V$3:$V$500,">="&TODAY(),'Master List'!$V$3:$V$500,"<="&TODAY()+30)
A14: Repeat Partner | B14: =COUNTIF('Master List'!$F$3:$F$500,"Repeat Partner") | D14: Ambassadors & Creators | E14: =COUNTA('Ambassadors & Creators'!$B$3:$B$32) | G14: Next 60 Days | H14: =COUNTIFS('Master List'!$V$3:$V$500,">="&TODAY(),'Master List'!$V$3:$V$500,"<="&TODAY()+60) | J14: SKU Status | K14: Requested | L14: Sampled | M14: Stocked
A15: Lost | B15: =COUNTIF('Master List'!$F$3:$F$500,"Lost") | D15: Charity & Causes | E15: =COUNTA('Charity & Causes'!$B$3:$B$32) | G15: Next 90 Days | H15: =COUNTIFS('Master List'!$V$3:$V$500,">="&TODAY(),'Master List'!$V$3:$V$500,"<="&TODAY()+90) | J15: Raspberry 4338 | K15: =COUNTIF('Master List'!$AH$3:$AH$500,"Requested") | L15: =COUNTIF('Master List'!$AH$3:$AH$500,"Sampled") | M15: =COUNTIF('Master List'!$AH$3:$AH$500,"Stocked")
A16: On Hold | B16: =COUNTIF('Master List'!$F$3:$F$500,"On Hold") | J16: Lemon Lime 4336 | K16: =COUNTIF('Master List'!$AI$3:$AI$500,"Requested") | L16: =COUNTIF('Master List'!$AI$3:$AI$500,"Sampled") | M16: =COUNTIF('Master List'!$AI$3:$AI$500,"Stocked")
G17: Region | H17: Count | J17: Pineapple Passion Fruit 4340 | K17: =COUNTIF('Master List'!$AJ$3:$AJ$500,"Requested") | L17: =COUNTIF('Master List'!$AJ$3:$AJ$500,"Sampled") | M17: =COUNTIF('Master List'!$AJ$3:$AJ$500,"Stocked")
A18: List Health | B18: Count | G18: Metro Vancouver | H18: =COUNTIF('Master List'!$C$3:$C$500,"Vancouver")+COUNTIF('Master List'!$C$3:$C$500,"Burnaby")+COUNTIF('Master List'!$C$3:$C$500,"North Vancouver")+COUNTIF('Master List'!$C$3:$C$500,"West Vancouver")+COUNTIF('Master List'!$C$3:$C$500,"Richmond")+COUNTIF('Master List'!$C$3:$C$500,"Surrey")+COUNTIF('Master List'!$C$3:$C$500,"Langley")+COUNTIF('Master List'!$C$3:$C$500,"Coquitlam")+COUNTIF('Master List'!$C$3:$C$500,"New Westminster")
A19: Overdue Next Actions | B19: =COUNTIF('Master List'!$T$3:$T$500,"<"&TODAY()) | G19: Victoria | H19: =COUNTIF('Master List'!$C$3:$C$500,"Victoria")
A20: Stale P1 Over 7 Days | B20: =COUNTIFS('Master List'!$E$3:$E$500,"P1",'Master List'!$R$3:$R$500,">7") | G20: Kelowna | H20: =COUNTIF('Master List'!$C$3:$C$500,"Kelowna")
A21: Verified Rows | B21: =COUNTIF('Master List'!$O$3:$O$500,"Verified Web")+COUNTIF('Master List'!$O$3:$O$500,"Verified Phone")+COUNTIF('Master List'!$O$3:$O$500,"Verified In Person")
A22: Pending Rows | B22: =COUNTIF('Master List'!$O$3:$O$500,"Pending")
A23: Unverified Rows | B23: =COUNTIF('Master List'!$O$3:$O$500,"Unverified")
A25: Every figure and chart refreshes on its own. To change a record, edit its type tab. The Master List, Calendar, tiles and charts all update automatically.

Sheet Activation Calendar
A1: Activation Calendar (every booked activation, soonest first)
A2: Activation Date | B2: Partner | C2: Type | D2: Owner | E2: Cases Committed | F2: Status | G2: Nearby Retail Doors
A3: =IFERROR(INDEX('Master List'!$V$3:$V$500,$I3),"") | B3: =IFERROR(INDEX('Master List'!$B$3:$B$500,$I3),"") | C3: =IFERROR(INDEX('Master List'!$A$3:$A$500,$I3),"") | D3: =IFERROR(INDEX('Master List'!$G$3:$G$500,$I3),"") | E3: =IFERROR(INDEX('Master List'!$W$3:$W$500,$I3),"") | F3: =IFERROR(INDEX('Master List'!$F$3:$F$500,$I3),"") | G3: =IFERROR(INDEX('Master List'!$AF$3:$AF$500,$I3),"") | I3: =IFERROR(MATCH(SMALL('Master List'!$AL$3:$AL$500,ROW()-2),'Master List'!$AL$3:$AL$500,0),"")
A4: =IFERROR(INDEX('Master List'!$V$3:$V$500,$I4),"") | B4: =IFERROR(INDEX('Master List'!$B$3:$B$500,$I4),"") | C4: =IFERROR(INDEX('Master List'!$A$3:$A$500,$I4),"") | D4: =IFERROR(INDEX('Master List'!$G$3:$G$500,$I4),"") | E4: =IFERROR(INDEX('Master List'!$W$3:$W$500,$I4),"") | F4: =IFERROR(INDEX('Master List'!$F$3:$F$500,$I4),"") | G4: =IFERROR(INDEX('Master List'!$AF$3:$AF$500,$I4),"") | I4: =IFERROR(MATCH(SMALL('Master List'!$AL$3:$AL$500,ROW()-2),'Master List'!$AL$3:$AL$500,0),"")
A5: =IFERROR(INDEX('Master List'!$V$3:$V$500,$I5),"") | B5: =IFERROR(INDEX('Master List'!$B$3:$B$500,$I5),"") | C5: =IFERROR(INDEX('Master List'!$A$3:$A$500,$I5),"") | D5: =IFERROR(INDEX('Master List'!$G$3:$G$500,$I5),"") | E5: =IFERROR(INDEX('Master List'!$W$3:$W$500,$I5),"") | F5: =IFERROR(INDEX('Master List'!$F$3:$F$500,$I5),"") | G5: =IFERROR(INDEX('Master List'!$AF$3:$AF$500,$I5),"") | I5: =IFERROR(MATCH(SMALL('Master List'!$AL$3:$AL$500,ROW()-2),'Master List'!$AL$3:$AL$500,0),"")
A6: =IFERROR(INDEX('Master List'!$V$3:$V$500,$I6),"") | B6: =IFERROR(INDEX('Master List'!$B$3:$B$500,$I6),"") | C6: =IFERROR(INDEX('Master List'!$A$3:$A$500,$I6),"") | D6: =IFERROR(INDEX('Master List'!$G$3:$G$500,$I6),"") | E6: =IFERROR(INDEX('Master List'!$W$3:$W$500,$I6),"") | F6: =IFERROR(INDEX('Master List'!$F$3:$F$500,$I6),"") | G6: =IFERROR(INDEX('Master List'!$AF$3:$AF$500,$I6),"") | I6: =IFERROR(MATCH(SMALL('Master List'!$AL$3:$AL$500,ROW()-2),'Master List'!$AL$3:$AL$500,0),"")
A7: =IFERROR(INDEX('Master List'!$V$3:$V$500,$I7),"") | B7: =IFERROR(INDEX('Master List'!$B$3:$B$500,$I7),"") | C7: =IFERROR(INDEX('Master List'!$A$3:$A$500,$I7),"") | D7: =IFERROR(INDEX('Master List'!$G$3:$G$500,$I7),"") | E7: =IFERROR(INDEX('Master List'!$W$3:$W$500,$I7),"") | F7: =IFERROR(INDEX('Master List'!$F$3:$F$500,$I7),"") | G7: =IFERROR(INDEX('Master List'!$AF$3:$AF$500,$I7),"") | I7: =IFERROR(MATCH(SMALL('Master List'!$AL$3:$AL$500,ROW()-2),'Master List'!$AL$3:$AL$500,0),"")
A8: =IFERROR(INDEX('Master List'!$V$3:$V$500,$I8),"") | B8: =IFERROR(INDEX('Master List'!$B$3:$B$500,$I8),"") | C8: =IFERROR(INDEX('Master List'!$A$3:$A$500,$I8),"") | D8: =IFERROR(INDEX('Master List'!$G$3:$G$500,$I8),"") | E8: =IFERROR(INDEX('Master List'!$W$3:$W$500,$I8),"") | F8: =IFERROR(INDEX('Master List'!$F$3:$F$500,$I8),"") | G8: =IFERROR(INDEX('Master List'!$AF$3:$AF$500,$I8),"") | I8: =IFERROR(MATCH(SMALL('Master List'!$AL$3:$AL$500,ROW()-2),'Master List'!$AL$3:$AL$500,0),"")
A9: =IFERROR(INDEX('Master List'!$V$3:$V$500,$I9),"") | B9: =IFERROR(INDEX('Master List'!$B$3:$B$500,$I9),"") | C9: =IFERROR(INDEX('Master List'!$A$3:$A$500,$I9),"") | D9: =IFERROR(INDEX('Master List'!$G$3:$G$500,$I9),"") | E9: =IFERROR(INDEX('Master List'!$W$3:$W$500,$I9),"") | F9: =IFERROR(INDEX('Master List'!$F$3:$F$500,$I9),"") | G9: =IFERROR(INDEX('Master List'!$AF$3:$AF$500,$I9),"") | I9: =IFERROR(MATCH(SMALL('Master List'!$AL$3:$AL$500,ROW()-2),'Master List'!$AL$3:$AL$500,0),"")
A10: =IFERROR(INDEX('Master List'!$V$3:$V$500,$I10),"") | B10: =IFERROR(INDEX('Master List'!$B$3:$B$500,$I10),"") | C10: =IFERROR(INDEX('Master List'!$A$3:$A$500,$I10),"") | D10: =IFERROR(INDEX('Master List'!$G$3:$G$500,$I10),"") | E10: =IFERROR(INDEX('Master List'!$W$3:$W$500,$I10),"") | F10: =IFERROR(INDEX('Master List'!$F$3:$F$500,$I10),"") | G10: =IFERROR(INDEX('Master List'!$AF$3:$AF$500,$I10),"") | I10: =IFERROR(MATCH(SMALL('Master List'!$AL$3:$AL$500,ROW()-2),'Master List'!$AL$3:$AL$500,0),"")
A11: =IFERROR(INDEX('Master List'!$V$3:$V$500,$I11),"") | B11: =IFERROR(INDEX('Master List'!$B$3:$B$500,$I11),"") | C11: =IFERROR(INDEX('Master List'!$A$3:$A$500,$I11),"") | D11: =IFERROR(INDEX('Master List'!$G$3:$G$500,$I11),"") | E11: =IFERROR(INDEX('Master List'!$W$3:$W$500,$I11),"") | F11: =IFERROR(INDEX('Master List'!$F$3:$F$500,$I11),"") | G11: =IFERROR(INDEX('Master List'!$AF$3:$AF$500,$I11),"") | I11: =IFERROR(MATCH(SMALL('Master List'!$AL$3:$AL$500,ROW()-2),'Master List'!$AL$3:$AL$500,0),"")
A12: =IFERROR(INDEX('Master List'!$V$3:$V$500,$I12),"") | B12: =IFERROR(INDEX('Master List'!$B$3:$B$500,$I12),"") | C12: =IFERROR(INDEX('Master List'!$A$3:$A$500,$I12),"") | D12: =IFERROR(INDEX('Master List'!$G$3:$G$500,$I12),"") | E12: =IFERROR(INDEX('Master List'!$W$3:$W$500,$I12),"") | F12: =IFERROR(INDEX('Master List'!$F$3:$F$500,$I12),"") | G12: =IFERROR(INDEX('Master List'!$AF$3:$AF$500,$I12),"") | I12: =IFERROR(MATCH(SMALL('Master List'!$AL$3:$AL$500,ROW()-2),'Master List'!$AL$3:$AL$500,0),"")
A13: =IFERROR(INDEX('Master List'!$V$3:$V$500,$I13),"") | B13: =IFERROR(INDEX('Master List'!$B$3:$B$500,$I13),"") | C13: =IFERROR(INDEX('Master List'!$A$3:$A$500,$I13),"") | D13: =IFERROR(INDEX('Master List'!$G$3:$G$500,$I13),"") | E13: =IFERROR(INDEX('Master List'!$W$3:$W$500,$I13),"") | F13: =IFERROR(INDEX('Master List'!$F$3:$F$500,$I13),"") | G13: =IFERROR(INDEX('Master List'!$AF$3:$AF$500,$I13),"") | I13: =IFERROR(MATCH(SMALL('Master List'!$AL$3:$AL$500,ROW()-2),'Master List'!$AL$3:$AL$500,0),"")
A14: =IFERROR(INDEX('Master List'!$V$3:$V$500,$I14),"") | B14: =IFERROR(INDEX('Master List'!$B$3:$B$500,$I14),"") | C14: =IFERROR(INDEX('Master List'!$A$3:$A$500,$I14),"") | D14: =IFERROR(INDEX('Master List'!$G$3:$G$500,$I14),"") | E14: =IFERROR(INDEX('Master List'!$W$3:$W$500,$I14),"") | F14: =IFERROR(INDEX('Master List'!$F$3:$F$500,$I14),"") | G14: =IFERROR(INDEX('Master List'!$AF$3:$AF$500,$I14),"") | I14: =IFERROR(MATCH(SMALL('Master List'!$AL$3:$AL$500,ROW()-2),'Master List'!$AL$3:$AL$500,0),"")
... A122: =IFERROR(INDEX('Master List'!$V$3:$V$500,$I122),"") | B122: =IFERROR(INDEX('Master List'!$B$3:$B$500,$I122),"") | C122: =IFERROR(INDEX('Master List'!$A$3:$A$500,$I122),"") | D122: =IFERROR(INDEX('Master List'!$G$3:$G$500,$I122),"") | E122: =IFERROR(INDEX('Master List'!$W$3:$W$500,$I122),"") | F122: =IFERROR(INDEX('Master List'!$F$3:$F$500,$I122),"") | G122: =IFERROR(INDEX('Master List'!$AF$3:$AF$500,$I122),"") | I122: =IFERROR(MATCH(SMALL('Master List'!$AL$3:$AL$500,ROW()-2),'Master List'!$AL$3:$AL$500,0),"")

Sheet Master List
A1: Master List (read only, auto updates from the type tabs)
A2: Partnership Type | B2: Partner Name | C2: City | D2: Neighbourhood | E2: Priority | F2: Status | G2: Primary Owner | H2: Contact Name | I2: Role | J2: Contact Email | K2: Contact Phone | L2: Instagram or Website | M2: Audience Size | N2: Audience Source | O2: Source | P2: Warm | Q2: Last Contacted | R2: Days Since Activity | S2: Next Action | T2: Next Action Date | U2: Activation Type | V2: Activation Date | W2: Cases Committed | X2: Cases Delivered | Y2: Cost ($) | Z2: Cost Per Can | AA2: Contra Value ($) | AB2: Deliverables Promised | AC2: Deliverables Received | AD2: What They Want | AE2: Risks | AF2: Nearby Retail Doors | AG2: In BC Tracker? | AH2: Raspberry 4338 | AI2: Lemon Lime 4336 | AJ2: Pineapple Passion Fruit 4340 | AK2: Notes
A3: =IF('Run Clubs'!B3="","","Run Clubs") | B3: =IF('Run Clubs'!B3="","",'Run Clubs'!B3) | C3: =IF('Run Clubs'!D3="","",'Run Clubs'!D3) | D3: =IF('Run Clubs'!E3="","",'Run Clubs'!E3) | E3: =IF('Run Clubs'!F3="","",'Run Clubs'!F3) | F3: =IF('Run Clubs'!G3="","",'Run Clubs'!G3) | G3: =IF('Run Clubs'!H3="","",'Run Clubs'!H3) | H3: =IF('Run Clubs'!I3="","",'Run Clubs'!I3) | I3: =IF('Run Clubs'!J3="","",'Run Clubs'!J3) | J3: =IF('Run Clubs'!K3="","",'Run Clubs'!K3) | ... AK3: =IF('Run Clubs'!AL3="","",'Run Clubs'!AL3) | AL3: =IF(V3="","",V3+ROW()/100000)
A4: =IF('Run Clubs'!B4="","","Run Clubs") | B4: =IF('Run Clubs'!B4="","",'Run Clubs'!B4) | C4: =IF('Run Clubs'!D4="","",'Run Clubs'!D4) | D4: =IF('Run Clubs'!E4="","",'Run Clubs'!E4) | E4: =IF('Run Clubs'!F4="","",'Run Clubs'!F4) | F4: =IF('Run Clubs'!G4="","",'Run Clubs'!G4) | G4: =IF('Run Clubs'!H4="","",'Run Clubs'!H4) | H4: =IF('Run Clubs'!I4="","",'Run Clubs'!I4) | I4: =IF('Run Clubs'!J4="","",'Run Clubs'!J4) | J4: =IF('Run Clubs'!K4="","",'Run Clubs'!K4) | ... AK4: =IF('Run Clubs'!AL4="","",'Run Clubs'!AL4) | AL4: =IF(V4="","",V4+ROW()/100000)
A5: =IF('Run Clubs'!B5="","","Run Clubs") | B5: =IF('Run Clubs'!B5="","",'Run Clubs'!B5) | C5: =IF('Run Clubs'!D5="","",'Run Clubs'!D5) | D5: =IF('Run Clubs'!E5="","",'Run Clubs'!E5) | E5: =IF('Run Clubs'!F5="","",'Run Clubs'!F5) | F5: =IF('Run Clubs'!G5="","",'Run Clubs'!G5) | G5: =IF('Run Clubs'!H5="","",'Run Clubs'!H5) | H5: =IF('Run Clubs'!I5="","",'Run Clubs'!I5) | I5: =IF('Run Clubs'!J5="","",'Run Clubs'!J5) | J5: =IF('Run Clubs'!K5="","",'Run Clubs'!K5) | ... AK5: =IF('Run Clubs'!AL5="","",'Run Clubs'!AL5) | AL5: =IF(V5="","",V5+ROW()/100000)
A6: =IF('Run Clubs'!B6="","","Run Clubs") | B6: =IF('Run Clubs'!B6="","",'Run Clubs'!B6) | C6: =IF('Run Clubs'!D6="","",'Run Clubs'!D6) | D6: =IF('Run Clubs'!E6="","",'Run Clubs'!E6) | E6: =IF('Run Clubs'!F6="","",'Run Clubs'!F6) | F6: =IF('Run Clubs'!G6="","",'Run Clubs'!G6) | G6: =IF('Run Clubs'!H6="","",'Run Clubs'!H6) | H6: =IF('Run Clubs'!I6="","",'Run Clubs'!I6) | I6: =IF('Run Clubs'!J6="","",'Run Clubs'!J6) | J6: =IF('Run Clubs'!K6="","",'Run Clubs'!K6) | ... AK6: =IF('Run Clubs'!AL6="","",'Run Clubs'!AL6) | AL6: =IF(V6="","",V6+ROW()/100000)
A7: =IF('Run Clubs'!B7="","","Run Clubs") | B7: =IF('Run Clubs'!B7="","",'Run Clubs'!B7) | C7: =IF('Run Clubs'!D7="","",'Run Clubs'!D7) | D7: =IF('Run Clubs'!E7="","",'Run Clubs'!E7) | E7: =IF('Run Clubs'!F7="","",'Run Clubs'!F7) | F7: =IF('Run Clubs'!G7="","",'Run Clubs'!G7) | G7: =IF('Run Clubs'!H7="","",'Run Clubs'!H7) | H7: =IF('Run Clubs'!I7="","",'Run Clubs'!I7) | I7: =IF('Run Clubs'!J7="","",'Run Clubs'!J7) | J7: =IF('Run Clubs'!K7="","",'Run Clubs'!K7) | ... AK7: =IF('Run Clubs'!AL7="","",'Run Clubs'!AL7) | AL7: =IF(V7="","",V7+ROW()/100000)
A8: =IF('Run Clubs'!B8="","","Run Clubs") | B8: =IF('Run Clubs'!B8="","",'Run Clubs'!B8) | C8: =IF('Run Clubs'!D8="","",'Run Clubs'!D8) | D8: =IF('Run Clubs'!E8="","",'Run Clubs'!E8) | E8: =IF('Run Clubs'!F8="","",'Run Clubs'!F8) | F8: =IF('Run Clubs'!G8="","",'Run Clubs'!G8) | G8: =IF('Run Clubs'!H8="","",'Run Clubs'!H8) | H8: =IF('Run Clubs'!I8="","",'Run Clubs'!I8) | I8: =IF('Run Clubs'!J8="","",'Run Clubs'!J8) | J8: =IF('Run Clubs'!K8="","",'Run Clubs'!K8) | ... AK8: =IF('Run Clubs'!AL8="","",'Run Clubs'!AL8) | AL8: =IF(V8="","",V8+ROW()/100000)
A9: =IF('Run Clubs'!B9="","","Run Clubs") | B9: =IF('Run Clubs'!B9="","",'Run Clubs'!B9) | C9: =IF('Run Clubs'!D9="","",'Run Clubs'!D9) | D9: =IF('Run Clubs'!E9="","",'Run Clubs'!E9) | E9: =IF('Run Clubs'!F9="","",'Run Clubs'!F9) | F9: =IF('Run Clubs'!G9="","",'Run Clubs'!G9) | G9: =IF('Run Clubs'!H9="","",'Run Clubs'!H9) | H9: =IF('Run Clubs'!I9="","",'Run Clubs'!I9) | I9: =IF('Run Clubs'!J9="","",'Run Clubs'!J9) | J9: =IF('Run Clubs'!K9="","",'Run Clubs'!K9) | ... AK9: =IF('Run Clubs'!AL9="","",'Run Clubs'!AL9) | AL9: =IF(V9="","",V9+ROW()/100000)
A10: =IF('Run Clubs'!B10="","","Run Clubs") | B10: =IF('Run Clubs'!B10="","",'Run Clubs'!B10) | C10: =IF('Run Clubs'!D10="","",'Run Clubs'!D10) | D10: =IF('Run Clubs'!E10="","",'Run Clubs'!E10) | E10: =IF('Run Clubs'!F10="","",'Run Clubs'!F10) | F10: =IF('Run Clubs'!G10="","",'Run Clubs'!G10) | G10: =IF('Run Clubs'!H10="","",'Run Clubs'!H10) | H10: =IF('Run Clubs'!I10="","",'Run Clubs'!I10) | I10: =IF('Run Clubs'!J10="","",'Run Clubs'!J10) | J10: =IF('Run Clubs'!K10="","",'Run Clubs'!K10) | ... AK10: =IF('Run Clubs'!AL10="","",'Run Clubs'!AL10) | AL10: =IF(V10="","",V10+ROW()/100000)
A11: =IF('Run Clubs'!B11="","","Run Clubs") | B11: =IF('Run Clubs'!B11="","",'Run Clubs'!B11) | C11: =IF('Run Clubs'!D11="","",'Run Clubs'!D11) | D11: =IF('Run Clubs'!E11="","",'Run Clubs'!E11) | E11: =IF('Run Clubs'!F11="","",'Run Clubs'!F11) | F11: =IF('Run Clubs'!G11="","",'Run Clubs'!G11) | G11: =IF('Run Clubs'!H11="","",'Run Clubs'!H11) | H11: =IF('Run Clubs'!I11="","",'Run Clubs'!I11) | I11: =IF('Run Clubs'!J11="","",'Run Clubs'!J11) | J11: =IF('Run Clubs'!K11="","",'Run Clubs'!K11) | ... AK11: =IF('Run Clubs'!AL11="","",'Run Clubs'!AL11) | AL11: =IF(V11="","",V11+ROW()/100000)
A12: =IF('Run Clubs'!B12="","","Run Clubs") | B12: =IF('Run Clubs'!B12="","",'Run Clubs'!B12) | C12: =IF('Run Clubs'!D12="","",'Run Clubs'!D12) | D12: =IF('Run Clubs'!E12="","",'Run Clubs'!E12) | E12: =IF('Run Clubs'!F12="","",'Run Clubs'!F12) | F12: =IF('Run Clubs'!G12="","",'Run Clubs'!G12) | G12: =IF('Run Clubs'!H12="","",'Run Clubs'!H12) | H12: =IF('Run Clubs'!I12="","",'Run Clubs'!I12) | I12: =IF('Run Clubs'!J12="","",'Run Clubs'!J12) | J12: =IF('Run Clubs'!K12="","",'Run Clubs'!K12) | ... AK12: =IF('Run Clubs'!AL12="","",'Run Clubs'!AL12) | AL12: =IF(V12="","",V12+ROW()/100000)
A13: =IF('Run Clubs'!B13="","","Run Clubs") | B13: =IF('Run Clubs'!B13="","",'Run Clubs'!B13) | C13: =IF('Run Clubs'!D13="","",'Run Clubs'!D13) | D13: =IF('Run Clubs'!E13="","",'Run Clubs'!E13) | E13: =IF('Run Clubs'!F13="","",'Run Clubs'!F13) | F13: =IF('Run Clubs'!G13="","",'Run Clubs'!G13) | G13: =IF('Run Clubs'!H13="","",'Run Clubs'!H13) | H13: =IF('Run Clubs'!I13="","",'Run Clubs'!I13) | I13: =IF('Run Clubs'!J13="","",'Run Clubs'!J13) | J13: =IF('Run Clubs'!K13="","",'Run Clubs'!K13) | ... AK13: =IF('Run Clubs'!AL13="","",'Run Clubs'!AL13) | AL13: =IF(V13="","",V13+ROW()/100000)
A14: =IF('Run Clubs'!B14="","","Run Clubs") | B14: =IF('Run Clubs'!B14="","",'Run Clubs'!B14) | C14: =IF('Run Clubs'!D14="","",'Run Clubs'!D14) | D14: =IF('Run Clubs'!E14="","",'Run Clubs'!E14) | E14: =IF('Run Clubs'!F14="","",'Run Clubs'!F14) | F14: =IF('Run Clubs'!G14="","",'Run Clubs'!G14) | G14: =IF('Run Clubs'!H14="","",'Run Clubs'!H14) | H14: =IF('Run Clubs'!I14="","",'Run Clubs'!I14) | I14: =IF('Run Clubs'!J14="","",'Run Clubs'!J14) | J14: =IF('Run Clubs'!K14="","",'Run Clubs'!K14) | ... AK14: =IF('Run Clubs'!AL14="","",'Run Clubs'!AL14) | AL14: =IF(V14="","",V14+ROW()/100000)
... A32: =IF('Run Clubs'!B32="","","Run Clubs") | B32: =IF('Run Clubs'!B32="","",'Run Clubs'!B32) | C32: =IF('Run Clubs'!D32="","",'Run Clubs'!D32) | D32: =IF('Run Clubs'!E32="","",'Run Clubs'!E32) | E32: =IF('Run Clubs'!F32="","",'Run Clubs'!F32) | F32: =IF('Run Clubs'!G32="","",'Run Clubs'!G32) | G32: =IF('Run Clubs'!H32="","",'Run Clubs'!H32) | H32: =IF('Run Clubs'!I32="","",'Run Clubs'!I32) | I32: =IF('Run Clubs'!J32="","",'Run Clubs'!J32) | J32: =IF('Run Clubs'!K32="","",'Run Clubs'!K32) | ... AK32: =IF('Run Clubs'!AL32="","",'Run Clubs'!AL32) | AL32: =IF(V32="","",V32+ROW()/100000)
A33: =IF('Gyms & Studios'!B3="","","Gyms & Studios") | B33: =IF('Gyms & Studios'!B3="","",'Gyms & Studios'!B3) | C33: =IF('Gyms & Studios'!D3="","",'Gyms & Studios'!D3) | D33: =IF('Gyms & Studios'!E3="","",'Gyms & Studios'!E3) | E33: =IF('Gyms & Studios'!F3="","",'Gyms & Studios'!F3) | F33: =IF('Gyms & Studios'!G3="","",'Gyms & Studios'!G3) | G33: =IF('Gyms & Studios'!H3="","",'Gyms & Studios'!H3) | H33: =IF('Gyms & Studios'!I3="","",'Gyms & Studios'!I3) | I33: =IF('Gyms & Studios'!J3="","",'Gyms & Studios'!J3) | J33: =IF('Gyms & Studios'!K3="","",'Gyms & Studios'!K3) | ... AK33: =IF('Gyms & Studios'!AL3="","",'Gyms & Studios'!AL3) | AL33: =IF(V33="","",V33+ROW()/100000)
A34: =IF('Gyms & Studios'!B4="","","Gyms & Studios") | B34: =IF('Gyms & Studios'!B4="","",'Gyms & Studios'!B4) | C34: =IF('Gyms & Studios'!D4="","",'Gyms & Studios'!D4) | D34: =IF('Gyms & Studios'!E4="","",'Gyms & Studios'!E4) | E34: =IF('Gyms & Studios'!F4="","",'Gyms & Studios'!F4) | F34: =IF('Gyms & Studios'!G4="","",'Gyms & Studios'!G4) | G34: =IF('Gyms & Studios'!H4="","",'Gyms & Studios'!H4) | H34: =IF('Gyms & Studios'!I4="","",'Gyms & Studios'!I4) | I34: =IF('Gyms & Studios'!J4="","",'Gyms & Studios'!J4) | J34: =IF('Gyms & Studios'!K4="","",'Gyms & Studios'!K4) | ... AK34: =IF('Gyms & Studios'!AL4="","",'Gyms & Studios'!AL4) | AL34: =IF(V34="","",V34+ROW()/100000)
A35: =IF('Gyms & Studios'!B5="","","Gyms & Studios") | B35: =IF('Gyms & Studios'!B5="","",'Gyms & Studios'!B5) | C35: =IF('Gyms & Studios'!D5="","",'Gyms & Studios'!D5) | D35: =IF('Gyms & Studios'!E5="","",'Gyms & Studios'!E5) | E35: =IF('Gyms & Studios'!F5="","",'Gyms & Studios'!F5) | F35: =IF('Gyms & Studios'!G5="","",'Gyms & Studios'!G5) | G35: =IF('Gyms & Studios'!H5="","",'Gyms & Studios'!H5) | H35: =IF('Gyms & Studios'!I5="","",'Gyms & Studios'!I5) | I35: =IF('Gyms & Studios'!J5="","",'Gyms & Studios'!J5) | J35: =IF('Gyms & Studios'!K5="","",'Gyms & Studios'!K5) | ... AK35: =IF('Gyms & Studios'!AL5="","",'Gyms & Studios'!AL5) | AL35: =IF(V35="","",V35+ROW()/100000)
A36: =IF('Gyms & Studios'!B6="","","Gyms & Studios") | B36: =IF('Gyms & Studios'!B6="","",'Gyms & Studios'!B6) | C36: =IF('Gyms & Studios'!D6="","",'Gyms & Studios'!D6) | D36: =IF('Gyms & Studios'!E6="","",'Gyms & Studios'!E6) | E36: =IF('Gyms & Studios'!F6="","",'Gyms & Studios'!F6) | F36: =IF('Gyms & Studios'!G6="","",'Gyms & Studios'!G6) | G36: =IF('Gyms & Studios'!H6="","",'Gyms & Studios'!H6) | H36: =IF('Gyms & Studios'!I6="","",'Gyms & Studios'!I6) | I36: =IF('Gyms & Studios'!J6="","",'Gyms & Studios'!J6) | J36: =IF('Gyms & Studios'!K6="","",'Gyms & Studios'!K6) | ... AK36: =IF('Gyms & Studios'!AL6="","",'Gyms & Studios'!AL6) | AL36: =IF(V36="","",V36+ROW()/100000)
A37: =IF('Gyms & Studios'!B7="","","Gyms & Studios") | B37: =IF('Gyms & Studios'!B7="","",'Gyms & Studios'!B7) | C37: =IF('Gyms & Studios'!D7="","",'Gyms & Studios'!D7) | D37: =IF('Gyms & Studios'!E7="","",'Gyms & Studios'!E7) | E37: =IF('Gyms & Studios'!F7="","",'Gyms & Studios'!F7) | F37: =IF('Gyms & Studios'!G7="","",'Gyms & Studios'!G7) | G37: =IF('Gyms & Studios'!H7="","",'Gyms & Studios'!H7) | H37: =IF('Gyms & Studios'!I7="","",'Gyms & Studios'!I7) | I37: =IF('Gyms & Studios'!J7="","",'Gyms & Studios'!J7) | J37: =IF('Gyms & Studios'!K7="","",'Gyms & Studios'!K7) | ... AK37: =IF('Gyms & Studios'!AL7="","",'Gyms & Studios'!AL7) | AL37: =IF(V37="","",V37+ROW()/100000)
A38: =IF('Gyms & Studios'!B8="","","Gyms & Studios") | B38: =IF('Gyms & Studios'!B8="","",'Gyms & Studios'!B8) | C38: =IF('Gyms & Studios'!D8="","",'Gyms & Studios'!D8) | D38: =IF('Gyms & Studios'!E8="","",'Gyms & Studios'!E8) | E38: =IF('Gyms & Studios'!F8="","",'Gyms & Studios'!F8) | F38: =IF('Gyms & Studios'!G8="","",'Gyms & Studios'!G8) | G38: =IF('Gyms & Studios'!H8="","",'Gyms & Studios'!H8) | H38: =IF('Gyms & Studios'!I8="","",'Gyms & Studios'!I8) | I38: =IF('Gyms & Studios'!J8="","",'Gyms & Studios'!J8) | J38: =IF('Gyms & Studios'!K8="","",'Gyms & Studios'!K8) | ... AK38: =IF('Gyms & Studios'!AL8="","",'Gyms & Studios'!AL8) | AL38: =IF(V38="","",V38+ROW()/100000)
A39: =IF('Gyms & Studios'!B9="","","Gyms & Studios") | B39: =IF('Gyms & Studios'!B9="","",'Gyms & Studios'!B9) | C39: =IF('Gyms & Studios'!D9="","",'Gyms & Studios'!D9) | D39: =IF('Gyms & Studios'!E9="","",'Gyms & Studios'!E9) | E39: =IF('Gyms & Studios'!F9="","",'Gyms & Studios'!F9) | F39: =IF('Gyms & Studios'!G9="","",'Gyms & Studios'!G9) | G39: =IF('Gyms & Studios'!H9="","",'Gyms & Studios'!H9) | H39: =IF('Gyms & Studios'!I9="","",'Gyms & Studios'!I9) | I39: =IF('Gyms & Studios'!J9="","",'Gyms & Studios'!J9) | J39: =IF('Gyms & Studios'!K9="","",'Gyms & Studios'!K9) | ... AK39: =IF('Gyms & Studios'!AL9="","",'Gyms & Studios'!AL9) | AL39: =IF(V39="","",V39+ROW()/100000)
A40: =IF('Gyms & Studios'!B10="","","Gyms & Studios") | B40: =IF('Gyms & Studios'!B10="","",'Gyms & Studios'!B10) | C40: =IF('Gyms & Studios'!D10="","",'Gyms & Studios'!D10) | D40: =IF('Gyms & Studios'!E10="","",'Gyms & Studios'!E10) | E40: =IF('Gyms & Studios'!F10="","",'Gyms & Studios'!F10) | F40: =IF('Gyms & Studios'!G10="","",'Gyms & Studios'!G10) | G40: =IF('Gyms & Studios'!H10="","",'Gyms & Studios'!H10) | H40: =IF('Gyms & Studios'!I10="","",'Gyms & Studios'!I10) | I40: =IF('Gyms & Studios'!J10="","",'Gyms & Studios'!J10) | J40: =IF('Gyms & Studios'!K10="","",'Gyms & Studios'!K10) | ... AK40: =IF('Gyms & Studios'!AL10="","",'Gyms & Studios'!AL10) | AL40: =IF(V40="","",V40+ROW()/100000)
A41: =IF('Gyms & Studios'!B11="","","Gyms & Studios") | B41: =IF('Gyms & Studios'!B11="","",'Gyms & Studios'!B11) | C41: =IF('Gyms & Studios'!D11="","",'Gyms & Studios'!D11) | D41: =IF('Gyms & Studios'!E11="","",'Gyms & Studios'!E11) | E41: =IF('Gyms & Studios'!F11="","",'Gyms & Studios'!F11) | F41: =IF('Gyms & Studios'!G11="","",'Gyms & Studios'!G11) | G41: =IF('Gyms & Studios'!H11="","",'Gyms & Studios'!H11) | H41: =IF('Gyms & Studios'!I11="","",'Gyms & Studios'!I11) | I41: =IF('Gyms & Studios'!J11="","",'Gyms & Studios'!J11) | J41: =IF('Gyms & Studios'!K11="","",'Gyms & Studios'!K11) | ... AK41: =IF('Gyms & Studios'!AL11="","",'Gyms & Studios'!AL11) | AL41: =IF(V41="","",V41+ROW()/100000)
A42: =IF('Gyms & Studios'!B12="","","Gyms & Studios") | B42: =IF('Gyms & Studios'!B12="","",'Gyms & Studios'!B12) | C42: =IF('Gyms & Studios'!D12="","",'Gyms & Studios'!D12) | D42: =IF('Gyms & Studios'!E12="","",'Gyms & Studios'!E12) | E42: =IF('Gyms & Studios'!F12="","",'Gyms & Studios'!F12) | F42: =IF('Gyms & Studios'!G12="","",'Gyms & Studios'!G12) | G42: =IF('Gyms & Studios'!H12="","",'Gyms & Studios'!H12) | H42: =IF('Gyms & Studios'!I12="","",'Gyms & Studios'!I12) | I42: =IF('Gyms & Studios'!J12="","",'Gyms & Studios'!J12) | J42: =IF('Gyms & Studios'!K12="","",'Gyms & Studios'!K12) | ... AK42: =IF('Gyms & Studios'!AL12="","",'Gyms & Studios'!AL12) | AL42: =IF(V42="","",V42+ROW()/100000)
A43: =IF('Gyms & Studios'!B13="","","Gyms & Studios") | B43: =IF('Gyms & Studios'!B13="","",'Gyms & Studios'!B13) | C43: =IF('Gyms & Studios'!D13="","",'Gyms & Studios'!D13) | D43: =IF('Gyms & Studios'!E13="","",'Gyms & Studios'!E13) | E43: =IF('Gyms & Studios'!F13="","",'Gyms & Studios'!F13) | F43: =IF('Gyms & Studios'!G13="","",'Gyms & Studios'!G13) | G43: =IF('Gyms & Studios'!H13="","",'Gyms & Studios'!H13) | H43: =IF('Gyms & Studios'!I13="","",'Gyms & Studios'!I13) | I43: =IF('Gyms & Studios'!J13="","",'Gyms & Studios'!J13) | J43: =IF('Gyms & Studios'!K13="","",'Gyms & Studios'!K13) | ... AK43: =IF('Gyms & Studios'!AL13="","",'Gyms & Studios'!AL13) | AL43: =IF(V43="","",V43+ROW()/100000)
A44: =IF('Gyms & Studios'!B14="","","Gyms & Studios") | B44: =IF('Gyms & Studios'!B14="","",'Gyms & Studios'!B14) | C44: =IF('Gyms & Studios'!D14="","",'Gyms & Studios'!D14) | D44: =IF('Gyms & Studios'!E14="","",'Gyms & Studios'!E14) | E44: =IF('Gyms & Studios'!F14="","",'Gyms & Studios'!F14) | F44: =IF('Gyms & Studios'!G14="","",'Gyms & Studios'!G14) | G44: =IF('Gyms & Studios'!H14="","",'Gyms & Studios'!H14) | H44: =IF('Gyms & Studios'!I14="","",'Gyms & Studios'!I14) | I44: =IF('Gyms & Studios'!J14="","",'Gyms & Studios'!J14) | J44: =IF('Gyms & Studios'!K14="","",'Gyms & Studios'!K14) | ... AK44: =IF('Gyms & Studios'!AL14="","",'Gyms & Studios'!AL14) | AL44: =IF(V44="","",V44+ROW()/100000)
... A62: =IF('Gyms & Studios'!B32="","","Gyms & Studios") | B62: =IF('Gyms & Studios'!B32="","",'Gyms & Studios'!B32) | C62: =IF('Gyms & Studios'!D32="","",'Gyms & Studios'!D32) | D62: =IF('Gyms & Studios'!E32="","",'Gyms & Studios'!E32) | E62: =IF('Gyms & Studios'!F32="","",'Gyms & Studios'!F32) | F62: =IF('Gyms & Studios'!G32="","",'Gyms & Studios'!G32) | G62: =IF('Gyms & Studios'!H32="","",'Gyms & Studios'!H32) | H62: =IF('Gyms & Studios'!I32="","",'Gyms & Studios'!I32) | I62: =IF('Gyms & Studios'!J32="","",'Gyms & Studios'!J32) | J62: =IF('Gyms & Studios'!K32="","",'Gyms & Studios'!K32) | ... AK62: =IF('Gyms & Studios'!AL32="","",'Gyms & Studios'!AL32) | AL62: =IF(V62="","",V62+ROW()/100000)
A63: =IF('Events & Festivals'!B3="","","Events & Festivals") | B63: =IF('Events & Festivals'!B3="","",'Events & Festivals'!B3) | C63: =IF('Events & Festivals'!D3="","",'Events & Festivals'!D3) | D63: =IF('Events & Festivals'!E3="","",'Events & Festivals'!E3) | E63: =IF('Events & Festivals'!F3="","",'Events & Festivals'!F3) | F63: =IF('Events & Festivals'!G3="","",'Events & Festivals'!G3) | G63: =IF('Events & Festivals'!H3="","",'Events & Festivals'!H3) | H63: =IF('Events & Festivals'!I3="","",'Events & Festivals'!I3) | I63: =IF('Events & Festivals'!J3="","",'Events & Festivals'!J3) | J63: =IF('Events & Festivals'!K3="","",'Events & Festivals'!K3) | ... AK63: =IF('Events & Festivals'!AL3="","",'Events & Festivals'!AL3) | AL63: =IF(V63="","",V63+ROW()/100000)
A64: =IF('Events & Festivals'!B4="","","Events & Festivals") | B64: =IF('Events & Festivals'!B4="","",'Events & Festivals'!B4) | C64: =IF('Events & Festivals'!D4="","",'Events & Festivals'!D4) | D64: =IF('Events & Festivals'!E4="","",'Events & Festivals'!E4) | E64: =IF('Events & Festivals'!F4="","",'Events & Festivals'!F4) | F64: =IF('Events & Festivals'!G4="","",'Events & Festivals'!G4) | G64: =IF('Events & Festivals'!H4="","",'Events & Festivals'!H4) | H64: =IF('Events & Festivals'!I4="","",'Events & Festivals'!I4) | I64: =IF('Events & Festivals'!J4="","",'Events & Festivals'!J4) | J64: =IF('Events & Festivals'!K4="","",'Events & Festivals'!K4) | ... AK64: =IF('Events & Festivals'!AL4="","",'Events & Festivals'!AL4) | AL64: =IF(V64="","",V64+ROW()/100000)
A65: =IF('Events & Festivals'!B5="","","Events & Festivals") | B65: =IF('Events & Festivals'!B5="","",'Events & Festivals'!B5) | C65: =IF('Events & Festivals'!D5="","",'Events & Festivals'!D5) | D65: =IF('Events & Festivals'!E5="","",'Events & Festivals'!E5) | E65: =IF('Events & Festivals'!F5="","",'Events & Festivals'!F5) | F65: =IF('Events & Festivals'!G5="","",'Events & Festivals'!G5) | G65: =IF('Events & Festivals'!H5="","",'Events & Festivals'!H5) | H65: =IF('Events & Festivals'!I5="","",'Events & Festivals'!I5) | I65: =IF('Events & Festivals'!J5="","",'Events & Festivals'!J5) | J65: =IF('Events & Festivals'!K5="","",'Events & Festivals'!K5) | ... AK65: =IF('Events & Festivals'!AL5="","",'Events & Festivals'!AL5) | AL65: =IF(V65="","",V65+ROW()/100000)
A66: =IF('Events & Festivals'!B6="","","Events & Festivals") | B66: =IF('Events & Festivals'!B6="","",'Events & Festivals'!B6) | C66: =IF('Events & Festivals'!D6="","",'Events & Festivals'!D6) | D66: =IF('Events & Festivals'!E6="","",'Events & Festivals'!E6) | E66: =IF('Events & Festivals'!F6="","",'Events & Festivals'!F6) | F66: =IF('Events & Festivals'!G6="","",'Events & Festivals'!G6) | G66: =IF('Events & Festivals'!H6="","",'Events & Festivals'!H6) | H66: =IF('Events & Festivals'!I6="","",'Events & Festivals'!I6) | I66: =IF('Events & Festivals'!J6="","",'Events & Festivals'!J6) | J66: =IF('Events & Festivals'!K6="","",'Events & Festivals'!K6) | ... AK66: =IF('Events & Festivals'!AL6="","",'Events & Festivals'!AL6) | AL66: =IF(V66="","",V66+ROW()/100000)
A67: =IF('Events & Festivals'!B7="","","Events & Festivals") | B67: =IF('Events & Festivals'!B7="","",'Events & Festivals'!B7) | C67: =IF('Events & Festivals'!D7="","",'Events & Festivals'!D7) | D67: =IF('Events & Festivals'!E7="","",'Events & Festivals'!E7) | E67: =IF('Events & Festivals'!F7="","",'Events & Festivals'!F7) | F67: =IF('Events & Festivals'!G7="","",'Events & Festivals'!G7) | G67: =IF('Events & Festivals'!H7="","",'Events & Festivals'!H7) | H67: =IF('Events & Festivals'!I7="","",'Events & Festivals'!I7) | I67: =IF('Events & Festivals'!J7="","",'Events & Festivals'!J7) | J67: =IF('Events & Festivals'!K7="","",'Events & Festivals'!K7) | ... AK67: =IF('Events & Festivals'!AL7="","",'Events & Festivals'!AL7) | AL67: =IF(V67="","",V67+ROW()/100000)
A68: =IF('Events & Festivals'!B8="","","Events & Festivals") | B68: =IF('Events & Festivals'!B8="","",'Events & Festivals'!B8) | C68: =IF('Events & Festivals'!D8="","",'Events & Festivals'!D8) | D68: =IF('Events & Festivals'!E8="","",'Events & Festivals'!E8) | E68: =IF('Events & Festivals'!F8="","",'Events & Festivals'!F8) | F68: =IF('Events & Festivals'!G8="","",'Events & Festivals'!G8) | G68: =IF('Events & Festivals'!H8="","",'Events & Festivals'!H8) | H68: =IF('Events & Festivals'!I8="","",'Events & Festivals'!I8) | I68: =IF('Events & Festivals'!J8="","",'Events & Festivals'!J8) | J68: =IF('Events & Festivals'!K8="","",'Events & Festivals'!K8) | ... AK68: =IF('Events & Festivals'!AL8="","",'Events & Festivals'!AL8) | AL68: =IF(V68="","",V68+ROW()/100000)
A69: =IF('Events & Festivals'!B9="","","Events & Festivals") | B69: =IF('Events & Festivals'!B9="","",'Events & Festivals'!B9) | C69: =IF('Events & Festivals'!D9="","",'Events & Festivals'!D9) | D69: =IF('Events & Festivals'!E9="","",'Events & Festivals'!E9) | E69: =IF('Events & Festivals'!F9="","",'Events & Festivals'!F9) | F69: =IF('Events & Festivals'!G9="","",'Events & Festivals'!G9) | G69: =IF('Events & Festivals'!H9="","",'Events & Festivals'!H9) | H69: =IF('Events & Festivals'!I9="","",'Events & Festivals'!I9) | I69: =IF('Events & Festivals'!J9="","",'Events & Festivals'!J9) | J69: =IF('Events & Festivals'!K9="","",'Events & Festivals'!K9) | ... AK69: =IF('Events & Festivals'!AL9="","",'Events & Festivals'!AL9) | AL69: =IF(V69="","",V69+ROW()/100000)
A70: =IF('Events & Festivals'!B10="","","Events & Festivals") | B70: =IF('Events & Festivals'!B10="","",'Events & Festivals'!B10) | C70: =IF('Events & Festivals'!D10="","",'Events & Festivals'!D10) | D70: =IF('Events & Festivals'!E10="","",'Events & Festivals'!E10) | E70: =IF('Events & Festivals'!F10="","",'Events & Festivals'!F10) | F70: =IF('Events & Festivals'!G10="","",'Events & Festivals'!G10) | G70: =IF('Events & Festivals'!H10="","",'Events & Festivals'!H10) | H70: =IF('Events & Festivals'!I10="","",'Events & Festivals'!I10) | I70: =IF('Events & Festivals'!J10="","",'Events & Festivals'!J10) | J70: =IF('Events & Festivals'!K10="","",'Events & Festivals'!K10) | ... AK70: =IF('Events & Festivals'!AL10="","",'Events & Festivals'!AL10) | AL70: =IF(V70="","",V70+ROW()/100000)
A71: =IF('Events & Festivals'!B11="","","Events & Festivals") | B71: =IF('Events & Festivals'!B11="","",'Events & Festivals'!B11) | C71: =IF('Events & Festivals'!D11="","",'Events & Festivals'!D11) | D71: =IF('Events & Festivals'!E11="","",'Events & Festivals'!E11) | E71: =IF('Events & Festivals'!F11="","",'Events & Festivals'!F11) | F71: =IF('Events & Festivals'!G11="","",'Events & Festivals'!G11) | G71: =IF('Events & Festivals'!H11="","",'Events & Festivals'!H11) | H71: =IF('Events & Festivals'!I11="","",'Events & Festivals'!I11) | I71: =IF('Events & Festivals'!J11="","",'Events & Festivals'!J11) | J71: =IF('Events & Festivals'!K11="","",'Events & Festivals'!K11) | ... AK71: =IF('Events & Festivals'!AL11="","",'Events & Festivals'!AL11) | AL71: =IF(V71="","",V71+ROW()/100000)
A72: =IF('Events & Festivals'!B12="","","Events & Festivals") | B72: =IF('Events & Festivals'!B12="","",'Events & Festivals'!B12) | C72: =IF('Events & Festivals'!D12="","",'Events & Festivals'!D12) | D72: =IF('Events & Festivals'!E12="","",'Events & Festivals'!E12) | E72: =IF('Events & Festivals'!F12="","",'Events & Festivals'!F12) | F72: =IF('Events & Festivals'!G12="","",'Events & Festivals'!G12) | G72: =IF('Events & Festivals'!H12="","",'Events & Festivals'!H12) | H72: =IF('Events & Festivals'!I12="","",'Events & Festivals'!I12) | I72: =IF('Events & Festivals'!J12="","",'Events & Festivals'!J12) | J72: =IF('Events & Festivals'!K12="","",'Events & Festivals'!K12) | ... AK72: =IF('Events & Festivals'!AL12="","",'Events & Festivals'!AL12) | AL72: =IF(V72="","",V72+ROW()/100000)
A73: =IF('Events & Festivals'!B13="","","Events & Festivals") | B73: =IF('Events & Festivals'!B13="","",'Events & Festivals'!B13) | C73: =IF('Events & Festivals'!D13="","",'Events & Festivals'!D13) | D73: =IF('Events & Festivals'!E13="","",'Events & Festivals'!E13) | E73: =IF('Events & Festivals'!F13="","",'Events & Festivals'!F13) | F73: =IF('Events & Festivals'!G13="","",'Events & Festivals'!G13) | G73: =IF('Events & Festivals'!H13="","",'Events & Festivals'!H13) | H73: =IF('Events & Festivals'!I13="","",'Events & Festivals'!I13) | I73: =IF('Events & Festivals'!J13="","",'Events & Festivals'!J13) | J73: =IF('Events & Festivals'!K13="","",'Events & Festivals'!K13) | ... AK73: =IF('Events & Festivals'!AL13="","",'Events & Festivals'!AL13) | AL73: =IF(V73="","",V73+ROW()/100000)
A74: =IF('Events & Festivals'!B14="","","Events & Festivals") | B74: =IF('Events & Festivals'!B14="","",'Events & Festivals'!B14) | C74: =IF('Events & Festivals'!D14="","",'Events & Festivals'!D14) | D74: =IF('Events & Festivals'!E14="","",'Events & Festivals'!E14) | E74: =IF('Events & Festivals'!F14="","",'Events & Festivals'!F14) | F74: =IF('Events & Festivals'!G14="","",'Events & Festivals'!G14) | G74: =IF('Events & Festivals'!H14="","",'Events & Festivals'!H14) | H74: =IF('Events & Festivals'!I14="","",'Events & Festivals'!I14) | I74: =IF('Events & Festivals'!J14="","",'Events & Festivals'!J14) | J74: =IF('Events & Festivals'!K14="","",'Events & Festivals'!K14) | ... AK74: =IF('Events & Festivals'!AL14="","",'Events & Festivals'!AL14) | AL74: =IF(V74="","",V74+ROW()/100000)
...

Sheet Type Summary
A1: Type Summary
A2: Partnership Type | B2: Target (draft) | C2: Partners | D2: P1 | E2: P2 | F2: P3 | G2: In Conversation | H2: Agreed | I2: Activated | J2: Cases Committed | K2: % to Target
A3: Run Clubs | B3: 10 | C3: =COUNTA('Run Clubs'!$B$3:$B$32) | D3: =COUNTIF('Run Clubs'!$F$3:$F$32,"P1") | E3: =COUNTIF('Run Clubs'!$F$3:$F$32,"P2") | F3: =COUNTIF('Run Clubs'!$F$3:$F$32,"P3") | G3: =COUNTIF('Run Clubs'!$G$3:$G$32,"In Conversation") | H3: =COUNTIF('Run Clubs'!$G$3:$G$32,"Agreed") | I3: =COUNTIF('Run Clubs'!$G$3:$G$32,"Activated")+COUNTIF('Run Clubs'!$G$3:$G$32,"Repeat Partner") | J3: =SUM('Run Clubs'!$X$3:$X$32) | K3: =IFERROR(C3/B3,0)
A4: Gyms & Studios | B4: 10 | C4: =COUNTA('Gyms & Studios'!$B$3:$B$32) | D4: =COUNTIF('Gyms & Studios'!$F$3:$F$32,"P1") | E4: =COUNTIF('Gyms & Studios'!$F$3:$F$32,"P2") | F4: =COUNTIF('Gyms & Studios'!$F$3:$F$32,"P3") | G4: =COUNTIF('Gyms & Studios'!$G$3:$G$32,"In Conversation") | H4: =COUNTIF('Gyms & Studios'!$G$3:$G$32,"Agreed") | I4: =COUNTIF('Gyms & Studios'!$G$3:$G$32,"Activated")+COUNTIF('Gyms & Studios'!$G$3:$G$32,"Repeat Partner") | J4: =SUM('Gyms & Studios'!$X$3:$X$32) | K4: =IFERROR(C4/B4,0)
A5: Events & Festivals | B5: 8 | C5: =COUNTA('Events & Festivals'!$B$3:$B$32) | D5: =COUNTIF('Events & Festivals'!$F$3:$F$32,"P1") | E5: =COUNTIF('Events & Festivals'!$F$3:$F$32,"P2") | F5: =COUNTIF('Events & Festivals'!$F$3:$F$32,"P3") | G5: =COUNTIF('Events & Festivals'!$G$3:$G$32,"In Conversation") | H5: =COUNTIF('Events & Festivals'!$G$3:$G$32,"Agreed") | I5: =COUNTIF('Events & Festivals'!$G$3:$G$32,"Activated")+COUNTIF('Events & Festivals'!$G$3:$G$32,"Repeat Partner") | J5: =SUM('Events & Festivals'!$X$3:$X$32) | K5: =IFERROR(C5/B5,0)
A6: Sports Teams & Leagues | B6: 6 | C6: =COUNTA('Sports Teams & Leagues'!$B$3:$B$32) | D6: =COUNTIF('Sports Teams & Leagues'!$F$3:$F$32,"P1") | E6: =COUNTIF('Sports Teams & Leagues'!$F$3:$F$32,"P2") | F6: =COUNTIF('Sports Teams & Leagues'!$F$3:$F$32,"P3") | G6: =COUNTIF('Sports Teams & Leagues'!$G$3:$G$32,"In Conversation") | H6: =COUNTIF('Sports Teams & Leagues'!$G$3:$G$32,"Agreed") | I6: =COUNTIF('Sports Teams & Leagues'!$G$3:$G$32,"Activated")+COUNTIF('Sports Teams & Leagues'!$G$3:$G$32,"Repeat Partner") | J6: =SUM('Sports Teams & Leagues'!$X$3:$X$32) | K6: =IFERROR(C6/B6,0)
A7: Campus & Student Groups | B7: 6 | C7: =COUNTA('Campus & Student Groups'!$B$3:$B$32) | D7: =COUNTIF('Campus & Student Groups'!$F$3:$F$32,"P1") | E7: =COUNTIF('Campus & Student Groups'!$F$3:$F$32,"P2") | F7: =COUNTIF('Campus & Student Groups'!$F$3:$F$32,"P3") | G7: =COUNTIF('Campus & Student Groups'!$G$3:$G$32,"In Conversation") | H7: =COUNTIF('Campus & Student Groups'!$G$3:$G$32,"Agreed") | I7: =COUNTIF('Campus & Student Groups'!$G$3:$G$32,"Activated")+COUNTIF('Campus & Student Groups'!$G$3:$G$32,"Repeat Partner") | J7: =SUM('Campus & Student Groups'!$X$3:$X$32) | K7: =IFERROR(C7/B7,0)
A8: Wellness & Recovery | B8: 6 | C8: =COUNTA('Wellness & Recovery'!$B$3:$B$32) | D8: =COUNTIF('Wellness & Recovery'!$F$3:$F$32,"P1") | E8: =COUNTIF('Wellness & Recovery'!$F$3:$F$32,"P2") | F8: =COUNTIF('Wellness & Recovery'!$F$3:$F$32,"P3") | G8: =COUNTIF('Wellness & Recovery'!$G$3:$G$32,"In Conversation") | H8: =COUNTIF('Wellness & Recovery'!$G$3:$G$32,"Agreed") | I8: =COUNTIF('Wellness & Recovery'!$G$3:$G$32,"Activated")+COUNTIF('Wellness & Recovery'!$G$3:$G$32,"Repeat Partner") | J8: =SUM('Wellness & Recovery'!$X$3:$X$32) | K8: =IFERROR(C8/B8,0)
A9: Ambassadors & Creators | B9: 8 | C9: =COUNTA('Ambassadors & Creators'!$B$3:$B$32) | D9: =COUNTIF('Ambassadors & Creators'!$F$3:$F$32,"P1") | E9: =COUNTIF('Ambassadors & Creators'!$F$3:$F$32,"P2") | F9: =COUNTIF('Ambassadors & Creators'!$F$3:$F$32,"P3") | G9: =COUNTIF('Ambassadors & Creators'!$G$3:$G$32,"In Conversation") | H9: =COUNTIF('Ambassadors & Creators'!$G$3:$G$32,"Agreed") | I9: =COUNTIF('Ambassadors & Creators'!$G$3:$G$32,"Activated")+COUNTIF('Ambassadors & Creators'!$G$3:$G$32,"Repeat Partner") | J9: =SUM('Ambassadors & Creators'!$X$3:$X$32) | K9: =IFERROR(C9/B9,0)
A10: Charity & Causes | B10: 4 | C10: =COUNTA('Charity & Causes'!$B$3:$B$32) | D10: =COUNTIF('Charity & Causes'!$F$3:$F$32,"P1") | E10: =COUNTIF('Charity & Causes'!$F$3:$F$32,"P2") | F10: =COUNTIF('Charity & Causes'!$F$3:$F$32,"P3") | G10: =COUNTIF('Charity & Causes'!$G$3:$G$32,"In Conversation") | H10: =COUNTIF('Charity & Causes'!$G$3:$G$32,"Agreed") | I10: =COUNTIF('Charity & Causes'!$G$3:$G$32,"Activated")+COUNTIF('Charity & Causes'!$G$3:$G$32,"Repeat Partner") | J10: =SUM('Charity & Causes'!$X$3:$X$32) | K10: =IFERROR(C10/B10,0)
A11: Total | B11: =SUM(B3:B10) | C11: =SUM(C3:C10) | D11: =SUM(D3:D10) | E11: =SUM(E3:E10) | F11: =SUM(F3:F10) | G11: =SUM(G3:G10) | H11: =SUM(H3:H10) | I11: =SUM(I3:I10) | J11: =SUM(J3:J10) | K11: =IFERROR(C11/B11,0)
A13: Targets are a starting draft for Louis to confirm. Edit the Target column any time.

Sheet Budget
A1: Budget
A2: Partnership Type | B2: Total Budget ($) | C2: Committed ($) | D2: Spent ($) | E2: Remaining ($) | F2: % Spent
A3: Run Clubs | B3: 0 | C3: 0 | D3: =SUM('Run Clubs'!$Z$3:$Z$32) | E3: =B3-D3 | F3: =IFERROR(D3/B3,0)
A4: Gyms & Studios | B4: 0 | C4: 0 | D4: =SUM('Gyms & Studios'!$Z$3:$Z$32) | E4: =B4-D4 | F4: =IFERROR(D4/B4,0)
A5: Events & Festivals | B5: 0 | C5: 0 | D5: =SUM('Events & Festivals'!$Z$3:$Z$32) | E5: =B5-D5 | F5: =IFERROR(D5/B5,0)
A6: Sports Teams & Leagues | B6: 0 | C6: 0 | D6: =SUM('Sports Teams & Leagues'!$Z$3:$Z$32) | E6: =B6-D6 | F6: =IFERROR(D6/B6,0)
A7: Campus & Student Groups | B7: 0 | C7: 0 | D7: =SUM('Campus & Student Groups'!$Z$3:$Z$32) | E7: =B7-D7 | F7: =IFERROR(D7/B7,0)
A8: Wellness & Recovery | B8: 0 | C8: 0 | D8: =SUM('Wellness & Recovery'!$Z$3:$Z$32) | E8: =B8-D8 | F8: =IFERROR(D8/B8,0)
A9: Ambassadors & Creators | B9: 0 | C9: 0 | D9: =SUM('Ambassadors & Creators'!$Z$3:$Z$32) | E9: =B9-D9 | F9: =IFERROR(D9/B9,0)
A10: Charity & Causes | B10: 0 | C10: 0 | D10: =SUM('Charity & Causes'!$Z$3:$Z$32) | E10: =B10-D10 | F10: =IFERROR(D10/B10,0)
A11: Total | B11: =SUM(B3:B10) | C11: =SUM(C3:C10) | D11: =SUM(D3:D10) | E11: =SUM(E3:E10) | F11: =IFERROR(D11/B11,0)
A13: Total Budget and Committed are yours to set and start at zero. Spent rolls up the Cost column from each type tab.

Sheet Run Clubs
A1: Run Clubs
A2: # | B2: Partner Name | C2: Partnership Type | D2: City | E2: Neighbourhood | F2: Priority | G2: Status | H2: Primary Owner | I2: Contact Name | J2: Role | K2: Contact Email | L2: Contact Phone | M2: Instagram or Website | N2: Audience Size | O2: Audience Source | P2: Source | Q2: Warm | R2: Last Contacted | S2: Days Since Activity | T2: Next Action | U2: Next Action Date | V2: Activation Type | W2: Activation Date | X2: Cases Committed | Y2: Cases Delivered | Z2: Cost ($) | AA2: Cost Per Can | AB2: Contra Value ($) | AC2: Deliverables Promised | AD2: Deliverables Received | AE2: What They Want | AF2: Risks | AG2: Nearby Retail Doors | AH2: In BC Tracker? | AI2: Raspberry 4338 | AJ2: Lemon Lime 4336 | AK2: Pineapple Passion Fruit 4340 | AL2: Notes
A3: =IF($B3="","",ROW()-2) | B3: East Van Run Crew | C3: =IF($B3="","","Run Clubs") | D3: Vancouver | E3: East Vancouver | F3: P1 | G3: Open | H3: Maddie | M3: @eastvanruncrew | N3: 11,000 IG | O3: Instagram @eastvanruncrew follower count, web search 2026 | P3: Verified Web | Q3: Cold | S3: =IF(ISBLANK(R3),"",TODAY()-R3) | AA3: =IF(OR($Z3="",$Y3="",$Y3=0),"",$Z3/($Y3*24)) | AH3: No | AL3: Monday night runs starting from a rotating East Van brewery.
A4: =IF($B4="","",ROW()-2) | B4: Social Run Club YVR | C4: =IF($B4="","","Run Clubs") | D4: Vancouver | E4: Yaletown | F4: P1 | G4: Open | H4: Maddie | M4: @socialrunclub.yvr | N4: 12,000 IG | O4: Instagram @socialrunclub.yvr follower count, web search 2026 | P4: Verified Web | Q4: Cold | S4: =IF(ISBLANK(R4),"",TODAY()-R4) | AA4: =IF(OR($Z4="",$Y4="",$Y4=0),"",$Z4/($Y4*24)) | AH4: No | AL4: Saturday 9:30am Form Focus run that ends with a coffee social.
A5: =IF($B5="","",ROW()-2) | B5: Slow Girls Run Club | C5: =IF($B5="","","Run Clubs") | D5: Vancouver | E5: Downtown | F5: P1 | G5: Open | H5: Maddie | M5: @slowgirlsrunclub | N5: 9,400 IG | O5: Instagram @slowgirlsrunclub follower count, web search 2026 | P5: Verified Web | Q5: Cold | S5: =IF(ISBLANK(R5),"",TODAY()-R5) | AA5: =IF(OR($Z5="",$Y5="",$Y5=0),"",$Z5/($Y5*24)) | AH5: No | AL5: Saturday 8am Social Saturdays 5km. Women focused community.
A6: =IF($B6="","",ROW()-2) | B6: One Run Club | C6: =IF($B6="","","Run Clubs") | D6: Vancouver | E6: West End | F6: P2 | G6: Open | H6: Maddie | M6: @onerunclubvan | N6: 7,950 IG | O6: Instagram @onerunclubvan follower count, web search 2026. About 1,536 active members on Heylo | P6: Verified Web | Q6: Cold | S6: =IF(ISBLANK(R6),"",TODAY()-R6) | AA6: =IF(OR($Z6="",$Y6="",$Y6=0),"",$Z6/($Y6*24)) | AH6: No | AL6: Wednesday 6:30pm run with a social wrap at English Bay.
A7: =IF($B7="","",ROW()-2) | B7: Striderz Run Club | C7: =IF($B7="","","Run Clubs") | D7: Vancouver | E7: Olympic Village | F7: P2 | G7: Open | H7: Maddie | M7: @striderzrunclub | N7: 1,120 IG | O7: Instagram @striderzrunclub follower count, web search 2026 | P7: Verified Web | Q7: Cold | S7: =IF(ISBLANK(R7),"",TODAY()-R7) | AA7: =IF(OR($Z7="",$Y7="",$Y7=0),"",$Z7/($Y7*24)) | AH7: No | AL7: Free Sunday 8:30am social run from Athletes Way, all paces regroup.
A8: =IF($B8="","",ROW()-2) | B8: North Shore Women's Trail Running Club | C8: =IF($B8="","","Run Clubs") | D8: North Vancouver | E8: Lynn Valley | F8: P2 | G8: Open | H8: Maddie | M8: @northshore__runclub | N8: 2,930 IG | O8: Instagram @northshore__runclub follower count, web search 2026 | P8: Verified Web | Q8: Cold | S8: =IF(ISBLANK(R8),"",TODAY()-R8) | AA8: =IF(OR($Z8="",$Y8="",$Y8=0),"",$Z8/($Y8*24)) | AH8: No | AL8: Trail runs meeting at the End of the Line General Store.
A9: =IF($B9="","",ROW()-2) | B9: North Burnaby Runners | C9: =IF($B9="","","Run Clubs") | D9: Burnaby | E9: North Burnaby | F9: P2 | G9: Open | H9: Maddie | M9: @northburnabyrunners | N9: 2,370 IG | O9: Instagram @northburnabyrunners follower count, web search 2026 | P9: Verified Web | Q9: Cold | S9: =IF(ISBLANK(R9),"",TODAY()-R9) | AA9: =IF(OR($Z9="",$Y9="",$Y9=0),"",$Z9/($Y9*24)) | AH9: No | AL9: Wednesday 6:30pm social run from Dageraad Brewing.
A10: =IF($B10="","",ROW()-2) | B10: Flight Crew Run Club | C10: =IF($B10="","","Run Clubs") | D10: Vancouver | E10: Kitsilano | F10: P2 | G10: Open | H10: Maddie | M10: @flightcrewrunclub | N10: TBD | P10: Verified Web | Q10: Cold | S10: =IF(ISBLANK(R10),"",TODAY()-R10) | AA10: =IF(OR($Z10="",$Y10="",$Y10=0),"",$Z10/($Y10*24)) | AH10: No | AL10: Thursday 6:15pm Kitsilano road run with 3km, 5km and 10km options. Run by Vancouver Running Company.
A11: =IF($B11="","",ROW()-2) | B11: Capital City Run Crew | C11: =IF($B11="","","Run Clubs") | D11: Victoria | E11: Downtown | F11: P2 | G11: Open | H11: Maddie | M11: @capitalcityruncrew | N11: 2,820 IG | O11: Instagram @capitalcityruncrew follower count, web search 2026 | P11: Verified Web | Q11: Cold | S11: =IF(ISBLANK(R11),"",TODAY()-R11) | AA11: =IF(OR($Z11="",$Y11="",$Y11=0),"",$Z11/($Y11*24)) | AH11: No | AL11: Thursday evening downtown run.
A12: =IF($B12="","",ROW()-2) | B12: Kelowna Running Club | C12: =IF($B12="","","Run Clubs") | D12: Kelowna | E12: Waterfront Park | F12: P3 | G12: Open | H12: Maddie | M12: @kelownarunningclub | N12: 990 IG | O12: Instagram @kelownarunningclub follower count, web search 2026 | P12: Verified Web | Q12: Cold | S12: =IF(ISBLANK(R12),"",TODAY()-R12) | AA12: =IF(OR($Z12="",$Y12="",$Y12=0),"",$Z12/($Y12*24)) | AH12: No | AL12: Saturday long runs from rotating spots plus Tuesday speed work. 2026 schedule on the club site.
A13: =IF($B13="","",ROW()-2) | C13: =IF($B13="","","Run Clubs") | S13: =IF(ISBLANK(R13),"",TODAY()-R13) | AA13: =IF(OR($Z13="",$Y13="",$Y13=0),"",$Z13/($Y13*24))
A14: =IF($B14="","",ROW()-2) | C14: =IF($B14="","","Run Clubs") | S14: =IF(ISBLANK(R14),"",TODAY()-R14) | AA14: =IF(OR($Z14="",$Y14="",$Y14=0),"",$Z14/($Y14*24))
A15: =IF($B15="","",ROW()-2) | C15: =IF($B15="","","Run Clubs") | S15: =IF(ISBLANK(R15),"",TODAY()-R15) | AA15: =IF(OR($Z15="",$Y15="",$Y15=0),"",$Z15/($Y15*24))
A16: =IF($B16="","",ROW()-2) | C16: =IF($B16="","","Run Clubs") | S16: =IF(ISBLANK(R16),"",TODAY()-R16) | AA16: =IF(OR($Z16="",$Y16="",$Y16=0),"",$Z16/($Y16*24))
A17: =IF($B17="","",ROW()-2) | C17: =IF($B17="","","Run Clubs") | S17: =IF(ISBLANK(R17),"",TODAY()-R17) | AA17: =IF(OR($Z17="",$Y17="",$Y17=0),"",$Z17/($Y17*24))
A18: =IF($B18="","",ROW()-2) | C18: =IF($B18="","","Run Clubs") | S18: =IF(ISBLANK(R18),"",TODAY()-R18) | AA18: =IF(OR($Z18="",$Y18="",$Y18=0),"",$Z18/($Y18*24))
A19: =IF($B19="","",ROW()-2) | C19: =IF($B19="","","Run Clubs") | S19: =IF(ISBLANK(R19),"",TODAY()-R19) | AA19: =IF(OR($Z19="",$Y19="",$Y19=0),"",$Z19/($Y19*24))
A20: =IF($B20="","",ROW()-2) | C20: =IF($B20="","","Run Clubs") | S20: =IF(ISBLANK(R20),"",TODAY()-R20) | AA20: =IF(OR($Z20="",$Y20="",$Y20=0),"",$Z20/($Y20*24))
A21: =IF($B21="","",ROW()-2) | C21: =IF($B21="","","Run Clubs") | S21: =IF(ISBLANK(R21),"",TODAY()-R21) | AA21: =IF(OR($Z21="",$Y21="",$Y21=0),"",$Z21/($Y21*24))
A22: =IF($B22="","",ROW()-2) | C22: =IF($B22="","","Run Clubs") | S22: =IF(ISBLANK(R22),"",TODAY()-R22) | AA22: =IF(OR($Z22="",$Y22="",$Y22=0),"",$Z22/($Y22*24))
A23: =IF($B23="","",ROW()-2) | C23: =IF($B23="","","Run Clubs") | S23: =IF(ISBLANK(R23),"",TODAY()-R23) | AA23: =IF(OR($Z23="",$Y23="",$Y23=0),"",$Z23/($Y23*24))
A24: =IF($B24="","",ROW()-2) | C24: =IF($B24="","","Run Clubs") | S24: =IF(ISBLANK(R24),"",TODAY()-R24) | AA24: =IF(OR($Z24="",$Y24="",$Y24=0),"",$Z24/($Y24*24))
... A32: =IF($B32="","",ROW()-2) | C32: =IF($B32="","","Run Clubs") | S32: =IF(ISBLANK(R32),"",TODAY()-R32) | AA32: =IF(OR($Z32="",$Y32="",$Y32=0),"",$Z32/($Y32*24))

Sheet Gyms & Studios
A1: Gyms & Studios
A2: # | B2: Partner Name | C2: Partnership Type | D2: City | E2: Neighbourhood | F2: Priority | G2: Status | H2: Primary Owner | I2: Contact Name | J2: Role | K2: Contact Email | L2: Contact Phone | M2: Instagram or Website | N2: Audience Size | O2: Audience Source | P2: Source | Q2: Warm | R2: Last Contacted | S2: Days Since Activity | T2: Next Action | U2: Next Action Date | V2: Activation Type | W2: Activation Date | X2: Cases Committed | Y2: Cases Delivered | Z2: Cost ($) | AA2: Cost Per Can | AB2: Contra Value ($) | AC2: Deliverables Promised | AD2: Deliverables Received | AE2: What They Want | AF2: Risks | AG2: Nearby Retail Doors | AH2: In BC Tracker? | AI2: Raspberry 4338 | AJ2: Lemon Lime 4336 | AK2: Pineapple Passion Fruit 4340 | AL2: Notes
A3: =IF($B3="","",ROW()-2) | B3: RIDE Cycle Club | C3: =IF($B3="","","Gyms & Studios") | D3: Vancouver | E3: Yaletown | F3: P1 | G3: Open | H3: Maddie | M3: @ridecycleclub | N3: 23,000 IG | O3: Instagram @ridecycleclub follower count, web search 2026. Account covers Vancouver and Toronto | P3: Verified Web | Q3: Cold | S3: =IF(ISBLANK(R3),"",TODAY()-R3) | AA3: =IF(OR($Z3="",$Y3="",$Y3=0),"",$Z3/($Y3*24)) | AH3: No | AL3: Spin studio on Hamilton Street, part of a multi city brand.
A4: =IF($B4="","",ROW()-2) | B4: The Hive Bouldering Gym | C4: =IF($B4="","","Gyms & Studios") | D4: Vancouver | E4: Strathcona | F4: P1 | G4: Open | H4: Maddie | M4: @hiveclimbing | N4: 21,000 IG | O4: Instagram @hiveclimbing follower count, web search 2026. Brand account, several BC sites | P4: Verified Web | Q4: Cold | S4: =IF(ISBLANK(R4),"",TODAY()-R4) | AA4: =IF(OR($Z4="",$Y4="",$Y4=0),"",$Z4/($Y4*24)) | AH4: No | AL4: Bouldering gym on Industrial Avenue, brand has several BC locations.
A5: =IF($B5="","",ROW()-2) | B5: Progression Bouldering | C5: =IF($B5="","","Gyms & Studios") | D5: Vancouver | E5: Mount Pleasant | F5: P1 | G5: Open | H5: Maddie | M5: @progressionbouldering | N5: 9,700 IG | O5: Instagram @progressionbouldering follower count, web search 2026 | P5: Verified Web | Q5: Cold | S5: =IF(ISBLANK(R5),"",TODAY()-R5) | AA5: =IF(OR($Z5="",$Y5="",$Y5=0),"",$Z5/($Y5*24)) | AH5: No | AL5: 18,000 sq ft bouldering gym with a licensed cafe on site.
A6: =IF($B6="","",ROW()-2) | B6: Tantra Fitness | C6: =IF($B6="","","Gyms & Studios") | D6: Vancouver | E6: Kitsilano | F6: P2 | G6: Open | H6: Maddie | M6: @tantrafitness | N6: 17,000 IG | O6: Instagram @tantrafitness follower count, web search 2026 (single snippet, reverify) | P6: Pending | Q6: Cold | S6: =IF(ISBLANK(R6),"",TODAY()-R6) | AA6: =IF(OR($Z6="",$Y6="",$Y6=0),"",$Z6/($Y6*24)) | AH6: No | AL6: Pole and aerial fitness across three Vancouver locations.
A7: =IF($B7="","",ROW()-2) | B7: 604 Athletics | C7: =IF($B7="","","Gyms & Studios") | D7: Vancouver | E7: Mount Pleasant | F7: P2 | G7: Open | H7: Maddie | M7: @604_athletics | N7: 6,100 IG | O7: Instagram @604_athletics follower count, web search 2026 (single snippet, reverify) | P7: Pending | Q7: Cold | S7: =IF(ISBLANK(R7),"",TODAY()-R7) | AA7: =IF(OR($Z7="",$Y7="",$Y7=0),"",$Z7/($Y7*24)) | AH7: No | AL7: CrossFit box on Main Street, runs HYROX prep classes.
A8: =IF($B8="","",ROW()-2) | B8: FAR Studio | C8: =IF($B8="","","Gyms & Studios") | D8: Vancouver | E8: Gastown | F8: P2 | G8: Open | H8: Maddie | M8: @farstudiogym | N8: 2,450 IG | O8: Instagram @farstudiogym follower count, web search 2026 (single snippet, reverify) | P8: Pending | Q8: Cold | S8: =IF(ISBLANK(R8),"",TODAY()-R8) | AA8: =IF(OR($Z8="",$Y8="",$Y8=0),"",$Z8/($Y8*24)) | AH8: No | AL8: Kickboxing and strength studio on Powell Street.
A9: =IF($B9="","",ROW()-2) | B9: The Lab Victoria | C9: =IF($B9="","","Gyms & Studios") | D9: Victoria | E9: Downtown | F9: P2 | G9: Open | H9: Maddie | M9: @thelabvictoria | N9: 3,500 IG | O9: Instagram @thelabvictoria follower count, web search 2026 (single snippet, reverify) | P9: Pending | Q9: Cold | S9: =IF(ISBLANK(R9),"",TODAY()-R9) | AA9: =IF(OR($Z9="",$Y9="",$Y9=0),"",$Z9/($Y9*24)) | AH9: No | AL9: Yoga and pilates studio on Fort Street.
A10: =IF($B10="","",ROW()-2) | B10: CrossFit BC | C10: =IF($B10="","","Gyms & Studios") | D10: Vancouver | E10: Olympic Village | F10: P3 | G10: Open | H10: Maddie | M10: @crossfitbc | N10: TBD | P10: Verified Web | Q10: Cold | S10: =IF(ISBLANK(R10),"",TODAY()-R10) | AA10: =IF(OR($Z10="",$Y10="",$Y10=0),"",$Z10/($Y10*24)) | AH10: No | AL10: CrossFit box on East 1st Avenue.
A11: =IF($B11="","",ROW()-2) | B11: CrossFit Zone | C11: =IF($B11="","","Gyms & Studios") | D11: Victoria | E11: Downtown | F11: P3 | G11: Open | H11: Maddie | M11: @crossfit_zone_ | N11: TBD | P11: Verified Web | Q11: Cold | S11: =IF(ISBLANK(R11),"",TODAY()-R11) | AA11: =IF(OR($Z11="",$Y11="",$Y11=0),"",$Z11/($Y11*24)) | AH11: No | AL11: One of the oldest CrossFit boxes in Victoria, operating since 2008.
A12: =IF($B12="","",ROW()-2) | B12: CrossFit Okanagan | C12: =IF($B12="","","Gyms & Studios") | D12: Kelowna | E12: Kelowna | F12: P3 | G12: Open | H12: Maddie | M12: @crossfitokanagan | N12: 4,700 IG | O12: Instagram @crossfitokanagan follower count, web search 2026 (single snippet, reverify) | P12: Pending | Q12: Cold | S12: =IF(ISBLANK(R12),"",TODAY()-R12) | AA12: =IF(OR($Z12="",$Y12="",$Y12=0),"",$Z12/($Y12*24)) | AH12: No | AL12: CrossFit box, also runs a ForeverFit 55 plus program.
A13: =IF($B13="","",ROW()-2) | C13: =IF($B13="","","Gyms & Studios") | S13: =IF(ISBLANK(R13),"",TODAY()-R13) | AA13: =IF(OR($Z13="",$Y13="",$Y13=0),"",$Z13/($Y13*24))
A14: =IF($B14="","",ROW()-2) | C14: =IF($B14="","","Gyms & Studios") | S14: =IF(ISBLANK(R14),"",TODAY()-R14) | AA14: =IF(OR($Z14="",$Y14="",$Y14=0),"",$Z14/($Y14*24))
A15: =IF($B15="","",ROW()-2) | C15: =IF($B15="","","Gyms & Studios") | S15: =IF(ISBLANK(R15),"",TODAY()-R15) | AA15: =IF(OR($Z15="",$Y15="",$Y15=0),"",$Z15/($Y15*24))
A16: =IF($B16="","",ROW()-2) | C16: =IF($B16="","","Gyms & Studios") | S16: =IF(ISBLANK(R16),"",TODAY()-R16) | AA16: =IF(OR($Z16="",$Y16="",$Y16=0),"",$Z16/($Y16*24))
A17: =IF($B17="","",ROW()-2) | C17: =IF($B17="","","Gyms & Studios") | S17: =IF(ISBLANK(R17),"",TODAY()-R17) | AA17: =IF(OR($Z17="",$Y17="",$Y17=0),"",$Z17/($Y17*24))
A18: =IF($B18="","",ROW()-2) | C18: =IF($B18="","","Gyms & Studios") | S18: =IF(ISBLANK(R18),"",TODAY()-R18) | AA18: =IF(OR($Z18="",$Y18="",$Y18=0),"",$Z18/($Y18*24))
A19: =IF($B19="","",ROW()-2) | C19: =IF($B19="","","Gyms & Studios") | S19: =IF(ISBLANK(R19),"",TODAY()-R19) | AA19: =IF(OR($Z19="",$Y19="",$Y19=0),"",$Z19/($Y19*24))
A20: =IF($B20="","",ROW()-2) | C20: =IF($B20="","","Gyms & Studios") | S20: =IF(ISBLANK(R20),"",TODAY()-R20) | AA20: =IF(OR($Z20="",$Y20="",$Y20=0),"",$Z20/($Y20*24))
