Workbook
Name CP_Pineapple_Singles: 'Assumptions'!$C$11
Name BaseVolume_Total: 'Assumptions'!$C$28:$H$28
Name TaxRate: 'Assumptions'!$C$38
Name LogisticsPct: 'Assumptions'!$C$35

Sheet Home
B2: ORGANIKA
B3: Sparkling Daily
B4: One-Year Operating Model · FY2026
B6: Scenario | C6: Base | D6: ▼ pick a scenario — everything below updates
B8: NET SALES | C8: GROSS PROFIT % | D8: EBITDA | E8: EBITDA % | F8: NET INCOME | G8: PHYSICAL CASES
B9: =INDIRECT("'"&$C$6&"'!I18") | C9: =INDIRECT("'"&$C$6&"'!I23") | D9: =INDIRECT("'"&$C$6&"'!I34") | E9: =INDIRECT("'"&$C$6&"'!I35") | F9: =INDIRECT("'"&$C$6&"'!I41") | G9: =INDIRECT("'"&$C$6&"'!I8")
B11: Break-even volume | C11: ='Sensitivity'!$C$23 | E11: Blended CP / case | F11: =INDIRECT("'"&$C$6&"'!I10")
B13: WHERE TO GO
B14: 1. Assumptions | C14: The ONE place you type. Change a yellow cell, everything updates.
B15: 2. Dashboard | C15: All four scenarios side by side.
B16: Base · Low · High · Stretch | C16: The full profit story for each scenario.
B17: Monthly | C17: The chosen scenario spread across the 12 months.
B18: Pricing Lab | C18: See the wholesale price that makes the most money.
B19: Targets | C19: Set a goal — it tells you the price or volume to get there.
B20: Sensitivity | C20: How profit moves with price and volume.
B21: Checks | C21: Built-in health check (should say ALL PASS).
B23: v2.0 · built 2026-06-05 · all $ CDN · figures are placeholders until you add real numbers

Sheet Assumptions
B1: Sparkling Daily - Assumptions (single source of truth)
B2: Edit YELLOW cells only. Every scenario, the monthly view, sensitivity and checks read from this sheet.
C4: SINGLES | F4: 4-PACK
B5: Per case (CDN $) | C5: Pineapple | D5: Passionfruit | E5: Lime Lemon | F5: Pineapple | G5: Passionfruit | H5: Lime Lemon
B6: SKU DEFINITION
B7: Format | C7: Singles | D7: Singles | E7: Singles | F7: 4-Pack | G7: 4-Pack | H7: 4-Pack
B8: Flavour | C8: Pineapple | D8: Passionfruit | E8: Lime Lemon | F8: Pineapple | G8: Passionfruit | H8: Lime Lemon
B9: Units per case | C9: 12 | D9: 12 | E9: 12 | F9: 6 | G9: 6 | H9: 6
B10: PRICE (per case)
B11: CP - List price / case | C11: 15 | D11: 15 | E11: 14 | F11: 33 | G11: 33 | H11: 31
B12: Trade discount (% of gross) | C12: 0.07 | D12: 0.07 | E12: 0.07 | F12: 0.08 | G12: 0.08 | H12: 0.08
B13: Price per unit (info) | C13: =IFERROR(C11/C9,0) | D13: =IFERROR(D11/D9,0) | E13: =IFERROR(E11/E9,0) | F13: =IFERROR(F11/F9,0) | G13: =IFERROR(G11/G9,0) | H13: =IFERROR(H11/H9,0)
B14: COGS (per case)
B15: Ingredients | C15: 2.16 | D15: 2.16 | E15: 2.06 | F15: 4.32 | G15: 4.32 | H15: 4.12
B16: Packaging | C16: 2.64 | D16: 2.64 | E16: 2.54 | F16: 7.08 | G16: 7.08 | H16: 6.88
B17: Manufacturing / Co-pack | C17: 1.44 | D17: 1.44 | E17: 1.4 | F17: 2.88 | G17: 2.88 | H17: 2.8
B18: Inbound Freight | C18: 0.29 | D18: 0.29 | E18: 0.28 | F18: 0.58 | G18: 0.58 | H18: 0.56
B19: COGS Direct / case | C19: =SUM(C15:C18) | D19: =SUM(D15:D18) | E19: =SUM(E15:E18) | F19: =SUM(F15:F18) | G19: =SUM(G15:G18) | H19: =SUM(H15:H18)
B20: Warehousing / Indirect | C20: 0.72 | D20: 0.72 | E20: 0.7 | F20: 1.44 | G20: 1.44 | H20: 1.4
B21: Cost of Sales / case | C21: =C19+C20 | D21: =D19+D20 | E21: =E19+E20 | F21: =F19+F20 | G21: =G19+G20 | H21: =H19+H20
B22: A&P (per case)
B23: Consumer | C23: 0.36 | D23: 0.36 | E23: 0.36 | F23: 0.72 | G23: 0.72 | H23: 0.72
B24: Trade | C24: 0.6 | D24: 0.6 | E24: 0.6 | F24: 1.2 | G24: 1.2 | H24: 1.2
B25: Sales / Broker | C25: 0.24 | D25: 0.24 | E25: 0.24 | F25: 0.48 | G25: 0.48 | H25: 0.48
B26: A&P / case | C26: =SUM(C23:C25) | D26: =SUM(D23:D25) | E26: =SUM(E23:E25) | F26: =SUM(F23:F25) | G26: =SUM(G23:G25) | H26: =SUM(H23:H25)
B27: VOLUME
B28: Base annual volume (cases) | C28: 15000 | D28: 11000 | E28: 9000 | F28: 6000 | G28: 5000 | H28: 4000
B30: COMPANY OPERATING ASSUMPTIONS (annual)
B31: Salaries & wages | C31: 180000
B32: G&A / overhead | C32: 60000
B33: Marketing overhead (brand) | C33: 40000
B34: Slotting / listing fees | C34: 20000
B35: Outbound logistics (% of net sales) | C35: 0.04
B36: Depreciation & amortisation | C36: 25000
B37: Interest expense | C37: 10000
B38: Tax rate | C38: 0.27
B39: Price elasticity (advanced; 0 = off) | C39: 0
B40: 3-yr volume growth / yr | C40: 0.25
B41: 3-yr price growth / yr | C41: 0.03
B42: 3-yr cost inflation / yr | C42: 0.02
...

Sheet Dashboard
B1: Sparkling Daily - Scenario Dashboard (FY2026)
B2: Company totals across the four scenarios. Driven live from each scenario tab.
B4: Metric | C4: Low | D4: Base | E4: High | F4: Stretch
B5: Physical Cases | C5: ='Low'!I8 | D5: ='Base'!I8 | E5: ='High'!I8 | F5: ='Stretch'!I8
B6: Gross Revenue | C6: ='Low'!I16 | D6: ='Base'!I16 | E6: ='High'!I16 | F6: ='Stretch'!I16
B7: Trade Discounts | C7: ='Low'!I17 | D7: ='Base'!I17 | E7: ='High'!I17 | F7: ='Stretch'!I17
B8: Net Sales | C8: ='Low'!I18 | D8: ='Base'!I18 | E8: ='High'!I18 | F8: ='Stretch'!I18
B9: Gross Profit | C9: ='Low'!I22 | D9: ='Base'!I22 | E9: ='High'!I22 | F9: ='Stretch'!I22
B10: GP % | C10: ='Low'!I23 | D10: ='Base'!I23 | E10: ='High'!I23 | F10: ='Stretch'!I23
B11: A&P | C11: ='Low'!I24 | D11: ='Base'!I24 | E11: ='High'!I24 | F11: ='Stretch'!I24
B12: Contribution Margin | C12: ='Low'!I25 | D12: ='Base'!I25 | E12: ='High'!I25 | F12: ='Stretch'!I25
B13: CM % | C13: ='Low'!I26 | D13: ='Base'!I26 | E13: ='High'!I26 | F13: ='Stretch'!I26
B14: Total Opex | C14: ='Low'!I33 | D14: ='Base'!I33 | E14: ='High'!I33 | F14: ='Stretch'!I33
B15: EBITDA | C15: ='Low'!I34 | D15: ='Base'!I34 | E15: ='High'!I34 | F15: ='Stretch'!I34
B16: EBITDA % | C16: ='Low'!I35 | D16: ='Base'!I35 | E16: ='High'!I35 | F16: ='Stretch'!I35
B17: Net Income | C17: ='Low'!I41 | D17: ='Base'!I41 | E17: ='High'!I41 | F17: ='Stretch'!I41
B18: Net Income % | C18: ='Low'!I42 | D18: ='Base'!I42 | E18: ='High'!I42 | F18: ='Stretch'!I42
B19: Blended CP / case | C19: ='Low'!I10 | D19: ='Base'!I10 | E19: ='High'!I10 | F19: ='Stretch'!I10
B20: Net Sales / case | C20: ='Low'!I44 | D20: ='Base'!I44 | E20: ='High'!I44 | F20: ='Stretch'!I44

Sheet Base
B1: Sparkling Daily - BASE Scenario (FY2026)
B2: Levers vs Base: Volume 100% • Price 100% • Trade-disc Δ +0% (all driven from Assumptions)
B3: CDN $. All figures calculate from the Assumptions tab - nothing here is hand-keyed.
C5: SINGLES | F5: 4-PACK | I5: TOTAL DAILY
B6: CDN $ | C6: Pineapple | D6: Passionfruit | E6: Lime Lemon | F6: Pineapple | G6: Passionfruit | H6: Lime Lemon
B7: VOLUME
B8: Physical Cases | C8: ='Assumptions'!C28*'Assumptions'!$C$47*('Assumptions'!$D$47^'Assumptions'!$C$39) | D8: ='Assumptions'!D28*'Assumptions'!$C$47*('Assumptions'!$D$47^'Assumptions'!$C$39) | E8: ='Assumptions'!E28*'Assumptions'!$C$47*('Assumptions'!$D$47^'Assumptions'!$C$39) | F8: ='Assumptions'!F28*'Assumptions'!$C$47*('Assumptions'!$D$47^'Assumptions'!$C$39) | G8: ='Assumptions'!G28*'Assumptions'!$C$47*('Assumptions'!$D$47^'Assumptions'!$C$39) | H8: ='Assumptions'!H28*'Assumptions'!$C$47*('Assumptions'!$D$47^'Assumptions'!$C$39) | I8: =SUM(C8:H8)
B9: PRICE & COST - PER CASE (from Assumptions x levers)
B10: CP - Gross Rev / case | C10: ='Assumptions'!C11*'Assumptions'!$D$47 | D10: ='Assumptions'!D11*'Assumptions'!$D$47 | E10: ='Assumptions'!E11*'Assumptions'!$D$47 | F10: ='Assumptions'!F11*'Assumptions'!$D$47 | G10: ='Assumptions'!G11*'Assumptions'!$D$47 | H10: ='Assumptions'!H11*'Assumptions'!$D$47 | I10: =IFERROR(I16/I8,0)
B11: Trade discount % | C11: ='Assumptions'!C12+'Assumptions'!$E$47 | D11: ='Assumptions'!D12+'Assumptions'!$E$47 | E11: ='Assumptions'!E12+'Assumptions'!$E$47 | F11: ='Assumptions'!F12+'Assumptions'!$E$47 | G11: ='Assumptions'!G12+'Assumptions'!$E$47 | H11: ='Assumptions'!H12+'Assumptions'!$E$47 | I11: =IFERROR(I17/I16,0)
B12: COGS Direct / case | C12: ='Assumptions'!C19 | D12: ='Assumptions'!D19 | E12: ='Assumptions'!E19 | F12: ='Assumptions'!F19 | G12: ='Assumptions'!G19 | H12: ='Assumptions'!H19 | I12: =IFERROR(I19/I8,0)
B13: COGS Indirect / case | C13: ='Assumptions'!C20 | D13: ='Assumptions'!D20 | E13: ='Assumptions'!E20 | F13: ='Assumptions'!F20 | G13: ='Assumptions'!G20 | H13: ='Assumptions'!H20 | I13: =IFERROR(I20/I8,0)
B14: A&P / case | C14: ='Assumptions'!C26 | D14: ='Assumptions'!D26 | E14: ='Assumptions'!E26 | F14: ='Assumptions'!F26 | G14: ='Assumptions'!G26 | H14: ='Assumptions'!H26 | I14: =IFERROR(I24/I8,0)
B15: P&L ($)
B16: Gross Revenue | C16: =C8*C10 | D16: =D8*D10 | E16: =E8*E10 | F16: =F8*F10 | G16: =G8*G10 | H16: =H8*H10 | I16: =SUM(C16:H16)
B17: Trade Discounts | C17: =C16*C11 | D17: =D16*D11 | E17: =E16*E11 | F17: =F16*F11 | G17: =G16*G11 | H17: =H16*H11 | I17: =SUM(C17:H17)
B18: Net Sales | C18: =C16-C17 | D18: =D16-D17 | E18: =E16-E17 | F18: =F16-F17 | G18: =G16-G17 | H18: =H16-H17 | I18: =I16-I17
B19: COGS Direct | C19: =C8*C12 | D19: =D8*D12 | E19: =E8*E12 | F19: =F8*F12 | G19: =G8*G12 | H19: =H8*H12 | I19: =SUM(C19:H19)
B20: COGS Indirect | C20: =C8*C13 | D20: =D8*D13 | E20: =E8*E13 | F20: =F8*F13 | G20: =G8*G13 | H20: =H8*H13 | I20: =SUM(C20:H20)
B21: Cost of Sales | C21: =C19+C20 | D21: =D19+D20 | E21: =E19+E20 | F21: =F19+F20 | G21: =G19+G20 | H21: =H19+H20 | I21: =I19+I20
B22: Gross Profit | C22: =C18-C21 | D22: =D18-D21 | E22: =E18-E21 | F22: =F18-F21 | G22: =G18-G21 | H22: =H18-H21 | I22: =I18-I21
B23: GP % | C23: =IFERROR(C22/C18,0) | D23: =IFERROR(D22/D18,0) | E23: =IFERROR(E22/E18,0) | F23: =IFERROR(F22/F18,0) | G23: =IFERROR(G22/G18,0) | H23: =IFERROR(H22/H18,0) | I23: =IFERROR(I22/I18,0)
B24: A&P | C24: =C8*C14 | D24: =D8*D14 | E24: =E8*E14 | F24: =F8*F14 | G24: =G8*G14 | H24: =H8*H14 | I24: =SUM(C24:H24)
B25: Contribution Margin | C25: =C22-C24 | D25: =D22-D24 | E25: =E22-E24 | F25: =F22-F24 | G25: =G22-G24 | H25: =H22-H24 | I25: =I22-I24
B26: CM % | C26: =IFERROR(C25/C18,0) | D26: =IFERROR(D25/D18,0) | E26: =IFERROR(E25/E18,0) | F26: =IFERROR(F25/F18,0) | G26: =IFERROR(G25/G18,0) | H26: =IFERROR(H25/H18,0) | I26: =IFERROR(I25/I18,0)
B27: OPERATING EXPENSES & PROFIT (company total)
B28: Salaries & wages | I28: ='Assumptions'!$C$31
B29: G&A / overhead | I29: ='Assumptions'!$C$32
B30: Marketing overhead | I30: ='Assumptions'!$C$33
B31: Slotting / listing | I31: ='Assumptions'!$C$34
B32: Outbound logistics | I32: =I18*'Assumptions'!$C$35
B33: Total Operating Expenses | I33: =SUM(I28:I32)
B34: EBITDA | I34: =I25-I33
B35: EBITDA % | I35: =IFERROR(I34/I18,0)
B36: Depreciation & amort. | I36: ='Assumptions'!$C$36
B37: EBIT | I37: =I34-I36
B38: Interest | I38: ='Assumptions'!$C$37
B39: Pre-tax Profit (EBT) | I39: =I37-I38
B40: Tax | I40: =MAX(0,I39*'Assumptions'!$C$38)
B41: Net Income | I41: =I39-I40
...

Sheet Low
B1: Sparkling Daily - LOW Scenario (FY2026)
B2: Levers vs Base: Volume 70% • Price 95% • Trade-disc Δ +1% (all driven from Assumptions)
B3: CDN $. All figures calculate from the Assumptions tab - nothing here is hand-keyed.
C5: SINGLES | F5: 4-PACK | I5: TOTAL DAILY
B6: CDN $ | C6: Pineapple | D6: Passionfruit | E6: Lime Lemon | F6: Pineapple | G6: Passionfruit | H6: Lime Lemon
B7: VOLUME
B8: Physical Cases | C8: ='Assumptions'!C28*'Assumptions'!$C$46*('Assumptions'!$D$46^'Assumptions'!$C$39) | D8: ='Assumptions'!D28*'Assumptions'!$C$46*('Assumptions'!$D$46^'Assumptions'!$C$39) | E8: ='Assumptions'!E28*'Assumptions'!$C$46*('Assumptions'!$D$46^'Assumptions'!$C$39) | F8: ='Assumptions'!F28*'Assumptions'!$C$46*('Assumptions'!$D$46^'Assumptions'!$C$39) | G8: ='Assumptions'!G28*'Assumptions'!$C$46*('Assumptions'!$D$46^'Assumptions'!$C$39) | H8: ='Assumptions'!H28*'Assumptions'!$C$46*('Assumptions'!$D$46^'Assumptions'!$C$39) | I8: =SUM(C8:H8)
B9: PRICE & COST - PER CASE (from Assumptions x levers)
B10: CP - Gross Rev / case | C10: ='Assumptions'!C11*'Assumptions'!$D$46 | D10: ='Assumptions'!D11*'Assumptions'!$D$46 | E10: ='Assumptions'!E11*'Assumptions'!$D$46 | F10: ='Assumptions'!F11*'Assumptions'!$D$46 | G10: ='Assumptions'!G11*'Assumptions'!$D$46 | H10: ='Assumptions'!H11*'Assumptions'!$D$46 | I10: =IFERROR(I16/I8,0)
B11: Trade discount % | C11: ='Assumptions'!C12+'Assumptions'!$E$46 | D11: ='Assumptions'!D12+'Assumptions'!$E$46 | E11: ='Assumptions'!E12+'Assumptions'!$E$46 | F11: ='Assumptions'!F12+'Assumptions'!$E$46 | G11: ='Assumptions'!G12+'Assumptions'!$E$46 | H11: ='Assumptions'!H12+'Assumptions'!$E$46 | I11: =IFERROR(I17/I16,0)
B12: COGS Direct / case | C12: ='Assumptions'!C19 | D12: ='Assumptions'!D19 | E12: ='Assumptions'!E19 | F12: ='Assumptions'!F19 | G12: ='Assumptions'!G19 | H12: ='Assumptions'!H19 | I12: =IFERROR(I19/I8,0)
B13: COGS Indirect / case | C13: ='Assumptions'!C20 | D13: ='Assumptions'!D20 | E13: ='Assumptions'!E20 | F13: ='Assumptions'!F20 | G13: ='Assumptions'!G20 | H13: ='Assumptions'!H20 | I13: =IFERROR(I20/I8,0)
B14: A&P / case | C14: ='Assumptions'!C26 | D14: ='Assumptions'!D26 | E14: ='Assumptions'!E26 | F14: ='Assumptions'!F26 | G14: ='Assumptions'!G26 | H14: ='Assumptions'!H26 | I14: =IFERROR(I24/I8,0)
B15: P&L ($)
B16: Gross Revenue | C16: =C8*C10 | D16: =D8*D10 | E16: =E8*E10 | F16: =F8*F10 | G16: =G8*G10 | H16: =H8*H10 | I16: =SUM(C16:H16)
B17: Trade Discounts | C17: =C16*C11 | D17: =D16*D11 | E17: =E16*E11 | F17: =F16*F11 | G17: =G16*G11 | H17: =H16*H11 | I17: =SUM(C17:H17)
B18: Net Sales | C18: =C16-C17 | D18: =D16-D17 | E18: =E16-E17 | F18: =F16-F17 | G18: =G16-G17 | H18: =H16-H17 | I18: =I16-I17
B19: COGS Direct | C19: =C8*C12 | D19: =D8*D12 | E19: =E8*E12 | F19: =F8*F12 | G19: =G8*G12 | H19: =H8*H12 | I19: =SUM(C19:H19)
B20: COGS Indirect | C20: =C8*C13 | D20: =D8*D13 | E20: =E8*E13 | F20: =F8*F13 | G20: =G8*G13 | H20: =H8*H13 | I20: =SUM(C20:H20)
B21: Cost of Sales | C21: =C19+C20 | D21: =D19+D20 | E21: =E19+E20 | F21: =F19+F20 | G21: =G19+G20 | H21: =H19+H20 | I21: =I19+I20
B22: Gross Profit | C22: =C18-C21 | D22: =D18-D21 | E22: =E18-E21 | F22: =F18-F21 | G22: =G18-G21 | H22: =H18-H21 | I22: =I18-I21
B23: GP % | C23: =IFERROR(C22/C18,0) | D23: =IFERROR(D22/D18,0) | E23: =IFERROR(E22/E18,0) | F23: =IFERROR(F22/F18,0) | G23: =IFERROR(G22/G18,0) | H23: =IFERROR(H22/H18,0) | I23: =IFERROR(I22/I18,0)
B24: A&P | C24: =C8*C14 | D24: =D8*D14 | E24: =E8*E14 | F24: =F8*F14 | G24: =G8*G14 | H24: =H8*H14 | I24: =SUM(C24:H24)
B25: Contribution Margin | C25: =C22-C24 | D25: =D22-D24 | E25: =E22-E24 | F25: =F22-F24 | G25: =G22-G24 | H25: =H22-H24 | I25: =I22-I24
B26: CM % | C26: =IFERROR(C25/C18,0) | D26: =IFERROR(D25/D18,0) | E26: =IFERROR(E25/E18,0) | F26: =IFERROR(F25/F18,0) | G26: =IFERROR(G25/G18,0) | H26: =IFERROR(H25/H18,0) | I26: =IFERROR(I25/I18,0)
B27: OPERATING EXPENSES & PROFIT (company total)
B28: Salaries & wages | I28: ='Assumptions'!$C$31
B29: G&A / overhead | I29: ='Assumptions'!$C$32
B30: Marketing overhead | I30: ='Assumptions'!$C$33
B31: Slotting / listing | I31: ='Assumptions'!$C$34
B32: Outbound logistics | I32: =I18*'Assumptions'!$C$35
B33: Total Operating Expenses | I33: =SUM(I28:I32)
B34: EBITDA | I34: =I25-I33
B35: EBITDA % | I35: =IFERROR(I34/I18,0)
B36: Depreciation & amort. | I36: ='Assumptions'!$C$36
B37: EBIT | I37: =I34-I36
B38: Interest | I38: ='Assumptions'!$C$37
B39: Pre-tax Profit (EBT) | I39: =I37-I38
B40: Tax | I40: =MAX(0,I39*'Assumptions'!$C$38)
B41: Net Income | I41: =I39-I40
...

Sheet High
B1: Sparkling Daily - HIGH Scenario (FY2026)
B2: Levers vs Base: Volume 130% • Price 100% • Trade-disc Δ +0% (all driven from Assumptions)
B3: CDN $. All figures calculate from the Assumptions tab - nothing here is hand-keyed.
C5: SINGLES | F5: 4-PACK | I5: TOTAL DAILY
B6: CDN $ | C6: Pineapple | D6: Passionfruit | E6: Lime Lemon | F6: Pineapple | G6: Passionfruit | H6: Lime Lemon
B7: VOLUME
B8: Physical Cases | C8: ='Assumptions'!C28*'Assumptions'!$C$48*('Assumptions'!$D$48^'Assumptions'!$C$39) | D8: ='Assumptions'!D28*'Assumptions'!$C$48*('Assumptions'!$D$48^'Assumptions'!$C$39) | E8: ='Assumptions'!E28*'Assumptions'!$C$48*('Assumptions'!$D$48^'Assumptions'!$C$39) | F8: ='Assumptions'!F28*'Assumptions'!$C$48*('Assumptions'!$D$48^'Assumptions'!$C$39) | G8: ='Assumptions'!G28*'Assumptions'!$C$48*('Assumptions'!$D$48^'Assumptions'!$C$39) | H8: ='Assumptions'!H28*'Assumptions'!$C$48*('Assumptions'!$D$48^'Assumptions'!$C$39) | I8: =SUM(C8:H8)
B9: PRICE & COST - PER CASE (from Assumptions x levers)
B10: CP - Gross Rev / case | C10: ='Assumptions'!C11*'Assumptions'!$D$48 | D10: ='Assumptions'!D11*'Assumptions'!$D$48 | E10: ='Assumptions'!E11*'Assumptions'!$D$48 | F10: ='Assumptions'!F11*'Assumptions'!$D$48 | G10: ='Assumptions'!G11*'Assumptions'!$D$48 | H10: ='Assumptions'!H11*'Assumptions'!$D$48 | I10: =IFERROR(I16/I8,0)
B11: Trade discount % | C11: ='Assumptions'!C12+'Assumptions'!$E$48 | D11: ='Assumptions'!D12+'Assumptions'!$E$48 | E11: ='Assumptions'!E12+'Assumptions'!$E$48 | F11: ='Assumptions'!F12+'Assumptions'!$E$48 | G11: ='Assumptions'!G12+'Assumptions'!$E$48 | H11: ='Assumptions'!H12+'Assumptions'!$E$48 | I11: =IFERROR(I17/I16,0)
B12: COGS Direct / case | C12: ='Assumptions'!C19 | D12: ='Assumptions'!D19 | E12: ='Assumptions'!E19 | F12: ='Assumptions'!F19 | G12: ='Assumptions'!G19 | H12: ='Assumptions'!H19 | I12: =IFERROR(I19/I8,0)
B13: COGS Indirect / case | C13: ='Assumptions'!C20 | D13: ='Assumptions'!D20 | E13: ='Assumptions'!E20 | F13: ='Assumptions'!F20 | G13: ='Assumptions'!G20 | H13: ='Assumptions'!H20 | I13: =IFERROR(I20/I8,0)
B14: A&P / case | C14: ='Assumptions'!C26 | D14: ='Assumptions'!D26 | E14: ='Assumptions'!E26 | F14: ='Assumptions'!F26 | G14: ='Assumptions'!G26 | H14: ='Assumptions'!H26 | I14: =IFERROR(I24/I8,0)
B15: P&L ($)
B16: Gross Revenue | C16: =C8*C10 | D16: =D8*D10 | E16: =E8*E10 | F16: =F8*F10 | G16: =G8*G10 | H16: =H8*H10 | I16: =SUM(C16:H16)
B17: Trade Discounts | C17: =C16*C11 | D17: =D16*D11 | E17: =E16*E11 | F17: =F16*F11 | G17: =G16*G11 | H17: =H16*H11 | I17: =SUM(C17:H17)
B18: Net Sales | C18: =C16-C17 | D18: =D16-D17 | E18: =E16-E17 | F18: =F16-F17 | G18: =G16-G17 | H18: =H16-H17 | I18: =I16-I17
B19: COGS Direct | C19: =C8*C12 | D19: =D8*D12 | E19: =E8*E12 | F19: =F8*F12 | G19: =G8*G12 | H19: =H8*H12 | I19: =SUM(C19:H19)
B20: COGS Indirect | C20: =C8*C13 | D20: =D8*D13 | E20: =E8*E13 | F20: =F8*F13 | G20: =G8*G13 | H20: =H8*H13 | I20: =SUM(C20:H20)
B21: Cost of Sales | C21: =C19+C20 | D21: =D19+D20 | E21: =E19+E20 | F21: =F19+F20 | G21: =G19+G20 | H21: =H19+H20 | I21: =I19+I20
B22: Gross Profit | C22: =C18-C21 | D22: =D18-D21 | E22: =E18-E21 | F22: =F18-F21 | G22: =G18-G21 | H22: =H18-H21 | I22: =I18-I21
B23: GP % | C23: =IFERROR(C22/C18,0) | D23: =IFERROR(D22/D18,0) | E23: =IFERROR(E22/E18,0) | F23: =IFERROR(F22/F18,0) | G23: =IFERROR(G22/G18,0) | H23: =IFERROR(H22/H18,0) | I23: =IFERROR(I22/I18,0)
B24: A&P | C24: =C8*C14 | D24: =D8*D14 | E24: =E8*E14 | F24: =F8*F14 | G24: =G8*G14 | H24: =H8*H14 | I24: =SUM(C24:H24)
B25: Contribution Margin | C25: =C22-C24 | D25: =D22-D24 | E25: =E22-E24 | F25: =F22-F24 | G25: =G22-G24 | H25: =H22-H24 | I25: =I22-I24
B26: CM % | C26: =IFERROR(C25/C18,0) | D26: =IFERROR(D25/D18,0) | E26: =IFERROR(E25/E18,0) | F26: =IFERROR(F25/F18,0) | G26: =IFERROR(G25/G18,0) | H26: =IFERROR(H25/H18,0) | I26: =IFERROR(I25/I18,0)
B27: OPERATING EXPENSES & PROFIT (company total)
B28: Salaries & wages | I28: ='Assumptions'!$C$31
B29: G&A / overhead | I29: ='Assumptions'!$C$32
B30: Marketing overhead | I30: ='Assumptions'!$C$33
B31: Slotting / listing | I31: ='Assumptions'!$C$34
B32: Outbound logistics | I32: =I18*'Assumptions'!$C$35
B33: Total Operating Expenses | I33: =SUM(I28:I32)
B34: EBITDA | I34: =I25-I33
B35: EBITDA % | I35: =IFERROR(I34/I18,0)
B36: Depreciation & amort. | I36: ='Assumptions'!$C$36
B37: EBIT | I37: =I34-I36
B38: Interest | I38: ='Assumptions'!$C$37
B39: Pre-tax Profit (EBT) | I39: =I37-I38
B40: Tax | I40: =MAX(0,I39*'Assumptions'!$C$38)
B41: Net Income | I41: =I39-I40
...

Sheet Stretch
B1: Sparkling Daily - STRETCH Scenario (FY2026)
B2: Levers vs Base: Volume 160% • Price 105% • Trade-disc Δ -1% (all driven from Assumptions)
B3: CDN $. All figures calculate from the Assumptions tab - nothing here is hand-keyed.
C5: SINGLES | F5: 4-PACK | I5: TOTAL DAILY
B6: CDN $ | C6: Pineapple | D6: Passionfruit | E6: Lime Lemon | F6: Pineapple | G6: Passionfruit | H6: Lime Lemon
B7: VOLUME
B8: Physical Cases | C8: ='Assumptions'!C28*'Assumptions'!$C$49*('Assumptions'!$D$49^'Assumptions'!$C$39) | D8: ='Assumptions'!D28*'Assumptions'!$C$49*('Assumptions'!$D$49^'Assumptions'!$C$39) | E8: ='Assumptions'!E28*'Assumptions'!$C$49*('Assumptions'!$D$49^'Assumptions'!$C$39) | F8: ='Assumptions'!F28*'Assumptions'!$C$49*('Assumptions'!$D$49^'Assumptions'!$C$39) | G8: ='Assumptions'!G28*'Assumptions'!$C$49*('Assumptions'!$D$49^'Assumptions'!$C$39) | H8: ='Assumptions'!H28*'Assumptions'!$C$49*('Assumptions'!$D$49^'Assumptions'!$C$39) | I8: =SUM(C8:H8)
B9: PRICE & COST - PER CASE (from Assumptions x levers)
B10: CP - Gross Rev / case | C10: ='Assumptions'!C11*'Assumptions'!$D$49 | D10: ='Assumptions'!D11*'Assumptions'!$D$49 | E10: ='Assumptions'!E11*'Assumptions'!$D$49 | F10: ='Assumptions'!F11*'Assumptions'!$D$49 | G10: ='Assumptions'!G11*'Assumptions'!$D$49 | H10: ='Assumptions'!H11*'Assumptions'!$D$49 | I10: =IFERROR(I16/I8,0)
B11: Trade discount % | C11: ='Assumptions'!C12+'Assumptions'!$E$49 | D11: ='Assumptions'!D12+'Assumptions'!$E$49 | E11: ='Assumptions'!E12+'Assumptions'!$E$49 | F11: ='Assumptions'!F12+'Assumptions'!$E$49 | G11: ='Assumptions'!G12+'Assumptions'!$E$49 | H11: ='Assumptions'!H12+'Assumptions'!$E$49 | I11: =IFERROR(I17/I16,0)
B12: COGS Direct / case | C12: ='Assumptions'!C19 | D12: ='Assumptions'!D19 | E12: ='Assumptions'!E19 | F12: ='Assumptions'!F19 | G12: ='Assumptions'!G19 | H12: ='Assumptions'!H19 | I12: =IFERROR(I19/I8,0)
B13: COGS Indirect / case | C13: ='Assumptions'!C20 | D13: ='Assumptions'!D20 | E13: ='Assumptions'!E20 | F13: ='Assumptions'!F20 | G13: ='Assumptions'!G20 | H13: ='Assumptions'!H20 | I13: =IFERROR(I20/I8,0)
B14: A&P / case | C14: ='Assumptions'!C26 | D14: ='Assumptions'!D26 | E14: ='Assumptions'!E26 | F14: ='Assumptions'!F26 | G14: ='Assumptions'!G26 | H14: ='Assumptions'!H26 | I14: =IFERROR(I24/I8,0)
B15: P&L ($)
B16: Gross Revenue | C16: =C8*C10 | D16: =D8*D10 | E16: =E8*E10 | F16: =F8*F10 | G16: =G8*G10 | H16: =H8*H10 | I16: =SUM(C16:H16)
B17: Trade Discounts | C17: =C16*C11 | D17: =D16*D11 | E17: =E16*E11 | F17: =F16*F11 | G17: =G16*G11 | H17: =H16*H11 | I17: =SUM(C17:H17)
B18: Net Sales | C18: =C16-C17 | D18: =D16-D17 | E18: =E16-E17 | F18: =F16-F17 | G18: =G16-G17 | H18: =H16-H17 | I18: =I16-I17
B19: COGS Direct | C19: =C8*C12 | D19: =D8*D12 | E19: =E8*E12 | F19: =F8*F12 | G19: =G8*G12 | H19: =H8*H12 | I19: =SUM(C19:H19)
B20: COGS Indirect | C20: =C8*C13 | D20: =D8*D13 | E20: =E8*E13 | F20: =F8*F13 | G20: =G8*G13 | H20: =H8*H13 | I20: =SUM(C20:H20)
B21: Cost of Sales | C21: =C19+C20 | D21: =D19+D20 | E21: =E19+E20 | F21: =F19+F20 | G21: =G19+G20 | H21: =H19+H20 | I21: =I19+I20
B22: Gross Profit | C22: =C18-C21 | D22: =D18-D21 | E22: =E18-E21 | F22: =F18-F21 | G22: =G18-G21 | H22: =H18-H21 | I22: =I18-I21
B23: GP % | C23: =IFERROR(C22/C18,0) | D23: =IFERROR(D22/D18,0) | E23: =IFERROR(E22/E18,0) | F23: =IFERROR(F22/F18,0) | G23: =IFERROR(G22/G18,0) | H23: =IFERROR(H22/H18,0) | I23: =IFERROR(I22/I18,0)
B24: A&P | C24: =C8*C14 | D24: =D8*D14 | E24: =E8*E14 | F24: =F8*F14 | G24: =G8*G14 | H24: =H8*H14 | I24: =SUM(C24:H24)
B25: Contribution Margin | C25: =C22-C24 | D25: =D22-D24 | E25: =E22-E24 | F25: =F22-F24 | G25: =G22-G24 | H25: =H22-H24 | I25: =I22-I24
B26: CM % | C26: =IFERROR(C25/C18,0) | D26: =IFERROR(D25/D18,0) | E26: =IFERROR(E25/E18,0) | F26: =IFERROR(F25/F18,0) | G26: =IFERROR(G25/G18,0) | H26: =IFERROR(H25/H18,0) | I26: =IFERROR(I25/I18,0)
B27: OPERATING EXPENSES & PROFIT (company total)
B28: Salaries & wages | I28: ='Assumptions'!$C$31
B29: G&A / overhead | I29: ='Assumptions'!$C$32
B30: Marketing overhead | I30: ='Assumptions'!$C$33
B31: Slotting / listing | I31: ='Assumptions'!$C$34
B32: Outbound logistics | I32: =I18*'Assumptions'!$C$35
B33: Total Operating Expenses | I33: =SUM(I28:I32)
B34: EBITDA | I34: =I25-I33
B35: EBITDA % | I35: =IFERROR(I34/I18,0)
B36: Depreciation & amort. | I36: ='Assumptions'!$C$36
B37: EBIT | I37: =I34-I36
B38: Interest | I38: ='Assumptions'!$C$37
B39: Pre-tax Profit (EBT) | I39: =I37-I38
B40: Tax | I40: =MAX(0,I39*'Assumptions'!$C$38)
B41: Net Income | I41: =I39-I40
...

Sheet Monthly
B1: Sparkling Daily - Monthly Phasing (FY2026)
B2: Pick a scenario; volume-driven lines follow the seasonality curve, fixed costs spread evenly.
B4: Scenario: | C4: Base | D4: ← change me
B6: CDN $ | C6: Jan | D6: Feb | E6: Mar | F6: Apr | G6: May | H6: Jun | I6: Jul | J6: Aug | K6: Sep | L6: Oct | M6: Nov | N6: Dec | O6: FY
B7: Physical Cases | C7: =INDIRECT("'"&$C$4&"'!I8")*'Assumptions'!C$53 | D7: =INDIRECT("'"&$C$4&"'!I8")*'Assumptions'!D$53 | E7: =INDIRECT("'"&$C$4&"'!I8")*'Assumptions'!E$53 | F7: =INDIRECT("'"&$C$4&"'!I8")*'Assumptions'!F$53 | G7: =INDIRECT("'"&$C$4&"'!I8")*'Assumptions'!G$53 | H7: =INDIRECT("'"&$C$4&"'!I8")*'Assumptions'!H$53 | I7: =INDIRECT("'"&$C$4&"'!I8")*'Assumptions'!I$53 | J7: =INDIRECT("'"&$C$4&"'!I8")*'Assumptions'!J$53 | ... N7: =INDIRECT("'"&$C$4&"'!I8")*'Assumptions'!N$53 | O7: =SUM(C7:N7)
B8: Net Sales | C8: =INDIRECT("'"&$C$4&"'!I18")*'Assumptions'!C$53 | D8: =INDIRECT("'"&$C$4&"'!I18")*'Assumptions'!D$53 | E8: =INDIRECT("'"&$C$4&"'!I18")*'Assumptions'!E$53 | F8: =INDIRECT("'"&$C$4&"'!I18")*'Assumptions'!F$53 | G8: =INDIRECT("'"&$C$4&"'!I18")*'Assumptions'!G$53 | H8: =INDIRECT("'"&$C$4&"'!I18")*'Assumptions'!H$53 | I8: =INDIRECT("'"&$C$4&"'!I18")*'Assumptions'!I$53 | J8: =INDIRECT("'"&$C$4&"'!I18")*'Assumptions'!J$53 | ... N8: =INDIRECT("'"&$C$4&"'!I18")*'Assumptions'!N$53 | O8: =SUM(C8:N8)
B9: Gross Profit | C9: =INDIRECT("'"&$C$4&"'!I22")*'Assumptions'!C$53 | D9: =INDIRECT("'"&$C$4&"'!I22")*'Assumptions'!D$53 | E9: =INDIRECT("'"&$C$4&"'!I22")*'Assumptions'!E$53 | F9: =INDIRECT("'"&$C$4&"'!I22")*'Assumptions'!F$53 | G9: =INDIRECT("'"&$C$4&"'!I22")*'Assumptions'!G$53 | H9: =INDIRECT("'"&$C$4&"'!I22")*'Assumptions'!H$53 | I9: =INDIRECT("'"&$C$4&"'!I22")*'Assumptions'!I$53 | J9: =INDIRECT("'"&$C$4&"'!I22")*'Assumptions'!J$53 | ... N9: =INDIRECT("'"&$C$4&"'!I22")*'Assumptions'!N$53 | O9: =SUM(C9:N9)
B10: A&P | C10: =INDIRECT("'"&$C$4&"'!I24")*'Assumptions'!C$53 | D10: =INDIRECT("'"&$C$4&"'!I24")*'Assumptions'!D$53 | E10: =INDIRECT("'"&$C$4&"'!I24")*'Assumptions'!E$53 | F10: =INDIRECT("'"&$C$4&"'!I24")*'Assumptions'!F$53 | G10: =INDIRECT("'"&$C$4&"'!I24")*'Assumptions'!G$53 | H10: =INDIRECT("'"&$C$4&"'!I24")*'Assumptions'!H$53 | I10: =INDIRECT("'"&$C$4&"'!I24")*'Assumptions'!I$53 | J10: =INDIRECT("'"&$C$4&"'!I24")*'Assumptions'!J$53 | ... N10: =INDIRECT("'"&$C$4&"'!I24")*'Assumptions'!N$53 | O10: =SUM(C10:N10)
B11: Contribution Margin | C11: =INDIRECT("'"&$C$4&"'!I25")*'Assumptions'!C$53 | D11: =INDIRECT("'"&$C$4&"'!I25")*'Assumptions'!D$53 | E11: =INDIRECT("'"&$C$4&"'!I25")*'Assumptions'!E$53 | F11: =INDIRECT("'"&$C$4&"'!I25")*'Assumptions'!F$53 | G11: =INDIRECT("'"&$C$4&"'!I25")*'Assumptions'!G$53 | H11: =INDIRECT("'"&$C$4&"'!I25")*'Assumptions'!H$53 | I11: =INDIRECT("'"&$C$4&"'!I25")*'Assumptions'!I$53 | J11: =INDIRECT("'"&$C$4&"'!I25")*'Assumptions'!J$53 | ... N11: =INDIRECT("'"&$C$4&"'!I25")*'Assumptions'!N$53 | O11: =SUM(C11:N11)
B12: Outbound logistics | C12: =C8*'Assumptions'!$C$35 | D12: =D8*'Assumptions'!$C$35 | E12: =E8*'Assumptions'!$C$35 | F12: =F8*'Assumptions'!$C$35 | G12: =G8*'Assumptions'!$C$35 | H12: =H8*'Assumptions'!$C$35 | I12: =I8*'Assumptions'!$C$35 | J12: =J8*'Assumptions'!$C$35 | ... N12: =N8*'Assumptions'!$C$35 | O12: =SUM(C12:N12)
B13: Fixed opex (salaries, G&A, mktg, slotting) | C13: =('Assumptions'!$C$31+'Assumptions'!$C$32+'Assumptions'!$C$33+'Assumptions'!$C$34)/12 | D13: =('Assumptions'!$C$31+'Assumptions'!$C$32+'Assumptions'!$C$33+'Assumptions'!$C$34)/12 | E13: =('Assumptions'!$C$31+'Assumptions'!$C$32+'Assumptions'!$C$33+'Assumptions'!$C$34)/12 | F13: =('Assumptions'!$C$31+'Assumptions'!$C$32+'Assumptions'!$C$33+'Assumptions'!$C$34)/12 | G13: =('Assumptions'!$C$31+'Assumptions'!$C$32+'Assumptions'!$C$33+'Assumptions'!$C$34)/12 | H13: =('Assumptions'!$C$31+'Assumptions'!$C$32+'Assumptions'!$C$33+'Assumptions'!$C$34)/12 | I13: =('Assumptions'!$C$31+'Assumptions'!$C$32+'Assumptions'!$C$33+'Assumptions'!$C$34)/12 | J13: =('Assumptions'!$C$31+'Assumptions'!$C$32+'Assumptions'!$C$33+'Assumptions'!$C$34)/12 | ... N13: =('Assumptions'!$C$31+'Assumptions'!$C$32+'Assumptions'!$C$33+'Assumptions'!$C$34)/12 | O13: =SUM(C13:N13)
B14: EBITDA | C14: =C11-C12-C13 | D14: =D11-D12-D13 | E14: =E11-E12-E13 | F14: =F11-F12-F13 | G14: =G11-G12-G13 | H14: =H11-H12-H13 | I14: =I11-I12-I13 | J14: =J11-J12-J13 | ... N14: =N11-N12-N13 | O14: =SUM(C14:N14)
B15: Depreciation & amort. | C15: ='Assumptions'!$C$36/12 | D15: ='Assumptions'!$C$36/12 | E15: ='Assumptions'!$C$36/12 | F15: ='Assumptions'!$C$36/12 | G15: ='Assumptions'!$C$36/12 | H15: ='Assumptions'!$C$36/12 | I15: ='Assumptions'!$C$36/12 | J15: ='Assumptions'!$C$36/12 | ... N15: ='Assumptions'!$C$36/12 | O15: =SUM(C15:N15)
B16: EBIT | C16: =C14-C15 | D16: =D14-D15 | E16: =E14-E15 | F16: =F14-F15 | G16: =G14-G15 | H16: =H14-H15 | I16: =I14-I15 | J16: =J14-J15 | ... N16: =N14-N15 | O16: =SUM(C16:N16)
B17: Interest | C17: ='Assumptions'!$C$37/12 | D17: ='Assumptions'!$C$37/12 | E17: ='Assumptions'!$C$37/12 | F17: ='Assumptions'!$C$37/12 | G17: ='Assumptions'!$C$37/12 | H17: ='Assumptions'!$C$37/12 | I17: ='Assumptions'!$C$37/12 | J17: ='Assumptions'!$C$37/12 | ... N17: ='Assumptions'!$C$37/12 | O17: =SUM(C17:N17)
B18: Pre-tax Profit | C18: =C16-C17 | D18: =D16-D17 | E18: =E16-E17 | F18: =F16-F17 | G18: =G16-G17 | H18: =H16-H17 | I18: =I16-I17 | J18: =J16-J17 | ... N18: =N16-N17 | O18: =SUM(C18:N18)
B19: Tax | C19: =MAX(0,C18*'Assumptions'!$C$38) | D19: =MAX(0,D18*'Assumptions'!$C$38) | E19: =MAX(0,E18*'Assumptions'!$C$38) | F19: =MAX(0,F18*'Assumptions'!$C$38) | G19: =MAX(0,G18*'Assumptions'!$C$38) | H19: =MAX(0,H18*'Assumptions'!$C$38) | I19: =MAX(0,I18*'Assumptions'!$C$38) | J19: =MAX(0,J18*'Assumptions'!$C$38) | ... N19: =MAX(0,N18*'Assumptions'!$C$38) | O19: =SUM(C19:N19)
B20: Net Income | C20: =C18-C19 | D20: =D18-D19 | E20: =E18-E19 | F20: =F18-F19 | G20: =G18-G19 | H20: =H18-H19 | I20: =I18-I19 | J20: =J18-J19 | ... N20: =N18-N19 | O20: =SUM(C20:N20)
B21: Cumulative Net Income | C21: =C20 | D21: =C21+D20 | E21: =D21+E20 | F21: =E21+F20 | G21: =F21+G20 | H21: =G21+H20 | I21: =H21+I20 | J21: =I21+J20 | K21: =J21+K20 | ... N21: =M21+N20 | O21: =N21

Sheet 3-Year
B1: Sparkling Daily - 3-Year Projection
B2: Grows the base year by the growth rates on Assumptions. Year 1 = base year, unlevered.
B4: Kgr base net (Σ vol·cp·(1-d)) | C4: =SUMPRODUCT('Assumptions'!C28:H28,'Assumptions'!C11:H11,(1-'Assumptions'!C12:H12))
B5: Kcos base COGS (Σ vol·COS/case) | C5: =SUMPRODUCT('Assumptions'!C28:H28,'Assumptions'!C21:H21)
B6: Kap base A&P (Σ vol·A&P/case) | C6: =SUMPRODUCT('Assumptions'!C28:H28,'Assumptions'!C26:H26)
B7: Fixed opex | C7: ='Assumptions'!C31+'Assumptions'!C32+'Assumptions'!C33+'Assumptions'!C34
B8: Logistics % of net | C8: ='Assumptions'!C35
B9: Base total cases | C9: =SUM('Assumptions'!C28:H28)
B12: 3-Year (CDN $) | C12: Year 1 | D12: Year 2 | E12: Year 3 | F12: CAGR
B13: Physical Cases | C13: =(1+'Assumptions'!$C$40)^0*$C$9 | D13: =(1+'Assumptions'!$C$40)^1*$C$9 | E13: =(1+'Assumptions'!$C$40)^2*$C$9 | F13: =IFERROR((E13/C13)^(1/2)-1,"")
B14: Net Sales | C14: =(1+'Assumptions'!$C$40)^0*(1+'Assumptions'!$C$41)^0*$C$4 | D14: =(1+'Assumptions'!$C$40)^1*(1+'Assumptions'!$C$41)^1*$C$4 | E14: =(1+'Assumptions'!$C$40)^2*(1+'Assumptions'!$C$41)^2*$C$4 | F14: =IFERROR((E14/C14)^(1/2)-1,"")
B15: Cost of Sales | C15: =(1+'Assumptions'!$C$40)^0*(1+'Assumptions'!$C$42)^0*$C$5 | D15: =(1+'Assumptions'!$C$40)^1*(1+'Assumptions'!$C$42)^1*$C$5 | E15: =(1+'Assumptions'!$C$40)^2*(1+'Assumptions'!$C$42)^2*$C$5 | F15: =IFERROR((E15/C15)^(1/2)-1,"")
B16: Gross Profit | C16: =C14-C15 | D16: =D14-D15 | E16: =E14-E15 | F16: =IFERROR((E16/C16)^(1/2)-1,"")
B17: GP % | C17: =IFERROR(C16/C14,0) | D17: =IFERROR(D16/D14,0) | E17: =IFERROR(E16/E14,0)
B18: A&P | C18: =(1+'Assumptions'!$C$40)^0*$C$6 | D18: =(1+'Assumptions'!$C$40)^1*$C$6 | E18: =(1+'Assumptions'!$C$40)^2*$C$6 | F18: =IFERROR((E18/C18)^(1/2)-1,"")
B19: Contribution | C19: =C16-C18 | D19: =D16-D18 | E19: =E16-E18 | F19: =IFERROR((E19/C19)^(1/2)-1,"")
B20: Logistics | C20: =$C$8*C14 | D20: =$C$8*D14 | E20: =$C$8*E14 | F20: =IFERROR((E20/C20)^(1/2)-1,"")
B21: Fixed opex | C21: =$C$7 | D21: =$C$7 | E21: =$C$7 | F21: =IFERROR((E21/C21)^(1/2)-1,"")
B22: EBITDA | C22: =C19-C20-C21 | D22: =D19-D20-D21 | E22: =E19-E20-E21 | F22: =IFERROR((E22/C22)^(1/2)-1,"")
B23: EBITDA % | C23: =IFERROR(C22/C14,0) | D23: =IFERROR(D22/D14,0) | E23: =IFERROR(E22/E14,0)
B24: D&A | C24: ='Assumptions'!$C$36 | D24: ='Assumptions'!$C$36 | E24: ='Assumptions'!$C$36 | F24: =IFERROR((E24/C24)^(1/2)-1,"")
B25: EBIT | C25: =C22-C24 | D25: =D22-D24 | E25: =E22-E24 | F25: =IFERROR((E25/C25)^(1/2)-1,"")
B26: Interest | C26: ='Assumptions'!$C$37 | D26: ='Assumptions'!$C$37 | E26: ='Assumptions'!$C$37 | F26: =IFERROR((E26/C26)^(1/2)-1,"")
B27: Pre-tax Profit | C27: =C25-C26 | D27: =D25-D26 | E27: =E25-E26 | F27: =IFERROR((E27/C27)^(1/2)-1,"")
B28: Tax | C28: =MAX(0,C27*'Assumptions'!$C$38) | D28: =MAX(0,D27*'Assumptions'!$C$38) | E28: =MAX(0,E27*'Assumptions'!$C$38) | F28: =IFERROR((E28/C28)^(1/2)-1,"")
B29: Net Income | C29: =C27-C28 | D29: =D27-D28 | E29: =E27-E28 | F29: =IFERROR((E29/C29)^(1/2)-1,"")
B31: Year 1 = base year. Years 2-3 compound the growth rates. CAGR = annual growth across the 3 years.

Sheet Pricing Lab
B1: Sparkling Daily - Pricing Lab (FY2026)
B2: How wholesale price (CP) drives margin. Each column flexes every SKU's CP vs its Assumptions base; volume & costs held at base.
B4: Gross Profit % (by SKU, by CP)
B5: SKU \ CP vs base | C5: 0.85 | D5: 0.9 | E5: 0.95 | F5: 1 | G5: 1.05 | H5: 1.1 | I5: 1.15
B6: Pineapple Singles | C6: =IFERROR(1-'Assumptions'!$C$21/('Assumptions'!$C$11*C$5*(1-'Assumptions'!$C$12)),0) | D6: =IFERROR(1-'Assumptions'!$C$21/('Assumptions'!$C$11*D$5*(1-'Assumptions'!$C$12)),0) | E6: =IFERROR(1-'Assumptions'!$C$21/('Assumptions'!$C$11*E$5*(1-'Assumptions'!$C$12)),0) | F6: =IFERROR(1-'Assumptions'!$C$21/('Assumptions'!$C$11*F$5*(1-'Assumptions'!$C$12)),0) | G6: =IFERROR(1-'Assumptions'!$C$21/('Assumptions'!$C$11*G$5*(1-'Assumptions'!$C$12)),0) | H6: =IFERROR(1-'Assumptions'!$C$21/('Assumptions'!$C$11*H$5*(1-'Assumptions'!$C$12)),0) | I6: =IFERROR(1-'Assumptions'!$C$21/('Assumptions'!$C$11*I$5*(1-'Assumptions'!$C$12)),0)
B7: Passionfruit Singles | C7: =IFERROR(1-'Assumptions'!$D$21/('Assumptions'!$D$11*C$5*(1-'Assumptions'!$D$12)),0) | D7: =IFERROR(1-'Assumptions'!$D$21/('Assumptions'!$D$11*D$5*(1-'Assumptions'!$D$12)),0) | E7: =IFERROR(1-'Assumptions'!$D$21/('Assumptions'!$D$11*E$5*(1-'Assumptions'!$D$12)),0) | F7: =IFERROR(1-'Assumptions'!$D$21/('Assumptions'!$D$11*F$5*(1-'Assumptions'!$D$12)),0) | G7: =IFERROR(1-'Assumptions'!$D$21/('Assumptions'!$D$11*G$5*(1-'Assumptions'!$D$12)),0) | H7: =IFERROR(1-'Assumptions'!$D$21/('Assumptions'!$D$11*H$5*(1-'Assumptions'!$D$12)),0) | I7: =IFERROR(1-'Assumptions'!$D$21/('Assumptions'!$D$11*I$5*(1-'Assumptions'!$D$12)),0)
B8: Lime Lemon Singles | C8: =IFERROR(1-'Assumptions'!$E$21/('Assumptions'!$E$11*C$5*(1-'Assumptions'!$E$12)),0) | D8: =IFERROR(1-'Assumptions'!$E$21/('Assumptions'!$E$11*D$5*(1-'Assumptions'!$E$12)),0) | E8: =IFERROR(1-'Assumptions'!$E$21/('Assumptions'!$E$11*E$5*(1-'Assumptions'!$E$12)),0) | F8: =IFERROR(1-'Assumptions'!$E$21/('Assumptions'!$E$11*F$5*(1-'Assumptions'!$E$12)),0) | G8: =IFERROR(1-'Assumptions'!$E$21/('Assumptions'!$E$11*G$5*(1-'Assumptions'!$E$12)),0) | H8: =IFERROR(1-'Assumptions'!$E$21/('Assumptions'!$E$11*H$5*(1-'Assumptions'!$E$12)),0) | I8: =IFERROR(1-'Assumptions'!$E$21/('Assumptions'!$E$11*I$5*(1-'Assumptions'!$E$12)),0)
B9: Pineapple 4-Pack | C9: =IFERROR(1-'Assumptions'!$F$21/('Assumptions'!$F$11*C$5*(1-'Assumptions'!$F$12)),0) | D9: =IFERROR(1-'Assumptions'!$F$21/('Assumptions'!$F$11*D$5*(1-'Assumptions'!$F$12)),0) | E9: =IFERROR(1-'Assumptions'!$F$21/('Assumptions'!$F$11*E$5*(1-'Assumptions'!$F$12)),0) | F9: =IFERROR(1-'Assumptions'!$F$21/('Assumptions'!$F$11*F$5*(1-'Assumptions'!$F$12)),0) | G9: =IFERROR(1-'Assumptions'!$F$21/('Assumptions'!$F$11*G$5*(1-'Assumptions'!$F$12)),0) | H9: =IFERROR(1-'Assumptions'!$F$21/('Assumptions'!$F$11*H$5*(1-'Assumptions'!$F$12)),0) | I9: =IFERROR(1-'Assumptions'!$F$21/('Assumptions'!$F$11*I$5*(1-'Assumptions'!$F$12)),0)
B10: Passionfruit 4-Pack | C10: =IFERROR(1-'Assumptions'!$G$21/('Assumptions'!$G$11*C$5*(1-'Assumptions'!$G$12)),0) | D10: =IFERROR(1-'Assumptions'!$G$21/('Assumptions'!$G$11*D$5*(1-'Assumptions'!$G$12)),0) | E10: =IFERROR(1-'Assumptions'!$G$21/('Assumptions'!$G$11*E$5*(1-'Assumptions'!$G$12)),0) | F10: =IFERROR(1-'Assumptions'!$G$21/('Assumptions'!$G$11*F$5*(1-'Assumptions'!$G$12)),0) | G10: =IFERROR(1-'Assumptions'!$G$21/('Assumptions'!$G$11*G$5*(1-'Assumptions'!$G$12)),0) | H10: =IFERROR(1-'Assumptions'!$G$21/('Assumptions'!$G$11*H$5*(1-'Assumptions'!$G$12)),0) | I10: =IFERROR(1-'Assumptions'!$G$21/('Assumptions'!$G$11*I$5*(1-'Assumptions'!$G$12)),0)
B11: Lime Lemon 4-Pack | C11: =IFERROR(1-'Assumptions'!$H$21/('Assumptions'!$H$11*C$5*(1-'Assumptions'!$H$12)),0) | D11: =IFERROR(1-'Assumptions'!$H$21/('Assumptions'!$H$11*D$5*(1-'Assumptions'!$H$12)),0) | E11: =IFERROR(1-'Assumptions'!$H$21/('Assumptions'!$H$11*E$5*(1-'Assumptions'!$H$12)),0) | F11: =IFERROR(1-'Assumptions'!$H$21/('Assumptions'!$H$11*F$5*(1-'Assumptions'!$H$12)),0) | G11: =IFERROR(1-'Assumptions'!$H$21/('Assumptions'!$H$11*G$5*(1-'Assumptions'!$H$12)),0) | H11: =IFERROR(1-'Assumptions'!$H$21/('Assumptions'!$H$11*H$5*(1-'Assumptions'!$H$12)),0) | I11: =IFERROR(1-'Assumptions'!$H$21/('Assumptions'!$H$11*I$5*(1-'Assumptions'!$H$12)),0)
B14: Annual Contribution $ (by SKU, by CP — demand-adjusted)
B15: SKU \ CP vs base | C15: 0.85 | D15: 0.9 | E15: 0.95 | F15: 1 | G15: 1.05 | H15: 1.1 | I15: 1.15 | K15: Best CP ×
B16: Pineapple Singles | C16: ='Assumptions'!$C$28*(C$15^'Assumptions'!$C$39)*(('Assumptions'!$C$11*C$15*(1-'Assumptions'!$C$12))-'Assumptions'!$C$21-'Assumptions'!$C$26) | D16: ='Assumptions'!$C$28*(D$15^'Assumptions'!$C$39)*(('Assumptions'!$C$11*D$15*(1-'Assumptions'!$C$12))-'Assumptions'!$C$21-'Assumptions'!$C$26) | E16: ='Assumptions'!$C$28*(E$15^'Assumptions'!$C$39)*(('Assumptions'!$C$11*E$15*(1-'Assumptions'!$C$12))-'Assumptions'!$C$21-'Assumptions'!$C$26) | F16: ='Assumptions'!$C$28*(F$15^'Assumptions'!$C$39)*(('Assumptions'!$C$11*F$15*(1-'Assumptions'!$C$12))-'Assumptions'!$C$21-'Assumptions'!$C$26) | G16: ='Assumptions'!$C$28*(G$15^'Assumptions'!$C$39)*(('Assumptions'!$C$11*G$15*(1-'Assumptions'!$C$12))-'Assumptions'!$C$21-'Assumptions'!$C$26) | H16: ='Assumptions'!$C$28*(H$15^'Assumptions'!$C$39)*(('Assumptions'!$C$11*H$15*(1-'Assumptions'!$C$12))-'Assumptions'!$C$21-'Assumptions'!$C$26) | I16: ='Assumptions'!$C$28*(I$15^'Assumptions'!$C$39)*(('Assumptions'!$C$11*I$15*(1-'Assumptions'!$C$12))-'Assumptions'!$C$21-'Assumptions'!$C$26) | K16: =INDEX($C$15:$I$15,MATCH(MAX(C16:I16),C16:I16,0))
B17: Passionfruit Singles | C17: ='Assumptions'!$D$28*(C$15^'Assumptions'!$C$39)*(('Assumptions'!$D$11*C$15*(1-'Assumptions'!$D$12))-'Assumptions'!$D$21-'Assumptions'!$D$26) | D17: ='Assumptions'!$D$28*(D$15^'Assumptions'!$C$39)*(('Assumptions'!$D$11*D$15*(1-'Assumptions'!$D$12))-'Assumptions'!$D$21-'Assumptions'!$D$26) | E17: ='Assumptions'!$D$28*(E$15^'Assumptions'!$C$39)*(('Assumptions'!$D$11*E$15*(1-'Assumptions'!$D$12))-'Assumptions'!$D$21-'Assumptions'!$D$26) | F17: ='Assumptions'!$D$28*(F$15^'Assumptions'!$C$39)*(('Assumptions'!$D$11*F$15*(1-'Assumptions'!$D$12))-'Assumptions'!$D$21-'Assumptions'!$D$26) | G17: ='Assumptions'!$D$28*(G$15^'Assumptions'!$C$39)*(('Assumptions'!$D$11*G$15*(1-'Assumptions'!$D$12))-'Assumptions'!$D$21-'Assumptions'!$D$26) | H17: ='Assumptions'!$D$28*(H$15^'Assumptions'!$C$39)*(('Assumptions'!$D$11*H$15*(1-'Assumptions'!$D$12))-'Assumptions'!$D$21-'Assumptions'!$D$26) | I17: ='Assumptions'!$D$28*(I$15^'Assumptions'!$C$39)*(('Assumptions'!$D$11*I$15*(1-'Assumptions'!$D$12))-'Assumptions'!$D$21-'Assumptions'!$D$26) | K17: =INDEX($C$15:$I$15,MATCH(MAX(C17:I17),C17:I17,0))
B18: Lime Lemon Singles | C18: ='Assumptions'!$E$28*(C$15^'Assumptions'!$C$39)*(('Assumptions'!$E$11*C$15*(1-'Assumptions'!$E$12))-'Assumptions'!$E$21-'Assumptions'!$E$26) | D18: ='Assumptions'!$E$28*(D$15^'Assumptions'!$C$39)*(('Assumptions'!$E$11*D$15*(1-'Assumptions'!$E$12))-'Assumptions'!$E$21-'Assumptions'!$E$26) | E18: ='Assumptions'!$E$28*(E$15^'Assumptions'!$C$39)*(('Assumptions'!$E$11*E$15*(1-'Assumptions'!$E$12))-'Assumptions'!$E$21-'Assumptions'!$E$26) | F18: ='Assumptions'!$E$28*(F$15^'Assumptions'!$C$39)*(('Assumptions'!$E$11*F$15*(1-'Assumptions'!$E$12))-'Assumptions'!$E$21-'Assumptions'!$E$26) | G18: ='Assumptions'!$E$28*(G$15^'Assumptions'!$C$39)*(('Assumptions'!$E$11*G$15*(1-'Assumptions'!$E$12))-'Assumptions'!$E$21-'Assumptions'!$E$26) | H18: ='Assumptions'!$E$28*(H$15^'Assumptions'!$C$39)*(('Assumptions'!$E$11*H$15*(1-'Assumptions'!$E$12))-'Assumptions'!$E$21-'Assumptions'!$E$26) | I18: ='Assumptions'!$E$28*(I$15^'Assumptions'!$C$39)*(('Assumptions'!$E$11*I$15*(1-'Assumptions'!$E$12))-'Assumptions'!$E$21-'Assumptions'!$E$26) | K18: =INDEX($C$15:$I$15,MATCH(MAX(C18:I18),C18:I18,0))
B19: Pineapple 4-Pack | C19: ='Assumptions'!$F$28*(C$15^'Assumptions'!$C$39)*(('Assumptions'!$F$11*C$15*(1-'Assumptions'!$F$12))-'Assumptions'!$F$21-'Assumptions'!$F$26) | D19: ='Assumptions'!$F$28*(D$15^'Assumptions'!$C$39)*(('Assumptions'!$F$11*D$15*(1-'Assumptions'!$F$12))-'Assumptions'!$F$21-'Assumptions'!$F$26) | E19: ='Assumptions'!$F$28*(E$15^'Assumptions'!$C$39)*(('Assumptions'!$F$11*E$15*(1-'Assumptions'!$F$12))-'Assumptions'!$F$21-'Assumptions'!$F$26) | F19: ='Assumptions'!$F$28*(F$15^'Assumptions'!$C$39)*(('Assumptions'!$F$11*F$15*(1-'Assumptions'!$F$12))-'Assumptions'!$F$21-'Assumptions'!$F$26) | G19: ='Assumptions'!$F$28*(G$15^'Assumptions'!$C$39)*(('Assumptions'!$F$11*G$15*(1-'Assumptions'!$F$12))-'Assumptions'!$F$21-'Assumptions'!$F$26) | H19: ='Assumptions'!$F$28*(H$15^'Assumptions'!$C$39)*(('Assumptions'!$F$11*H$15*(1-'Assumptions'!$F$12))-'Assumptions'!$F$21-'Assumptions'!$F$26) | I19: ='Assumptions'!$F$28*(I$15^'Assumptions'!$C$39)*(('Assumptions'!$F$11*I$15*(1-'Assumptions'!$F$12))-'Assumptions'!$F$21-'Assumptions'!$F$26) | K19: =INDEX($C$15:$I$15,MATCH(MAX(C19:I19),C19:I19,0))
B20: Passionfruit 4-Pack | C20: ='Assumptions'!$G$28*(C$15^'Assumptions'!$C$39)*(('Assumptions'!$G$11*C$15*(1-'Assumptions'!$G$12))-'Assumptions'!$G$21-'Assumptions'!$G$26) | D20: ='Assumptions'!$G$28*(D$15^'Assumptions'!$C$39)*(('Assumptions'!$G$11*D$15*(1-'Assumptions'!$G$12))-'Assumptions'!$G$21-'Assumptions'!$G$26) | E20: ='Assumptions'!$G$28*(E$15^'Assumptions'!$C$39)*(('Assumptions'!$G$11*E$15*(1-'Assumptions'!$G$12))-'Assumptions'!$G$21-'Assumptions'!$G$26) | F20: ='Assumptions'!$G$28*(F$15^'Assumptions'!$C$39)*(('Assumptions'!$G$11*F$15*(1-'Assumptions'!$G$12))-'Assumptions'!$G$21-'Assumptions'!$G$26) | G20: ='Assumptions'!$G$28*(G$15^'Assumptions'!$C$39)*(('Assumptions'!$G$11*G$15*(1-'Assumptions'!$G$12))-'Assumptions'!$G$21-'Assumptions'!$G$26) | H20: ='Assumptions'!$G$28*(H$15^'Assumptions'!$C$39)*(('Assumptions'!$G$11*H$15*(1-'Assumptions'!$G$12))-'Assumptions'!$G$21-'Assumptions'!$G$26) | I20: ='Assumptions'!$G$28*(I$15^'Assumptions'!$C$39)*(('Assumptions'!$G$11*I$15*(1-'Assumptions'!$G$12))-'Assumptions'!$G$21-'Assumptions'!$G$26) | K20: =INDEX($C$15:$I$15,MATCH(MAX(C20:I20),C20:I20,0))
B21: Lime Lemon 4-Pack | C21: ='Assumptions'!$H$28*(C$15^'Assumptions'!$C$39)*(('Assumptions'!$H$11*C$15*(1-'Assumptions'!$H$12))-'Assumptions'!$H$21-'Assumptions'!$H$26) | D21: ='Assumptions'!$H$28*(D$15^'Assumptions'!$C$39)*(('Assumptions'!$H$11*D$15*(1-'Assumptions'!$H$12))-'Assumptions'!$H$21-'Assumptions'!$H$26) | E21: ='Assumptions'!$H$28*(E$15^'Assumptions'!$C$39)*(('Assumptions'!$H$11*E$15*(1-'Assumptions'!$H$12))-'Assumptions'!$H$21-'Assumptions'!$H$26) | F21: ='Assumptions'!$H$28*(F$15^'Assumptions'!$C$39)*(('Assumptions'!$H$11*F$15*(1-'Assumptions'!$H$12))-'Assumptions'!$H$21-'Assumptions'!$H$26) | G21: ='Assumptions'!$H$28*(G$15^'Assumptions'!$C$39)*(('Assumptions'!$H$11*G$15*(1-'Assumptions'!$H$12))-'Assumptions'!$H$21-'Assumptions'!$H$26) | H21: ='Assumptions'!$H$28*(H$15^'Assumptions'!$C$39)*(('Assumptions'!$H$11*H$15*(1-'Assumptions'!$H$12))-'Assumptions'!$H$21-'Assumptions'!$H$26) | I21: ='Assumptions'!$H$28*(I$15^'Assumptions'!$C$39)*(('Assumptions'!$H$11*I$15*(1-'Assumptions'!$H$12))-'Assumptions'!$H$21-'Assumptions'!$H$26) | K21: =INDEX($C$15:$I$15,MATCH(MAX(C21:I21),C21:I21,0))

Sheet Unit Economics
B1: Sparkling Daily - Unit Economics & Retail Price (FY2026)
B2: Per-unit view of each SKU, plus the suggested shelf price at your retailer's margin.
B4: Retailer margin | C4: 0.35 | D4: shelf price = wholesale unit price / (1 - margin)
B6: Per unit (CDN $) | C6: Pineapple | D6: Passionfruit | E6: Lime Lemon | F6: Pineapple | G6: Passionfruit | H6: Lime Lemon
B7: Units per case | C7: ='Assumptions'!C9 | D7: ='Assumptions'!D9 | E7: ='Assumptions'!E9 | F7: ='Assumptions'!F9 | G7: ='Assumptions'!G9 | H7: ='Assumptions'!H9
B8: Wholesale (CP) / unit | C8: =IFERROR('Assumptions'!C11/'Assumptions'!C9,0) | D8: =IFERROR('Assumptions'!D11/'Assumptions'!D9,0) | E8: =IFERROR('Assumptions'!E11/'Assumptions'!E9,0) | F8: =IFERROR('Assumptions'!F11/'Assumptions'!F9,0) | G8: =IFERROR('Assumptions'!G11/'Assumptions'!G9,0) | H8: =IFERROR('Assumptions'!H11/'Assumptions'!H9,0)
B9: Net / unit (after disc) | C9: =IFERROR('Assumptions'!C11*(1-'Assumptions'!C12)/'Assumptions'!C9,0) | D9: =IFERROR('Assumptions'!D11*(1-'Assumptions'!D12)/'Assumptions'!D9,0) | E9: =IFERROR('Assumptions'!E11*(1-'Assumptions'!E12)/'Assumptions'!E9,0) | F9: =IFERROR('Assumptions'!F11*(1-'Assumptions'!F12)/'Assumptions'!F9,0) | G9: =IFERROR('Assumptions'!G11*(1-'Assumptions'!G12)/'Assumptions'!G9,0) | H9: =IFERROR('Assumptions'!H11*(1-'Assumptions'!H12)/'Assumptions'!H9,0)
B10: COGS / unit | C10: =IFERROR('Assumptions'!C21/'Assumptions'!C9,0) | D10: =IFERROR('Assumptions'!D21/'Assumptions'!D9,0) | E10: =IFERROR('Assumptions'!E21/'Assumptions'!E9,0) | F10: =IFERROR('Assumptions'!F21/'Assumptions'!F9,0) | G10: =IFERROR('Assumptions'!G21/'Assumptions'!G9,0) | H10: =IFERROR('Assumptions'!H21/'Assumptions'!H9,0)
B11: Gross profit / unit | C11: =C9-C10 | D11: =D9-D10 | E11: =E9-E10 | F11: =F9-F10 | G11: =G9-G10 | H11: =H9-H10
B12: GP % | C12: =IFERROR(C11/C9,0) | D12: =IFERROR(D11/D9,0) | E12: =IFERROR(E11/E9,0) | F12: =IFERROR(F11/F9,0) | G12: =IFERROR(G11/G9,0) | H12: =IFERROR(H11/H9,0)
B13: Suggested shelf / unit | C13: =IFERROR(C8/(1-$C$4),0) | D13: =IFERROR(D8/(1-$C$4),0) | E13: =IFERROR(E8/(1-$C$4),0) | F13: =IFERROR(F8/(1-$C$4),0) | G13: =IFERROR(G8/(1-$C$4),0) | H13: =IFERROR(H8/(1-$C$4),0)

Sheet Targets
B1: Sparkling Daily - Targets / Goal-Seek (FY2026)
B2: Set a goal; the model solves the price or volume needed - exact closed form, no iteration.
B4: Model constants (from Assumptions)
B5: K1 Net @ base (Σ vol·cp·(1-d)) | C5: =SUMPRODUCT('Assumptions'!C28:H28,'Assumptions'!C11:H11,(1-'Assumptions'!C12:H12))
B6: Kcos Σ vol·Cost of Sales | C6: =SUMPRODUCT('Assumptions'!C28:H28,'Assumptions'!C21:H21)
B7: Kap Σ vol·A&P | C7: =SUMPRODUCT('Assumptions'!C28:H28,'Assumptions'!C26:H26)
B8: Fixed opex | C8: ='Assumptions'!C31+'Assumptions'!C32+'Assumptions'!C33+'Assumptions'!C34
B9: Logistics % of net | C9: ='Assumptions'!C35
B10: Base total cases | C10: =SUM('Assumptions'!C28:H28)
B13: Your targets (edit yellow)
B14: Target company GP % | C14: 0.45
B15: Target EBITDA ($) | C15: 150000
B17: Solved answers
B18: Price × to hit target GP % (base volume) | C18: =IFERROR($C$6/($C$5*(1-$C$14)),"n/a")
B19: → implied blended CP change | C19: =IFERROR($C$6/($C$5*(1-$C$14))-1,"n/a")
B20: Volume × to hit target EBITDA (base price) | C20: =IFERROR(($C$15+$C$8)/(($C$5-$C$6-$C$7)-$C$9*$C$5),"n/a")
B21: → implied total cases | C21: =IFERROR(($C$15+$C$8)/(($C$5-$C$6-$C$7)-$C$9*$C$5)*$C$10,"n/a")
B22: Price × to hit target EBITDA (base vol; ε=0 approx) | C22: =IFERROR(($C$15+$C$8+$C$6+$C$7)/($C$5*(1-$C$9)),"n/a")
B23: Break-even volume × (EBITDA = 0, base price) | C23: =IFERROR($C$8/(($C$5-$C$6-$C$7)-$C$9*$C$5),"n/a")
B24: → break-even cases | C24: =IFERROR($C$8/(($C$5-$C$6-$C$7)-$C$9*$C$5)*$C$10,"n/a")

Sheet Sensitivity
B1: Sparkling Daily - Sensitivity & Break-even (FY2026)
B2: EBITDA as price and volume flex around Base. Exact closed-form from Assumptions.
B4: K1 Base gross-less-disc (Σ vol·cp·(1-d)) | C4: =SUMPRODUCT('Assumptions'!C28:H28,'Assumptions'!C11:H11,(1-'Assumptions'!C12:H12))
B5: K2 Base variable cost (Σ vol·(COS+A&P)) | C5: =SUMPRODUCT('Assumptions'!C28:H28,('Assumptions'!C21:H21+'Assumptions'!C26:H26))
B6: Fixed opex (sal+G&A+mktg+slot) | C6: ='Assumptions'!C31+'Assumptions'!C32+'Assumptions'!C33+'Assumptions'!C34
B7: Logistics % of net | C7: ='Assumptions'!C35
B8: Base total cases | C8: =SUM('Assumptions'!C28:H28)
B9: Price elasticity (from Assumptions) | C9: ='Assumptions'!C39
B11: EBITDA ($)
B12: Price x \ Volume x | C12: 0.7 | D12: 0.9 | E12: 1 | F12: 1.1 | G12: 1.3 | H12: 1.5 | I12: 1.7
B13: 0.9 | C13: =C$12*($B13^$C$9)*($B13*$C$4-$C$5)-$C$6-$C$7*C$12*($B13^($C$9+1))*$C$4 | D13: =D$12*($B13^$C$9)*($B13*$C$4-$C$5)-$C$6-$C$7*D$12*($B13^($C$9+1))*$C$4 | E13: =E$12*($B13^$C$9)*($B13*$C$4-$C$5)-$C$6-$C$7*E$12*($B13^($C$9+1))*$C$4 | F13: =F$12*($B13^$C$9)*($B13*$C$4-$C$5)-$C$6-$C$7*F$12*($B13^($C$9+1))*$C$4 | G13: =G$12*($B13^$C$9)*($B13*$C$4-$C$5)-$C$6-$C$7*G$12*($B13^($C$9+1))*$C$4 | H13: =H$12*($B13^$C$9)*($B13*$C$4-$C$5)-$C$6-$C$7*H$12*($B13^($C$9+1))*$C$4 | I13: =I$12*($B13^$C$9)*($B13*$C$4-$C$5)-$C$6-$C$7*I$12*($B13^($C$9+1))*$C$4
B14: 0.95 | C14: =C$12*($B14^$C$9)*($B14*$C$4-$C$5)-$C$6-$C$7*C$12*($B14^($C$9+1))*$C$4 | D14: =D$12*($B14^$C$9)*($B14*$C$4-$C$5)-$C$6-$C$7*D$12*($B14^($C$9+1))*$C$4 | E14: =E$12*($B14^$C$9)*($B14*$C$4-$C$5)-$C$6-$C$7*E$12*($B14^($C$9+1))*$C$4 | F14: =F$12*($B14^$C$9)*($B14*$C$4-$C$5)-$C$6-$C$7*F$12*($B14^($C$9+1))*$C$4 | G14: =G$12*($B14^$C$9)*($B14*$C$4-$C$5)-$C$6-$C$7*G$12*($B14^($C$9+1))*$C$4 | H14: =H$12*($B14^$C$9)*($B14*$C$4-$C$5)-$C$6-$C$7*H$12*($B14^($C$9+1))*$C$4 | I14: =I$12*($B14^$C$9)*($B14*$C$4-$C$5)-$C$6-$C$7*I$12*($B14^($C$9+1))*$C$4
B15: 1 | C15: =C$12*($B15^$C$9)*($B15*$C$4-$C$5)-$C$6-$C$7*C$12*($B15^($C$9+1))*$C$4 | D15: =D$12*($B15^$C$9)*($B15*$C$4-$C$5)-$C$6-$C$7*D$12*($B15^($C$9+1))*$C$4 | E15: =E$12*($B15^$C$9)*($B15*$C$4-$C$5)-$C$6-$C$7*E$12*($B15^($C$9+1))*$C$4 | F15: =F$12*($B15^$C$9)*($B15*$C$4-$C$5)-$C$6-$C$7*F$12*($B15^($C$9+1))*$C$4 | G15: =G$12*($B15^$C$9)*($B15*$C$4-$C$5)-$C$6-$C$7*G$12*($B15^($C$9+1))*$C$4 | H15: =H$12*($B15^$C$9)*($B15*$C$4-$C$5)-$C$6-$C$7*H$12*($B15^($C$9+1))*$C$4 | I15: =I$12*($B15^$C$9)*($B15*$C$4-$C$5)-$C$6-$C$7*I$12*($B15^($C$9+1))*$C$4
B16: 1.05 | C16: =C$12*($B16^$C$9)*($B16*$C$4-$C$5)-$C$6-$C$7*C$12*($B16^($C$9+1))*$C$4 | D16: =D$12*($B16^$C$9)*($B16*$C$4-$C$5)-$C$6-$C$7*D$12*($B16^($C$9+1))*$C$4 | E16: =E$12*($B16^$C$9)*($B16*$C$4-$C$5)-$C$6-$C$7*E$12*($B16^($C$9+1))*$C$4 | F16: =F$12*($B16^$C$9)*($B16*$C$4-$C$5)-$C$6-$C$7*F$12*($B16^($C$9+1))*$C$4 | G16: =G$12*($B16^$C$9)*($B16*$C$4-$C$5)-$C$6-$C$7*G$12*($B16^($C$9+1))*$C$4 | H16: =H$12*($B16^$C$9)*($B16*$C$4-$C$5)-$C$6-$C$7*H$12*($B16^($C$9+1))*$C$4 | I16: =I$12*($B16^$C$9)*($B16*$C$4-$C$5)-$C$6-$C$7*I$12*($B16^($C$9+1))*$C$4
B17: 1.1 | C17: =C$12*($B17^$C$9)*($B17*$C$4-$C$5)-$C$6-$C$7*C$12*($B17^($C$9+1))*$C$4 | D17: =D$12*($B17^$C$9)*($B17*$C$4-$C$5)-$C$6-$C$7*D$12*($B17^($C$9+1))*$C$4 | E17: =E$12*($B17^$C$9)*($B17*$C$4-$C$5)-$C$6-$C$7*E$12*($B17^($C$9+1))*$C$4 | F17: =F$12*($B17^$C$9)*($B17*$C$4-$C$5)-$C$6-$C$7*F$12*($B17^($C$9+1))*$C$4 | G17: =G$12*($B17^$C$9)*($B17*$C$4-$C$5)-$C$6-$C$7*G$12*($B17^($C$9+1))*$C$4 | H17: =H$12*($B17^$C$9)*($B17*$C$4-$C$5)-$C$6-$C$7*H$12*($B17^($C$9+1))*$C$4 | I17: =I$12*($B17^$C$9)*($B17*$C$4-$C$5)-$C$6-$C$7*I$12*($B17^($C$9+1))*$C$4
B18: 1.15 | C18: =C$12*($B18^$C$9)*($B18*$C$4-$C$5)-$C$6-$C$7*C$12*($B18^($C$9+1))*$C$4 | D18: =D$12*($B18^$C$9)*($B18*$C$4-$C$5)-$C$6-$C$7*D$12*($B18^($C$9+1))*$C$4 | E18: =E$12*($B18^$C$9)*($B18*$C$4-$C$5)-$C$6-$C$7*E$12*($B18^($C$9+1))*$C$4 | F18: =F$12*($B18^$C$9)*($B18*$C$4-$C$5)-$C$6-$C$7*F$12*($B18^($C$9+1))*$C$4 | G18: =G$12*($B18^$C$9)*($B18*$C$4-$C$5)-$C$6-$C$7*G$12*($B18^($C$9+1))*$C$4 | H18: =H$12*($B18^$C$9)*($B18*$C$4-$C$5)-$C$6-$C$7*H$12*($B18^($C$9+1))*$C$4 | I18: =I$12*($B18^$C$9)*($B18*$C$4-$C$5)-$C$6-$C$7*I$12*($B18^($C$9+1))*$C$4
B21: BREAK-EVEN (at Base price)
B22: Volume x for EBITDA = 0 | C22: =IFERROR($C$6/(($C$4-$C$5)-$C$7*$C$4),0)
B23: Break-even cases | C23: =C22*$C$8
B24: Base case volume | C24: =$C$8

Sheet Checks
B1: Sparkling Daily - Model Checks
B2: Automated validation. Everything should read PASS.
B4: Check | C4: Result | D4: Status
B5: Seasonality sums to 100% | C5: =SUM('Assumptions'!C53:N53) | D5: =IF(ABS(SUM('Assumptions'!C53:N53)-1)<0.0001,"PASS","FAIL")
B6: All CP / case > 0 | C6: =MIN('Assumptions'!C11:H11) | D6: =IF(MIN('Assumptions'!C11:H11)>0,"PASS","FAIL")
B7: All volumes >= 0 | C7: =MIN('Assumptions'!C28:H28) | D7: =IF(MIN('Assumptions'!C28:H28)>=0,"PASS","FAIL")
B8: Trade discount within 0-50% | C8: =MAX('Assumptions'!C12:H12) | D8: =IF(AND(MIN('Assumptions'!C12:H12)>=0,MAX('Assumptions'!C12:H12)<=0.5),"PASS","FAIL")
B9: Base GP% between 0 and 100% | C9: ='Base'!I23 | D9: =IF(AND('Base'!I23>0,'Base'!I23<1),"PASS","FAIL")
B10: COGS Direct < CP (each SKU) | C10: =SUMPRODUCT(--('Assumptions'!C19:H19>='Assumptions'!C11:H11)) | D10: =IF(SUMPRODUCT(--('Assumptions'!C19:H19>='Assumptions'!C11:H11))=0,"PASS","FAIL")
B11: Tax rate within 0-50% | C11: ='Assumptions'!C38 | D11: =IF(AND('Assumptions'!C38>=0,'Assumptions'!C38<=0.5),"PASS","FAIL")
B12: All scenario volume levers > 0 | C12: =MIN('Assumptions'!C46:C49) | D12: =IF(MIN('Assumptions'!C46:C49)>0,"PASS","FAIL")
B13: Price elasticity <= 0 (demand sane) | C13: ='Assumptions'!C39 | D13: =IF('Assumptions'!C39<=0,"PASS","FAIL")
B14: Dashboard Net Sales ties to Base tab | C14: ='Dashboard'!D8-'Base'!I18 | D14: =IF(ABS('Dashboard'!D8-'Base'!I18)<1,"PASS","FAIL")
B16: OVERALL | D16: =IF(COUNTIF(D5:D14,"FAIL")=0,"ALL PASS","REVIEW")

Sheet Guide
B1: Sparkling Daily — Model Guide
B3: START HERE
B4: Open the Home tab. Pick a scenario from the dropdown and the KPI cards update instantly.
B5: To change the numbers, go to Assumptions and edit the yellow cells. That's the only place you type.
B6: Advanced (optional): set Price elasticity on Assumptions to a negative number (e.g. -1.3) to make
B7: volume respond to price; the Pricing Lab then highlights the wholesale price that earns the most.
B9: HOW IT FITS TOGETHER
B10: Assumptions is the only place you key numbers. Scenario tabs, Monthly, Dashboard, Sensitivity and Checks all read from it.
B11: Change a price, cost or volume once on Assumptions and the entire workbook updates.
B13: STEP BY STEP
B14: 1. On Assumptions, set each SKU's CP, trade discount, COGS build-up, A&P and base volume (yellow cells).
B15: 2. Set company operating assumptions (salaries, G&A, logistics %, D&A, interest, tax).
... B38: Single-currency (CDN $), one fiscal year. No balance sheet / cash flow — this is an operating P&L.

Sheet Review Log
B1: Sparkling Daily — Review Log (devil's advocate)
B2: Issues identified in the first-pass model and how each was resolved in this build.
B4: # | C4: Issue / risk | D4: Resolution | E4: Status
B5: 1 | C5: No single source of truth — costs hand-keyed in ~24 places across tabs. | D5: Added Assumptions tab; all scenarios/monthly/sensitivity read from it (DRY). | E5: Resolved
B6: 2 | C6: Trade discount modelled as flat $/case — unrealistic. | D6: Now % of gross revenue, per SKU, flexed by scenario. | E6: Resolved
B7: 3 | C7: COGS was a single lump — no cost visibility. | D7: Built up from ingredients, packaging, co-pack, inbound freight + warehousing. | E7: Resolved
B8: 4 | C8: P&L stopped at contribution — not a real P&L. | D8: Extended to Opex → EBITDA → EBIT → Pre-tax → Net Income. | E8: Resolved
B9: 5 | C9: No operating leverage — all costs implicitly variable. | D9: Split fixed (salaries/G&A/mktg/slotting) vs variable (logistics % of net). | E9: Resolved
B10: 6 | C10: Annual only — no phasing. | D10: Added Monthly tab driven by a seasonality curve. | E10: Resolved
B11: 7 | C11: No way to switch scenario in one view. | D11: Monthly has a dropdown selector (INDIRECT-driven). | E11: Resolved
B12: 8 | C12: No sensitivity or break-even. | D12: Two-way EBITDA table (price × volume) + break-even volume, closed-form. | E12: Resolved
B13: 9 | C13: No validation of inputs/outputs. | D13: Checks tab with PASS/FAIL incl. a tie-out of Dashboard to Base. | E13: Resolved
B14: 10 | C14: No governance / context. | D14: Cover (purpose, version, owner, legend), Guide + glossary, this Review Log. | E14: Resolved
B15: 11 | C15: Tax could show a fictitious credit on losses. | D15: Tax floored at 0 via MAX(0, EBT×rate). | E15: Resolved
B16: 12 | C16: Inputs vs calcs indistinguishable. | D16: Colour coding: yellow = input, blue tint = calculated total; freeze panes throughout. | E16: Resolved
... B19: 15 | C19: Workbook opened on a dense tab — not approachable. | D19: Added a clean Home screen (scenario picker + live KPI cards + guided navigation); simple-first tab order. | E19: Resolved

Sheet Cover
B2: ORGANIKA
B3: Sparkling Daily — One-Year Operating Model
B5: BASE-CASE SNAPSHOT (FY2026)
B6: Net Sales | C6: Gross Profit % | D6: EBITDA | E6: Net Income | F6: Total Cases | G6: Break-even Cases
B7: ='Base'!I18 | C7: ='Base'!I23 | D7: ='Base'!I34 | E7: ='Base'!I41 | F7: ='Base'!I8 | G7: ='Sensitivity'!$C$23
B9: Purpose | C9: Model FY net sales, margin and EBITDA for Sparkling Daily across pricing & volume scenarios.
B10: Scope | C10: 3 flavours (Pineapple, Passionfruit, Lime Lemon) × Singles (12-ct) + 4-Pack = 6 SKUs; one fiscal year.
B11: Fiscal year | C11: FY2026
B12: Version | C12: v2.0
B13: Built | C13: 2026-06-05
B14: Currency | C14: CDN $
B15: Owner | C15: Commercial Finance
B16: Status | C16: DRAFT — figures are placeholders pending real inputs
B18: TAB INDEX
B19: Guide | C19: How to use + glossary of terms
B20: Review Log | C20: Devil's-advocate critique and how each issue was resolved
B21: Assumptions | C21: SINGLE SOURCE OF TRUTH — edit yellow cells here
B22: Dashboard | C22: Scenario comparison (table)
B23: Low / Base / High / Stretch | C23: Full P&L per scenario (6 SKUs + total → Net Income)
B24: Monthly | C24: Seasonalised monthly P&L for a selected scenario
B25: Pricing Lab | C25: Best wholesale price (CP) per SKU
B26: Unit Economics | C26: Per-unit costs + suggested retail shelf price
B27: Targets | C27: Goal-seek: price/volume to hit a GP% or EBITDA
B28: Sensitivity | C28: Two-way EBITDA table + break-even volume
B29: Checks | C29: Automated validation (should read ALL PASS)
B31: LEGEND
B32: Yellow cell | C32: Input — safe to edit
B33: Blue tint | C33: Calculated total — do not overwrite
