Workbook

Sheet Model
A1: Revenue & Profit Forecast — Cases-Sold Model
A2: Yellow = inputs. Everything else is live formulas. Profit layers in discounts, COGS, cost-to-serve & fixed costs.
A4: ASSUMPTIONS
A5: Annual gross revenue target | B5: 2500000
A6: Units per case | B6: 12
A7: Selling days / year | B7: 260
A8: Annual fixed costs | B8: 600000
A9: YoY growth (projection) | B9: 0.15
A10: Projection years | B10: 3
A11: CHANNELS — pricing & unit economics
A12: Channel | B12: Gross/case | C12: Mix | D12: COGS/case | E12: Disc % | F12: Sell % | G12: Net/case | H12: Contrib/case | I12: Margin | J12: Cases | K12: Gross $ | L12: Net $ | M12: COGS $ | N12: Sell $ | O12: Contrib $
A13: Direct-to-Consumer (DTC) | B13: 300 | C13: 20 | D13: 90 | E13: 0.05 | F13: 0.18 | G13: =B13*(1-E13) | H13: =G13*(1-F13)-D13 | I13: =IF(G13=0,0,H13/G13) | J13: =$B$37*(C13/SUM($C$13:$C$17)) | K13: =J13*B13 | L13: =J13*G13 | M13: =J13*D13 | N13: =J13*G13*F13 | O13: =J13*H13
A14: On-Premise / Food Service | B14: 216 | C14: 15 | D14: 90 | E14: 0.1 | F14: 0.05 | G14: =B14*(1-E14) | H14: =G14*(1-F14)-D14 | I14: =IF(G14=0,0,H14/G14) | J14: =$B$37*(C14/SUM($C$13:$C$17)) | K14: =J14*B14 | L14: =J14*G14 | M14: =J14*D14 | N14: =J14*G14*F14 | O14: =J14*H14
A15: Off-Premise Retail | B15: 180 | C15: 30 | D15: 90 | E15: 0.12 | F15: 0.04 | G15: =B15*(1-E15) | H15: =G15*(1-F15)-D15 | I15: =IF(G15=0,0,H15/G15) | J15: =$B$37*(C15/SUM($C$13:$C$17)) | K15: =J15*B15 | L15: =J15*G15 | M15: =J15*D15 | N15: =J15*G15*F15 | O15: =J15*H15
A16: Wholesale / Distributor | B16: 120 | C16: 30 | D16: 90 | E16: 0 | F16: 0.03 | G16: =B16*(1-E16) | H16: =G16*(1-F16)-D16 | I16: =IF(G16=0,0,H16/G16) | J16: =$B$37*(C16/SUM($C$13:$C$17)) | K16: =J16*B16 | L16: =J16*G16 | M16: =J16*D16 | N16: =J16*G16*F16 | O16: =J16*H16
A17: Online Marketplace | B17: 150 | C17: 5 | D17: 90 | E17: 0.08 | F17: 0.15 | G17: =B17*(1-E17) | H17: =G17*(1-F17)-D17 | I17: =IF(G17=0,0,H17/G17) | J17: =$B$37*(C17/SUM($C$13:$C$17)) | K17: =J17*B17 | L17: =J17*G17 | M17: =J17*D17 | N17: =J17*G17*F17 | O17: =J17*H17
A18: Blended / Total | B18: =SUMPRODUCT(B13:B17,C13:C17)/SUM(C13:C17) | C18: =SUM(C13:C17) | D18: =SUMPRODUCT(D13:D17,C13:C17)/SUM(C13:C17) | E18: =SUMPRODUCT(E13:E17,C13:C17)/SUM(C13:C17) | F18: =SUMPRODUCT(F13:F17,C13:C17)/SUM(C13:C17) | G18: =SUMPRODUCT(G13:G17,C13:C17)/SUM(C13:C17) | H18: =SUMPRODUCT(H13:H17,C13:C17)/SUM(C13:C17) | I18: =IF(B18=0,0,H18/G18) | J18: =SUM(J13:J17) | K18: =SUM(K13:K17) | L18: =SUM(L13:L17) | M18: =SUM(M13:M17) | N18: =SUM(N13:N17) | O18: =SUM(O13:O17)
A21: PROFIT CASCADE (at target)
A22: Gross revenue | B22: =SUM(K13:K17)
A23: Trade discounts | B23: =B24-B22
A24: Net revenue | B24: =SUM(L13:L17)
A25: COGS | B25: =-SUM(M13:M17)
A26: Selling / cost-to-serve | B26: =-SUM(N13:N17)
A27: Contribution | B27: =SUM(O13:O17)
A28: Fixed costs | B28: =-B8
A29: Operating profit | B29: =B27+B28
A30: Contribution margin | B30: =B27/B24
A31: Operating margin | B31: =B29/B24
A33: KEY METRICS
A34: Blended gross / case | B34: =SUMPRODUCT(B13:B17,C13:C17)/SUM(C13:C17)
A35: Blended net / case | B35: =SUMPRODUCT(G13:G17,C13:C17)/SUM(C13:C17)
A36: Blended contribution / case | B36: =SUMPRODUCT(H13:H17,C13:C17)/SUM(C13:C17)
A37: TOTAL cases to hit target | B37: =B5/B34
A38: Cases / month | B38: =B37/12
A39: Cases / week | B39: =B37/52
A40: Cases / selling-day | B40: =B37/B7
A41: Price / unit | B41: =B34/B6
A42: Break-even cases | B42: =B8/B36
A43: Break-even revenue | B43: =B42*B34
A44: Blended discount % | B44: =SUMPRODUCT(E13:E17,C13:C17)/SUM(C13:C17)
...

Sheet Scenarios
A1: Scenarios — same economics, three goals
A3: Scenario | B3: Revenue target | C3: Cases | D3: Net revenue | E3: Contribution | F3: Operating profit | G3: Op margin
A4: Conservative | B4: 2000000 | C4: =B4/Model!$B$34 | D4: =C4*Model!$B$35 | E4: =C4*Model!$B$36 | F4: =E4-Model!$B$8 | G4: =IF(D4=0,0,F4/D4)
A5: Base | B5: 2500000 | C5: =B5/Model!$B$34 | D5: =C5*Model!$B$35 | E5: =C5*Model!$B$36 | F5: =E5-Model!$B$8 | G5: =IF(D5=0,0,F5/D5)
A6: Aggressive | B6: 3200000 | C6: =B6/Model!$B$34 | D6: =C6*Model!$B$35 | E6: =C6*Model!$B$36 | F6: =E6-Model!$B$8 | G6: =IF(D6=0,0,F6/D6)

Sheet Projection
A1: Multi-year projection (constant price & cost structure)
A3: Year | B3: Revenue | C3: Cases | D3: Contribution | E3: Operating profit
A4: Y1 | B4: =Model!$B$5*(1+Model!$B$9)^0 | C4: =B4/Model!$B$34 | D4: =C4*Model!$B$36 | E4: =D4-Model!$B$8
A5: Y2 | B5: =Model!$B$5*(1+Model!$B$9)^1 | C5: =B5/Model!$B$34 | D5: =C5*Model!$B$36 | E5: =D5-Model!$B$8
A6: Y3 | B6: =Model!$B$5*(1+Model!$B$9)^2 | C6: =B6/Model!$B$34 | D6: =C6*Model!$B$36 | E6: =D6-Model!$B$8

Sheet Profit Grid
A1: Profit grid — price/case × cases → operating profit
A2: Green = profit, red = loss. Uses blended discount/selling/COGS.
A4: Price ╲ Cases | B4: =ROUND(Model!$B$37*0.5/100,0)*100 | C4: =ROUND(Model!$B$37*0.75/100,0)*100 | D4: =ROUND(Model!$B$37*1.0/100,0)*100 | E4: =ROUND(Model!$B$37*1.25/100,0)*100 | F4: =ROUND(Model!$B$37*1.5/100,0)*100 | G4: =ROUND(Model!$B$37*1.75/100,0)*100
A5: =ROUND(Model!$B$34*0.6/5,0)*5 | B5: =B$4*($A5*(1-Model!$B$44)*(1-Model!$B$45)-Model!$B$46)-Model!$B$8 | C5: =C$4*($A5*(1-Model!$B$44)*(1-Model!$B$45)-Model!$B$46)-Model!$B$8 | D5: =D$4*($A5*(1-Model!$B$44)*(1-Model!$B$45)-Model!$B$46)-Model!$B$8 | E5: =E$4*($A5*(1-Model!$B$44)*(1-Model!$B$45)-Model!$B$46)-Model!$B$8 | F5: =F$4*($A5*(1-Model!$B$44)*(1-Model!$B$45)-Model!$B$46)-Model!$B$8 | G5: =G$4*($A5*(1-Model!$B$44)*(1-Model!$B$45)-Model!$B$46)-Model!$B$8
A6: =ROUND(Model!$B$34*0.8/5,0)*5 | B6: =B$4*($A6*(1-Model!$B$44)*(1-Model!$B$45)-Model!$B$46)-Model!$B$8 | C6: =C$4*($A6*(1-Model!$B$44)*(1-Model!$B$45)-Model!$B$46)-Model!$B$8 | D6: =D$4*($A6*(1-Model!$B$44)*(1-Model!$B$45)-Model!$B$46)-Model!$B$8 | E6: =E$4*($A6*(1-Model!$B$44)*(1-Model!$B$45)-Model!$B$46)-Model!$B$8 | F6: =F$4*($A6*(1-Model!$B$44)*(1-Model!$B$45)-Model!$B$46)-Model!$B$8 | G6: =G$4*($A6*(1-Model!$B$44)*(1-Model!$B$45)-Model!$B$46)-Model!$B$8
A7: =ROUND(Model!$B$34*1.0/5,0)*5 | B7: =B$4*($A7*(1-Model!$B$44)*(1-Model!$B$45)-Model!$B$46)-Model!$B$8 | C7: =C$4*($A7*(1-Model!$B$44)*(1-Model!$B$45)-Model!$B$46)-Model!$B$8 | D7: =D$4*($A7*(1-Model!$B$44)*(1-Model!$B$45)-Model!$B$46)-Model!$B$8 | E7: =E$4*($A7*(1-Model!$B$44)*(1-Model!$B$45)-Model!$B$46)-Model!$B$8 | F7: =F$4*($A7*(1-Model!$B$44)*(1-Model!$B$45)-Model!$B$46)-Model!$B$8 | G7: =G$4*($A7*(1-Model!$B$44)*(1-Model!$B$45)-Model!$B$46)-Model!$B$8
A8: =ROUND(Model!$B$34*1.2/5,0)*5 | B8: =B$4*($A8*(1-Model!$B$44)*(1-Model!$B$45)-Model!$B$46)-Model!$B$8 | C8: =C$4*($A8*(1-Model!$B$44)*(1-Model!$B$45)-Model!$B$46)-Model!$B$8 | D8: =D$4*($A8*(1-Model!$B$44)*(1-Model!$B$45)-Model!$B$46)-Model!$B$8 | E8: =E$4*($A8*(1-Model!$B$44)*(1-Model!$B$45)-Model!$B$46)-Model!$B$8 | F8: =F$4*($A8*(1-Model!$B$44)*(1-Model!$B$45)-Model!$B$46)-Model!$B$8 | G8: =G$4*($A8*(1-Model!$B$44)*(1-Model!$B$45)-Model!$B$46)-Model!$B$8
A9: =ROUND(Model!$B$34*1.4/5,0)*5 | B9: =B$4*($A9*(1-Model!$B$44)*(1-Model!$B$45)-Model!$B$46)-Model!$B$8 | C9: =C$4*($A9*(1-Model!$B$44)*(1-Model!$B$45)-Model!$B$46)-Model!$B$8 | D9: =D$4*($A9*(1-Model!$B$44)*(1-Model!$B$45)-Model!$B$46)-Model!$B$8 | E9: =E$4*($A9*(1-Model!$B$44)*(1-Model!$B$45)-Model!$B$46)-Model!$B$8 | F9: =F$4*($A9*(1-Model!$B$44)*(1-Model!$B$45)-Model!$B$46)-Model!$B$8 | G9: =G$4*($A9*(1-Model!$B$44)*(1-Model!$B$45)-Model!$B$46)-Model!$B$8

Sheet Monthly Plan
A1: Monthly plan — seasonality spread
A2: Weights are inputs (relative). Edit to model peaks & ramp-ups.
A4: Month | B4: Weight | C4: Mix % | D4: Cases | E4: Gross rev | F4: Contribution | G4: Cum. cases | H4: Cum. rev
A5: Jan | B5: 0.7 | C5: =B5/SUM($B$5:$B$16) | D5: =Model!$B$37*C5 | E5: =Model!$B$22*C5 | F5: =Model!$B$27*C5 | G5: =SUM($D$5:D5) | H5: =SUM($E$5:E5)
A6: Feb | B6: 0.7 | C6: =B6/SUM($B$5:$B$16) | D6: =Model!$B$37*C6 | E6: =Model!$B$22*C6 | F6: =Model!$B$27*C6 | G6: =SUM($D$5:D6) | H6: =SUM($E$5:E6)
A7: Mar | B7: 0.9 | C7: =B7/SUM($B$5:$B$16) | D7: =Model!$B$37*C7 | E7: =Model!$B$22*C7 | F7: =Model!$B$27*C7 | G7: =SUM($D$5:D7) | H7: =SUM($E$5:E7)
A8: Apr | B8: 1 | C8: =B8/SUM($B$5:$B$16) | D8: =Model!$B$37*C8 | E8: =Model!$B$22*C8 | F8: =Model!$B$27*C8 | G8: =SUM($D$5:D8) | H8: =SUM($E$5:E8)
A9: May | B9: 1.1 | C9: =B9/SUM($B$5:$B$16) | D9: =Model!$B$37*C9 | E9: =Model!$B$22*C9 | F9: =Model!$B$27*C9 | G9: =SUM($D$5:D9) | H9: =SUM($E$5:E9)
A10: Jun | B10: 1.2 | C10: =B10/SUM($B$5:$B$16) | D10: =Model!$B$37*C10 | E10: =Model!$B$22*C10 | F10: =Model!$B$27*C10 | G10: =SUM($D$5:D10) | H10: =SUM($E$5:E10)
A11: Jul | B11: 1.2 | C11: =B11/SUM($B$5:$B$16) | D11: =Model!$B$37*C11 | E11: =Model!$B$22*C11 | F11: =Model!$B$27*C11 | G11: =SUM($D$5:D11) | H11: =SUM($E$5:E11)
A12: Aug | B12: 1.1 | C12: =B12/SUM($B$5:$B$16) | D12: =Model!$B$37*C12 | E12: =Model!$B$22*C12 | F12: =Model!$B$27*C12 | G12: =SUM($D$5:D12) | H12: =SUM($E$5:E12)
A13: Sep | B13: 1 | C13: =B13/SUM($B$5:$B$16) | D13: =Model!$B$37*C13 | E13: =Model!$B$22*C13 | F13: =Model!$B$27*C13 | G13: =SUM($D$5:D13) | H13: =SUM($E$5:E13)
A14: Oct | B14: 1 | C14: =B14/SUM($B$5:$B$16) | D14: =Model!$B$37*C14 | E14: =Model!$B$22*C14 | F14: =Model!$B$27*C14 | G14: =SUM($D$5:D14) | H14: =SUM($E$5:E14)
A15: Nov | B15: 1.3 | C15: =B15/SUM($B$5:$B$16) | D15: =Model!$B$37*C15 | E15: =Model!$B$22*C15 | F15: =Model!$B$27*C15 | G15: =SUM($D$5:D15) | H15: =SUM($E$5:E15)
A16: Dec | B16: 1.8 | C16: =B16/SUM($B$5:$B$16) | D16: =Model!$B$37*C16 | E16: =Model!$B$22*C16 | F16: =Model!$B$27*C16 | G16: =SUM($D$5:D16) | H16: =SUM($E$5:E16)
A17: TOTAL | B17: =SUM(B5:B16) | C17: =SUM(C5:C16) | D17: =SUM(D5:D16) | E17: =SUM(E5:E16) | F17: =SUM(F5:F16)

Sheet Channel View
A1: Channel view — one channel at a time
A3: A) Cases to hit target if 100% sold through one channel
A4: Channel | B4: Gross/case | C4: Cases to target | D4: Units | E4: Contribution
A5: =Model!A13 | B5: =Model!B13 | C5: =Model!$B$5/B5 | D5: =C5*Model!$B$6 | E5: =C5*Model!H13
A6: =Model!A14 | B6: =Model!B14 | C6: =Model!$B$5/B6 | D6: =C6*Model!$B$6 | E6: =C6*Model!H14
A7: =Model!A15 | B7: =Model!B15 | C7: =Model!$B$5/B7 | D7: =C7*Model!$B$6 | E7: =C7*Model!H15
A8: =Model!A16 | B8: =Model!B16 | C8: =Model!$B$5/B8 | D8: =C8*Model!$B$6 | E8: =C8*Model!H16
A9: =Model!A17 | B9: =Model!B17 | C9: =Model!$B$5/B9 | D9: =C9*Model!$B$6 | E9: =C9*Model!H17
A11: B) Gross revenue at a given number of cases
A12: Channel | B12: Gross/case | C12: 5000 | D12: 10000 | E12: 15000 | F12: 20000 | G12: 25000 | H12: 30000
A13: =Model!A13 | B13: =Model!B13 | C13: =C$12*$B13 | D13: =D$12*$B13 | E13: =E$12*$B13 | F13: =F$12*$B13 | G13: =G$12*$B13 | H13: =H$12*$B13
A14: =Model!A14 | B14: =Model!B14 | C14: =C$12*$B14 | D14: =D$12*$B14 | E14: =E$12*$B14 | F14: =F$12*$B14 | G14: =G$12*$B14 | H14: =H$12*$B14
A15: =Model!A15 | B15: =Model!B15 | C15: =C$12*$B15 | D15: =D$12*$B15 | E15: =E$12*$B15 | F15: =F$12*$B15 | G15: =G$12*$B15 | H15: =H$12*$B15
A16: =Model!A16 | B16: =Model!B16 | C16: =C$12*$B16 | D16: =D$12*$B16 | E16: =E$12*$B16 | F16: =F$12*$B16 | G16: =G$12*$B16 | H16: =H$12*$B16
A17: =Model!A17 | B17: =Model!B17 | C17: =C$12*$B17 | D17: =D$12*$B17 | E17: =E$12*$B17 | F17: =F$12*$B17 | G17: =G$12*$B17 | H17: =H$12*$B17

Sheet Goal-Seek & Sensitivity
A1: Goal-seek & sensitivity
A3: GOAL-SEEK — plan to a profit
A4: Target operating profit | B4: 500000
A5: Cases needed | B5: =(B4+Model!$B$8)/Model!$B$36
A6: Gross revenue | B6: =B5*Model!$B$34
A7: Net revenue | B7: =B5*Model!$B$35
A9: CAPACITY — what a ceiling delivers
A10: Max cases you can sell | B10: 12000
A11: Gross revenue | B11: =B10*Model!$B$34
A12: Contribution | B12: =B10*Model!$B$36
A13: Operating profit | B13: =B12-Model!$B$8
A15: SENSITIVITY — operating profit at ±10% (volumes held)
A16: Driver | B16: −10% | C16: +10% | D16: Swing
A17: Price / case | B17: =SUMPRODUCT(Model!$J$13:$J$17,(Model!$B$13:$B$17*0.9)*(1-Model!$E$13:$E$17)*(1-Model!$F$13:$F$17)-Model!$D$13:$D$17)-Model!$B$8 | C17: =SUMPRODUCT(Model!$J$13:$J$17,(Model!$B$13:$B$17*1.1)*(1-Model!$E$13:$E$17)*(1-Model!$F$13:$F$17)-Model!$D$13:$D$17)-Model!$B$8 | D17: =ABS(C17-B17)
A18: Sales volume | B18: =Model!$B$27*0.9-Model!$B$8 | C18: =Model!$B$27*1.1-Model!$B$8 | D18: =ABS(C18-B18)
A19: COGS / case | B19: =SUMPRODUCT(Model!$J$13:$J$17,Model!$B$13:$B$17*(1-Model!$E$13:$E$17)*(1-Model!$F$13:$F$17)-Model!$D$13:$D$17*0.9)-Model!$B$8 | C19: =SUMPRODUCT(Model!$J$13:$J$17,Model!$B$13:$B$17*(1-Model!$E$13:$E$17)*(1-Model!$F$13:$F$17)-Model!$D$13:$D$17*1.1)-Model!$B$8 | D19: =ABS(C19-B19)
A20: Fixed costs | B20: =Model!$B$27-Model!$B$8*0.9 | C20: =Model!$B$27-Model!$B$8*1.1 | D20: =ABS(C20-B20)
A21: Trade discounts | B21: =SUMPRODUCT(Model!$J$13:$J$17,Model!$B$13:$B$17*(1-Model!$E$13:$E$17*0.9)*(1-Model!$F$13:$F$17)-Model!$D$13:$D$17)-Model!$B$8 | C21: =SUMPRODUCT(Model!$J$13:$J$17,Model!$B$13:$B$17*(1-Model!$E$13:$E$17*1.1)*(1-Model!$F$13:$F$17)-Model!$D$13:$D$17)-Model!$B$8 | D21: =ABS(C21-B21)
A23: Longest swing = the lever that moves profit most. Price typically dominates.
