Workbook

Sheet Cover
A1: RTD Co Man P&L
A4: Display unit | B4: Per case (24)
A5: Conversion (computed)
D6: =IF($B$4="Per can",IFERROR(1/Inputs!D16,0),IF($B$4="Per 4pk",IFERROR(4/Inputs!D16,0),IF($B$4="Per 6pk",IFERROR(6/Inputs!D16,0),IF($B$4="Per 8pk",IFERROR(8/Inputs!D16,0),IF($B$4="Per 12pk",IFERROR(12/Inputs!D16,0),IF($B$4="Per 15pk",IFERROR(15/Inputs!D16,0),IF($B$4="Per 18pk",IFERROR(18/Inputs!D16,0),IF($B$4="Per case (24)",IFERROR(24/Inputs!D16,0),IF($B$4="Per pallet",Inputs!D18,1))))))))) | E6: =IF($B$4="Per can",IFERROR(1/Inputs!E16,0),IF($B$4="Per 4pk",IFERROR(4/Inputs!E16,0),IF($B$4="Per 6pk",IFERROR(6/Inputs!E16,0),IF($B$4="Per 8pk",IFERROR(8/Inputs!E16,0),IF($B$4="Per 12pk",IFERROR(12/Inputs!E16,0),IF($B$4="Per 15pk",IFERROR(15/Inputs!E16,0),IF($B$4="Per 18pk",IFERROR(18/Inputs!E16,0),IF($B$4="Per case (24)",IFERROR(24/Inputs!E16,0),IF($B$4="Per pallet",Inputs!E18,1))))))))) | F6: =IF($B$4="Per can",IFERROR(1/Inputs!F16,0),IF($B$4="Per 4pk",IFERROR(4/Inputs!F16,0),IF($B$4="Per 6pk",IFERROR(6/Inputs!F16,0),IF($B$4="Per 8pk",IFERROR(8/Inputs!F16,0),IF($B$4="Per 12pk",IFERROR(12/Inputs!F16,0),IF($B$4="Per 15pk",IFERROR(15/Inputs!F16,0),IF($B$4="Per 18pk",IFERROR(18/Inputs!F16,0),IF($B$4="Per case (24)",IFERROR(24/Inputs!F16,0),IF($B$4="Per pallet",Inputs!F18,1))))))))) | G6: =IF($B$4="Per can",IFERROR(1/Inputs!G16,0),IF($B$4="Per 4pk",IFERROR(4/Inputs!G16,0),IF($B$4="Per 6pk",IFERROR(6/Inputs!G16,0),IF($B$4="Per 8pk",IFERROR(8/Inputs!G16,0),IF($B$4="Per 12pk",IFERROR(12/Inputs!G16,0),IF($B$4="Per 15pk",IFERROR(15/Inputs!G16,0),IF($B$4="Per 18pk",IFERROR(18/Inputs!G16,0),IF($B$4="Per case (24)",IFERROR(24/Inputs!G16,0),IF($B$4="Per pallet",Inputs!G18,1))))))))) | H6: =IF($B$4="Per can",IFERROR(1/Inputs!H16,0),IF($B$4="Per 4pk",IFERROR(4/Inputs!H16,0),IF($B$4="Per 6pk",IFERROR(6/Inputs!H16,0),IF($B$4="Per 8pk",IFERROR(8/Inputs!H16,0),IF($B$4="Per 12pk",IFERROR(12/Inputs!H16,0),IF($B$4="Per 15pk",IFERROR(15/Inputs!H16,0),IF($B$4="Per 18pk",IFERROR(18/Inputs!H16,0),IF($B$4="Per case (24)",IFERROR(24/Inputs!H16,0),IF($B$4="Per pallet",Inputs!H18,1))))))))) | I6: =IF($B$4="Per can",IFERROR(1/Inputs!I16,0),IF($B$4="Per 4pk",IFERROR(4/Inputs!I16,0),IF($B$4="Per 6pk",IFERROR(6/Inputs!I16,0),IF($B$4="Per 8pk",IFERROR(8/Inputs!I16,0),IF($B$4="Per 12pk",IFERROR(12/Inputs!I16,0),IF($B$4="Per 15pk",IFERROR(15/Inputs!I16,0),IF($B$4="Per 18pk",IFERROR(18/Inputs!I16,0),IF($B$4="Per case (24)",IFERROR(24/Inputs!I16,0),IF($B$4="Per pallet",Inputs!I18,1)))))))))
A10: Metric | D10: =Inputs!D4 | E10: =Inputs!E4 | F10: =Inputs!F4 | G10: =Inputs!G4 | H10: =Inputs!H4 | I10: =Inputs!I4
A11: Co manufacturer name | D11: =Inputs!D5 | E11: =Inputs!E5 | F11: =Inputs!F5 | G11: =Inputs!G5 | H11: =Inputs!H5 | I11: =Inputs!I5
A12: Province | D12: =Inputs!D6 | E12: =Inputs!E6 | F12: =Inputs!F6 | G12: =Inputs!G6 | H12: =Inputs!H6 | I12: =Inputs!I6
A13: Type | D13: =Inputs!D7 | E13: =Inputs!E7 | F13: =Inputs!F7 | G13: =Inputs!G7 | H13: =Inputs!H7 | I13: =Inputs!I7
A14: =CONCATENATE("Physical units (",B4,")") | D14: ='P&L by Scenario'!D6 | E14: ='P&L by Scenario'!E6 | F14: ='P&L by Scenario'!F6 | G14: ='P&L by Scenario'!G6 | H14: ='P&L by Scenario'!H6 | I14: ='P&L by Scenario'!I6
A15: Gross Revenue (CP) | D15: ='P&L by Scenario'!D7 | E15: ='P&L by Scenario'!E7 | F15: ='P&L by Scenario'!F7 | G15: ='P&L by Scenario'!G7 | H15: ='P&L by Scenario'!H7 | I15: ='P&L by Scenario'!I7
A16: Net Sales | D16: ='P&L by Scenario'!D9 | E16: ='P&L by Scenario'!E9 | F16: ='P&L by Scenario'!F9 | G16: ='P&L by Scenario'!G9 | H16: ='P&L by Scenario'!H9 | I16: ='P&L by Scenario'!I9
A17: Direct COGS | D17: ='P&L by Scenario'!D12 | E17: ='P&L by Scenario'!E12 | F17: ='P&L by Scenario'!F12 | G17: ='P&L by Scenario'!G12 | H17: ='P&L by Scenario'!H12 | I17: ='P&L by Scenario'!I12
A18: Indirect COGS | D18: ='P&L by Scenario'!D13 | E18: ='P&L by Scenario'!E13 | F18: ='P&L by Scenario'!F13 | G18: ='P&L by Scenario'!G13 | H18: ='P&L by Scenario'!H13 | I18: ='P&L by Scenario'!I13
A19: Cost of Sales | D19: ='P&L by Scenario'!D14 | E19: ='P&L by Scenario'!E14 | F19: ='P&L by Scenario'!F14 | G19: ='P&L by Scenario'!G14 | H19: ='P&L by Scenario'!H14 | I19: ='P&L by Scenario'!I14
A20: Gross Profit | D20: ='P&L by Scenario'!D15 | E20: ='P&L by Scenario'!E15 | F20: ='P&L by Scenario'!F15 | G20: ='P&L by Scenario'!G15 | H20: ='P&L by Scenario'!H15 | I20: ='P&L by Scenario'!I15
A21: GP % | D21: ='P&L by Scenario'!D16 | E21: ='P&L by Scenario'!E16 | F21: ='P&L by Scenario'!F16 | G21: ='P&L by Scenario'!G16 | H21: ='P&L by Scenario'!H16 | I21: ='P&L by Scenario'!I16
A22: A&P (total) | D22: ='P&L by Scenario'!D24 | E22: ='P&L by Scenario'!E24 | F22: ='P&L by Scenario'!F24 | G22: ='P&L by Scenario'!G24 | H22: ='P&L by Scenario'!H24 | I22: ='P&L by Scenario'!I24
A23: Contrib After A&P | D23: ='P&L by Scenario'!D26 | E23: ='P&L by Scenario'!E26 | F23: ='P&L by Scenario'!F26 | G23: ='P&L by Scenario'!G26 | H23: ='P&L by Scenario'!H26 | I23: ='P&L by Scenario'!I26
A24: CAAP % | D24: ='P&L by Scenario'!D27 | E24: ='P&L by Scenario'!E27 | F24: ='P&L by Scenario'!F27 | G24: ='P&L by Scenario'!G27 | H24: ='P&L by Scenario'!H27 | I24: ='P&L by Scenario'!I27
A25: Tax | D25: ='P&L by Scenario'!D30 | E25: ='P&L by Scenario'!E30 | F25: ='P&L by Scenario'!F30 | G25: ='P&L by Scenario'!G30 | H25: ='P&L by Scenario'!H30 | I25: ='P&L by Scenario'!I30
A26: Profit After Tax | D26: ='P&L by Scenario'!D31 | E26: ='P&L by Scenario'!E31 | F26: ='P&L by Scenario'!F31 | G26: ='P&L by Scenario'!G31 | H26: ='P&L by Scenario'!H31 | I26: ='P&L by Scenario'!I31
A27: Net Margin % | D27: ='P&L by Scenario'!D32 | E27: ='P&L by Scenario'!E32 | F27: ='P&L by Scenario'!F32 | G27: ='P&L by Scenario'!G32 | H27: ='P&L by Scenario'!H32 | I27: ='P&L by Scenario'!I32

Sheet Inputs
A1: Inputs
A4: Variable | B4: Unit | D4: =CONCATENATE(D6," ",D7) | E4: =CONCATENATE(E6," ",E7) | F4: =CONCATENATE(F6," ",F7) | G4: =CONCATENATE(G6," ",G7) | H4: =CONCATENATE(H6," ",H7) | I4: =CONCATENATE(I6," ",I7)
A5: Co manufacturer name (type here) | B5: name
A6: Province (dropdown) | B6: pick | D6: ON | E6: ON | F6: AB | G6: AB | H6: BC | I6: BC
A7: Mode (dropdown) | B7: pick | D7: Turnkey | E7: Tolling | F7: Turnkey | G7: Tolling | H7: Turnkey | I7: Tolling
A9: Global inputs. Edit column D. All scenarios use the same value.
A10: Physical Cases Year 1 | B10: cases | D10: 5000 | E10: =$D$10 | F10: =$D$10 | G10: =$D$10 | H10: =$D$10 | I10: =$D$10
A11: mL per can | B11: mL | D11: 355 | E11: =$D$11 | F11: =$D$11 | G11: =$D$11 | H11: =$D$11 | I11: =$D$11
A12: Pallets per truck | B12: pallets/truck | D12: 24 | E12: =$D$12 | F12: =$D$12 | G12: =$D$12 | H12: =$D$12 | I12: =$D$12
A14: Pack format per scenario. Unit = pack size (varies). Case = 24 can tray case (standard).
A15: Cans per unit | B15: cans | D15: 4 | E15: 6 | F15: 12 | G15: 18 | H15: 24 | I15: 4
A16: Cans per case | B16: cans | D16: 24 | E16: 24 | F16: 24 | G16: 24 | H16: 24 | I16: 24
A17: Cans per tray | B17: cans | D17: 24 | E17: 24 | F17: 24 | G17: 24 | H17: 24 | I17: 24
A18: Cases per pallet | B18: cases/pallet | D18: 100 | E18: 100 | F18: 100 | G18: 100 | H18: 100 | I18: 100
A20: Trade rates per channel (global)
A21: Costco trade rate | B21: % of Gross Rev | D21: 0.235 | E21: =$D$21 | F21: =$D$21 | G21: =$D$21 | H21: =$D$21 | I21: =$D$21
A22: Specialty trade rate | B22: % of Gross Rev | D22: 0.05 | E22: =$D$22 | F22: =$D$22 | G22: =$D$22 | H22: =$D$22 | I22: =$D$22
A23: FDM trade rate | B23: % of Gross Rev | D23: 0.13 | E23: =$D$23 | F23: =$D$23 | G23: =$D$23 | H23: =$D$23 | I23: =$D$23
A24: DTC / Other trade rate | B24: % of Gross Rev | D24: 0.1 | E24: =$D$24 | F24: =$D$24 | G24: =$D$24 | H24: =$D$24 | I24: =$D$24
A26: Tax
A27: Corporate tax rate (Canada combined federal + BC) | B27: % | D27: 0.27 | E27: =$D$27 | F27: =$D$27 | G27: =$D$27 | H27: =$D$27 | I27: =$D$27
A29: Scenario specific.
A30: MOQ per production run | B30: cases | D30: 5000 | E30: 5000 | F30: 5000 | G30: 5000 | H30: 5000 | I30: 5000
A31: Lead time | B31: days | D31: 60 | E31: 60 | F31: 60 | G31: 60 | H31: 60 | I31: 60
A32: Scrap rate | B32: % | D32: 0.02 | E32: 0.02 | F32: 0.02 | G32: 0.02 | H32: 0.02 | I32: 0.02
A34: Pricing per case
A35: Customer Price (CP) per case | B35: $/case | D35: 7.16 | E35: 10.76 | F35: 17.93 | G35: 26.89 | H35: 35.86 | I35: 7.16
A36: Suggested Retail Price (SRP) per case | B36: $/case | D36: 11.96 | E36: 17.94 | F36: 29.88 | G36: 44.82 | H36: 59.76 | I36: 11.96
A38: Channel mix per scenario. Must sum to 100 pct.
A39: Costco share of cases | B39: % | D39: 0 | E39: 0 | F39: 0 | G39: 0 | H39: 0 | I39: 0
A40: Specialty share of cases | B40: % | D40: 0.3 | E40: 0.3 | F40: 0.3 | G40: 0.3 | H40: 0.3 | I40: 0.3
A41: FDM share of cases | B41: % | D41: 0.6 | E41: 0.6 | F41: 0.6 | G41: 0.6 | H41: 0.6 | I41: 0.6
A42: DTC / Other share of cases | B42: % | D42: 0.1 | E42: 0.1 | F42: 0.1 | G42: 0.1 | H42: 0.1 | I42: 0.1
A43: Channel mix check (= 100 pct) | B43: % | D43: =D39+D40+D41+D42 | E43: =E39+E40+E41+E42 | F43: =F39+F40+F41+F42 | G43: =G39+G40+G41+G42 | H43: =H39+H40+H41+H42 | I43: =I39+I40+I41+I42
A44: Blended Discounts rate (derived) | B44: % | D44: =D39*D21+D40*D22+D41*D23+D42*D24 | E44: =E39*E21+E40*E22+E41*E23+E42*E24 | F44: =F39*F21+F40*F22+F41*F23+F42*F24 | G44: =G39*G21+G40*G22+G41*G23+G42*G24 | H44: =H39*H21+H40*H22+H41*H23+H42*H24 | I44: =I39*I21+I40*I22+I41*I23+I42*I24
A46: DIRECT MATERIAL COST.
A47: Ingredients
A48: Liquid concentrate | B48: $/can | D48: 0.1 | E48: 0.1 | F48: 0.1 | G48: 0.1 | H48: 0.1 | I48: 0.1
A49: Water | B49: $/can | D49: 0.02 | E49: 0.02 | F49: 0.02 | G49: 0.02 | H49: 0.02 | I49: 0.02
A50: Sweetener | B50: $/can | D50: 0.01 | E50: 0.01 | F50: 0.01 | G50: 0.01 | H50: 0.01 | I50: 0.01
...

Sheet Direct COGS
A1: Direct COGS
D3: Per can (CAD) | K3: Per case (CAD)
A4: Component | B4: Native | D4: =Inputs!D4 | E4: =Inputs!E4 | F4: =Inputs!F4 | G4: =Inputs!G4 | H4: =Inputs!H4 | I4: =Inputs!I4 | K4: =Inputs!D4 | L4: =Inputs!E4 | M4: =Inputs!F4 | N4: =Inputs!G4 | O4: =Inputs!H4 | P4: =Inputs!I4
A6: Direct Material — Ingredients
A7: Liquid concentrate | B7: $/can | D7: =Inputs!D48 | E7: =Inputs!E48 | F7: =Inputs!F48 | G7: =Inputs!G48 | H7: =Inputs!H48 | I7: =Inputs!I48 | K7: =Inputs!D48*Inputs!D16 | L7: =Inputs!E48*Inputs!E16 | M7: =Inputs!F48*Inputs!F16 | N7: =Inputs!G48*Inputs!G16 | O7: =Inputs!H48*Inputs!H16 | P7: =Inputs!I48*Inputs!I16
A8: Water | B8: $/can | D8: =Inputs!D49 | E8: =Inputs!E49 | F8: =Inputs!F49 | G8: =Inputs!G49 | H8: =Inputs!H49 | I8: =Inputs!I49 | K8: =Inputs!D49*Inputs!D16 | L8: =Inputs!E49*Inputs!E16 | M8: =Inputs!F49*Inputs!F16 | N8: =Inputs!G49*Inputs!G16 | O8: =Inputs!H49*Inputs!H16 | P8: =Inputs!I49*Inputs!I16
A9: Sweetener | B9: $/can | D9: =Inputs!D50 | E9: =Inputs!E50 | F9: =Inputs!F50 | G9: =Inputs!G50 | H9: =Inputs!H50 | I9: =Inputs!I50 | K9: =Inputs!D50*Inputs!D16 | L9: =Inputs!E50*Inputs!E16 | M9: =Inputs!F50*Inputs!F16 | N9: =Inputs!G50*Inputs!G16 | O9: =Inputs!H50*Inputs!H16 | P9: =Inputs!I50*Inputs!I16
A10: Acidulants | B10: $/can | D10: =Inputs!D51 | E10: =Inputs!E51 | F10: =Inputs!F51 | G10: =Inputs!G51 | H10: =Inputs!H51 | I10: =Inputs!I51 | K10: =Inputs!D51*Inputs!D16 | L10: =Inputs!E51*Inputs!E16 | M10: =Inputs!F51*Inputs!F16 | N10: =Inputs!G51*Inputs!G16 | O10: =Inputs!H51*Inputs!H16 | P10: =Inputs!I51*Inputs!I16
A11: Probiotics | B11: $/can | D11: =Inputs!D52 | E11: =Inputs!E52 | F11: =Inputs!F52 | G11: =Inputs!G52 | H11: =Inputs!H52 | I11: =Inputs!I52 | K11: =Inputs!D52*Inputs!D16 | L11: =Inputs!E52*Inputs!E16 | M11: =Inputs!F52*Inputs!F16 | N11: =Inputs!G52*Inputs!G16 | O11: =Inputs!H52*Inputs!H16 | P11: =Inputs!I52*Inputs!I16
A12: Other ingredients | B12: $/can | D12: =Inputs!D53 | E12: =Inputs!E53 | F12: =Inputs!F53 | G12: =Inputs!G53 | H12: =Inputs!H53 | I12: =Inputs!I53 | K12: =Inputs!D53*Inputs!D16 | L12: =Inputs!E53*Inputs!E16 | M12: =Inputs!F53*Inputs!F16 | N12: =Inputs!G53*Inputs!G16 | O12: =Inputs!H53*Inputs!H16 | P12: =Inputs!I53*Inputs!I16
A13: Direct Material — Primary packaging
A14: Can body | B14: $/can | D14: =Inputs!D55 | E14: =Inputs!E55 | F14: =Inputs!F55 | G14: =Inputs!G55 | H14: =Inputs!H55 | I14: =Inputs!I55 | K14: =Inputs!D55*Inputs!D16 | L14: =Inputs!E55*Inputs!E16 | M14: =Inputs!F55*Inputs!F16 | N14: =Inputs!G55*Inputs!G16 | O14: =Inputs!H55*Inputs!H16 | P14: =Inputs!I55*Inputs!I16
A15: Can lid / end | B15: $/can | D15: =Inputs!D56 | E15: =Inputs!E56 | F15: =Inputs!F56 | G15: =Inputs!G56 | H15: =Inputs!H56 | I15: =Inputs!I56 | K15: =Inputs!D56*Inputs!D16 | L15: =Inputs!E56*Inputs!E16 | M15: =Inputs!F56*Inputs!F16 | N15: =Inputs!G56*Inputs!G16 | O15: =Inputs!H56*Inputs!H16 | P15: =Inputs!I56*Inputs!I16
A16: Label | B16: $/can | D16: =Inputs!D57 | E16: =Inputs!E57 | F16: =Inputs!F57 | G16: =Inputs!G57 | H16: =Inputs!H57 | I16: =Inputs!I57 | K16: =Inputs!D57*Inputs!D16 | L16: =Inputs!E57*Inputs!E16 | M16: =Inputs!F57*Inputs!F16 | N16: =Inputs!G57*Inputs!G16 | O16: =Inputs!H57*Inputs!H16 | P16: =Inputs!I57*Inputs!I16
A17: Label application | B17: $/can | D17: =Inputs!D58 | E17: =Inputs!E58 | F17: =Inputs!F58 | G17: =Inputs!G58 | H17: =Inputs!H58 | I17: =Inputs!I58 | K17: =Inputs!D58*Inputs!D16 | L17: =Inputs!E58*Inputs!E16 | M17: =Inputs!F58*Inputs!F16 | N17: =Inputs!G58*Inputs!G16 | O17: =Inputs!H58*Inputs!H16 | P17: =Inputs!I58*Inputs!I16
A18: Direct Material — Secondary packaging
A19: Tray | B19: $/tray | D19: =IFERROR(Inputs!D60/Inputs!D17,0) | E19: =IFERROR(Inputs!E60/Inputs!E17,0) | F19: =IFERROR(Inputs!F60/Inputs!F17,0) | G19: =IFERROR(Inputs!G60/Inputs!G17,0) | H19: =IFERROR(Inputs!H60/Inputs!H17,0) | I19: =IFERROR(Inputs!I60/Inputs!I17,0) | K19: =IFERROR(Inputs!D60*Inputs!D16/Inputs!D17,0) | L19: =IFERROR(Inputs!E60*Inputs!E16/Inputs!E17,0) | M19: =IFERROR(Inputs!F60*Inputs!F16/Inputs!F17,0) | N19: =IFERROR(Inputs!G60*Inputs!G16/Inputs!G17,0) | O19: =IFERROR(Inputs!H60*Inputs!H16/Inputs!H17,0) | P19: =IFERROR(Inputs!I60*Inputs!I16/Inputs!I17,0)
A20: Tray shrink wrap | B20: $/tray | D20: =IFERROR(Inputs!D61/Inputs!D17,0) | E20: =IFERROR(Inputs!E61/Inputs!E17,0) | F20: =IFERROR(Inputs!F61/Inputs!F17,0) | G20: =IFERROR(Inputs!G61/Inputs!G17,0) | H20: =IFERROR(Inputs!H61/Inputs!H17,0) | I20: =IFERROR(Inputs!I61/Inputs!I17,0) | K20: =IFERROR(Inputs!D61*Inputs!D16/Inputs!D17,0) | L20: =IFERROR(Inputs!E61*Inputs!E16/Inputs!E17,0) | M20: =IFERROR(Inputs!F61*Inputs!F16/Inputs!F17,0) | N20: =IFERROR(Inputs!G61*Inputs!G16/Inputs!G17,0) | O20: =IFERROR(Inputs!H61*Inputs!H16/Inputs!H17,0) | P20: =IFERROR(Inputs!I61*Inputs!I16/Inputs!I17,0)
A21: Tray label | B21: $/tray | D21: =IFERROR(Inputs!D62/Inputs!D17,0) | E21: =IFERROR(Inputs!E62/Inputs!E17,0) | F21: =IFERROR(Inputs!F62/Inputs!F17,0) | G21: =IFERROR(Inputs!G62/Inputs!G17,0) | H21: =IFERROR(Inputs!H62/Inputs!H17,0) | I21: =IFERROR(Inputs!I62/Inputs!I17,0) | K21: =IFERROR(Inputs!D62*Inputs!D16/Inputs!D17,0) | L21: =IFERROR(Inputs!E62*Inputs!E16/Inputs!E17,0) | M21: =IFERROR(Inputs!F62*Inputs!F16/Inputs!F17,0) | N21: =IFERROR(Inputs!G62*Inputs!G16/Inputs!G17,0) | O21: =IFERROR(Inputs!H62*Inputs!H16/Inputs!H17,0) | P21: =IFERROR(Inputs!I62*Inputs!I16/Inputs!I17,0)
A22: Direct Material — Tertiary packaging
A23: CHEP pallet | B23: $/pallet | D23: =IFERROR(Inputs!D64/(Inputs!D18*Inputs!D16),0) | E23: =IFERROR(Inputs!E64/(Inputs!E18*Inputs!E16),0) | F23: =IFERROR(Inputs!F64/(Inputs!F18*Inputs!F16),0) | G23: =IFERROR(Inputs!G64/(Inputs!G18*Inputs!G16),0) | H23: =IFERROR(Inputs!H64/(Inputs!H18*Inputs!H16),0) | I23: =IFERROR(Inputs!I64/(Inputs!I18*Inputs!I16),0) | K23: =IFERROR(Inputs!D64/Inputs!D18,0) | L23: =IFERROR(Inputs!E64/Inputs!E18,0) | M23: =IFERROR(Inputs!F64/Inputs!F18,0) | N23: =IFERROR(Inputs!G64/Inputs!G18,0) | O23: =IFERROR(Inputs!H64/Inputs!H18,0) | P23: =IFERROR(Inputs!I64/Inputs!I18,0)
A24: Pallet wrap | B24: $/pallet | D24: =IFERROR(Inputs!D65/(Inputs!D18*Inputs!D16),0) | E24: =IFERROR(Inputs!E65/(Inputs!E18*Inputs!E16),0) | F24: =IFERROR(Inputs!F65/(Inputs!F18*Inputs!F16),0) | G24: =IFERROR(Inputs!G65/(Inputs!G18*Inputs!G16),0) | H24: =IFERROR(Inputs!H65/(Inputs!H18*Inputs!H16),0) | I24: =IFERROR(Inputs!I65/(Inputs!I18*Inputs!I16),0) | K24: =IFERROR(Inputs!D65/Inputs!D18,0) | L24: =IFERROR(Inputs!E65/Inputs!E18,0) | M24: =IFERROR(Inputs!F65/Inputs!F18,0) | N24: =IFERROR(Inputs!G65/Inputs!G18,0) | O24: =IFERROR(Inputs!H65/Inputs!H18,0) | P24: =IFERROR(Inputs!I65/Inputs!I18,0)
A25: Pallet corners | B25: $/pallet | D25: =IFERROR(Inputs!D66/(Inputs!D18*Inputs!D16),0) | E25: =IFERROR(Inputs!E66/(Inputs!E18*Inputs!E16),0) | F25: =IFERROR(Inputs!F66/(Inputs!F18*Inputs!F16),0) | G25: =IFERROR(Inputs!G66/(Inputs!G18*Inputs!G16),0) | H25: =IFERROR(Inputs!H66/(Inputs!H18*Inputs!H16),0) | I25: =IFERROR(Inputs!I66/(Inputs!I18*Inputs!I16),0) | K25: =IFERROR(Inputs!D66/Inputs!D18,0) | L25: =IFERROR(Inputs!E66/Inputs!E18,0) | M25: =IFERROR(Inputs!F66/Inputs!F18,0) | N25: =IFERROR(Inputs!G66/Inputs!G18,0) | O25: =IFERROR(Inputs!H66/Inputs!H18,0) | P25: =IFERROR(Inputs!I66/Inputs!I18,0)
A26: Pallet label | B26: $/pallet | D26: =IFERROR(Inputs!D67/(Inputs!D18*Inputs!D16),0) | E26: =IFERROR(Inputs!E67/(Inputs!E18*Inputs!E16),0) | F26: =IFERROR(Inputs!F67/(Inputs!F18*Inputs!F16),0) | G26: =IFERROR(Inputs!G67/(Inputs!G18*Inputs!G16),0) | H26: =IFERROR(Inputs!H67/(Inputs!H18*Inputs!H16),0) | I26: =IFERROR(Inputs!I67/(Inputs!I18*Inputs!I16),0) | K26: =IFERROR(Inputs!D67/Inputs!D18,0) | L26: =IFERROR(Inputs!E67/Inputs!E18,0) | M26: =IFERROR(Inputs!F67/Inputs!F18,0) | N26: =IFERROR(Inputs!G67/Inputs!G18,0) | O26: =IFERROR(Inputs!H67/Inputs!H18,0) | P26: =IFERROR(Inputs!I67/Inputs!I18,0)
A27: Direct Production Overhead — Tolling / canning
A28: Tolling / canning | B28: $/can | D28: =Inputs!D71 | E28: =Inputs!E71 | F28: =Inputs!F71 | G28: =Inputs!G71 | H28: =Inputs!H71 | I28: =Inputs!I71 | K28: =Inputs!D71*Inputs!D16 | L28: =Inputs!E71*Inputs!E16 | M28: =Inputs!F71*Inputs!F16 | N28: =Inputs!G71*Inputs!G16 | O28: =Inputs!H71*Inputs!H16 | P28: =Inputs!I71*Inputs!I16
A29: Pasteurization | B29: $/can | D29: =Inputs!D72 | E29: =Inputs!E72 | F29: =Inputs!F72 | G29: =Inputs!G72 | H29: =Inputs!H72 | I29: =Inputs!I72 | K29: =Inputs!D72*Inputs!D16 | L29: =Inputs!E72*Inputs!E16 | M29: =Inputs!F72*Inputs!F16 | N29: =Inputs!G72*Inputs!G16 | O29: =Inputs!H72*Inputs!H16 | P29: =Inputs!I72*Inputs!I16
A30: Carbonation | B30: $/can | D30: =Inputs!D73 | E30: =Inputs!E73 | F30: =Inputs!F73 | G30: =Inputs!G73 | H30: =Inputs!H73 | I30: =Inputs!I73 | K30: =Inputs!D73*Inputs!D16 | L30: =Inputs!E73*Inputs!E16 | M30: =Inputs!F73*Inputs!F16 | N30: =Inputs!G73*Inputs!G16 | O30: =Inputs!H73*Inputs!H16 | P30: =Inputs!I73*Inputs!I16
A31: Tank mixing / blending | B31: $/can | D31: =Inputs!D74 | E31: =Inputs!E74 | F31: =Inputs!F74 | G31: =Inputs!G74 | H31: =Inputs!H74 | I31: =Inputs!I74 | K31: =Inputs!D74*Inputs!D16 | L31: =Inputs!E74*Inputs!E16 | M31: =Inputs!F74*Inputs!F16 | N31: =Inputs!G74*Inputs!G16 | O31: =Inputs!H74*Inputs!H16 | P31: =Inputs!I74*Inputs!I16
A32: Lab / micro hold | B32: $/can | D32: =Inputs!D75 | E32: =Inputs!E75 | F32: =Inputs!F75 | G32: =Inputs!G75 | H32: =Inputs!H75 | I32: =Inputs!I75 | K32: =Inputs!D75*Inputs!D16 | L32: =Inputs!E75*Inputs!E16 | M32: =Inputs!F75*Inputs!F16 | N32: =Inputs!G75*Inputs!G16 | O32: =Inputs!H75*Inputs!H16 | P32: =Inputs!I75*Inputs!I16
A33: Allergen handling | B33: $/can | D33: =Inputs!D76 | E33: =Inputs!E76 | F33: =Inputs!F76 | G33: =Inputs!G76 | H33: =Inputs!H76 | I33: =Inputs!I76 | K33: =Inputs!D76*Inputs!D16 | L33: =Inputs!E76*Inputs!E16 | M33: =Inputs!F76*Inputs!F16 | N33: =Inputs!G76*Inputs!G16 | O33: =Inputs!H76*Inputs!H16 | P33: =Inputs!I76*Inputs!I16
A34: Other tolling | B34: $/can | D34: =Inputs!D77 | E34: =Inputs!E77 | F34: =Inputs!F77 | G34: =Inputs!G77 | H34: =Inputs!H77 | I34: =Inputs!I77 | K34: =Inputs!D77*Inputs!D16 | L34: =Inputs!E77*Inputs!E16 | M34: =Inputs!F77*Inputs!F16 | N34: =Inputs!G77*Inputs!G16 | O34: =Inputs!H77*Inputs!H16 | P34: =Inputs!I77*Inputs!I16
A35: Setup and skid packing
A36: Skid packing fee | B36: $/pallet | D36: =IFERROR(Inputs!D79/(Inputs!D18*Inputs!D16),0) | E36: =IFERROR(Inputs!E79/(Inputs!E18*Inputs!E16),0) | F36: =IFERROR(Inputs!F79/(Inputs!F18*Inputs!F16),0) | G36: =IFERROR(Inputs!G79/(Inputs!G18*Inputs!G16),0) | H36: =IFERROR(Inputs!H79/(Inputs!H18*Inputs!H16),0) | I36: =IFERROR(Inputs!I79/(Inputs!I18*Inputs!I16),0) | K36: =IFERROR(Inputs!D79/Inputs!D18,0) | L36: =IFERROR(Inputs!E79/Inputs!E18,0) | M36: =IFERROR(Inputs!F79/Inputs!F18,0) | N36: =IFERROR(Inputs!G79/Inputs!G18,0) | O36: =IFERROR(Inputs!H79/Inputs!H18,0) | P36: =IFERROR(Inputs!I79/Inputs!I18,0)
A37: Setup cost per case (with first run premium) | B37: derived | D37: =IFERROR(Inputs!D85/Inputs!D16,0) | E37: =IFERROR(Inputs!E85/Inputs!E16,0) | F37: =IFERROR(Inputs!F85/Inputs!F16,0) | G37: =IFERROR(Inputs!G85/Inputs!G16,0) | H37: =IFERROR(Inputs!H85/Inputs!H16,0) | I37: =IFERROR(Inputs!I85/Inputs!I16,0) | K37: =Inputs!D85 | L37: =Inputs!E85 | M37: =Inputs!F85 | N37: =Inputs!G85 | O37: =Inputs!H85 | P37: =Inputs!I85
A39: Direct COGS (total) | D39: =D7+D8+D9+D10+D11+D12+D14+D15+D16+D17+D19+D20+D21+D23+D24+D25+D26+D28+D29+D30+D31+D32+D33+D34+D36+D37 | E39: =E7+E8+E9+E10+E11+E12+E14+E15+E16+E17+E19+E20+E21+E23+E24+E25+E26+E28+E29+E30+E31+E32+E33+E34+E36+E37 | F39: =F7+F8+F9+F10+F11+F12+F14+F15+F16+F17+F19+F20+F21+F23+F24+F25+F26+F28+F29+F30+F31+F32+F33+F34+F36+F37 | G39: =G7+G8+G9+G10+G11+G12+G14+G15+G16+G17+G19+G20+G21+G23+G24+G25+G26+G28+G29+G30+G31+G32+G33+G34+G36+G37 | H39: =H7+H8+H9+H10+H11+H12+H14+H15+H16+H17+H19+H20+H21+H23+H24+H25+H26+H28+H29+H30+H31+H32+H33+H34+H36+H37 | I39: =I7+I8+I9+I10+I11+I12+I14+I15+I16+I17+I19+I20+I21+I23+I24+I25+I26+I28+I29+I30+I31+I32+I33+I34+I36+I37 | K39: =K7+K8+K9+K10+K11+K12+K14+K15+K16+K17+K19+K20+K21+K23+K24+K25+K26+K28+K29+K30+K31+K32+K33+K34+K36+K37 | L39: =L7+L8+L9+L10+L11+L12+L14+L15+L16+L17+L19+L20+L21+L23+L24+L25+L26+L28+L29+L30+L31+L32+L33+L34+L36+L37 | M39: =M7+M8+M9+M10+M11+M12+M14+M15+M16+M17+M19+M20+M21+M23+M24+M25+M26+M28+M29+M30+M31+M32+M33+M34+M36+M37 | N39: =N7+N8+N9+N10+N11+N12+N14+N15+N16+N17+N19+N20+N21+N23+N24+N25+N26+N28+N29+N30+N31+N32+N33+N34+N36+N37 | O39: =O7+O8+O9+O10+O11+O12+O14+O15+O16+O17+O19+O20+O21+O23+O24+O25+O26+O28+O29+O30+O31+O32+O33+O34+O36+O37 | P39: =P7+P8+P9+P10+P11+P12+P14+P15+P16+P17+P19+P20+P21+P23+P24+P25+P26+P28+P29+P30+P31+P32+P33+P34+P36+P37

Sheet Indirect COGS
A1: Indirect COGS. Corporate allocated.
D3: Per can (CAD) | K3: Per case (CAD)
A4: Component | B4: Native | D4: =Inputs!D4 | E4: =Inputs!E4 | F4: =Inputs!F4 | G4: =Inputs!G4 | H4: =Inputs!H4 | I4: =Inputs!I4 | K4: =Inputs!D4 | L4: =Inputs!E4 | M4: =Inputs!F4 | N4: =Inputs!G4 | O4: =Inputs!H4 | P4: =Inputs!I4
A6: Warehousing and pick/pack
A7: Warehousing raw materials | B7: $/case | D7: =IFERROR(Inputs!D90/Inputs!D16,0) | E7: =IFERROR(Inputs!E90/Inputs!E16,0) | F7: =IFERROR(Inputs!F90/Inputs!F16,0) | G7: =IFERROR(Inputs!G90/Inputs!G16,0) | H7: =IFERROR(Inputs!H90/Inputs!H16,0) | I7: =IFERROR(Inputs!I90/Inputs!I16,0) | K7: =Inputs!D90 | L7: =Inputs!E90 | M7: =Inputs!F90 | N7: =Inputs!G90 | O7: =Inputs!H90 | P7: =Inputs!I90
A8: Warehousing finished goods | B8: $/case | D8: =IFERROR(Inputs!D94/Inputs!D16,0) | E8: =IFERROR(Inputs!E94/Inputs!E16,0) | F8: =IFERROR(Inputs!F94/Inputs!F16,0) | G8: =IFERROR(Inputs!G94/Inputs!G16,0) | H8: =IFERROR(Inputs!H94/Inputs!H16,0) | I8: =IFERROR(Inputs!I94/Inputs!I16,0) | K8: =Inputs!D94 | L8: =Inputs!E94 | M8: =Inputs!F94 | N8: =Inputs!G94 | O8: =Inputs!H94 | P8: =Inputs!I94
A9: Pick and pack | B9: $/case | D9: =IFERROR(Inputs!D98/Inputs!D16,0) | E9: =IFERROR(Inputs!E98/Inputs!E16,0) | F9: =IFERROR(Inputs!F98/Inputs!F16,0) | G9: =IFERROR(Inputs!G98/Inputs!G16,0) | H9: =IFERROR(Inputs!H98/Inputs!H16,0) | I9: =IFERROR(Inputs!I98/Inputs!I16,0) | K9: =Inputs!D98 | L9: =Inputs!E98 | M9: =Inputs!F98 | N9: =Inputs!G98 | O9: =Inputs!H98 | P9: =Inputs!I98
A10: Freight (from Freight Model)
A11: Freight In | B11: $/case | D11: =IFERROR('Freight Model'!D17/Inputs!D16,0) | E11: =IFERROR('Freight Model'!E17/Inputs!E16,0) | F11: =IFERROR('Freight Model'!F17/Inputs!F16,0) | G11: =IFERROR('Freight Model'!G17/Inputs!G16,0) | H11: =IFERROR('Freight Model'!H17/Inputs!H16,0) | I11: =IFERROR('Freight Model'!I17/Inputs!I16,0) | K11: ='Freight Model'!D17 | L11: ='Freight Model'!E17 | M11: ='Freight Model'!F17 | N11: ='Freight Model'!G17 | O11: ='Freight Model'!H17 | P11: ='Freight Model'!I17
A12: Freight Out | B12: $/case | D12: =IFERROR('Freight Model'!D18/Inputs!D16,0) | E12: =IFERROR('Freight Model'!E18/Inputs!E16,0) | F12: =IFERROR('Freight Model'!F18/Inputs!F16,0) | G12: =IFERROR('Freight Model'!G18/Inputs!G16,0) | H12: =IFERROR('Freight Model'!H18/Inputs!H16,0) | I12: =IFERROR('Freight Model'!I18/Inputs!I16,0) | K12: ='Freight Model'!D18 | L12: ='Freight Model'!E18 | M12: ='Freight Model'!F18 | N12: ='Freight Model'!G18 | O12: ='Freight Model'!H18 | P12: ='Freight Model'!I18
A13: Inventory adjustment and scrap (derived)
A14: Inventory adjustment | B14: $/case | D14: =IFERROR((Inputs!D104*'Direct COGS'!K39)/Inputs!D16,0) | E14: =IFERROR((Inputs!E104*'Direct COGS'!L39)/Inputs!E16,0) | F14: =IFERROR((Inputs!F104*'Direct COGS'!M39)/Inputs!F16,0) | G14: =IFERROR((Inputs!G104*'Direct COGS'!N39)/Inputs!G16,0) | H14: =IFERROR((Inputs!H104*'Direct COGS'!O39)/Inputs!H16,0) | I14: =IFERROR((Inputs!I104*'Direct COGS'!P39)/Inputs!I16,0) | K14: =Inputs!D104*'Direct COGS'!K39 | L14: =Inputs!E104*'Direct COGS'!L39 | M14: =Inputs!F104*'Direct COGS'!M39 | N14: =Inputs!G104*'Direct COGS'!N39 | O14: =Inputs!H104*'Direct COGS'!O39 | P14: =Inputs!I104*'Direct COGS'!P39
A15: Scrap allowance | B15: $/case | D15: =IFERROR((Inputs!D32*'Direct COGS'!K39)/Inputs!D16,0) | E15: =IFERROR((Inputs!E32*'Direct COGS'!L39)/Inputs!E16,0) | F15: =IFERROR((Inputs!F32*'Direct COGS'!M39)/Inputs!F16,0) | G15: =IFERROR((Inputs!G32*'Direct COGS'!N39)/Inputs!G16,0) | H15: =IFERROR((Inputs!H32*'Direct COGS'!O39)/Inputs!H16,0) | I15: =IFERROR((Inputs!I32*'Direct COGS'!P39)/Inputs!I16,0) | K15: =Inputs!D32*'Direct COGS'!K39 | L15: =Inputs!E32*'Direct COGS'!L39 | M15: =Inputs!F32*'Direct COGS'!M39 | N15: =Inputs!G32*'Direct COGS'!N39 | O15: =Inputs!H32*'Direct COGS'!O39 | P15: =Inputs!I32*'Direct COGS'!P39
A16: Insurance and other
A17: Insurance | B17: $/case | D17: =IFERROR(Inputs!D103/Inputs!D16,0) | E17: =IFERROR(Inputs!E103/Inputs!E16,0) | F17: =IFERROR(Inputs!F103/Inputs!F16,0) | G17: =IFERROR(Inputs!G103/Inputs!G16,0) | H17: =IFERROR(Inputs!H103/Inputs!H16,0) | I17: =IFERROR(Inputs!I103/Inputs!I16,0) | K17: =Inputs!D103 | L17: =Inputs!E103 | M17: =Inputs!F103 | N17: =Inputs!G103 | O17: =Inputs!H103 | P17: =Inputs!I103
A18: Other indirect | B18: $/case | D18: =IFERROR(Inputs!D105/Inputs!D16,0) | E18: =IFERROR(Inputs!E105/Inputs!E16,0) | F18: =IFERROR(Inputs!F105/Inputs!F16,0) | G18: =IFERROR(Inputs!G105/Inputs!G16,0) | H18: =IFERROR(Inputs!H105/Inputs!H16,0) | I18: =IFERROR(Inputs!I105/Inputs!I16,0) | K18: =Inputs!D105 | L18: =Inputs!E105 | M18: =Inputs!F105 | N18: =Inputs!G105 | O18: =Inputs!H105 | P18: =Inputs!I105
A20: Indirect COGS (total) | D20: =D7+D8+D9+D11+D12+D14+D15+D17+D18 | E20: =E7+E8+E9+E11+E12+E14+E15+E17+E18 | F20: =F7+F8+F9+F11+F12+F14+F15+F17+F18 | G20: =G7+G8+G9+G11+G12+G14+G15+G17+G18 | H20: =H7+H8+H9+H11+H12+H14+H15+H17+H18 | I20: =I7+I8+I9+I11+I12+I14+I15+I17+I18 | K20: =K7+K8+K9+K11+K12+K14+K15+K17+K18 | L20: =L7+L8+L9+L11+L12+L14+L15+L17+L18 | M20: =M7+M8+M9+M11+M12+M14+M15+M17+M18 | N20: =N7+N8+N9+N11+N12+N14+N15+N17+N18 | O20: =O7+O8+O9+O11+O12+O14+O15+O17+O18 | P20: =P7+P8+P9+P11+P12+P14+P15+P17+P18

Sheet Freight Model
A1: Freight Model.
A4: Lane | B4: Unit | D4: =Inputs!D4 | E4: =Inputs!E4 | F4: =Inputs!F4 | G4: =Inputs!G4 | H4: =Inputs!H4 | I4: =Inputs!I4
A6: Per pallet with fuel
A7: Inbound | B7: $/pallet | D7: =Inputs!D117*(1+Inputs!D120) | E7: =Inputs!E117*(1+Inputs!E120) | F7: =Inputs!F117*(1+Inputs!F120) | G7: =Inputs!G117*(1+Inputs!G120) | H7: =Inputs!H117*(1+Inputs!H120) | I7: =Inputs!I117*(1+Inputs!I120)
A8: Transfer | B8: $/pallet | D8: =Inputs!D118*(1+Inputs!D120) | E8: =Inputs!E118*(1+Inputs!E120) | F8: =Inputs!F118*(1+Inputs!F120) | G8: =Inputs!G118*(1+Inputs!G120) | H8: =Inputs!H118*(1+Inputs!H120) | I8: =Inputs!I118*(1+Inputs!I120)
A9: Outbound | B9: $/pallet | D9: =Inputs!D119*(1+Inputs!D120) | E9: =Inputs!E119*(1+Inputs!E120) | F9: =Inputs!F119*(1+Inputs!F120) | G9: =Inputs!G119*(1+Inputs!G120) | H9: =Inputs!H119*(1+Inputs!H120) | I9: =Inputs!I119*(1+Inputs!I120)
A10: LTL premium (memo) | B10: $/pallet | D10: =Inputs!D121 | E10: =Inputs!E121 | F10: =Inputs!F121 | G10: =Inputs!G121 | H10: =Inputs!H121 | I10: =Inputs!I121
A12: Per case
A13: Inbound per case | B13: $/case | D13: =IFERROR(D7/Inputs!D18,0) | E13: =IFERROR(E7/Inputs!E18,0) | F13: =IFERROR(F7/Inputs!F18,0) | G13: =IFERROR(G7/Inputs!G18,0) | H13: =IFERROR(H7/Inputs!H18,0) | I13: =IFERROR(I7/Inputs!I18,0)
A14: Transfer per case | B14: $/case | D14: =IFERROR(D8/Inputs!D18,0) | E14: =IFERROR(E8/Inputs!E18,0) | F14: =IFERROR(F8/Inputs!F18,0) | G14: =IFERROR(G8/Inputs!G18,0) | H14: =IFERROR(H8/Inputs!H18,0) | I14: =IFERROR(I8/Inputs!I18,0)
A15: Outbound per case | B15: $/case | D15: =IFERROR(D9/Inputs!D18,0) | E15: =IFERROR(E9/Inputs!E18,0) | F15: =IFERROR(F9/Inputs!F18,0) | G15: =IFERROR(G9/Inputs!G18,0) | H15: =IFERROR(H9/Inputs!H18,0) | I15: =IFERROR(I9/Inputs!I18,0)
A17: Freight In (inbound + transfer) | B17: $/case | D17: =D13+D14 | E17: =E13+E14 | F17: =F13+F14 | G17: =G13+G14 | H17: =H13+H14 | I17: =I13+I14
A18: Freight Out | B18: $/case | D18: =D15 | E18: =E15 | F18: =F15 | G18: =G15 | H18: =H15 | I18: =I15

Sheet P&L by Scenario
A1: P&L by Scenario
D3: =CONCATENATE(Cover!B4," (CAD)") | K3: Year 1 total (CAD)
A4: Line item | D4: =Inputs!D4 | E4: =Inputs!E4 | F4: =Inputs!F4 | G4: =Inputs!G4 | H4: =Inputs!H4 | I4: =Inputs!I4 | K4: =Inputs!D4 | L4: =Inputs!E4 | M4: =Inputs!F4 | N4: =Inputs!G4 | O4: =Inputs!H4 | P4: =Inputs!I4
A6: =CONCATENATE("Physical units (",Cover!$B$4,")") | D6: =IFERROR(Inputs!D10/Cover!D6,0) | E6: =IFERROR(Inputs!E10/Cover!E6,0) | F6: =IFERROR(Inputs!F10/Cover!F6,0) | G6: =IFERROR(Inputs!G10/Cover!G6,0) | H6: =IFERROR(Inputs!H10/Cover!H6,0) | I6: =IFERROR(Inputs!I10/Cover!I6,0) | K6: =D6 | L6: =E6 | M6: =F6 | N6: =G6 | O6: =H6 | P6: =I6
A7: Gross Revenue (CP) | D7: =(Inputs!D35)*Cover!D6 | E7: =(Inputs!E35)*Cover!E6 | F7: =(Inputs!F35)*Cover!F6 | G7: =(Inputs!G35)*Cover!G6 | H7: =(Inputs!H35)*Cover!H6 | I7: =(Inputs!I35)*Cover!I6 | K7: =(Inputs!D35)*Inputs!D10 | L7: =(Inputs!E35)*Inputs!E10 | M7: =(Inputs!F35)*Inputs!F10 | N7: =(Inputs!G35)*Inputs!G10 | O7: =(Inputs!H35)*Inputs!H10 | P7: =(Inputs!I35)*Inputs!I10
A8: Discounts (blended trade) | D8: =(-Inputs!D44*Inputs!D35)*Cover!D6 | E8: =(-Inputs!E44*Inputs!E35)*Cover!E6 | F8: =(-Inputs!F44*Inputs!F35)*Cover!F6 | G8: =(-Inputs!G44*Inputs!G35)*Cover!G6 | H8: =(-Inputs!H44*Inputs!H35)*Cover!H6 | I8: =(-Inputs!I44*Inputs!I35)*Cover!I6 | K8: =(-Inputs!D44*Inputs!D35)*Inputs!D10 | L8: =(-Inputs!E44*Inputs!E35)*Inputs!E10 | M8: =(-Inputs!F44*Inputs!F35)*Inputs!F10 | N8: =(-Inputs!G44*Inputs!G35)*Inputs!G10 | O8: =(-Inputs!H44*Inputs!H35)*Inputs!H10 | P8: =(-Inputs!I44*Inputs!I35)*Inputs!I10
A9: Net Sales | D9: =(Inputs!D35*(1-Inputs!D44))*Cover!D6 | E9: =(Inputs!E35*(1-Inputs!E44))*Cover!E6 | F9: =(Inputs!F35*(1-Inputs!F44))*Cover!F6 | G9: =(Inputs!G35*(1-Inputs!G44))*Cover!G6 | H9: =(Inputs!H35*(1-Inputs!H44))*Cover!H6 | I9: =(Inputs!I35*(1-Inputs!I44))*Cover!I6 | K9: =(Inputs!D35*(1-Inputs!D44))*Inputs!D10 | L9: =(Inputs!E35*(1-Inputs!E44))*Inputs!E10 | M9: =(Inputs!F35*(1-Inputs!F44))*Inputs!F10 | N9: =(Inputs!G35*(1-Inputs!G44))*Inputs!G10 | O9: =(Inputs!H35*(1-Inputs!H44))*Inputs!H10 | P9: =(Inputs!I35*(1-Inputs!I44))*Inputs!I10
A11: Cost of Sales
A12: COGS Direct | D12: =('Direct COGS'!K39)*Cover!D6 | E12: =('Direct COGS'!L39)*Cover!E6 | F12: =('Direct COGS'!M39)*Cover!F6 | G12: =('Direct COGS'!N39)*Cover!G6 | H12: =('Direct COGS'!O39)*Cover!H6 | I12: =('Direct COGS'!P39)*Cover!I6 | K12: =('Direct COGS'!K39)*Inputs!D10 | L12: =('Direct COGS'!L39)*Inputs!E10 | M12: =('Direct COGS'!M39)*Inputs!F10 | N12: =('Direct COGS'!N39)*Inputs!G10 | O12: =('Direct COGS'!O39)*Inputs!H10 | P12: =('Direct COGS'!P39)*Inputs!I10
A13: COGS Indirect | D13: =('Indirect COGS'!K20)*Cover!D6 | E13: =('Indirect COGS'!L20)*Cover!E6 | F13: =('Indirect COGS'!M20)*Cover!F6 | G13: =('Indirect COGS'!N20)*Cover!G6 | H13: =('Indirect COGS'!O20)*Cover!H6 | I13: =('Indirect COGS'!P20)*Cover!I6 | K13: =('Indirect COGS'!K20)*Inputs!D10 | L13: =('Indirect COGS'!L20)*Inputs!E10 | M13: =('Indirect COGS'!M20)*Inputs!F10 | N13: =('Indirect COGS'!N20)*Inputs!G10 | O13: =('Indirect COGS'!O20)*Inputs!H10 | P13: =('Indirect COGS'!P20)*Inputs!I10
A14: Cost of Sales | D14: =('Direct COGS'!K39+'Indirect COGS'!K20)*Cover!D6 | E14: =('Direct COGS'!L39+'Indirect COGS'!L20)*Cover!E6 | F14: =('Direct COGS'!M39+'Indirect COGS'!M20)*Cover!F6 | G14: =('Direct COGS'!N39+'Indirect COGS'!N20)*Cover!G6 | H14: =('Direct COGS'!O39+'Indirect COGS'!O20)*Cover!H6 | I14: =('Direct COGS'!P39+'Indirect COGS'!P20)*Cover!I6 | K14: =('Direct COGS'!K39+'Indirect COGS'!K20)*Inputs!D10 | L14: =('Direct COGS'!L39+'Indirect COGS'!L20)*Inputs!E10 | M14: =('Direct COGS'!M39+'Indirect COGS'!M20)*Inputs!F10 | N14: =('Direct COGS'!N39+'Indirect COGS'!N20)*Inputs!G10 | O14: =('Direct COGS'!O39+'Indirect COGS'!O20)*Inputs!H10 | P14: =('Direct COGS'!P39+'Indirect COGS'!P20)*Inputs!I10
A15: Gross Profit | D15: =((Inputs!D35*(1-Inputs!D44))-('Direct COGS'!K39+'Indirect COGS'!K20))*Cover!D6 | E15: =((Inputs!E35*(1-Inputs!E44))-('Direct COGS'!L39+'Indirect COGS'!L20))*Cover!E6 | F15: =((Inputs!F35*(1-Inputs!F44))-('Direct COGS'!M39+'Indirect COGS'!M20))*Cover!F6 | G15: =((Inputs!G35*(1-Inputs!G44))-('Direct COGS'!N39+'Indirect COGS'!N20))*Cover!G6 | H15: =((Inputs!H35*(1-Inputs!H44))-('Direct COGS'!O39+'Indirect COGS'!O20))*Cover!H6 | I15: =((Inputs!I35*(1-Inputs!I44))-('Direct COGS'!P39+'Indirect COGS'!P20))*Cover!I6 | K15: =((Inputs!D35*(1-Inputs!D44))-('Direct COGS'!K39+'Indirect COGS'!K20))*Inputs!D10 | L15: =((Inputs!E35*(1-Inputs!E44))-('Direct COGS'!L39+'Indirect COGS'!L20))*Inputs!E10 | M15: =((Inputs!F35*(1-Inputs!F44))-('Direct COGS'!M39+'Indirect COGS'!M20))*Inputs!F10 | N15: =((Inputs!G35*(1-Inputs!G44))-('Direct COGS'!N39+'Indirect COGS'!N20))*Inputs!G10 | O15: =((Inputs!H35*(1-Inputs!H44))-('Direct COGS'!O39+'Indirect COGS'!O20))*Inputs!H10 | P15: =((Inputs!I35*(1-Inputs!I44))-('Direct COGS'!P39+'Indirect COGS'!P20))*Inputs!I10
A16: GP % | D16: =IFERROR(((Inputs!D35*(1-Inputs!D44))-('Direct COGS'!K39+'Indirect COGS'!K20))/(Inputs!D35*(1-Inputs!D44)),0) | E16: =IFERROR(((Inputs!E35*(1-Inputs!E44))-('Direct COGS'!L39+'Indirect COGS'!L20))/(Inputs!E35*(1-Inputs!E44)),0) | F16: =IFERROR(((Inputs!F35*(1-Inputs!F44))-('Direct COGS'!M39+'Indirect COGS'!M20))/(Inputs!F35*(1-Inputs!F44)),0) | G16: =IFERROR(((Inputs!G35*(1-Inputs!G44))-('Direct COGS'!N39+'Indirect COGS'!N20))/(Inputs!G35*(1-Inputs!G44)),0) | H16: =IFERROR(((Inputs!H35*(1-Inputs!H44))-('Direct COGS'!O39+'Indirect COGS'!O20))/(Inputs!H35*(1-Inputs!H44)),0) | I16: =IFERROR(((Inputs!I35*(1-Inputs!I44))-('Direct COGS'!P39+'Indirect COGS'!P20))/(Inputs!I35*(1-Inputs!I44)),0) | K16: =D16 | L16: =E16 | M16: =F16 | N16: =G16 | O16: =H16 | P16: =I16
A18: A and P
A19: A&P Consumer | D19: =(Inputs!D108*(Inputs!D35*(1-Inputs!D44)))*Cover!D6 | E19: =(Inputs!E108*(Inputs!E35*(1-Inputs!E44)))*Cover!E6 | F19: =(Inputs!F108*(Inputs!F35*(1-Inputs!F44)))*Cover!F6 | G19: =(Inputs!G108*(Inputs!G35*(1-Inputs!G44)))*Cover!G6 | H19: =(Inputs!H108*(Inputs!H35*(1-Inputs!H44)))*Cover!H6 | I19: =(Inputs!I108*(Inputs!I35*(1-Inputs!I44)))*Cover!I6 | K19: =(Inputs!D108*(Inputs!D35*(1-Inputs!D44)))*Inputs!D10 | L19: =(Inputs!E108*(Inputs!E35*(1-Inputs!E44)))*Inputs!E10 | M19: =(Inputs!F108*(Inputs!F35*(1-Inputs!F44)))*Inputs!F10 | N19: =(Inputs!G108*(Inputs!G35*(1-Inputs!G44)))*Inputs!G10 | O19: =(Inputs!H108*(Inputs!H35*(1-Inputs!H44)))*Inputs!H10 | P19: =(Inputs!I108*(Inputs!I35*(1-Inputs!I44)))*Inputs!I10
A20: A&P Trade | D20: =(Inputs!D109*(Inputs!D35*(1-Inputs!D44)))*Cover!D6 | E20: =(Inputs!E109*(Inputs!E35*(1-Inputs!E44)))*Cover!E6 | F20: =(Inputs!F109*(Inputs!F35*(1-Inputs!F44)))*Cover!F6 | G20: =(Inputs!G109*(Inputs!G35*(1-Inputs!G44)))*Cover!G6 | H20: =(Inputs!H109*(Inputs!H35*(1-Inputs!H44)))*Cover!H6 | I20: =(Inputs!I109*(Inputs!I35*(1-Inputs!I44)))*Cover!I6 | K20: =(Inputs!D109*(Inputs!D35*(1-Inputs!D44)))*Inputs!D10 | L20: =(Inputs!E109*(Inputs!E35*(1-Inputs!E44)))*Inputs!E10 | M20: =(Inputs!F109*(Inputs!F35*(1-Inputs!F44)))*Inputs!F10 | N20: =(Inputs!G109*(Inputs!G35*(1-Inputs!G44)))*Inputs!G10 | O20: =(Inputs!H109*(Inputs!H35*(1-Inputs!H44)))*Inputs!H10 | P20: =(Inputs!I109*(Inputs!I35*(1-Inputs!I44)))*Inputs!I10
A21: A&P Sales | D21: =(Inputs!D110*(Inputs!D35*(1-Inputs!D44)))*Cover!D6 | E21: =(Inputs!E110*(Inputs!E35*(1-Inputs!E44)))*Cover!E6 | F21: =(Inputs!F110*(Inputs!F35*(1-Inputs!F44)))*Cover!F6 | G21: =(Inputs!G110*(Inputs!G35*(1-Inputs!G44)))*Cover!G6 | H21: =(Inputs!H110*(Inputs!H35*(1-Inputs!H44)))*Cover!H6 | I21: =(Inputs!I110*(Inputs!I35*(1-Inputs!I44)))*Cover!I6 | K21: =(Inputs!D110*(Inputs!D35*(1-Inputs!D44)))*Inputs!D10 | L21: =(Inputs!E110*(Inputs!E35*(1-Inputs!E44)))*Inputs!E10 | M21: =(Inputs!F110*(Inputs!F35*(1-Inputs!F44)))*Inputs!F10 | N21: =(Inputs!G110*(Inputs!G35*(1-Inputs!G44)))*Inputs!G10 | O21: =(Inputs!H110*(Inputs!H35*(1-Inputs!H44)))*Inputs!H10 | P21: =(Inputs!I110*(Inputs!I35*(1-Inputs!I44)))*Inputs!I10
A22: Slotting / listing fees | D22: =(Inputs!D111)*Cover!D6 | E22: =(Inputs!E111)*Cover!E6 | F22: =(Inputs!F111)*Cover!F6 | G22: =(Inputs!G111)*Cover!G6 | H22: =(Inputs!H111)*Cover!H6 | I22: =(Inputs!I111)*Cover!I6 | K22: =(Inputs!D111)*Inputs!D10 | L22: =(Inputs!E111)*Inputs!E10 | M22: =(Inputs!F111)*Inputs!F10 | N22: =(Inputs!G111)*Inputs!G10 | O22: =(Inputs!H111)*Inputs!H10 | P22: =(Inputs!I111)*Inputs!I10
A23: Broker, distributor, sales commission, royalties | D23: =((Inputs!D112+Inputs!D113+Inputs!D114)*(Inputs!D35*(1-Inputs!D44))+Inputs!D122+Inputs!D123+Inputs!D124)*Cover!D6 | E23: =((Inputs!E112+Inputs!E113+Inputs!E114)*(Inputs!E35*(1-Inputs!E44))+Inputs!E122+Inputs!E123+Inputs!E124)*Cover!E6 | F23: =((Inputs!F112+Inputs!F113+Inputs!F114)*(Inputs!F35*(1-Inputs!F44))+Inputs!F122+Inputs!F123+Inputs!F124)*Cover!F6 | G23: =((Inputs!G112+Inputs!G113+Inputs!G114)*(Inputs!G35*(1-Inputs!G44))+Inputs!G122+Inputs!G123+Inputs!G124)*Cover!G6 | H23: =((Inputs!H112+Inputs!H113+Inputs!H114)*(Inputs!H35*(1-Inputs!H44))+Inputs!H122+Inputs!H123+Inputs!H124)*Cover!H6 | I23: =((Inputs!I112+Inputs!I113+Inputs!I114)*(Inputs!I35*(1-Inputs!I44))+Inputs!I122+Inputs!I123+Inputs!I124)*Cover!I6 | K23: =((Inputs!D112+Inputs!D113+Inputs!D114)*(Inputs!D35*(1-Inputs!D44))+Inputs!D122+Inputs!D123+Inputs!D124)*Inputs!D10 | L23: =((Inputs!E112+Inputs!E113+Inputs!E114)*(Inputs!E35*(1-Inputs!E44))+Inputs!E122+Inputs!E123+Inputs!E124)*Inputs!E10 | M23: =((Inputs!F112+Inputs!F113+Inputs!F114)*(Inputs!F35*(1-Inputs!F44))+Inputs!F122+Inputs!F123+Inputs!F124)*Inputs!F10 | N23: =((Inputs!G112+Inputs!G113+Inputs!G114)*(Inputs!G35*(1-Inputs!G44))+Inputs!G122+Inputs!G123+Inputs!G124)*Inputs!G10 | O23: =((Inputs!H112+Inputs!H113+Inputs!H114)*(Inputs!H35*(1-Inputs!H44))+Inputs!H122+Inputs!H123+Inputs!H124)*Inputs!H10 | P23: =((Inputs!I112+Inputs!I113+Inputs!I114)*(Inputs!I35*(1-Inputs!I44))+Inputs!I122+Inputs!I123+Inputs!I124)*Inputs!I10
A24: A&P (total) | D24: =((Inputs!D108+Inputs!D109+Inputs!D110+Inputs!D112+Inputs!D113+Inputs!D114)*(Inputs!D35*(1-Inputs!D44))+Inputs!D111+Inputs!D122+Inputs!D123+Inputs!D124)*Cover!D6 | E24: =((Inputs!E108+Inputs!E109+Inputs!E110+Inputs!E112+Inputs!E113+Inputs!E114)*(Inputs!E35*(1-Inputs!E44))+Inputs!E111+Inputs!E122+Inputs!E123+Inputs!E124)*Cover!E6 | F24: =((Inputs!F108+Inputs!F109+Inputs!F110+Inputs!F112+Inputs!F113+Inputs!F114)*(Inputs!F35*(1-Inputs!F44))+Inputs!F111+Inputs!F122+Inputs!F123+Inputs!F124)*Cover!F6 | G24: =((Inputs!G108+Inputs!G109+Inputs!G110+Inputs!G112+Inputs!G113+Inputs!G114)*(Inputs!G35*(1-Inputs!G44))+Inputs!G111+Inputs!G122+Inputs!G123+Inputs!G124)*Cover!G6 | H24: =((Inputs!H108+Inputs!H109+Inputs!H110+Inputs!H112+Inputs!H113+Inputs!H114)*(Inputs!H35*(1-Inputs!H44))+Inputs!H111+Inputs!H122+Inputs!H123+Inputs!H124)*Cover!H6 | I24: =((Inputs!I108+Inputs!I109+Inputs!I110+Inputs!I112+Inputs!I113+Inputs!I114)*(Inputs!I35*(1-Inputs!I44))+Inputs!I111+Inputs!I122+Inputs!I123+Inputs!I124)*Cover!I6 | K24: =((Inputs!D108+Inputs!D109+Inputs!D110+Inputs!D112+Inputs!D113+Inputs!D114)*(Inputs!D35*(1-Inputs!D44))+Inputs!D111+Inputs!D122+Inputs!D123+Inputs!D124)*Inputs!D10 | L24: =((Inputs!E108+Inputs!E109+Inputs!E110+Inputs!E112+Inputs!E113+Inputs!E114)*(Inputs!E35*(1-Inputs!E44))+Inputs!E111+Inputs!E122+Inputs!E123+Inputs!E124)*Inputs!E10 | M24: =((Inputs!F108+Inputs!F109+Inputs!F110+Inputs!F112+Inputs!F113+Inputs!F114)*(Inputs!F35*(1-Inputs!F44))+Inputs!F111+Inputs!F122+Inputs!F123+Inputs!F124)*Inputs!F10 | N24: =((Inputs!G108+Inputs!G109+Inputs!G110+Inputs!G112+Inputs!G113+Inputs!G114)*(Inputs!G35*(1-Inputs!G44))+Inputs!G111+Inputs!G122+Inputs!G123+Inputs!G124)*Inputs!G10 | O24: =((Inputs!H108+Inputs!H109+Inputs!H110+Inputs!H112+Inputs!H113+Inputs!H114)*(Inputs!H35*(1-Inputs!H44))+Inputs!H111+Inputs!H122+Inputs!H123+Inputs!H124)*Inputs!H10 | P24: =((Inputs!I108+Inputs!I109+Inputs!I110+Inputs!I112+Inputs!I113+Inputs!I114)*(Inputs!I35*(1-Inputs!I44))+Inputs!I111+Inputs!I122+Inputs!I123+Inputs!I124)*Inputs!I10
A26: Contrib After A&P (PBT before tax) | D26: =((Inputs!D35*(1-Inputs!D44))-('Direct COGS'!K39+'Indirect COGS'!K20)-((Inputs!D108+Inputs!D109+Inputs!D110+Inputs!D112+Inputs!D113+Inputs!D114)*(Inputs!D35*(1-Inputs!D44))+Inputs!D111+Inputs!D122+Inputs!D123+Inputs!D124))*Cover!D6 | E26: =((Inputs!E35*(1-Inputs!E44))-('Direct COGS'!L39+'Indirect COGS'!L20)-((Inputs!E108+Inputs!E109+Inputs!E110+Inputs!E112+Inputs!E113+Inputs!E114)*(Inputs!E35*(1-Inputs!E44))+Inputs!E111+Inputs!E122+Inputs!E123+Inputs!E124))*Cover!E6 | F26: =((Inputs!F35*(1-Inputs!F44))-('Direct COGS'!M39+'Indirect COGS'!M20)-((Inputs!F108+Inputs!F109+Inputs!F110+Inputs!F112+Inputs!F113+Inputs!F114)*(Inputs!F35*(1-Inputs!F44))+Inputs!F111+Inputs!F122+Inputs!F123+Inputs!F124))*Cover!F6 | G26: =((Inputs!G35*(1-Inputs!G44))-('Direct COGS'!N39+'Indirect COGS'!N20)-((Inputs!G108+Inputs!G109+Inputs!G110+Inputs!G112+Inputs!G113+Inputs!G114)*(Inputs!G35*(1-Inputs!G44))+Inputs!G111+Inputs!G122+Inputs!G123+Inputs!G124))*Cover!G6 | H26: =((Inputs!H35*(1-Inputs!H44))-('Direct COGS'!O39+'Indirect COGS'!O20)-((Inputs!H108+Inputs!H109+Inputs!H110+Inputs!H112+Inputs!H113+Inputs!H114)*(Inputs!H35*(1-Inputs!H44))+Inputs!H111+Inputs!H122+Inputs!H123+Inputs!H124))*Cover!H6 | I26: =((Inputs!I35*(1-Inputs!I44))-('Direct COGS'!P39+'Indirect COGS'!P20)-((Inputs!I108+Inputs!I109+Inputs!I110+Inputs!I112+Inputs!I113+Inputs!I114)*(Inputs!I35*(1-Inputs!I44))+Inputs!I111+Inputs!I122+Inputs!I123+Inputs!I124))*Cover!I6 | K26: =((Inputs!D35*(1-Inputs!D44))-('Direct COGS'!K39+'Indirect COGS'!K20)-((Inputs!D108+Inputs!D109+Inputs!D110+Inputs!D112+Inputs!D113+Inputs!D114)*(Inputs!D35*(1-Inputs!D44))+Inputs!D111+Inputs!D122+Inputs!D123+Inputs!D124))*Inputs!D10 | L26: =((Inputs!E35*(1-Inputs!E44))-('Direct COGS'!L39+'Indirect COGS'!L20)-((Inputs!E108+Inputs!E109+Inputs!E110+Inputs!E112+Inputs!E113+Inputs!E114)*(Inputs!E35*(1-Inputs!E44))+Inputs!E111+Inputs!E122+Inputs!E123+Inputs!E124))*Inputs!E10 | M26: =((Inputs!F35*(1-Inputs!F44))-('Direct COGS'!M39+'Indirect COGS'!M20)-((Inputs!F108+Inputs!F109+Inputs!F110+Inputs!F112+Inputs!F113+Inputs!F114)*(Inputs!F35*(1-Inputs!F44))+Inputs!F111+Inputs!F122+Inputs!F123+Inputs!F124))*Inputs!F10 | N26: =((Inputs!G35*(1-Inputs!G44))-('Direct COGS'!N39+'Indirect COGS'!N20)-((Inputs!G108+Inputs!G109+Inputs!G110+Inputs!G112+Inputs!G113+Inputs!G114)*(Inputs!G35*(1-Inputs!G44))+Inputs!G111+Inputs!G122+Inputs!G123+Inputs!G124))*Inputs!G10 | O26: =((Inputs!H35*(1-Inputs!H44))-('Direct COGS'!O39+'Indirect COGS'!O20)-((Inputs!H108+Inputs!H109+Inputs!H110+Inputs!H112+Inputs!H113+Inputs!H114)*(Inputs!H35*(1-Inputs!H44))+Inputs!H111+Inputs!H122+Inputs!H123+Inputs!H124))*Inputs!H10 | P26: =((Inputs!I35*(1-Inputs!I44))-('Direct COGS'!P39+'Indirect COGS'!P20)-((Inputs!I108+Inputs!I109+Inputs!I110+Inputs!I112+Inputs!I113+Inputs!I114)*(Inputs!I35*(1-Inputs!I44))+Inputs!I111+Inputs!I122+Inputs!I123+Inputs!I124))*Inputs!I10
A27: CAAP % | D27: =IFERROR(((Inputs!D35*(1-Inputs!D44))-('Direct COGS'!K39+'Indirect COGS'!K20)-((Inputs!D108+Inputs!D109+Inputs!D110+Inputs!D112+Inputs!D113+Inputs!D114)*(Inputs!D35*(1-Inputs!D44))+Inputs!D111+Inputs!D122+Inputs!D123+Inputs!D124))/(Inputs!D35*(1-Inputs!D44)),0) | E27: =IFERROR(((Inputs!E35*(1-Inputs!E44))-('Direct COGS'!L39+'Indirect COGS'!L20)-((Inputs!E108+Inputs!E109+Inputs!E110+Inputs!E112+Inputs!E113+Inputs!E114)*(Inputs!E35*(1-Inputs!E44))+Inputs!E111+Inputs!E122+Inputs!E123+Inputs!E124))/(Inputs!E35*(1-Inputs!E44)),0) | F27: =IFERROR(((Inputs!F35*(1-Inputs!F44))-('Direct COGS'!M39+'Indirect COGS'!M20)-((Inputs!F108+Inputs!F109+Inputs!F110+Inputs!F112+Inputs!F113+Inputs!F114)*(Inputs!F35*(1-Inputs!F44))+Inputs!F111+Inputs!F122+Inputs!F123+Inputs!F124))/(Inputs!F35*(1-Inputs!F44)),0) | G27: =IFERROR(((Inputs!G35*(1-Inputs!G44))-('Direct COGS'!N39+'Indirect COGS'!N20)-((Inputs!G108+Inputs!G109+Inputs!G110+Inputs!G112+Inputs!G113+Inputs!G114)*(Inputs!G35*(1-Inputs!G44))+Inputs!G111+Inputs!G122+Inputs!G123+Inputs!G124))/(Inputs!G35*(1-Inputs!G44)),0) | H27: =IFERROR(((Inputs!H35*(1-Inputs!H44))-('Direct COGS'!O39+'Indirect COGS'!O20)-((Inputs!H108+Inputs!H109+Inputs!H110+Inputs!H112+Inputs!H113+Inputs!H114)*(Inputs!H35*(1-Inputs!H44))+Inputs!H111+Inputs!H122+Inputs!H123+Inputs!H124))/(Inputs!H35*(1-Inputs!H44)),0) | I27: =IFERROR(((Inputs!I35*(1-Inputs!I44))-('Direct COGS'!P39+'Indirect COGS'!P20)-((Inputs!I108+Inputs!I109+Inputs!I110+Inputs!I112+Inputs!I113+Inputs!I114)*(Inputs!I35*(1-Inputs!I44))+Inputs!I111+Inputs!I122+Inputs!I123+Inputs!I124))/(Inputs!I35*(1-Inputs!I44)),0) | K27: =D27 | L27: =E27 | M27: =F27 | N27: =G27 | O27: =H27 | P27: =I27
A29: Tax
A30: Income tax | D30: =(MAX(0,((Inputs!D35*(1-Inputs!D44))-('Direct COGS'!K39+'Indirect COGS'!K20)-((Inputs!D108+Inputs!D109+Inputs!D110+Inputs!D112+Inputs!D113+Inputs!D114)*(Inputs!D35*(1-Inputs!D44))+Inputs!D111+Inputs!D122+Inputs!D123+Inputs!D124)))*Inputs!D27)*Cover!D6 | E30: =(MAX(0,((Inputs!E35*(1-Inputs!E44))-('Direct COGS'!L39+'Indirect COGS'!L20)-((Inputs!E108+Inputs!E109+Inputs!E110+Inputs!E112+Inputs!E113+Inputs!E114)*(Inputs!E35*(1-Inputs!E44))+Inputs!E111+Inputs!E122+Inputs!E123+Inputs!E124)))*Inputs!E27)*Cover!E6 | F30: =(MAX(0,((Inputs!F35*(1-Inputs!F44))-('Direct COGS'!M39+'Indirect COGS'!M20)-((Inputs!F108+Inputs!F109+Inputs!F110+Inputs!F112+Inputs!F113+Inputs!F114)*(Inputs!F35*(1-Inputs!F44))+Inputs!F111+Inputs!F122+Inputs!F123+Inputs!F124)))*Inputs!F27)*Cover!F6 | G30: =(MAX(0,((Inputs!G35*(1-Inputs!G44))-('Direct COGS'!N39+'Indirect COGS'!N20)-((Inputs!G108+Inputs!G109+Inputs!G110+Inputs!G112+Inputs!G113+Inputs!G114)*(Inputs!G35*(1-Inputs!G44))+Inputs!G111+Inputs!G122+Inputs!G123+Inputs!G124)))*Inputs!G27)*Cover!G6 | H30: =(MAX(0,((Inputs!H35*(1-Inputs!H44))-('Direct COGS'!O39+'Indirect COGS'!O20)-((Inputs!H108+Inputs!H109+Inputs!H110+Inputs!H112+Inputs!H113+Inputs!H114)*(Inputs!H35*(1-Inputs!H44))+Inputs!H111+Inputs!H122+Inputs!H123+Inputs!H124)))*Inputs!H27)*Cover!H6 | I30: =(MAX(0,((Inputs!I35*(1-Inputs!I44))-('Direct COGS'!P39+'Indirect COGS'!P20)-((Inputs!I108+Inputs!I109+Inputs!I110+Inputs!I112+Inputs!I113+Inputs!I114)*(Inputs!I35*(1-Inputs!I44))+Inputs!I111+Inputs!I122+Inputs!I123+Inputs!I124)))*Inputs!I27)*Cover!I6 | K30: =(MAX(0,((Inputs!D35*(1-Inputs!D44))-('Direct COGS'!K39+'Indirect COGS'!K20)-((Inputs!D108+Inputs!D109+Inputs!D110+Inputs!D112+Inputs!D113+Inputs!D114)*(Inputs!D35*(1-Inputs!D44))+Inputs!D111+Inputs!D122+Inputs!D123+Inputs!D124)))*Inputs!D27)*Inputs!D10 | L30: =(MAX(0,((Inputs!E35*(1-Inputs!E44))-('Direct COGS'!L39+'Indirect COGS'!L20)-((Inputs!E108+Inputs!E109+Inputs!E110+Inputs!E112+Inputs!E113+Inputs!E114)*(Inputs!E35*(1-Inputs!E44))+Inputs!E111+Inputs!E122+Inputs!E123+Inputs!E124)))*Inputs!E27)*Inputs!E10 | M30: =(MAX(0,((Inputs!F35*(1-Inputs!F44))-('Direct COGS'!M39+'Indirect COGS'!M20)-((Inputs!F108+Inputs!F109+Inputs!F110+Inputs!F112+Inputs!F113+Inputs!F114)*(Inputs!F35*(1-Inputs!F44))+Inputs!F111+Inputs!F122+Inputs!F123+Inputs!F124)))*Inputs!F27)*Inputs!F10 | N30: =(MAX(0,((Inputs!G35*(1-Inputs!G44))-('Direct COGS'!N39+'Indirect COGS'!N20)-((Inputs!G108+Inputs!G109+Inputs!G110+Inputs!G112+Inputs!G113+Inputs!G114)*(Inputs!G35*(1-Inputs!G44))+Inputs!G111+Inputs!G122+Inputs!G123+Inputs!G124)))*Inputs!G27)*Inputs!G10 | O30: =(MAX(0,((Inputs!H35*(1-Inputs!H44))-('Direct COGS'!O39+'Indirect COGS'!O20)-((Inputs!H108+Inputs!H109+Inputs!H110+Inputs!H112+Inputs!H113+Inputs!H114)*(Inputs!H35*(1-Inputs!H44))+Inputs!H111+Inputs!H122+Inputs!H123+Inputs!H124)))*Inputs!H27)*Inputs!H10 | P30: =(MAX(0,((Inputs!I35*(1-Inputs!I44))-('Direct COGS'!P39+'Indirect COGS'!P20)-((Inputs!I108+Inputs!I109+Inputs!I110+Inputs!I112+Inputs!I113+Inputs!I114)*(Inputs!I35*(1-Inputs!I44))+Inputs!I111+Inputs!I122+Inputs!I123+Inputs!I124)))*Inputs!I27)*Inputs!I10
A31: Profit After Tax (PAT) | D31: =(((Inputs!D35*(1-Inputs!D44))-('Direct COGS'!K39+'Indirect COGS'!K20)-((Inputs!D108+Inputs!D109+Inputs!D110+Inputs!D112+Inputs!D113+Inputs!D114)*(Inputs!D35*(1-Inputs!D44))+Inputs!D111+Inputs!D122+Inputs!D123+Inputs!D124))-MAX(0,((Inputs!D35*(1-Inputs!D44))-('Direct COGS'!K39+'Indirect COGS'!K20)-((Inputs!D108+Inputs!D109+Inputs!D110+Inputs!D112+Inputs!D113+Inputs!D114)*(Inputs!D35*(1-Inputs!D44))+Inputs!D111+Inputs!D122+Inputs!D123+Inputs!D124)))*Inputs!D27)*Cover!D6 | E31: =(((Inputs!E35*(1-Inputs!E44))-('Direct COGS'!L39+'Indirect COGS'!L20)-((Inputs!E108+Inputs!E109+Inputs!E110+Inputs!E112+Inputs!E113+Inputs!E114)*(Inputs!E35*(1-Inputs!E44))+Inputs!E111+Inputs!E122+Inputs!E123+Inputs!E124))-MAX(0,((Inputs!E35*(1-Inputs!E44))-('Direct COGS'!L39+'Indirect COGS'!L20)-((Inputs!E108+Inputs!E109+Inputs!E110+Inputs!E112+Inputs!E113+Inputs!E114)*(Inputs!E35*(1-Inputs!E44))+Inputs!E111+Inputs!E122+Inputs!E123+Inputs!E124)))*Inputs!E27)*Cover!E6 | F31: =(((Inputs!F35*(1-Inputs!F44))-('Direct COGS'!M39+'Indirect COGS'!M20)-((Inputs!F108+Inputs!F109+Inputs!F110+Inputs!F112+Inputs!F113+Inputs!F114)*(Inputs!F35*(1-Inputs!F44))+Inputs!F111+Inputs!F122+Inputs!F123+Inputs!F124))-MAX(0,((Inputs!F35*(1-Inputs!F44))-('Direct COGS'!M39+'Indirect COGS'!M20)-((Inputs!F108+Inputs!F109+Inputs!F110+Inputs!F112+Inputs!F113+Inputs!F114)*(Inputs!F35*(1-Inputs!F44))+Inputs!F111+Inputs!F122+Inputs!F123+Inputs!F124)))*Inputs!F27)*Cover!F6 | G31: =(((Inputs!G35*(1-Inputs!G44))-('Direct COGS'!N39+'Indirect COGS'!N20)-((Inputs!G108+Inputs!G109+Inputs!G110+Inputs!G112+Inputs!G113+Inputs!G114)*(Inputs!G35*(1-Inputs!G44))+Inputs!G111+Inputs!G122+Inputs!G123+Inputs!G124))-MAX(0,((Inputs!G35*(1-Inputs!G44))-('Direct COGS'!N39+'Indirect COGS'!N20)-((Inputs!G108+Inputs!G109+Inputs!G110+Inputs!G112+Inputs!G113+Inputs!G114)*(Inputs!G35*(1-Inputs!G44))+Inputs!G111+Inputs!G122+Inputs!G123+Inputs!G124)))*Inputs!G27)*Cover!G6 | H31: =(((Inputs!H35*(1-Inputs!H44))-('Direct COGS'!O39+'Indirect COGS'!O20)-((Inputs!H108+Inputs!H109+Inputs!H110+Inputs!H112+Inputs!H113+Inputs!H114)*(Inputs!H35*(1-Inputs!H44))+Inputs!H111+Inputs!H122+Inputs!H123+Inputs!H124))-MAX(0,((Inputs!H35*(1-Inputs!H44))-('Direct COGS'!O39+'Indirect COGS'!O20)-((Inputs!H108+Inputs!H109+Inputs!H110+Inputs!H112+Inputs!H113+Inputs!H114)*(Inputs!H35*(1-Inputs!H44))+Inputs!H111+Inputs!H122+Inputs!H123+Inputs!H124)))*Inputs!H27)*Cover!H6 | I31: =(((Inputs!I35*(1-Inputs!I44))-('Direct COGS'!P39+'Indirect COGS'!P20)-((Inputs!I108+Inputs!I109+Inputs!I110+Inputs!I112+Inputs!I113+Inputs!I114)*(Inputs!I35*(1-Inputs!I44))+Inputs!I111+Inputs!I122+Inputs!I123+Inputs!I124))-MAX(0,((Inputs!I35*(1-Inputs!I44))-('Direct COGS'!P39+'Indirect COGS'!P20)-((Inputs!I108+Inputs!I109+Inputs!I110+Inputs!I112+Inputs!I113+Inputs!I114)*(Inputs!I35*(1-Inputs!I44))+Inputs!I111+Inputs!I122+Inputs!I123+Inputs!I124)))*Inputs!I27)*Cover!I6 | K31: =(((Inputs!D35*(1-Inputs!D44))-('Direct COGS'!K39+'Indirect COGS'!K20)-((Inputs!D108+Inputs!D109+Inputs!D110+Inputs!D112+Inputs!D113+Inputs!D114)*(Inputs!D35*(1-Inputs!D44))+Inputs!D111+Inputs!D122+Inputs!D123+Inputs!D124))-MAX(0,((Inputs!D35*(1-Inputs!D44))-('Direct COGS'!K39+'Indirect COGS'!K20)-((Inputs!D108+Inputs!D109+Inputs!D110+Inputs!D112+Inputs!D113+Inputs!D114)*(Inputs!D35*(1-Inputs!D44))+Inputs!D111+Inputs!D122+Inputs!D123+Inputs!D124)))*Inputs!D27)*Inputs!D10 | L31: =(((Inputs!E35*(1-Inputs!E44))-('Direct COGS'!L39+'Indirect COGS'!L20)-((Inputs!E108+Inputs!E109+Inputs!E110+Inputs!E112+Inputs!E113+Inputs!E114)*(Inputs!E35*(1-Inputs!E44))+Inputs!E111+Inputs!E122+Inputs!E123+Inputs!E124))-MAX(0,((Inputs!E35*(1-Inputs!E44))-('Direct COGS'!L39+'Indirect COGS'!L20)-((Inputs!E108+Inputs!E109+Inputs!E110+Inputs!E112+Inputs!E113+Inputs!E114)*(Inputs!E35*(1-Inputs!E44))+Inputs!E111+Inputs!E122+Inputs!E123+Inputs!E124)))*Inputs!E27)*Inputs!E10 | M31: =(((Inputs!F35*(1-Inputs!F44))-('Direct COGS'!M39+'Indirect COGS'!M20)-((Inputs!F108+Inputs!F109+Inputs!F110+Inputs!F112+Inputs!F113+Inputs!F114)*(Inputs!F35*(1-Inputs!F44))+Inputs!F111+Inputs!F122+Inputs!F123+Inputs!F124))-MAX(0,((Inputs!F35*(1-Inputs!F44))-('Direct COGS'!M39+'Indirect COGS'!M20)-((Inputs!F108+Inputs!F109+Inputs!F110+Inputs!F112+Inputs!F113+Inputs!F114)*(Inputs!F35*(1-Inputs!F44))+Inputs!F111+Inputs!F122+Inputs!F123+Inputs!F124)))*Inputs!F27)*Inputs!F10 | N31: =(((Inputs!G35*(1-Inputs!G44))-('Direct COGS'!N39+'Indirect COGS'!N20)-((Inputs!G108+Inputs!G109+Inputs!G110+Inputs!G112+Inputs!G113+Inputs!G114)*(Inputs!G35*(1-Inputs!G44))+Inputs!G111+Inputs!G122+Inputs!G123+Inputs!G124))-MAX(0,((Inputs!G35*(1-Inputs!G44))-('Direct COGS'!N39+'Indirect COGS'!N20)-((Inputs!G108+Inputs!G109+Inputs!G110+Inputs!G112+Inputs!G113+Inputs!G114)*(Inputs!G35*(1-Inputs!G44))+Inputs!G111+Inputs!G122+Inputs!G123+Inputs!G124)))*Inputs!G27)*Inputs!G10 | O31: =(((Inputs!H35*(1-Inputs!H44))-('Direct COGS'!O39+'Indirect COGS'!O20)-((Inputs!H108+Inputs!H109+Inputs!H110+Inputs!H112+Inputs!H113+Inputs!H114)*(Inputs!H35*(1-Inputs!H44))+Inputs!H111+Inputs!H122+Inputs!H123+Inputs!H124))-MAX(0,((Inputs!H35*(1-Inputs!H44))-('Direct COGS'!O39+'Indirect COGS'!O20)-((Inputs!H108+Inputs!H109+Inputs!H110+Inputs!H112+Inputs!H113+Inputs!H114)*(Inputs!H35*(1-Inputs!H44))+Inputs!H111+Inputs!H122+Inputs!H123+Inputs!H124)))*Inputs!H27)*Inputs!H10 | P31: =(((Inputs!I35*(1-Inputs!I44))-('Direct COGS'!P39+'Indirect COGS'!P20)-((Inputs!I108+Inputs!I109+Inputs!I110+Inputs!I112+Inputs!I113+Inputs!I114)*(Inputs!I35*(1-Inputs!I44))+Inputs!I111+Inputs!I122+Inputs!I123+Inputs!I124))-MAX(0,((Inputs!I35*(1-Inputs!I44))-('Direct COGS'!P39+'Indirect COGS'!P20)-((Inputs!I108+Inputs!I109+Inputs!I110+Inputs!I112+Inputs!I113+Inputs!I114)*(Inputs!I35*(1-Inputs!I44))+Inputs!I111+Inputs!I122+Inputs!I123+Inputs!I124)))*Inputs!I27)*Inputs!I10
A32: Net Margin % | D32: =IFERROR((((Inputs!D35*(1-Inputs!D44))-('Direct COGS'!K39+'Indirect COGS'!K20)-((Inputs!D108+Inputs!D109+Inputs!D110+Inputs!D112+Inputs!D113+Inputs!D114)*(Inputs!D35*(1-Inputs!D44))+Inputs!D111+Inputs!D122+Inputs!D123+Inputs!D124))-MAX(0,((Inputs!D35*(1-Inputs!D44))-('Direct COGS'!K39+'Indirect COGS'!K20)-((Inputs!D108+Inputs!D109+Inputs!D110+Inputs!D112+Inputs!D113+Inputs!D114)*(Inputs!D35*(1-Inputs!D44))+Inputs!D111+Inputs!D122+Inputs!D123+Inputs!D124)))*Inputs!D27)/(Inputs!D35*(1-Inputs!D44)),0) | E32: =IFERROR((((Inputs!E35*(1-Inputs!E44))-('Direct COGS'!L39+'Indirect COGS'!L20)-((Inputs!E108+Inputs!E109+Inputs!E110+Inputs!E112+Inputs!E113+Inputs!E114)*(Inputs!E35*(1-Inputs!E44))+Inputs!E111+Inputs!E122+Inputs!E123+Inputs!E124))-MAX(0,((Inputs!E35*(1-Inputs!E44))-('Direct COGS'!L39+'Indirect COGS'!L20)-((Inputs!E108+Inputs!E109+Inputs!E110+Inputs!E112+Inputs!E113+Inputs!E114)*(Inputs!E35*(1-Inputs!E44))+Inputs!E111+Inputs!E122+Inputs!E123+Inputs!E124)))*Inputs!E27)/(Inputs!E35*(1-Inputs!E44)),0) | F32: =IFERROR((((Inputs!F35*(1-Inputs!F44))-('Direct COGS'!M39+'Indirect COGS'!M20)-((Inputs!F108+Inputs!F109+Inputs!F110+Inputs!F112+Inputs!F113+Inputs!F114)*(Inputs!F35*(1-Inputs!F44))+Inputs!F111+Inputs!F122+Inputs!F123+Inputs!F124))-MAX(0,((Inputs!F35*(1-Inputs!F44))-('Direct COGS'!M39+'Indirect COGS'!M20)-((Inputs!F108+Inputs!F109+Inputs!F110+Inputs!F112+Inputs!F113+Inputs!F114)*(Inputs!F35*(1-Inputs!F44))+Inputs!F111+Inputs!F122+Inputs!F123+Inputs!F124)))*Inputs!F27)/(Inputs!F35*(1-Inputs!F44)),0) | G32: =IFERROR((((Inputs!G35*(1-Inputs!G44))-('Direct COGS'!N39+'Indirect COGS'!N20)-((Inputs!G108+Inputs!G109+Inputs!G110+Inputs!G112+Inputs!G113+Inputs!G114)*(Inputs!G35*(1-Inputs!G44))+Inputs!G111+Inputs!G122+Inputs!G123+Inputs!G124))-MAX(0,((Inputs!G35*(1-Inputs!G44))-('Direct COGS'!N39+'Indirect COGS'!N20)-((Inputs!G108+Inputs!G109+Inputs!G110+Inputs!G112+Inputs!G113+Inputs!G114)*(Inputs!G35*(1-Inputs!G44))+Inputs!G111+Inputs!G122+Inputs!G123+Inputs!G124)))*Inputs!G27)/(Inputs!G35*(1-Inputs!G44)),0) | H32: =IFERROR((((Inputs!H35*(1-Inputs!H44))-('Direct COGS'!O39+'Indirect COGS'!O20)-((Inputs!H108+Inputs!H109+Inputs!H110+Inputs!H112+Inputs!H113+Inputs!H114)*(Inputs!H35*(1-Inputs!H44))+Inputs!H111+Inputs!H122+Inputs!H123+Inputs!H124))-MAX(0,((Inputs!H35*(1-Inputs!H44))-('Direct COGS'!O39+'Indirect COGS'!O20)-((Inputs!H108+Inputs!H109+Inputs!H110+Inputs!H112+Inputs!H113+Inputs!H114)*(Inputs!H35*(1-Inputs!H44))+Inputs!H111+Inputs!H122+Inputs!H123+Inputs!H124)))*Inputs!H27)/(Inputs!H35*(1-Inputs!H44)),0) | I32: =IFERROR((((Inputs!I35*(1-Inputs!I44))-('Direct COGS'!P39+'Indirect COGS'!P20)-((Inputs!I108+Inputs!I109+Inputs!I110+Inputs!I112+Inputs!I113+Inputs!I114)*(Inputs!I35*(1-Inputs!I44))+Inputs!I111+Inputs!I122+Inputs!I123+Inputs!I124))-MAX(0,((Inputs!I35*(1-Inputs!I44))-('Direct COGS'!P39+'Indirect COGS'!P20)-((Inputs!I108+Inputs!I109+Inputs!I110+Inputs!I112+Inputs!I113+Inputs!I114)*(Inputs!I35*(1-Inputs!I44))+Inputs!I111+Inputs!I122+Inputs!I123+Inputs!I124)))*Inputs!I27)/(Inputs!I35*(1-Inputs!I44)),0) | K32: =D32 | L32: =E32 | M32: =F32 | N32: =G32 | O32: =H32 | P32: =I32
