Workbook

Sheet Summary
A1: Whole Foods Market UK — Research Workbook
A2: Figures reflect research completed June 2026 and have not been refreshed since. Workbook prepared 23 Oct 2026. See Read Me for conventions and caveats.
A4: Key metric | B4: Value | C4: Basis (green values link to the tab named)
A5: Revenue, FY2025 (£m) | B5: =Financials!F5 -> 88.3 | C5: Financials — Companies House accounts via The Grocer
A6: Revenue growth, FY2025 | B6: =Financials!F6 -> 0.021990741 | C6: Financials — after King's Road opened Mar 2025
A7: Pre-tax loss, FY2025 (£m) | B7: =Financials!F8 -> 19.4 | C7: Financials
A8: Pre-tax loss as % of revenue, FY2025 | B8: =Financials!F10 -> 0.21970555 | C8: Financials
A9: Gross margin, FY2025 | B9: =Financials!F11 -> 0.31 | C9: Financials — down from 35% in FY2023
A10: Cumulative pre-tax losses since 2004, floor (£m) | B10: =Financials!B23 -> 219.4 | C10: Financials — >£200m through FY2024 plus FY2025 loss
A11: Loss narrowing, FY2022 to FY2025 (£m) | B11: =Financials!B25 -> 6.9 | C11: Financials
A12: Illustrative years to breakeven at that pace | B12: =Financials!B27 -> 8.4347826 | C12: Financials — straight-line extrapolation, not a forecast
A13: UK stores open (June 2026) | B13: =Stores!L4 -> 12 | C13: Stores — all in Greater London
A14: of which Daily Shop format | B14: =Stores!L5 -> 6 | C14: Stores
A15: of which former Amazon Fresh sites | B15: =Stores!L6 -> 5 | C15: Stores
A16: Estate growth vs end of FY2025 | B16: =Stores!L9 -> 1 | C16: Stores
A17: Aldi + Lidl combined UK grocery share | B17: =Competitors!B15 -> 0.178 | C17: Competitors — Kantar
A18: Waitrose basket premium over Aldi (Which?, Dec 2024) | B18: =Competitors!B21 -> 0.29454582 | C18: Competitors
A19: UK organic market, 2024 (£bn) | B19: =Market!B6 -> 3.7 | C19: Market — Soil Association
A21: Key takeaways
A22: 1. Never profitable in the UK since entering in 2004; losses have narrowed four years running but remain about a fifth of revenue.
A23: 2. Amazon doubled the estate to 12 London stores in Apr–Jun 2026 using the small Daily Shop format, five of them in former Amazon Fresh sites.
A24: 3. The value gap is the core problem: shoppers rate Whole Foods dearer than Waitrose, already the UK's most expensive supermarket.
A25: 4. Gross margin is being squeezed (35% to 31%) by supply chain, Brexit friction and staffing costs.
A26: 5. Tailwind: UK organic demand keeps growing (£3.7bn in 2024, 13th straight year), but every major grocer now sells organic.
A27: 6. The 2026 test: whether convenience-sized stores plus Amazon same-day delivery can lift sales density enough to close the loss.
A29: Tabs
A30: Tab | C30: Contents
A31: Read Me | C31: Purpose, colour conventions, caveats and corrections
A32: Financials | C32: FY2021–FY2025 P&L, ratios, cumulative losses, breakeven illustration
A33: Stores | C33: All 12 open stores with addresses and opening dates, closed sites, estate counts
A34: Competitors | C34: Market shares, positioning, price benchmark, value perception, rivals
A35: Market | C35: UK organic market size, growth and channel split
A36: Timeline | C36: Dated events 2004–2026
A37: Products | C37: UK vs US assortment, UK staples added, named UK suppliers, Brand Pitch Day
A38: Customers | C38: Demographic and psychographic indicators, with geographic scope flagged
A39: Sustainability | C39: Sourcing standards and environmental commitments
A40: Outlook | C40: Tailwinds, headwinds and risks
A41: Sources | C41: Source list with URLs

Sheet Read Me
A1: Read Me
A2: How to read and update this workbook
A4: Purpose
A5: What this is | B5: Structured data behind whole-foods-uk-report.md (same repository): Whole Foods Market's UK business — footprint, financials, customers, products, pricing, competitors, sustainability and outlook.
A6: As of | B6: Research completed June 2026. Nothing has been refreshed since; store status and market shares may have moved.
A8: Colour conventions
A9: Blue text | B9: Hardcoded inputs taken from a source. Edit these to update the workbook.
A10: Black text | B10: Formulas, or plain descriptive text.
A11: Green text | B11: Formulas linking to another tab.
A12: Yellow-cream fill | B12: A caveat or correction worth reading before you use the number.
A14: Caveats and corrections
A15: Cumulative losses | B15: CORRECTION: an earlier draft of the report said 'more than £240m'. The source (The Grocer, Sept 2025, FY2024 accounts) says more than £200m through FY2024. Adding the FY2025 loss of £19.4m gives a floor of about £219m. The report has been corrected and Financials!B23 now computes the figure.
A16: Source access | B16: Most UK trade press (The Grocer, Retail Week, Retail Gazette) blocked direct fetching. Figures come from search result extracts, corroborated across two or more outlets wherever possible.
A17: Customer data | B17: No UK-specific Whole Foods shopper data is public (Kantar, Mintel and Numerator UK are paywalled). Customer indicators are US/global Whole Foods data or UK organic-market proxies; the Scope column on Customers flags which.
A18: Gross margin | B18: The FY2023 35% figure comes from a single outlet; FY2024 (32%) is inferred from the reported 1-point fall to 31% in FY2025.
A19: Organic market base | B19: The 2023 market was first reported as £3.2bn, but the 2024 figure (£3.7bn, +7.3%) implies a restated 2023 base of about £3.45bn. Market tab column D shows the implied base. The 2025 figure (£3.9bn) is single-source.
A20: Private label name | B20: The claim that '365' cannot be used in the UK because of a prior trademark, so UK stores use 'Fresh & Wild Everyday Value', rests on one source (Supermarket News) and was not independently confirmed.
A21: Store opening years | B21: Opening years for legacy London stores were not verified, except Kensington (June 2007, widely reported but not re-checked here). Daily Shop opening dates are from the March 2026 Whole Foods announcement.
A22: Market shares | B22: Kantar shares are approximate and their periods differ (2024 to Sept 2025). Treat them as directional.
A23: Outlook ratings | B23: Impact ratings on the Outlook tab are analyst judgment, not sourced figures.
A25: Updating
A26: New accounts | B26: Add a column to Financials and update the cell references on Summary. Every ratio row is a formula, so copy the formulas across rather than typing values.

Sheet Financials
A1: UK Financial Performance
A2: Whole Foods Market UK (filed at Companies House as Fresh & Wild). £ millions unless stated. Financial years to 31 December.
A4: Metric | B4: FY2021 | C4: FY2022 | D4: FY2023 | E4: FY2024 | F4: FY2025 | G4: Notes / source
A5: Revenue (£m) | C5: 91.6 | D5: 93.1 | E5: 86.4 | F5: 88.3 | G5: The Grocer, Retail Gazette, Retail Week from Companies House filings. FY2024 includes Fulham and Richmond only to 10 Jun 2024.
A6: Revenue growth, YoY | C6: -0.03 | D6: =IFERROR(D5/C5-1,"") -> 0.016375546 | E6: =IFERROR(E5/D5-1,"") -> -0.071965628 | F6: =IFERROR(F5/E5-1,"") -> 0.021990741 | G6: FY2022 is the reported -3% (FY2021 revenue not captured); later years calculated.
A7: Revenue change (£m) | D7: =D5-C5 -> 1.5 | E7: =E5-D5 -> -6.7 | F7: =F5-E5 -> 1.9 | G7: Calculated
A8: Pre-tax loss (£m) | B8: 17.2 | C8: 26.3 | D8: 23.1 | E8: 20 | F8: 19.4 | G8: Shown as positive numbers. FY2021 £17.2m from The Grocer's report that FY2022 losses rose 53%.
A9: Pre-tax loss change, YoY | C9: =IFERROR(C8/B8-1,"") -> 0.52906977 | D9: =IFERROR(D8/C8-1,"") -> -0.121673 | E9: =IFERROR(E8/D8-1,"") -> -0.13419913 | F9: =IFERROR(F8/E8-1,"") -> -0.03 | G9: Calculated; negative means the loss narrowed
A10: Pre-tax loss as % of revenue | C10: =IFERROR(C8/C5,"") -> 0.2871179 | D10: =IFERROR(D8/D5,"") -> 0.2481203 | E10: =IFERROR(E8/E5,"") -> 0.23148148 | F10: =IFERROR(F8/F5,"") -> 0.21970555 | G10: Calculated
A11: Gross margin | D11: 0.35 | E11: 0.32 | F11: 0.31 | G11: FY2023 single source; FY2025 31% reported as down 1 point, so FY2024 = 32%. UK grocery norm is about 26%.
A12: Gross margin change (points) | E12: =E11-D11 -> -0.03 | F12: =F11-E11 -> -0.01 | G12: Calculated
A13: Average monthly employees | D13: 798 | E13: 608 | G13: Reported in FY2024 accounts
A14: Revenue per employee (£k) | D14: =IFERROR(D5*1000/D13,"") -> 116.66667 | E14: =IFERROR(E5*1000/E13,"") -> 142.10526 | G14: Calculated
A15: Administrative expenses (£m) | E15: 47.7 | G15: Reported as down 14% in FY2024
A16: Onerous lease charge (£m) | E16: 0.35 | F16: 1.5 | G16: Underperforming and closed stores
A17: Stores at year end | C17: 7 | D17: 7 | E17: 5 | F17: 6 | G17: 7 until Fulham and Richmond closed Jun 2024; King's Road opened Mar 2025. Six more opened Apr–Jun 2026 (see Stores).
A18: Revenue per store (£m) | C18: =IFERROR(C5/C17,"") -> 13.085714 | D18: =IFERROR(D5/D17,"") -> 13.3 | E18: =IFERROR(E5/E17,"") -> 17.28 | F18: =IFERROR(F5/F17,"") -> 14.716667 | G18: Calculated on year-end count; FY2024 overstated because closed stores traded half the year
A20: Cumulative losses and trajectory
A21: Reported cumulative pre-tax losses since 2004, through FY2024 (£m, floor) | B21: 200 | G21: The Grocer, Sept 2025: 'more than £200m'. A floor, not an exact total.
A22: Add: FY2025 pre-tax loss (£m) | B22: =F8 -> 19.4 | G22: From row 8
A23: Implied cumulative losses through FY2025 (£m, floor) | B23: =B21+B22 -> 219.4 | G23: Replaces the '£240m' in an earlier report draft, which was not supported by the sources
A24: Combined pre-tax losses FY2022–FY2025 (£m) | B24: =SUM(C8:F8) -> 88.8 | G24: Calculated
A25: Loss narrowing, FY2022 to FY2025 (£m) | B25: =C8-F8 -> 6.9 | G25: Calculated
A26: Average annual narrowing (£m per year) | B26: =B25/3 -> 2.3 | G26: Three year-on-year steps
A27: Illustrative years to breakeven at that pace | B27: =IFERROR(F8/B26,"") -> 8.4347826 | G27: Straight-line extrapolation of the FY2022–25 trend. Illustration only: ignores the 2026 store doubling.

Sheet Stores
A1: UK Store Estate
A2: Status as of June 2026 research. All stores are in Greater London.
A3: Store | B3: Address | C3: Area | D3: Format | E3: Size (sq ft) | F3: Opened | G3: Former Amazon Fresh site? | H3: Status | I3: Notes | K3: Estate summary | L3: Count
A4: Kensington High Street | B4: 63–97 Kensington High St, W8 5SE | C4: Kensington | D4: Full format | E4: 80000 | F4: 2007 | G4: No | H4: Open | I4: UK flagship, three floors; 13 dining venues, 350+ seats, Genji Sushi & Robata | K4: Open stores | L4: =COUNTIF(H4:H15,"Open") -> 12
A5: Piccadilly | B5: 20 Glasshouse St, W1B 5AR | C5: Soho / Piccadilly | D5: Full format | F5: Not verified | G5: No | H5: Open | I5: Highlights 500 UK producers, 34 within 60 miles | K5: Daily Shop format | L5: =COUNTIF(D4:D15,"Daily Shop") -> 6
A6: Camden | B6: 49 Parkway, NW1 7PN | C6: Camden | D6: Full format | F6: Not verified | G6: No | H6: Open | K6: Former Amazon Fresh sites | L6: =COUNTIF(G4:G15,"Yes") -> 5
A7: Stoke Newington | B7: 32–40 Stoke Newington Church St, N16 0LU | C7: Hackney | D7: Full format | F7: Not verified | G7: No | H7: Open | K7: Opened in 2026 | L7: =COUNTIF(F4:F15,">="&DATE(2026,1,1)) -> 6
A8: Clapham Junction | B8: 305–311 Lavender Hill, SW11 1LN | C8: Wandsworth | D8: Full format | F8: Not verified | G8: No | H8: Open | K8: Stores closed in 2024 | L8: =COUNTIF(C20:C22,"Store") -> 2
A9: King's Road | B9: 120 King's Road, Chelsea, SW3 | C9: Chelsea | D9: Mid format | E9: 21800 | F9: 45741 | G9: No | H9: Open | I9: First new UK store in over a decade | K9: Growth vs end of FY2025 | L9: =IFERROR(L4/Financials!F17-1,"") -> 1
A10: Angel | B10: 359 Upper St, N1 0PD | C10: Islington | D10: Daily Shop | F10: 46114 | G10: Yes | H10: Open | I10: Includes an Amazon kiosk; on Deliveroo
A11: Liverpool Street | B11: Unit 4b-5, Blomfield St, EC2M 7BD | C11: City of London | D11: Daily Shop | F11: 46135 | G11: Yes | H11: Open | I11: Commuter hub
A12: Notting Hill Gate | B12: 66–74 Notting Hill Gate, W11 3HT | C12: Notting Hill | D12: Daily Shop | F12: 46156 | G12: Yes | H12: Open
A13: Wood Wharf | B13: 4 Water St, E14 5GX | C13: Canary Wharf | D13: Daily Shop | F13: 46170 | G13: Yes | H13: Open
A14: Monument | B14: Unit 1, 20 Gracechurch St, EC3V 0BG | C14: City of London | D14: Daily Shop | F14: 46177 | G14: Yes | H14: Open
A15: St James's | B15: 57 Victoria St, SW1P 2HX | C15: Westminster | D15: Daily Shop | F15: 46184 | G15: No | H15: Open | I15: The one new-build site among the six 2026 openings
A16: Daily Shop stores are 3,300–10,000 sq ft; per-store sizes were not published.
A18: Closed sites
A19: Site | B19: Location | C19: Type | D19: Closed | E19: Notes
A20: Fulham Broadway | B20: SW6 | C20: Store | D20: 45453 | E20: Closure announced Mar 2024
A21: Richmond | B21: TW9 | C21: Store | D21: 45453 | E21: Fulham and Richmond together: £9.2m sales, £0.2m operating loss in 2024
A22: Dartford | B22: Kent | C22: Distribution centre | D22: 45453 | E22: Closed alongside the two stores
A23: Earlier non-London stores (e.g. Bristol, Glasgow, Cheltenham) closed before 2024; dates not verified in this research. 14 other former Amazon Fresh UK stores closed outright in 2025.

Sheet Competitors
A1: Competitive Landscape
A2: UK grocery shares are approximate (Kantar, periods from 2024 to Sept 2025).
A3: Retailer | B3: UK grocery share | C3: Share basis | D3: Positioning | E3: Core shopper | F3: UK footprint | G3: Notes
A4: Tesco | B4: 0.273 | C4: Kantar 2024/25 | D4: Mainstream leader | E4: Cross-class, cross-age | F4: UK-wide
A5: Sainsbury's | B5: 0.155 | C5: Kantar 2024 (15–16%) | D5: Quality mainstream | E5: ABC1, female-skewed | F5: UK-wide | G5: Widest income gap of the majors (YouGov)
A6: Aldi | B6: 0.101 | C6: Kantar | D6: Discounter | E6: Broad; gaining higher-income shoppers | F6: UK-wide
A7: Lidl | B7: 0.077 | C7: Kantar | D7: Discounter | E7: Broad | F7: UK-wide
A8: Waitrose | B8: 0.045 | C8: Kantar, Sept 2025 | D8: Premium mainstream | E8: 75% ABC1, 46% AB, older | F8: UK-wide, South-heavy | G8: Most expensive UK supermarket all 12 months of 2024 (Which?)
A9: M&S Food | B9: 0.045 | C9: Kantar, Sept 2025 | D9: Premium; food-to-go, own label | E9: ABC1, 45+, adding families | F9: UK-wide plus Ocado | G9: Overtook Waitrose share in Nov 2024, first time outside Christmas
A10: Planet Organic | C10: Not tracked | D10: Specialist, 100% certified organic | E10: Health-first, affluent | F10: c. 8–10 London stores | G10: Administration May 2023; bought back by founders
A11: Daylesford | C11: Not tracked | D11: Ultra-premium; B Corp | E11: Ultra-affluent | F11: London and Cotswolds | G11: Bamford family owned; Green Michelin Star
A12: Whole Foods Market | C12: Not tracked (well under 1%) | D12: Premium natural and organic | E12: LOHAS, urban professionals | F12: 12 London stores | G12: UK revenue £88.3m in FY2025
A14: Calculations
A15: Aldi + Lidl combined share | B15: =B6+B7 -> 0.178
A16: Waitrose + M&S Food combined share | B16: =B8+B9 -> 0.09
A18: Price benchmark: Which? 56-item basket, December 2024
A19: Waitrose basket (£) | B19: 129.83
A20: Aldi basket (£) | B20: 100.29
A21: Waitrose premium over Aldi | B21: =IFERROR(B19/B20-1,"") -> 0.29454582 | C21: UK shoppers on Trustpilot describe Whole Foods as dearer than Waitrose for most items.
A22: Gap per basket (£) | B22: =B19-B20 -> 29.54
A24: Value perception: YouGov BrandIndex value score, 2023
A25: Retailer | B25: Start of 2023 | C25: End of 2023 | D25: Change
A26: Waitrose | B26: -10.3 | C26: -13.2 | D26: =C26-B26 -> -2.9
A27: Aldi | B27: 53 | C27: 55 | D27: =C27-B27 -> 2
A28: Lidl | B28: 48.8 | C28: 50.3 | D28: =C28-B28 -> 1.5
A29: Negative score = more people rate it poor value than good value. Whole Foods is not tracked.
A31: Specialist rival: Daylesford, FY2025
A32: Revenue (£m) | B32: 58
A33: Profit (£m) | B33: 1.3
A34: Profit margin | B34: =IFERROR(B33/B32,"") -> 0.022413793
A35: Revenue vs Whole Foods UK FY2025 | B35: =IFERROR(B32/Financials!F5,"") -> 0.65685164
A37: Customer satisfaction: Net Promoter Score (global, QuestionPro Q1 2025)
A38: Whole Foods Market NPS | B38: 35
A39: Grocery industry average NPS | B39: 37
A40: Gap to average | B40: =B38-B39 -> -2
A41: No UK-specific score is published.

Sheet Market
A1: UK Organic Market
A2: Soil Association Organic Market Reports. £ billions.
A3: Year | B3: Market value (£bn) | C3: Reported growth | D3: Implied prior-year value (£bn) | E3: Notes
A4: 2014 | B4: 1.86 | E4: Baseline
A5: 2023 | B5: 3.2 | C5: 0.02 | D5: =IFERROR(B5/(1+C5),"") -> 3.1372549 | E5: 12th consecutive year of growth (as first reported)
A6: 2024 | B6: 3.7 | C6: 0.073 | D6: =IFERROR(B6/(1+C6),"") -> 3.4482759 | E6: 13th consecutive year; implies 2023 restated to about £3.45bn
A7: 2025 | B7: 3.9 | C7: 0.042 | D7: =IFERROR(B7/(1+C7),"") -> 3.7428023 | E7: 14th consecutive year; single source, not independently verified
A8: Growth 2014 to 2024 | B8: =B6/B4-1 -> 0.98924731 | E8: Roughly doubled in ten years
A10: 2024 channel split
A11: Channel | B11: Value (£bn) | C11: Growth | D11: Share of total
A12: Supermarkets, discounters and online | B12: 2.43 | C12: 0.08 | D12: =IFERROR(B12/$B$16,"") -> 0.65734304
A13: Independent retail | B13: 0.5176 | C13: 0.09 | D13: =IFERROR(B13/$B$16,"") -> 0.14001677
A14: Home delivery (veg boxes etc.) | B14: 0.5409 | C14: 0.03 | D14: =IFERROR(B14/$B$16,"") -> 0.14631969
A15: Foodservice | B15: 0.2082 | C15: 0.065 | D15: =IFERROR(B15/$B$16,"") -> 0.056320502
A16: Total | B16: =SUM(B12:B15) -> 3.6967 | D16: =SUM(D12:D15) -> 1
A17: Difference from headline 2024 figure (£bn) | B17: =B16-B6 -> -0.0033 | E17: Rounding only; the channels reconcile to the £3.7bn headline
A19: Whole Foods UK in context
A20: Whole Foods UK revenue FY2024 as share of UK organic market 2024 | B20: =IFERROR(Financials!E5/(B6*1000),"") -> 0.023351351 | E20: Upper bound: Whole Foods revenue includes non-organic lines

Sheet Timeline
A1: Timeline, 2004–2026
A2: Dated where the day is known; year or month otherwise.
A3: Date | B3: Event | C3: Category
A4: 2004 | B4: Enters the UK by acquiring Fresh & Wild (7 London stores) | C4: Footprint
A5: 2007 | B5: Kensington High Street flagship opens (80,000 sq ft) | C5: Footprint
A6: 42902 | B6: Amazon announces acquisition of Whole Foods Market for $13.7bn | C6: Ownership
A7: 42975 | B7: Acquisition completes | C7: Ownership
A8: Mar 2021 | B8: First UK Amazon Fresh store opens in Ealing (Just Walk Out); estate later reaches 19 | C8: Amazon
A9: 44454 | B9: Amazon/Deliveroo Prime bundle: free Deliveroo Plus on £25+ orders | C9: Online
A10: FY2022 | B10: Pre-tax loss rises 53% to £26.3m as inflation hits demand | C10: Financial
A11: 45140 | B11: Amazon grocery refresh: Whole Foods, Amazon Fresh and Amazon.com baskets begin to merge | C11: Amazon
A12: 2023 | B12: Value push: 'Low Prices, Same High Standards' signage, new opening price points | C12: Pricing
A13: Mar 2024 | B13: 141 mainstream UK staples added (Heinz, Marmite, Weetabix and others) | C13: Products
A14: Mar 2024 | B14: Closure of Fulham, Richmond and Dartford DC announced | C14: Footprint
A15: 45453 | B15: Fulham, Richmond and Dartford DC close | C15: Footprint
A16: Jul 2024 | B16: Third-party welfare certification required for all meat by end of 2026 | C16: Sustainability
A17: Sep 2024 | B17: Waitrose price-match launched on branded lines | C17: Pricing
A18: Jan 2025 | B18: Jason Buechel also becomes VP of Amazon Worldwide Grocery Stores | C18: Amazon
A19: 45741 | B19: King's Road, Chelsea opens: first new UK store in over a decade | C19: Footprint
A20: Jun 2025 | B20: 'One Grocery' strategy: Whole Foods and Amazon grocery under single leadership | C20: Amazon
A21: Sep 2025 | B21: FY2024 accounts: cumulative UK losses reported above £200m | C21: Financial
A22: 45923 | B22: All 19 UK Amazon Fresh stores to close; 5 to become Whole Foods | C22: Amazon
A23: Mar 2026 | B23: Six Daily Shop stores announced, doubling the estate | C23: Footprint
A24: 46114 | B24: Angel opens | C24: Footprint
A25: 46135 | B25: Liverpool Street opens | C25: Footprint
A26: 46156 | B26: Notting Hill Gate opens | C26: Footprint
A27: 46170 | B27: Wood Wharf opens | C27: Footprint
A28: 46177 | B28: Monument opens | C28: Footprint
A29: 46184 | B29: St James's opens: estate reaches 12 | C29: Footprint
A30: Jun 2026 | B30: Amazon same-day perishable grocery delivery in Central and East London | C30: Online
A31: 2026 | B31: FY2025 accounts: revenue £88.3m (+2%), pre-tax loss £19.4m | C31: Financial
A32: Dec 2026 | B32: Planned: One Grocery staff transition and meat certification deadline | C32: Upcoming

Sheet Products
A1: Product Mix and Suppliers
A2: UK assortment, how it differs from the US, and named UK suppliers.
A3: Dimension | B3: UK | C3: US
A4: Private label | B4: 'Fresh & Wild Everyday Value' (single source says '365' is blocked by a UK trademark) | C4: 365 by Whole Foods Market, a major category driver
A5: Mainstream staples | B5: 141 British brands added Mar 2024 | C5: No equivalent
A6: CBD | B6: Not sold (FSA Novel Foods rules) | C6: Topical CBD in 30+ states
A7: In-store dining | B7: Kensington food hall: 13 venues, 350+ seats | C7: Prepared food bars
A8: Signature bakery | B8: Brown Butter Cookies; Berry Chantilly Cake arrived at King's Road 2025 | C8: Berry Chantilly Cake
A9: Organic certification | B9: Soil Association, audited annually | C9: USDA Organic
A10: Alcohol age | B10: 18+, Challenge 25 | C10: 21+
A11: Banned ingredients | B11: Same 300+ food list; UK law also bans E171, potassium bromate, ADA | C11: 300+ food list
A13: UK staple brands added, March 2024 (named examples)
A14: Heinz
A15: Marmite
A16: Weetabix
A17: McVitie's Hobnobs
A18: Kellogg's Cornflakes
A19: Twinings
A20: Tropicana
A21: Cathedral City
A22: Colman's
A23: Bonne Maman
A24: Quaker Oats
... A28: Ambrosia
A29: Named here | B29: =COUNTA(A14:A28) -> 15
A30: Total added (reported) | B30: 141
A32: Named UK suppliers
A33: Supplier | B33: Category | C33: Detail
A34: Natoora | B34: Produce | C34: Hampshire regenerative farm; network of 600+ growers
A35: Neal's Yard Dairy | B35: Cheese
A36: Mons | B36: Cheese | C36: European cheese
A37: Ashdale Farm | B37: Beef
A38: Dingley Dell | B38: Pork | C38: Suffolk
A39: Crate to Plate | B39: Produce | C39: London vertical farm; herbs and lettuce, King's Road
A40: Mondo Brewing | B40: Beer | C40: Battersea; exclusive collaboration
A41: Celtic Bakers | B41: Bakery | C41: London
A42: Pourtoi | B42: Bakery | C42: London
A43: Ice Cream Union | B43: Frozen | C43: Bespoke rose and pistachio flavour for King's Road opening
A44: Old Spike Roastery | B44: Coffee | C44: London
A45: Mirabeau | B45: Wine | C45: Exclusive King's Road rosé, regenerative organic certified
...

Sheet Customers
A1: Customer Indicators
A2: No UK-specific Whole Foods shopper data is public. Check the Scope column before using a figure.
A3: Indicator | B3: Value | C3: Scope | D3: Source | E3: Note
A4: LOHAS shoppers' spend in Whole Foods vs other segments | B4: 1.33 | C4: Global / US | D4: Natural Marketing Institute | E4: 133% more
A5: LOHAS shoppers who read labels for simple ingredients | B5: 0.8 | C5: Global / US | D5: Natural Marketing Institute
A6: LOHAS shoppers citing organic range as main store-choice factor | B6: 0.64 | C6: Global / US | D6: Natural Marketing Institute
A7: LOHAS shoppers seeking local or regional products | B7: 0.68 | C7: Global / US | D7: Natural Marketing Institute
A8: US household penetration | B8: 0.33 | C8: US | D8: Numerator 2023–24 | E8: Only about 1 in 10 are core shoppers
A9: Typical US shopper | B9: Millennial woman, 25–34, graduate degree, $80k+ income | C9: US | D9: Numerator via Business Insider
A10: US visits per year | B10: 15 | C10: US | D10: Numerator | E10: About $42 and 9 items per trip
A11: Site selection: degree attainment threshold | B11: 0.45 | C11: US | D11: Company statements (secondary) | E11: Plus household income $75k+
A12: Awareness of '365 by WFM' among UK organic eaters, 2022 | B12: 0.32 | C12: UK | D12: Statista | E12: Brand loyalty among users 71%
A13: UK organic buyers motivated by avoiding pesticides | B13: 0.73 | C13: UK organic market | D13: Soil Association / ORC, Jan 2024
A14: UK organic buyers motivated by higher production standards | B14: 0.69 | C14: UK organic market | D14: Soil Association / ORC
A15: UK 18–24s buying organic at least monthly | B15: 0.42 | C15: UK organic market | D15: Soil Association | E15: Most active age group
A16: UK households buying organic at least occasionally | B16: 0.83 | C16: UK organic market | D16: Wicked Leeks / Riverford
A17: UK organic buyers citing sustainability, 2022 | B17: 0.24 | C17: UK organic market | D17: Soil Association
A18: UK organic buyers citing sustainability, 2023 | B18: 0.33 | C18: UK organic market | D18: Soil Association
A19: Change in sustainability citation (points) | B19: =B18-B17 -> 0.09 | C19: UK organic market | D19: Calculated
A20: Waitrose shoppers in ABC1 grades | B20: 0.75 | C20: UK, Waitrose | D20: Waitrose Media Kit 2023 | E20: Self-published
A21: Waitrose shoppers in AB grades | B21: 0.46 | C21: UK, Waitrose | D21: Waitrose Media Kit 2023 | E21: Self-published
A22: Waitrose basket spend vs grocery average | B22: 0.27 | C22: UK, Waitrose | D22: Waitrose Media Kit 2023
A23: Gen Z supporting climate-smart farming | B23: 0.7 | C23: Global survey | D23: Whole Foods survey, Sep 2024
A24: Gen Z willing to pay more for sustainable products | B24: 0.55 | C24: Global survey | D24: Whole Foods survey, Sep 2024
A25: Gen Z willing to spend more for high-quality food | B25: 0.7 | C25: Global survey | D25: Whole Foods survey, Sep 2024
A26: UK shoppers describing themselves as price-conscious | B26: 0.92 | C26: UK | D26: Pricer (single source) | E26: Treat with caution
A27: UK shopping mission at Whole Foods | B27: Top-up and convenience, not the weekly shop | C27: UK | D27: Trade press

Sheet Sustainability
A1: Sourcing and Sustainability
A2: Commitments that apply to UK stores unless Scope says otherwise.
A3: Area | B3: Commitment | C3: Detail | D3: Deadline / status | E3: Scope
A4: Organic | B4: Soil Association certified organic retailer | C4: Annual independent audit; exceeds the legal baseline | D4: Ongoing | E4: UK
A5: Ingredients | B5: 550+ banned ingredients and substances | C5: Food 300+, supplements 150+, beauty and body care 240+; no hydrogenated fats, HFCS or artificial sweeteners | D5: Ongoing | E5: Global
A6: Seafood | B6: MSC certified wild-caught; Responsibly Farmed standard | C6: No antibiotics, added hormones or synthetic parasiticides; farm traceability. Standards updated May 2024 | D6: Code of Conduct Jan 2025 | E6: Global
A7: Meat | B7: Third-party animal welfare certification for all meat and poultry | C7: Extended Jul 2024 to bison, veal, venison, duck, goose and quail | D7: End of 2026 | E7: Global
A8: Meat | B8: Baseline meat standards | C8: No antibiotics ever, no crates, cages or tethers, no added hormones | D8: Ongoing | E8: Global
A9: Food waste | B9: Halve food waste | C9: About 70% of operational waste kept from landfill today | D9: 2030 | E9: Global
A10: Packaging | B10: 100% of private-label packaging reusable, recyclable or compostable | D10: Target | E10: Global
A11: Agriculture | B11: Prairie Strips programme with Mad Agriculture | C11: About 100 acres of prairie hedgerows on supplier farms | D11: Launched 2024 | E11: Global
A12: Fair trade | B12: Sourced for Good premiums | C12: $9.35m returned to suppliers in 2023; $8.8m in 2024 | D12: Annual | E12: Global
A13: Suppliers | B13: Supplier Code of Conduct | C13: Aligned to UN Guiding Principles and ILO Core Conventions | D13: Updated Jan 2023 | E13: Global
A14: Food waste | B14: Too Good To Go partnership | C14: Surplus food sold through the app | D14: King's Road | E14: UK
A15: Compliance risk | B15: Groceries Supply Code of Practice (GSCOP) | C15: Ranked worst-performing grocer for compliance since 2022, including supplier payment delays | D15: Ongoing risk | E15: UK

Sheet Outlook
A1: Strategic Outlook
A2: Impact ratings are analyst judgment, not sourced figures.
A3: Type | B3: Factor | C3: Evidence | D3: Impact (judgment)
A4: Tailwind | B4: Organic demand growth | C4: £3.7bn in 2024, +7.3%, 13th straight year; organic units growing 4x non-organic | D4: High
A5: Tailwind | B5: Low-cost expansion format | C5: Daily Shop (3,300–10,000 sq ft) reuses Amazon Fresh sites, cutting fit-out and lease risk | D5: High
A6: Tailwind | B6: Amazon ecosystem | C6: Prime, Amazon.co.uk storefront, same-day perishables (sales up 40x since Jan 2025) | D6: Medium
A7: Tailwind | B7: Supplier pipeline | C7: Brand Pitch Day drew 500+ submissions in Q1 2026 | D7: Low
A8: Headwind | B8: Never profitable | C8: Losses every year since 2004; £19.4m in FY2025, about 22% of revenue | D8: High
A9: Headwind | B9: Value perception | C9: Seen as dearer than Waitrose; global NPS 35 vs grocery average 37 | D9: High
A10: Headwind | B10: Margin squeeze | C10: Gross margin 35% to 31% (FY2023–25): supply chain, Brexit friction, staffing | D10: Medium
A11: Headwind | B11: Organic is no longer distinctive | C11: Every major grocer sells organic at scale; discounters hold 17.8% share | D11: Medium
A12: Headwind | B12: London-only footprint | C12: All 12 stores in Greater London; no visible plan beyond it | D12: Medium
A13: Risk | B13: GSCOP compliance | C13: Worst-ranked grocer since 2022; regulatory and supplier-relationship exposure | D13: Medium
A14: Risk | B14: One Grocery integration | C14: Amazon HR, pay and review systems by Dec 2026 could dilute the culture behind the brand | D14: Low
A15: Risk | B15: Private-label handicap | C15: No '365' brand in the UK (single source) limits value signalling | D15: Low

Sheet Sources
A1: Sources
A2: Primary sources behind the figures in this workbook.
A3: # | B3: Title | C3: Publisher | D3: Date | E3: URL
A4: 1 | B4: Whole Foods Market losses in the UK total more than £200m as sales decline | C4: The Grocer | D4: Sep 2025 | E4: https://www.thegrocer.co.uk/news/whole-foods-market-losses-in-the-uk-total-more-than-200m-as-sales-decline/709247.article
A5: 2 | B5: Whole Foods Market losses narrow after new store openings | C5: The Grocer | D5: 2026 | E5: https://www.thegrocer.co.uk/news/whole-foods-market-losses-narrow-after-new-store-openings/719907.article
A6: 3 | B6: Whole Foods Market UK 2023 losses narrow after value push | C6: The Grocer | D6: 2024 | E6: https://www.thegrocer.co.uk/news/whole-foods-market-uk-losses-narrow-after-value-push/696486.article
A7: 4 | B7: Whole Foods Market sees UK losses rise to £26m | C7: The Grocer | D7: 2023 | E7: https://www.thegrocer.co.uk/news/whole-foods-market-sees-uk-losses-rise-to-26m/680536.article
A8: 5 | B8: Whole Foods UK reports loss as sales slide | C8: Retail Gazette | D8: Sep 2025 | E8: https://www.retailgazette.co.uk/blog/2025/09/whole-foods-uk-losses/
A9: 6 | B9: Whole Foods Market to open six new U.K. stores | C9: Whole Foods Market | D9: Mar 2026 | E9: https://www.wholefoodsmarket.com/company-info/newsroom/news-releases/whole-foods-market-to-open-six-new-u-k-stores
A10: 7 | B10: Whole Foods to double UK stores with Daily Shop | C10: Grocery Dive | D10: 2026 | E10: https://www.grocerydive.com/news/whole-foods-market-daily-shop-london-uk-store-openings-small-format/814557/
A11: 8 | B11: Amazon closing all UK Amazon Fresh stores, converting five to Whole Foods | C11: Chain Store Age | D11: Sep 2025 | E11: https://chainstoreage.com/amazon-closing-all-uk-amazon-fresh-stores-converting-five-whole-foods
A12: 9 | B12: Amazon UK online grocery delivery | C12: About Amazon UK | D12: Sep 2025 | E12: https://www.aboutamazon.co.uk/news/retail/amazon-uk-online-grocery-delivery-amazon-fresh
A13: 10 | B13: Whole Foods Market to roll out over 140 staple UK brands | C13: Grocery Gazette | D13: Mar 2024 | E13: https://www.grocerygazette.co.uk/2024/03/01/whole-foods-roll-out-uk-brands/
A14: 11 | B14: Whole Foods Market to shutter two stores and Dartford DC | C14: The Grocer | D14: Mar 2024 | E14: https://www.thegrocer.co.uk/news/whole-foods-market-to-shutter-two-stores-and-dartford-dc/689300.article
A15: 12 | B15: Whole Foods Market expands international footprint with new U.K. location | C15: Business Wire | D15: Feb 2025 | E15: https://www.businesswire.com/news/home/20250227667597/en/Whole-Foods-Market-Expands-International-Footprint-with-New-U.K.-Location
... A23: 20 | B23: Gen Z survey on food transparency | C23: Business Wire / Whole Foods | D23: Sep 2024 | E23: https://www.businesswire.com/news/home/20240923383099/en/Gen-Z-Is-Hungry-for-Transparency-in-Food-Sustainability-and-Quality-Amid-Climate-Concerns-According-to-New-Whole-Foods-Market-Survey
A24: 21 | B24: What do LOHAS shoppers want? | C24: Supermarket News | E24: https://www.supermarketnews.com/grocery-marketing/what-do-lohas-shoppers-want-
A25: 22 | B25: Meet the typical Whole Foods shopper (Numerator data) | C25: AOL / Business Insider | D25: 2023 | E25: https://www.aol.com/news/meet-typical-whole-foods-shopper-142830882.html
A26: 23 | B26: 365 by Whole Foods Market brand profile, UK | C26: Statista | D26: 2022 | E26: https://www.statista.com/forecasts/1335340/365-by-whole-foods-market-organic-food-brand-profile-in-the-uk
A27: 24 | B27: Whole Foods Market UK reviews | C27: Trustpilot | E27: https://uk.trustpilot.com/review/wholefoodsmarket.com
